Workbook

Sheet Template
A1: =+'Annual Raw'!C4 -> #NAME? | B1: 36951 | C1: =EOMONTH(B1,12) -> 37346 | D1: =EOMONTH(C1,12) -> 37711 | E1: =EOMONTH(D1,12) -> 38077 | F1: =EOMONTH(E1,12) -> 38442 | G1: =EOMONTH(F1,12) -> 38807 | H1: =EOMONTH(G1,12) -> 39172 | I1: =EOMONTH(H1,12) -> 39538 | J1: =EOMONTH(I1,12) -> 39903 | ... AE1: =EOMONTH(AD1,12) -> 47573 | AH1: QTR | AI1: 41061 | AJ1: 41153 | AK1: 41244 | AL1: 41334 | AM1: 41426 | AN1: 41518 | AO1: 41609 | AP1: 41699 | AQ1: 41791 | AR1: 41883 | AS1: 41974 | AT1: 42064 | AU1: 42156 | AV1: 42248 | AW1: 42339 | AX1: 42430 | AY1: 42522 | AZ1: 42614 | BA1: 42705 | BB1: 42795 | BC1: 42887 | BD1: 42979 | BE1: 43070 | BF1: 43160 | BG1: 43252 | BH1: 43344 | BI1: 43435 | BJ1: 43525 | BK1: 43617 | BL1: 43709 | BM1: 43800 | BN1: 43891 | BO1: 43983 | BP1: 44075 | BQ1: =EOMONTH(BP1,3) -> 44196 | BR1: =EOMONTH(BQ1,3) -> 44286 | BS1: =EOMONTH(BR1,3) -> 44377 | BT1: =EOMONTH(BS1,3) -> 44469 | BU1: =EOMONTH(BT1,3) -> 44561 | BV1: =EOMONTH(BU1,3) -> 44651 | BW1: =EOMONTH(BV1,3) -> 44742 | BX1: =EOMONTH(BW1,3) -> 44834 | ... DB1: =EOMONTH(DA1,3) -> 47573 | DE1: HISTORICAL ESTIMATES | DF1: 46112
A2: Presentation Data (Start)
A4: Total Clients | AA4: 999186 | CJ4: 957265 | CK4: 992531 | CL4: 999186
A5: Rise in Active clients in Broking | Y5: 127792 | Z5: 147942 | AA5: 149404 | CG5: 90901 | CH5: 73670 | CJ5: 92326 | CK5: 96851 | CL5: 85640
CK6: =+CK5/CG5-1 -> 0.065455826 | CL6: =+CL5/CH5-1 -> 0.16248134
A7: Sales Break Up
A8: Broking Segment | Y8: 458 | Z8: 510 | AA8: 476 | CG8: 115 | CH8: 105 | CJ8: 116 | CK8: 129 | CL8: 120
A9: Non-Broking (Int on margin trading & distribution Income) | Y9: 132 | Z9: 193 | AA9: 265 | CG9: 48 | CH9: 55 | CJ9: 68 | CK9: 69 | CL9: 78
A10: Other income from Operations | Y10: 92 | Z10: 143 | AA10: 192 | CG10: 41 | CH10: 39.7 | CJ10: 43 | CK10: 50.6 | CL10: 57
A13: Assets under custody - crs | Y13: 53884 | Z13: 81369 | AA13: 94416 | CJ13: 101960 | CK13: 105772 | CL13: 94415
A14: Assets under distribution - crs | Z14: 6459 | AA14: 7788 | CG14: 6335 | CJ14: 7736 | CK14: 8368 | CL14: 7787
A15: MTF Books - crs | Z15: 686 | AA15: 1101 | CH15: 686 | CI15: 861 | CJ15: 1084 | CK15: 1231 | CL15: 1102
CH17: =+CH8/CH13 -> #DIV/0! | CI17: =+CI8/CI13 -> #DIV/0! | CJ17: =+CJ8/CJ13 -> 0.0011377011 | CK17: =+CK8/CK13 -> 0.0012196044 | CL17: =+CL8/CL13 -> 0.0012709845
CH18: =+CH9/CH14 -> #DIV/0! | CI18: =+CI9/CI14 -> #DIV/0! | CJ18: =+CJ9/CJ14 -> 0.0087900724 | CK18: =+CK9/CK14 -> 0.0082456979 | CL18: =+CL9/CL14 -> 0.010016694
CH19: =+CH10/CH15 -> 0.05787172 | CI19: =+CI10/CI15 -> 0 | CJ19: =+CJ10/CJ15 -> 0.039667897 | CK19: =+CK10/CK15 -> 0.041104793 | CL19: =+CL10/CL15 -> 0.051724138
A20: Presentation Data (End)
A21: Profit & Loss- Annual (Start)
A22: Gross Revenue | B22: ='Annual Raw'!C6 -> #NAME? | C22: ='Annual Raw'!D6 -> #NAME? | D22: ='Annual Raw'!E6 -> #NAME? | E22: ='Annual Raw'!F6 -> #NAME? | F22: ='Annual Raw'!G6 -> #NAME? | G22: ='Annual Raw'!H6 -> #NAME? | H22: ='Annual Raw'!I6 -> #NAME? | I22: ='Annual Raw'!J6 -> #NAME? | ... AA22: ='Annual Raw'!AB6 -> #NAME? | AB22: =+SUM(CM22:CP22) -> #NAME? | AC22: =+SUM(CQ22:CT22) -> #NAME? | AD22: =+SUM(CU22:CX22) -> #NAME? | AE22: =+SUM(CY22:DB22) -> #NAME? | AI22: ='QTR Raw'!C6+'QTR Raw'!C8 -> #NAME? | AJ22: ='QTR Raw'!D6+'QTR Raw'!D8 -> #NAME? | AK22: ='QTR Raw'!E6+'QTR Raw'!E8 -> #NAME? | AL22: ='QTR Raw'!F6+'QTR Raw'!F8 -> #NAME? | AM22: ='QTR Raw'!G6+'QTR Raw'!G8 -> #NAME? | AN22: ='QTR Raw'!H6+'QTR Raw'!H8 -> #NAME? | AO22: ='QTR Raw'!I6+'QTR Raw'!I8 -> #NAME? | AP22: ='QTR Raw'!J6+'QTR Raw'!J8 -> #NAME? | ... CG22: ='QTR Raw'!BA6+'QTR Raw'!BA8 -> #NAME? | CH22: 199.625 | CI22: ='QTR Raw'!BC6+'QTR Raw'!BC8 -> #NAME? | CJ22: ='QTR Raw'!BD6+'QTR Raw'!BD8 -> #NAME? | CK22: ='QTR Raw'!BE6+'QTR Raw'!BE8 -> #NAME? | CL22: ='QTR Raw'!BF6+'QTR Raw'!BF8 -> #NAME? | CM22: =+CI24+(CM25*CI24) -> #NAME? | CN22: =+CJ24+(CN25*CJ24) -> #NAME? | CO22: =+CK24+(CO25*CK24) -> #NAME? | CP22: =+CL24+(CP25*CL24) -> #NAME? | CQ22: =+CM24+(CQ25*CM24) -> #NAME? | CR22: =+CN24+(CR25*CN24) -> #NAME? | CS22: =+CO24+(CS25*CO24) -> #NAME? | CT22: =+CP24+(CT25*CP24) -> #NAME? | ... DB22: =+CX24+(DB25*CX24) -> #NAME? | DF22: 932.157
A23: Less: Exise Duty | B23: ='Annual Raw'!C7+'Annual Raw'!C8+'Annual Raw'!C9 -> #NAME? | C23: ='Annual Raw'!D7+'Annual Raw'!D8+'Annual Raw'!D9 -> #NAME? | D23: ='Annual Raw'!E7+'Annual Raw'!E8+'Annual Raw'!E9 -> #NAME? | E23: ='Annual Raw'!F7+'Annual Raw'!F8+'Annual Raw'!F9 -> #NAME? | F23: ='Annual Raw'!G7+'Annual Raw'!G8+'Annual Raw'!G9 -> #NAME? | G23: ='Annual Raw'!H7+'Annual Raw'!H8+'Annual Raw'!H9 -> #NAME? | H23: ='Annual Raw'!I7+'Annual Raw'!I8+'Annual Raw'!I9 -> #NAME? | I23: ='Annual Raw'!J7+'Annual Raw'!J8+'Annual Raw'!J9 -> #NAME? | ... AA23: ='Annual Raw'!AB7+'Annual Raw'!AB8+'Annual Raw'!AB9 -> #NAME? | AB23: =+SUM(CM23:CP23) -> 0 | AC23: =+SUM(CQ23:CT23) -> 0 | AD23: =+SUM(CU23:CX23) -> 0 | AE23: =+SUM(CY23:DB23) -> 0 | AI23: =+'QTR Raw'!C20+'QTR Raw'!C19+'QTR Raw'!C13+'QTR Raw'!C7 -> #NAME? | AJ23: =+'QTR Raw'!D20+'QTR Raw'!D19+'QTR Raw'!D13+'QTR Raw'!D7 -> #NAME? | AK23: =+'QTR Raw'!E20+'QTR Raw'!E19+'QTR Raw'!E13+'QTR Raw'!E7 -> #NAME? | AL23: =+'QTR Raw'!F20+'QTR Raw'!F19+'QTR Raw'!F13+'QTR Raw'!F7 -> #NAME? | AM23: =+'QTR Raw'!G20+'QTR Raw'!G19+'QTR Raw'!G13+'QTR Raw'!G7 -> #NAME? | AN23: =+'QTR Raw'!H20+'QTR Raw'!H19+'QTR Raw'!H13+'QTR Raw'!H7 -> #NAME? | AO23: =+'QTR Raw'!I20+'QTR Raw'!I19+'QTR Raw'!I13+'QTR Raw'!I7 -> #NAME? | AP23: =+'QTR Raw'!J20+'QTR Raw'!J19+'QTR Raw'!J13+'QTR Raw'!J7 -> #NAME? | ... CL23: =+'QTR Raw'!BF20+'QTR Raw'!BF19+'QTR Raw'!BF13+'QTR Raw'!BF7 -> #NAME? | DF23: 0
A24: Net Revenue | B24: =+B22-B23 -> #NAME? | C24: =+C22-C23 -> #NAME? | D24: =+D22-D23 -> #NAME? | E24: =+E22-E23 -> #NAME? | F24: =+F22-F23 -> #NAME? | G24: =+G22-G23 -> #NAME? | H24: =+H22-H23 -> #NAME? | I24: =+I22-I23 -> #NAME? | ... AE24: =+AE22-AE23 -> #NAME? | AI24: =+AI22-AI23 -> #NAME? | AJ24: =+AJ22-AJ23 -> #NAME? | AK24: =+AK22-AK23 -> #NAME? | AL24: =+AL22-AL23 -> #NAME? | AM24: =+AM22-AM23 -> #NAME? | AN24: =+AN22-AN23 -> #NAME? | AO24: =+AO22-AO23 -> #NAME? | AP24: =+AP22-AP23 -> #NAME? | ... DB24: =+DB22-DB23 -> #NAME? | DF24: 932.157
A25: Net Revenue YOY% | C25: =C24/B24-1 -> #NAME? | D25: =D24/C24-1 -> #NAME? | E25: =E24/D24-1 -> #NAME? | F25: =F24/E24-1 -> #NAME? | G25: =G24/F24-1 -> #NAME? | H25: =H24/G24-1 -> #NAME? | I25: =I24/H24-1 -> #NAME? | J25: =J24/I24-1 -> #NAME? | ... AE25: =AE24/AD24-1 -> #NAME? | AM25: =+IF(AI24<0,1-AM24/AI24,AM24/AI24-1) -> #NAME? | AN25: =+IF(AJ24<0,1-AN24/AJ24,AN24/AJ24-1) -> #NAME? | AO25: =+IF(AK24<0,1-AO24/AK24,AO24/AK24-1) -> #NAME? | AP25: =+IF(AL24<0,1-AP24/AL24,AP24/AL24-1) -> #NAME? | AQ25: =+IF(AM24<0,1-AQ24/AM24,AQ24/AM24-1) -> #NAME? | AR25: =+IF(AN24<0,1-AR24/AN24,AR24/AN24-1) -> #NAME? | AS25: =+IF(AO24<0,1-AS24/AO24,AS24/AO24-1) -> #NAME? | AT25: =+IF(AP24<0,1-AT24/AP24,AT24/AP24-1) -> #NAME? | ... CL25: =+IF(CH24<0,1-CL24/CH24,CL24/CH24-1) -> #NAME? | CM25: 0.25 | CN25: =+AVERAGE(CJ25:CM25) -> #NAME? | CO25: =+AVERAGE(CK25:CN25) -> #NAME? | CP25: =+AVERAGE(CL25:CO25) -> #NAME? | CQ25: =+AVERAGE(CM25:CP25) -> #NAME? | CR25: =+AVERAGE(CN25:CQ25) -> #NAME? | CS25: =+AVERAGE(CO25:CR25) -> #NAME? | CT25: =+AVERAGE(CP25:CS25) -> #NAME? | CU25: =+AVERAGE(CQ25:CT25) -> #NAME? | ... DB25: =+AVERAGE(CX25:DA25) -> #NAME? | DF25: 0.10223389
A26: Net Revenue QOQ% | AJ26: =+IF(AI24<0,1-AJ24/AI24,AJ24/AI24-1) -> #NAME? | AK26: =+IF(AJ24<0,1-AK24/AJ24,AK24/AJ24-1) -> #NAME? | AL26: =+IF(AK24<0,1-AL24/AK24,AL24/AK24-1) -> #NAME? | AM26: =+IF(AL24<0,1-AM24/AL24,AM24/AL24-1) -> #NAME? | AN26: =+IF(AM24<0,1-AN24/AM24,AN24/AM24-1) -> #NAME? | AO26: =+IF(AN24<0,1-AO24/AN24,AO24/AN24-1) -> #NAME? | AP26: =+IF(AO24<0,1-AP24/AO24,AP24/AO24-1) -> #NAME? | AQ26: =+IF(AP24<0,1-AQ24/AP24,AQ24/AP24-1) -> #NAME? | ... CL26: =+IF(CK24<0,1-CL24/CK24,CL24/CK24-1) -> #NAME? | CM26: =+CM24/CL24-1 -> #NAME? | CN26: =+CN24/CM24-1 -> #NAME? | CO26: =+CO24/CN24-1 -> #NAME? | CP26: =+CP24/CO24-1 -> #NAME? | CQ26: =+CQ24/CP24-1 -> #NAME? | CR26: =+CR24/CQ24-1 -> #NAME? | CS26: =+CS24/CR24-1 -> #NAME? | CT26: =+CT24/CS24-1 -> #NAME? | ... DB26: =+DB24/DA24-1 -> #NAME?
A27: Increase/Decrease in Stock | B27: ='Annual Raw'!C11 -> #NAME? | C27: ='Annual Raw'!D11 -> #NAME? | D27: ='Annual Raw'!E11 -> #NAME? | E27: ='Annual Raw'!F11 -> #NAME? | F27: ='Annual Raw'!G11 -> #NAME? | G27: ='Annual Raw'!H11 -> #NAME? | H27: ='Annual Raw'!I11 -> #NAME? | I27: ='Annual Raw'!J11 -> #NAME? | ... AA27: ='Annual Raw'!AB11 -> #NAME? | AB27: =+SUM(CM27:CP27) -> 0 | AC27: =+SUM(CQ27:CT27) -> 0 | AD27: =+SUM(CU27:CX27) -> 0 | AE27: =+SUM(CY27:DB27) -> 0 | AI27: ='QTR Raw'!C10 -> #NAME? | AJ27: ='QTR Raw'!D10 -> #NAME? | AK27: ='QTR Raw'!E10 -> #NAME? | AL27: ='QTR Raw'!F10 -> #NAME? | AM27: ='QTR Raw'!G10 -> #NAME? | AN27: ='QTR Raw'!H10 -> #NAME? | AO27: ='QTR Raw'!I10 -> #NAME? | AP27: ='QTR Raw'!J10 -> #NAME? | ... CL27: ='QTR Raw'!BF10 -> #NAME? | DF27: 0
A28: Purchase of Finished Goods | B28: 0 | C28: 0 | D28: 0 | E28: 0 | F28: 0 | G28: 0 | H28: 0 | I28: 0 | J28: 0 | K28: 0 | L28: 0 | M28: 0 | N28: 0 | O28: 0 | P28: 0 | Q28: 0 | R28: 0 | S28: 0 | T28: 0 | U28: 0 | V28: 0 | W28: 0 | X28: 0 | Y28: 0 | Z28: 0 | AA28: 0 | AB28: =+SUM(CM28:CP28) -> 0 | AC28: =+SUM(CQ28:CT28) -> 0 | AD28: =+SUM(CU28:CX28) -> 0 | AE28: =+SUM(CY28:DB28) -> 0 | AI28: ='QTR Raw'!C12 -> #NAME? | AJ28: ='QTR Raw'!D12 -> #NAME? | AK28: ='QTR Raw'!E12 -> #NAME? | AL28: ='QTR Raw'!F12 -> #NAME? | AM28: ='QTR Raw'!G12 -> #NAME? | AN28: ='QTR Raw'!H12 -> #NAME? | AO28: ='QTR Raw'!I12 -> #NAME? | AP28: ='QTR Raw'!J12 -> #NAME? | ... CL28: ='QTR Raw'!BF12 -> #NAME? | DF28: 0
A29: Raw Material Consumed | B29: ='Annual Raw'!C12 -> #NAME? | C29: ='Annual Raw'!D12 -> #NAME? | D29: ='Annual Raw'!E12 -> #NAME? | E29: ='Annual Raw'!F12 -> #NAME? | F29: ='Annual Raw'!G12 -> #NAME? | G29: ='Annual Raw'!H12 -> #NAME? | H29: ='Annual Raw'!I12 -> #NAME? | I29: ='Annual Raw'!J12 -> #NAME? | ... AA29: ='Annual Raw'!AB12 -> #NAME? | AB29: =+SUM(CM29:CP29) -> #NAME? | AC29: =+SUM(CQ29:CT29) -> #NAME? | AD29: =+SUM(CU29:CX29) -> #NAME? | AE29: =+SUM(CY29:DB29) -> #NAME? | AI29: ='QTR Raw'!C11 -> #NAME? | AJ29: ='QTR Raw'!D11 -> #NAME? | AK29: ='QTR Raw'!E11 -> #NAME? | AL29: ='QTR Raw'!F11 -> #NAME? | AM29: ='QTR Raw'!G11 -> #NAME? | AN29: ='QTR Raw'!H11 -> #NAME? | AO29: ='QTR Raw'!I11 -> #NAME? | AP29: ='QTR Raw'!J11 -> #NAME? | ... CL29: ='QTR Raw'!BF11 -> #NAME? | CM29: =+CM24-CM30 -> #NAME? | CN29: =+CN24-CN30 -> #NAME? | CO29: =+CO24-CO30 -> #NAME? | CP29: =+CP24-CP30 -> #NAME? | CQ29: =+CQ24-CQ30 -> #NAME? | CR29: =+CR24-CR30 -> #NAME? | CS29: =+CS24-CS30 -> #NAME? | CT29: =+CT24-CT30 -> #NAME? | ... DB29: =+DB24-DB30 -> #NAME? | DF29: 0
A30: Gross Profit | B30: =B24-B27-B29-B28 -> #NAME? | C30: =C24-C27-C29-C28 -> #NAME? | D30: =D24-D27-D29-D28 -> #NAME? | E30: =E24-E27-E29-E28 -> #NAME? | F30: =F24-F27-F29-F28 -> #NAME? | G30: =G24-G27-G29-G28 -> #NAME? | H30: =H24-H27-H29-H28 -> #NAME? | I30: =I24-I27-I29-I28 -> #NAME? | ... AE30: =AE24-AE27-AE29-AE28 -> #NAME? | AI30: =AI24-AI27-AI29-AI28 -> #NAME? | AJ30: =AJ24-AJ27-AJ29-AJ28 -> #NAME? | AK30: =AK24-AK27-AK29-AK28 -> #NAME? | AL30: =AL24-AL27-AL29-AL28 -> #NAME? | AM30: =AM24-AM27-AM29-AM28 -> #NAME? | AN30: =AN24-AN27-AN29-AN28 -> #NAME? | AO30: =AO24-AO27-AO29-AO28 -> #NAME? | AP30: =AP24-AP27-AP29-AP28 -> #NAME? | ... CL30: =CL24-CL27-CL29-CL28 -> #NAME? | CM30: =+CM31*CM24 -> #NAME? | CN30: =+CN31*CN24 -> #NAME? | CO30: =+CO31*CO24 -> #NAME? | CP30: =+CP31*CP24 -> #NAME? | CQ30: =+CQ31*CQ24 -> #NAME? | CR30: =+CR31*CR24 -> #NAME? | CS30: =+CS31*CS24 -> #NAME? | CT30: =+CT31*CT24 -> #NAME? | ... DB30: =+DB31*DB24 -> #NAME? | DF30: 932.157
A31: GP% | B31: =B30/B24 -> #NAME? | C31: =C30/C24 -> #NAME? | D31: =D30/D24 -> #NAME? | E31: =E30/E24 -> #NAME? | F31: =F30/F24 -> #NAME? | G31: =G30/G24 -> #NAME? | H31: =H30/H24 -> #NAME? | I31: =I30/I24 -> #NAME? | ... AE31: =AE30/AE24 -> #NAME? | AI31: =AI30/AI24 -> #NAME? | AJ31: =AJ30/AJ24 -> #NAME? | AK31: =AK30/AK24 -> #NAME? | AL31: =AL30/AL24 -> #NAME? | AM31: =AM30/AM24 -> #NAME? | AN31: =AN30/AN24 -> #NAME? | AO31: =AO30/AO24 -> #NAME? | AP31: =AP30/AP24 -> #NAME? | ... CL31: =CL30/CL24 -> #NAME? | CM31: =AVERAGE(CI31:CL31) -> #NAME? | CN31: =AVERAGE(CJ31:CM31) -> #NAME? | CO31: =AVERAGE(CK31:CN31) -> #NAME? | CP31: =AVERAGE(CL31:CO31) -> #NAME? | CQ31: =AVERAGE(CM31:CP31) -> #NAME? | CR31: =AVERAGE(CN31:CQ31) -> #NAME? | CS31: =AVERAGE(CO31:CR31) -> #NAME? | CT31: =AVERAGE(CP31:CS31) -> #NAME? | ... DB31: =AVERAGE(CX31:DA31) -> #NAME? | DF31: 1
A32: GP YOY% | C32: =+IF(B30<0,1-C30/B30,C30/B30-1) -> #NAME? | D32: =+IF(C30<0,1-D30/C30,D30/C30-1) -> #NAME? | E32: =+IF(D30<0,1-E30/D30,E30/D30-1) -> #NAME? | F32: =+IF(E30<0,1-F30/E30,F30/E30-1) -> #NAME? | G32: =+IF(F30<0,1-G30/F30,G30/F30-1) -> #NAME? | H32: =+IF(G30<0,1-H30/G30,H30/G30-1) -> #NAME? | I32: =+IF(H30<0,1-I30/H30,I30/H30-1) -> #NAME? | J32: =+IF(I30<0,1-J30/I30,J30/I30-1) -> #NAME? | ... AE32: =+IF(AD30<0,1-AE30/AD30,AE30/AD30-1) -> #NAME? | AM32: =+IF(AI30<0,1-AM30/AI30,AM30/AI30-1) -> #NAME? | AN32: =+IF(AJ30<0,1-AN30/AJ30,AN30/AJ30-1) -> #NAME? | AO32: =+IF(AK30<0,1-AO30/AK30,AO30/AK30-1) -> #NAME? | AP32: =+IF(AL30<0,1-AP30/AL30,AP30/AL30-1) -> #NAME? | AQ32: =+IF(AM30<0,1-AQ30/AM30,AQ30/AM30-1) -> #NAME? | AR32: =+IF(AN30<0,1-AR30/AN30,AR30/AN30-1) -> #NAME? | AS32: =+IF(AO30<0,1-AS30/AO30,AS30/AO30-1) -> #NAME? | AT32: =+IF(AP30<0,1-AT30/AP30,AT30/AP30-1) -> #NAME? | ... CL32: =+IF(CH30<0,1-CL30/CH30,CL30/CH30-1) -> #NAME? | CM32: =+CM30/CI30-1 -> #NAME? | CN32: =+CN30/CJ30-1 -> #NAME? | CO32: =+CO30/CK30-1 -> #NAME? | CP32: =+CP30/CL30-1 -> #NAME? | CQ32: =+CQ30/CM30-1 -> #NAME? | CR32: =+CR30/CN30-1 -> #NAME? | CS32: =+CS30/CO30-1 -> #NAME? | CT32: =+CT30/CP30-1 -> #NAME? | ... DB32: =+DB30/CX30-1 -> #NAME? | DF32: 0.10223389
A33: GP QOQ% | AJ33: =+IF(AI30<0,1-AJ30/AI30,AJ30/AI30-1) -> #NAME? | AK33: =+IF(AJ30<0,1-AK30/AJ30,AK30/AJ30-1) -> #NAME? | AL33: =+IF(AK30<0,1-AL30/AK30,AL30/AK30-1) -> #NAME? | AM33: =+IF(AL30<0,1-AM30/AL30,AM30/AL30-1) -> #NAME? | AN33: =+IF(AM30<0,1-AN30/AM30,AN30/AM30-1) -> #NAME? | AO33: =+IF(AN30<0,1-AO30/AN30,AO30/AN30-1) -> #NAME? | AP33: =+IF(AO30<0,1-AP30/AO30,AP30/AO30-1) -> #NAME? | AQ33: =+IF(AP30<0,1-AQ30/AP30,AQ30/AP30-1) -> #NAME? | ... CL33: =+IF(CK30<0,1-CL30/CK30,CL30/CK30-1) -> #NAME? | CM33: =+CM30/CL30-1 -> #NAME? | CN33: =+CN30/CM30-1 -> #NAME? | CO33: =+CO30/CN30-1 -> #NAME? | CP33: =+CP30/CO30-1 -> #NAME? | CQ33: =+CQ30/CP30-1 -> #NAME? | CR33: =+CR30/CQ30-1 -> #NAME? | CS33: =+CS30/CR30-1 -> #NAME? | CT33: =+CT30/CS30-1 -> #NAME? | ... DB33: =+DB30/DA30-1 -> #NAME?
A34: Employee Cost | B34: ='Annual Raw'!C14 -> #NAME? | C34: ='Annual Raw'!D14 -> #NAME? | D34: ='Annual Raw'!E14 -> #NAME? | E34: ='Annual Raw'!F14 -> #NAME? | F34: ='Annual Raw'!G14 -> #NAME? | G34: ='Annual Raw'!H14 -> #NAME? | H34: ='Annual Raw'!I14 -> #NAME? | I34: ='Annual Raw'!J14 -> #NAME? | ... AA34: ='Annual Raw'!AB14 -> #NAME? | AB34: =+SUM(CM34:CP34) -> #NAME? | AC34: =+SUM(CQ34:CT34) -> #NAME? | AD34: =+SUM(CU34:CX34) -> #NAME? | AE34: =+SUM(CY34:DB34) -> #NAME? | AI34: ='QTR Raw'!C16 -> #NAME? | AJ34: ='QTR Raw'!D16 -> #NAME? | AK34: ='QTR Raw'!E16 -> #NAME? | AL34: ='QTR Raw'!F16 -> #NAME? | AM34: ='QTR Raw'!G16 -> #NAME? | AN34: ='QTR Raw'!H16 -> #NAME? | AO34: ='QTR Raw'!I16 -> #NAME? | AP34: ='QTR Raw'!J16 -> #NAME? | ... CG34: ='QTR Raw'!BA16 -> #NAME? | CH34: 66.834 | CI34: ='QTR Raw'!BC16 -> #NAME? | CJ34: ='QTR Raw'!BD16 -> #NAME? | CK34: ='QTR Raw'!BE16 -> #NAME? | CL34: ='QTR Raw'!BF16 -> #NAME? | CM34: =CI34*107% -> #NAME? | CN34: =CJ34*107% -> #NAME? | CO34: =CK34*107% -> #NAME? | CP34: =CL34*107% -> #NAME? | CQ34: =CM34*107% -> #NAME? | CR34: =CN34*107% -> #NAME? | CS34: =CO34*107% -> #NAME? | CT34: =CP34*107% -> #NAME? | ... DB34: =CX34*107% -> #NAME? | DF34: 303.296
A35: General and Administration Expenses | B35: ='Annual Raw'!C17 -> #NAME? | C35: ='Annual Raw'!D17 -> #NAME? | D35: ='Annual Raw'!E17 -> #NAME? | E35: ='Annual Raw'!F17 -> #NAME? | F35: ='Annual Raw'!G17 -> #NAME? | G35: ='Annual Raw'!H17 -> #NAME? | H35: ='Annual Raw'!I17 -> #NAME? | I35: ='Annual Raw'!J17 -> #NAME? | ... AA35: ='Annual Raw'!AB17 -> #NAME? | AB35: =+SUM(CM35:CP35) -> 0 | AC35: =+SUM(CQ35:CT35) -> 0 | AD35: =+SUM(CU35:CX35) -> 0 | AE35: =+SUM(CY35:DB35) -> 0 | AI35: ='QTR Raw'!C17 -> #NAME? | AJ35: ='QTR Raw'!D17 -> #NAME? | AK35: ='QTR Raw'!E17 -> #NAME? | AL35: ='QTR Raw'!F17 -> #NAME? | AM35: ='QTR Raw'!G17 -> #NAME? | AN35: ='QTR Raw'!H17 -> #NAME? | AO35: ='QTR Raw'!I17 -> #NAME? | AP35: ='QTR Raw'!J17 -> #NAME? | ... CG35: ='QTR Raw'!BA17 -> #NAME? | CH35: 23.9 | CI35: ='QTR Raw'!BC17 -> #NAME? | CJ35: ='QTR Raw'!BD17 -> #NAME? | CK35: ='QTR Raw'!BE17 -> #NAME? | CL35: ='QTR Raw'!BF17 -> #NAME? | DF35: 98.548
A36: Miscellaneous Expenses | B36: ='Annual Raw'!C19-'Annual Raw'!C20 -> #NAME? | C36: ='Annual Raw'!D19-'Annual Raw'!D20 -> #NAME? | D36: ='Annual Raw'!E19-'Annual Raw'!E20 -> #NAME? | E36: ='Annual Raw'!F19-'Annual Raw'!F20 -> #NAME? | F36: ='Annual Raw'!G19-'Annual Raw'!G20 -> #NAME? | G36: ='Annual Raw'!H19-'Annual Raw'!H20 -> #NAME? | H36: ='Annual Raw'!I19-'Annual Raw'!I20 -> #NAME? | I36: ='Annual Raw'!J19-'Annual Raw'!J20 -> #NAME? | ... AA36: ='Annual Raw'!AB19-'Annual Raw'!AB20 -> #NAME? | AB36: =+SUM(CM36:CP36) -> 0 | AC36: =+SUM(CQ36:CT36) -> 0 | AD36: =+SUM(CU36:CX36) -> 0 | AE36: =+SUM(CY36:DB36) -> 0 | AI36: =+'QTR Raw'!C21 -> #NAME? | AJ36: =+'QTR Raw'!D21 -> #NAME? | AK36: =+'QTR Raw'!E21 -> #NAME? | AL36: =+'QTR Raw'!F21 -> #NAME? | AM36: =+'QTR Raw'!G21 -> #NAME? | AN36: =+'QTR Raw'!H21 -> #NAME? | AO36: =+'QTR Raw'!I21 -> #NAME? | AP36: =+'QTR Raw'!J21 -> #NAME? | ... CG36: =+'QTR Raw'!BA21 -> #NAME? | CH36: -0.29 | CI36: =+'QTR Raw'!BC21 -> #NAME? | CJ36: =+'QTR Raw'!BD21 -> #NAME? | CK36: =+'QTR Raw'!BE21 -> #NAME? | CL36: =+'QTR Raw'!BF21 -> #NAME? | DF36: 1.3
A37: Other Manufacturing Expenses | B37: ='Annual Raw'!C15+'Annual Raw'!C16 -> #NAME? | C37: ='Annual Raw'!D15+'Annual Raw'!D16 -> #NAME? | D37: ='Annual Raw'!E15+'Annual Raw'!E16 -> #NAME? | E37: ='Annual Raw'!F15+'Annual Raw'!F16 -> #NAME? | F37: ='Annual Raw'!G15+'Annual Raw'!G16 -> #NAME? | G37: ='Annual Raw'!H15+'Annual Raw'!H16 -> #NAME? | H37: ='Annual Raw'!I15+'Annual Raw'!I16 -> #NAME? | I37: ='Annual Raw'!J15+'Annual Raw'!J16 -> #NAME? | ... AA37: ='Annual Raw'!AB15+'Annual Raw'!AB16 -> #NAME? | AB37: =+SUM(CM37:CP37) -> #NAME? | AC37: =+SUM(CQ37:CT37) -> #NAME? | AD37: =+SUM(CU37:CX37) -> #NAME? | AE37: =+SUM(CY37:DB37) -> #NAME? | AI37: ='QTR Raw'!C14 -> #NAME? | AJ37: ='QTR Raw'!D14 -> #NAME? | AK37: ='QTR Raw'!E14 -> #NAME? | AL37: ='QTR Raw'!F14 -> #NAME? | AM37: ='QTR Raw'!G14 -> #NAME? | AN37: ='QTR Raw'!H14 -> #NAME? | AO37: ='QTR Raw'!I14 -> #NAME? | AP37: ='QTR Raw'!J14 -> #NAME? | ... CG37: ='QTR Raw'!BA14 -> #NAME? | CH37: 36.28 | CI37: ='QTR Raw'!BC14 -> #NAME? | CJ37: ='QTR Raw'!BD14 -> #NAME? | CK37: ='QTR Raw'!BE14 -> #NAME? | CL37: ='QTR Raw'!BF14 -> #NAME? | CM37: =CM40-CM34-CM35-CM36-CM38-CM39 -> #NAME? | CN37: =CN40-CN34-CN35-CN36-CN38-CN39 -> #NAME? | CO37: =CO40-CO34-CO35-CO36-CO38-CO39 -> #NAME? | CP37: =CP40-CP34-CP35-CP36-CP38-CP39 -> #NAME? | CQ37: =CQ40-CQ34-CQ35-CQ36-CQ38-CQ39 -> #NAME? | CR37: =CR40-CR34-CR35-CR36-CR38-CR39 -> #NAME? | CS37: =CS40-CS34-CS35-CS36-CS38-CS39 -> #NAME? | CT37: =CT40-CT34-CT35-CT36-CT38-CT39 -> #NAME? | ... DB37: =DB40-DB34-DB35-DB36-DB38-DB39 -> #NAME? | DF37: 150.144
A38: Power & Fuel Cost | B38: ='Annual Raw'!C13 -> #NAME? | C38: ='Annual Raw'!D13 -> #NAME? | D38: ='Annual Raw'!E13 -> #NAME? | E38: ='Annual Raw'!F13 -> #NAME? | F38: ='Annual Raw'!G13 -> #NAME? | G38: ='Annual Raw'!H13 -> #NAME? | H38: ='Annual Raw'!I13 -> #NAME? | I38: ='Annual Raw'!J13 -> #NAME? | ... AA38: ='Annual Raw'!AB13 -> #NAME? | AB38: =+SUM(CM38:CP38) -> 0 | AC38: =+SUM(CQ38:CT38) -> 0 | AD38: =+SUM(CU38:CX38) -> 0 | AE38: =+SUM(CY38:DB38) -> 0 | AI38: ='QTR Raw'!C15 -> #NAME? | AJ38: ='QTR Raw'!D15 -> #NAME? | AK38: ='QTR Raw'!E15 -> #NAME? | AL38: ='QTR Raw'!F15 -> #NAME? | AM38: ='QTR Raw'!G15 -> #NAME? | AN38: ='QTR Raw'!H15 -> #NAME? | AO38: ='QTR Raw'!I15 -> #NAME? | AP38: ='QTR Raw'!J15 -> #NAME? | ... CL38: ='QTR Raw'!BF15 -> #NAME? | DF38: 0
A39: Selling and Distribution Expenses | B39: ='Annual Raw'!C18 -> #NAME? | C39: ='Annual Raw'!D18 -> #NAME? | D39: ='Annual Raw'!E18 -> #NAME? | E39: ='Annual Raw'!F18 -> #NAME? | F39: ='Annual Raw'!G18 -> #NAME? | G39: ='Annual Raw'!H18 -> #NAME? | H39: ='Annual Raw'!I18 -> #NAME? | I39: ='Annual Raw'!J18 -> #NAME? | ... AA39: ='Annual Raw'!AB18 -> #NAME? | AB39: =+SUM(CM39:CP39) -> 0 | AC39: =+SUM(CQ39:CT39) -> 0 | AD39: =+SUM(CU39:CX39) -> 0 | AE39: =+SUM(CY39:DB39) -> 0 | AI39: ='QTR Raw'!C18 -> #NAME? | AJ39: ='QTR Raw'!D18 -> #NAME? | AK39: ='QTR Raw'!E18 -> #NAME? | AL39: ='QTR Raw'!F18 -> #NAME? | AM39: ='QTR Raw'!G18 -> #NAME? | AN39: ='QTR Raw'!H18 -> #NAME? | AO39: ='QTR Raw'!I18 -> #NAME? | AP39: ='QTR Raw'!J18 -> #NAME? | ... CL39: ='QTR Raw'!BF18 -> #NAME? | DF39: 0
A40: Total Cost | B40: =+SUM(B34:B39) -> #NAME? | C40: =+SUM(C34:C39) -> #NAME? | D40: =+SUM(D34:D39) -> #NAME? | E40: =+SUM(E34:E39) -> #NAME? | F40: =+SUM(F34:F39) -> #NAME? | G40: =+SUM(G34:G39) -> #NAME? | H40: =+SUM(H34:H39) -> #NAME? | I40: =+SUM(I34:I39) -> #NAME? | ... AE40: =+SUM(AE34:AE39) -> #NAME? | AI40: =+SUM(AI34:AI39) -> #NAME? | AJ40: =+SUM(AJ34:AJ39) -> #NAME? | AK40: =+SUM(AK34:AK39) -> #NAME? | AL40: =+SUM(AL34:AL39) -> #NAME? | AM40: =+SUM(AM34:AM39) -> #NAME? | AN40: =+SUM(AN34:AN39) -> #NAME? | AO40: =+SUM(AO34:AO39) -> #NAME? | AP40: =+SUM(AP34:AP39) -> #NAME? | ... CL40: =+SUM(CL34:CL39) -> #NAME? | CM40: =CM41*CM24 -> #NAME? | CN40: =CN41*CN24 -> #NAME? | CO40: =CO41*CO24 -> #NAME? | CP40: =CP41*CP24 -> #NAME? | CQ40: =CQ41*CQ24 -> #NAME? | CR40: =CR41*CR24 -> #NAME? | CS40: =CS41*CS24 -> #NAME? | CT40: =CT41*CT24 -> #NAME? | ... DB40: =DB41*DB24 -> #NAME? | DF40: 553.288
A41: Cost % | B41: =B40/B24 -> #NAME? | C41: =C40/C24 -> #NAME? | D41: =D40/D24 -> #NAME? | E41: =E40/E24 -> #NAME? | F41: =F40/F24 -> #NAME? | G41: =G40/G24 -> #NAME? | H41: =H40/H24 -> #NAME? | I41: =I40/I24 -> #NAME? | ... AE41: =AE40/AE24 -> #NAME? | AI41: =AI40/AI24 -> #NAME? | AJ41: =AJ40/AJ24 -> #NAME? | AK41: =AK40/AK24 -> #NAME? | AL41: =AL40/AL24 -> #NAME? | AM41: =AM40/AM24 -> #NAME? | AN41: =AN40/AN24 -> #NAME? | AO41: =AO40/AO24 -> #NAME? | AP41: =AP40/AP24 -> #NAME? | ... CL41: =CL40/CL24 -> #NAME? | CM41: =CL41 -> #NAME? | CN41: =AVERAGE(CJ41:CM41) -> #NAME? | CO41: =AVERAGE(CK41:CN41) -> #NAME? | CP41: =AVERAGE(CL41:CO41) -> #NAME? | CQ41: =AVERAGE(CM41:CP41) -> #NAME? | CR41: =AVERAGE(CN41:CQ41) -> #NAME? | CS41: =AVERAGE(CO41:CR41) -> #NAME? | CT41: =AVERAGE(CP41:CS41) -> #NAME? | CU41: =AVERAGE(CQ41:CT41) -> #NAME? | ... DB41: =AVERAGE(CX41:DA41) -> #NAME? | DF41: 0.59355666
A42: EBITDA | B42: =B30-B40 -> #NAME? | C42: =C30-C40 -> #NAME? | D42: =D30-D40 -> #NAME? | E42: =E30-E40 -> #NAME? | F42: =F30-F40 -> #NAME? | G42: =G30-G40 -> #NAME? | H42: =H30-H40 -> #NAME? | I42: =I30-I40 -> #NAME? | ... AE42: =AE30-AE40 -> #NAME? | AI42: =AI30-AI40 -> #NAME? | AJ42: =AJ30-AJ40 -> #NAME? | AK42: =AK30-AK40 -> #NAME? | AL42: =AL30-AL40 -> #NAME? | AM42: =AM30-AM40 -> #NAME? | AN42: =AN30-AN40 -> #NAME? | AO42: =AO30-AO40 -> #NAME? | AP42: =AP30-AP40 -> #NAME? | ... DB42: =DB30-DB40 -> #NAME? | DF42: 378.869
A43: EBITDA Margins | B43: =B42/B24 -> #NAME? | C43: =C42/C24 -> #NAME? | D43: =D42/D24 -> #NAME? | E43: =E42/E24 -> #NAME? | F43: =F42/F24 -> #NAME? | G43: =G42/G24 -> #NAME? | H43: =H42/H24 -> #NAME? | I43: =I42/I24 -> #NAME? | ... AE43: =AE42/AE24 -> #NAME? | AI43: =AI42/AI24 -> #NAME? | AJ43: =AJ42/AJ24 -> #NAME? | AK43: =AK42/AK24 -> #NAME? | AL43: =AL42/AL24 -> #NAME? | AM43: =AM42/AM24 -> #NAME? | AN43: =AN42/AN24 -> #NAME? | AO43: =AO42/AO24 -> #NAME? | AP43: =AP42/AP24 -> #NAME? | ... DB43: =DB42/DB24 -> #NAME? | DF43: 0.40644334
A44: EBITDA YOY% | C44: =+IF(B42<0,1-C42/B42,C42/B42-1) -> #NAME? | D44: =+IF(C42<0,1-D42/C42,D42/C42-1) -> #NAME? | E44: =+IF(D42<0,1-E42/D42,E42/D42-1) -> #NAME? | F44: =+IF(E42<0,1-F42/E42,F42/E42-1) -> #NAME? | G44: =+IF(F42<0,1-G42/F42,G42/F42-1) -> #NAME? | H44: =+IF(G42<0,1-H42/G42,H42/G42-1) -> #NAME? | I44: =+IF(H42<0,1-I42/H42,I42/H42-1) -> #NAME? | J44: =+IF(I42<0,1-J42/I42,J42/I42-1) -> #NAME? | ... AE44: =+IF(AD42<0,1-AE42/AD42,AE42/AD42-1) -> #NAME? | AM44: =+IF(AI42<0,1-AM42/AI42,AM42/AI42-1) -> #NAME? | AN44: =+IF(AJ42<0,1-AN42/AJ42,AN42/AJ42-1) -> #NAME? | AO44: =+IF(AK42<0,1-AO42/AK42,AO42/AK42-1) -> #NAME? | AP44: =+IF(AL42<0,1-AP42/AL42,AP42/AL42-1) -> #NAME? | AQ44: =+IF(AM42<0,1-AQ42/AM42,AQ42/AM42-1) -> #NAME? | AR44: =+IF(AN42<0,1-AR42/AN42,AR42/AN42-1) -> #NAME? | AS44: =+IF(AO42<0,1-AS42/AO42,AS42/AO42-1) -> #NAME? | AT44: =+IF(AP42<0,1-AT42/AP42,AT42/AP42-1) -> #NAME? | ... CL44: =+IF(CH42<0,1-CL42/CH42,CL42/CH42-1) -> #NAME? | CM44: =+CM42/CI42-1 -> #NAME? | CN44: =+CN42/CJ42-1 -> #NAME? | CO44: =+CO42/CK42-1 -> #NAME? | CP44: =+CP42/CL42-1 -> #NAME? | CQ44: =+CQ42/CM42-1 -> #NAME? | CR44: =+CR42/CN42-1 -> #NAME? | CS44: =+CS42/CO42-1 -> #NAME? | CT44: =+CT42/CP42-1 -> #NAME? | ... DB44: =+DB42/CX42-1 -> #NAME? | DF44: 0.21718332
...

Sheet QTR Raw
A1: ='Annual Raw'!A1 -> 226159 | B1: X | C1: 201206 | D1: 201209 | E1: 201212 | F1: 201303 | G1: 201306 | H1: 201309 | I1: 201312 | J1: 201403 | K1: 201406 | L1: 201409 | M1: 201412 | N1: 201503 | O1: 201506 | P1: 201509 | Q1: 201512 | R1: 201603 | S1: 201606 | T1: 201609 | U1: 201612 | V1: 201703 | W1: 201706 | X1: 201709 | Y1: 201712 | Z1: 201803 | AA1: 201806 | AB1: 201809 | AC1: 201812 | AD1: 201903 | AE1: 201906 | AF1: 201909 | AG1: 201912 | AH1: 202003 | AI1: 202006 | AJ1: 202009 | AK1: 202012 | AL1: 202103 | AM1: 202106 | AN1: 202109 | AO1: 202112 | AP1: 202203 | AQ1: 202206 | AR1: 202209 | AS1: 202212 | AT1: 202303 | AU1: 202306 | AV1: 202309 | AW1: 202312 | AX1: 202403 | AY1: 202406 | AZ1: 202409 | BA1: 202412 | BB1: 202503 | BC1: 202506 | BD1: 202509 | BE1: 202512 | BF1: 202603 | BG1: 202606 | BH1: 202609 | BI1: 202612 | BJ1: 202703 | BK1: 202706 | BL1: 202709 | BM1: 202712 | BN1: 202803 | BO1: 202806 | BP1: 202809 | BQ1: 202812 | BR1: 202903 | BS1: 202906 | BT1: 202909 | BU1: 202912 | BV1: 203003
A3: Field Description | B3: Field Name
A4: Company Name | B4: CD_COMPNAME | C4: =_xll.EQNXTDZ(A1,B4,C1) -> #NAME?
A5: Date End | B5: QTR_DATE_END | C5: =_xll.EQNXTDZ($A$1,$B5,C$1,$B$1) -> #NAME? | D5: =_xll.EQNXTDZ($A$1,$B5,D$1,$B$1) -> #NAME? | E5: =_xll.EQNXTDZ($A$1,$B5,E$1,$B$1) -> #NAME? | F5: =_xll.EQNXTDZ($A$1,$B5,F$1,$B$1) -> #NAME? | G5: =_xll.EQNXTDZ($A$1,$B5,G$1,$B$1) -> #NAME? | H5: =_xll.EQNXTDZ($A$1,$B5,H$1,$B$1) -> #NAME? | I5: =_xll.EQNXTDZ($A$1,$B5,I$1,$B$1) -> #NAME? | J5: =_xll.EQNXTDZ($A$1,$B5,J$1,$B$1) -> #NAME? | ... BV5: =_xll.EQNXTDZ($A$1,$B5,BV$1,$B$1) -> #NAME?
A6: Gross Sales | B6: QTR_GROSS_SALE | C6: =_xll.EQNXTDZ($A$1,$B6,C$1,$B$1) -> #NAME? | D6: =_xll.EQNXTDZ($A$1,$B6,D$1,$B$1) -> #NAME? | E6: =_xll.EQNXTDZ($A$1,$B6,E$1,$B$1) -> #NAME? | F6: =_xll.EQNXTDZ($A$1,$B6,F$1,$B$1) -> #NAME? | G6: =_xll.EQNXTDZ($A$1,$B6,G$1,$B$1) -> #NAME? | H6: =_xll.EQNXTDZ($A$1,$B6,H$1,$B$1) -> #NAME? | I6: =_xll.EQNXTDZ($A$1,$B6,I$1,$B$1) -> #NAME? | J6: =_xll.EQNXTDZ($A$1,$B6,J$1,$B$1) -> #NAME? | ... BV6: =_xll.EQNXTDZ($A$1,$B6,BV$1,$B$1) -> #NAME?
A7: Less: Excise Duty | B7: QTR_EXCISE_DUTY | C7: =_xll.EQNXTDZ($A$1,$B7,C$1,$B$1) -> #NAME? | D7: =_xll.EQNXTDZ($A$1,$B7,D$1,$B$1) -> #NAME? | E7: =_xll.EQNXTDZ($A$1,$B7,E$1,$B$1) -> #NAME? | F7: =_xll.EQNXTDZ($A$1,$B7,F$1,$B$1) -> #NAME? | G7: =_xll.EQNXTDZ($A$1,$B7,G$1,$B$1) -> #NAME? | H7: =_xll.EQNXTDZ($A$1,$B7,H$1,$B$1) -> #NAME? | I7: =_xll.EQNXTDZ($A$1,$B7,I$1,$B$1) -> #NAME? | J7: =_xll.EQNXTDZ($A$1,$B7,J$1,$B$1) -> #NAME? | ... BV7: =_xll.EQNXTDZ($A$1,$B7,BV$1,$B$1) -> #NAME?
A8: Other operating income | B8: QTR_JOB_WORKS | C8: =_xll.EQNXTDZ($A$1,$B8,C$1,$B$1) -> #NAME? | D8: =_xll.EQNXTDZ($A$1,$B8,D$1,$B$1) -> #NAME? | E8: =_xll.EQNXTDZ($A$1,$B8,E$1,$B$1) -> #NAME? | F8: =_xll.EQNXTDZ($A$1,$B8,F$1,$B$1) -> #NAME? | G8: =_xll.EQNXTDZ($A$1,$B8,G$1,$B$1) -> #NAME? | H8: =_xll.EQNXTDZ($A$1,$B8,H$1,$B$1) -> #NAME? | I8: =_xll.EQNXTDZ($A$1,$B8,I$1,$B$1) -> #NAME? | J8: =_xll.EQNXTDZ($A$1,$B8,J$1,$B$1) -> #NAME? | ... BV8: =_xll.EQNXTDZ($A$1,$B8,BV$1,$B$1) -> #NAME?
A9: Net Sales & Other Operating Income | B9: QTR_NET_SALES | C9: =_xll.EQNXTDZ($A$1,$B9,C$1,$B$1) -> #NAME? | D9: =_xll.EQNXTDZ($A$1,$B9,D$1,$B$1) -> #NAME? | E9: =_xll.EQNXTDZ($A$1,$B9,E$1,$B$1) -> #NAME? | F9: =_xll.EQNXTDZ($A$1,$B9,F$1,$B$1) -> #NAME? | G9: =_xll.EQNXTDZ($A$1,$B9,G$1,$B$1) -> #NAME? | H9: =_xll.EQNXTDZ($A$1,$B9,H$1,$B$1) -> #NAME? | I9: =_xll.EQNXTDZ($A$1,$B9,I$1,$B$1) -> #NAME? | J9: =_xll.EQNXTDZ($A$1,$B9,J$1,$B$1) -> #NAME? | ... BV9: =_xll.EQNXTDZ($A$1,$B9,BV$1,$B$1) -> #NAME?
A10: (Increase) / Decrease In Stocks | B10: QTR_INC_DEC_INVENTORY | C10: =_xll.EQNXTDZ($A$1,$B10,C$1,$B$1) -> #NAME? | D10: =_xll.EQNXTDZ($A$1,$B10,D$1,$B$1) -> #NAME? | E10: =_xll.EQNXTDZ($A$1,$B10,E$1,$B$1) -> #NAME? | F10: =_xll.EQNXTDZ($A$1,$B10,F$1,$B$1) -> #NAME? | G10: =_xll.EQNXTDZ($A$1,$B10,G$1,$B$1) -> #NAME? | H10: =_xll.EQNXTDZ($A$1,$B10,H$1,$B$1) -> #NAME? | I10: =_xll.EQNXTDZ($A$1,$B10,I$1,$B$1) -> #NAME? | J10: =_xll.EQNXTDZ($A$1,$B10,J$1,$B$1) -> #NAME? | ... BV10: =_xll.EQNXTDZ($A$1,$B10,BV$1,$B$1) -> #NAME?
A11: Cost of Services & Raw Materials | B11: QTR_RAW_MATERIAL_COST | C11: =_xll.EQNXTDZ($A$1,$B11,C$1,$B$1) -> #NAME? | D11: =_xll.EQNXTDZ($A$1,$B11,D$1,$B$1) -> #NAME? | E11: =_xll.EQNXTDZ($A$1,$B11,E$1,$B$1) -> #NAME? | F11: =_xll.EQNXTDZ($A$1,$B11,F$1,$B$1) -> #NAME? | G11: =_xll.EQNXTDZ($A$1,$B11,G$1,$B$1) -> #NAME? | H11: =_xll.EQNXTDZ($A$1,$B11,H$1,$B$1) -> #NAME? | I11: =_xll.EQNXTDZ($A$1,$B11,I$1,$B$1) -> #NAME? | J11: =_xll.EQNXTDZ($A$1,$B11,J$1,$B$1) -> #NAME? | ... BV11: =_xll.EQNXTDZ($A$1,$B11,BV$1,$B$1) -> #NAME?
A12: Purchase of Finished Goods | B12: QTR_PURCHASE_FIN_GOOD | C12: =_xll.EQNXTDZ($A$1,$B12,C$1,$B$1) -> #NAME? | D12: =_xll.EQNXTDZ($A$1,$B12,D$1,$B$1) -> #NAME? | E12: =_xll.EQNXTDZ($A$1,$B12,E$1,$B$1) -> #NAME? | F12: =_xll.EQNXTDZ($A$1,$B12,F$1,$B$1) -> #NAME? | G12: =_xll.EQNXTDZ($A$1,$B12,G$1,$B$1) -> #NAME? | H12: =_xll.EQNXTDZ($A$1,$B12,H$1,$B$1) -> #NAME? | I12: =_xll.EQNXTDZ($A$1,$B12,I$1,$B$1) -> #NAME? | J12: =_xll.EQNXTDZ($A$1,$B12,J$1,$B$1) -> #NAME? | ... BV12: =_xll.EQNXTDZ($A$1,$B12,BV$1,$B$1) -> #NAME?
A13: Excise Duty | B13: QTR_EXCISE | C13: =_xll.EQNXTDZ($A$1,$B13,C$1,$B$1) -> #NAME? | D13: =_xll.EQNXTDZ($A$1,$B13,D$1,$B$1) -> #NAME? | E13: =_xll.EQNXTDZ($A$1,$B13,E$1,$B$1) -> #NAME? | F13: =_xll.EQNXTDZ($A$1,$B13,F$1,$B$1) -> #NAME? | G13: =_xll.EQNXTDZ($A$1,$B13,G$1,$B$1) -> #NAME? | H13: =_xll.EQNXTDZ($A$1,$B13,H$1,$B$1) -> #NAME? | I13: =_xll.EQNXTDZ($A$1,$B13,I$1,$B$1) -> #NAME? | J13: =_xll.EQNXTDZ($A$1,$B13,J$1,$B$1) -> #NAME? | ... BV13: =_xll.EQNXTDZ($A$1,$B13,BV$1,$B$1) -> #NAME?
A14: Operating & Manufacturing Expenses | B14: QTR_MFG_EXPS | C14: =_xll.EQNXTDZ($A$1,$B14,C$1,$B$1) -> #NAME? | D14: =_xll.EQNXTDZ($A$1,$B14,D$1,$B$1) -> #NAME? | E14: =_xll.EQNXTDZ($A$1,$B14,E$1,$B$1) -> #NAME? | F14: =_xll.EQNXTDZ($A$1,$B14,F$1,$B$1) -> #NAME? | G14: =_xll.EQNXTDZ($A$1,$B14,G$1,$B$1) -> #NAME? | H14: =_xll.EQNXTDZ($A$1,$B14,H$1,$B$1) -> #NAME? | I14: =_xll.EQNXTDZ($A$1,$B14,I$1,$B$1) -> #NAME? | J14: =_xll.EQNXTDZ($A$1,$B14,J$1,$B$1) -> #NAME? | ... BV14: =_xll.EQNXTDZ($A$1,$B14,BV$1,$B$1) -> #NAME?
A15: Electricity Power & Fuel Cost | B15: QTR_ELECTRICITY_POWER_FUEL | C15: =_xll.EQNXTDZ($A$1,$B15,C$1,$B$1) -> #NAME? | D15: =_xll.EQNXTDZ($A$1,$B15,D$1,$B$1) -> #NAME? | E15: =_xll.EQNXTDZ($A$1,$B15,E$1,$B$1) -> #NAME? | F15: =_xll.EQNXTDZ($A$1,$B15,F$1,$B$1) -> #NAME? | G15: =_xll.EQNXTDZ($A$1,$B15,G$1,$B$1) -> #NAME? | H15: =_xll.EQNXTDZ($A$1,$B15,H$1,$B$1) -> #NAME? | I15: =_xll.EQNXTDZ($A$1,$B15,I$1,$B$1) -> #NAME? | J15: =_xll.EQNXTDZ($A$1,$B15,J$1,$B$1) -> #NAME? | ... BV15: =_xll.EQNXTDZ($A$1,$B15,BV$1,$B$1) -> #NAME?
A16: Employee Cost | B16: QTR_EXPLOYEE_COST | C16: =_xll.EQNXTDZ($A$1,$B16,C$1,$B$1) -> #NAME? | D16: =_xll.EQNXTDZ($A$1,$B16,D$1,$B$1) -> #NAME? | E16: =_xll.EQNXTDZ($A$1,$B16,E$1,$B$1) -> #NAME? | F16: =_xll.EQNXTDZ($A$1,$B16,F$1,$B$1) -> #NAME? | G16: =_xll.EQNXTDZ($A$1,$B16,G$1,$B$1) -> #NAME? | H16: =_xll.EQNXTDZ($A$1,$B16,H$1,$B$1) -> #NAME? | I16: =_xll.EQNXTDZ($A$1,$B16,I$1,$B$1) -> #NAME? | J16: =_xll.EQNXTDZ($A$1,$B16,J$1,$B$1) -> #NAME? | ... BV16: =_xll.EQNXTDZ($A$1,$B16,BV$1,$B$1) -> #NAME?
... A42: Consolidated PAT(after extra items) | B42: QTR_CONS_PAT_EXITM | C42: =_xll.EQNXTDZ($A$1,$B42,C$1,$B$1) -> #NAME? | D42: =_xll.EQNXTDZ($A$1,$B42,D$1,$B$1) -> #NAME? | E42: =_xll.EQNXTDZ($A$1,$B42,E$1,$B$1) -> #NAME? | F42: =_xll.EQNXTDZ($A$1,$B42,F$1,$B$1) -> #NAME? | G42: =_xll.EQNXTDZ($A$1,$B42,G$1,$B$1) -> #NAME? | H42: =_xll.EQNXTDZ($A$1,$B42,H$1,$B$1) -> #NAME? | I42: =_xll.EQNXTDZ($A$1,$B42,I$1,$B$1) -> #NAME? | J42: =_xll.EQNXTDZ($A$1,$B42,J$1,$B$1) -> #NAME? | ... BV42: =_xll.EQNXTDZ($A$1,$B42,BV$1,$B$1) -> #NAME?
A44: Field Description | B44: Field Name
A45: Equity Capital | B45: QTR_EQUITY_CAP | C45: =_xll.EQNXTDZ($A$1,$B45,C$1,$B$1) -> #NAME? | D45: =_xll.EQNXTDZ($A$1,$B45,D$1,$B$1) -> #NAME? | E45: =_xll.EQNXTDZ($A$1,$B45,E$1,$B$1) -> #NAME? | F45: =_xll.EQNXTDZ($A$1,$B45,F$1,$B$1) -> #NAME? | G45: =_xll.EQNXTDZ($A$1,$B45,G$1,$B$1) -> #NAME? | H45: =_xll.EQNXTDZ($A$1,$B45,H$1,$B$1) -> #NAME? | I45: =_xll.EQNXTDZ($A$1,$B45,I$1,$B$1) -> #NAME? | J45: =_xll.EQNXTDZ($A$1,$B45,J$1,$B$1) -> #NAME? | ... BV45: =_xll.EQNXTDZ($A$1,$B45,BV$1,$B$1) -> #NAME?
A46: Face Value | B46: QTR_FV | C46: =_xll.EQNXTDZ($A$1,$B46,C$1,$B$1) -> #NAME? | D46: =_xll.EQNXTDZ($A$1,$B46,D$1,$B$1) -> #NAME? | E46: =_xll.EQNXTDZ($A$1,$B46,E$1,$B$1) -> #NAME? | F46: =_xll.EQNXTDZ($A$1,$B46,F$1,$B$1) -> #NAME? | G46: =_xll.EQNXTDZ($A$1,$B46,G$1,$B$1) -> #NAME? | H46: =_xll.EQNXTDZ($A$1,$B46,H$1,$B$1) -> #NAME? | I46: =_xll.EQNXTDZ($A$1,$B46,I$1,$B$1) -> #NAME? | J46: =_xll.EQNXTDZ($A$1,$B46,J$1,$B$1) -> #NAME? | ... BV46: =_xll.EQNXTDZ($A$1,$B46,BV$1,$B$1) -> #NAME?
A47: Month End | B47: BMONTH_MONTHEND | C47: =_xll.EQNXTDZ($A$1,$B47,C$5) -> #NAME? | D47: =_xll.EQNXTDZ($A$1,$B47,D$5) -> #NAME? | E47: =_xll.EQNXTDZ($A$1,$B47,E$5) -> #NAME? | F47: =_xll.EQNXTDZ($A$1,$B47,F$5) -> #NAME? | G47: =_xll.EQNXTDZ($A$1,$B47,G$5) -> #NAME? | H47: =_xll.EQNXTDZ($A$1,$B47,H$5) -> #NAME? | I47: =_xll.EQNXTDZ($A$1,$B47,I$5) -> #NAME? | J47: =_xll.EQNXTDZ($A$1,$B47,J$5) -> #NAME? | ... BV47: =_xll.EQNXTDZ($A$1,$B47,BV$5) -> #NAME?
A48: Close | B48: BMONTH_CLOSE | C48: =_xll.EQNXTDZ($A$1,$B48,C$5) -> #NAME? | D48: =_xll.EQNXTDZ($A$1,$B48,D$5) -> #NAME? | E48: =_xll.EQNXTDZ($A$1,$B48,E$5) -> #NAME? | F48: =_xll.EQNXTDZ($A$1,$B48,F$5) -> #NAME? | G48: =_xll.EQNXTDZ($A$1,$B48,G$5) -> #NAME? | H48: =_xll.EQNXTDZ($A$1,$B48,H$5) -> #NAME? | I48: =_xll.EQNXTDZ($A$1,$B48,I$5) -> #NAME? | J48: =_xll.EQNXTDZ($A$1,$B48,J$5) -> #NAME? | ... BV48: =_xll.EQNXTDZ($A$1,$B48,BV$5) -> #NAME?
A49: Total of Promoter and Promoter Group | B49: SHP_TPFTOTALPROMOTER | C49: =_xll.EQNXTDZ($A$1,$B49,C$5) -> #NAME? | D49: =_xll.EQNXTDZ($A$1,$B49,D$5) -> #NAME? | E49: =_xll.EQNXTDZ($A$1,$B49,E$5) -> #NAME? | F49: =_xll.EQNXTDZ($A$1,$B49,F$5) -> #NAME? | G49: =_xll.EQNXTDZ($A$1,$B49,G$5) -> #NAME? | H49: =_xll.EQNXTDZ($A$1,$B49,H$5) -> #NAME? | I49: =_xll.EQNXTDZ($A$1,$B49,I$5) -> #NAME? | J49: =_xll.EQNXTDZ($A$1,$B49,J$5) -> #NAME? | ... BV49: =_xll.EQNXTDZ($A$1,$B49,BV$5) -> #NAME?
A50: Total of Promoter and Promoter Group Pledged | B50: SHP_PSHFTOTALPROMOTER | C50: =_xll.EQNXTDZ($A$1,$B50,C$5) -> #NAME? | D50: =_xll.EQNXTDZ($A$1,$B50,D$5) -> #NAME? | E50: =_xll.EQNXTDZ($A$1,$B50,E$5) -> #NAME? | F50: =_xll.EQNXTDZ($A$1,$B50,F$5) -> #NAME? | G50: =_xll.EQNXTDZ($A$1,$B50,G$5) -> #NAME? | H50: =_xll.EQNXTDZ($A$1,$B50,H$5) -> #NAME? | I50: =_xll.EQNXTDZ($A$1,$B50,I$5) -> #NAME? | J50: =_xll.EQNXTDZ($A$1,$B50,J$5) -> #NAME? | ... BV50: =_xll.EQNXTDZ($A$1,$B50,BV$5) -> #NAME?
A54: Field Description | B54: Field Name | C54: =_xll.EQNXTDZ($A$1,$B54,C$5) -> #NAME? | D54: =_xll.EQNXTDZ($A$1,$B54,D$5) -> #NAME? | E54: =_xll.EQNXTDZ($A$1,$B54,E$5) -> #NAME? | F54: =_xll.EQNXTDZ($A$1,$B54,F$5) -> #NAME? | G54: =_xll.EQNXTDZ($A$1,$B54,G$5) -> #NAME? | H54: =_xll.EQNXTDZ($A$1,$B54,H$5) -> #NAME? | I54: =_xll.EQNXTDZ($A$1,$B54,I$5) -> #NAME? | J54: =_xll.EQNXTDZ($A$1,$B54,J$5) -> #NAME? | ... BV54: =_xll.EQNXTDZ($A$1,$B54,BV$5) -> #NAME?
A55: Year End | B55: QTRB_DATE_END | C55: =_xll.EQNXTDZ($A$1,$B55,C$5,$B$1) -> #NAME? | D55: =_xll.EQNXTDZ($A$1,$B55,D$5,$B$1) -> #NAME? | E55: =_xll.EQNXTDZ($A$1,$B55,E$5,$B$1) -> #NAME? | F55: =_xll.EQNXTDZ($A$1,$B55,F$5,$B$1) -> #NAME? | G55: =_xll.EQNXTDZ($A$1,$B55,G$5,$B$1) -> #NAME? | H55: =_xll.EQNXTDZ($A$1,$B55,H$5,$B$1) -> #NAME? | I55: =_xll.EQNXTDZ($A$1,$B55,I$5,$B$1) -> #NAME? | J55: =_xll.EQNXTDZ($A$1,$B55,J$5,$B$1) -> #NAME? | ... BV55: =_xll.EQNXTDZ($A$1,$B55,BV$5,$B$1) -> #NAME?
A56: Share Capital | B56: QTRB_SHARE_CAPITAL | C56: =_xll.EQNXTDZ($A$1,$B56,C$5,$B$1) -> #NAME? | D56: =_xll.EQNXTDZ($A$1,$B56,D$5,$B$1) -> #NAME? | E56: =_xll.EQNXTDZ($A$1,$B56,E$5,$B$1) -> #NAME? | F56: =_xll.EQNXTDZ($A$1,$B56,F$5,$B$1) -> #NAME? | G56: =_xll.EQNXTDZ($A$1,$B56,G$5,$B$1) -> #NAME? | H56: =_xll.EQNXTDZ($A$1,$B56,H$5,$B$1) -> #NAME? | I56: =_xll.EQNXTDZ($A$1,$B56,I$5,$B$1) -> #NAME? | J56: =_xll.EQNXTDZ($A$1,$B56,J$5,$B$1) -> #NAME? | ... BV56: =_xll.EQNXTDZ($A$1,$B56,BV$5,$B$1) -> #NAME?
A57: Share Warrants & outstandings | B57: QTRB_SHAREWARNDOUT | C57: =_xll.EQNXTDZ($A$1,$B57,C$5,$B$1) -> #NAME? | D57: =_xll.EQNXTDZ($A$1,$B57,D$5,$B$1) -> #NAME? | E57: =_xll.EQNXTDZ($A$1,$B57,E$5,$B$1) -> #NAME? | F57: =_xll.EQNXTDZ($A$1,$B57,F$5,$B$1) -> #NAME? | G57: =_xll.EQNXTDZ($A$1,$B57,G$5,$B$1) -> #NAME? | H57: =_xll.EQNXTDZ($A$1,$B57,H$5,$B$1) -> #NAME? | I57: =_xll.EQNXTDZ($A$1,$B57,I$5,$B$1) -> #NAME? | J57: =_xll.EQNXTDZ($A$1,$B57,J$5,$B$1) -> #NAME? | ... BV57: =_xll.EQNXTDZ($A$1,$B57,BV$5,$B$1) -> #NAME?
A58: Reserves & Surplus | B58: QTRB_RESERVE | C58: =_xll.EQNXTDZ($A$1,$B58,C$5,$B$1) -> #NAME? | D58: =_xll.EQNXTDZ($A$1,$B58,D$5,$B$1) -> #NAME? | E58: =_xll.EQNXTDZ($A$1,$B58,E$5,$B$1) -> #NAME? | F58: =_xll.EQNXTDZ($A$1,$B58,F$5,$B$1) -> #NAME? | G58: =_xll.EQNXTDZ($A$1,$B58,G$5,$B$1) -> #NAME? | H58: =_xll.EQNXTDZ($A$1,$B58,H$5,$B$1) -> #NAME? | I58: =_xll.EQNXTDZ($A$1,$B58,I$5,$B$1) -> #NAME? | J58: =_xll.EQNXTDZ($A$1,$B58,J$5,$B$1) -> #NAME? | ... BV58: =_xll.EQNXTDZ($A$1,$B58,BV$5,$B$1) -> #NAME?
A59: Shareholder's Funds | B59: QTRB_SHAREHODERS_FUNDS | C59: =_xll.EQNXTDZ($A$1,$B59,C$5,$B$1) -> #NAME? | D59: =_xll.EQNXTDZ($A$1,$B59,D$5,$B$1) -> #NAME? | E59: =_xll.EQNXTDZ($A$1,$B59,E$5,$B$1) -> #NAME? | F59: =_xll.EQNXTDZ($A$1,$B59,F$5,$B$1) -> #NAME? | G59: =_xll.EQNXTDZ($A$1,$B59,G$5,$B$1) -> #NAME? | H59: =_xll.EQNXTDZ($A$1,$B59,H$5,$B$1) -> #NAME? | I59: =_xll.EQNXTDZ($A$1,$B59,I$5,$B$1) -> #NAME? | J59: =_xll.EQNXTDZ($A$1,$B59,J$5,$B$1) -> #NAME? | ... BV59: =_xll.EQNXTDZ($A$1,$B59,BV$5,$B$1) -> #NAME?
A60: Minority Interest | B60: QTRB_MINORITY_INTEREST_BS | C60: =_xll.EQNXTDZ($A$1,$B60,C$5,$B$1) -> #NAME? | D60: =_xll.EQNXTDZ($A$1,$B60,D$5,$B$1) -> #NAME? | E60: =_xll.EQNXTDZ($A$1,$B60,E$5,$B$1) -> #NAME? | F60: =_xll.EQNXTDZ($A$1,$B60,F$5,$B$1) -> #NAME? | G60: =_xll.EQNXTDZ($A$1,$B60,G$5,$B$1) -> #NAME? | H60: =_xll.EQNXTDZ($A$1,$B60,H$5,$B$1) -> #NAME? | I60: =_xll.EQNXTDZ($A$1,$B60,I$5,$B$1) -> #NAME? | J60: =_xll.EQNXTDZ($A$1,$B60,J$5,$B$1) -> #NAME? | ... BV60: =_xll.EQNXTDZ($A$1,$B60,BV$5,$B$1) -> #NAME?
A61: Long Term Borrowings | B61: QTRB_TOTAL_DEBTS | C61: =_xll.EQNXTDZ($A$1,$B61,C$5,$B$1) -> #NAME? | D61: =_xll.EQNXTDZ($A$1,$B61,D$5,$B$1) -> #NAME? | E61: =_xll.EQNXTDZ($A$1,$B61,E$5,$B$1) -> #NAME? | F61: =_xll.EQNXTDZ($A$1,$B61,F$5,$B$1) -> #NAME? | G61: =_xll.EQNXTDZ($A$1,$B61,G$5,$B$1) -> #NAME? | H61: =_xll.EQNXTDZ($A$1,$B61,H$5,$B$1) -> #NAME? | I61: =_xll.EQNXTDZ($A$1,$B61,I$5,$B$1) -> #NAME? | J61: =_xll.EQNXTDZ($A$1,$B61,J$5,$B$1) -> #NAME? | ... BV61: =_xll.EQNXTDZ($A$1,$B61,BV$5,$B$1) -> #NAME?
A62: Secured Loans | B62: QTRB_SECURED_LOANS | C62: =_xll.EQNXTDZ($A$1,$B62,C$5,$B$1) -> #NAME? | D62: =_xll.EQNXTDZ($A$1,$B62,D$5,$B$1) -> #NAME? | E62: =_xll.EQNXTDZ($A$1,$B62,E$5,$B$1) -> #NAME? | F62: =_xll.EQNXTDZ($A$1,$B62,F$5,$B$1) -> #NAME? | G62: =_xll.EQNXTDZ($A$1,$B62,G$5,$B$1) -> #NAME? | H62: =_xll.EQNXTDZ($A$1,$B62,H$5,$B$1) -> #NAME? | I62: =_xll.EQNXTDZ($A$1,$B62,I$5,$B$1) -> #NAME? | J62: =_xll.EQNXTDZ($A$1,$B62,J$5,$B$1) -> #NAME? | ... BV62: =_xll.EQNXTDZ($A$1,$B62,BV$5,$B$1) -> #NAME?
A63: Unsecured Loans | B63: QTRB_UNSECURED_LOANS_NF | C63: =_xll.EQNXTDZ($A$1,$B63,C$5,$B$1) -> #NAME? | D63: =_xll.EQNXTDZ($A$1,$B63,D$5,$B$1) -> #NAME? | E63: =_xll.EQNXTDZ($A$1,$B63,E$5,$B$1) -> #NAME? | F63: =_xll.EQNXTDZ($A$1,$B63,F$5,$B$1) -> #NAME? | G63: =_xll.EQNXTDZ($A$1,$B63,G$5,$B$1) -> #NAME? | H63: =_xll.EQNXTDZ($A$1,$B63,H$5,$B$1) -> #NAME? | I63: =_xll.EQNXTDZ($A$1,$B63,I$5,$B$1) -> #NAME? | J63: =_xll.EQNXTDZ($A$1,$B63,J$5,$B$1) -> #NAME? | ... BV63: =_xll.EQNXTDZ($A$1,$B63,BV$5,$B$1) -> #NAME?
A64: Other Long Term Liabilities | B64: QTRB_OTHER_LT_LIABILITIES | C64: =_xll.EQNXTDZ($A$1,$B64,C$5,$B$1) -> #NAME? | D64: =_xll.EQNXTDZ($A$1,$B64,D$5,$B$1) -> #NAME? | E64: =_xll.EQNXTDZ($A$1,$B64,E$5,$B$1) -> #NAME? | F64: =_xll.EQNXTDZ($A$1,$B64,F$5,$B$1) -> #NAME? | G64: =_xll.EQNXTDZ($A$1,$B64,G$5,$B$1) -> #NAME? | H64: =_xll.EQNXTDZ($A$1,$B64,H$5,$B$1) -> #NAME? | I64: =_xll.EQNXTDZ($A$1,$B64,I$5,$B$1) -> #NAME? | J64: =_xll.EQNXTDZ($A$1,$B64,J$5,$B$1) -> #NAME? | ... BV64: =_xll.EQNXTDZ($A$1,$B64,BV$5,$B$1) -> #NAME?
A65: Long Term Trade Payables | B65: QTRB_LT_TRADE_PAYABLE | C65: =_xll.EQNXTDZ($A$1,$B65,C$5,$B$1) -> #NAME? | D65: =_xll.EQNXTDZ($A$1,$B65,D$5,$B$1) -> #NAME? | E65: =_xll.EQNXTDZ($A$1,$B65,E$5,$B$1) -> #NAME? | F65: =_xll.EQNXTDZ($A$1,$B65,F$5,$B$1) -> #NAME? | G65: =_xll.EQNXTDZ($A$1,$B65,G$5,$B$1) -> #NAME? | H65: =_xll.EQNXTDZ($A$1,$B65,H$5,$B$1) -> #NAME? | I65: =_xll.EQNXTDZ($A$1,$B65,I$5,$B$1) -> #NAME? | J65: =_xll.EQNXTDZ($A$1,$B65,J$5,$B$1) -> #NAME? | ... BV65: =_xll.EQNXTDZ($A$1,$B65,BV$5,$B$1) -> #NAME?
A66: Lont Term Provisions | B66: QTRB_LT_PROVISIONS | C66: =_xll.EQNXTDZ($A$1,$B66,C$5,$B$1) -> #NAME? | D66: =_xll.EQNXTDZ($A$1,$B66,D$5,$B$1) -> #NAME? | E66: =_xll.EQNXTDZ($A$1,$B66,E$5,$B$1) -> #NAME? | F66: =_xll.EQNXTDZ($A$1,$B66,F$5,$B$1) -> #NAME? | G66: =_xll.EQNXTDZ($A$1,$B66,G$5,$B$1) -> #NAME? | H66: =_xll.EQNXTDZ($A$1,$B66,H$5,$B$1) -> #NAME? | I66: =_xll.EQNXTDZ($A$1,$B66,I$5,$B$1) -> #NAME? | J66: =_xll.EQNXTDZ($A$1,$B66,J$5,$B$1) -> #NAME? | ... BV66: =_xll.EQNXTDZ($A$1,$B66,BV$5,$B$1) -> #NAME?
... A97: Total Assets | B97: QTRB_TOTAL_APPLICATIONS | C97: =_xll.EQNXTDZ($A$1,$B97,C$5,$B$1) -> #NAME? | D97: =_xll.EQNXTDZ($A$1,$B97,D$5,$B$1) -> #NAME? | E97: =_xll.EQNXTDZ($A$1,$B97,E$5,$B$1) -> #NAME? | F97: =_xll.EQNXTDZ($A$1,$B97,F$5,$B$1) -> #NAME? | G97: =_xll.EQNXTDZ($A$1,$B97,G$5,$B$1) -> #NAME? | H97: =_xll.EQNXTDZ($A$1,$B97,H$5,$B$1) -> #NAME? | I97: =_xll.EQNXTDZ($A$1,$B97,I$5,$B$1) -> #NAME? | J97: =_xll.EQNXTDZ($A$1,$B97,J$5,$B$1) -> #NAME? | ... BV97: =_xll.EQNXTDZ($A$1,$B97,BV$5,$B$1) -> #NAME?

Sheet Annual Raw
A1: 226159 | B1: X | C1: 200103 | D1: 200203 | E1: 200303 | F1: 200403 | G1: 200503 | H1: 200603 | I1: 200703 | J1: 200803 | K1: 200903 | L1: 201003 | M1: 201103 | N1: 201203 | O1: 201303 | P1: 201403 | Q1: 201503 | R1: 201603 | S1: 201703 | T1: 201803 | U1: 201903 | V1: 202003 | W1: 202103 | X1: 202203 | Y1: 202303 | Z1: 202403 | AA1: 202503 | AB1: 202603 | AC1: 202703 | AD1: 202803 | AE1: 202903 | AF1: 203003
A3: Field Description | B3: Field Name
A4: Company Name | B4: CD_COMPNAME | C4: =_xll.EQNXTDZ(A1,B4,"L") -> #NAME?
A5: Year End | B5: PL_YEAR_END | C5: =_xll.EQNXTDZ($A$1,$B5,C$1,$B$1) -> #NAME? | D5: =_xll.EQNXTDZ($A$1,$B5,D$1,$B$1) -> #NAME? | E5: =_xll.EQNXTDZ($A$1,$B5,E$1,$B$1) -> #NAME? | F5: =_xll.EQNXTDZ($A$1,$B5,F$1,$B$1) -> #NAME? | G5: =_xll.EQNXTDZ($A$1,$B5,G$1,$B$1) -> #NAME? | H5: =_xll.EQNXTDZ($A$1,$B5,H$1,$B$1) -> #NAME? | I5: =_xll.EQNXTDZ($A$1,$B5,I$1,$B$1) -> #NAME? | J5: =_xll.EQNXTDZ($A$1,$B5,J$1,$B$1) -> #NAME? | ... AF5: =_xll.EQNXTDZ($A$1,$B5,AF$1,$B$1) -> #NAME?
A6: Sales Turnover | B6: PL_TOTAL_GROSS_SALES | C6: =_xll.EQNXTDZ($A$1,$B6,C$1,$B$1) -> #NAME? | D6: =_xll.EQNXTDZ($A$1,$B6,D$1,$B$1) -> #NAME? | E6: =_xll.EQNXTDZ($A$1,$B6,E$1,$B$1) -> #NAME? | F6: =_xll.EQNXTDZ($A$1,$B6,F$1,$B$1) -> #NAME? | G6: =_xll.EQNXTDZ($A$1,$B6,G$1,$B$1) -> #NAME? | H6: =_xll.EQNXTDZ($A$1,$B6,H$1,$B$1) -> #NAME? | I6: =_xll.EQNXTDZ($A$1,$B6,I$1,$B$1) -> #NAME? | J6: =_xll.EQNXTDZ($A$1,$B6,J$1,$B$1) -> #NAME? | ... AF6: =_xll.EQNXTDZ($A$1,$B6,AF$1,$B$1) -> #NAME?
A7: Less: Inter divisional transfers | B7: PL_INTER_DIV_TRF | C7: =_xll.EQNXTDZ($A$1,$B7,C$1,$B$1) -> #NAME? | D7: =_xll.EQNXTDZ($A$1,$B7,D$1,$B$1) -> #NAME? | E7: =_xll.EQNXTDZ($A$1,$B7,E$1,$B$1) -> #NAME? | F7: =_xll.EQNXTDZ($A$1,$B7,F$1,$B$1) -> #NAME? | G7: =_xll.EQNXTDZ($A$1,$B7,G$1,$B$1) -> #NAME? | H7: =_xll.EQNXTDZ($A$1,$B7,H$1,$B$1) -> #NAME? | I7: =_xll.EQNXTDZ($A$1,$B7,I$1,$B$1) -> #NAME? | J7: =_xll.EQNXTDZ($A$1,$B7,J$1,$B$1) -> #NAME? | ... AF7: =_xll.EQNXTDZ($A$1,$B7,AF$1,$B$1) -> #NAME?
A8: Less: Sales Returns | B8: PL_SALES_RETURN | C8: =_xll.EQNXTDZ($A$1,$B8,C$1,$B$1) -> #NAME? | D8: =_xll.EQNXTDZ($A$1,$B8,D$1,$B$1) -> #NAME? | E8: =_xll.EQNXTDZ($A$1,$B8,E$1,$B$1) -> #NAME? | F8: =_xll.EQNXTDZ($A$1,$B8,F$1,$B$1) -> #NAME? | G8: =_xll.EQNXTDZ($A$1,$B8,G$1,$B$1) -> #NAME? | H8: =_xll.EQNXTDZ($A$1,$B8,H$1,$B$1) -> #NAME? | I8: =_xll.EQNXTDZ($A$1,$B8,I$1,$B$1) -> #NAME? | J8: =_xll.EQNXTDZ($A$1,$B8,J$1,$B$1) -> #NAME? | ... AF8: =_xll.EQNXTDZ($A$1,$B8,AF$1,$B$1) -> #NAME?
A9: Less: Excise | B9: PL_EXCISE | C9: =_xll.EQNXTDZ($A$1,$B9,C$1,$B$1) -> #NAME? | D9: =_xll.EQNXTDZ($A$1,$B9,D$1,$B$1) -> #NAME? | E9: =_xll.EQNXTDZ($A$1,$B9,E$1,$B$1) -> #NAME? | F9: =_xll.EQNXTDZ($A$1,$B9,F$1,$B$1) -> #NAME? | G9: =_xll.EQNXTDZ($A$1,$B9,G$1,$B$1) -> #NAME? | H9: =_xll.EQNXTDZ($A$1,$B9,H$1,$B$1) -> #NAME? | I9: =_xll.EQNXTDZ($A$1,$B9,I$1,$B$1) -> #NAME? | J9: =_xll.EQNXTDZ($A$1,$B9,J$1,$B$1) -> #NAME? | ... AF9: =_xll.EQNXTDZ($A$1,$B9,AF$1,$B$1) -> #NAME?
A10: Net Sales | B10: PL_NET_SALES | C10: =_xll.EQNXTDZ($A$1,$B10,C$1,$B$1) -> #NAME? | D10: =_xll.EQNXTDZ($A$1,$B10,D$1,$B$1) -> #NAME? | E10: =_xll.EQNXTDZ($A$1,$B10,E$1,$B$1) -> #NAME? | F10: =_xll.EQNXTDZ($A$1,$B10,F$1,$B$1) -> #NAME? | G10: =_xll.EQNXTDZ($A$1,$B10,G$1,$B$1) -> #NAME? | H10: =_xll.EQNXTDZ($A$1,$B10,H$1,$B$1) -> #NAME? | I10: =_xll.EQNXTDZ($A$1,$B10,I$1,$B$1) -> #NAME? | J10: =_xll.EQNXTDZ($A$1,$B10,J$1,$B$1) -> #NAME? | ... AF10: =_xll.EQNXTDZ($A$1,$B10,AF$1,$B$1) -> #NAME?
A11: Increase/Decrease in Stock | B11: PL_INC_DEC_INVENTORY | C11: =_xll.EQNXTDZ($A$1,$B11,C$1,$B$1) -> #NAME? | D11: =_xll.EQNXTDZ($A$1,$B11,D$1,$B$1) -> #NAME? | E11: =_xll.EQNXTDZ($A$1,$B11,E$1,$B$1) -> #NAME? | F11: =_xll.EQNXTDZ($A$1,$B11,F$1,$B$1) -> #NAME? | G11: =_xll.EQNXTDZ($A$1,$B11,G$1,$B$1) -> #NAME? | H11: =_xll.EQNXTDZ($A$1,$B11,H$1,$B$1) -> #NAME? | I11: =_xll.EQNXTDZ($A$1,$B11,I$1,$B$1) -> #NAME? | J11: =_xll.EQNXTDZ($A$1,$B11,J$1,$B$1) -> #NAME? | ... AF11: =_xll.EQNXTDZ($A$1,$B11,AF$1,$B$1) -> #NAME?
A12: Raw Material Consumed | B12: PL_RAW_MATRS_CONSUMED | C12: =_xll.EQNXTDZ($A$1,$B12,C$1,$B$1) -> #NAME? | D12: =_xll.EQNXTDZ($A$1,$B12,D$1,$B$1) -> #NAME? | E12: =_xll.EQNXTDZ($A$1,$B12,E$1,$B$1) -> #NAME? | F12: =_xll.EQNXTDZ($A$1,$B12,F$1,$B$1) -> #NAME? | G12: =_xll.EQNXTDZ($A$1,$B12,G$1,$B$1) -> #NAME? | H12: =_xll.EQNXTDZ($A$1,$B12,H$1,$B$1) -> #NAME? | I12: =_xll.EQNXTDZ($A$1,$B12,I$1,$B$1) -> #NAME? | J12: =_xll.EQNXTDZ($A$1,$B12,J$1,$B$1) -> #NAME? | ... AF12: =_xll.EQNXTDZ($A$1,$B12,AF$1,$B$1) -> #NAME?
A13: Power & Fuel Cost | B13: PL_POWER_FUEL | C13: =_xll.EQNXTDZ($A$1,$B13,C$1,$B$1) -> #NAME? | D13: =_xll.EQNXTDZ($A$1,$B13,D$1,$B$1) -> #NAME? | E13: =_xll.EQNXTDZ($A$1,$B13,E$1,$B$1) -> #NAME? | F13: =_xll.EQNXTDZ($A$1,$B13,F$1,$B$1) -> #NAME? | G13: =_xll.EQNXTDZ($A$1,$B13,G$1,$B$1) -> #NAME? | H13: =_xll.EQNXTDZ($A$1,$B13,H$1,$B$1) -> #NAME? | I13: =_xll.EQNXTDZ($A$1,$B13,I$1,$B$1) -> #NAME? | J13: =_xll.EQNXTDZ($A$1,$B13,J$1,$B$1) -> #NAME? | ... AF13: =_xll.EQNXTDZ($A$1,$B13,AF$1,$B$1) -> #NAME?
A14: Employee Cost | B14: PL_EMPLOYEES | C14: =_xll.EQNXTDZ($A$1,$B14,C$1,$B$1) -> #NAME? | D14: =_xll.EQNXTDZ($A$1,$B14,D$1,$B$1) -> #NAME? | E14: =_xll.EQNXTDZ($A$1,$B14,E$1,$B$1) -> #NAME? | F14: =_xll.EQNXTDZ($A$1,$B14,F$1,$B$1) -> #NAME? | G14: =_xll.EQNXTDZ($A$1,$B14,G$1,$B$1) -> #NAME? | H14: =_xll.EQNXTDZ($A$1,$B14,H$1,$B$1) -> #NAME? | I14: =_xll.EQNXTDZ($A$1,$B14,I$1,$B$1) -> #NAME? | J14: =_xll.EQNXTDZ($A$1,$B14,J$1,$B$1) -> #NAME? | ... AF14: =_xll.EQNXTDZ($A$1,$B14,AF$1,$B$1) -> #NAME?
A15: Operating & Manufacturing Expenses | B15: PL_GEN_OTHER_MFG_EXPS | C15: =_xll.EQNXTDZ($A$1,$B15,C$1,$B$1) -> #NAME? | D15: =_xll.EQNXTDZ($A$1,$B15,D$1,$B$1) -> #NAME? | E15: =_xll.EQNXTDZ($A$1,$B15,E$1,$B$1) -> #NAME? | F15: =_xll.EQNXTDZ($A$1,$B15,F$1,$B$1) -> #NAME? | G15: =_xll.EQNXTDZ($A$1,$B15,G$1,$B$1) -> #NAME? | H15: =_xll.EQNXTDZ($A$1,$B15,H$1,$B$1) -> #NAME? | I15: =_xll.EQNXTDZ($A$1,$B15,I$1,$B$1) -> #NAME? | J15: =_xll.EQNXTDZ($A$1,$B15,J$1,$B$1) -> #NAME? | ... AF15: =_xll.EQNXTDZ($A$1,$B15,AF$1,$B$1) -> #NAME?
A16: Cost of Software development | B16: PL_COST_SW | C16: =_xll.EQNXTDZ($A$1,$B16,C$1,$B$1) -> #NAME? | D16: =_xll.EQNXTDZ($A$1,$B16,D$1,$B$1) -> #NAME? | E16: =_xll.EQNXTDZ($A$1,$B16,E$1,$B$1) -> #NAME? | F16: =_xll.EQNXTDZ($A$1,$B16,F$1,$B$1) -> #NAME? | G16: =_xll.EQNXTDZ($A$1,$B16,G$1,$B$1) -> #NAME? | H16: =_xll.EQNXTDZ($A$1,$B16,H$1,$B$1) -> #NAME? | I16: =_xll.EQNXTDZ($A$1,$B16,I$1,$B$1) -> #NAME? | J16: =_xll.EQNXTDZ($A$1,$B16,J$1,$B$1) -> #NAME? | ... AF16: =_xll.EQNXTDZ($A$1,$B16,AF$1,$B$1) -> #NAME?
... A36: Profit After Tax from Discontinued Operations | B36: PL_PAT_DIS_OP | C36: =_xll.EQNXTDZ($A$1,$B36,C$1,$B$1) -> #NAME? | D36: =_xll.EQNXTDZ($A$1,$B36,D$1,$B$1) -> #NAME? | E36: =_xll.EQNXTDZ($A$1,$B36,E$1,$B$1) -> #NAME? | F36: =_xll.EQNXTDZ($A$1,$B36,F$1,$B$1) -> #NAME? | G36: =_xll.EQNXTDZ($A$1,$B36,G$1,$B$1) -> #NAME? | H36: =_xll.EQNXTDZ($A$1,$B36,H$1,$B$1) -> #NAME? | I36: =_xll.EQNXTDZ($A$1,$B36,I$1,$B$1) -> #NAME? | J36: =_xll.EQNXTDZ($A$1,$B36,J$1,$B$1) -> #NAME? | ... AF36: =_xll.EQNXTDZ($A$1,$B36,AF$1,$B$1) -> #NAME?
A39: Field Description | B39: Field Name
A40: Year End | B40: BS_YEAR_END | C40: =_xll.EQNXTDZ($A$1,$B40,C$1,$B$1) -> #NAME? | D40: =_xll.EQNXTDZ($A$1,$B40,D$1,$B$1) -> #NAME? | E40: =_xll.EQNXTDZ($A$1,$B40,E$1,$B$1) -> #NAME? | F40: =_xll.EQNXTDZ($A$1,$B40,F$1,$B$1) -> #NAME? | G40: =_xll.EQNXTDZ($A$1,$B40,G$1,$B$1) -> #NAME? | H40: =_xll.EQNXTDZ($A$1,$B40,H$1,$B$1) -> #NAME? | I40: =_xll.EQNXTDZ($A$1,$B40,I$1,$B$1) -> #NAME? | J40: =_xll.EQNXTDZ($A$1,$B40,J$1,$B$1) -> #NAME? | ... AF40: =_xll.EQNXTDZ($A$1,$B40,AF$1,$B$1) -> #NAME?
A41: Share Capital | B41: BS_SHARE_CAPITAL | C41: =_xll.EQNXTDZ($A$1,$B41,C$1,$B$1) -> #NAME? | D41: =_xll.EQNXTDZ($A$1,$B41,D$1,$B$1) -> #NAME? | E41: =_xll.EQNXTDZ($A$1,$B41,E$1,$B$1) -> #NAME? | F41: =_xll.EQNXTDZ($A$1,$B41,F$1,$B$1) -> #NAME? | G41: =_xll.EQNXTDZ($A$1,$B41,G$1,$B$1) -> #NAME? | H41: =_xll.EQNXTDZ($A$1,$B41,H$1,$B$1) -> #NAME? | I41: =_xll.EQNXTDZ($A$1,$B41,I$1,$B$1) -> #NAME? | J41: =_xll.EQNXTDZ($A$1,$B41,J$1,$B$1) -> #NAME? | ... AF41: =_xll.EQNXTDZ($A$1,$B41,AF$1,$B$1) -> #NAME?
A42: Share Warrants & Outstandings | B42: BS_SHAREWROUTST | C42: =_xll.EQNXTDZ($A$1,$B42,C$1,$B$1) -> #NAME? | D42: =_xll.EQNXTDZ($A$1,$B42,D$1,$B$1) -> #NAME? | E42: =_xll.EQNXTDZ($A$1,$B42,E$1,$B$1) -> #NAME? | F42: =_xll.EQNXTDZ($A$1,$B42,F$1,$B$1) -> #NAME? | G42: =_xll.EQNXTDZ($A$1,$B42,G$1,$B$1) -> #NAME? | H42: =_xll.EQNXTDZ($A$1,$B42,H$1,$B$1) -> #NAME? | I42: =_xll.EQNXTDZ($A$1,$B42,I$1,$B$1) -> #NAME? | J42: =_xll.EQNXTDZ($A$1,$B42,J$1,$B$1) -> #NAME? | ... AF42: =_xll.EQNXTDZ($A$1,$B42,AF$1,$B$1) -> #NAME?
A43: Total Reserves | B43: BS_RESERVE | C43: =_xll.EQNXTDZ($A$1,$B43,C$1,$B$1) -> #NAME? | D43: =_xll.EQNXTDZ($A$1,$B43,D$1,$B$1) -> #NAME? | E43: =_xll.EQNXTDZ($A$1,$B43,E$1,$B$1) -> #NAME? | F43: =_xll.EQNXTDZ($A$1,$B43,F$1,$B$1) -> #NAME? | G43: =_xll.EQNXTDZ($A$1,$B43,G$1,$B$1) -> #NAME? | H43: =_xll.EQNXTDZ($A$1,$B43,H$1,$B$1) -> #NAME? | I43: =_xll.EQNXTDZ($A$1,$B43,I$1,$B$1) -> #NAME? | J43: =_xll.EQNXTDZ($A$1,$B43,J$1,$B$1) -> #NAME? | ... AF43: =_xll.EQNXTDZ($A$1,$B43,AF$1,$B$1) -> #NAME?
A44: Shareholder's Funds | B44: BS_SHAREHODERS_FUNDS | C44: =_xll.EQNXTDZ($A$1,$B44,C$1,$B$1) -> #NAME? | D44: =_xll.EQNXTDZ($A$1,$B44,D$1,$B$1) -> #NAME? | E44: =_xll.EQNXTDZ($A$1,$B44,E$1,$B$1) -> #NAME? | F44: =_xll.EQNXTDZ($A$1,$B44,F$1,$B$1) -> #NAME? | G44: =_xll.EQNXTDZ($A$1,$B44,G$1,$B$1) -> #NAME? | H44: =_xll.EQNXTDZ($A$1,$B44,H$1,$B$1) -> #NAME? | I44: =_xll.EQNXTDZ($A$1,$B44,I$1,$B$1) -> #NAME? | J44: =_xll.EQNXTDZ($A$1,$B44,J$1,$B$1) -> #NAME? | ... AF44: =_xll.EQNXTDZ($A$1,$B44,AF$1,$B$1) -> #NAME?
A45: Minority Interest | B45: BS_MINORITY_INTEREST | C45: =_xll.EQNXTDZ($A$1,$B45,C$1,$B$1) -> #NAME? | D45: =_xll.EQNXTDZ($A$1,$B45,D$1,$B$1) -> #NAME? | E45: =_xll.EQNXTDZ($A$1,$B45,E$1,$B$1) -> #NAME? | F45: =_xll.EQNXTDZ($A$1,$B45,F$1,$B$1) -> #NAME? | G45: =_xll.EQNXTDZ($A$1,$B45,G$1,$B$1) -> #NAME? | H45: =_xll.EQNXTDZ($A$1,$B45,H$1,$B$1) -> #NAME? | I45: =_xll.EQNXTDZ($A$1,$B45,I$1,$B$1) -> #NAME? | J45: =_xll.EQNXTDZ($A$1,$B45,J$1,$B$1) -> #NAME? | ... AF45: =_xll.EQNXTDZ($A$1,$B45,AF$1,$B$1) -> #NAME?
A46: Long-Term Borrowings | B46: BS_LTRM_BORROWING | C46: =_xll.EQNXTDZ($A$1,$B46,C$1,$B$1) -> #NAME? | D46: =_xll.EQNXTDZ($A$1,$B46,D$1,$B$1) -> #NAME? | E46: =_xll.EQNXTDZ($A$1,$B46,E$1,$B$1) -> #NAME? | F46: =_xll.EQNXTDZ($A$1,$B46,F$1,$B$1) -> #NAME? | G46: =_xll.EQNXTDZ($A$1,$B46,G$1,$B$1) -> #NAME? | H46: =_xll.EQNXTDZ($A$1,$B46,H$1,$B$1) -> #NAME? | I46: =_xll.EQNXTDZ($A$1,$B46,I$1,$B$1) -> #NAME? | J46: =_xll.EQNXTDZ($A$1,$B46,J$1,$B$1) -> #NAME? | ... AF46: =_xll.EQNXTDZ($A$1,$B46,AF$1,$B$1) -> #NAME?
A47: Secured Loans | B47: BS_SECURED_LOANS | C47: =_xll.EQNXTDZ($A$1,$B47,C$1,$B$1) -> #NAME? | D47: =_xll.EQNXTDZ($A$1,$B47,D$1,$B$1) -> #NAME? | E47: =_xll.EQNXTDZ($A$1,$B47,E$1,$B$1) -> #NAME? | F47: =_xll.EQNXTDZ($A$1,$B47,F$1,$B$1) -> #NAME? | G47: =_xll.EQNXTDZ($A$1,$B47,G$1,$B$1) -> #NAME? | H47: =_xll.EQNXTDZ($A$1,$B47,H$1,$B$1) -> #NAME? | I47: =_xll.EQNXTDZ($A$1,$B47,I$1,$B$1) -> #NAME? | J47: =_xll.EQNXTDZ($A$1,$B47,J$1,$B$1) -> #NAME? | ... AF47: =_xll.EQNXTDZ($A$1,$B47,AF$1,$B$1) -> #NAME?
A48: Unsecured Loans | B48: BS_UNSECURED_LOANS_NF | C48: =_xll.EQNXTDZ($A$1,$B48,C$1,$B$1) -> #NAME? | D48: =_xll.EQNXTDZ($A$1,$B48,D$1,$B$1) -> #NAME? | E48: =_xll.EQNXTDZ($A$1,$B48,E$1,$B$1) -> #NAME? | F48: =_xll.EQNXTDZ($A$1,$B48,F$1,$B$1) -> #NAME? | G48: =_xll.EQNXTDZ($A$1,$B48,G$1,$B$1) -> #NAME? | H48: =_xll.EQNXTDZ($A$1,$B48,H$1,$B$1) -> #NAME? | I48: =_xll.EQNXTDZ($A$1,$B48,I$1,$B$1) -> #NAME? | J48: =_xll.EQNXTDZ($A$1,$B48,J$1,$B$1) -> #NAME? | ... AF48: =_xll.EQNXTDZ($A$1,$B48,AF$1,$B$1) -> #NAME?
A49: Deferred Tax Assets / Liabilities | B49: BS_NET_DEF_TAX_NF | C49: =_xll.EQNXTDZ($A$1,$B49,C$1,$B$1) -> #NAME? | D49: =_xll.EQNXTDZ($A$1,$B49,D$1,$B$1) -> #NAME? | E49: =_xll.EQNXTDZ($A$1,$B49,E$1,$B$1) -> #NAME? | F49: =_xll.EQNXTDZ($A$1,$B49,F$1,$B$1) -> #NAME? | G49: =_xll.EQNXTDZ($A$1,$B49,G$1,$B$1) -> #NAME? | H49: =_xll.EQNXTDZ($A$1,$B49,H$1,$B$1) -> #NAME? | I49: =_xll.EQNXTDZ($A$1,$B49,I$1,$B$1) -> #NAME? | J49: =_xll.EQNXTDZ($A$1,$B49,J$1,$B$1) -> #NAME? | ... AF49: =_xll.EQNXTDZ($A$1,$B49,AF$1,$B$1) -> #NAME?
A50: Other Long Term Liabilities | B50: BS_OTH_LT_LIAB | C50: =_xll.EQNXTDZ($A$1,$B50,C$1,$B$1) -> #NAME? | D50: =_xll.EQNXTDZ($A$1,$B50,D$1,$B$1) -> #NAME? | E50: =_xll.EQNXTDZ($A$1,$B50,E$1,$B$1) -> #NAME? | F50: =_xll.EQNXTDZ($A$1,$B50,F$1,$B$1) -> #NAME? | G50: =_xll.EQNXTDZ($A$1,$B50,G$1,$B$1) -> #NAME? | H50: =_xll.EQNXTDZ($A$1,$B50,H$1,$B$1) -> #NAME? | I50: =_xll.EQNXTDZ($A$1,$B50,I$1,$B$1) -> #NAME? | J50: =_xll.EQNXTDZ($A$1,$B50,J$1,$B$1) -> #NAME? | ... AF50: =_xll.EQNXTDZ($A$1,$B50,AF$1,$B$1) -> #NAME?
A51: Long Term Trade Payables | B51: BS_LT_TRADE_PAYABLES | C51: =_xll.EQNXTDZ($A$1,$B51,C$1,$B$1) -> #NAME? | D51: =_xll.EQNXTDZ($A$1,$B51,D$1,$B$1) -> #NAME? | E51: =_xll.EQNXTDZ($A$1,$B51,E$1,$B$1) -> #NAME? | F51: =_xll.EQNXTDZ($A$1,$B51,F$1,$B$1) -> #NAME? | G51: =_xll.EQNXTDZ($A$1,$B51,G$1,$B$1) -> #NAME? | H51: =_xll.EQNXTDZ($A$1,$B51,H$1,$B$1) -> #NAME? | I51: =_xll.EQNXTDZ($A$1,$B51,I$1,$B$1) -> #NAME? | J51: =_xll.EQNXTDZ($A$1,$B51,J$1,$B$1) -> #NAME? | ... AF51: =_xll.EQNXTDZ($A$1,$B51,AF$1,$B$1) -> #NAME?
... A99: Estimated Capital Contracts Remaining | B99: BS_ESTIMATED_CAPITAL_CONTRACT | C99: =_xll.EQNXTDZ($A$1,$B99,C$1,$B$1) -> #NAME? | D99: =_xll.EQNXTDZ($A$1,$B99,D$1,$B$1) -> #NAME? | E99: =_xll.EQNXTDZ($A$1,$B99,E$1,$B$1) -> #NAME? | F99: =_xll.EQNXTDZ($A$1,$B99,F$1,$B$1) -> #NAME? | G99: =_xll.EQNXTDZ($A$1,$B99,G$1,$B$1) -> #NAME? | H99: =_xll.EQNXTDZ($A$1,$B99,H$1,$B$1) -> #NAME? | I99: =_xll.EQNXTDZ($A$1,$B99,I$1,$B$1) -> #NAME? | J99: =_xll.EQNXTDZ($A$1,$B99,J$1,$B$1) -> #NAME? | ... AF99: =_xll.EQNXTDZ($A$1,$B99,AF$1,$B$1) -> #NAME?
A103: Field Description | B103: Field Name
A104: Equity Paid Up | B104: BS_EQUITY_PAIDUP | C104: =_xll.EQNXTDZ($A$1,$B104,C$1,$B$1) -> #NAME? | D104: =_xll.EQNXTDZ($A$1,$B104,D$1,$B$1) -> #NAME? | E104: =_xll.EQNXTDZ($A$1,$B104,E$1,$B$1) -> #NAME? | F104: =_xll.EQNXTDZ($A$1,$B104,F$1,$B$1) -> #NAME? | G104: =_xll.EQNXTDZ($A$1,$B104,G$1,$B$1) -> #NAME? | H104: =_xll.EQNXTDZ($A$1,$B104,H$1,$B$1) -> #NAME? | I104: =_xll.EQNXTDZ($A$1,$B104,I$1,$B$1) -> #NAME? | J104: =_xll.EQNXTDZ($A$1,$B104,J$1,$B$1) -> #NAME? | ... AF104: =_xll.EQNXTDZ($A$1,$B104,AF$1,$B$1) -> #NAME?
A105: Face Value | B105: BS_FACE_VALUE | C105: =_xll.EQNXTDZ($A$1,$B105,C$1,$B$1) -> #NAME? | D105: =_xll.EQNXTDZ($A$1,$B105,D$1,$B$1) -> #NAME? | E105: =_xll.EQNXTDZ($A$1,$B105,E$1,$B$1) -> #NAME? | F105: =_xll.EQNXTDZ($A$1,$B105,F$1,$B$1) -> #NAME? | G105: =_xll.EQNXTDZ($A$1,$B105,G$1,$B$1) -> #NAME? | H105: =_xll.EQNXTDZ($A$1,$B105,H$1,$B$1) -> #NAME? | I105: =_xll.EQNXTDZ($A$1,$B105,I$1,$B$1) -> #NAME? | J105: =_xll.EQNXTDZ($A$1,$B105,J$1,$B$1) -> #NAME? | ... AF105: =_xll.EQNXTDZ($A$1,$B105,AF$1,$B$1) -> #NAME?
A106: Close Price (Unit Curr.) | B106: FH_YEAR_PRICE | C106: =_xll.EQNXTDZ($A$1,$B106,C$1,$B$1) -> #NAME? | D106: =_xll.EQNXTDZ($A$1,$B106,D$1,$B$1) -> #NAME? | E106: =_xll.EQNXTDZ($A$1,$B106,E$1,$B$1) -> #NAME? | F106: =_xll.EQNXTDZ($A$1,$B106,F$1,$B$1) -> #NAME? | G106: =_xll.EQNXTDZ($A$1,$B106,G$1,$B$1) -> #NAME? | H106: =_xll.EQNXTDZ($A$1,$B106,H$1,$B$1) -> #NAME? | I106: =_xll.EQNXTDZ($A$1,$B106,I$1,$B$1) -> #NAME? | J106: =_xll.EQNXTDZ($A$1,$B106,J$1,$B$1) -> #NAME? | ... AF106: =_xll.EQNXTDZ($A$1,$B106,AF$1,$B$1) -> #NAME?
A107: High Price (Unit Curr.) | B107: FH_HIGH | C107: =_xll.EQNXTDZ($A$1,$B107,C$1,$B$1) -> #NAME? | D107: =_xll.EQNXTDZ($A$1,$B107,D$1,$B$1) -> #NAME? | E107: =_xll.EQNXTDZ($A$1,$B107,E$1,$B$1) -> #NAME? | F107: =_xll.EQNXTDZ($A$1,$B107,F$1,$B$1) -> #NAME? | G107: =_xll.EQNXTDZ($A$1,$B107,G$1,$B$1) -> #NAME? | H107: =_xll.EQNXTDZ($A$1,$B107,H$1,$B$1) -> #NAME? | I107: =_xll.EQNXTDZ($A$1,$B107,I$1,$B$1) -> #NAME? | J107: =_xll.EQNXTDZ($A$1,$B107,J$1,$B$1) -> #NAME? | ... AF107: =_xll.EQNXTDZ($A$1,$B107,AF$1,$B$1) -> #NAME?
A108: Low Price (Unit Curr.) | B108: FH_LOW | C108: =_xll.EQNXTDZ($A$1,$B108,C$1,$B$1) -> #NAME? | D108: =_xll.EQNXTDZ($A$1,$B108,D$1,$B$1) -> #NAME? | E108: =_xll.EQNXTDZ($A$1,$B108,E$1,$B$1) -> #NAME? | F108: =_xll.EQNXTDZ($A$1,$B108,F$1,$B$1) -> #NAME? | G108: =_xll.EQNXTDZ($A$1,$B108,G$1,$B$1) -> #NAME? | H108: =_xll.EQNXTDZ($A$1,$B108,H$1,$B$1) -> #NAME? | I108: =_xll.EQNXTDZ($A$1,$B108,I$1,$B$1) -> #NAME? | J108: =_xll.EQNXTDZ($A$1,$B108,J$1,$B$1) -> #NAME? | ... AF108: =_xll.EQNXTDZ($A$1,$B108,AF$1,$B$1) -> #NAME?
