Workbook

Sheet Template
A1: =+'Annual Raw'!C3 -> #NAME? | B1: =+EOMONTH(C1,-12) -> 36981 | C1: =+EOMONTH(D1,-12) -> 37346 | D1: =+EOMONTH(E1,-12) -> 37711 | E1: =+EOMONTH(F1,-12) -> 38077 | F1: =+EOMONTH(G1,-12) -> 38442 | G1: =+EOMONTH(H1,-12) -> 38807 | H1: =+EOMONTH(I1,-12) -> 39172 | I1: =+EOMONTH(J1,-12) -> 39538 | ... N1: =+EOMONTH(O1,-12) -> 41364 | O1: 41699 | P1: 42064 | Q1: 42430 | R1: 42795 | S1: 43160 | T1: 43525 | U1: 43891 | V1: 44256 | W1: 44621 | X1: 44986 | Y1: 45352 | Z1: 45717 | AA1: 46082 | AB1: 46447 | AC1: 46813 | AD1: 47178 | AE1: 47543 | AG1: Quarterly | AH1: 42185 | AI1: =+EOMONTH(AH1,3) -> 42277 | AJ1: =+EOMONTH(AI1,3) -> 42369 | AK1: =+EOMONTH(AJ1,3) -> 42460 | AL1: =+EOMONTH(AK1,3) -> 42551 | AM1: =+EOMONTH(AL1,3) -> 42643 | AN1: =+EOMONTH(AM1,3) -> 42735 | AO1: =+EOMONTH(AN1,3) -> 42825 | AP1: =+EOMONTH(AO1,3) -> 42916 | ... CO1: =+EOMONTH(CN1,3) -> 47573 | CR1: Historical Estimates | CS1: 46082
A2: Presentation Data (Start)
A4: Average eq | D4: =AVERAGE(C109:D109) -> #NAME? | E4: =AVERAGE(D109:E109) -> #NAME? | F4: =AVERAGE(E109:F109) -> #NAME? | G4: =AVERAGE(F109:G109) -> #NAME? | H4: =AVERAGE(G109:H109) -> #NAME? | I4: =AVERAGE(H109:I109) -> #NAME? | J4: =AVERAGE(I109:J109) -> #NAME? | K4: =AVERAGE(J109:K109) -> #NAME? | ... X4: =AVERAGE(W109:X109) -> #NAME? | Y4: =+AVERAGE(BN4:BQ4) -> #NAME? | Z4: =+AVERAGE(BR4:BU4) -> #NAME? | AA4: =+AVERAGE(BV4:BY4) -> #NAME? | AB4: =+AVERAGE(BZ4:CC4) -> #NAME? | AC4: =+AVERAGE(CD4:CG4) -> #NAME? | AD4: =+AVERAGE(CH4:CK4) -> #NAME? | AE4: =+AVERAGE(CL4:CO4) -> #NAME? | AH4: =AVERAGE(AG109:AH109) -> #NAME? | AI4: =AVERAGE(AH109:AI109) -> #NAME? | AJ4: =AVERAGE(AI109:AJ109) -> #NAME? | AK4: =AVERAGE(AJ109:AK109) -> #NAME? | AL4: =AVERAGE(AK109:AL109) -> #NAME? | AM4: =AVERAGE(AL109:AM109) -> #NAME? | AN4: =AVERAGE(AM109:AN109) -> #NAME? | AO4: =AVERAGE(AN109:AO109) -> #NAME? | ... CO4: =AVERAGE(CN109:CO109) -> #NAME? | CS4: 34079.696
A5: Average assets | D5: =AVERAGE(C116:D116) -> #NAME? | E5: =AVERAGE(D116:E116) -> #NAME? | F5: =AVERAGE(E116:F116) -> #NAME? | G5: =AVERAGE(F116:G116) -> #NAME? | H5: =AVERAGE(G116:H116) -> #NAME? | I5: =AVERAGE(H116:I116) -> #NAME? | J5: =AVERAGE(I116:J116) -> #NAME? | K5: =AVERAGE(J116:K116) -> #NAME? | ... X5: =AVERAGE(W116:X116) -> #NAME? | Y5: =+AVERAGE(BN5:BQ5) -> #NAME? | Z5: =+AVERAGE(BR5:BU5) -> #NAME? | AA5: =+AVERAGE(BV5:BY5) -> #NAME? | AB5: =+AVERAGE(BZ5:CC5) -> #NAME? | AC5: =+AVERAGE(CD5:CG5) -> #NAME? | AD5: =+AVERAGE(CH5:CK5) -> #NAME? | AE5: =+AVERAGE(CL5:CO5) -> #NAME? | AH5: =AVERAGE(AG116:AH116) -> #NAME? | AI5: =AVERAGE(AH116:AI116) -> #NAME? | AJ5: =AVERAGE(AI116:AJ116) -> #NAME? | AK5: =AVERAGE(AJ116:AK116) -> #NAME? | AL5: =AVERAGE(AK116:AL116) -> #NAME? | AM5: =AVERAGE(AL116:AM116) -> #NAME? | AN5: =AVERAGE(AM116:AN116) -> #NAME? | AO5: =AVERAGE(AN116:AO116) -> #NAME? | ... CO5: =AVERAGE(CN116:CO116) -> #NAME? | CS5: 402336.1
A7: Growth (%) | D7: =+D5/C5-1 -> #NAME? | E7: =+E5/D5-1 -> #NAME? | F7: =+F5/E5-1 -> #NAME? | G7: =+G5/F5-1 -> #NAME? | H7: =+H5/G5-1 -> #NAME? | I7: =+I5/H5-1 -> #NAME? | J7: =+J5/I5-1 -> #NAME? | K7: =+K5/J5-1 -> #NAME? | ... AE7: =+AE5/AD5-1 -> #NAME? | AM7: =AM5/AI5-1 -> #NAME? | AN7: =AN5/AJ5-1 -> #NAME? | AO7: =AO5/AK5-1 -> #NAME? | AP7: =AP5/AL5-1 -> #NAME? | AQ7: =AQ5/AM5-1 -> #NAME? | AR7: =AR5/AN5-1 -> #NAME? | AS7: =AS5/AO5-1 -> #NAME? | AT7: =AT5/AP5-1 -> #NAME? | ... CO7: =CO5/CK5-1 -> #NAME? | CS7: 0.18127355
A9: Leverage | D9: =D115/D109 -> #NAME? | E9: =E115/E109 -> #NAME? | F9: =F115/F109 -> #NAME? | G9: =G115/G109 -> #NAME? | H9: =H115/H109 -> #NAME? | I9: =I115/I109 -> #NAME? | J9: =J115/J109 -> #NAME? | K9: =K115/K109 -> #NAME? | ... AE9: =AE115/AE109 -> #NAME? | AH9: =AH115/AH109 -> #NAME? | AI9: =AI115/AI109 -> #NAME? | AJ9: =AJ115/AJ109 -> #NAME? | AK9: =AK115/AK109 -> #NAME? | AL9: =AL115/AL109 -> #NAME? | AM9: =AM115/AM109 -> #NAME? | AN9: =AN115/AN109 -> #NAME? | AO9: =AO115/AO109 -> #NAME? | ... CO9: =CO115/CO109 -> #NAME? | CS9: 11.032997
A12: Interest Income | D12: =D34/C5 -> #NAME? | E12: =E34/D5 -> #NAME? | F12: =F34/E5 -> #NAME? | G12: =G34/F5 -> #NAME? | H12: =H34/G5 -> #NAME? | I12: =I34/H5 -> #NAME? | J12: =J34/I5 -> #NAME? | K12: =K34/J5 -> #NAME? | ... AE12: =AE34/AD5 -> #NAME? | AH12: =AH34/AG5 -> #NAME? | AI12: =AI34/AH5 -> #NAME? | AJ12: =AJ34/AI5 -> #NAME? | AK12: =AK34/AJ5 -> #NAME? | AL12: =AL34/AK5 -> #NAME? | AM12: =AM34/AL5 -> #NAME? | AN12: =AN34/AM5 -> #NAME? | AO12: =AO34/AN5 -> #NAME? | ... BY12: =BY34/BX5 -> #NAME? | BZ12: =BY12 -> #NAME? | CA12: =BZ12 -> #NAME? | CB12: =CA12 -> #NAME? | CC12: =CB12 -> #NAME? | CD12: =CC12 -> #NAME? | CE12: =CD12 -> #NAME? | CF12: =CE12 -> #NAME? | CG12: =CF12 -> #NAME? | ... CO12: =CN12 -> #NAME? | CS12: 0.020251781
A13: Interest Expenses | D13: =D35/C5 -> #NAME? | E13: =E35/D5 -> #NAME? | F13: =F35/E5 -> #NAME? | G13: =G35/F5 -> #NAME? | H13: =H35/G5 -> #NAME? | I13: =I35/H5 -> #NAME? | J13: =J35/I5 -> #NAME? | K13: =K35/J5 -> #NAME? | ... AE13: =AE35/AD5 -> #NAME? | AH13: =AH35/AG5 -> #NAME? | AI13: =AI35/AH5 -> #NAME? | AJ13: =AJ35/AI5 -> #NAME? | AK13: =AK35/AJ5 -> #NAME? | AL13: =AL35/AK5 -> #NAME? | AM13: =AM35/AL5 -> #NAME? | AN13: =AN35/AM5 -> #NAME? | AO13: =AO35/AN5 -> #NAME? | ... BY13: =BY35/BX5 -> #NAME? | BZ13: =BY13 -> #NAME? | CA13: =BZ13 -> #NAME? | CB13: =CA13 -> #NAME? | CC13: =CB13 -> #NAME? | CD13: =CC13 -> #NAME? | CE13: =CD13 -> #NAME? | CF13: =CE13 -> #NAME? | CG13: =CF13 -> #NAME? | ... CO13: =CN13 -> #NAME? | CS13: 0.010814774
A14: NII | D14: =D12-D13 -> #NAME? | E14: =E12-E13 -> #NAME? | F14: =F12-F13 -> #NAME? | G14: =G12-G13 -> #NAME? | H14: =H12-H13 -> #NAME? | I14: =I12-I13 -> #NAME? | J14: =J12-J13 -> #NAME? | K14: =K12-K13 -> #NAME? | ... AE14: =AE12-AE13 -> #NAME? | AH14: =AH12-AH13 -> #NAME? | AI14: =AI12-AI13 -> #NAME? | AJ14: =AJ12-AJ13 -> #NAME? | AK14: =AK12-AK13 -> #NAME? | AL14: =AL12-AL13 -> #NAME? | AM14: =AM12-AM13 -> #NAME? | AN14: =AN12-AN13 -> #NAME? | AO14: =AO12-AO13 -> #NAME? | ... CO14: =CO12-CO13 -> #NAME? | CS14: 0.009437007
A15: Others income | D15: =D37/C5 -> #NAME? | E15: =E37/D5 -> #NAME? | F15: =F37/E5 -> #NAME? | G15: =G37/F5 -> #NAME? | H15: =H37/G5 -> #NAME? | I15: =I37/H5 -> #NAME? | J15: =J37/I5 -> #NAME? | K15: =K37/J5 -> #NAME? | ... AE15: =AE37/AD5 -> #NAME? | AH15: =AH37/AG5 -> #NAME? | AI15: =AI37/AH5 -> #NAME? | AJ15: =AJ37/AI5 -> #NAME? | AK15: =AK37/AJ5 -> #NAME? | AL15: =AL37/AK5 -> #NAME? | AM15: =AM37/AL5 -> #NAME? | AN15: =AN37/AM5 -> #NAME? | AO15: =AO37/AN5 -> #NAME? | ... BY15: =BY37/BX5 -> #NAME? | BZ15: =BY15 -> #NAME? | CA15: =BZ15 -> #NAME? | CB15: =CA15 -> #NAME? | CC15: =CB15 -> #NAME? | CD15: =CC15 -> #NAME? | CE15: =CD15 -> #NAME? | CF15: =CE15 -> #NAME? | CG15: =CF15 -> #NAME? | ... CO15: =CN15 -> #NAME? | CS15: 0.0025723805
A16: Other non-operating income
A17: Total income | D17: =D14+D15+D16 -> #NAME? | E17: =E14+E15+E16 -> #NAME? | F17: =F14+F15+F16 -> #NAME? | G17: =G14+G15+G16 -> #NAME? | H17: =H14+H15+H16 -> #NAME? | I17: =I14+I15+I16 -> #NAME? | J17: =J14+J15+J16 -> #NAME? | K17: =K14+K15+K16 -> #NAME? | ... AE17: =AE14+AE15+AE16 -> #NAME? | AH17: =AH14+AH15+AH16 -> #NAME? | AI17: =AI14+AI15+AI16 -> #NAME? | AJ17: =AJ14+AJ15+AJ16 -> #NAME? | AK17: =AK14+AK15+AK16 -> #NAME? | AL17: =AL14+AL15+AL16 -> #NAME? | AM17: =AM14+AM15+AM16 -> #NAME? | AN17: =AN14+AN15+AN16 -> #NAME? | AO17: =AO14+AO15+AO16 -> #NAME? | ... CO17: =CO14+CO15+CO16 -> #NAME? | CS17: 0.012009387
A18: TC | D18: =D46/C5 -> #NAME? | E18: =E46/D5 -> #NAME? | F18: =F46/E5 -> #NAME? | G18: =G46/F5 -> #NAME? | H18: =H46/G5 -> #NAME? | I18: =I46/H5 -> #NAME? | J18: =J46/I5 -> #NAME? | K18: =K46/J5 -> #NAME? | ... AE18: =AE46/AD5 -> #NAME? | AH18: =AH46/AG5 -> #NAME? | AI18: =AI46/AH5 -> #NAME? | AJ18: =AJ46/AI5 -> #NAME? | AK18: =AK46/AJ5 -> #NAME? | AL18: =AL46/AK5 -> #NAME? | AM18: =AM46/AL5 -> #NAME? | AN18: =AN46/AM5 -> #NAME? | AO18: =AO46/AN5 -> #NAME? | ... BY18: =BY46/BX5 -> #NAME? | BZ18: =BY18 -> #NAME? | CA18: =BZ18 -> #NAME? | CB18: =CA18 -> #NAME? | CC18: =CB18 -> #NAME? | CD18: =CC18 -> #NAME? | CE18: =CD18 -> #NAME? | CF18: =CE18 -> #NAME? | CG18: =CF18 -> #NAME? | ... CO18: =CN18 -> #NAME? | CS18: 0.0044659973
A19: PPP | D19: =D17-D18 -> #NAME? | E19: =E17-E18 -> #NAME? | F19: =F17-F18 -> #NAME? | G19: =G17-G18 -> #NAME? | H19: =H17-H18 -> #NAME? | I19: =I17-I18 -> #NAME? | J19: =J17-J18 -> #NAME? | K19: =K17-K18 -> #NAME? | ... AE19: =AE17-AE18 -> #NAME? | AH19: =AH17-AH18 -> #NAME? | AI19: =AI17-AI18 -> #NAME? | AJ19: =AJ17-AJ18 -> #NAME? | AK19: =AK17-AK18 -> #NAME? | AL19: =AL17-AL18 -> #NAME? | AM19: =AM17-AM18 -> #NAME? | AN19: =AN17-AN18 -> #NAME? | AO19: =AO17-AO18 -> #NAME? | ... CO19: =CO17-CO18 -> #NAME? | CS19: 0.0075433901
A20: Provision | D20: =D49/C5 -> #NAME? | E20: =E49/D5 -> #NAME? | F20: =F49/E5 -> #NAME? | G20: =G49/F5 -> #NAME? | H20: =H49/G5 -> #NAME? | I20: =I49/H5 -> #NAME? | J20: =J49/I5 -> #NAME? | K20: =K49/J5 -> #NAME? | ... AE20: =AE49/AD5 -> #NAME? | AH20: =AH49/AG5 -> #NAME? | AI20: =AI49/AH5 -> #NAME? | AJ20: =AJ49/AI5 -> #NAME? | AK20: =AK49/AJ5 -> #NAME? | AL20: =AL49/AK5 -> #NAME? | AM20: =AM49/AL5 -> #NAME? | AN20: =AN49/AM5 -> #NAME? | AO20: =AO49/AN5 -> #NAME? | ... BY20: =BY49/BX5 -> #NAME? | BZ20: =BY20 -> #NAME? | CA20: =BZ20 -> #NAME? | CB20: =CA20 -> #NAME? | CC20: =CB20 -> #NAME? | CD20: =CC20 -> #NAME? | CE20: =CD20 -> #NAME? | CF20: =CE20 -> #NAME? | CG20: =CF20 -> #NAME? | ... CO20: =CN20 -> #NAME? | CS20: 0.0020079988
A21: PBT | D21: =D19-D20 -> #NAME? | E21: =E19-E20 -> #NAME? | F21: =F19-F20 -> #NAME? | G21: =G19-G20 -> #NAME? | H21: =H19-H20 -> #NAME? | I21: =I19-I20 -> #NAME? | J21: =J19-J20 -> #NAME? | K21: =K19-K20 -> #NAME? | ... AE21: =AE19-AE20 -> #NAME? | AH21: =AH19-AH20 -> #NAME? | AI21: =AI19-AI20 -> #NAME? | AJ21: =AJ19-AJ20 -> #NAME? | AK21: =AK19-AK20 -> #NAME? | AL21: =AL19-AL20 -> #NAME? | AM21: =AM19-AM20 -> #NAME? | AN21: =AN19-AN20 -> #NAME? | AO21: =AO19-AO20 -> #NAME? | ... CO21: =CO19-CO20 -> #NAME? | CS21: 0.0055353913
A22: Tax | D22: =D51/C5 -> #NAME? | E22: =E51/D5 -> #NAME? | F22: =F51/E5 -> #NAME? | G22: =G51/F5 -> #NAME? | H22: =H51/G5 -> #NAME? | I22: =I51/H5 -> #NAME? | J22: =J51/I5 -> #NAME? | K22: =K51/J5 -> #NAME? | ... AE22: =AE51/AD5 -> #NAME? | AH22: =AH51/AG5 -> #NAME? | AI22: =AI51/AH5 -> #NAME? | AJ22: =AJ51/AI5 -> #NAME? | AK22: =AK51/AJ5 -> #NAME? | AL22: =AL51/AK5 -> #NAME? | AM22: =AM51/AL5 -> #NAME? | AN22: =AN51/AM5 -> #NAME? | AO22: =AO51/AN5 -> #NAME? | ... CO22: =CO51/CN5 -> #NAME? | CS22: 0.0014392017
A23: PAT | D23: =D21-D22 -> #NAME? | E23: =E21-E22 -> #NAME? | F23: =F21-F22 -> #NAME? | G23: =G21-G22 -> #NAME? | H23: =H21-H22 -> #NAME? | I23: =I21-I22 -> #NAME? | J23: =J21-J22 -> #NAME? | K23: =K21-K22 -> #NAME? | ... AE23: =AE21-AE22 -> #NAME? | AH23: =AH21-AH22 -> #NAME? | AI23: =AI21-AI22 -> #NAME? | AJ23: =AJ21-AJ22 -> #NAME? | AK23: =AK21-AK22 -> #NAME? | AL23: =AL21-AL22 -> #NAME? | AM23: =AM21-AM22 -> #NAME? | AN23: =AN21-AN22 -> #NAME? | AO23: =AO21-AO22 -> #NAME? | ... CO23: =CO21-CO22 -> #NAME? | CS23: 0.0040961896
BR24: =+BR23*4 -> #NAME? | BS24: =+BS23*4 -> #NAME? | BT24: =+BT23*4 -> #NAME? | BU24: =+BU23*4 -> #NAME? | BV24: =+BV23*4 -> #NAME? | BW24: =+BW23*4 -> #NAME? | BX24: =+BX23*4 -> #NAME? | BY24: =+BY23*4 -> #NAME?
A25: Preview
A26: Deposits | BH26: 186614 | BI26: 202294 | BJ26: 195909 | BK26: 195849 | BL26: 208436 | BM26: 234092 | BN26: 244364 | BO26: 239306 | BP26: 245738 | BQ26: 270727 | BR26: 267423 | BS26: 276289 | BT26: 279018 | BU26: 307152 | BV26: 305046 | BW26: 309800 | BX26: 321695 | BY26: 321695
A27: Advances | BH27: 129006 | BI27: 135240 | BJ27: 140561 | BK27: 148216 | BL27: 157139 | BM27: 175255 | BN27: 175603 | BO27: 183113 | BP27: 188796 | BQ27: 203677 | BR27: 209065 | BS27: 217504 | BT27: 228652 | BU27: 240007 | BV27: 241097 | BW27: 254187 | BX27: 273476 | BY27: 273476
BH28: =+BH119/BH27 -> #NAME? | BI28: =+BI119/BI27 -> #NAME? | BJ28: =+BJ119/BJ27 -> #NAME? | BK28: =+BK119/BK27 -> #NAME? | BL28: =+BL119/BL27 -> #NAME? | BM28: =+BM119/BM27 -> #NAME? | BN28: =+BN119/BN27 -> #NAME? | BO28: =+BO119/BO27 -> #NAME? | ... BY28: =+BY119/BY27 -> #NAME?
A30: CD Ratio | B30: =+B119/B113 -> #NAME? | C30: =+C119/C113 -> #NAME? | D30: =+D119/D113 -> #NAME? | E30: =+E119/E113 -> #NAME? | F30: =+F119/F113 -> #NAME? | G30: =+G119/G113 -> #NAME? | H30: =+H119/H113 -> #NAME? | I30: =+I119/I113 -> #NAME? | ... AE30: =+AE119/AE113 -> #NAME? | AI30: =+AI119/AI113 -> #NAME? | AJ30: =+AJ119/AJ113 -> #NAME? | AK30: =+AK119/AK113 -> #NAME? | AL30: =+AL119/AL113 -> #NAME? | AM30: =+AM119/AM113 -> #NAME? | AN30: =+AN119/AN113 -> #NAME? | AO30: =+AO119/AO113 -> #NAME? | AP30: =+AP119/AP113 -> #NAME? | ... CO30: =+CO119/CO113 -> #NAME? | CS30: 0.78664508
A32: Presentation Data (End)
A33: Profit & Loss- Annual (Start)
A34: Interest Income | B34: =+'Annual Raw'!C7 -> #NAME? | C34: =+'Annual Raw'!D7 -> #NAME? | D34: =+'Annual Raw'!E7 -> #NAME? | E34: =+'Annual Raw'!F7 -> #NAME? | F34: =+'Annual Raw'!G7 -> #NAME? | G34: =+'Annual Raw'!H7 -> #NAME? | H34: =+'Annual Raw'!I7 -> #NAME? | I34: =+'Annual Raw'!J7 -> #NAME? | ... AA34: =+'Annual Raw'!AB7 -> #NAME? | AB34: =SUM(BZ34:CC34) -> #NAME? | AC34: =SUM(CD34:CG34) -> #NAME? | AD34: =SUM(CH34:CK34) -> #NAME? | AE34: =SUM(CL34:CO34) -> #NAME? | AH34: =+'QTR Raw'!C6 -> #NAME? | AI34: =+'QTR Raw'!D6 -> #NAME? | AJ34: =+'QTR Raw'!E6 -> #NAME? | AK34: =+'QTR Raw'!F6 -> #NAME? | AL34: =+'QTR Raw'!G6 -> #NAME? | AM34: =+'QTR Raw'!H6 -> #NAME? | AN34: =+'QTR Raw'!I6 -> #NAME? | AO34: =+'QTR Raw'!J6 -> #NAME? | ... BY34: =+'QTR Raw'!AT6 -> #NAME? | BZ34: =BZ12*BY5 -> #NAME? | CA34: =CA12*BZ5 -> #NAME? | CB34: =CB12*CA5 -> #NAME? | CC34: =CC12*CB5 -> #NAME? | CD34: =CD12*CC5 -> #NAME? | CE34: =CE12*CD5 -> #NAME? | CF34: =CF12*CE5 -> #NAME? | CG34: =CG12*CF5 -> #NAME? | ... CO34: =CO12*CN5 -> #NAME? | CS34: 29281.64
A35: Interest exp | B35: =+'Annual Raw'!C10 -> #NAME? | C35: =+'Annual Raw'!D10 -> #NAME? | D35: =+'Annual Raw'!E10 -> #NAME? | E35: =+'Annual Raw'!F10 -> #NAME? | F35: =+'Annual Raw'!G10 -> #NAME? | G35: =+'Annual Raw'!H10 -> #NAME? | H35: =+'Annual Raw'!I10 -> #NAME? | I35: =+'Annual Raw'!J10 -> #NAME? | ... AA35: =+'Annual Raw'!AB10 -> #NAME? | AB35: =SUM(BZ35:CC35) -> #NAME? | AC35: =SUM(CD35:CG35) -> #NAME? | AD35: =SUM(CH35:CK35) -> #NAME? | AE35: =SUM(CL35:CO35) -> #NAME? | AH35: =+'QTR Raw'!C9 -> #NAME? | AI35: =+'QTR Raw'!D9 -> #NAME? | AJ35: =+'QTR Raw'!E9 -> #NAME? | AK35: =+'QTR Raw'!F9 -> #NAME? | AL35: =+'QTR Raw'!G9 -> #NAME? | AM35: =+'QTR Raw'!H9 -> #NAME? | AN35: =+'QTR Raw'!I9 -> #NAME? | AO35: =+'QTR Raw'!J9 -> #NAME? | ... BY35: =+'QTR Raw'!AT9 -> #NAME? | BZ35: =BZ13*BY5 -> #NAME? | CA35: =CA13*BZ5 -> #NAME? | CB35: =CB13*CA5 -> #NAME? | CC35: =CC13*CB5 -> #NAME? | CD35: =CD13*CC5 -> #NAME? | CE35: =CE13*CD5 -> #NAME? | CF35: =CF13*CE5 -> #NAME? | CG35: =CG13*CF5 -> #NAME? | ... CO35: =CO13*CN5 -> #NAME? | CS35: 15617.58
A36: NII | B36: =B34-B35 -> #NAME? | C36: =C34-C35 -> #NAME? | D36: =D34-D35 -> #NAME? | E36: =E34-E35 -> #NAME? | F36: =F34-F35 -> #NAME? | G36: =G34-G35 -> #NAME? | H36: =H34-H35 -> #NAME? | I36: =I34-I35 -> #NAME? | ... AE36: =AE34-AE35 -> #NAME? | AH36: =AH34-AH35 -> #NAME? | AI36: =AI34-AI35 -> #NAME? | AJ36: =AJ34-AJ35 -> #NAME? | AK36: =AK34-AK35 -> #NAME? | AL36: =AL34-AL35 -> #NAME? | AM36: =AM34-AM35 -> #NAME? | AN36: =AN34-AN35 -> #NAME? | AO36: =AO34-AO35 -> #NAME? | ... CO36: =CO34-CO35 -> #NAME? | CS36: 13664.06
A37: Other Income | B37: =+'Annual Raw'!C8 -> #NAME? | C37: =+'Annual Raw'!D8 -> #NAME? | D37: =+'Annual Raw'!E8 -> #NAME? | E37: =+'Annual Raw'!F8 -> #NAME? | F37: =+'Annual Raw'!G8 -> #NAME? | G37: =+'Annual Raw'!H8 -> #NAME? | H37: =+'Annual Raw'!I8 -> #NAME? | I37: =+'Annual Raw'!J8 -> #NAME? | ... AA37: =+'Annual Raw'!AB8 -> #NAME? | AB37: =SUM(BZ37:CC37) -> #NAME? | AC37: =SUM(CD37:CG37) -> #NAME? | AD37: =SUM(CH37:CK37) -> #NAME? | AE37: =SUM(CL37:CO37) -> #NAME? | AH37: =+'QTR Raw'!C7 -> #NAME? | AI37: =+'QTR Raw'!D7 -> #NAME? | AJ37: =+'QTR Raw'!E7 -> #NAME? | AK37: =+'QTR Raw'!F7 -> #NAME? | AL37: =+'QTR Raw'!G7 -> #NAME? | AM37: =+'QTR Raw'!H7 -> #NAME? | AN37: =+'QTR Raw'!I7 -> #NAME? | AO37: =+'QTR Raw'!J7 -> #NAME? | ... BY37: =+'QTR Raw'!AT7 -> #NAME? | BZ37: =BZ15*BY5 -> #NAME? | CA37: =CA15*BZ5 -> #NAME? | CB37: =CB15*CA5 -> #NAME? | CC37: =CC15*CB5 -> #NAME? | CD37: =CD15*CC5 -> #NAME? | CE37: =CE15*CD5 -> #NAME? | CF37: =CF15*CE5 -> #NAME? | CG37: =CG15*CF5 -> #NAME? | ... CO37: =CO15*CN5 -> #NAME? | CS37: 3540.89
A38: TI | B38: =B36+B37 -> #NAME? | C38: =C36+C37 -> #NAME? | D38: =D36+D37 -> #NAME? | E38: =E36+E37 -> #NAME? | F38: =F36+F37 -> #NAME? | G38: =G36+G37 -> #NAME? | H38: =H36+H37 -> #NAME? | I38: =I36+I37 -> #NAME? | ... AE38: =AE36+AE37 -> #NAME? | AH38: =AH36+AH37 -> #NAME? | AI38: =AI36+AI37 -> #NAME? | AJ38: =AJ36+AJ37 -> #NAME? | AK38: =AK36+AK37 -> #NAME? | AL38: =AL36+AL37 -> #NAME? | AM38: =AM36+AM37 -> #NAME? | AN38: =AN36+AN37 -> #NAME? | AO38: =AO36+AO37 -> #NAME? | ... CO38: =CO36+CO37 -> #NAME? | CS38: 17204.95
A39: YOY% | C39: =+IF(B38<0,1-C38/B38,C38/B38-1) -> #NAME? | D39: =+IF(C38<0,1-D38/C38,D38/C38-1) -> #NAME? | E39: =+IF(D38<0,1-E38/D38,E38/D38-1) -> #NAME? | F39: =+IF(E38<0,1-F38/E38,F38/E38-1) -> #NAME? | G39: =+IF(F38<0,1-G38/F38,G38/F38-1) -> #NAME? | H39: =+IF(G38<0,1-H38/G38,H38/G38-1) -> #NAME? | I39: =+IF(H38<0,1-I38/H38,I38/H38-1) -> #NAME? | J39: =+IF(I38<0,1-J38/I38,J38/I38-1) -> #NAME? | ... AB39: =+IF(AA38<0,1-AB38/AA38,AB38/AA38-1) -> #NAME? | AC39: =AC38/AB38-1 -> #NAME? | AD39: =AD38/AC38-1 -> #NAME? | AE39: =AE38/AD38-1 -> #NAME? | AL39: =+IF(AH38<0,1-AL38/AH38,AL38/AH38-1) -> #NAME? | AM39: =+IF(AI38<0,1-AM38/AI38,AM38/AI38-1) -> #NAME? | AN39: =+IF(AJ38<0,1-AN38/AJ38,AN38/AJ38-1) -> #NAME? | AO39: =+IF(AK38<0,1-AO38/AK38,AO38/AK38-1) -> #NAME? | AP39: =+IF(AL38<0,1-AP38/AL38,AP38/AL38-1) -> #NAME? | AQ39: =+IF(AM38<0,1-AQ38/AM38,AQ38/AM38-1) -> #NAME? | AR39: =+IF(AN38<0,1-AR38/AN38,AR38/AN38-1) -> #NAME? | AS39: =+IF(AO38<0,1-AS38/AO38,AS38/AO38-1) -> #NAME? | ... CO39: =+IF(CK38<0,1-CO38/CK38,CO38/CK38-1) -> #NAME? | CS39: 0.13791279
A40: Employee Cost | B40: =+'Annual Raw'!C12 -> #NAME? | C40: =+'Annual Raw'!D12 -> #NAME? | D40: =+'Annual Raw'!E12 -> #NAME? | E40: =+'Annual Raw'!F12 -> #NAME? | F40: =+'Annual Raw'!G12 -> #NAME? | G40: =+'Annual Raw'!H12 -> #NAME? | H40: =+'Annual Raw'!I12 -> #NAME? | I40: =+'Annual Raw'!J12 -> #NAME? | ... AA40: =+'Annual Raw'!AB12 -> #NAME? | AB40: =SUM(BZ40:CC40) -> #NAME? | AC40: =SUM(CD40:CG40) -> #NAME? | AD40: =SUM(CH40:CK40) -> #NAME? | AE40: =SUM(CL40:CO40) -> #NAME? | AH40: =+'QTR Raw'!C11 -> #NAME? | AI40: =+'QTR Raw'!D11 -> #NAME? | AJ40: =+'QTR Raw'!E11 -> #NAME? | AK40: =+'QTR Raw'!F11 -> #NAME? | AL40: =+'QTR Raw'!G11 -> #NAME? | AM40: =+'QTR Raw'!H11 -> #NAME? | AN40: =+'QTR Raw'!I11 -> #NAME? | AO40: =+'QTR Raw'!J11 -> #NAME? | ... BY40: =+'QTR Raw'!AT11 -> #NAME? | BZ40: =BZ18*BY5 -> #NAME? | CA40: =CA18*BZ5 -> #NAME? | CB40: =CB18*CA5 -> #NAME? | CC40: =CC18*CB5 -> #NAME? | CD40: =CD18*CC5 -> #NAME? | CE40: =CE18*CD5 -> #NAME? | CF40: =CF18*CE5 -> #NAME? | CG40: =CG18*CF5 -> #NAME? | ... CO40: =CO18*CN5 -> #NAME? | CS40: 3375.77
A41: Operating & Establishment Expenses | B41: =+'Annual Raw'!C11-'Annual Raw'!C12-'Annual Raw'!C13-'Annual Raw'!C14-'Annual Raw'!C15-'Annual Raw'!C16-'Annual Raw'!C17 -> #NAME? | C41: =+'Annual Raw'!D11-'Annual Raw'!D12-'Annual Raw'!D13-'Annual Raw'!D14-'Annual Raw'!D15-'Annual Raw'!D16-'Annual Raw'!D17 -> #NAME? | D41: =+'Annual Raw'!E11-'Annual Raw'!E12-'Annual Raw'!E13-'Annual Raw'!E14-'Annual Raw'!E15-'Annual Raw'!E16-'Annual Raw'!E17 -> #NAME? | E41: =+'Annual Raw'!F11-'Annual Raw'!F12-'Annual Raw'!F13-'Annual Raw'!F14-'Annual Raw'!F15-'Annual Raw'!F16-'Annual Raw'!F17 -> #NAME? | F41: =+'Annual Raw'!G11-'Annual Raw'!G12-'Annual Raw'!G13-'Annual Raw'!G14-'Annual Raw'!G15-'Annual Raw'!G16-'Annual Raw'!G17 -> #NAME? | G41: =+'Annual Raw'!H11-'Annual Raw'!H12-'Annual Raw'!H13-'Annual Raw'!H14-'Annual Raw'!H15-'Annual Raw'!H16-'Annual Raw'!H17 -> #NAME? | H41: =+'Annual Raw'!I11-'Annual Raw'!I12-'Annual Raw'!I13-'Annual Raw'!I14-'Annual Raw'!I15-'Annual Raw'!I16-'Annual Raw'!I17 -> #NAME? | I41: =+'Annual Raw'!J11-'Annual Raw'!J12-'Annual Raw'!J13-'Annual Raw'!J14-'Annual Raw'!J15-'Annual Raw'!J16-'Annual Raw'!J17 -> #NAME? | ... AA41: =+'Annual Raw'!AB11-'Annual Raw'!AB12-'Annual Raw'!AB13-'Annual Raw'!AB14-'Annual Raw'!AB15-'Annual Raw'!AB16-'Annual Raw'!AB17 -> #NAME? | AB41: =SUM(BZ41:CC41) -> 0 | AC41: =SUM(CD41:CG41) -> 0 | AD41: =SUM(CH41:CK41) -> 0 | AE41: =SUM(CL41:CO41) -> 0 | AH41: =+'QTR Raw'!C10-'QTR Raw'!C11-'QTR Raw'!C12 -> #NAME? | AI41: =+'QTR Raw'!D10-'QTR Raw'!D11-'QTR Raw'!D12 -> #NAME? | AJ41: =+'QTR Raw'!E10-'QTR Raw'!E11-'QTR Raw'!E12 -> #NAME? | AK41: =+'QTR Raw'!F10-'QTR Raw'!F11-'QTR Raw'!F12 -> #NAME? | AL41: =+'QTR Raw'!G10-'QTR Raw'!G11-'QTR Raw'!G12 -> #NAME? | AM41: =+'QTR Raw'!H10-'QTR Raw'!H11-'QTR Raw'!H12 -> #NAME? | AN41: =+'QTR Raw'!I10-'QTR Raw'!I11-'QTR Raw'!I12 -> #NAME? | AO41: =+'QTR Raw'!J10-'QTR Raw'!J11-'QTR Raw'!J12 -> #NAME? | ... BY41: =+'QTR Raw'!AT10-'QTR Raw'!AT11-'QTR Raw'!AT12 -> #NAME? | CS41: 3003.36
A42: Insurance | B42: =+'Annual Raw'!C17 -> #NAME? | C42: =+'Annual Raw'!D17 -> #NAME? | D42: =+'Annual Raw'!E17 -> #NAME? | E42: =+'Annual Raw'!F17 -> #NAME? | F42: =+'Annual Raw'!G17 -> #NAME? | G42: =+'Annual Raw'!H17 -> #NAME? | H42: =+'Annual Raw'!I17 -> #NAME? | I42: =+'Annual Raw'!J17 -> #NAME? | ... AA42: =+'Annual Raw'!AB17 -> #NAME?
A43: Rent, Rates & Taxes | B43: =+'Annual Raw'!C14 -> #NAME? | C43: =+'Annual Raw'!D14 -> #NAME? | D43: =+'Annual Raw'!E14 -> #NAME? | E43: =+'Annual Raw'!F14 -> #NAME? | F43: =+'Annual Raw'!G14 -> #NAME? | G43: =+'Annual Raw'!H14 -> #NAME? | H43: =+'Annual Raw'!I14 -> #NAME? | I43: =+'Annual Raw'!J14 -> #NAME? | ... AA43: =+'Annual Raw'!AB14 -> #NAME? | AB43: =SUM(BZ43:CC43) -> 0 | AC43: =SUM(CD43:CG43) -> 0 | AD43: =SUM(CH43:CK43) -> 0 | AE43: =SUM(CL43:CO43) -> 0 | CS43: 0
A44: Depreciation | B44: =+'Annual Raw'!C15+'Annual Raw'!C16 -> #NAME? | C44: =+'Annual Raw'!D15+'Annual Raw'!D16 -> #NAME? | D44: =+'Annual Raw'!E15+'Annual Raw'!E16 -> #NAME? | E44: =+'Annual Raw'!F15+'Annual Raw'!F16 -> #NAME? | F44: =+'Annual Raw'!G15+'Annual Raw'!G16 -> #NAME? | G44: =+'Annual Raw'!H15+'Annual Raw'!H16 -> #NAME? | H44: =+'Annual Raw'!I15+'Annual Raw'!I16 -> #NAME? | I44: =+'Annual Raw'!J15+'Annual Raw'!J16 -> #NAME? | ... AA44: =+'Annual Raw'!AB15+'Annual Raw'!AB16 -> #NAME? | AB44: =SUM(BZ44:CC44) -> 0 | AC44: =SUM(CD44:CG44) -> 0 | AD44: =SUM(CH44:CK44) -> 0 | AE44: =SUM(CL44:CO44) -> 0 | AH44: =+'QTR Raw'!C12 -> #NAME? | AI44: =+'QTR Raw'!D12 -> #NAME? | AJ44: =+'QTR Raw'!E12 -> #NAME? | AK44: =+'QTR Raw'!F12 -> #NAME? | AL44: =+'QTR Raw'!G12 -> #NAME? | AM44: =+'QTR Raw'!H12 -> #NAME? | AN44: =+'QTR Raw'!I12 -> #NAME? | AO44: =+'QTR Raw'!J12 -> #NAME? | ... BY44: =+'QTR Raw'!AT12 -> #NAME? | CS44: 0
A45: Advertisement & Sales Promotion | B45: =+'Annual Raw'!C13 -> #NAME? | C45: =+'Annual Raw'!D13 -> #NAME? | D45: =+'Annual Raw'!E13 -> #NAME? | E45: =+'Annual Raw'!F13 -> #NAME? | F45: =+'Annual Raw'!G13 -> #NAME? | G45: =+'Annual Raw'!H13 -> #NAME? | H45: =+'Annual Raw'!I13 -> #NAME? | I45: =+'Annual Raw'!J13 -> #NAME? | ... AA45: =+'Annual Raw'!AB13 -> #NAME? | AB45: =SUM(BZ45:CC45) -> 0 | AC45: =SUM(CD45:CG45) -> 0 | AD45: =SUM(CH45:CK45) -> 0 | AE45: =SUM(CL45:CO45) -> 0 | CS45: 0
A46: TC | B46: =SUM(B40:B45) -> #NAME? | C46: =SUM(C40:C45) -> #NAME? | D46: =SUM(D40:D45) -> #NAME? | E46: =SUM(E40:E45) -> #NAME? | F46: =SUM(F40:F45) -> #NAME? | G46: =SUM(G40:G45) -> #NAME? | H46: =SUM(H40:H45) -> #NAME? | I46: =SUM(I40:I45) -> #NAME? | ... AE46: =SUM(AE40:AE45) -> #NAME? | AH46: =SUM(AH40:AH44) -> #NAME? | AI46: =SUM(AI40:AI44) -> #NAME? | AJ46: =SUM(AJ40:AJ44) -> #NAME? | AK46: =SUM(AK40:AK44) -> #NAME? | AL46: =SUM(AL40:AL44) -> #NAME? | AM46: =SUM(AM40:AM44) -> #NAME? | AN46: =SUM(AN40:AN44) -> #NAME? | AO46: =SUM(AO40:AO44) -> #NAME? | ... AS46: =SUM(AS40:AS44) -> #NAME? | AT46: =SUM(AT40:AT45) -> #NAME? | AU46: =SUM(AU40:AU45) -> #NAME? | AV46: =SUM(AV40:AV45) -> #NAME? | AW46: =SUM(AW40:AW45) -> #NAME? | AX46: =SUM(AX40:AX45) -> #NAME? | AY46: =SUM(AY40:AY45) -> #NAME? | AZ46: =SUM(AZ40:AZ45) -> #NAME? | BA46: =SUM(BA40:BA45) -> #NAME? | ... CO46: =SUM(CO40:CO45) -> #NAME? | CS46: 6379.13
A47: PPP | B47: =+B38-B46 -> #NAME? | C47: =+C38-C46 -> #NAME? | D47: =+D38-D46 -> #NAME? | E47: =+E38-E46 -> #NAME? | F47: =+F38-F46 -> #NAME? | G47: =+G38-G46 -> #NAME? | H47: =+H38-H46 -> #NAME? | I47: =+I38-I46 -> #NAME? | ... AE47: =+AE38-AE46 -> #NAME? | AH47: =+AH38-AH46 -> #NAME? | AI47: =+AI38-AI46 -> #NAME? | AJ47: =+AJ38-AJ46 -> #NAME? | AK47: =+AK38-AK46 -> #NAME? | AL47: =+AL38-AL46 -> #NAME? | AM47: =+AM38-AM46 -> #NAME? | AN47: =+AN38-AN46 -> #NAME? | AO47: =+AO38-AO46 -> #NAME? | ... CO47: =+CO38-CO46 -> #NAME? | CS47: 10825.82
...

Sheet Share price Daily
A1: =_xll.EQNXTH(B1,"[ADJC];[ADJH];[ADJL];[ADJO];[UCLS];[VOLUME]","2015-Jan-01","Y","All traded days","Asc") -> #NAME? | B1: =+'Annual Raw'!A1 -> 132525 | L1: =_xll.EQNXTH(B1,"[NADJC];[NADJH];[NADJLOW];[NADJOPEN];[NUCLOSE];[NVOLUME]","2015-Jan-01","Y","All traded days","Asc") -> #NAME?
A2: Bank Of Maharashtra | L2: Bank Of Maharashtra
A3: DATE | B3: ADJHIGH | C3: ADJCLOSE | D3: ADJLOW | E3: ADJOPEN | F3: CLOSE | G3: VOLUME | L3: DATE | M3: ADJCLOSE | N3: ADJHIGH | O3: ADJLOW | P3: ADJOPEN | Q3: CLOSE | R3: VOLUME
A4: 42005 | B4: 43.9 | C4: 43.4 | D4: 42.8 | E4: 43.2 | F4: 43.4 | G4: 87842 | L4: 42005 | M4: 43.3 | N4: 43.9 | O4: 42.55 | P4: 43.25 | Q4: 43.3 | R4: 359899
A5: 42006 | B5: 44.6 | C5: 44.25 | D5: 43.5 | E5: 43.7 | F5: 44.25 | G5: 93679 | L5: 42006 | M5: 44.2 | N5: 44.75 | O5: 43.45 | P5: 43.6 | Q5: 44.2 | R5: 439062
A6: 42009 | B6: 44.8 | C6: 43.8 | D6: 43.7 | E6: 44.75 | F6: 43.8 | G6: 54031 | L6: 42009 | M6: 43.75 | N6: 44.75 | O6: 43.6 | P6: 44.75 | Q6: 43.75 | R6: 233477
A7: 42010 | B7: 43.65 | C7: 42.6 | D7: 42.45 | E7: 43.65 | F7: 42.6 | G7: 41454 | L7: 42010 | M7: 42.75 | N7: 44 | O7: 42.6 | P7: 44 | Q7: 42.75 | R7: 183005
A8: 42011 | B8: 43.75 | C8: 42.35 | D8: 42.3 | E8: 43.75 | F8: 42.35 | G8: 36840 | L8: 42011 | M8: 42.5 | N8: 43.1 | O8: 42.25 | P8: 42.8 | Q8: 42.5 | R8: 116260
A9: 42012 | B9: 44.2 | C9: 43.65 | D9: 42.7 | E9: 42.95 | F9: 43.65 | G9: 105860 | L9: 42012 | M9: 43.9 | N9: 44.3 | O9: 42.75 | P9: 42.9 | Q9: 43.9 | R9: 351327
A10: 42013 | B10: 45.6 | C10: 44 | D10: 43.8 | E10: 45.1 | F10: 44 | G10: 162152 | L10: 42013 | M10: 44.1 | N10: 46 | O10: 43.9 | P10: 45.5 | Q10: 44.1 | R10: 790610
A11: 42016 | B11: 44.3 | C11: 44 | D11: 43.7 | E11: 44.1 | F11: 44 | G11: 47354 | L11: 42016 | M11: 43.95 | N11: 44.5 | O11: 43.8 | P11: 44.5 | Q11: 43.95 | R11: 166721
A12: 42017 | B12: 44.6 | C12: 43.75 | D12: 43.65 | E12: 44 | F12: 43.75 | G12: 61577 | L12: 42017 | M12: 43.8 | N12: 44.8 | O12: 43.65 | P12: 44.8 | Q12: 43.8 | R12: 188129
A13: 42018 | B13: 44.05 | C13: 43.3 | D13: 43 | E13: 44.05 | F13: 43.3 | G13: 22521 | L13: 42018 | M13: 43.1 | N13: 44 | O13: 42.9 | P13: 44 | Q13: 43.1 | R13: 131202
A14: 42019 | B14: 45 | C14: 44.1 | D14: 43.9 | E14: 44.2 | F14: 44.1 | G14: 120873 | L14: 42019 | M14: 44.15 | N14: 45 | O14: 44 | P14: 44.9 | Q14: 44.15 | R14: 361670
A15: 42020 | B15: 44.1 | C15: 43.65 | D15: 43.45 | E15: 44.1 | F15: 43.65 | G15: 27773 | L15: 42020 | M15: 43.6 | N15: 44.25 | O15: 43.4 | P15: 44.05 | Q15: 43.6 | R15: 98041
... A2800: 46129 | B2800: 72.97 | C2800: 72.72 | D2800: 71.24 | E2800: 71.45 | F2800: 72.72 | G2800: 723770 | L2800: 46129 | M2800: 72.73 | N2800: 72.99 | O2800: 71.24 | P2800: 71.8 | Q2800: 72.73 | R2800: 17291825

Sheet QTR Raw
A1: =+'Annual Raw'!A1 -> 132525
C2: 201506 | D2: 201509 | E2: 201512 | F2: 201603 | G2: 201606 | H2: 201609 | I2: 201612 | J2: 201703 | K2: 201706 | L2: 201709 | M2: 201712 | N2: 201803 | O2: 201806 | P2: 201809 | Q2: 201812 | R2: 201903 | S2: 201906 | T2: 201909 | U2: 201912 | V2: 202003 | W2: 202006 | X2: 202009 | Y2: 202012 | Z2: 202103 | AA2: 202106 | AB2: 202109 | AC2: 202112 | AD2: 202203 | AE2: 202206 | AF2: 202209 | AG2: 202212 | AH2: 202303 | AI2: 202306 | AJ2: 202309 | AK2: 202312 | AL2: 202403 | AM2: 202406 | AN2: 202409 | AO2: 202412 | AP2: 202503 | AQ2: 202506 | AR2: 202509 | AS2: 202512 | AT2: 202603 | AU2: 202606 | AV2: 202609 | AW2: 202612 | AX2: 202703 | AY2: 202706 | AZ2: 202709 | BA2: 202712 | BB2: 202803 | BC2: 202806 | BD2: 202809 | BE2: 202812 | BF2: 202903 | BG2: 202906 | BH2: 202909 | BI2: 202912 | BJ2: 203003
A4: Field Description | B4: Field Name
A5: Date End | B5: BQTR_DATE_END | C5: {=+_xll.EQNXTDZ($A$1,$B5,C$2)} -> #NAME? | D5: {=+_xll.EQNXTDZ($A$1,$B5,D$2)} -> #NAME? | E5: {=+_xll.EQNXTDZ($A$1,$B5,E$2)} -> #NAME? | F5: {=+_xll.EQNXTDZ($A$1,$B5,F$2)} -> #NAME? | G5: {=+_xll.EQNXTDZ($A$1,$B5,G$2)} -> #NAME? | H5: {=+_xll.EQNXTDZ($A$1,$B5,H$2)} -> #NAME? | I5: {=+_xll.EQNXTDZ($A$1,$B5,I$2)} -> #NAME? | J5: {=+_xll.EQNXTDZ($A$1,$B5,J$2)} -> #NAME? | ... BJ5: {=+_xll.EQNXTDZ($A$1,$B5,BJ$2)} -> #NAME?
A6: Interest Earned | B6: BQTR_NET_SALES | C6: {=+_xll.EQNXTDZ($A$1,$B6,C$2)} -> #NAME? | D6: {=+_xll.EQNXTDZ($A$1,$B6,D$2)} -> #NAME? | E6: {=+_xll.EQNXTDZ($A$1,$B6,E$2)} -> #NAME? | F6: {=+_xll.EQNXTDZ($A$1,$B6,F$2)} -> #NAME? | G6: {=+_xll.EQNXTDZ($A$1,$B6,G$2)} -> #NAME? | H6: {=+_xll.EQNXTDZ($A$1,$B6,H$2)} -> #NAME? | I6: {=+_xll.EQNXTDZ($A$1,$B6,I$2)} -> #NAME? | J6: {=+_xll.EQNXTDZ($A$1,$B6,J$2)} -> #NAME? | ... BJ6: {=+_xll.EQNXTDZ($A$1,$B6,BJ$2)} -> #NAME?
A7: Other Income | B7: BQTR_OTHER_INCOME | C7: {=+_xll.EQNXTDZ($A$1,$B7,C$2)} -> #NAME? | D7: {=+_xll.EQNXTDZ($A$1,$B7,D$2)} -> #NAME? | E7: {=+_xll.EQNXTDZ($A$1,$B7,E$2)} -> #NAME? | F7: {=+_xll.EQNXTDZ($A$1,$B7,F$2)} -> #NAME? | G7: {=+_xll.EQNXTDZ($A$1,$B7,G$2)} -> #NAME? | H7: {=+_xll.EQNXTDZ($A$1,$B7,H$2)} -> #NAME? | I7: {=+_xll.EQNXTDZ($A$1,$B7,I$2)} -> #NAME? | J7: {=+_xll.EQNXTDZ($A$1,$B7,J$2)} -> #NAME? | ... BJ7: {=+_xll.EQNXTDZ($A$1,$B7,BJ$2)} -> #NAME?
A8: Total Income | B8: BQTR_TOTAL_INCOME | C8: {=+_xll.EQNXTDZ($A$1,$B8,C$2)} -> #NAME? | D8: {=+_xll.EQNXTDZ($A$1,$B8,D$2)} -> #NAME? | E8: {=+_xll.EQNXTDZ($A$1,$B8,E$2)} -> #NAME? | F8: {=+_xll.EQNXTDZ($A$1,$B8,F$2)} -> #NAME? | G8: {=+_xll.EQNXTDZ($A$1,$B8,G$2)} -> #NAME? | H8: {=+_xll.EQNXTDZ($A$1,$B8,H$2)} -> #NAME? | I8: {=+_xll.EQNXTDZ($A$1,$B8,I$2)} -> #NAME? | J8: {=+_xll.EQNXTDZ($A$1,$B8,J$2)} -> #NAME? | ... BJ8: {=+_xll.EQNXTDZ($A$1,$B8,BJ$2)} -> #NAME?
A9: Interest Expended | B9: BQTR_INTEREST | C9: {=+_xll.EQNXTDZ($A$1,$B9,C$2)} -> #NAME? | D9: {=+_xll.EQNXTDZ($A$1,$B9,D$2)} -> #NAME? | E9: {=+_xll.EQNXTDZ($A$1,$B9,E$2)} -> #NAME? | F9: {=+_xll.EQNXTDZ($A$1,$B9,F$2)} -> #NAME? | G9: {=+_xll.EQNXTDZ($A$1,$B9,G$2)} -> #NAME? | H9: {=+_xll.EQNXTDZ($A$1,$B9,H$2)} -> #NAME? | I9: {=+_xll.EQNXTDZ($A$1,$B9,I$2)} -> #NAME? | J9: {=+_xll.EQNXTDZ($A$1,$B9,J$2)} -> #NAME? | ... BJ9: {=+_xll.EQNXTDZ($A$1,$B9,BJ$2)} -> #NAME?
A10: Operating Expenses | B10: BQTR_OPERATING_EX | C10: {=+_xll.EQNXTDZ($A$1,$B10,C$2)} -> #NAME? | D10: {=+_xll.EQNXTDZ($A$1,$B10,D$2)} -> #NAME? | E10: {=+_xll.EQNXTDZ($A$1,$B10,E$2)} -> #NAME? | F10: {=+_xll.EQNXTDZ($A$1,$B10,F$2)} -> #NAME? | G10: {=+_xll.EQNXTDZ($A$1,$B10,G$2)} -> #NAME? | H10: {=+_xll.EQNXTDZ($A$1,$B10,H$2)} -> #NAME? | I10: {=+_xll.EQNXTDZ($A$1,$B10,I$2)} -> #NAME? | J10: {=+_xll.EQNXTDZ($A$1,$B10,J$2)} -> #NAME? | ... BJ10: {=+_xll.EQNXTDZ($A$1,$B10,BJ$2)} -> #NAME?
A11: Payment To Provisions For Employees | B11: BQTR_PROV_EMP | C11: {=+_xll.EQNXTDZ($A$1,$B11,C$2)} -> #NAME? | D11: {=+_xll.EQNXTDZ($A$1,$B11,D$2)} -> #NAME? | E11: {=+_xll.EQNXTDZ($A$1,$B11,E$2)} -> #NAME? | F11: {=+_xll.EQNXTDZ($A$1,$B11,F$2)} -> #NAME? | G11: {=+_xll.EQNXTDZ($A$1,$B11,G$2)} -> #NAME? | H11: {=+_xll.EQNXTDZ($A$1,$B11,H$2)} -> #NAME? | I11: {=+_xll.EQNXTDZ($A$1,$B11,I$2)} -> #NAME? | J11: {=+_xll.EQNXTDZ($A$1,$B11,J$2)} -> #NAME? | ... BJ11: {=+_xll.EQNXTDZ($A$1,$B11,BJ$2)} -> #NAME?
A12: Depreciation | B12: BQTR_DEPRECIATION | C12: {=+_xll.EQNXTDZ($A$1,$B12,C$2)} -> #NAME? | D12: {=+_xll.EQNXTDZ($A$1,$B12,D$2)} -> #NAME? | E12: {=+_xll.EQNXTDZ($A$1,$B12,E$2)} -> #NAME? | F12: {=+_xll.EQNXTDZ($A$1,$B12,F$2)} -> #NAME? | G12: {=+_xll.EQNXTDZ($A$1,$B12,G$2)} -> #NAME? | H12: {=+_xll.EQNXTDZ($A$1,$B12,H$2)} -> #NAME? | I12: {=+_xll.EQNXTDZ($A$1,$B12,I$2)} -> #NAME? | J12: {=+_xll.EQNXTDZ($A$1,$B12,J$2)} -> #NAME? | ... BJ12: {=+_xll.EQNXTDZ($A$1,$B12,BJ$2)} -> #NAME?
A13: Total Expenditure | B13: BQTR_EXPENDITURE | C13: {=+_xll.EQNXTDZ($A$1,$B13,C$2)} -> #NAME? | D13: {=+_xll.EQNXTDZ($A$1,$B13,D$2)} -> #NAME? | E13: {=+_xll.EQNXTDZ($A$1,$B13,E$2)} -> #NAME? | F13: {=+_xll.EQNXTDZ($A$1,$B13,F$2)} -> #NAME? | G13: {=+_xll.EQNXTDZ($A$1,$B13,G$2)} -> #NAME? | H13: {=+_xll.EQNXTDZ($A$1,$B13,H$2)} -> #NAME? | I13: {=+_xll.EQNXTDZ($A$1,$B13,I$2)} -> #NAME? | J13: {=+_xll.EQNXTDZ($A$1,$B13,J$2)} -> #NAME? | ... BJ13: {=+_xll.EQNXTDZ($A$1,$B13,BJ$2)} -> #NAME?
A14: Operating Profit before Prov.& Cont. | B14: BQTR_OPERATING_PROFIT | C14: {=+_xll.EQNXTDZ($A$1,$B14,C$2)} -> #NAME? | D14: {=+_xll.EQNXTDZ($A$1,$B14,D$2)} -> #NAME? | E14: {=+_xll.EQNXTDZ($A$1,$B14,E$2)} -> #NAME? | F14: {=+_xll.EQNXTDZ($A$1,$B14,F$2)} -> #NAME? | G14: {=+_xll.EQNXTDZ($A$1,$B14,G$2)} -> #NAME? | H14: {=+_xll.EQNXTDZ($A$1,$B14,H$2)} -> #NAME? | I14: {=+_xll.EQNXTDZ($A$1,$B14,I$2)} -> #NAME? | J14: {=+_xll.EQNXTDZ($A$1,$B14,J$2)} -> #NAME? | ... BJ14: {=+_xll.EQNXTDZ($A$1,$B14,BJ$2)} -> #NAME?
A15: Exceptional Items | B15: BQTR_EXCEPTION_ITEMS | C15: {=+_xll.EQNXTDZ($A$1,$B15,C$2)} -> #NAME? | D15: {=+_xll.EQNXTDZ($A$1,$B15,D$2)} -> #NAME? | E15: {=+_xll.EQNXTDZ($A$1,$B15,E$2)} -> #NAME? | F15: {=+_xll.EQNXTDZ($A$1,$B15,F$2)} -> #NAME? | G15: {=+_xll.EQNXTDZ($A$1,$B15,G$2)} -> #NAME? | H15: {=+_xll.EQNXTDZ($A$1,$B15,H$2)} -> #NAME? | I15: {=+_xll.EQNXTDZ($A$1,$B15,I$2)} -> #NAME? | J15: {=+_xll.EQNXTDZ($A$1,$B15,J$2)} -> #NAME? | ... BJ15: {=+_xll.EQNXTDZ($A$1,$B15,BJ$2)} -> #NAME?
A16: Foreign Exchange Gain / Loss | B16: BQTR_EXC_FOREIGN_EXCH_GAIN | C16: {=+_xll.EQNXTDZ($A$1,$B16,C$2)} -> #NAME? | D16: {=+_xll.EQNXTDZ($A$1,$B16,D$2)} -> #NAME? | E16: {=+_xll.EQNXTDZ($A$1,$B16,E$2)} -> #NAME? | F16: {=+_xll.EQNXTDZ($A$1,$B16,F$2)} -> #NAME? | G16: {=+_xll.EQNXTDZ($A$1,$B16,G$2)} -> #NAME? | H16: {=+_xll.EQNXTDZ($A$1,$B16,H$2)} -> #NAME? | I16: {=+_xll.EQNXTDZ($A$1,$B16,I$2)} -> #NAME? | J16: {=+_xll.EQNXTDZ($A$1,$B16,J$2)} -> #NAME? | ... BJ16: {=+_xll.EQNXTDZ($A$1,$B16,BJ$2)} -> #NAME?
... A48: NIM % | B48: BQTR_NIM | C48: {=+_xll.EQNXTDZ($A$1,$B48,C$2)} -> #NAME? | D48: {=+_xll.EQNXTDZ($A$1,$B48,D$2)} -> #NAME? | E48: {=+_xll.EQNXTDZ($A$1,$B48,E$2)} -> #NAME? | F48: {=+_xll.EQNXTDZ($A$1,$B48,F$2)} -> #NAME? | G48: {=+_xll.EQNXTDZ($A$1,$B48,G$2)} -> #NAME? | H48: {=+_xll.EQNXTDZ($A$1,$B48,H$2)} -> #NAME? | I48: {=+_xll.EQNXTDZ($A$1,$B48,I$2)} -> #NAME? | J48: {=+_xll.EQNXTDZ($A$1,$B48,J$2)} -> #NAME? | ... BJ48: {=+_xll.EQNXTDZ($A$1,$B48,BJ$2)} -> #NAME?
C51: =C5 -> #NAME? | D51: =D5 -> #NAME? | E51: =E5 -> #NAME? | F51: =F5 -> #NAME? | G51: =G5 -> #NAME? | H51: =H5 -> #NAME? | I51: =I5 -> #NAME? | J51: =J5 -> #NAME? | ... BJ51: =BJ5 -> #NAME?
A52: Field Description | B52: Field Name
A53: Year End | B53: BQTRB_DATE_END | C53: {=+_xll.EQNXTDZ($A$1,$B53,C$51)} -> #NAME? | D53: {=+_xll.EQNXTDZ($A$1,$B53,D$51)} -> #NAME? | E53: {=+_xll.EQNXTDZ($A$1,$B53,E$51)} -> #NAME? | F53: {=+_xll.EQNXTDZ($A$1,$B53,F$51)} -> #NAME? | G53: {=+_xll.EQNXTDZ($A$1,$B53,G$51)} -> #NAME? | H53: {=+_xll.EQNXTDZ($A$1,$B53,H$51)} -> #NAME? | I53: {=+_xll.EQNXTDZ($A$1,$B53,I$51)} -> #NAME? | J53: {=+_xll.EQNXTDZ($A$1,$B53,J$51)} -> #NAME? | ... BJ53: {=+_xll.EQNXTDZ($A$1,$B53,BJ$51)} -> #NAME?
A54: Share Capital | B54: BQTRB_SHARE_CAPITAL | C54: {=+_xll.EQNXTDZ($A$1,$B54,C$51)} -> #NAME? | D54: {=+_xll.EQNXTDZ($A$1,$B54,D$51)} -> #NAME? | E54: {=+_xll.EQNXTDZ($A$1,$B54,E$51)} -> #NAME? | F54: {=+_xll.EQNXTDZ($A$1,$B54,F$51)} -> #NAME? | G54: {=+_xll.EQNXTDZ($A$1,$B54,G$51)} -> #NAME? | H54: {=+_xll.EQNXTDZ($A$1,$B54,H$51)} -> #NAME? | I54: {=+_xll.EQNXTDZ($A$1,$B54,I$51)} -> #NAME? | J54: {=+_xll.EQNXTDZ($A$1,$B54,J$51)} -> #NAME? | ... BJ54: {=+_xll.EQNXTDZ($A$1,$B54,BJ$51)} -> #NAME?
A55: Share Warrants & outstandings | B55: BQTRB_SHAREWARRANTS | C55: {=+_xll.EQNXTDZ($A$1,$B55,C$51)} -> #NAME? | D55: {=+_xll.EQNXTDZ($A$1,$B55,D$51)} -> #NAME? | E55: {=+_xll.EQNXTDZ($A$1,$B55,E$51)} -> #NAME? | F55: {=+_xll.EQNXTDZ($A$1,$B55,F$51)} -> #NAME? | G55: {=+_xll.EQNXTDZ($A$1,$B55,G$51)} -> #NAME? | H55: {=+_xll.EQNXTDZ($A$1,$B55,H$51)} -> #NAME? | I55: {=+_xll.EQNXTDZ($A$1,$B55,I$51)} -> #NAME? | J55: {=+_xll.EQNXTDZ($A$1,$B55,J$51)} -> #NAME? | ... BJ55: {=+_xll.EQNXTDZ($A$1,$B55,BJ$51)} -> #NAME?
A56: Reserves and Surplus | B56: BQTRB_RESERVE | C56: {=+_xll.EQNXTDZ($A$1,$B56,C$51)} -> #NAME? | D56: {=+_xll.EQNXTDZ($A$1,$B56,D$51)} -> #NAME? | E56: {=+_xll.EQNXTDZ($A$1,$B56,E$51)} -> #NAME? | F56: {=+_xll.EQNXTDZ($A$1,$B56,F$51)} -> #NAME? | G56: {=+_xll.EQNXTDZ($A$1,$B56,G$51)} -> #NAME? | H56: {=+_xll.EQNXTDZ($A$1,$B56,H$51)} -> #NAME? | I56: {=+_xll.EQNXTDZ($A$1,$B56,I$51)} -> #NAME? | J56: {=+_xll.EQNXTDZ($A$1,$B56,J$51)} -> #NAME? | ... BJ56: {=+_xll.EQNXTDZ($A$1,$B56,BJ$51)} -> #NAME?
A57: Minority Interest | B57: BQTRB_MINORITY_INTEREST_BS | C57: {=+_xll.EQNXTDZ($A$1,$B57,C$51)} -> #NAME? | D57: {=+_xll.EQNXTDZ($A$1,$B57,D$51)} -> #NAME? | E57: {=+_xll.EQNXTDZ($A$1,$B57,E$51)} -> #NAME? | F57: {=+_xll.EQNXTDZ($A$1,$B57,F$51)} -> #NAME? | G57: {=+_xll.EQNXTDZ($A$1,$B57,G$51)} -> #NAME? | H57: {=+_xll.EQNXTDZ($A$1,$B57,H$51)} -> #NAME? | I57: {=+_xll.EQNXTDZ($A$1,$B57,I$51)} -> #NAME? | J57: {=+_xll.EQNXTDZ($A$1,$B57,J$51)} -> #NAME? | ... BJ57: {=+_xll.EQNXTDZ($A$1,$B57,BJ$51)} -> #NAME?
A58: Deposits | B58: BQTRB_DEPOSITS | C58: {=+_xll.EQNXTDZ($A$1,$B58,C$51)} -> #NAME? | D58: {=+_xll.EQNXTDZ($A$1,$B58,D$51)} -> #NAME? | E58: {=+_xll.EQNXTDZ($A$1,$B58,E$51)} -> #NAME? | F58: {=+_xll.EQNXTDZ($A$1,$B58,F$51)} -> #NAME? | G58: {=+_xll.EQNXTDZ($A$1,$B58,G$51)} -> #NAME? | H58: {=+_xll.EQNXTDZ($A$1,$B58,H$51)} -> #NAME? | I58: {=+_xll.EQNXTDZ($A$1,$B58,I$51)} -> #NAME? | J58: {=+_xll.EQNXTDZ($A$1,$B58,J$51)} -> #NAME? | ... BJ58: {=+_xll.EQNXTDZ($A$1,$B58,BJ$51)} -> #NAME?
A59: Savings Deposits | B59: BQTRB_SAVING_DEPOSITS | C59: {=+_xll.EQNXTDZ($A$1,$B59,C$51)} -> #NAME? | D59: {=+_xll.EQNXTDZ($A$1,$B59,D$51)} -> #NAME? | E59: {=+_xll.EQNXTDZ($A$1,$B59,E$51)} -> #NAME? | F59: {=+_xll.EQNXTDZ($A$1,$B59,F$51)} -> #NAME? | G59: {=+_xll.EQNXTDZ($A$1,$B59,G$51)} -> #NAME? | H59: {=+_xll.EQNXTDZ($A$1,$B59,H$51)} -> #NAME? | I59: {=+_xll.EQNXTDZ($A$1,$B59,I$51)} -> #NAME? | J59: {=+_xll.EQNXTDZ($A$1,$B59,J$51)} -> #NAME? | ... BJ59: {=+_xll.EQNXTDZ($A$1,$B59,BJ$51)} -> #NAME?
A60: Term / Fixed Deposits | B60: BQTRB_TERM_FIXED_DEPOSITS | C60: {=+_xll.EQNXTDZ($A$1,$B60,C$51)} -> #NAME? | D60: {=+_xll.EQNXTDZ($A$1,$B60,D$51)} -> #NAME? | E60: {=+_xll.EQNXTDZ($A$1,$B60,E$51)} -> #NAME? | F60: {=+_xll.EQNXTDZ($A$1,$B60,F$51)} -> #NAME? | G60: {=+_xll.EQNXTDZ($A$1,$B60,G$51)} -> #NAME? | H60: {=+_xll.EQNXTDZ($A$1,$B60,H$51)} -> #NAME? | I60: {=+_xll.EQNXTDZ($A$1,$B60,I$51)} -> #NAME? | J60: {=+_xll.EQNXTDZ($A$1,$B60,J$51)} -> #NAME? | ... BJ60: {=+_xll.EQNXTDZ($A$1,$B60,BJ$51)} -> #NAME?
A61: Current Deposits | B61: BQTRB_CURRENT_DEPOSITS | C61: {=+_xll.EQNXTDZ($A$1,$B61,C$51)} -> #NAME? | D61: {=+_xll.EQNXTDZ($A$1,$B61,D$51)} -> #NAME? | E61: {=+_xll.EQNXTDZ($A$1,$B61,E$51)} -> #NAME? | F61: {=+_xll.EQNXTDZ($A$1,$B61,F$51)} -> #NAME? | G61: {=+_xll.EQNXTDZ($A$1,$B61,G$51)} -> #NAME? | H61: {=+_xll.EQNXTDZ($A$1,$B61,H$51)} -> #NAME? | I61: {=+_xll.EQNXTDZ($A$1,$B61,I$51)} -> #NAME? | J61: {=+_xll.EQNXTDZ($A$1,$B61,J$51)} -> #NAME? | ... BJ61: {=+_xll.EQNXTDZ($A$1,$B61,BJ$51)} -> #NAME?
A62: Other Deposits | B62: BQTRB_OTHER_DEPOSITS | C62: {=+_xll.EQNXTDZ($A$1,$B62,C$51)} -> #NAME? | D62: {=+_xll.EQNXTDZ($A$1,$B62,D$51)} -> #NAME? | E62: {=+_xll.EQNXTDZ($A$1,$B62,E$51)} -> #NAME? | F62: {=+_xll.EQNXTDZ($A$1,$B62,F$51)} -> #NAME? | G62: {=+_xll.EQNXTDZ($A$1,$B62,G$51)} -> #NAME? | H62: {=+_xll.EQNXTDZ($A$1,$B62,H$51)} -> #NAME? | I62: {=+_xll.EQNXTDZ($A$1,$B62,I$51)} -> #NAME? | J62: {=+_xll.EQNXTDZ($A$1,$B62,J$51)} -> #NAME? | ... BJ62: {=+_xll.EQNXTDZ($A$1,$B62,BJ$51)} -> #NAME?
A63: Borrowings | B63: BQTRB_BORROWINGS | C63: {=+_xll.EQNXTDZ($A$1,$B63,C$51)} -> #NAME? | D63: {=+_xll.EQNXTDZ($A$1,$B63,D$51)} -> #NAME? | E63: {=+_xll.EQNXTDZ($A$1,$B63,E$51)} -> #NAME? | F63: {=+_xll.EQNXTDZ($A$1,$B63,F$51)} -> #NAME? | G63: {=+_xll.EQNXTDZ($A$1,$B63,G$51)} -> #NAME? | H63: {=+_xll.EQNXTDZ($A$1,$B63,H$51)} -> #NAME? | I63: {=+_xll.EQNXTDZ($A$1,$B63,I$51)} -> #NAME? | J63: {=+_xll.EQNXTDZ($A$1,$B63,J$51)} -> #NAME? | ... BJ63: {=+_xll.EQNXTDZ($A$1,$B63,BJ$51)} -> #NAME?
A64: Other Liabilities & Provisions | B64: BQTRB_OTHER_LIABILITIES | C64: {=+_xll.EQNXTDZ($A$1,$B64,C$51)} -> #NAME? | D64: {=+_xll.EQNXTDZ($A$1,$B64,D$51)} -> #NAME? | E64: {=+_xll.EQNXTDZ($A$1,$B64,E$51)} -> #NAME? | F64: {=+_xll.EQNXTDZ($A$1,$B64,F$51)} -> #NAME? | G64: {=+_xll.EQNXTDZ($A$1,$B64,G$51)} -> #NAME? | H64: {=+_xll.EQNXTDZ($A$1,$B64,H$51)} -> #NAME? | I64: {=+_xll.EQNXTDZ($A$1,$B64,I$51)} -> #NAME? | J64: {=+_xll.EQNXTDZ($A$1,$B64,J$51)} -> #NAME? | ... BJ64: {=+_xll.EQNXTDZ($A$1,$B64,BJ$51)} -> #NAME?
... A83: Book Value | B83: BQTRB_BOOKVALUE | C83: {=+_xll.EQNXTDZ($A$1,$B83,C$51)} -> #NAME? | D83: {=+_xll.EQNXTDZ($A$1,$B83,D$51)} -> #NAME? | E83: {=+_xll.EQNXTDZ($A$1,$B83,E$51)} -> #NAME? | F83: {=+_xll.EQNXTDZ($A$1,$B83,F$51)} -> #NAME? | G83: {=+_xll.EQNXTDZ($A$1,$B83,G$51)} -> #NAME? | H83: {=+_xll.EQNXTDZ($A$1,$B83,H$51)} -> #NAME? | I83: {=+_xll.EQNXTDZ($A$1,$B83,I$51)} -> #NAME? | J83: {=+_xll.EQNXTDZ($A$1,$B83,J$51)} -> #NAME? | ... BJ83: {=+_xll.EQNXTDZ($A$1,$B83,BJ$51)} -> #NAME?

Sheet Annual Raw
A1: 132525 | C1: 200103 | D1: 200203 | E1: 200303 | F1: 200403 | G1: 200503 | H1: 200603 | I1: 200703 | J1: 200803 | K1: 200903 | L1: 201003 | M1: 201103 | N1: 201203 | O1: 201303 | P1: 201403 | Q1: 201503 | R1: 201603 | S1: 201703 | T1: 201803 | U1: 201903 | V1: 202003 | W1: 202103 | X1: 202203 | Y1: 202303 | Z1: 202403 | AA1: 202503 | AB1: 202603 | AC1: 202703 | AD1: 202803 | AE1: 202903 | AF1: 203003
A3: Company Name | B3: CD_COMPNAME | C3: {=_xll.EQNXTDZ($A$1,$B3,C$2)} -> #NAME?
A4: Field Description | B4: Field Name
A5: No of Months | B5: BPL_NO_MONTHS | C5: {=_xll.EQNXTDZ($A$1,$B5,C$1)} -> #NAME? | D5: {=_xll.EQNXTDZ($A$1,$B5,D$1)} -> #NAME? | E5: {=_xll.EQNXTDZ($A$1,$B5,E$1)} -> #NAME? | F5: {=_xll.EQNXTDZ($A$1,$B5,F$1)} -> #NAME? | G5: {=_xll.EQNXTDZ($A$1,$B5,G$1)} -> #NAME? | H5: {=_xll.EQNXTDZ($A$1,$B5,H$1)} -> #NAME? | I5: {=_xll.EQNXTDZ($A$1,$B5,I$1)} -> #NAME? | J5: {=_xll.EQNXTDZ($A$1,$B5,J$1)} -> #NAME? | ... AF5: {=_xll.EQNXTDZ($A$1,$B5,AF$1)} -> #NAME?
A6: Year end date | B6: BPL_YEAR_ENDDATE | C6: {=_xll.EQNXTDZ($A$1,$B6,C$1)} -> #NAME? | D6: {=_xll.EQNXTDZ($A$1,$B6,D$1)} -> #NAME? | E6: {=_xll.EQNXTDZ($A$1,$B6,E$1)} -> #NAME? | F6: {=_xll.EQNXTDZ($A$1,$B6,F$1)} -> #NAME? | G6: {=_xll.EQNXTDZ($A$1,$B6,G$1)} -> #NAME? | H6: {=_xll.EQNXTDZ($A$1,$B6,H$1)} -> #NAME? | I6: {=_xll.EQNXTDZ($A$1,$B6,I$1)} -> #NAME? | J6: {=_xll.EQNXTDZ($A$1,$B6,J$1)} -> #NAME? | ... AF6: {=_xll.EQNXTDZ($A$1,$B6,AF$1)} -> #NAME?
A7: Interest Earned | B7: BPL_INTEREST_EARNED | C7: {=_xll.EQNXTDZ($A$1,$B7,C$1)} -> #NAME? | D7: {=_xll.EQNXTDZ($A$1,$B7,D$1)} -> #NAME? | E7: {=_xll.EQNXTDZ($A$1,$B7,E$1)} -> #NAME? | F7: {=_xll.EQNXTDZ($A$1,$B7,F$1)} -> #NAME? | G7: {=_xll.EQNXTDZ($A$1,$B7,G$1)} -> #NAME? | H7: {=_xll.EQNXTDZ($A$1,$B7,H$1)} -> #NAME? | I7: {=_xll.EQNXTDZ($A$1,$B7,I$1)} -> #NAME? | J7: {=_xll.EQNXTDZ($A$1,$B7,J$1)} -> #NAME? | ... AF7: {=_xll.EQNXTDZ($A$1,$B7,AF$1)} -> #NAME?
A8: Other Income | B8: BPL_OTHER_INCOME | C8: {=_xll.EQNXTDZ($A$1,$B8,C$1)} -> #NAME? | D8: {=_xll.EQNXTDZ($A$1,$B8,D$1)} -> #NAME? | E8: {=_xll.EQNXTDZ($A$1,$B8,E$1)} -> #NAME? | F8: {=_xll.EQNXTDZ($A$1,$B8,F$1)} -> #NAME? | G8: {=_xll.EQNXTDZ($A$1,$B8,G$1)} -> #NAME? | H8: {=_xll.EQNXTDZ($A$1,$B8,H$1)} -> #NAME? | I8: {=_xll.EQNXTDZ($A$1,$B8,I$1)} -> #NAME? | J8: {=_xll.EQNXTDZ($A$1,$B8,J$1)} -> #NAME? | ... AF8: {=_xll.EQNXTDZ($A$1,$B8,AF$1)} -> #NAME?
A9: Total Income | B9: BPL_TOTAL_INCOME | C9: {=_xll.EQNXTDZ($A$1,$B9,C$1)} -> #NAME? | D9: {=_xll.EQNXTDZ($A$1,$B9,D$1)} -> #NAME? | E9: {=_xll.EQNXTDZ($A$1,$B9,E$1)} -> #NAME? | F9: {=_xll.EQNXTDZ($A$1,$B9,F$1)} -> #NAME? | G9: {=_xll.EQNXTDZ($A$1,$B9,G$1)} -> #NAME? | H9: {=_xll.EQNXTDZ($A$1,$B9,H$1)} -> #NAME? | I9: {=_xll.EQNXTDZ($A$1,$B9,I$1)} -> #NAME? | J9: {=_xll.EQNXTDZ($A$1,$B9,J$1)} -> #NAME? | ... AF9: {=_xll.EQNXTDZ($A$1,$B9,AF$1)} -> #NAME?
A10: Interest Expended | B10: BPL_INTEREST | C10: {=_xll.EQNXTDZ($A$1,$B10,C$1)} -> #NAME? | D10: {=_xll.EQNXTDZ($A$1,$B10,D$1)} -> #NAME? | E10: {=_xll.EQNXTDZ($A$1,$B10,E$1)} -> #NAME? | F10: {=_xll.EQNXTDZ($A$1,$B10,F$1)} -> #NAME? | G10: {=_xll.EQNXTDZ($A$1,$B10,G$1)} -> #NAME? | H10: {=_xll.EQNXTDZ($A$1,$B10,H$1)} -> #NAME? | I10: {=_xll.EQNXTDZ($A$1,$B10,I$1)} -> #NAME? | J10: {=_xll.EQNXTDZ($A$1,$B10,J$1)} -> #NAME? | ... AF10: {=_xll.EQNXTDZ($A$1,$B10,AF$1)} -> #NAME?
A11: Operating Expenses | B11: BPL_OPERATING_EXPENSES | C11: {=_xll.EQNXTDZ($A$1,$B11,C$1)} -> #NAME? | D11: {=_xll.EQNXTDZ($A$1,$B11,D$1)} -> #NAME? | E11: {=_xll.EQNXTDZ($A$1,$B11,E$1)} -> #NAME? | F11: {=_xll.EQNXTDZ($A$1,$B11,F$1)} -> #NAME? | G11: {=_xll.EQNXTDZ($A$1,$B11,G$1)} -> #NAME? | H11: {=_xll.EQNXTDZ($A$1,$B11,H$1)} -> #NAME? | I11: {=_xll.EQNXTDZ($A$1,$B11,I$1)} -> #NAME? | J11: {=_xll.EQNXTDZ($A$1,$B11,J$1)} -> #NAME? | ... AF11: {=_xll.EQNXTDZ($A$1,$B11,AF$1)} -> #NAME?
A12: Payments to and provisions for employees | B12: BPL_EMPLOYEES | C12: {=_xll.EQNXTDZ($A$1,$B12,C$1)} -> #NAME? | D12: {=_xll.EQNXTDZ($A$1,$B12,D$1)} -> #NAME? | E12: {=_xll.EQNXTDZ($A$1,$B12,E$1)} -> #NAME? | F12: {=_xll.EQNXTDZ($A$1,$B12,F$1)} -> #NAME? | G12: {=_xll.EQNXTDZ($A$1,$B12,G$1)} -> #NAME? | H12: {=_xll.EQNXTDZ($A$1,$B12,H$1)} -> #NAME? | I12: {=_xll.EQNXTDZ($A$1,$B12,I$1)} -> #NAME? | J12: {=_xll.EQNXTDZ($A$1,$B12,J$1)} -> #NAME? | ... AF12: {=_xll.EQNXTDZ($A$1,$B12,AF$1)} -> #NAME?
A13: Advertisement & Sales Promotion | B13: BPL_ADVERTISING | C13: {=_xll.EQNXTDZ($A$1,$B13,C$1)} -> #NAME? | D13: {=_xll.EQNXTDZ($A$1,$B13,D$1)} -> #NAME? | E13: {=_xll.EQNXTDZ($A$1,$B13,E$1)} -> #NAME? | F13: {=_xll.EQNXTDZ($A$1,$B13,F$1)} -> #NAME? | G13: {=_xll.EQNXTDZ($A$1,$B13,G$1)} -> #NAME? | H13: {=_xll.EQNXTDZ($A$1,$B13,H$1)} -> #NAME? | I13: {=_xll.EQNXTDZ($A$1,$B13,I$1)} -> #NAME? | J13: {=_xll.EQNXTDZ($A$1,$B13,J$1)} -> #NAME? | ... AF13: {=_xll.EQNXTDZ($A$1,$B13,AF$1)} -> #NAME?
A14: Rent, Taxes and lighting | B14: BPL_RENT_RATES_TAXES | C14: {=_xll.EQNXTDZ($A$1,$B14,C$1)} -> #NAME? | D14: {=_xll.EQNXTDZ($A$1,$B14,D$1)} -> #NAME? | E14: {=_xll.EQNXTDZ($A$1,$B14,E$1)} -> #NAME? | F14: {=_xll.EQNXTDZ($A$1,$B14,F$1)} -> #NAME? | G14: {=_xll.EQNXTDZ($A$1,$B14,G$1)} -> #NAME? | H14: {=_xll.EQNXTDZ($A$1,$B14,H$1)} -> #NAME? | I14: {=_xll.EQNXTDZ($A$1,$B14,I$1)} -> #NAME? | J14: {=_xll.EQNXTDZ($A$1,$B14,J$1)} -> #NAME? | ... AF14: {=_xll.EQNXTDZ($A$1,$B14,AF$1)} -> #NAME?
A15: Depreciation on Banks property | B15: BPL_DEPRECIATION | C15: {=_xll.EQNXTDZ($A$1,$B15,C$1)} -> #NAME? | D15: {=_xll.EQNXTDZ($A$1,$B15,D$1)} -> #NAME? | E15: {=_xll.EQNXTDZ($A$1,$B15,E$1)} -> #NAME? | F15: {=_xll.EQNXTDZ($A$1,$B15,F$1)} -> #NAME? | G15: {=_xll.EQNXTDZ($A$1,$B15,G$1)} -> #NAME? | H15: {=_xll.EQNXTDZ($A$1,$B15,H$1)} -> #NAME? | I15: {=_xll.EQNXTDZ($A$1,$B15,I$1)} -> #NAME? | J15: {=_xll.EQNXTDZ($A$1,$B15,J$1)} -> #NAME? | ... AF15: {=_xll.EQNXTDZ($A$1,$B15,AF$1)} -> #NAME?
A16: Depreciation on leased assets | B16: BPL_DEPRECIATION_LEASED_ASSETS | C16: {=_xll.EQNXTDZ($A$1,$B16,C$1)} -> #NAME? | D16: {=_xll.EQNXTDZ($A$1,$B16,D$1)} -> #NAME? | E16: {=_xll.EQNXTDZ($A$1,$B16,E$1)} -> #NAME? | F16: {=_xll.EQNXTDZ($A$1,$B16,F$1)} -> #NAME? | G16: {=_xll.EQNXTDZ($A$1,$B16,G$1)} -> #NAME? | H16: {=_xll.EQNXTDZ($A$1,$B16,H$1)} -> #NAME? | I16: {=_xll.EQNXTDZ($A$1,$B16,I$1)} -> #NAME? | J16: {=_xll.EQNXTDZ($A$1,$B16,J$1)} -> #NAME? | ... AF16: {=_xll.EQNXTDZ($A$1,$B16,AF$1)} -> #NAME?
... A35: Consolidated PAT | B35: BPL_CONSOLPAT | C35: {=_xll.EQNXTDZ($A$1,$B35,C$1)} -> #NAME? | D35: {=_xll.EQNXTDZ($A$1,$B35,D$1)} -> #NAME? | E35: {=_xll.EQNXTDZ($A$1,$B35,E$1)} -> #NAME? | F35: {=_xll.EQNXTDZ($A$1,$B35,F$1)} -> #NAME? | G35: {=_xll.EQNXTDZ($A$1,$B35,G$1)} -> #NAME? | H35: {=_xll.EQNXTDZ($A$1,$B35,H$1)} -> #NAME? | I35: {=_xll.EQNXTDZ($A$1,$B35,I$1)} -> #NAME? | J35: {=_xll.EQNXTDZ($A$1,$B35,J$1)} -> #NAME? | ... AF35: {=_xll.EQNXTDZ($A$1,$B35,AF$1)} -> #NAME?
A37: Field Description | B37: Field Name
A38: Equity Paid Up | B38: FH_EQUITY_PAIDUP | C38: {=_xll.EQNXTDZ($A$1,$B38,C$1)} -> #NAME? | D38: {=_xll.EQNXTDZ($A$1,$B38,D$1)} -> #NAME? | E38: {=_xll.EQNXTDZ($A$1,$B38,E$1)} -> #NAME? | F38: {=_xll.EQNXTDZ($A$1,$B38,F$1)} -> #NAME? | G38: {=_xll.EQNXTDZ($A$1,$B38,G$1)} -> #NAME? | H38: {=_xll.EQNXTDZ($A$1,$B38,H$1)} -> #NAME? | I38: {=_xll.EQNXTDZ($A$1,$B38,I$1)} -> #NAME? | J38: {=_xll.EQNXTDZ($A$1,$B38,J$1)} -> #NAME? | ... AF38: {=_xll.EQNXTDZ($A$1,$B38,AF$1)} -> #NAME?
A39: Reserves and Surplus | B39: FH_RESERVE | C39: {=_xll.EQNXTDZ($A$1,$B39,C$1)} -> #NAME? | D39: {=_xll.EQNXTDZ($A$1,$B39,D$1)} -> #NAME? | E39: {=_xll.EQNXTDZ($A$1,$B39,E$1)} -> #NAME? | F39: {=_xll.EQNXTDZ($A$1,$B39,F$1)} -> #NAME? | G39: {=_xll.EQNXTDZ($A$1,$B39,G$1)} -> #NAME? | H39: {=_xll.EQNXTDZ($A$1,$B39,H$1)} -> #NAME? | I39: {=_xll.EQNXTDZ($A$1,$B39,I$1)} -> #NAME? | J39: {=_xll.EQNXTDZ($A$1,$B39,J$1)} -> #NAME? | ... AF39: {=_xll.EQNXTDZ($A$1,$B39,AF$1)} -> #NAME?
A40: Net Worth | B40: FH_NET_WORTH | C40: {=_xll.EQNXTDZ($A$1,$B40,C$1)} -> #NAME? | D40: {=_xll.EQNXTDZ($A$1,$B40,D$1)} -> #NAME? | E40: {=_xll.EQNXTDZ($A$1,$B40,E$1)} -> #NAME? | F40: {=_xll.EQNXTDZ($A$1,$B40,F$1)} -> #NAME? | G40: {=_xll.EQNXTDZ($A$1,$B40,G$1)} -> #NAME? | H40: {=_xll.EQNXTDZ($A$1,$B40,H$1)} -> #NAME? | I40: {=_xll.EQNXTDZ($A$1,$B40,I$1)} -> #NAME? | J40: {=_xll.EQNXTDZ($A$1,$B40,J$1)} -> #NAME? | ... AF40: {=_xll.EQNXTDZ($A$1,$B40,AF$1)} -> #NAME?
A41: Total Debt | B41: FH_TOTAL_DEBTS | C41: {=_xll.EQNXTDZ($A$1,$B41,C$1)} -> #NAME? | D41: {=_xll.EQNXTDZ($A$1,$B41,D$1)} -> #NAME? | E41: {=_xll.EQNXTDZ($A$1,$B41,E$1)} -> #NAME? | F41: {=_xll.EQNXTDZ($A$1,$B41,F$1)} -> #NAME? | G41: {=_xll.EQNXTDZ($A$1,$B41,G$1)} -> #NAME? | H41: {=_xll.EQNXTDZ($A$1,$B41,H$1)} -> #NAME? | I41: {=_xll.EQNXTDZ($A$1,$B41,I$1)} -> #NAME? | J41: {=_xll.EQNXTDZ($A$1,$B41,J$1)} -> #NAME? | ... AF41: {=_xll.EQNXTDZ($A$1,$B41,AF$1)} -> #NAME?
A42: Deposits | B42: FH_DEPOSITS | C42: {=_xll.EQNXTDZ($A$1,$B42,C$1)} -> #NAME? | D42: {=_xll.EQNXTDZ($A$1,$B42,D$1)} -> #NAME? | E42: {=_xll.EQNXTDZ($A$1,$B42,E$1)} -> #NAME? | F42: {=_xll.EQNXTDZ($A$1,$B42,F$1)} -> #NAME? | G42: {=_xll.EQNXTDZ($A$1,$B42,G$1)} -> #NAME? | H42: {=_xll.EQNXTDZ($A$1,$B42,H$1)} -> #NAME? | I42: {=_xll.EQNXTDZ($A$1,$B42,I$1)} -> #NAME? | J42: {=_xll.EQNXTDZ($A$1,$B42,J$1)} -> #NAME? | ... AF42: {=_xll.EQNXTDZ($A$1,$B42,AF$1)} -> #NAME?
A43: Borrowings | B43: FH_BORROWINGS | C43: {=_xll.EQNXTDZ($A$1,$B43,C$1)} -> #NAME? | D43: {=_xll.EQNXTDZ($A$1,$B43,D$1)} -> #NAME? | E43: {=_xll.EQNXTDZ($A$1,$B43,E$1)} -> #NAME? | F43: {=_xll.EQNXTDZ($A$1,$B43,F$1)} -> #NAME? | G43: {=_xll.EQNXTDZ($A$1,$B43,G$1)} -> #NAME? | H43: {=_xll.EQNXTDZ($A$1,$B43,H$1)} -> #NAME? | I43: {=_xll.EQNXTDZ($A$1,$B43,I$1)} -> #NAME? | J43: {=_xll.EQNXTDZ($A$1,$B43,J$1)} -> #NAME? | ... AF43: {=_xll.EQNXTDZ($A$1,$B43,AF$1)} -> #NAME?
A44: Month End | B44: BMONTH_MONTHEND | C44: {=_xll.EQNXTDZ($A$1,$B44,C$1)} -> #NAME? | D44: {=_xll.EQNXTDZ($A$1,$B44,D$1)} -> #NAME? | E44: {=_xll.EQNXTDZ($A$1,$B44,E$1)} -> #NAME? | F44: {=_xll.EQNXTDZ($A$1,$B44,F$1)} -> #NAME? | G44: {=_xll.EQNXTDZ($A$1,$B44,G$1)} -> #NAME? | H44: {=_xll.EQNXTDZ($A$1,$B44,H$1)} -> #NAME? | I44: {=_xll.EQNXTDZ($A$1,$B44,I$1)} -> #NAME? | J44: {=_xll.EQNXTDZ($A$1,$B44,J$1)} -> #NAME? | ... AF44: {=_xll.EQNXTDZ($A$1,$B44,AF$1)} -> #NAME?
A45: Close Price (Unit Curr.) | B45: FH_YEAR_PRICE | C45: {=_xll.EQNXTDZ($A$1,$B45,C$1)} -> #NAME? | D45: {=_xll.EQNXTDZ($A$1,$B45,D$1)} -> #NAME? | E45: {=_xll.EQNXTDZ($A$1,$B45,E$1)} -> #NAME? | F45: {=_xll.EQNXTDZ($A$1,$B45,F$1)} -> #NAME? | G45: {=_xll.EQNXTDZ($A$1,$B45,G$1)} -> #NAME? | H45: {=_xll.EQNXTDZ($A$1,$B45,H$1)} -> #NAME? | I45: {=_xll.EQNXTDZ($A$1,$B45,I$1)} -> #NAME? | J45: {=_xll.EQNXTDZ($A$1,$B45,J$1)} -> #NAME? | ... AF45: {=_xll.EQNXTDZ($A$1,$B45,AF$1)} -> #NAME?
A46: High Price (Unit Curr.) | B46: FH_HIGH | C46: {=_xll.EQNXTDZ($A$1,$B46,C$1)} -> #NAME? | D46: {=_xll.EQNXTDZ($A$1,$B46,D$1)} -> #NAME? | E46: {=_xll.EQNXTDZ($A$1,$B46,E$1)} -> #NAME? | F46: {=_xll.EQNXTDZ($A$1,$B46,F$1)} -> #NAME? | G46: {=_xll.EQNXTDZ($A$1,$B46,G$1)} -> #NAME? | H46: {=_xll.EQNXTDZ($A$1,$B46,H$1)} -> #NAME? | I46: {=_xll.EQNXTDZ($A$1,$B46,I$1)} -> #NAME? | J46: {=_xll.EQNXTDZ($A$1,$B46,J$1)} -> #NAME? | ... AF46: {=_xll.EQNXTDZ($A$1,$B46,AF$1)} -> #NAME?
A47: Low Price (Unit Curr.) | B47: FH_LOW | C47: {=_xll.EQNXTDZ($A$1,$B47,C$1)} -> #NAME? | D47: {=_xll.EQNXTDZ($A$1,$B47,D$1)} -> #NAME? | E47: {=_xll.EQNXTDZ($A$1,$B47,E$1)} -> #NAME? | F47: {=_xll.EQNXTDZ($A$1,$B47,F$1)} -> #NAME? | G47: {=_xll.EQNXTDZ($A$1,$B47,G$1)} -> #NAME? | H47: {=_xll.EQNXTDZ($A$1,$B47,H$1)} -> #NAME? | I47: {=_xll.EQNXTDZ($A$1,$B47,I$1)} -> #NAME? | J47: {=_xll.EQNXTDZ($A$1,$B47,J$1)} -> #NAME? | ... AF47: {=_xll.EQNXTDZ($A$1,$B47,AF$1)} -> #NAME?
A48: Month end date | B48: BMONTH_CLOSEDATE | C48: {=_xll.EQNXTDZ($A$1,$B48,C$1)} -> #NAME? | D48: {=_xll.EQNXTDZ($A$1,$B48,D$1)} -> #NAME? | E48: {=_xll.EQNXTDZ($A$1,$B48,E$1)} -> #NAME? | F48: {=_xll.EQNXTDZ($A$1,$B48,F$1)} -> #NAME? | G48: {=_xll.EQNXTDZ($A$1,$B48,G$1)} -> #NAME? | H48: {=_xll.EQNXTDZ($A$1,$B48,H$1)} -> #NAME? | I48: {=_xll.EQNXTDZ($A$1,$B48,I$1)} -> #NAME? | J48: {=_xll.EQNXTDZ($A$1,$B48,J$1)} -> #NAME? | ... AF48: {=_xll.EQNXTDZ($A$1,$B48,AF$1)} -> #NAME?
A49: Volume ('000) | B49: BMONTH_VOLUME | C49: {=_xll.EQNXTDZ($A$1,$B49,C$1)} -> #NAME? | D49: {=_xll.EQNXTDZ($A$1,$B49,D$1)} -> #NAME? | E49: {=_xll.EQNXTDZ($A$1,$B49,E$1)} -> #NAME? | F49: {=_xll.EQNXTDZ($A$1,$B49,F$1)} -> #NAME? | G49: {=_xll.EQNXTDZ($A$1,$B49,G$1)} -> #NAME? | H49: {=_xll.EQNXTDZ($A$1,$B49,H$1)} -> #NAME? | I49: {=_xll.EQNXTDZ($A$1,$B49,I$1)} -> #NAME? | J49: {=_xll.EQNXTDZ($A$1,$B49,J$1)} -> #NAME? | ... AF49: {=_xll.EQNXTDZ($A$1,$B49,AF$1)} -> #NAME?
... A54: NIM_Reported (%) | B54: RBI_NIMAR | C54: {=_xll.EQNXTDZ($A$1,$B54,C$1)} -> #NAME? | D54: {=_xll.EQNXTDZ($A$1,$B54,D$1)} -> #NAME? | E54: {=_xll.EQNXTDZ($A$1,$B54,E$1)} -> #NAME? | F54: {=_xll.EQNXTDZ($A$1,$B54,F$1)} -> #NAME? | G54: {=_xll.EQNXTDZ($A$1,$B54,G$1)} -> #NAME? | H54: {=_xll.EQNXTDZ($A$1,$B54,H$1)} -> #NAME? | I54: {=_xll.EQNXTDZ($A$1,$B54,I$1)} -> #NAME? | J54: {=_xll.EQNXTDZ($A$1,$B54,J$1)} -> #NAME? | ... AF54: {=_xll.EQNXTDZ($A$1,$B54,AF$1)} -> #NAME?
A58: Field Description | B58: Field Name
A59: Year End | B59: BBS_YEAR_END | C59: {=_xll.EQNXTDZ($A$1,$B59,C$1)} -> #NAME? | D59: {=_xll.EQNXTDZ($A$1,$B59,D$1)} -> #NAME? | E59: {=_xll.EQNXTDZ($A$1,$B59,E$1)} -> #NAME? | F59: {=_xll.EQNXTDZ($A$1,$B59,F$1)} -> #NAME? | G59: {=_xll.EQNXTDZ($A$1,$B59,G$1)} -> #NAME? | H59: {=_xll.EQNXTDZ($A$1,$B59,H$1)} -> #NAME? | I59: {=_xll.EQNXTDZ($A$1,$B59,I$1)} -> #NAME? | J59: {=_xll.EQNXTDZ($A$1,$B59,J$1)} -> #NAME? | ... AF59: {=_xll.EQNXTDZ($A$1,$B59,AF$1)} -> #NAME?
A60: Year | B60: BBS_YEAR | C60: {=_xll.EQNXTDZ($A$1,$B60,C$1)} -> #NAME? | D60: {=_xll.EQNXTDZ($A$1,$B60,D$1)} -> #NAME? | E60: {=_xll.EQNXTDZ($A$1,$B60,E$1)} -> #NAME? | F60: {=_xll.EQNXTDZ($A$1,$B60,F$1)} -> #NAME? | G60: {=_xll.EQNXTDZ($A$1,$B60,G$1)} -> #NAME? | H60: {=_xll.EQNXTDZ($A$1,$B60,H$1)} -> #NAME? | I60: {=_xll.EQNXTDZ($A$1,$B60,I$1)} -> #NAME? | J60: {=_xll.EQNXTDZ($A$1,$B60,J$1)} -> #NAME? | ... AF60: {=_xll.EQNXTDZ($A$1,$B60,AF$1)} -> #NAME?
A61: No of Months | B61: BBS_NO_MONTHS | C61: {=_xll.EQNXTDZ($A$1,$B61,C$1)} -> #NAME? | D61: {=_xll.EQNXTDZ($A$1,$B61,D$1)} -> #NAME? | E61: {=_xll.EQNXTDZ($A$1,$B61,E$1)} -> #NAME? | F61: {=_xll.EQNXTDZ($A$1,$B61,F$1)} -> #NAME? | G61: {=_xll.EQNXTDZ($A$1,$B61,G$1)} -> #NAME? | H61: {=_xll.EQNXTDZ($A$1,$B61,H$1)} -> #NAME? | I61: {=_xll.EQNXTDZ($A$1,$B61,I$1)} -> #NAME? | J61: {=_xll.EQNXTDZ($A$1,$B61,J$1)} -> #NAME? | ... AF61: {=_xll.EQNXTDZ($A$1,$B61,AF$1)} -> #NAME?
A62: Year end date | B62: BBS_YEAR_ENDDATE | C62: {=_xll.EQNXTDZ($A$1,$B62,C$1)} -> #NAME? | D62: {=_xll.EQNXTDZ($A$1,$B62,D$1)} -> #NAME? | E62: {=_xll.EQNXTDZ($A$1,$B62,E$1)} -> #NAME? | F62: {=_xll.EQNXTDZ($A$1,$B62,F$1)} -> #NAME? | G62: {=_xll.EQNXTDZ($A$1,$B62,G$1)} -> #NAME? | H62: {=_xll.EQNXTDZ($A$1,$B62,H$1)} -> #NAME? | I62: {=_xll.EQNXTDZ($A$1,$B62,I$1)} -> #NAME? | J62: {=_xll.EQNXTDZ($A$1,$B62,J$1)} -> #NAME? | ... AF62: {=_xll.EQNXTDZ($A$1,$B62,AF$1)} -> #NAME?
A63: Share Capital | B63: BBS_SHARE_CAPITAL | C63: {=_xll.EQNXTDZ($A$1,$B63,C$1)} -> #NAME? | D63: {=_xll.EQNXTDZ($A$1,$B63,D$1)} -> #NAME? | E63: {=_xll.EQNXTDZ($A$1,$B63,E$1)} -> #NAME? | F63: {=_xll.EQNXTDZ($A$1,$B63,F$1)} -> #NAME? | G63: {=_xll.EQNXTDZ($A$1,$B63,G$1)} -> #NAME? | H63: {=_xll.EQNXTDZ($A$1,$B63,H$1)} -> #NAME? | I63: {=_xll.EQNXTDZ($A$1,$B63,I$1)} -> #NAME? | J63: {=_xll.EQNXTDZ($A$1,$B63,J$1)} -> #NAME? | ... AF63: {=_xll.EQNXTDZ($A$1,$B63,AF$1)} -> #NAME?
A64: Share Warrants & Outstandings | B64: BBS_SHAREWROUTST | C64: {=_xll.EQNXTDZ($A$1,$B64,C$1)} -> #NAME? | D64: {=_xll.EQNXTDZ($A$1,$B64,D$1)} -> #NAME? | E64: {=_xll.EQNXTDZ($A$1,$B64,E$1)} -> #NAME? | F64: {=_xll.EQNXTDZ($A$1,$B64,F$1)} -> #NAME? | G64: {=_xll.EQNXTDZ($A$1,$B64,G$1)} -> #NAME? | H64: {=_xll.EQNXTDZ($A$1,$B64,H$1)} -> #NAME? | I64: {=_xll.EQNXTDZ($A$1,$B64,I$1)} -> #NAME? | J64: {=_xll.EQNXTDZ($A$1,$B64,J$1)} -> #NAME? | ... AF64: {=_xll.EQNXTDZ($A$1,$B64,AF$1)} -> #NAME?
A65: Total Reserves | B65: BBS_RESERVE | C65: {=_xll.EQNXTDZ($A$1,$B65,C$1)} -> #NAME? | D65: {=_xll.EQNXTDZ($A$1,$B65,D$1)} -> #NAME? | E65: {=_xll.EQNXTDZ($A$1,$B65,E$1)} -> #NAME? | F65: {=_xll.EQNXTDZ($A$1,$B65,F$1)} -> #NAME? | G65: {=_xll.EQNXTDZ($A$1,$B65,G$1)} -> #NAME? | H65: {=_xll.EQNXTDZ($A$1,$B65,H$1)} -> #NAME? | I65: {=_xll.EQNXTDZ($A$1,$B65,I$1)} -> #NAME? | J65: {=_xll.EQNXTDZ($A$1,$B65,J$1)} -> #NAME? | ... AF65: {=_xll.EQNXTDZ($A$1,$B65,AF$1)} -> #NAME?
A66: Minority Interest | B66: BBS_MINORITY_INTEREST | C66: {=_xll.EQNXTDZ($A$1,$B66,C$1)} -> #NAME? | D66: {=_xll.EQNXTDZ($A$1,$B66,D$1)} -> #NAME? | E66: {=_xll.EQNXTDZ($A$1,$B66,E$1)} -> #NAME? | F66: {=_xll.EQNXTDZ($A$1,$B66,F$1)} -> #NAME? | G66: {=_xll.EQNXTDZ($A$1,$B66,G$1)} -> #NAME? | H66: {=_xll.EQNXTDZ($A$1,$B66,H$1)} -> #NAME? | I66: {=_xll.EQNXTDZ($A$1,$B66,I$1)} -> #NAME? | J66: {=_xll.EQNXTDZ($A$1,$B66,J$1)} -> #NAME? | ... AF66: {=_xll.EQNXTDZ($A$1,$B66,AF$1)} -> #NAME?
A67: Deposits | B67: BBS_DEPOSITS | C67: {=_xll.EQNXTDZ($A$1,$B67,C$1)} -> #NAME? | D67: {=_xll.EQNXTDZ($A$1,$B67,D$1)} -> #NAME? | E67: {=_xll.EQNXTDZ($A$1,$B67,E$1)} -> #NAME? | F67: {=_xll.EQNXTDZ($A$1,$B67,F$1)} -> #NAME? | G67: {=_xll.EQNXTDZ($A$1,$B67,G$1)} -> #NAME? | H67: {=_xll.EQNXTDZ($A$1,$B67,H$1)} -> #NAME? | I67: {=_xll.EQNXTDZ($A$1,$B67,I$1)} -> #NAME? | J67: {=_xll.EQNXTDZ($A$1,$B67,J$1)} -> #NAME? | ... AF67: {=_xll.EQNXTDZ($A$1,$B67,AF$1)} -> #NAME?
...

Sheet QTR Share Price
