Workbook

Sheet Template
A1: =+'Annual Raw'!C3 -> Canara Bank | B1: =+EOMONTH(C1,-12) -> 36981 | C1: =+EOMONTH(D1,-12) -> 37346 | D1: =+EOMONTH(E1,-12) -> 37711 | E1: =+EOMONTH(F1,-12) -> 38077 | F1: =+EOMONTH(G1,-12) -> 38442 | G1: =+EOMONTH(H1,-12) -> 38807 | H1: =+EOMONTH(I1,-12) -> 39172 | I1: =+EOMONTH(J1,-12) -> 39538 | ... N1: =+EOMONTH(O1,-12) -> 41364 | O1: 41699 | P1: 42064 | Q1: 42430 | R1: 42795 | S1: 43160 | T1: 43525 | U1: 43891 | V1: 44256 | W1: 44621 | X1: 44986 | Y1: 45352 | Z1: 45717 | AA1: 46082 | AB1: 46447 | AC1: 46813 | AD1: 47178 | AE1: 47543 | AG1: Quarterly | AH1: 42185 | AI1: =+EOMONTH(AH1,3) -> 42277 | AJ1: =+EOMONTH(AI1,3) -> 42369 | AK1: =+EOMONTH(AJ1,3) -> 42460 | AL1: =+EOMONTH(AK1,3) -> 42551 | AM1: =+EOMONTH(AL1,3) -> 42643 | AN1: =+EOMONTH(AM1,3) -> 42735 | AO1: =+EOMONTH(AN1,3) -> 42825 | AP1: =+EOMONTH(AO1,3) -> 42916 | ... CO1: =+EOMONTH(CN1,3) -> 47573 | CS1: 46022 | CW1: HISTORICAL ESTIMATES | CX1: 46082
A2: Presentation Data (Start)
A4: Average eq | D4: =AVERAGE(C104:D104) -> 3810.1617 | E4: =AVERAGE(D104:E104) -> 4700.2357 | F4: =AVERAGE(E104:F104) -> 5680.3001 | G4: =AVERAGE(F104:G104) -> 6620.5965 | H4: =AVERAGE(G104:H104) -> 8743.111 | I4: =AVERAGE(H104:I104) -> 10427.239 | J4: =AVERAGE(I104:J104) -> 11354.131 | K4: =AVERAGE(J104:K104) -> 13439.776 | ... X4: =AVERAGE(W104:X104) -> 69859.246 | Y4: =+AVERAGE(BN4:BQ4) -> 80625.276 | Z4: =+AVERAGE(BR4:BU4) -> 95347.747 | AA4: =+AVERAGE(BV4:BY4) -> 108156.54 | AB4: =+AVERAGE(BZ4:CC4) -> 123100.66 | AC4: =+AVERAGE(CD4:CG4) -> 143148.07 | AD4: =+AVERAGE(CH4:CK4) -> 164224.27 | AE4: =+AVERAGE(CL4:CO4) -> 186884.59 | AH4: =AVERAGE(AG104:AH104) -> 33892.79 | AI4: =AVERAGE(AH104:AI104) -> 34686.46 | AJ4: =AVERAGE(AI104:AJ104) -> 35506.175 | AK4: =AVERAGE(AJ104:AK104) -> 33567.71 | AL4: =AVERAGE(AK104:AL104) -> 31705.9 | AM4: =AVERAGE(AL104:AM104) -> 31962.705 | AN4: =AVERAGE(AM104:AN104) -> 32272.755 | AO4: =AVERAGE(AN104:AO104) -> 33057.12 | ... CO4: =AVERAGE(CN104:CO104) -> 195884.77 | CS4: 110653.27
A5: Average assets | D5: =AVERAGE(C111:D111) -> 72053.188 | E5: =AVERAGE(D111:E111) -> 84344.285 | F5: =AVERAGE(E111:F111) -> 97685.068 | G5: =AVERAGE(F111:G111) -> 113490.17 | H5: =AVERAGE(G111:H111) -> 139135.54 | I5: =AVERAGE(H111:I111) -> 160699.97 | J5: =AVERAGE(I111:J111) -> 190095.69 | K5: =AVERAGE(J111:K111) -> 235432.51 | ... X5: =AVERAGE(W111:X111) -> 1254860.5 | Y5: =+AVERAGE(BN5:BQ5) -> 1392055.1 | Z5: =+AVERAGE(BR5:BU5) -> 1537863.1 | AA5: =+AVERAGE(BV5:BY5) -> 1735857.6 | AB5: =+AVERAGE(BZ5:CC5) -> 1936531.8 | AC5: =+AVERAGE(CD5:CG5) -> 2122534.6 | AD5: =+AVERAGE(CH5:CK5) -> 2326382.3 | AE5: =+AVERAGE(CL5:CO5) -> 2550111.4 | AH5: =AVERAGE(AG111:AH111) -> 529674.33 | AI5: =AVERAGE(AH111:AI111) -> 537262.43 | AJ5: =AVERAGE(AI111:AJ111) -> 548170.79 | AK5: =AVERAGE(AJ111:AK111) -> 544879.56 | AL5: =AVERAGE(AK111:AL111) -> 531967.85 | AM5: =AVERAGE(AL111:AM111) -> 533800.95 | AN5: =AVERAGE(AM111:AN111) -> 558001.03 | AO5: =AVERAGE(AN111:AO111) -> 571266.06 | ... CO5: =AVERAGE(CN111:CO111) -> 2608316.3 | CS5: 1723696.7
A7: Growth (%) | D7: =+D5/C5-1 -> #DIV/0! | E7: =+E5/D5-1 -> 0.17058366 | F7: =+F5/E5-1 -> 0.15817057 | G7: =+G5/F5-1 -> 0.16179645 | H7: =+H5/G5-1 -> 0.22597002 | I7: =+I5/H5-1 -> 0.15498863 | J7: =+J5/I5-1 -> 0.18292299 | K7: =+K5/J5-1 -> 0.23849473 | ... AE7: =+AE5/AD5-1 -> 0.096170408 | AM7: =AM5/AI5-1 -> -0.0064428012 | AN7: =AN5/AJ5-1 -> 0.017932814 | AO7: =AO5/AK5-1 -> 0.048426288 | AP7: =AP5/AL5-1 -> 0.064162186 | AQ7: =AQ5/AM5-1 -> 0.053384253 | AR7: =AR5/AN5-1 -> 0.026974108 | AS7: =AS5/AO5-1 -> 0.036672116 | AT7: =AT5/AP5-1 -> 0.062433626 | ... CO7: =CO5/CK5-1 -> 0.096228994 | CS7: 0.11228322
A9: Leverage | D9: =D110/D104 -> 17.399767 | E9: =E110/E104 -> 16.585182 | F9: =F110/F104 -> 15.863605 | G9: =G110/G104 -> 16.380425 | H9: =H110/H104 -> 13.903419 | I9: =I110/I104 -> 14.912601 | J9: =J110/J104 -> 16.456197 | K9: =K110/K104 -> 16.568674 | ... AE9: =AE110/AE104 -> 12.264108 | AH9: =AH110/AH104 -> 14.627935 | AI9: =AI110/AI104 -> 14.356497 | AJ9: =AJ110/AJ104 -> 14.520872 | AK9: =AK110/AK104 -> 16.032075 | AL9: =AL110/AL104 -> 15.525959 | AM9: =AM110/AM104 -> 15.873851 | AN9: =AN110/AN104 -> 16.70246 | AO9: =AO110/AO104 -> 15.875619 | ... CO9: =CO110/CO104 -> 12.264108 | CS9: 14.219563
A12: Interest Income | D12: =D29/C5 -> #DIV/0! | E12: =E29/D5 -> 0.097246505 | F12: =F29/E5 -> 0.089774533 | G12: =G29/F5 -> 0.089179569 | H12: =H29/G5 -> 0.10013692 | I12: =I29/H5 -> 0.10206405 | J12: =J29/I5 -> 0.10652805 | K12: =K29/J5 -> 0.09864486 | ... AE12: =AE29/AD5 -> 0.081566124 | AH12: =AH29/AG5 -> #DIV/0! | AI12: =AI29/AH5 -> 0.021272505 | AJ12: =AJ29/AI5 -> 0.020254664 | AK12: =AK29/AJ5 -> 0.0195795 | AL12: =AL29/AK5 -> 0.018722853 | AM12: =AM29/AL5 -> 0.019560111 | AN12: =AN29/AM5 -> 0.019272483 | AO12: =AO29/AN5 -> 0.018804481 | ... BY12: =BY29/BX5 -> 0.018142501 | BZ12: =+AVERAGE(BV12:BY12)*1.02 -> 0.019146751 | CA12: =+AVERAGE(BW12:BZ12)*1.02 -> 0.019098309 | CB12: =+AVERAGE(BX12:CA12)*1.01 -> 0.018961501 | CC12: =+AVERAGE(BY12:CB12)*1.01 -> 0.019025638 | CD12: =+AVERAGE(BZ12:CC12)*1.01 -> 0.01924863 | CE12: =+AVERAGE(CA12:CD12)*1.01 -> 0.019274355 | CF12: =+AVERAGE(CB12:CE12) -> 0.019127531 | CG12: =+AVERAGE(CC12:CF12) -> 0.019169038 | CH12: =+AVERAGE(CD12:CG12)*0.99 -> 0.01901284 | CI12: =+AVERAGE(CE12:CH12)*0.99 -> 0.018954482 | CJ12: =+AVERAGE(CF12:CI12) -> 0.019065973 | CK12: =+AVERAGE(CG12:CJ12) -> 0.019050583 | CL12: =+AVERAGE(CH12:CK12) -> 0.019020969 | CM12: =+AVERAGE(CI12:CL12) -> 0.019023002 | CN12: =+AVERAGE(CJ12:CM12) -> 0.019040132 | CO12: =+AVERAGE(CK12:CN12) -> 0.019033671 | CS12: 0.018898587
A13: Interest Expenses | D13: =D30/C5 -> #DIV/0! | E13: =E30/D5 -> 0.060019072 | F13: =F30/E5 -> 0.052422038 | G13: =G30/F5 -> 0.052515773 | H13: =H30/G5 -> 0.06465521 | I13: =I30/H5 -> 0.0766371 | J13: =J30/I5 -> 0.077170185 | K13: =K30/J5 -> 0.068762362 | ... AE13: =AE30/AD5 -> 0.056908294 | AH13: =AH30/AG5 -> #DIV/0! | AI13: =AI30/AH5 -> 0.016276039 | AJ13: =AJ30/AI5 -> 0.016110321 | AK13: =AK30/AJ5 -> 0.015249171 | AL13: =AL30/AK5 -> 0.014488156 | AM13: =AM30/AL5 -> 0.01496895 | AN13: =AN30/AM5 -> 0.014750573 | AO13: =AO30/AN5 -> 0.01395105 | ... BY13: =BY30/BX5 -> 0.012553521 | BZ13: =+AVERAGE(BV13:BY13)*1.01 -> 0.013379648 | CA13: =+AVERAGE(BW13:BZ13)*1.01 -> 0.013294244 | CB13: =+AVERAGE(BX13:CA13)*1.01 -> 0.013262007 | CC13: =+AVERAGE(BY13:CB13)*1.01 -> 0.013253579 | CD13: =+AVERAGE(BZ13:CC13) -> 0.01329737 | CE13: =+AVERAGE(CA13:CD13) -> 0.0132768 | CF13: =+AVERAGE(CB13:CE13) -> 0.013272439 | CG13: =+AVERAGE(CC13:CF13) -> 0.013275047 | CH13: =+AVERAGE(CD13:CG13) -> 0.013280414 | CI13: =+AVERAGE(CE13:CH13) -> 0.013276175 | CJ13: =+AVERAGE(CF13:CI13) -> 0.013276019 | CK13: =+AVERAGE(CG13:CJ13) -> 0.013276913 | ... CO13: =+AVERAGE(CK13:CN13) -> 0.013276912 | CS13: 0.013421914
A14: NII | D14: =D12-D13 -> #DIV/0! | E14: =E12-E13 -> 0.037227433 | F14: =F12-F13 -> 0.037352495 | G14: =G12-G13 -> 0.036663796 | H14: =H12-H13 -> 0.035481715 | I14: =I12-I13 -> 0.025426951 | J14: =J12-J13 -> 0.02935786 | K14: =K12-K13 -> 0.029882498 | ... AE14: =AE12-AE13 -> 0.02465783 | AH14: =AH12-AH13 -> #DIV/0! | AI14: =AI12-AI13 -> 0.0049964664 | AJ14: =AJ12-AJ13 -> 0.0041443434 | AK14: =AK12-AK13 -> 0.0043303293 | AL14: =AL12-AL13 -> 0.0042346973 | AM14: =AM12-AM13 -> 0.0045911609 | AN14: =AN12-AN13 -> 0.0045219103 | AO14: =AO12-AO13 -> 0.0048534319 | ... CO14: =CO12-CO13 -> 0.0057567592 | CS14: 0.005476673
A15: Others income | D15: =D32/C5 -> #DIV/0! | E15: =E32/D5 -> 0.028769209 | F15: =F32/E5 -> 0.018303876 | G15: =G32/F5 -> 0.014101591 | H15: =H32/G5 -> 0.012784806 | I15: =I32/H5 -> 0.015904437 | J15: =J32/I5 -> 0.014382163 | K15: =K32/J5 -> 0.01503402 | ... AE15: =AE32/AD5 -> 0.013468627 | AH15: =AH32/AG5 -> #DIV/0! | AI15: =AI32/AH5 -> 0.0022852722 | AJ15: =AJ32/AI5 -> 0.0021750265 | AK15: =AK32/AJ5 -> 0.0025233559 | AL15: =AL32/AK5 -> 0.0029082574 | AM15: =AM32/AL5 -> 0.0033493941 | AN15: =AN32/AM5 -> 0.0033564946 | AO15: =AO32/AN5 -> 0.0042944007 | ... BY15: =BY32/BX5 -> 0.0027491164 | BZ15: =+AVERAGE(BV15:BY15)*0.92 -> 0.0036799056 | CA15: =+AVERAGE(BW15:BZ15)*0.92 -> 0.0035134376 | CB15: =+AVERAGE(BX15:CA15)*0.92 -> 0.0033495255 | CC15: =+AVERAGE(BY15:CB15)*0.92 -> 0.0030571566 | CD15: =+AVERAGE(BZ15:CC15)*0.97 -> 0.0032980061 | CE15: =+AVERAGE(CA15:CD15)*0.97 -> 0.0032053955 | CF15: =+AVERAGE(CB15:CE15)*0.97 -> 0.0031306953 | CG15: =+AVERAGE(CC15:CF15)*0.97 -> 0.003077629 | CH15: =+AVERAGE(CD15:CG15) -> 0.0031779315 | CI15: =+AVERAGE(CE15:CH15) -> 0.0031479128 | CJ15: =+AVERAGE(CF15:CI15) -> 0.0031335421 | CK15: =+AVERAGE(CG15:CJ15) -> 0.0031342538 | CL15: =+AVERAGE(CH15:CK15) -> 0.0031484101 | CM15: =+AVERAGE(CI15:CL15) -> 0.0031410297 | CN15: =+AVERAGE(CJ15:CM15) -> 0.0031393089 | CO15: =+AVERAGE(CK15:CN15) -> 0.0031407506 | CS15: 0.0042260991
A16: Other non-operating income
A17: Total income | D17: =D14+D15+D16 -> #DIV/0! | E17: =E14+E15+E16 -> 0.065996641 | F17: =F14+F15+F16 -> 0.055656371 | G17: =G14+G15+G16 -> 0.050765387 | H17: =H14+H15+H16 -> 0.04826652 | I17: =I14+I15+I16 -> 0.041331388 | J17: =J14+J15+J16 -> 0.043740023 | K17: =K14+K15+K16 -> 0.044916518 | ... AE17: =AE14+AE15+AE16 -> 0.038126456 | AH17: =AH14+AH15+AH16 -> #DIV/0! | AI17: =AI14+AI15+AI16 -> 0.0072817386 | AJ17: =AJ14+AJ15+AJ16 -> 0.0063193699 | AK17: =AK14+AK15+AK16 -> 0.0068536852 | AL17: =AL14+AL15+AL16 -> 0.0071429546 | AM17: =AM14+AM15+AM16 -> 0.0079405551 | AN17: =AN14+AN15+AN16 -> 0.0078784049 | AO17: =AO14+AO15+AO16 -> 0.0091478326 | ... CO17: =CO14+CO15+CO16 -> 0.0088975098 | CS17: 0.0097027722
A18: TC | D18: =D41/C5 -> #DIV/0! | E18: =E41/D5 -> 0.026321515 | F18: =F41/E5 -> 0.025004321 | G18: =G41/F5 -> 0.024027576 | H18: =H41/G5 -> 0.022603768 | I18: =I41/H5 -> 0.02006167 | J18: =J41/I5 -> 0.01907435 | K18: =K41/J5 -> 0.018294068 | ... AE18: =AE41/AD5 -> 0.019651606 | AH18: =AH41/AG5 -> #DIV/0! | AI18: =AI41/AH5 -> 0.00361137 | AJ18: =AJ41/AI5 -> 0.0034298323 | AK18: =AK41/AJ5 -> 0.003849968 | AL18: =AL41/AK5 -> 0.0038048408 | AM18: =AM41/AL5 -> 0.0039163081 | AN18: =AN41/AM5 -> 0.0041666655 | AO18: =AO41/AN5 -> 0.0038200288 | ... BY18: =BY41/BX5 -> 0.0044874666 | BZ18: =+AVERAGE(BV18:BY18) -> 0.0046077231 | CA18: =+AVERAGE(BW18:BZ18) -> 0.0045877607 | CB18: =+AVERAGE(BX18:CA18) -> 0.0045953388 | CC18: =+AVERAGE(BY18:CB18) -> 0.0045695723 | CD18: =+AVERAGE(BZ18:CC18) -> 0.0045900987 | CE18: =+AVERAGE(CA18:CD18) -> 0.0045856926 | CF18: =+AVERAGE(CB18:CE18) -> 0.0045851756 | CG18: =+AVERAGE(CC18:CF18) -> 0.0045826348 | ... CO18: =+AVERAGE(CK18:CN18) -> 0.0045847351 | CS18: 0.0045574486
A19: PPP | D19: =D17-D18 -> #DIV/0! | E19: =E17-E18 -> 0.039675126 | F19: =F17-F18 -> 0.03065205 | G19: =G17-G18 -> 0.026737811 | H19: =H17-H18 -> 0.025662752 | I19: =I17-I18 -> 0.021269718 | J19: =J17-J18 -> 0.024665673 | K19: =K17-K18 -> 0.026622449 | ... AE19: =AE17-AE18 -> 0.01847485 | AH19: =AH17-AH18 -> #DIV/0! | AI19: =AI17-AI18 -> 0.0036703685 | AJ19: =AJ17-AJ18 -> 0.0028895376 | AK19: =AK17-AK18 -> 0.0030037172 | AL19: =AL17-AL18 -> 0.0033381138 | AM19: =AM17-AM18 -> 0.004024247 | AN19: =AN17-AN18 -> 0.0037117394 | AO19: =AO17-AO18 -> 0.0053278038 | ... CO19: =CO17-CO18 -> 0.0043127747 | CS19: 0.0051453235
A20: Provision | D20: =D44/C5 -> #DIV/0! | E20: =E44/D5 -> 0.016525483 | F20: =F44/E5 -> 0.015482029 | G20: =G44/F5 -> 0.0109399 | H20: =H44/G5 -> 0.010940684 | I20: =I44/H5 -> 0.0075779847 | J20: =J44/I5 -> 0.0086580776 | K20: =K44/J5 -> 0.0065197818 | ... AE20: =AE44/AD5 -> 0.0046992989 | AH20: =AH44/AG5 -> #DIV/0! | AI20: =AI44/AH5 -> 0.0022887838 | AJ20: =AJ44/AI5 -> 0.0026595011 | AK20: =AK44/AJ5 -> 0.011550305 | AL20: =AL44/AK5 -> 0.0027399082 | AM20: =AM44/AL5 -> 0.0029808944 | AN20: =AN44/AM5 -> 0.0027811303 | AO20: =AO44/AN5 -> 0.0048543638 | ... BY20: =BY44/BX5 -> 0.00056517365 | BZ20: =+AVERAGE(BV20:BY20)*1.005 -> 0.0012197084 | CA20: =+AVERAGE(BW20:BZ20)*1.005 -> 0.001157655 | CB20: =+AVERAGE(BX20:CA20)*1.005 -> 0.001094145 | CC20: =+AVERAGE(BY20:CB20)*1.005 -> 0.0010142164 | CD20: =+AVERAGE(BZ20:CC20)*1.005 -> 0.0011270384 | CE20: =+AVERAGE(CA20:CD20)*1.005 -> 0.001103755 | CF20: =+AVERAGE(CB20:CE20)*1.005 -> 0.0010902126 | CG20: =+AVERAGE(CC20:CF20)*1.005 -> 0.0010892246 | CH20: =+AVERAGE(CD20:CG20) -> 0.0011025577 | CI20: =+AVERAGE(CE20:CH20) -> 0.0010964375 | CJ20: =+AVERAGE(CF20:CI20) -> 0.0010946081 | CK20: =+AVERAGE(CG20:CJ20) -> 0.001095707 | CL20: =+AVERAGE(CH20:CK20) -> 0.0010973275 | CM20: =+AVERAGE(CI20:CL20) -> 0.00109602 | CN20: =+AVERAGE(CJ20:CM20) -> 0.0010959157 | CO20: =+AVERAGE(CK20:CN20) -> 0.0010962425 | CS20: 0.0014104312
A21: PBT | D21: =D19-D20 -> #DIV/0! | E21: =E19-E20 -> 0.023149643 | F21: =F19-F20 -> 0.01517002 | G21: =G19-G20 -> 0.015797911 | H21: =H19-H20 -> 0.014722069 | I21: =I19-I20 -> 0.013691733 | J21: =J19-J20 -> 0.016007595 | K21: =K19-K20 -> 0.020102668 | ... AE21: =AE19-AE20 -> 0.013775551 | AH21: =AH19-AH20 -> #DIV/0! | AI21: =AI19-AI20 -> 0.0013815848 | AJ21: =AJ19-AJ20 -> 0.00023003656 | AK21: =AK19-AK20 -> -0.0085465883 | AL21: =AL19-AL20 -> 0.00059820559 | AM21: =AM19-AM20 -> 0.0010433525 | AN21: =AN19-AN20 -> 0.00093060906 | AO21: =AO19-AO20 -> 0.00047343999 | ... CO21: =CO19-CO20 -> 0.0032165321 | CS21: 0.0037348923
A22: Tax | D22: =D46/C5 -> #DIV/0! | E22: =E46/D5 -> 0.00457995 | F22: =F46/E5 -> 0.0020155485 | G22: =G46/F5 -> 0.0020473958 | H22: =H46/G5 -> 0.002202834 | I22: =I46/H5 -> 0.0024436603 | J22: =J46/I5 -> 0.0031113883 | K22: =K46/J5 -> 0.0042084069 | ... AE22: =AE46/AD5 -> 0.0035816433 | AH22: =AH46/AG5 -> #DIV/0! | AI22: =AI46/AH5 -> 0.00038312221 | AJ22: =AJ46/AI5 -> 7.1882935e-05 | AK22: =AK46/AJ5 -> -0.0014220021 | AL22: =AL46/AK5 -> 0.00017802099 | AM22: =AM46/AL5 -> 0.00037242852 | AN22: =AN46/AM5 -> 0.00032761276 | AO22: =AO46/AN5 -> 8.9605569e-05 | ... CO22: =CO46/CN5 -> 0.00083629835 | CS22: 0.00097107201
A23: PAT | D23: =D21-D22 -> #DIV/0! | E23: =E21-E22 -> 0.018569693 | F23: =F21-F22 -> 0.013154472 | G23: =G21-G22 -> 0.013750515 | H23: =H21-H22 -> 0.012519235 | I23: =I21-I22 -> 0.011248073 | J23: =J21-J22 -> 0.012896207 | K23: =K21-K22 -> 0.015894261 | ... AE23: =AE21-AE22 -> 0.010193908 | AH23: =AH21-AH22 -> #DIV/0! | AI23: =AI21-AI22 -> 0.00099846258 | AJ23: =AJ21-AJ22 -> 0.00015815362 | AK23: =AK21-AK22 -> -0.0071245862 | AL23: =AL21-AL22 -> 0.0004201846 | AM23: =AM21-AM22 -> 0.000670924 | AN23: =AN21-AN22 -> 0.0006029963 | AO23: =AO21-AO22 -> 0.00038383442 | ... CO23: =CO21-CO22 -> 0.0023802338 | CS23: 0.0027638203
A25: CD Ratio % | B25: =+B114/B108 -> 0.47116968 | C25: =+C114/C108 -> 0.51736218 | D25: =+D114/D108 -> 0.56136622 | E25: =+E114/E108 -> 0.55172705 | F25: =+F114/F108 -> 0.62421438 | G25: =+G114/G108 -> 0.67999574 | H25: =+H114/H108 -> 0.69184353 | I25: =+I114/I108 -> 0.69602359 | ... AB25: =+AB114/AB108 -> 0.81956643 | AH25: =+AH114/AH108 -> 0.68675334 | AI25: =+AI114/AI108 -> 0.66585693 | AJ25: =+AJ114/AJ108 -> 0.6765504 | AK25: =+AK114/AK108 -> 0.67678312 | AL25: =+AL114/AL108 -> 0.6904653 | AM25: =+AM114/AM108 -> 0.67543869 | AN25: =+AN114/AN108 -> 0.64985014 | AO25: =+AO114/AO108 -> 0.69054282 | ... CO25: =+CO114/CO108 -> 0.9416547 | CS25: 0.76328756
A27: Presentation Data (End)
A28: Profit & Loss- Annual (Start)
A29: Interest Income | B29: =+'Annual Raw'!C7 -> 5618.2669 | C29: =+'Annual Raw'!D7 -> 6370.5611 | D29: =+'Annual Raw'!E7 -> 6657.7229 | E29: =+'Annual Raw'!F7 -> 7006.9207 | F29: =+'Annual Raw'!G7 -> 7571.9688 | G29: =+'Annual Raw'!H7 -> 8711.5123 | H29: =+'Annual Raw'!I7 -> 11364.556 | I29: =+'Annual Raw'!J7 -> 14200.737 | ... AA29: =+'Annual Raw'!AB7 -> 126366.17 | AB29: =SUM(BZ29:CC29) -> 144337.57 | AC29: =SUM(CD29:CG29) -> 159397.79 | AD29: =SUM(CH29:CK29) -> 173050.53 | AE29: =SUM(CL29:CO29) -> 189753.98 | AH29: =+'QTR Raw'!C6 -> 11139.65 | AI29: =+'QTR Raw'!D6 -> 11267.5 | AJ29: =+'QTR Raw'!E6 -> 10882.07 | AK29: =+'QTR Raw'!F6 -> 10732.91 | AL29: =+'QTR Raw'!G6 -> 10201.7 | AM29: =+'QTR Raw'!H6 -> 10405.35 | AN29: =+'QTR Raw'!I6 -> 10287.67 | AO29: =+'QTR Raw'!J6 -> 10492.92 | ... BW29: =+'QTR Raw'!AR6 -> 31543.89 | BX29: 31981.6 | BY29: =+'QTR Raw'!AT6 -> 31837.85 | BZ29: =BZ12*BY5 -> 34653.306 | CA29: =CA12*BZ5 -> 35653.96 | CB29: =CB12*CA5 -> 36658.544 | CC29: =CC12*CB5 -> 37371.757 | CD29: =CD12*CC5 -> 38144.318 | CE29: =CE12*CD5 -> 39385.522 | CF29: =CF12*CE5 -> 40583.065 | CG29: =CG12*CF5 -> 41284.887 | ... CO29: =CO12*CN5 -> 49248.808 | CS29: 32308.289 | CX29: 126366.17
A30: Interest exp | B30: =+'Annual Raw'!C10 -> 3735.2481 | C30: =+'Annual Raw'!D10 -> 4550.2484 | D30: =+'Annual Raw'!E10 -> 4424.7728 | E30: =+'Annual Raw'!F10 -> 4324.5655 | F30: =+'Annual Raw'!G10 -> 4421.4993 | G30: =+'Annual Raw'!H10 -> 5130.0069 | H30: =+'Annual Raw'!I10 -> 7337.7305 | I30: =+'Annual Raw'!J10 -> 10662.944 | ... AA30: =+'Annual Raw'!AB10 -> 89155.928 | AB30: =SUM(BZ30:CC30) -> 100707.53 | AC30: =SUM(CD30:CG30) -> 110232.04 | AD30: =SUM(CH30:CK30) -> 120790.07 | AE30: =SUM(CL30:CO30) -> 132390.45 | AH30: =+'QTR Raw'!C9 -> 8623.15 | AI30: =+'QTR Raw'!D9 -> 8621 | AJ30: =+'QTR Raw'!E9 -> 8655.47 | AK30: =+'QTR Raw'!F9 -> 8359.15 | AL30: =+'QTR Raw'!G9 -> 7894.3 | AM30: =+'QTR Raw'!H9 -> 7963 | AN30: =+'QTR Raw'!I9 -> 7873.87 | AO30: =+'QTR Raw'!J9 -> 7784.7 | ... BW30: =+'QTR Raw'!AR9 -> 22402.7 | BX30: 22729.28 | BY30: =+'QTR Raw'!AT9 -> 22029.88 | BZ30: =BZ13*BY5 -> 24215.546 | CA30: =CA13*BZ5 -> 24818.556 | CB30: =CB13*CA5 -> 25639.631 | CC30: =CC13*CB5 -> 26033.793 | CD30: =CD13*CC5 -> 26350.919 | CE30: =CE13*CD5 -> 27130.024 | CF30: =CF13*CE5 -> 28160.261 | CG30: =CG13*CF5 -> 28590.834 | ... CO30: =CO13*CN5 -> 34353.441 | CS30: 22945.582 | CX30: 89155.928
A31: NII | B31: =B29-B30 -> 1883.0188 | C31: =C29-C30 -> 1820.3127 | D31: =D29-D30 -> 2232.9501 | E31: =E29-E30 -> 2682.3552 | F31: =F29-F30 -> 3150.4695 | G31: =G29-G30 -> 3581.5054 | H31: =H29-H30 -> 4026.8257 | I31: =I29-I30 -> 3537.7926 | ... AE31: =AE29-AE30 -> 57363.538 | AH31: =AH29-AH30 -> 2516.5 | AI31: =AI29-AI30 -> 2646.5 | AJ31: =AJ29-AJ30 -> 2226.6 | AK31: =AK29-AK30 -> 2373.76 | AL31: =AL29-AL30 -> 2307.4 | AM31: =AM29-AM30 -> 2442.35 | AN31: =AN29-AN30 -> 2413.8 | AO31: =AO29-AO30 -> 2708.22 | ... CO31: =CO29-CO30 -> 14895.367 | CS31: 9362.7073 | CX31: 37210.24
A32: Other Income | B32: =+'Annual Raw'!C8 -> 917.787 | C32: =+'Annual Raw'!D8 -> 1428.5343 | D32: =+'Annual Raw'!E8 -> 1512.1313 | E32: =+'Annual Raw'!F8 -> 2072.9132 | F32: =+'Annual Raw'!G8 -> 1543.8273 | G32: =+'Annual Raw'!H8 -> 1377.5149 | H32: =+'Annual Raw'!I8 -> 1450.9497 | I32: =+'Annual Raw'!J8 -> 2212.8724 | ... AA32: =+'Annual Raw'!AB8 -> 26838.037 | AB32: =SUM(BZ32:CC32) -> 25700.107 | AC32: =SUM(CD32:CG32) -> 26356.297 | AD32: =SUM(CH32:CK32) -> 28637.526 | AE32: =SUM(CL32:CO32) -> 31333.174 | AH32: =+'QTR Raw'!C7 -> 1112.99 | AI32: =+'QTR Raw'!D7 -> 1210.45 | AJ32: =+'QTR Raw'!E7 -> 1168.56 | AK32: =+'QTR Raw'!F7 -> 1383.23 | AL32: =+'QTR Raw'!G7 -> 1584.65 | AM32: =+'QTR Raw'!H7 -> 1781.77 | AN32: =+'QTR Raw'!I7 -> 1791.7 | AO32: =+'QTR Raw'!J7 -> 2396.28 | ... BW32: =+'QTR Raw'!AR7 -> 7053.84 | BX32: 7899.36 | BY32: =+'QTR Raw'!AT7 -> 4824.36 | BZ32: =BZ15*BY5 -> 6660.1844 | CA32: =CA15*BZ5 -> 6559.1129 | CB32: =CB15*CA5 -> 6475.6861 | CC32: =CC15*CB5 -> 6005.1238 | CD32: =CD15*CC5 -> 6535.5402 | CE32: =CE15*CD5 -> 6549.956 | CF32: =CF15*CE5 -> 6642.4262 | CG32: =CG15*CF5 -> 6628.3744 | ... CO32: =CO15*CN5 -> 8126.5575 | CS32: 7224.7748 | CX32: 26838.037
A33: TI | B33: =B31+B32 -> 2800.8058 | C33: =C31+C32 -> 3248.847 | D33: =D31+D32 -> 3745.0814 | E33: =E31+E32 -> 4755.2684 | F33: =F31+F32 -> 4694.2968 | G33: =G31+G32 -> 4959.0203 | H33: =H31+H32 -> 5477.7754 | I33: =I31+I32 -> 5750.665 | ... AE33: =AE31+AE32 -> 88696.712 | AH33: =AH31+AH32 -> 3629.49 | AI33: =AI31+AI32 -> 3856.95 | AJ33: =AJ31+AJ32 -> 3395.16 | AK33: =AK31+AK32 -> 3756.99 | AL33: =AL31+AL32 -> 3892.05 | AM33: =AM31+AM32 -> 4224.12 | AN33: =AN31+AN32 -> 4205.5 | AO33: =AO31+AO32 -> 5104.5 | ... CO33: =CO31+CO32 -> 23021.925 | CS33: 16587.482 | CX33: 64048.277
A34: YOY% | C34: =+IF(B33<0,1-C33/B33,C33/B33-1) -> 0.15996868 | D34: =+IF(C33<0,1-D33/C33,D33/C33-1) -> 0.1527417 | E34: =+IF(D33<0,1-E33/D33,E33/D33-1) -> 0.26973699 | F34: =+IF(E33<0,1-F33/E33,F33/E33-1) -> -0.012821905 | G34: =+IF(F33<0,1-G33/F33,G33/F33-1) -> 0.056392578 | H34: =+IF(G33<0,1-H33/G33,H33/G33-1) -> 0.10460838 | I34: =+IF(H33<0,1-I33/H33,I33/H33-1) -> 0.049817596 | J34: =+IF(I33<0,1-J33/I33,J33/I33-1) -> 0.22229695 | ... AB34: =+IF(AA33<0,1-AB33/AA33,AB33/AA33-1) -> 0.082467019 | AC34: =AC33/AB33-1 -> 0.089310409 | AD34: =AD33/AC33-1 -> 0.071183757 | AE34: =AE33/AD33-1 -> 0.096401859 | AL34: =+IF(AH33<0,1-AL33/AH33,AL33/AH33-1) -> 0.072340742 | AM34: =+IF(AI33<0,1-AM33/AI33,AM33/AI33-1) -> 0.095196982 | AN34: =+IF(AJ33<0,1-AN33/AJ33,AN33/AJ33-1) -> 0.23867506 | AO34: =+IF(AK33<0,1-AO33/AK33,AO33/AK33-1) -> 0.35866744 | AP34: =+IF(AL33<0,1-AP33/AL33,AP33/AL33-1) -> 0.23887155 | AQ34: =+IF(AM33<0,1-AQ33/AM33,AQ33/AM33-1) -> 0.11728833 | AR34: =+IF(AN33<0,1-AR33/AN33,AR33/AN33-1) -> 0.24731423 | AS34: =+IF(AO33<0,1-AS33/AO33,AS33/AO33-1) -> -0.15382702 | ... CO34: =+IF(CK33<0,1-CO33/CK33,CO33/CK33-1) -> 0.094938444 | CS34: 0.10947641 | CX34: 0.075993897
A35: Employee Cost | B35: =+'Annual Raw'!C12 -> 1253.073 | C35: =+'Annual Raw'!D12 -> 1122.5201 | D35: =+'Annual Raw'!E12 -> 1162.199 | E35: =+'Annual Raw'!F12 -> 1273.2058 | F35: =+'Annual Raw'!G12 -> 1380.1499 | G35: =+'Annual Raw'!H12 -> 1515.3032 | H35: =+'Annual Raw'!I12 -> 1609.2919 | I35: =+'Annual Raw'!J12 -> 1661.2807 | ... AA35: =+'Annual Raw'!AB12 -> 19265.997 | AB35: =SUM(BZ35:CC35) -> 34764.324 | AC35: =SUM(CD35:CG35) -> 38064.669 | AD35: =SUM(CH35:CK35) -> 41711.478 | AE35: =SUM(CL35:CO35) -> 45717.149 | AH35: =+'QTR Raw'!C11 -> 1058.75 | AI35: =+'QTR Raw'!D11 -> 1107.84 | AJ35: =+'QTR Raw'!E11 -> 1039.75 | AK35: =+'QTR Raw'!F11 -> 1239.54 | AL35: =+'QTR Raw'!G11 -> 1208.17 | AM35: =+'QTR Raw'!H11 -> 1216.94 | AN35: =+'QTR Raw'!I11 -> 1305.74 | AO35: =+'QTR Raw'!J11 -> 1184.24 | ... BW35: =+'QTR Raw'!AR11 -> 4822.25 | BX35: 4904.57 | BY35: =+'QTR Raw'!AT11 -> 4743.64 | BZ35: =BZ18*BY5 -> 8339.422 | CA35: =CA18*BZ5 -> 8564.7289 | CB35: =CB18*CA5 -> 8884.2349 | CC35: =CC18*CB5 -> 8975.9378 | CD35: =CD18*CC5 -> 9096.0336 | CE35: =CE18*CD5 -> 9370.4771 | CF35: =CF18*CE5 -> 9728.411 | CG35: =CG18*CF5 -> 9869.7469 | ... CO35: =CO18*CN5 -> 11862.805 | CS35: 7791.2371 | CX35: 19265.997
A36: Operating & Establishment Expenses | B36: =+'Annual Raw'!C11-'Annual Raw'!C12-'Annual Raw'!C13-'Annual Raw'!C14-'Annual Raw'!C15-'Annual Raw'!C16-'Annual Raw'!C17 -> 188.1405 | C36: =+'Annual Raw'!D11-'Annual Raw'!D12-'Annual Raw'!D13-'Annual Raw'!D14-'Annual Raw'!D15-'Annual Raw'!D16-'Annual Raw'!D17 -> 196.247 | D36: =+'Annual Raw'!E11-'Annual Raw'!E12-'Annual Raw'!E13-'Annual Raw'!E14-'Annual Raw'!E15-'Annual Raw'!E16-'Annual Raw'!E17 -> 270.5371 | E36: =+'Annual Raw'!F11-'Annual Raw'!F12-'Annual Raw'!F13-'Annual Raw'!F14-'Annual Raw'!F15-'Annual Raw'!F16-'Annual Raw'!F17 -> 280.0778 | F36: =+'Annual Raw'!G11-'Annual Raw'!G12-'Annual Raw'!G13-'Annual Raw'!G14-'Annual Raw'!G15-'Annual Raw'!G16-'Annual Raw'!G17 -> 306.7664 | G36: =+'Annual Raw'!H11-'Annual Raw'!H12-'Annual Raw'!H13-'Annual Raw'!H14-'Annual Raw'!H15-'Annual Raw'!H16-'Annual Raw'!H17 -> 360.81 | H36: =+'Annual Raw'!I11-'Annual Raw'!I12-'Annual Raw'!I13-'Annual Raw'!I14-'Annual Raw'!I15-'Annual Raw'!I16-'Annual Raw'!I17 -> 420.066 | I36: =+'Annual Raw'!J11-'Annual Raw'!J12-'Annual Raw'!J13-'Annual Raw'!J14-'Annual Raw'!J15-'Annual Raw'!J16-'Annual Raw'!J17 -> 504.4824 | ... AA36: =+'Annual Raw'!AB11-'Annual Raw'!AB12-'Annual Raw'!AB13-'Annual Raw'!AB14-'Annual Raw'!AB15-'Annual Raw'!AB16-'Annual Raw'!AB17 -> 7605.5766 | AB36: =SUM(BZ36:CC36) -> 0 | AC36: =SUM(CD36:CG36) -> 0 | AD36: =SUM(CH36:CK36) -> 0 | AE36: =SUM(CL36:CO36) -> 0 | AH36: =+'QTR Raw'!C10-'QTR Raw'!C11-'QTR Raw'!C12 -> 567.17 | AI36: =+'QTR Raw'!D10-'QTR Raw'!D11-'QTR Raw'!D12 -> 805.01 | AJ36: =+'QTR Raw'!E10-'QTR Raw'!E11-'QTR Raw'!E12 -> 802.97 | AK36: =+'QTR Raw'!F10-'QTR Raw'!F11-'QTR Raw'!F12 -> 870.9 | AL36: =+'QTR Raw'!G10-'QTR Raw'!G11-'QTR Raw'!G12 -> 865.01 | AM36: =+'QTR Raw'!H10-'QTR Raw'!H11-'QTR Raw'!H12 -> 866.41 | AN36: =+'QTR Raw'!I10-'QTR Raw'!I11-'QTR Raw'!I12 -> 918.43 | AO36: =+'QTR Raw'!J10-'QTR Raw'!J11-'QTR Raw'!J12 -> 947.34 | ... BW36: =+'QTR Raw'!AR10-'QTR Raw'!AR11-'QTR Raw'!AR12 -> 2784.65 | BX36: 3127.64 | BY36: =+'QTR Raw'!AT10-'QTR Raw'!AT11-'QTR Raw'!AT12 -> 3131.31 | CX36: 7605.5766
A37: Insurance | B37: =+'Annual Raw'!C17 -> 25.3782 | C37: =+'Annual Raw'!D17 -> 30.8664 | D37: =+'Annual Raw'!E17 -> 33.7607 | E37: =+'Annual Raw'!F17 -> 38.4367 | F37: =+'Annual Raw'!G17 -> 69.3415 | G37: =+'Annual Raw'!H17 -> 97.6895 | H37: =+'Annual Raw'!I17 -> 115.5902 | I37: =+'Annual Raw'!J17 -> 139.7206 | ... AA37: =+'Annual Raw'!AB17 -> 1853.1619 | CX37: 1853.1619
A38: Rent, Rates & Taxes | B38: =+'Annual Raw'!C14 -> 133.7397 | C38: =+'Annual Raw'!D14 -> 144.3182 | D38: =+'Annual Raw'!E14 -> 162.8883 | E38: =+'Annual Raw'!F14 -> 175.2801 | F38: =+'Annual Raw'!G14 -> 205.462 | G38: =+'Annual Raw'!H14 -> 206.6958 | H38: =+'Annual Raw'!I14 -> 232.902 | I38: =+'Annual Raw'!J14 -> 270.1871 | ... AA38: =+'Annual Raw'!AB14 -> 1231.0793 | AB38: =SUM(BZ38:CC38) -> 0 | AC38: =SUM(CD38:CG38) -> 0 | AD38: =SUM(CH38:CK38) -> 0 | AE38: =SUM(CL38:CO38) -> 0 | CX38: 1231.0793
A39: Depreciation | B39: =+'Annual Raw'!C15+'Annual Raw'!C16 -> 65.9137 | C39: =+'Annual Raw'!D15+'Annual Raw'!D16 -> 92.6775 | D39: =+'Annual Raw'!E15+'Annual Raw'!E16 -> 108.6539 | E39: =+'Annual Raw'!F15+'Annual Raw'!F16 -> 113.7141 | F39: =+'Annual Raw'!G15+'Annual Raw'!G16 -> 132.9457 | G39: =+'Annual Raw'!H15+'Annual Raw'!H16 -> 145.0284 | H39: =+'Annual Raw'!I15+'Annual Raw'!I16 -> 148.177 | I39: =+'Annual Raw'!J15+'Annual Raw'!J16 -> 169.9684 | ... AA39: =+'Annual Raw'!AB15+'Annual Raw'!AB16 -> 917.3623 | AB39: =SUM(BZ39:CC39) -> 0 | AC39: =SUM(CD39:CG39) -> 0 | AD39: =SUM(CH39:CK39) -> 0 | AE39: =SUM(CL39:CO39) -> 0 | AH39: =+'QTR Raw'!C12 -> 0 | AI39: =+'QTR Raw'!D12 -> 0 | AJ39: =+'QTR Raw'!E12 -> 0 | AK39: =+'QTR Raw'!F12 -> 0 | AL39: =+'QTR Raw'!G12 -> 0 | AM39: =+'QTR Raw'!H12 -> 0 | AN39: =+'QTR Raw'!I12 -> 0 | AO39: =+'QTR Raw'!J12 -> 0 | ... BW39: =+'QTR Raw'!AR12 -> 0 | BY39: =+'QTR Raw'!AT12 -> 0 | CX39: 917.3623
A40: Advertisement & Sales Promotion | B40: =+'Annual Raw'!C13 -> 3.3333 | C40: =+'Annual Raw'!D13 -> 5.9777 | D40: =+'Annual Raw'!E13 -> 9.6667 | E40: =+'Annual Raw'!F13 -> 15.8346 | F40: =+'Annual Raw'!G13 -> 14.3061 | G40: =+'Annual Raw'!H13 -> 21.6085 | H40: =+'Annual Raw'!I13 -> 39.2783 | I40: =+'Annual Raw'!J13 -> 45.6521 | ... AA40: =+'Annual Raw'!AB13 -> 156.5283 | AB40: =SUM(BZ40:CC40) -> 0 | AC40: =SUM(CD40:CG40) -> 0 | AD40: =SUM(CH40:CK40) -> 0 | AE40: =SUM(CL40:CO40) -> 0 | CX40: 156.5283
A41: TC | B41: =SUM(B35:B40) -> 1669.5784 | C41: =SUM(C35:C40) -> 1592.6069 | D41: =SUM(D35:D40) -> 1747.7057 | E41: =SUM(E35:E40) -> 1896.5491 | F41: =SUM(F35:F40) -> 2108.9716 | G41: =SUM(G35:G40) -> 2347.1354 | H41: =SUM(H35:H40) -> 2565.3054 | I41: =SUM(I35:I40) -> 2791.2913 | ... AE41: =SUM(AE35:AE40) -> 45717.149 | AH41: =SUM(AH35:AH39) -> 1625.92 | AI41: =SUM(AI35:AI39) -> 1912.85 | AJ41: =SUM(AJ35:AJ39) -> 1842.72 | AK41: =SUM(AK35:AK39) -> 2110.44 | AL41: =SUM(AL35:AL39) -> 2073.18 | AM41: =SUM(AM35:AM39) -> 2083.35 | AN41: =SUM(AN35:AN39) -> 2224.17 | AO41: =SUM(AO35:AO39) -> 2131.58 | ... AS41: =SUM(AS35:AS39) -> 2554.64 | AT41: =SUM(AT35:AT40) -> 2783.02 | AU41: =SUM(AU35:AU40) -> 2509.2 | AV41: =SUM(AV35:AV40) -> 2781.35 | AW41: =SUM(AW35:AW40) -> 2388.64 | AX41: =SUM(AX35:AX40) -> 2662.47 | AY41: =SUM(AY35:AY40) -> 2654.74 | AZ41: =SUM(AZ35:AZ40) -> 2807.43 | BA41: =SUM(BA35:BA40) -> 3452.6 | ... CO41: =SUM(CO35:CO40) -> 11862.805 | CS41: 7791.2371 | CX41: 31029.706
A42: PPP | B42: =+B33-B41 -> 1131.2274 | C42: =+C33-C41 -> 1656.2401 | D42: =+D33-D41 -> 1997.3757 | E42: =+E33-E41 -> 2858.7193 | F42: =+F33-F41 -> 2585.3252 | G42: =+G33-G41 -> 2611.8849 | H42: =+H33-H41 -> 2912.47 | I42: =+I33-I41 -> 2959.3737 | ... AE42: =+AE33-AE41 -> 42979.563 | AH42: =+AH33-AH41 -> 2003.57 | AI42: =+AI33-AI41 -> 1944.1 | AJ42: =+AJ33-AJ41 -> 1552.44 | AK42: =+AK33-AK41 -> 1646.55 | AL42: =+AL33-AL41 -> 1818.87 | AM42: =+AM33-AM41 -> 2140.77 | AN42: =+AN33-AN41 -> 1981.33 | AO42: =+AO33-AO41 -> 2972.92 | ... CO42: =+CO33-CO41 -> 11159.119 | CS42: 8796.2451 | CX42: 33018.572
A43: YOY% | C43: =+IF(B42<0,1-C42/B42,C42/B42-1) -> 0.4641089 | D43: =+IF(C42<0,1-D42/C42,D42/C42-1) -> 0.2059699 | E43: =+IF(D42<0,1-E42/D42,E42/D42-1) -> 0.43123765 | F43: =+IF(E42<0,1-F42/E42,F42/E42-1) -> -0.095635168 | G43: =+IF(F42<0,1-G42/F42,G42/F42-1) -> 0.010273253 | H43: =+IF(G42<0,1-H42/G42,H42/G42-1) -> 0.11508359 | I43: =+IF(H42<0,1-I42/H42,I42/H42-1) -> 0.016104441 | J43: =+IF(I42<0,1-J42/I42,J42/I42-1) -> 0.33939583 | ... AB43: =+IF(AA42<0,1-AB42/AA42,AB42/AA42-1) -> 0.046860064 | AC43: =+AC42/AB42-1 -> 0.083653695 | AD43: =+AD42/AC42-1 -> 0.04616269 | AE43: =+AE42/AD42-1 -> 0.096794692 | AL43: =+IF(AH42<0,1-AL42/AH42,AL42/AH42-1) -> -0.092185449 | AM43: =+IF(AI42<0,1-AM42/AI42,AM42/AI42-1) -> 0.10116249 | AN43: =+IF(AJ42<0,1-AN42/AJ42,AN42/AJ42-1) -> 0.27626833 | AO43: =+IF(AK42<0,1-AO42/AK42,AO42/AK42-1) -> 0.80554493 | AP43: =+IF(AL42<0,1-AP42/AL42,AP42/AL42-1) -> 0.35929451 | AQ43: =+IF(AM42<0,1-AQ42/AM42,AQ42/AM42-1) -> 0.15837759 | AR43: =+IF(AN42<0,1-AR42/AN42,AR42/AN42-1) -> 0.42903504 | AS43: =+IF(AO42<0,1-AS42/AO42,AS42/AO42-1) -> -0.40642533 | ... CO43: =+IF(CK42<0,1-CO42/CK42,CO42/CK42-1) -> 0.093521601 | CS43: 0.12245395 | CX43: 0.051873037
A44: Provisions and Contingencies | B44: =+'Annual Raw'!C19 -> 655.1274 | C44: =+'Annual Raw'!D19 -> 604.8401 | D44: =+'Annual Raw'!E19 -> 678.1938 | E44: =+'Annual Raw'!F19 -> 1190.7137 | F44: =+'Annual Raw'!G19 -> 1305.8207 | G44: =+'Annual Raw'!H19 -> 1068.6649 | H44: =+'Annual Raw'!I19 -> 1241.66 | I44: =+'Annual Raw'!J19 -> 1054.367 | ... AA44: =+'Annual Raw'!AB19 -> 8111.9006 | AB44: =SUM(BZ44:CC44) -> 8476.2456 | AC44: =SUM(CD44:CG44) -> 9147.8496 | AD44: =SUM(CH44:CK44) -> 9982.1062 | AE44: =SUM(CL44:CO44) -> 10932.366 | AH44: =+'QTR Raw'!C18 -> 1359.73 | AI44: =+'QTR Raw'!D18 -> 1212.31 | AJ44: =+'QTR Raw'!E18 -> 1428.85 | AK44: =+'QTR Raw'!F18 -> 6331.54 | AL44: =+'QTR Raw'!G18 -> 1492.92 | AM44: =+'QTR Raw'!H18 -> 1585.74 | AN44: =+'QTR Raw'!I18 -> 1484.57 | AO44: =+'QTR Raw'!J18 -> 2708.74 | ... BW44: =+'QTR Raw'!AR18 -> 2354.17 | BX44: 2414.36 | BY44: =+'QTR Raw'!AT18 -> 991.81 | BZ44: =BZ20*BY5 -> 2207.5249 | CA44: =CA20*BZ5 -> 2161.1854 | CB44: =CB20*CA5 -> 2115.3264 | CC44: =CC20*CB5 -> 1992.209 | CD44: =CD20*CC5 -> 2233.4114 | CE44: =CE20*CD5 -> 2255.4305 | CF44: =CF20*CE5 -> 2313.1146 | CG44: =CG20*CF5 -> 2345.8931 | ... CO44: =CO20*CN5 -> 2836.4805 | CS44: 2411.2183 | CX44: 8111.9006
A45: PBT | B45: =B42-B44 -> 476.1 | C45: =C42-C44 -> 1051.4 | D45: =D42-D44 -> 1319.1819 | E45: =E42-E44 -> 1668.0056 | F45: =F42-F44 -> 1279.5045 | G45: =G42-G44 -> 1543.22 | H45: =H42-H44 -> 1670.81 | I45: =I42-I44 -> 1905.0067 | ... AE45: =AE42-AE44 -> 32047.198 | AH45: =AH42-AH44 -> 643.84 | AI45: =AI42-AI44 -> 731.79 | AJ45: =AJ42-AJ44 -> 123.59 | AK45: =AK42-AK44 -> -4684.99 | AL45: =AL42-AL44 -> 325.95 | AM45: =AM42-AM44 -> 555.03 | AN45: =AN42-AN44 -> 496.76 | AO45: =AO42-AO44 -> 264.18 | ... CO45: =CO42-CO44 -> 8322.6388 | CS45: 6385.0268 | CX45: 24906.671
A46: Tax | B46: =+'Annual Raw'!C18 -> 191 | C46: =+'Annual Raw'!D18 -> 310 | D46: =+'Annual Raw'!E18 -> 300.29 | E46: =+'Annual Raw'!F18 -> 330 | F46: =+'Annual Raw'!G18 -> 170 | G46: =+'Annual Raw'!H18 -> 200 | H46: =+'Annual Raw'!I18 -> 250 | I46: =+'Annual Raw'!J18 -> 340 | ... AA46: =+'Annual Raw'!AB18 -> 5720 | AB46: =SUM(BZ46:CC46) -> 6783.2904 | AC46: =SUM(CD46:CG46) -> 7360.4787 | AD46: =SUM(CH46:CK46) -> 7593.1467 | AE46: =SUM(CL46:CO46) -> 8332.2715 | AH46: =+'QTR Raw'!C20 -> 165 | AI46: =+'QTR Raw'!D20 -> 202.93 | AJ46: =+'QTR Raw'!E20 -> 38.62 | AK46: =+'QTR Raw'!F20 -> -779.5 | AL46: =+'QTR Raw'!G20 -> 97 | AM46: =+'QTR Raw'!H20 -> 198.12 | AN46: =+'QTR Raw'!I20 -> 174.88 | AO46: =+'QTR Raw'!J20 -> 50 | ... BW46: =+'QTR Raw'!AR20 -> 1460 | BX46: 1550 | BY46: =+'QTR Raw'!AT20 -> 1260 | BZ46: =BZ45*0.26 -> 1703.2592 | CA46: =CA45*0.26 -> 1733.8368 | CB46: =CB45*0.26 -> 1688.7097 | CC46: =CC45*0.26 -> 1657.4846 | CD46: =CD45*0.26 -> 1819.8685 | CE46: =CE45*0.26 -> 1866.6822 | CF46: =CF45*0.26 -> 1826.1634 | CG46: =CG45*0.26 -> 1847.7646 | ... CO46: =CO45*0.26 -> 2163.8861 | CS46: 1660.107 | CX46: 5720
A47: PAT | B47: =B45-B46 -> 285.1 | C47: =C45-C46 -> 741.4 | D47: =D45-D46 -> 1018.8919 | E47: =E45-E46 -> 1338.0056 | F47: =F45-F46 -> 1109.5045 | G47: =G45-G46 -> 1343.22 | H47: =H45-H46 -> 1420.81 | I47: =I45-I46 -> 1565.0067 | ... AE47: =AE45-AE46 -> 23714.926 | AH47: =AH45-AH46 -> 478.84 | AI47: =AI45-AI46 -> 528.86 | AJ47: =AJ45-AJ46 -> 84.97 | AK47: =AK45-AK46 -> -3905.49 | AL47: =AL45-AL46 -> 228.95 | AM47: =AM45-AM46 -> 356.91 | AN47: =AN45-AN46 -> 321.88 | AO47: =AO45-AO46 -> 214.18 | ... CO47: =CO45-CO46 -> 6158.7527 | CS47: 4724.9198 | CX47: 19186.671
...

Sheet Share price Daily
A1: =_xll.EQNXTH(B1,"[ADJC];[ADJH];[ADJL];[ADJO];[UCLS];[VOLUME]","2015-Jan-01","Y","All traded days","Asc") -> EQNXTH | B1: =+'Annual Raw'!A1 -> 132483 | L1: =_xll.EQNXTH(B1,"[NADJC];[NADJH];[NADJLOW];[NADJOPEN];[NUCLOSE];[NVOLUME]","2015-Jan-01","Y","All traded days","Asc") -> EQNXTH
A2: Canara Bank | L2: Canara Bank
A3: DATE | B3: ADJHIGH | C3: ADJCLOSE | D3: ADJLOW | E3: ADJOPEN | F3: CLOSE | G3: VOLUME | L3: DATE | M3: ADJCLOSE | N3: ADJHIGH | O3: ADJLOW | P3: ADJOPEN | Q3: CLOSE | R3: VOLUME
A4: 42005 | B4: 88.066138 | C4: 87.453352 | D4: 87.122642 | E4: 87.229636 | F4: 449.55 | G4: 96217 | L4: 42005 | M4: 87.393062 | N4: 88.025287 | O4: 87.052632 | P4: 87.344429 | Q4: 449.25 | R4: 822446
A5: 42006 | B5: 88.678925 | C5: 87.336631 | D5: 86.967014 | E5: 87.735428 | F5: 448.95 | G5: 163216 | L5: 42006 | M5: 87.276343 | N5: 88.608881 | O5: 87.013726 | P5: 88.064194 | Q5: 448.65 | R5: 1552797
A6: 42009 | B6: 88.124499 | C6: 87.540893 | D6: 86.694664 | E6: 87.540893 | F6: 450 | G6: 142232 | L6: 42009 | M6: 87.616772 | N6: 88.151733 | O6: 86.66357 | P6: 87.383335 | Q6: 450.4 | R6: 1444209
A7: 42010 | B7: 87.054555 | C7: 85.080021 | D7: 84.739584 | E7: 87.054555 | F7: 437.35 | G7: 164083 | L7: 42010 | M7: 85.194861 | N7: 86.916461 | O7: 84.854432 | P7: 86.585758 | Q7: 437.95 | R7: 1863201
A8: 42011 | B8: 85.469092 | C8: 84.973027 | D8: 83.805815 | E8: 84.233793 | F8: 436.8 | G8: 143924 | L8: 42011 | M8: 85.048963 | N8: 85.554744 | O8: 83.745605 | P8: 84.620995 | Q8: 437.2 | R8: 1464071
A9: 42012 | B9: 88.377395 | C9: 88.036958 | D9: 85.401004 | E9: 85.809529 | F9: 452.55 | G9: 132504 | L9: 42012 | M9: 87.918295 | N9: 88.210092 | O9: 85.331033 | P9: 85.982712 | Q9: 451.95 | R9: 1579533
A10: 42013 | B10: 88.747012 | C10: 85.692807 | D10: 85.080021 | E10: 88.51357 | F10: 440.5 | G10: 199133 | L10: 42013 | M10: 85.739548 | N10: 88.793685 | O10: 85.010057 | P10: 88.793685 | Q10: 440.75 | R10: 1890184
A11: 42016 | B11: 87.074008 | C11: 86.441768 | D11: 84.613136 | E11: 85.401004 | F11: 444.35 | G11: 182974 | L11: 42016 | M11: 86.556578 | N11: 87.072085 | O11: 84.543182 | P11: 85.360212 | Q11: 444.95 | R11: 1298682
A12: 42017 | B12: 87.151822 | C12: 86.519583 | D12: 85.702534 | E12: 86.646031 | F12: 444.75 | G12: 115582 | L12: 42017 | M12: 86.507946 | N12: 87.169351 | O12: 85.652009 | P12: 86.712203 | Q12: 444.7 | R12: 1542933
A13: 42018 | B13: 86.879473 | C13: 85.32319 | D13: 84.768765 | E13: 86.081878 | F13: 438.6 | G13: 106996 | L13: 42018 | M13: 85.321306 | N13: 86.867828 | O13: 84.737713 | P13: 86.760836 | Q13: 438.6 | R13: 946520
A14: 42019 | B14: 90.916081 | C14: 88.824826 | D14: 87.929964 | E14: 90.283841 | F14: 456.6 | G14: 349202 | L14: 42019 | M14: 89.046575 | N14: 91.069698 | O14: 87.918295 | P14: 90.534738 | Q14: 457.75 | R14: 2264066
A15: 42020 | B15: 89.447339 | C15: 88.299581 | D15: 87.793789 | E15: 88.90264 | F15: 453.9 | G15: 118831 | L15: 42020 | M15: 88.492162 | N15: 89.464817 | O15: 87.772397 | P15: 89.066028 | Q15: 454.9 | R15: 1202830
... A2838: 46185 | B2838: 131.9 | C2838: 131.6 | D2838: 128.8 | E2838: 130.1 | F2838: 131.6 | G2838: 1802030 | L2838: 46185 | M2838: 131.67 | N2838: 131.92 | O2838: 128.8 | P2838: 130 | Q2838: 131.67 | R2838: 25287693

Sheet QTR Raw
A1: =+'Annual Raw'!A1 -> 132483
C2: 201506 | D2: 201509 | E2: 201512 | F2: 201603 | G2: 201606 | H2: 201609 | I2: 201612 | J2: 201703 | K2: 201706 | L2: 201709 | M2: 201712 | N2: 201803 | O2: 201806 | P2: 201809 | Q2: 201812 | R2: 201903 | S2: 201906 | T2: 201909 | U2: 201912 | V2: 202003 | W2: 202006 | X2: 202009 | Y2: 202012 | Z2: 202103 | AA2: 202106 | AB2: 202109 | AC2: 202112 | AD2: 202203 | AE2: 202206 | AF2: 202209 | AG2: 202212 | AH2: 202303 | AI2: 202306 | AJ2: 202309 | AK2: 202312 | AL2: 202403 | AM2: 202406 | AN2: 202409 | AO2: 202412 | AP2: 202503 | AQ2: 202506 | AR2: 202509 | AS2: 202512 | AT2: 202603 | AU2: 202606 | AV2: 202609 | AW2: 202612 | AX2: 202703 | AY2: 202706 | AZ2: 202709 | BA2: 202712 | BB2: 202803 | BC2: 202806 | BD2: 202809 | BE2: 202812 | BF2: 202903 | BG2: 202906 | BH2: 202909 | BI2: 202912 | BJ2: 203003
A4: Field Description | B4: Field Name
A5: Date End | B5: BQTR_DATE_END | C5: {=+_xll.EQNXTDZ($A$1,$B5,C$2)} -> 201506 | D5: {=+_xll.EQNXTDZ($A$1,$B5,D$2)} -> 201509 | E5: {=+_xll.EQNXTDZ($A$1,$B5,E$2)} -> 201512 | F5: {=+_xll.EQNXTDZ($A$1,$B5,F$2)} -> 201603 | G5: {=+_xll.EQNXTDZ($A$1,$B5,G$2)} -> 201606 | H5: {=+_xll.EQNXTDZ($A$1,$B5,H$2)} -> 201609 | I5: {=+_xll.EQNXTDZ($A$1,$B5,I$2)} -> 201612 | J5: {=+_xll.EQNXTDZ($A$1,$B5,J$2)} -> 201703 | ... BJ5: {=+_xll.EQNXTDZ($A$1,$B5,BJ$2)} -> 0
A6: Interest Earned | B6: BQTR_NET_SALES | C6: {=+_xll.EQNXTDZ($A$1,$B6,C$2)} -> 11139.65 | D6: {=+_xll.EQNXTDZ($A$1,$B6,D$2)} -> 11267.5 | E6: {=+_xll.EQNXTDZ($A$1,$B6,E$2)} -> 10882.07 | F6: {=+_xll.EQNXTDZ($A$1,$B6,F$2)} -> 10732.91 | G6: {=+_xll.EQNXTDZ($A$1,$B6,G$2)} -> 10201.7 | H6: {=+_xll.EQNXTDZ($A$1,$B6,H$2)} -> 10405.35 | I6: {=+_xll.EQNXTDZ($A$1,$B6,I$2)} -> 10287.67 | J6: {=+_xll.EQNXTDZ($A$1,$B6,J$2)} -> 10492.92 | ... BJ6: {=+_xll.EQNXTDZ($A$1,$B6,BJ$2)} -> 0
A7: Other Income | B7: BQTR_OTHER_INCOME | C7: {=+_xll.EQNXTDZ($A$1,$B7,C$2)} -> 1112.99 | D7: {=+_xll.EQNXTDZ($A$1,$B7,D$2)} -> 1210.45 | E7: {=+_xll.EQNXTDZ($A$1,$B7,E$2)} -> 1168.56 | F7: {=+_xll.EQNXTDZ($A$1,$B7,F$2)} -> 1383.23 | G7: {=+_xll.EQNXTDZ($A$1,$B7,G$2)} -> 1584.65 | H7: {=+_xll.EQNXTDZ($A$1,$B7,H$2)} -> 1781.77 | I7: {=+_xll.EQNXTDZ($A$1,$B7,I$2)} -> 1791.7 | J7: {=+_xll.EQNXTDZ($A$1,$B7,J$2)} -> 2396.28 | ... BJ7: {=+_xll.EQNXTDZ($A$1,$B7,BJ$2)} -> 0
A8: Total Income | B8: BQTR_TOTAL_INCOME | C8: {=+_xll.EQNXTDZ($A$1,$B8,C$2)} -> 12252.64 | D8: {=+_xll.EQNXTDZ($A$1,$B8,D$2)} -> 12477.95 | E8: {=+_xll.EQNXTDZ($A$1,$B8,E$2)} -> 12050.63 | F8: {=+_xll.EQNXTDZ($A$1,$B8,F$2)} -> 12116.14 | G8: {=+_xll.EQNXTDZ($A$1,$B8,G$2)} -> 11786.35 | H8: {=+_xll.EQNXTDZ($A$1,$B8,H$2)} -> 12187.12 | I8: {=+_xll.EQNXTDZ($A$1,$B8,I$2)} -> 12079.37 | J8: {=+_xll.EQNXTDZ($A$1,$B8,J$2)} -> 12889.2 | ... BJ8: {=+_xll.EQNXTDZ($A$1,$B8,BJ$2)} -> 0
A9: Interest Expended | B9: BQTR_INTEREST | C9: {=+_xll.EQNXTDZ($A$1,$B9,C$2)} -> 8623.15 | D9: {=+_xll.EQNXTDZ($A$1,$B9,D$2)} -> 8621 | E9: {=+_xll.EQNXTDZ($A$1,$B9,E$2)} -> 8655.47 | F9: {=+_xll.EQNXTDZ($A$1,$B9,F$2)} -> 8359.15 | G9: {=+_xll.EQNXTDZ($A$1,$B9,G$2)} -> 7894.3 | H9: {=+_xll.EQNXTDZ($A$1,$B9,H$2)} -> 7963 | I9: {=+_xll.EQNXTDZ($A$1,$B9,I$2)} -> 7873.87 | J9: {=+_xll.EQNXTDZ($A$1,$B9,J$2)} -> 7784.7 | ... BJ9: {=+_xll.EQNXTDZ($A$1,$B9,BJ$2)} -> 0
A10: Operating Expenses | B10: BQTR_OPERATING_EX | C10: {=+_xll.EQNXTDZ($A$1,$B10,C$2)} -> 1625.92 | D10: {=+_xll.EQNXTDZ($A$1,$B10,D$2)} -> 1912.85 | E10: {=+_xll.EQNXTDZ($A$1,$B10,E$2)} -> 1842.72 | F10: {=+_xll.EQNXTDZ($A$1,$B10,F$2)} -> 2110.44 | G10: {=+_xll.EQNXTDZ($A$1,$B10,G$2)} -> 2073.18 | H10: {=+_xll.EQNXTDZ($A$1,$B10,H$2)} -> 2083.35 | I10: {=+_xll.EQNXTDZ($A$1,$B10,I$2)} -> 2224.17 | J10: {=+_xll.EQNXTDZ($A$1,$B10,J$2)} -> 2131.58 | ... BJ10: {=+_xll.EQNXTDZ($A$1,$B10,BJ$2)} -> 0
A11: Payment To Provisions For Employees | B11: BQTR_PROV_EMP | C11: {=+_xll.EQNXTDZ($A$1,$B11,C$2)} -> 1058.75 | D11: {=+_xll.EQNXTDZ($A$1,$B11,D$2)} -> 1107.84 | E11: {=+_xll.EQNXTDZ($A$1,$B11,E$2)} -> 1039.75 | F11: {=+_xll.EQNXTDZ($A$1,$B11,F$2)} -> 1239.54 | G11: {=+_xll.EQNXTDZ($A$1,$B11,G$2)} -> 1208.17 | H11: {=+_xll.EQNXTDZ($A$1,$B11,H$2)} -> 1216.94 | I11: {=+_xll.EQNXTDZ($A$1,$B11,I$2)} -> 1305.74 | J11: {=+_xll.EQNXTDZ($A$1,$B11,J$2)} -> 1184.24 | ... BJ11: {=+_xll.EQNXTDZ($A$1,$B11,BJ$2)} -> 0
A12: Depreciation | B12: BQTR_DEPRECIATION | C12: {=+_xll.EQNXTDZ($A$1,$B12,C$2)} -> 0 | D12: {=+_xll.EQNXTDZ($A$1,$B12,D$2)} -> 0 | E12: {=+_xll.EQNXTDZ($A$1,$B12,E$2)} -> 0 | F12: {=+_xll.EQNXTDZ($A$1,$B12,F$2)} -> 0 | G12: {=+_xll.EQNXTDZ($A$1,$B12,G$2)} -> 0 | H12: {=+_xll.EQNXTDZ($A$1,$B12,H$2)} -> 0 | I12: {=+_xll.EQNXTDZ($A$1,$B12,I$2)} -> 0 | J12: {=+_xll.EQNXTDZ($A$1,$B12,J$2)} -> 0 | ... BJ12: {=+_xll.EQNXTDZ($A$1,$B12,BJ$2)} -> 0
A13: Total Expenditure | B13: BQTR_EXPENDITURE | C13: {=+_xll.EQNXTDZ($A$1,$B13,C$2)} -> 1625.92 | D13: {=+_xll.EQNXTDZ($A$1,$B13,D$2)} -> 1912.85 | E13: {=+_xll.EQNXTDZ($A$1,$B13,E$2)} -> 1842.72 | F13: {=+_xll.EQNXTDZ($A$1,$B13,F$2)} -> 2110.44 | G13: {=+_xll.EQNXTDZ($A$1,$B13,G$2)} -> 2073.18 | H13: {=+_xll.EQNXTDZ($A$1,$B13,H$2)} -> 2083.35 | I13: {=+_xll.EQNXTDZ($A$1,$B13,I$2)} -> 2224.17 | J13: {=+_xll.EQNXTDZ($A$1,$B13,J$2)} -> 2131.58 | ... BJ13: {=+_xll.EQNXTDZ($A$1,$B13,BJ$2)} -> 0
A14: Operating Profit before Prov.& Cont. | B14: BQTR_OPERATING_PROFIT | C14: {=+_xll.EQNXTDZ($A$1,$B14,C$2)} -> 2003.57 | D14: {=+_xll.EQNXTDZ($A$1,$B14,D$2)} -> 1944.1 | E14: {=+_xll.EQNXTDZ($A$1,$B14,E$2)} -> 1552.44 | F14: {=+_xll.EQNXTDZ($A$1,$B14,F$2)} -> 1646.55 | G14: {=+_xll.EQNXTDZ($A$1,$B14,G$2)} -> 1818.87 | H14: {=+_xll.EQNXTDZ($A$1,$B14,H$2)} -> 2140.77 | I14: {=+_xll.EQNXTDZ($A$1,$B14,I$2)} -> 1981.33 | J14: {=+_xll.EQNXTDZ($A$1,$B14,J$2)} -> 2972.92 | ... BJ14: {=+_xll.EQNXTDZ($A$1,$B14,BJ$2)} -> 0
A15: Exceptional Items | B15: BQTR_EXCEPTION_ITEMS | C15: {=+_xll.EQNXTDZ($A$1,$B15,C$2)} -> 0 | D15: {=+_xll.EQNXTDZ($A$1,$B15,D$2)} -> 0 | E15: {=+_xll.EQNXTDZ($A$1,$B15,E$2)} -> 0 | F15: {=+_xll.EQNXTDZ($A$1,$B15,F$2)} -> 0 | G15: {=+_xll.EQNXTDZ($A$1,$B15,G$2)} -> 0 | H15: {=+_xll.EQNXTDZ($A$1,$B15,H$2)} -> 0 | I15: {=+_xll.EQNXTDZ($A$1,$B15,I$2)} -> 0 | J15: {=+_xll.EQNXTDZ($A$1,$B15,J$2)} -> 0 | ... BJ15: {=+_xll.EQNXTDZ($A$1,$B15,BJ$2)} -> 0
A16: Foreign Exchange Gain / Loss | B16: BQTR_EXC_FOREIGN_EXCH_GAIN | C16: {=+_xll.EQNXTDZ($A$1,$B16,C$2)} -> 0 | D16: {=+_xll.EQNXTDZ($A$1,$B16,D$2)} -> 0 | E16: {=+_xll.EQNXTDZ($A$1,$B16,E$2)} -> 0 | F16: {=+_xll.EQNXTDZ($A$1,$B16,F$2)} -> 0 | G16: {=+_xll.EQNXTDZ($A$1,$B16,G$2)} -> 0 | H16: {=+_xll.EQNXTDZ($A$1,$B16,H$2)} -> 0 | I16: {=+_xll.EQNXTDZ($A$1,$B16,I$2)} -> 0 | J16: {=+_xll.EQNXTDZ($A$1,$B16,J$2)} -> 0 | ... BJ16: {=+_xll.EQNXTDZ($A$1,$B16,BJ$2)} -> 0
... A48: NIM % | B48: BQTR_NIM | C48: {=+_xll.EQNXTDZ($A$1,$B48,C$2)} -> 2.21 | D48: {=+_xll.EQNXTDZ($A$1,$B48,D$2)} -> 2.38 | E48: {=+_xll.EQNXTDZ($A$1,$B48,E$2)} -> 2.29 | F48: {=+_xll.EQNXTDZ($A$1,$B48,F$2)} -> 2.34 | G48: {=+_xll.EQNXTDZ($A$1,$B48,G$2)} -> 2.29 | H48: {=+_xll.EQNXTDZ($A$1,$B48,H$2)} -> 2.35 | I48: {=+_xll.EQNXTDZ($A$1,$B48,I$2)} -> 2.34 | J48: {=+_xll.EQNXTDZ($A$1,$B48,J$2)} -> 2.39 | ... BJ48: {=+_xll.EQNXTDZ($A$1,$B48,BJ$2)} -> 0
C51: =C5 -> 201506 | D51: =D5 -> 201509 | E51: =E5 -> 201512 | F51: =F5 -> 201603 | G51: =G5 -> 201606 | H51: =H5 -> 201609 | I51: =I5 -> 201612 | J51: =J5 -> 201703 | ... BJ51: =BJ5 -> 0
A52: Field Description | B52: Field Name
A53: Year End | B53: BQTRB_DATE_END | C53: {=+_xll.EQNXTDZ($A$1,$B53,C$51)} -> 201506 | D53: {=+_xll.EQNXTDZ($A$1,$B53,D$51)} -> 201509 | E53: {=+_xll.EQNXTDZ($A$1,$B53,E$51)} -> 201512 | F53: {=+_xll.EQNXTDZ($A$1,$B53,F$51)} -> 201603 | G53: {=+_xll.EQNXTDZ($A$1,$B53,G$51)} -> 201606 | H53: {=+_xll.EQNXTDZ($A$1,$B53,H$51)} -> 201609 | I53: {=+_xll.EQNXTDZ($A$1,$B53,I$51)} -> 201612 | J53: {=+_xll.EQNXTDZ($A$1,$B53,J$51)} -> 201703 | ... BJ53: {=+_xll.EQNXTDZ($A$1,$B53,BJ$51)} -> 0
A54: Share Capital | B54: BQTRB_SHARE_CAPITAL | C54: {=+_xll.EQNXTDZ($A$1,$B54,C$51)} -> 515.2 | D54: {=+_xll.EQNXTDZ($A$1,$B54,D$51)} -> 542.99 | E54: {=+_xll.EQNXTDZ($A$1,$B54,E$51)} -> 542.99 | F54: {=+_xll.EQNXTDZ($A$1,$B54,F$51)} -> 542.99 | G54: {=+_xll.EQNXTDZ($A$1,$B54,G$51)} -> 542.99 | H54: {=+_xll.EQNXTDZ($A$1,$B54,H$51)} -> 542.99 | I54: {=+_xll.EQNXTDZ($A$1,$B54,I$51)} -> 542.99 | J54: {=+_xll.EQNXTDZ($A$1,$B54,J$51)} -> 597.29 | ... BJ54: {=+_xll.EQNXTDZ($A$1,$B54,BJ$51)} -> 0
A55: Share Warrants & outstandings | B55: BQTRB_SHAREWARRANTS | C55: {=+_xll.EQNXTDZ($A$1,$B55,C$51)} -> 0 | D55: {=+_xll.EQNXTDZ($A$1,$B55,D$51)} -> 0 | E55: {=+_xll.EQNXTDZ($A$1,$B55,E$51)} -> 0 | F55: {=+_xll.EQNXTDZ($A$1,$B55,F$51)} -> 0 | G55: {=+_xll.EQNXTDZ($A$1,$B55,G$51)} -> 0 | H55: {=+_xll.EQNXTDZ($A$1,$B55,H$51)} -> 0 | I55: {=+_xll.EQNXTDZ($A$1,$B55,I$51)} -> 0 | J55: {=+_xll.EQNXTDZ($A$1,$B55,J$51)} -> 0 | ... BJ55: {=+_xll.EQNXTDZ($A$1,$B55,BJ$51)} -> 0
A56: Reserves and Surplus | B56: BQTRB_RESERVE | C56: {=+_xll.EQNXTDZ($A$1,$B56,C$51)} -> 33377.59 | D56: {=+_xll.EQNXTDZ($A$1,$B56,D$51)} -> 34937.14 | E56: {=+_xll.EQNXTDZ($A$1,$B56,E$51)} -> 34989.23 | F56: {=+_xll.EQNXTDZ($A$1,$B56,F$51)} -> 31060.21 | G56: {=+_xll.EQNXTDZ($A$1,$B56,G$51)} -> 31265.61 | H56: {=+_xll.EQNXTDZ($A$1,$B56,H$51)} -> 31573.82 | I56: {=+_xll.EQNXTDZ($A$1,$B56,I$51)} -> 31885.71 | J56: {=+_xll.EQNXTDZ($A$1,$B56,J$51)} -> 33088.25 | ... BJ56: {=+_xll.EQNXTDZ($A$1,$B56,BJ$51)} -> 0
A57: Minority Interest | B57: BQTRB_MINORITY_INTEREST_BS | C57: {=+_xll.EQNXTDZ($A$1,$B57,C$51)} -> 0 | D57: {=+_xll.EQNXTDZ($A$1,$B57,D$51)} -> 0 | E57: {=+_xll.EQNXTDZ($A$1,$B57,E$51)} -> 0 | F57: {=+_xll.EQNXTDZ($A$1,$B57,F$51)} -> 0 | G57: {=+_xll.EQNXTDZ($A$1,$B57,G$51)} -> 0 | H57: {=+_xll.EQNXTDZ($A$1,$B57,H$51)} -> 0 | I57: {=+_xll.EQNXTDZ($A$1,$B57,I$51)} -> 0 | J57: {=+_xll.EQNXTDZ($A$1,$B57,J$51)} -> 0 | ... BJ57: {=+_xll.EQNXTDZ($A$1,$B57,BJ$51)} -> 0
A58: Deposits | B58: BQTRB_DEPOSITS | C58: {=+_xll.EQNXTDZ($A$1,$B58,C$51)} -> 471876.73 | D58: {=+_xll.EQNXTDZ($A$1,$B58,D$51)} -> 485205.52 | E58: {=+_xll.EQNXTDZ($A$1,$B58,E$51)} -> 490598.87 | F58: {=+_xll.EQNXTDZ($A$1,$B58,F$51)} -> 479791.56 | G58: {=+_xll.EQNXTDZ($A$1,$B58,G$51)} -> 465314.16 | H58: {=+_xll.EQNXTDZ($A$1,$B58,H$51)} -> 484321.25 | I58: {=+_xll.EQNXTDZ($A$1,$B58,I$51)} -> 510327.47 | J58: {=+_xll.EQNXTDZ($A$1,$B58,J$51)} -> 495275.24 | ... BJ58: {=+_xll.EQNXTDZ($A$1,$B58,BJ$51)} -> 0
A59: Savings Deposits | B59: BQTRB_SAVING_DEPOSITS | C59: {=+_xll.EQNXTDZ($A$1,$B59,C$51)} -> 92149 | D59: {=+_xll.EQNXTDZ($A$1,$B59,D$51)} -> 96745 | E59: {=+_xll.EQNXTDZ($A$1,$B59,E$51)} -> 98878 | F59: {=+_xll.EQNXTDZ($A$1,$B59,F$51)} -> 103715 | G59: {=+_xll.EQNXTDZ($A$1,$B59,G$51)} -> 107839 | H59: {=+_xll.EQNXTDZ($A$1,$B59,H$51)} -> 111075 | I59: {=+_xll.EQNXTDZ($A$1,$B59,I$51)} -> 132087 | J59: {=+_xll.EQNXTDZ($A$1,$B59,J$51)} -> 127168 | ... BJ59: {=+_xll.EQNXTDZ($A$1,$B59,BJ$51)} -> 0
A60: Term / Fixed Deposits | B60: BQTRB_TERM_FIXED_DEPOSITS | C60: {=+_xll.EQNXTDZ($A$1,$B60,C$51)} -> 362193.73 | D60: {=+_xll.EQNXTDZ($A$1,$B60,D$51)} -> 369203.52 | E60: {=+_xll.EQNXTDZ($A$1,$B60,E$51)} -> 372473.87 | F60: {=+_xll.EQNXTDZ($A$1,$B60,F$51)} -> 356249.56 | G60: {=+_xll.EQNXTDZ($A$1,$B60,G$51)} -> 337044.16 | H60: {=+_xll.EQNXTDZ($A$1,$B60,H$51)} -> 352583.25 | I60: {=+_xll.EQNXTDZ($A$1,$B60,I$51)} -> 356622.47 | J60: {=+_xll.EQNXTDZ($A$1,$B60,J$51)} -> 345526.24 | ... BJ60: {=+_xll.EQNXTDZ($A$1,$B60,BJ$51)} -> 0
A61: Current Deposits | B61: BQTRB_CURRENT_DEPOSITS | C61: {=+_xll.EQNXTDZ($A$1,$B61,C$51)} -> 17534 | D61: {=+_xll.EQNXTDZ($A$1,$B61,D$51)} -> 19257 | E61: {=+_xll.EQNXTDZ($A$1,$B61,E$51)} -> 19247 | F61: {=+_xll.EQNXTDZ($A$1,$B61,F$51)} -> 19827 | G61: {=+_xll.EQNXTDZ($A$1,$B61,G$51)} -> 20431 | H61: {=+_xll.EQNXTDZ($A$1,$B61,H$51)} -> 20663 | I61: {=+_xll.EQNXTDZ($A$1,$B61,I$51)} -> 21618 | J61: {=+_xll.EQNXTDZ($A$1,$B61,J$51)} -> 22581 | ... BJ61: {=+_xll.EQNXTDZ($A$1,$B61,BJ$51)} -> 0
A62: Other Deposits | B62: BQTRB_OTHER_DEPOSITS | C62: {=+_xll.EQNXTDZ($A$1,$B62,C$51)} -> 0 | D62: {=+_xll.EQNXTDZ($A$1,$B62,D$51)} -> 0 | E62: {=+_xll.EQNXTDZ($A$1,$B62,E$51)} -> 0 | F62: {=+_xll.EQNXTDZ($A$1,$B62,F$51)} -> 0 | G62: {=+_xll.EQNXTDZ($A$1,$B62,G$51)} -> 0 | H62: {=+_xll.EQNXTDZ($A$1,$B62,H$51)} -> 0 | I62: {=+_xll.EQNXTDZ($A$1,$B62,I$51)} -> 0 | J62: {=+_xll.EQNXTDZ($A$1,$B62,J$51)} -> 0 | ... BJ62: {=+_xll.EQNXTDZ($A$1,$B62,BJ$51)} -> 0
A63: Borrowings | B63: BQTRB_BORROWINGS | C63: {=+_xll.EQNXTDZ($A$1,$B63,C$51)} -> 23904.81 | D63: {=+_xll.EQNXTDZ($A$1,$B63,D$51)} -> 24164.87 | E63: {=+_xll.EQNXTDZ($A$1,$B63,E$51)} -> 25359.96 | F63: {=+_xll.EQNXTDZ($A$1,$B63,F$51)} -> 26873.32 | G63: {=+_xll.EQNXTDZ($A$1,$B63,G$51)} -> 28544.86 | H63: {=+_xll.EQNXTDZ($A$1,$B63,H$51)} -> 25496.22 | I63: {=+_xll.EQNXTDZ($A$1,$B63,I$51)} -> 31311.61 | J63: {=+_xll.EQNXTDZ($A$1,$B63,J$51)} -> 39503.56 | ... BJ63: {=+_xll.EQNXTDZ($A$1,$B63,BJ$51)} -> 0
A64: Other Liabilities & Provisions | B64: BQTRB_OTHER_LIABILITIES | C64: {=+_xll.EQNXTDZ($A$1,$B64,C$51)} -> 14994.32 | D64: {=+_xll.EQNXTDZ($A$1,$B64,D$51)} -> 13997.93 | E64: {=+_xll.EQNXTDZ($A$1,$B64,E$51)} -> 15194.92 | F64: {=+_xll.EQNXTDZ($A$1,$B64,F$51)} -> 14692.7 | G64: {=+_xll.EQNXTDZ($A$1,$B64,G$51)} -> 14099.59 | H64: {=+_xll.EQNXTDZ($A$1,$B64,H$51)} -> 20198.41 | I64: {=+_xll.EQNXTDZ($A$1,$B64,I$51)} -> 16948.17 | J64: {=+_xll.EQNXTDZ($A$1,$B64,J$51)} -> 15055.1 | ... BJ64: {=+_xll.EQNXTDZ($A$1,$B64,BJ$51)} -> 0
... A83: Book Value | B83: BQTRB_BOOKVALUE | C83: {=+_xll.EQNXTDZ($A$1,$B83,C$51)} -> 0 | D83: {=+_xll.EQNXTDZ($A$1,$B83,D$51)} -> 0 | E83: {=+_xll.EQNXTDZ($A$1,$B83,E$51)} -> 0 | F83: {=+_xll.EQNXTDZ($A$1,$B83,F$51)} -> 0 | G83: {=+_xll.EQNXTDZ($A$1,$B83,G$51)} -> 0 | H83: {=+_xll.EQNXTDZ($A$1,$B83,H$51)} -> 0 | I83: {=+_xll.EQNXTDZ($A$1,$B83,I$51)} -> 0 | J83: {=+_xll.EQNXTDZ($A$1,$B83,J$51)} -> 0 | ... BJ83: {=+_xll.EQNXTDZ($A$1,$B83,BJ$51)} -> 0

Sheet Annual Raw
A1: 132483 | C1: 200103 | D1: 200203 | E1: 200303 | F1: 200403 | G1: 200503 | H1: 200603 | I1: 200703 | J1: 200803 | K1: 200903 | L1: 201003 | M1: 201103 | N1: 201203 | O1: 201303 | P1: 201403 | Q1: 201503 | R1: 201603 | S1: 201703 | T1: 201803 | U1: 201903 | V1: 202003 | W1: 202103 | X1: 202203 | Y1: 202303 | Z1: 202403 | AA1: 202503 | AB1: 202603 | AC1: 202703 | AD1: 202803 | AE1: 202903 | AF1: 203003
A3: Company Name | B3: CD_COMPNAME | C3: {=_xll.EQNXTDZ($A$1,$B3,C$2)} -> Canara Bank
A4: Field Description | B4: Field Name
A5: No of Months | B5: BPL_NO_MONTHS | C5: {=_xll.EQNXTDZ($A$1,$B5,C$1)} -> 12 | D5: {=_xll.EQNXTDZ($A$1,$B5,D$1)} -> 12 | E5: {=_xll.EQNXTDZ($A$1,$B5,E$1)} -> 12 | F5: {=_xll.EQNXTDZ($A$1,$B5,F$1)} -> 12 | G5: {=_xll.EQNXTDZ($A$1,$B5,G$1)} -> 12 | H5: {=_xll.EQNXTDZ($A$1,$B5,H$1)} -> 12 | I5: {=_xll.EQNXTDZ($A$1,$B5,I$1)} -> 12 | J5: {=_xll.EQNXTDZ($A$1,$B5,J$1)} -> 12 | ... AF5: {=_xll.EQNXTDZ($A$1,$B5,AF$1)} -> 0
A6: Year end date | B6: BPL_YEAR_ENDDATE | C6: {=_xll.EQNXTDZ($A$1,$B6,C$1)} -> 36981 | D6: {=_xll.EQNXTDZ($A$1,$B6,D$1)} -> 37346 | E6: {=_xll.EQNXTDZ($A$1,$B6,E$1)} -> 37711 | F6: {=_xll.EQNXTDZ($A$1,$B6,F$1)} -> 38077 | G6: {=_xll.EQNXTDZ($A$1,$B6,G$1)} -> 38442 | H6: {=_xll.EQNXTDZ($A$1,$B6,H$1)} -> 38807 | I6: {=_xll.EQNXTDZ($A$1,$B6,I$1)} -> 39172 | J6: {=_xll.EQNXTDZ($A$1,$B6,J$1)} -> 39538 | ... AF6: {=_xll.EQNXTDZ($A$1,$B6,AF$1)} -> 0
A7: Interest Earned | B7: BPL_INTEREST_EARNED | C7: {=_xll.EQNXTDZ($A$1,$B7,C$1)} -> 5618.2669 | D7: {=_xll.EQNXTDZ($A$1,$B7,D$1)} -> 6370.5611 | E7: {=_xll.EQNXTDZ($A$1,$B7,E$1)} -> 6657.7229 | F7: {=_xll.EQNXTDZ($A$1,$B7,F$1)} -> 7006.9207 | G7: {=_xll.EQNXTDZ($A$1,$B7,G$1)} -> 7571.9688 | H7: {=_xll.EQNXTDZ($A$1,$B7,H$1)} -> 8711.5123 | I7: {=_xll.EQNXTDZ($A$1,$B7,I$1)} -> 11364.556 | J7: {=_xll.EQNXTDZ($A$1,$B7,J$1)} -> 14200.737 | ... AF7: {=_xll.EQNXTDZ($A$1,$B7,AF$1)} -> 0
A8: Other Income | B8: BPL_OTHER_INCOME | C8: {=_xll.EQNXTDZ($A$1,$B8,C$1)} -> 917.787 | D8: {=_xll.EQNXTDZ($A$1,$B8,D$1)} -> 1428.5343 | E8: {=_xll.EQNXTDZ($A$1,$B8,E$1)} -> 1512.1313 | F8: {=_xll.EQNXTDZ($A$1,$B8,F$1)} -> 2072.9132 | G8: {=_xll.EQNXTDZ($A$1,$B8,G$1)} -> 1543.8273 | H8: {=_xll.EQNXTDZ($A$1,$B8,H$1)} -> 1377.5149 | I8: {=_xll.EQNXTDZ($A$1,$B8,I$1)} -> 1450.9497 | J8: {=_xll.EQNXTDZ($A$1,$B8,J$1)} -> 2212.8724 | ... AF8: {=_xll.EQNXTDZ($A$1,$B8,AF$1)} -> 0
A9: Total Income | B9: BPL_TOTAL_INCOME | C9: {=_xll.EQNXTDZ($A$1,$B9,C$1)} -> 6536.0539 | D9: {=_xll.EQNXTDZ($A$1,$B9,D$1)} -> 7799.0954 | E9: {=_xll.EQNXTDZ($A$1,$B9,E$1)} -> 8169.8542 | F9: {=_xll.EQNXTDZ($A$1,$B9,F$1)} -> 9079.8339 | G9: {=_xll.EQNXTDZ($A$1,$B9,G$1)} -> 9115.7961 | H9: {=_xll.EQNXTDZ($A$1,$B9,H$1)} -> 10089.027 | I9: {=_xll.EQNXTDZ($A$1,$B9,I$1)} -> 12815.506 | J9: {=_xll.EQNXTDZ($A$1,$B9,J$1)} -> 16413.609 | ... AF9: {=_xll.EQNXTDZ($A$1,$B9,AF$1)} -> 0
A10: Interest Expended | B10: BPL_INTEREST | C10: {=_xll.EQNXTDZ($A$1,$B10,C$1)} -> 3735.2481 | D10: {=_xll.EQNXTDZ($A$1,$B10,D$1)} -> 4550.2484 | E10: {=_xll.EQNXTDZ($A$1,$B10,E$1)} -> 4424.7728 | F10: {=_xll.EQNXTDZ($A$1,$B10,F$1)} -> 4324.5655 | G10: {=_xll.EQNXTDZ($A$1,$B10,G$1)} -> 4421.4993 | H10: {=_xll.EQNXTDZ($A$1,$B10,H$1)} -> 5130.0069 | I10: {=_xll.EQNXTDZ($A$1,$B10,I$1)} -> 7337.7305 | J10: {=_xll.EQNXTDZ($A$1,$B10,J$1)} -> 10662.944 | ... AF10: {=_xll.EQNXTDZ($A$1,$B10,AF$1)} -> 0
A11: Operating Expenses | B11: BPL_OPERATING_EXPENSES | C11: {=_xll.EQNXTDZ($A$1,$B11,C$1)} -> 1669.5784 | D11: {=_xll.EQNXTDZ($A$1,$B11,D$1)} -> 1592.6069 | E11: {=_xll.EQNXTDZ($A$1,$B11,E$1)} -> 1747.7057 | F11: {=_xll.EQNXTDZ($A$1,$B11,F$1)} -> 1896.5491 | G11: {=_xll.EQNXTDZ($A$1,$B11,G$1)} -> 2108.9716 | H11: {=_xll.EQNXTDZ($A$1,$B11,H$1)} -> 2347.1354 | I11: {=_xll.EQNXTDZ($A$1,$B11,I$1)} -> 2565.3054 | J11: {=_xll.EQNXTDZ($A$1,$B11,J$1)} -> 2791.2913 | ... AF11: {=_xll.EQNXTDZ($A$1,$B11,AF$1)} -> 0
A12: Payments to and provisions for employees | B12: BPL_EMPLOYEES | C12: {=_xll.EQNXTDZ($A$1,$B12,C$1)} -> 1253.073 | D12: {=_xll.EQNXTDZ($A$1,$B12,D$1)} -> 1122.5201 | E12: {=_xll.EQNXTDZ($A$1,$B12,E$1)} -> 1162.199 | F12: {=_xll.EQNXTDZ($A$1,$B12,F$1)} -> 1273.2058 | G12: {=_xll.EQNXTDZ($A$1,$B12,G$1)} -> 1380.1499 | H12: {=_xll.EQNXTDZ($A$1,$B12,H$1)} -> 1515.3032 | I12: {=_xll.EQNXTDZ($A$1,$B12,I$1)} -> 1609.2919 | J12: {=_xll.EQNXTDZ($A$1,$B12,J$1)} -> 1661.2807 | ... AF12: {=_xll.EQNXTDZ($A$1,$B12,AF$1)} -> 0
A13: Advertisement & Sales Promotion | B13: BPL_ADVERTISING | C13: {=_xll.EQNXTDZ($A$1,$B13,C$1)} -> 3.3333 | D13: {=_xll.EQNXTDZ($A$1,$B13,D$1)} -> 5.9777 | E13: {=_xll.EQNXTDZ($A$1,$B13,E$1)} -> 9.6667 | F13: {=_xll.EQNXTDZ($A$1,$B13,F$1)} -> 15.8346 | G13: {=_xll.EQNXTDZ($A$1,$B13,G$1)} -> 14.3061 | H13: {=_xll.EQNXTDZ($A$1,$B13,H$1)} -> 21.6085 | I13: {=_xll.EQNXTDZ($A$1,$B13,I$1)} -> 39.2783 | J13: {=_xll.EQNXTDZ($A$1,$B13,J$1)} -> 45.6521 | ... AF13: {=_xll.EQNXTDZ($A$1,$B13,AF$1)} -> 0
A14: Rent, Taxes and lighting | B14: BPL_RENT_RATES_TAXES | C14: {=_xll.EQNXTDZ($A$1,$B14,C$1)} -> 133.7397 | D14: {=_xll.EQNXTDZ($A$1,$B14,D$1)} -> 144.3182 | E14: {=_xll.EQNXTDZ($A$1,$B14,E$1)} -> 162.8883 | F14: {=_xll.EQNXTDZ($A$1,$B14,F$1)} -> 175.2801 | G14: {=_xll.EQNXTDZ($A$1,$B14,G$1)} -> 205.462 | H14: {=_xll.EQNXTDZ($A$1,$B14,H$1)} -> 206.6958 | I14: {=_xll.EQNXTDZ($A$1,$B14,I$1)} -> 232.902 | J14: {=_xll.EQNXTDZ($A$1,$B14,J$1)} -> 270.1871 | ... AF14: {=_xll.EQNXTDZ($A$1,$B14,AF$1)} -> 0
A15: Depreciation on Banks property | B15: BPL_DEPRECIATION | C15: {=_xll.EQNXTDZ($A$1,$B15,C$1)} -> 65.9137 | D15: {=_xll.EQNXTDZ($A$1,$B15,D$1)} -> 92.6775 | E15: {=_xll.EQNXTDZ($A$1,$B15,E$1)} -> 108.6539 | F15: {=_xll.EQNXTDZ($A$1,$B15,F$1)} -> 113.7141 | G15: {=_xll.EQNXTDZ($A$1,$B15,G$1)} -> 132.9457 | H15: {=_xll.EQNXTDZ($A$1,$B15,H$1)} -> 145.0284 | I15: {=_xll.EQNXTDZ($A$1,$B15,I$1)} -> 148.177 | J15: {=_xll.EQNXTDZ($A$1,$B15,J$1)} -> 169.9684 | ... AF15: {=_xll.EQNXTDZ($A$1,$B15,AF$1)} -> 0
A16: Depreciation on leased assets | B16: BPL_DEPRECIATION_LEASED_ASSETS | C16: {=_xll.EQNXTDZ($A$1,$B16,C$1)} -> 0 | D16: {=_xll.EQNXTDZ($A$1,$B16,D$1)} -> 0 | E16: {=_xll.EQNXTDZ($A$1,$B16,E$1)} -> 0 | F16: {=_xll.EQNXTDZ($A$1,$B16,F$1)} -> 0 | G16: {=_xll.EQNXTDZ($A$1,$B16,G$1)} -> 0 | H16: {=_xll.EQNXTDZ($A$1,$B16,H$1)} -> 0 | I16: {=_xll.EQNXTDZ($A$1,$B16,I$1)} -> 0 | J16: {=_xll.EQNXTDZ($A$1,$B16,J$1)} -> 0 | ... AF16: {=_xll.EQNXTDZ($A$1,$B16,AF$1)} -> 0
... A35: Consolidated PAT | B35: BPL_CONSOLPAT | C35: {=_xll.EQNXTDZ($A$1,$B35,C$1)} -> 285.1 | D35: {=_xll.EQNXTDZ($A$1,$B35,D$1)} -> 741.4 | E35: {=_xll.EQNXTDZ($A$1,$B35,E$1)} -> 1018.8919 | F35: {=_xll.EQNXTDZ($A$1,$B35,F$1)} -> 1338.0056 | G35: {=_xll.EQNXTDZ($A$1,$B35,G$1)} -> 1109.5045 | H35: {=_xll.EQNXTDZ($A$1,$B35,H$1)} -> 1343.22 | I35: {=_xll.EQNXTDZ($A$1,$B35,I$1)} -> 1420.81 | J35: {=_xll.EQNXTDZ($A$1,$B35,J$1)} -> 1565.0067 | ... AF35: {=_xll.EQNXTDZ($A$1,$B35,AF$1)} -> 0
A37: Field Description | B37: Field Name
A38: Equity Paid Up | B38: FH_EQUITY_PAIDUP | C38: {=_xll.EQNXTDZ($A$1,$B38,C$1)} -> 577.8681 | D38: {=_xll.EQNXTDZ($A$1,$B38,D$1)} -> 577.8681 | E38: {=_xll.EQNXTDZ($A$1,$B38,E$1)} -> 410 | F38: {=_xll.EQNXTDZ($A$1,$B38,F$1)} -> 410 | G38: {=_xll.EQNXTDZ($A$1,$B38,G$1)} -> 410 | H38: {=_xll.EQNXTDZ($A$1,$B38,H$1)} -> 410 | I38: {=_xll.EQNXTDZ($A$1,$B38,I$1)} -> 410 | J38: {=_xll.EQNXTDZ($A$1,$B38,J$1)} -> 410 | ... AF38: {=_xll.EQNXTDZ($A$1,$B38,AF$1)} -> 0
A39: Reserves and Surplus | B39: FH_RESERVE | C39: {=_xll.EQNXTDZ($A$1,$B39,C$1)} -> 2236.5819 | D39: {=_xll.EQNXTDZ($A$1,$B39,D$1)} -> 2893.6269 | E39: {=_xll.EQNXTDZ($A$1,$B39,E$1)} -> 3738.8283 | F39: {=_xll.EQNXTDZ($A$1,$B39,F$1)} -> 4841.643 | G39: {=_xll.EQNXTDZ($A$1,$B39,G$1)} -> 5698.9572 | H39: {=_xll.EQNXTDZ($A$1,$B39,H$1)} -> 6722.2358 | I39: {=_xll.EQNXTDZ($A$1,$B39,I$1)} -> 9943.9861 | J39: {=_xll.EQNXTDZ($A$1,$B39,J$1)} -> 10090.492 | ... AF39: {=_xll.EQNXTDZ($A$1,$B39,AF$1)} -> 0
A40: Net Worth | B40: FH_NET_WORTH | C40: {=_xll.EQNXTDZ($A$1,$B40,C$1)} -> 2681.2643 | D40: {=_xll.EQNXTDZ($A$1,$B40,D$1)} -> 3342.6643 | E40: {=_xll.EQNXTDZ($A$1,$B40,E$1)} -> 4024.1348 | F40: {=_xll.EQNXTDZ($A$1,$B40,F$1)} -> 5130.8799 | G40: {=_xll.EQNXTDZ($A$1,$B40,G$1)} -> 5992.0379 | H40: {=_xll.EQNXTDZ($A$1,$B40,H$1)} -> 7018.8582 | I40: {=_xll.EQNXTDZ($A$1,$B40,I$1)} -> 8111.1138 | J40: {=_xll.EQNXTDZ($A$1,$B40,J$1)} -> 8295.6333 | ... AF40: {=_xll.EQNXTDZ($A$1,$B40,AF$1)} -> 0
A41: Total Debt | B41: FH_TOTAL_DEBTS | C41: {=_xll.EQNXTDZ($A$1,$B41,C$1)} -> 0 | D41: {=_xll.EQNXTDZ($A$1,$B41,D$1)} -> 0 | E41: {=_xll.EQNXTDZ($A$1,$B41,E$1)} -> 0 | F41: {=_xll.EQNXTDZ($A$1,$B41,F$1)} -> 0 | G41: {=_xll.EQNXTDZ($A$1,$B41,G$1)} -> 0 | H41: {=_xll.EQNXTDZ($A$1,$B41,H$1)} -> 0 | I41: {=_xll.EQNXTDZ($A$1,$B41,I$1)} -> 0 | J41: {=_xll.EQNXTDZ($A$1,$B41,J$1)} -> 0 | ... AF41: {=_xll.EQNXTDZ($A$1,$B41,AF$1)} -> 0
A42: Deposits | B42: FH_DEPOSITS | C42: {=_xll.EQNXTDZ($A$1,$B42,C$1)} -> 59069.528 | D42: {=_xll.EQNXTDZ($A$1,$B42,D$1)} -> 64030.009 | E42: {=_xll.EQNXTDZ($A$1,$B42,E$1)} -> 72094.822 | F42: {=_xll.EQNXTDZ($A$1,$B42,F$1)} -> 86344.557 | G42: {=_xll.EQNXTDZ($A$1,$B42,G$1)} -> 96795.919 | H42: {=_xll.EQNXTDZ($A$1,$B42,H$1)} -> 116803.23 | I42: {=_xll.EQNXTDZ($A$1,$B42,I$1)} -> 142381.45 | J42: {=_xll.EQNXTDZ($A$1,$B42,J$1)} -> 154072.42 | ... AF42: {=_xll.EQNXTDZ($A$1,$B42,AF$1)} -> 0
A43: Borrowings | B43: FH_BORROWINGS | C43: {=_xll.EQNXTDZ($A$1,$B43,C$1)} -> 1547.8468 | D43: {=_xll.EQNXTDZ($A$1,$B43,D$1)} -> 267.3984 | E43: {=_xll.EQNXTDZ($A$1,$B43,E$1)} -> 93.8223 | F43: {=_xll.EQNXTDZ($A$1,$B43,F$1)} -> 754.897 | G43: {=_xll.EQNXTDZ($A$1,$B43,G$1)} -> 114.1642 | H43: {=_xll.EQNXTDZ($A$1,$B43,H$1)} -> 25.824 | I43: {=_xll.EQNXTDZ($A$1,$B43,I$1)} -> 1574.3517 | J43: {=_xll.EQNXTDZ($A$1,$B43,J$1)} -> 2517.2322 | ... AF43: {=_xll.EQNXTDZ($A$1,$B43,AF$1)} -> 0
