Workbook

Sheet Template
A1: =+'Annual Raw'!C4 -> #NAME? | B1: 36951 | C1: =EOMONTH(B1,12) -> 37346 | D1: =EOMONTH(C1,12) -> 37711 | E1: =EOMONTH(D1,12) -> 38077 | F1: =EOMONTH(E1,12) -> 38442 | G1: =EOMONTH(F1,12) -> 38807 | H1: =EOMONTH(G1,12) -> 39172 | I1: =EOMONTH(H1,12) -> 39538 | J1: =EOMONTH(I1,12) -> 39903 | ... AE1: =EOMONTH(AD1,12) -> 47573 | AH1: QTR | AI1: 41061 | AJ1: 41153 | AK1: 41244 | AL1: 41334 | AM1: 41426 | AN1: 41518 | AO1: 41609 | AP1: 41699 | AQ1: 41791 | AR1: 41883 | AS1: 41974 | AT1: 42064 | AU1: 42156 | AV1: 42248 | AW1: 42339 | AX1: 42430 | AY1: 42522 | AZ1: 42614 | BA1: 42705 | BB1: 42795 | BC1: 42887 | BD1: 42979 | BE1: 43070 | BF1: 43160 | BG1: 43252 | BH1: 43344 | BI1: 43435 | BJ1: 43525 | BK1: 43617 | BL1: 43709 | BM1: 43800 | BN1: 43891 | BO1: 43983 | BP1: 44075 | BQ1: =EOMONTH(BP1,3) -> 44196 | BR1: =EOMONTH(BQ1,3) -> 44286 | BS1: =EOMONTH(BR1,3) -> 44377 | BT1: =EOMONTH(BS1,3) -> 44469 | BU1: =EOMONTH(BT1,3) -> 44561 | BV1: =EOMONTH(BU1,3) -> 44651 | BW1: =EOMONTH(BV1,3) -> 44742 | BX1: =EOMONTH(BW1,3) -> 44834 | ... DB1: =EOMONTH(DA1,3) -> 47573 | DE1: HISTORICAL ESTIMATES | DF1: 46112
A2: Presentation Data (Start)
A3: Sales
A4: Direct Export | BW4: 4.28 | BX4: 7.57 | BY4: 9.32 | BZ4: 10.37 | CA4: 9.63 | CB4: 12.59 | CC4: 14.82 | CD4: 22.42 | CE4: 16.62 | CF4: 24.53 | CG4: 25.73 | CH4: 41.85 | CI4: 30 | CJ4: 36 | CK4: 40 | CL4: =CH4+(CH4*CL11) -> 50.22 | CM4: =CI4+(CI4*CM11) -> 36 | CN4: =CJ4+(CJ4*CN11) -> 43.2 | CO4: =CK4+(CK4*CO11) -> 48 | CP4: =CL4+(CL4*CP11) -> 60.264 | CQ4: =CM4+(CM4*CQ11) -> 43.2 | CR4: =CN4+(CN4*CR11) -> 51.84 | CS4: =CO4+(CO4*CS11) -> 57.6 | ... DB4: =CX4+(CX4*DB11) -> 104.13619 | DF4: 50.22
A5: Third party and Tolling | BW5: 38.95 | BX5: 53.01 | BY5: 56.68 | BZ5: 53.47 | CA5: 39.16 | CB5: 46.43 | CC5: 48.83 | CD5: 62.54 | CE5: 36.39 | CF5: 44.79 | CG5: 36.02 | CH5: 58.59 | CI5: 45 | CJ5: 52 | CK5: 55 | CL5: =CH5+(CH5*CL12) -> 70.308 | CM5: =CI5+(CI5*CM12) -> 54 | CN5: =CJ5+(CJ5*CN12) -> 62.4 | CO5: =CK5+(CK5*CO12) -> 66 | CP5: =CL5+(CL5*CP12) -> 84.3696 | CQ5: =CM5+(CM5*CQ12) -> 64.8 | CR5: =CN5+(CN5*CR12) -> 74.88 | CS5: =CO5+(CO5*CS12) -> 79.2 | ... DB5: =CX5+(CX5*DB12) -> 145.79067 | DF5: 70.308
A6: Institutional sales | BW6: 0.95 | BX6: 2.07 | BY6: 3.11 | BZ6: 3.99 | CA6: 4.49 | CB6: 5.51 | CC6: 6.1 | CD6: 7.08 | CE6: 6.33 | CF6: 9.6 | CG6: 10.29 | CH6: 16.74 | CI6: 10 | CJ6: 14 | CK6: 15 | CL6: =CH6+(CH6*CL13) -> 21.762 | CM6: =CI6+(CI6*CM13) -> 13 | CN6: =CJ6+(CJ6*CN13) -> 18.2 | CO6: =CK6+(CK6*CO13) -> 19.5 | CP6: =CL6+(CL6*CP13) -> 28.2906 | CQ6: =CM6+(CM6*CQ13) -> 16.9 | CR6: =CN6+(CN6*CR13) -> 23.66 | CS6: =CO6+(CO6*CS13) -> 25.35 | ... DB6: =CX6+(CX6*DB13) -> 62.154448 | DF6: 21.762
A7: New age ( pet /nutra) | BW7: 3.33 | BX7: 6.19 | BY7: 8.54 | BZ7: 11.97 | CA7: 10.91 | CB7: 14.17 | CC7: 17.44 | CD7: 25.96 | CE7: 19.78 | CF7: 27.73 | CG7: 30.87 | CH7: 50.22 | CI7: 35 | CJ7: 43 | CK7: 50 | CL7: =CH7+(CH7*CL14) -> 75.33 | CM7: =CI7+(CI7*CM14) -> 52.5 | CN7: =CJ7+(CJ7*CN14) -> 64.5 | CO7: =CK7+(CK7*CO14) -> 75 | CP7: =CL7+(CL7*CP14) -> 112.995 | CQ7: =CM7+(CM7*CQ14) -> 78.75 | CR7: =CN7+(CN7*CR14) -> 96.75 | CS7: =CO7+(CO7*CS14) -> 112.5 | ... DB7: =CX7+(CX7*DB14) -> 381.35813 | DF7: 75.33
BW8: =SUM(BW4:BW7) -> 47.51 | BX8: =SUM(BX4:BX7) -> 68.84 | BY8: =SUM(BY4:BY7) -> 77.65 | BZ8: =SUM(BZ4:BZ7) -> 79.8 | CA8: =SUM(CA4:CA7) -> 64.19 | CB8: =SUM(CB4:CB7) -> 78.7 | CC8: =SUM(CC4:CC7) -> 87.19 | CD8: =SUM(CD4:CD7) -> 118 | ... DB8: =SUM(DB4:DB7) -> 693.43943 | DF8: 217.62
A10: YOY%
A11: Direct Export | CA11: =CA4/BW4-1 -> 1.25 | CB11: =CB4/BX4-1 -> 0.66314399 | CC11: =CC4/BY4-1 -> 0.59012876 | CD11: =CD4/BZ4-1 -> 1.1620058 | CE11: =CE4/CA4-1 -> 0.7258567 | CF11: =CF4/CB4-1 -> 0.94837172 | CG11: =CG4/CC4-1 -> 0.73616734 | CH11: =CH4/CD4-1 -> 0.86663693 | ... CK11: =CK4/CG4-1 -> 0.55460552 | CL11: 0.2 | CM11: 0.2 | CN11: 0.2 | CO11: 0.2 | CP11: 0.2 | CQ11: 0.2 | CR11: 0.2 | CS11: 0.2 | CT11: 0.2 | CU11: 0.2 | CV11: 0.2 | CW11: 0.2 | CX11: 0.2 | CY11: 0.2 | CZ11: 0.2 | DA11: 0.2 | DB11: 0.2 | DF11: 0.2
A12: Third party and Tolling | CA12: =CA5/BW5-1 -> 0.0053915276 | CB12: =CB5/BX5-1 -> -0.12412752 | CC12: =CC5/BY5-1 -> -0.13849682 | CD12: =CD5/BZ5-1 -> 0.16962783 | CE12: =CE5/CA5-1 -> -0.070735444 | CF12: =CF5/CB5-1 -> -0.03532199 | CG12: =CG5/CC5-1 -> -0.26233873 | CH12: =CH5/CD5-1 -> -0.063159578 | ... CK12: =CK5/CG5-1 -> 0.52692948 | CL12: 0.2 | CM12: 0.2 | CN12: 0.2 | CO12: 0.2 | CP12: 0.2 | CQ12: 0.2 | CR12: 0.2 | CS12: 0.2 | CT12: 0.2 | CU12: 0.2 | CV12: 0.2 | CW12: 0.2 | CX12: 0.2 | CY12: 0.2 | CZ12: 0.2 | DA12: 0.2 | DB12: 0.2 | DF12: 0.2
A13: Institutional sales | CA13: =CA6/BW6-1 -> 3.7263158 | CB13: =CB6/BX6-1 -> 1.6618357 | CC13: =CC6/BY6-1 -> 0.96141479 | CD13: =CD6/BZ6-1 -> 0.77443609 | CE13: =CE6/CA6-1 -> 0.40979955 | CF13: =CF6/CB6-1 -> 0.74228675 | CG13: =CG6/CC6-1 -> 0.68688525 | CH13: =CH6/CD6-1 -> 1.3644068 | ... CK13: =CK6/CG6-1 -> 0.45772595 | CL13: 0.3 | CM13: 0.3 | CN13: 0.3 | CO13: 0.3 | CP13: 0.3 | CQ13: 0.3 | CR13: 0.3 | CS13: 0.3 | CT13: 0.3 | CU13: 0.3 | CV13: 0.3 | CW13: 0.3 | CX13: 0.3 | CY13: 0.3 | CZ13: 0.3 | DA13: 0.3 | DB13: 0.3 | DF13: 0.3
A14: New age ( pet /nutra) | CA14: =CA7/BW7-1 -> 2.2762763 | CB14: =CB7/BX7-1 -> 1.2891761 | CC14: =CC7/BY7-1 -> 1.0421546 | CD14: =CD7/BZ7-1 -> 1.1687552 | CE14: =CE7/CA7-1 -> 0.81301558 | CF14: =CF7/CB7-1 -> 0.95695131 | CG14: =CG7/CC7-1 -> 0.77006881 | CH14: =CH7/CD7-1 -> 0.93451464 | ... CK14: =CK7/CG7-1 -> 0.6196955 | CL14: 0.5 | CM14: 0.5 | CN14: 0.5 | CO14: 0.5 | CP14: 0.5 | CQ14: 0.5 | CR14: 0.5 | CS14: 0.5 | CT14: 0.5 | CU14: 0.5 | CV14: 0.5 | CW14: 0.5 | CX14: 0.5 | CY14: 0.5 | CZ14: 0.5 | DA14: 0.5 | DB14: 0.5 | DF14: 0.5
A17: Presentation Data (End)
A18: Profit & Loss- Annual (Start)
A19: Gross Revenue | B19: ='Annual Raw'!C6 -> #NAME? | C19: ='Annual Raw'!D6 -> #NAME? | D19: ='Annual Raw'!E6 -> #NAME? | E19: ='Annual Raw'!F6 -> #NAME? | F19: ='Annual Raw'!G6 -> #NAME? | G19: ='Annual Raw'!H6 -> #NAME? | H19: ='Annual Raw'!I6 -> #NAME? | I19: ='Annual Raw'!J6 -> #NAME? | ... AA19: ='Annual Raw'!AB6 -> #NAME? | AB19: =+SUM(CM19:CP19) -> 838.2192 | AC19: =+SUM(CQ19:CT19) -> 1105.2606 | AD19: =+SUM(CU19:CX19) -> 1473.8292 | AE19: =+SUM(CY19:DB19) -> 1987.8161 | AI19: ='QTR Raw'!C6+'QTR Raw'!C8 -> #NAME? | AJ19: ='QTR Raw'!D6+'QTR Raw'!D8 -> #NAME? | AK19: ='QTR Raw'!E6+'QTR Raw'!E8 -> #NAME? | AL19: ='QTR Raw'!F6+'QTR Raw'!F8 -> #NAME? | AM19: ='QTR Raw'!G6+'QTR Raw'!G8 -> #NAME? | AN19: ='QTR Raw'!H6+'QTR Raw'!H8 -> #NAME? | AO19: ='QTR Raw'!I6+'QTR Raw'!I8 -> #NAME? | AP19: ='QTR Raw'!J6+'QTR Raw'!J8 -> #NAME? | ... CF19: ='QTR Raw'!AZ6+'QTR Raw'!AZ8 -> #NAME? | CG19: 102.697 | CH19: ='QTR Raw'!BB6+'QTR Raw'!BB8 -> #NAME? | CI19: ='QTR Raw'!BC6+'QTR Raw'!BC8 -> #NAME? | CJ19: ='QTR Raw'!BD6+'QTR Raw'!BD8 -> #NAME? | CK19: ='QTR Raw'!BE6+'QTR Raw'!BE8 -> #NAME? | CL19: ='QTR Raw'!BF6+'QTR Raw'!BF8 -> #NAME? | CM19: =CM8 -> 155.5 | CN19: =CN8 -> 188.3 | CO19: =CO8 -> 208.5 | CP19: =CP8 -> 285.9192 | CQ19: =CQ8 -> 203.65 | CR19: =CR8 -> 247.13 | CS19: =CS8 -> 274.65 | CT19: =CT8 -> 379.8306 | ... DB19: =DB8 -> 693.43943 | DF19: 639.124
A20: Less: Exise Duty | B20: ='Annual Raw'!C7+'Annual Raw'!C8+'Annual Raw'!C9 -> #NAME? | C20: ='Annual Raw'!D7+'Annual Raw'!D8+'Annual Raw'!D9 -> #NAME? | D20: ='Annual Raw'!E7+'Annual Raw'!E8+'Annual Raw'!E9 -> #NAME? | E20: ='Annual Raw'!F7+'Annual Raw'!F8+'Annual Raw'!F9 -> #NAME? | F20: ='Annual Raw'!G7+'Annual Raw'!G8+'Annual Raw'!G9 -> #NAME? | G20: ='Annual Raw'!H7+'Annual Raw'!H8+'Annual Raw'!H9 -> #NAME? | H20: ='Annual Raw'!I7+'Annual Raw'!I8+'Annual Raw'!I9 -> #NAME? | I20: ='Annual Raw'!J7+'Annual Raw'!J8+'Annual Raw'!J9 -> #NAME? | ... AA20: ='Annual Raw'!AB7+'Annual Raw'!AB8+'Annual Raw'!AB9 -> #NAME? | AB20: =+SUM(CM20:CP20) -> 0 | AC20: =+SUM(CQ20:CT20) -> 0 | AD20: =+SUM(CU20:CX20) -> 0 | AE20: =+SUM(CY20:DB20) -> 0 | AI20: =+'QTR Raw'!C20+'QTR Raw'!C19+'QTR Raw'!C13+'QTR Raw'!C7 -> #NAME? | AJ20: =+'QTR Raw'!D20+'QTR Raw'!D19+'QTR Raw'!D13+'QTR Raw'!D7 -> #NAME? | AK20: =+'QTR Raw'!E20+'QTR Raw'!E19+'QTR Raw'!E13+'QTR Raw'!E7 -> #NAME? | AL20: =+'QTR Raw'!F20+'QTR Raw'!F19+'QTR Raw'!F13+'QTR Raw'!F7 -> #NAME? | AM20: =+'QTR Raw'!G20+'QTR Raw'!G19+'QTR Raw'!G13+'QTR Raw'!G7 -> #NAME? | AN20: =+'QTR Raw'!H20+'QTR Raw'!H19+'QTR Raw'!H13+'QTR Raw'!H7 -> #NAME? | AO20: =+'QTR Raw'!I20+'QTR Raw'!I19+'QTR Raw'!I13+'QTR Raw'!I7 -> #NAME? | AP20: =+'QTR Raw'!J20+'QTR Raw'!J19+'QTR Raw'!J13+'QTR Raw'!J7 -> #NAME? | ... CF20: =+'QTR Raw'!AZ20+'QTR Raw'!AZ19+'QTR Raw'!AZ13+'QTR Raw'!AZ7 -> #NAME? | CG20: 0 | CH20: =+'QTR Raw'!BB20+'QTR Raw'!BB19+'QTR Raw'!BB13+'QTR Raw'!BB7 -> #NAME? | CI20: =+'QTR Raw'!BC20+'QTR Raw'!BC19+'QTR Raw'!BC13+'QTR Raw'!BC7 -> #NAME? | CJ20: =+'QTR Raw'!BD20+'QTR Raw'!BD19+'QTR Raw'!BD13+'QTR Raw'!BD7 -> #NAME? | CK20: =+'QTR Raw'!BE20+'QTR Raw'!BE19+'QTR Raw'!BE13+'QTR Raw'!BE7 -> #NAME? | CL20: =+'QTR Raw'!BF20+'QTR Raw'!BF19+'QTR Raw'!BF13+'QTR Raw'!BF7 -> #NAME? | DF20: 0
A21: Net Revenue | B21: =+B19-B20 -> #NAME? | C21: =+C19-C20 -> #NAME? | D21: =+D19-D20 -> #NAME? | E21: =+E19-E20 -> #NAME? | F21: =+F19-F20 -> #NAME? | G21: =+G19-G20 -> #NAME? | H21: =+H19-H20 -> #NAME? | I21: =+I19-I20 -> #NAME? | ... AE21: =+AE19-AE20 -> 1987.8161 | AI21: =+AI19-AI20 -> #NAME? | AJ21: =+AJ19-AJ20 -> #NAME? | AK21: =+AK19-AK20 -> #NAME? | AL21: =+AL19-AL20 -> #NAME? | AM21: =+AM19-AM20 -> #NAME? | AN21: =+AN19-AN20 -> #NAME? | AO21: =+AO19-AO20 -> #NAME? | AP21: =+AP19-AP20 -> #NAME? | ... CF21: =+CF19-CF20 -> #NAME? | CG21: 102.697 | CH21: =+CH19-CH20 -> #NAME? | CI21: =+CI19-CI20 -> #NAME? | CJ21: =+CJ19-CJ20 -> #NAME? | CK21: =+CK19-CK20 -> #NAME? | CL21: =+CL19-CL20 -> #NAME? | CM21: =+CM19-CM20 -> 155.5 | CN21: =+CN19-CN20 -> 188.3 | CO21: =+CO19-CO20 -> 208.5 | ... DB21: =+DB19-DB20 -> 693.43943 | DF21: 639.124
A22: Net Revenue YOY% | C22: =C21/B21-1 -> #NAME? | D22: =D21/C21-1 -> #NAME? | E22: =E21/D21-1 -> #NAME? | F22: =F21/E21-1 -> #NAME? | G22: =G21/F21-1 -> #NAME? | H22: =H21/G21-1 -> #NAME? | I22: =I21/H21-1 -> #NAME? | J22: =J21/I21-1 -> #NAME? | ... AE22: =AE21/AD21-1 -> 0.34874249 | AM22: =+IF(AI21<0,1-AM21/AI21,AM21/AI21-1) -> #NAME? | AN22: =+IF(AJ21<0,1-AN21/AJ21,AN21/AJ21-1) -> #NAME? | AO22: =+IF(AK21<0,1-AO21/AK21,AO21/AK21-1) -> #NAME? | AP22: =+IF(AL21<0,1-AP21/AL21,AP21/AL21-1) -> #NAME? | AQ22: =+IF(AM21<0,1-AQ21/AM21,AQ21/AM21-1) -> #NAME? | AR22: =+IF(AN21<0,1-AR21/AN21,AR21/AN21-1) -> #NAME? | AS22: =+IF(AO21<0,1-AS21/AO21,AS21/AO21-1) -> #NAME? | AT22: =+IF(AP21<0,1-AT21/AP21,AT21/AP21-1) -> #NAME? | ... CF22: =+IF(CB21<0,1-CF21/CB21,CF21/CB21-1) -> #NAME? | CG22: 0.18031675 | CH22: =+IF(CD21<0,1-CH21/CD21,CH21/CD21-1) -> #NAME? | CI22: =+IF(CE21<0,1-CI21/CE21,CI21/CE21-1) -> #NAME? | CJ22: =+IF(CF21<0,1-CJ21/CF21,CJ21/CF21-1) -> #NAME? | CK22: =+IF(CG21<0,1-CK21/CG21,CK21/CG21-1) -> #NAME? | CL22: =+IF(CH21<0,1-CL21/CH21,CL21/CH21-1) -> #NAME? | CM22: =+IF(CI21<0,1-CM21/CI21,CM21/CI21-1) -> #NAME? | CN22: =+IF(CJ21<0,1-CN21/CJ21,CN21/CJ21-1) -> #NAME? | CO22: =+IF(CK21<0,1-CO21/CK21,CO21/CK21-1) -> #NAME? | ... DB22: =+IF(CX21<0,1-DB21/CX21,DB21/CX21-1) -> 0.35882658 | DF22: 0.40832762
A23: Net Revenue QOQ% | AJ23: =+IF(AI21<0,1-AJ21/AI21,AJ21/AI21-1) -> #NAME? | AK23: =+IF(AJ21<0,1-AK21/AJ21,AK21/AJ21-1) -> #NAME? | AL23: =+IF(AK21<0,1-AL21/AK21,AL21/AK21-1) -> #NAME? | AM23: =+IF(AL21<0,1-AM21/AL21,AM21/AL21-1) -> #NAME? | AN23: =+IF(AM21<0,1-AN21/AM21,AN21/AM21-1) -> #NAME? | AO23: =+IF(AN21<0,1-AO21/AN21,AO21/AN21-1) -> #NAME? | AP23: =+IF(AO21<0,1-AP21/AO21,AP21/AO21-1) -> #NAME? | AQ23: =+IF(AP21<0,1-AQ21/AP21,AQ21/AP21-1) -> #NAME? | ... CF23: =+IF(CE21<0,1-CF21/CE21,CF21/CE21-1) -> #NAME? | CG23: -0.043379846 | CH23: =+IF(CG21<0,1-CH21/CG21,CH21/CG21-1) -> #NAME? | CI23: =+IF(CH21<0,1-CI21/CH21,CI21/CH21-1) -> #NAME? | CJ23: =+IF(CI21<0,1-CJ21/CI21,CJ21/CI21-1) -> #NAME? | CK23: =+IF(CJ21<0,1-CK21/CJ21,CK21/CJ21-1) -> #NAME? | CL23: =+IF(CK21<0,1-CL21/CK21,CL21/CK21-1) -> #NAME? | CM23: =+IF(CL21<0,1-CM21/CL21,CM21/CL21-1) -> #NAME? | CN23: =+IF(CM21<0,1-CN21/CM21,CN21/CM21-1) -> 0.21093248 | CO23: =+IF(CN21<0,1-CO21/CN21,CO21/CN21-1) -> 0.10727562 | ... DB23: =+IF(DA21<0,1-DB21/DA21,DB21/DA21-1) -> 0.40668927
A24: Increase/Decrease in Stock | B24: ='Annual Raw'!C11 -> #NAME? | C24: ='Annual Raw'!D11 -> #NAME? | D24: ='Annual Raw'!E11 -> #NAME? | E24: ='Annual Raw'!F11 -> #NAME? | F24: ='Annual Raw'!G11 -> #NAME? | G24: ='Annual Raw'!H11 -> #NAME? | H24: ='Annual Raw'!I11 -> #NAME? | I24: ='Annual Raw'!J11 -> #NAME? | ... AA24: ='Annual Raw'!AB11 -> #NAME? | AB24: =+SUM(CM24:CP24) -> 0 | AC24: =+SUM(CQ24:CT24) -> 0 | AD24: =+SUM(CU24:CX24) -> 0 | AE24: =+SUM(CY24:DB24) -> 0 | AI24: ='QTR Raw'!C10 -> #NAME? | AJ24: ='QTR Raw'!D10 -> #NAME? | AK24: ='QTR Raw'!E10 -> #NAME? | AL24: ='QTR Raw'!F10 -> #NAME? | AM24: ='QTR Raw'!G10 -> #NAME? | AN24: ='QTR Raw'!H10 -> #NAME? | AO24: ='QTR Raw'!I10 -> #NAME? | AP24: ='QTR Raw'!J10 -> #NAME? | ... CF24: ='QTR Raw'!AZ10 -> #NAME? | CG24: -0.261 | CH24: ='QTR Raw'!BB10 -> #NAME? | CI24: ='QTR Raw'!BC10 -> #NAME? | CJ24: ='QTR Raw'!BD10 -> #NAME? | CK24: ='QTR Raw'!BE10 -> #NAME? | CL24: ='QTR Raw'!BF10 -> #NAME? | DF24: -31.692
A25: Purchase of Finished Goods | B25: 0 | C25: 0 | D25: 0 | E25: 0 | F25: 0 | G25: 0 | H25: 0 | I25: 0 | J25: 0 | K25: 0 | L25: 0 | M25: 0 | N25: 0 | O25: 0 | P25: 0 | Q25: 0 | R25: 0 | S25: 0 | T25: 0 | U25: 0 | V25: 0 | W25: 0 | X25: 0 | Y25: 0 | Z25: 0 | AA25: 0 | AB25: =+SUM(CM25:CP25) -> 0 | AC25: =+SUM(CQ25:CT25) -> 0 | AD25: =+SUM(CU25:CX25) -> 0 | AE25: =+SUM(CY25:DB25) -> 0 | AI25: ='QTR Raw'!C12 -> #NAME? | AJ25: ='QTR Raw'!D12 -> #NAME? | AK25: ='QTR Raw'!E12 -> #NAME? | AL25: ='QTR Raw'!F12 -> #NAME? | AM25: ='QTR Raw'!G12 -> #NAME? | AN25: ='QTR Raw'!H12 -> #NAME? | AO25: ='QTR Raw'!I12 -> #NAME? | AP25: ='QTR Raw'!J12 -> #NAME? | ... CF25: ='QTR Raw'!AZ12 -> #NAME? | CG25: 0 | CH25: ='QTR Raw'!BB12 -> #NAME? | CI25: ='QTR Raw'!BC12 -> #NAME? | CJ25: ='QTR Raw'!BD12 -> #NAME? | CK25: ='QTR Raw'!BE12 -> #NAME? | CL25: ='QTR Raw'!BF12 -> #NAME? | DF25: 0
A26: Raw Material Consumed | B26: ='Annual Raw'!C12 -> #NAME? | C26: ='Annual Raw'!D12 -> #NAME? | D26: ='Annual Raw'!E12 -> #NAME? | E26: ='Annual Raw'!F12 -> #NAME? | F26: ='Annual Raw'!G12 -> #NAME? | G26: ='Annual Raw'!H12 -> #NAME? | H26: ='Annual Raw'!I12 -> #NAME? | I26: ='Annual Raw'!J12 -> #NAME? | ... AA26: ='Annual Raw'!AB12 -> #NAME? | AB26: =+SUM(CM26:CP26) -> #NAME? | AC26: =+SUM(CQ26:CT26) -> #NAME? | AD26: =+SUM(CU26:CX26) -> #NAME? | AE26: =+SUM(CY26:DB26) -> #NAME? | AI26: ='QTR Raw'!C11 -> #NAME? | AJ26: ='QTR Raw'!D11 -> #NAME? | AK26: ='QTR Raw'!E11 -> #NAME? | AL26: ='QTR Raw'!F11 -> #NAME? | AM26: ='QTR Raw'!G11 -> #NAME? | AN26: ='QTR Raw'!H11 -> #NAME? | AO26: ='QTR Raw'!I11 -> #NAME? | AP26: ='QTR Raw'!J11 -> #NAME? | ... CF26: ='QTR Raw'!AZ11 -> #NAME? | CG26: 73.179 | CH26: ='QTR Raw'!BB11 -> #NAME? | CI26: ='QTR Raw'!BC11 -> #NAME? | CJ26: ='QTR Raw'!BD11 -> #NAME? | CK26: ='QTR Raw'!BE11 -> #NAME? | CL26: ='QTR Raw'!BF11 -> #NAME? | CM26: =+CM21-CM27 -> #NAME? | CN26: =+CN21-CN27 -> #NAME? | CO26: =+CO21-CO27 -> #NAME? | CP26: =+CP21-CP27 -> #NAME? | CQ26: =+CQ21-CQ27 -> #NAME? | CR26: =+CR21-CR27 -> #NAME? | CS26: =+CS21-CS27 -> #NAME? | CT26: =+CT21-CT27 -> #NAME? | ... DB26: =+DB21-DB27 -> #NAME? | DF26: 485.838
A27: Gross Profit | B27: =B21-B24-B26-B25 -> #NAME? | C27: =C21-C24-C26-C25 -> #NAME? | D27: =D21-D24-D26-D25 -> #NAME? | E27: =E21-E24-E26-E25 -> #NAME? | F27: =F21-F24-F26-F25 -> #NAME? | G27: =G21-G24-G26-G25 -> #NAME? | H27: =H21-H24-H26-H25 -> #NAME? | I27: =I21-I24-I26-I25 -> #NAME? | ... AE27: =AE21-AE24-AE26-AE25 -> #NAME? | AI27: =AI21-AI24-AI26-AI25 -> #NAME? | AJ27: =AJ21-AJ24-AJ26-AJ25 -> #NAME? | AK27: =AK21-AK24-AK26-AK25 -> #NAME? | AL27: =AL21-AL24-AL26-AL25 -> #NAME? | AM27: =AM21-AM24-AM26-AM25 -> #NAME? | AN27: =AN21-AN24-AN26-AN25 -> #NAME? | AO27: =AO21-AO24-AO26-AO25 -> #NAME? | AP27: =AP21-AP24-AP26-AP25 -> #NAME? | ... CF27: =CF21-CF24-CF26-CF25 -> #NAME? | CG27: 29.779 | CH27: =CH21-CH24-CH26-CH25 -> #NAME? | CI27: =CI21-CI24-CI26-CI25 -> #NAME? | CJ27: =CJ21-CJ24-CJ26-CJ25 -> #NAME? | CK27: =CK21-CK24-CK26-CK25 -> #NAME? | CL27: =CL21-CL24-CL26-CL25 -> #NAME? | CM27: =+CM28*CM21 -> #NAME? | CN27: =+CN28*CN21 -> #NAME? | CO27: =+CO28*CO21 -> #NAME? | CP27: =+CP28*CP21 -> #NAME? | CQ27: =+CQ28*CQ21 -> #NAME? | CR27: =+CR28*CR21 -> #NAME? | CS27: =+CS28*CS21 -> #NAME? | CT27: =+CT28*CT21 -> #NAME? | ... DB27: =+DB28*DB21 -> #NAME? | DF27: 184.978
A28: GP% | B28: =B27/B21 -> #NAME? | C28: =C27/C21 -> #NAME? | D28: =D27/D21 -> #NAME? | E28: =E27/E21 -> #NAME? | F28: =F27/F21 -> #NAME? | G28: =G27/G21 -> #NAME? | H28: =H27/H21 -> #NAME? | I28: =I27/I21 -> #NAME? | ... AE28: =AE27/AE21 -> #NAME? | AI28: =AI27/AI21 -> #NAME? | AJ28: =AJ27/AJ21 -> #NAME? | AK28: =AK27/AK21 -> #NAME? | AL28: =AL27/AL21 -> #NAME? | AM28: =AM27/AM21 -> #NAME? | AN28: =AN27/AN21 -> #NAME? | AO28: =AO27/AO21 -> #NAME? | AP28: =AP27/AP21 -> #NAME? | ... CF28: =CF27/CF21 -> #NAME? | CG28: 0.28996952 | CH28: =CH27/CH21 -> #NAME? | CI28: =CI27/CI21 -> #NAME? | CJ28: =CJ27/CJ21 -> #NAME? | CK28: =CK27/CK21 -> #NAME? | CL28: =CL27/CL21 -> #NAME? | CM28: =AVERAGE(CI28:CL28)*0.98 -> #NAME? | CN28: =AVERAGE(CJ28:CM28)*0.98 -> #NAME? | CO28: =AVERAGE(CK28:CN28) -> #NAME? | CP28: =AVERAGE(CL28:CO28) -> #NAME? | CQ28: =AVERAGE(CM28:CP28) -> #NAME? | CR28: =AVERAGE(CN28:CQ28) -> #NAME? | CS28: =AVERAGE(CO28:CR28) -> #NAME? | CT28: =AVERAGE(CP28:CS28) -> #NAME? | CU28: =AVERAGE(CQ28:CT28) -> #NAME? | CV28: =AVERAGE(CR28:CU28) -> #NAME? | ... DB28: =AVERAGE(CX28:DA28) -> #NAME? | DF28: 0.28942427
A29: GP YOY% | C29: =+IF(B27<0,1-C27/B27,C27/B27-1) -> #NAME? | D29: =+IF(C27<0,1-D27/C27,D27/C27-1) -> #NAME? | E29: =+IF(D27<0,1-E27/D27,E27/D27-1) -> #NAME? | F29: =+IF(E27<0,1-F27/E27,F27/E27-1) -> #NAME? | G29: =+IF(F27<0,1-G27/F27,G27/F27-1) -> #NAME? | H29: =+IF(G27<0,1-H27/G27,H27/G27-1) -> #NAME? | I29: =+IF(H27<0,1-I27/H27,I27/H27-1) -> #NAME? | J29: =+IF(I27<0,1-J27/I27,J27/I27-1) -> #NAME? | ... AE29: =+IF(AD27<0,1-AE27/AD27,AE27/AD27-1) -> #NAME? | AM29: =+IF(AI27<0,1-AM27/AI27,AM27/AI27-1) -> #NAME? | AN29: =+IF(AJ27<0,1-AN27/AJ27,AN27/AJ27-1) -> #NAME? | AO29: =+IF(AK27<0,1-AO27/AK27,AO27/AK27-1) -> #NAME? | AP29: =+IF(AL27<0,1-AP27/AL27,AP27/AL27-1) -> #NAME? | AQ29: =+IF(AM27<0,1-AQ27/AM27,AQ27/AM27-1) -> #NAME? | AR29: =+IF(AN27<0,1-AR27/AN27,AR27/AN27-1) -> #NAME? | AS29: =+IF(AO27<0,1-AS27/AO27,AS27/AO27-1) -> #NAME? | AT29: =+IF(AP27<0,1-AT27/AP27,AT27/AP27-1) -> #NAME? | ... CF29: =+IF(CB27<0,1-CF27/CB27,CF27/CB27-1) -> #NAME? | CG29: 0.26649088 | CH29: =+IF(CD27<0,1-CH27/CD27,CH27/CD27-1) -> #NAME? | CI29: =+IF(CE27<0,1-CI27/CE27,CI27/CE27-1) -> #NAME? | CJ29: =+IF(CF27<0,1-CJ27/CF27,CJ27/CF27-1) -> #NAME? | CK29: =+IF(CG27<0,1-CK27/CG27,CK27/CG27-1) -> #NAME? | CL29: =+IF(CH27<0,1-CL27/CH27,CL27/CH27-1) -> #NAME? | CM29: =+CM27/CI27-1 -> #NAME? | CN29: =+CN27/CJ27-1 -> #NAME? | CO29: =+CO27/CK27-1 -> #NAME? | CP29: =+CP27/CL27-1 -> #NAME? | CQ29: =+CQ27/CM27-1 -> #NAME? | CR29: =+CR27/CN27-1 -> #NAME? | CS29: =+CS27/CO27-1 -> #NAME? | CT29: =+CT27/CP27-1 -> #NAME? | ... DB29: =+DB27/CX27-1 -> #NAME? | DF29: 0.49434424
A30: GP QOQ% | AJ30: =+IF(AI27<0,1-AJ27/AI27,AJ27/AI27-1) -> #NAME? | AK30: =+IF(AJ27<0,1-AK27/AJ27,AK27/AJ27-1) -> #NAME? | AL30: =+IF(AK27<0,1-AL27/AK27,AL27/AK27-1) -> #NAME? | AM30: =+IF(AL27<0,1-AM27/AL27,AM27/AL27-1) -> #NAME? | AN30: =+IF(AM27<0,1-AN27/AM27,AN27/AM27-1) -> #NAME? | AO30: =+IF(AN27<0,1-AO27/AN27,AO27/AN27-1) -> #NAME? | AP30: =+IF(AO27<0,1-AP27/AO27,AP27/AO27-1) -> #NAME? | AQ30: =+IF(AP27<0,1-AQ27/AP27,AQ27/AP27-1) -> #NAME? | ... CF30: =+IF(CE27<0,1-CF27/CE27,CF27/CE27-1) -> #NAME? | CG30: -0.056820701 | CH30: =+IF(CG27<0,1-CH27/CG27,CH27/CG27-1) -> #NAME? | CI30: =+IF(CH27<0,1-CI27/CH27,CI27/CH27-1) -> #NAME? | CJ30: =+IF(CI27<0,1-CJ27/CI27,CJ27/CI27-1) -> #NAME? | CK30: =+IF(CJ27<0,1-CK27/CJ27,CK27/CJ27-1) -> #NAME? | CL30: =+IF(CK27<0,1-CL27/CK27,CL27/CK27-1) -> #NAME? | CM30: =+CM27/CL27-1 -> #NAME? | CN30: =+CN27/CM27-1 -> #NAME? | CO30: =+CO27/CN27-1 -> #NAME? | CP30: =+CP27/CO27-1 -> #NAME? | CQ30: =+CQ27/CP27-1 -> #NAME? | CR30: =+CR27/CQ27-1 -> #NAME? | CS30: =+CS27/CR27-1 -> #NAME? | CT30: =+CT27/CS27-1 -> #NAME? | ... DB30: =+DB27/DA27-1 -> #NAME?
A31: Employee Cost | B31: ='Annual Raw'!C14 -> #NAME? | C31: ='Annual Raw'!D14 -> #NAME? | D31: ='Annual Raw'!E14 -> #NAME? | E31: ='Annual Raw'!F14 -> #NAME? | F31: ='Annual Raw'!G14 -> #NAME? | G31: ='Annual Raw'!H14 -> #NAME? | H31: ='Annual Raw'!I14 -> #NAME? | I31: ='Annual Raw'!J14 -> #NAME? | ... AA31: ='Annual Raw'!AB14 -> #NAME? | AB31: =+SUM(CM31:CP31) -> #NAME? | AC31: =+SUM(CQ31:CT31) -> #NAME? | AD31: =+SUM(CU31:CX31) -> #NAME? | AE31: =+SUM(CY31:DB31) -> #NAME? | AI31: ='QTR Raw'!C16 -> #NAME? | AJ31: ='QTR Raw'!D16 -> #NAME? | AK31: ='QTR Raw'!E16 -> #NAME? | AL31: ='QTR Raw'!F16 -> #NAME? | AM31: ='QTR Raw'!G16 -> #NAME? | AN31: ='QTR Raw'!H16 -> #NAME? | AO31: ='QTR Raw'!I16 -> #NAME? | AP31: ='QTR Raw'!J16 -> #NAME? | ... CF31: ='QTR Raw'!AZ16 -> #NAME? | CG31: 5.849 | CH31: ='QTR Raw'!BB16 -> #NAME? | CI31: ='QTR Raw'!BC16 -> #NAME? | CJ31: ='QTR Raw'!BD16 -> #NAME? | CK31: ='QTR Raw'!BE16 -> #NAME? | CL31: ='QTR Raw'!BF16 -> #NAME? | CM31: =CI31*107% -> #NAME? | CN31: =CJ31*107% -> #NAME? | CO31: =CK31*107% -> #NAME? | CP31: =CL31*107% -> #NAME? | CQ31: =CM31*107% -> #NAME? | CR31: =CN31*107% -> #NAME? | CS31: =CO31*107% -> #NAME? | CT31: =CP31*107% -> #NAME? | ... DB31: =CX31*107% -> #NAME? | DF31: 32.944
A32: General and Administration Expenses | B32: ='Annual Raw'!C17 -> #NAME? | C32: ='Annual Raw'!D17 -> #NAME? | D32: ='Annual Raw'!E17 -> #NAME? | E32: ='Annual Raw'!F17 -> #NAME? | F32: ='Annual Raw'!G17 -> #NAME? | G32: ='Annual Raw'!H17 -> #NAME? | H32: ='Annual Raw'!I17 -> #NAME? | I32: ='Annual Raw'!J17 -> #NAME? | ... AA32: ='Annual Raw'!AB17 -> #NAME? | AB32: =+SUM(CM32:CP32) -> 0 | AC32: =+SUM(CQ32:CT32) -> 0 | AD32: =+SUM(CU32:CX32) -> 0 | AE32: =+SUM(CY32:DB32) -> 0 | AI32: ='QTR Raw'!C17 -> #NAME? | AJ32: ='QTR Raw'!D17 -> #NAME? | AK32: ='QTR Raw'!E17 -> #NAME? | AL32: ='QTR Raw'!F17 -> #NAME? | AM32: ='QTR Raw'!G17 -> #NAME? | AN32: ='QTR Raw'!H17 -> #NAME? | AO32: ='QTR Raw'!I17 -> #NAME? | AP32: ='QTR Raw'!J17 -> #NAME? | ... CF32: ='QTR Raw'!AZ17 -> #NAME? | CG32: 0 | CH32: ='QTR Raw'!BB17 -> #NAME? | CI32: ='QTR Raw'!BC17 -> #NAME? | CJ32: ='QTR Raw'!BD17 -> #NAME? | CK32: ='QTR Raw'!BE17 -> #NAME? | CL32: ='QTR Raw'!BF17 -> #NAME? | DF32: 0
A33: Miscellaneous Expenses | B33: ='Annual Raw'!C19-'Annual Raw'!C20 -> #NAME? | C33: ='Annual Raw'!D19-'Annual Raw'!D20 -> #NAME? | D33: ='Annual Raw'!E19-'Annual Raw'!E20 -> #NAME? | E33: ='Annual Raw'!F19-'Annual Raw'!F20 -> #NAME? | F33: ='Annual Raw'!G19-'Annual Raw'!G20 -> #NAME? | G33: ='Annual Raw'!H19-'Annual Raw'!H20 -> #NAME? | H33: ='Annual Raw'!I19-'Annual Raw'!I20 -> #NAME? | I33: ='Annual Raw'!J19-'Annual Raw'!J20 -> #NAME? | ... AA33: ='Annual Raw'!AB19-'Annual Raw'!AB20 -> #NAME? | AB33: =+SUM(CM33:CP33) -> 0 | AC33: =+SUM(CQ33:CT33) -> 0 | AD33: =+SUM(CU33:CX33) -> 0 | AE33: =+SUM(CY33:DB33) -> 0 | AI33: =+'QTR Raw'!C21 -> #NAME? | AJ33: =+'QTR Raw'!D21 -> #NAME? | AK33: =+'QTR Raw'!E21 -> #NAME? | AL33: =+'QTR Raw'!F21 -> #NAME? | AM33: =+'QTR Raw'!G21 -> #NAME? | AN33: =+'QTR Raw'!H21 -> #NAME? | AO33: =+'QTR Raw'!I21 -> #NAME? | AP33: =+'QTR Raw'!J21 -> #NAME? | ... CF33: =+'QTR Raw'!AZ21 -> #NAME? | CG33: 0 | CH33: =+'QTR Raw'!BB21 -> #NAME? | CI33: =+'QTR Raw'!BC21 -> #NAME? | CJ33: =+'QTR Raw'!BD21 -> #NAME? | CK33: =+'QTR Raw'!BE21 -> #NAME? | CL33: =+'QTR Raw'!BF21 -> #NAME? | DF33: 0
A34: Other Manufacturing Expenses | B34: ='Annual Raw'!C15+'Annual Raw'!C16 -> #NAME? | C34: ='Annual Raw'!D15+'Annual Raw'!D16 -> #NAME? | D34: ='Annual Raw'!E15+'Annual Raw'!E16 -> #NAME? | E34: ='Annual Raw'!F15+'Annual Raw'!F16 -> #NAME? | F34: ='Annual Raw'!G15+'Annual Raw'!G16 -> #NAME? | G34: ='Annual Raw'!H15+'Annual Raw'!H16 -> #NAME? | H34: ='Annual Raw'!I15+'Annual Raw'!I16 -> #NAME? | I34: ='Annual Raw'!J15+'Annual Raw'!J16 -> #NAME? | ... AA34: ='Annual Raw'!AB15+'Annual Raw'!AB16 -> #NAME? | AB34: =+SUM(CM34:CP34) -> #NAME? | AC34: =+SUM(CQ34:CT34) -> #NAME? | AD34: =+SUM(CU34:CX34) -> #NAME? | AE34: =+SUM(CY34:DB34) -> #NAME? | AI34: ='QTR Raw'!C14 -> #NAME? | AJ34: ='QTR Raw'!D14 -> #NAME? | AK34: ='QTR Raw'!E14 -> #NAME? | AL34: ='QTR Raw'!F14 -> #NAME? | AM34: ='QTR Raw'!G14 -> #NAME? | AN34: ='QTR Raw'!H14 -> #NAME? | AO34: ='QTR Raw'!I14 -> #NAME? | AP34: ='QTR Raw'!J14 -> #NAME? | ... CF34: ='QTR Raw'!AZ14 -> #NAME? | CG34: 10.701 | CH34: ='QTR Raw'!BB14 -> #NAME? | CI34: ='QTR Raw'!BC14 -> #NAME? | CJ34: ='QTR Raw'!BD14 -> #NAME? | CK34: ='QTR Raw'!BE14 -> #NAME? | CL34: ='QTR Raw'!BF14 -> #NAME? | CM34: =CM37-CM31-CM32-CM33-CM35-CM36 -> #NAME? | CN34: =CN37-CN31-CN32-CN33-CN35-CN36 -> #NAME? | CO34: =CO37-CO31-CO32-CO33-CO35-CO36 -> #NAME? | CP34: =CP37-CP31-CP32-CP33-CP35-CP36 -> #NAME? | CQ34: =CQ37-CQ31-CQ32-CQ33-CQ35-CQ36 -> #NAME? | CR34: =CR37-CR31-CR32-CR33-CR35-CR36 -> #NAME? | CS34: =CS37-CS31-CS32-CS33-CS35-CS36 -> #NAME? | CT34: =CT37-CT31-CT32-CT33-CT35-CT36 -> #NAME? | ... DB34: =DB37-DB31-DB32-DB33-DB35-DB36 -> #NAME? | DF34: 57.496
A35: Power & Fuel Cost | B35: ='Annual Raw'!C13 -> #NAME? | C35: ='Annual Raw'!D13 -> #NAME? | D35: ='Annual Raw'!E13 -> #NAME? | E35: ='Annual Raw'!F13 -> #NAME? | F35: ='Annual Raw'!G13 -> #NAME? | G35: ='Annual Raw'!H13 -> #NAME? | H35: ='Annual Raw'!I13 -> #NAME? | I35: ='Annual Raw'!J13 -> #NAME? | ... AA35: ='Annual Raw'!AB13 -> #NAME? | AB35: =+SUM(CM35:CP35) -> 0 | AC35: =+SUM(CQ35:CT35) -> 0 | AD35: =+SUM(CU35:CX35) -> 0 | AE35: =+SUM(CY35:DB35) -> 0 | AI35: ='QTR Raw'!C15 -> #NAME? | AJ35: ='QTR Raw'!D15 -> #NAME? | AK35: ='QTR Raw'!E15 -> #NAME? | AL35: ='QTR Raw'!F15 -> #NAME? | AM35: ='QTR Raw'!G15 -> #NAME? | AN35: ='QTR Raw'!H15 -> #NAME? | AO35: ='QTR Raw'!I15 -> #NAME? | AP35: ='QTR Raw'!J15 -> #NAME? | ... CF35: ='QTR Raw'!AZ15 -> #NAME? | CG35: 0 | CH35: ='QTR Raw'!BB15 -> #NAME? | CI35: ='QTR Raw'!BC15 -> #NAME? | CJ35: ='QTR Raw'!BD15 -> #NAME? | CK35: ='QTR Raw'!BE15 -> #NAME? | CL35: ='QTR Raw'!BF15 -> #NAME? | DF35: 0
A36: Selling and Distribution Expenses | B36: ='Annual Raw'!C18 -> #NAME? | C36: ='Annual Raw'!D18 -> #NAME? | D36: ='Annual Raw'!E18 -> #NAME? | E36: ='Annual Raw'!F18 -> #NAME? | F36: ='Annual Raw'!G18 -> #NAME? | G36: ='Annual Raw'!H18 -> #NAME? | H36: ='Annual Raw'!I18 -> #NAME? | I36: ='Annual Raw'!J18 -> #NAME? | ... AA36: ='Annual Raw'!AB18 -> #NAME? | AB36: =+SUM(CM36:CP36) -> 0 | AC36: =+SUM(CQ36:CT36) -> 0 | AD36: =+SUM(CU36:CX36) -> 0 | AE36: =+SUM(CY36:DB36) -> 0 | AI36: ='QTR Raw'!C18 -> #NAME? | AJ36: ='QTR Raw'!D18 -> #NAME? | AK36: ='QTR Raw'!E18 -> #NAME? | AL36: ='QTR Raw'!F18 -> #NAME? | AM36: ='QTR Raw'!G18 -> #NAME? | AN36: ='QTR Raw'!H18 -> #NAME? | AO36: ='QTR Raw'!I18 -> #NAME? | AP36: ='QTR Raw'!J18 -> #NAME? | ... CF36: ='QTR Raw'!AZ18 -> #NAME? | CG36: 0 | CH36: ='QTR Raw'!BB18 -> #NAME? | CI36: ='QTR Raw'!BC18 -> #NAME? | CJ36: ='QTR Raw'!BD18 -> #NAME? | CK36: ='QTR Raw'!BE18 -> #NAME? | CL36: ='QTR Raw'!BF18 -> #NAME? | DF36: 0
A37: Total Cost | B37: =+SUM(B31:B36) -> #NAME? | C37: =+SUM(C31:C36) -> #NAME? | D37: =+SUM(D31:D36) -> #NAME? | E37: =+SUM(E31:E36) -> #NAME? | F37: =+SUM(F31:F36) -> #NAME? | G37: =+SUM(G31:G36) -> #NAME? | H37: =+SUM(H31:H36) -> #NAME? | I37: =+SUM(I31:I36) -> #NAME? | ... AE37: =+SUM(AE31:AE36) -> #NAME? | AI37: =+SUM(AI31:AI36) -> #NAME? | AJ37: =+SUM(AJ31:AJ36) -> #NAME? | AK37: =+SUM(AK31:AK36) -> #NAME? | AL37: =+SUM(AL31:AL36) -> #NAME? | AM37: =+SUM(AM31:AM36) -> #NAME? | AN37: =+SUM(AN31:AN36) -> #NAME? | AO37: =+SUM(AO31:AO36) -> #NAME? | AP37: =+SUM(AP31:AP36) -> #NAME? | ... CF37: =+SUM(CF31:CF36) -> #NAME? | CG37: 16.55 | CH37: =+SUM(CH31:CH36) -> #NAME? | CI37: =+SUM(CI31:CI36) -> #NAME? | CJ37: =+SUM(CJ31:CJ36) -> #NAME? | CK37: =+SUM(CK31:CK36) -> #NAME? | CL37: =+SUM(CL31:CL36) -> #NAME? | CM37: =CM38*CM21 -> #NAME? | CN37: =CN38*CN21 -> #NAME? | CO37: =CO38*CO21 -> #NAME? | CP37: =CP38*CP21 -> #NAME? | CQ37: =CQ38*CQ21 -> #NAME? | CR37: =CR38*CR21 -> #NAME? | CS37: =CS38*CS21 -> #NAME? | CT37: =CT38*CT21 -> #NAME? | ... DB37: =DB38*DB21 -> #NAME? | DF37: 90.44
A38: Cost % | B38: =B37/B21 -> #NAME? | C38: =C37/C21 -> #NAME? | D38: =D37/D21 -> #NAME? | E38: =E37/E21 -> #NAME? | F38: =F37/F21 -> #NAME? | G38: =G37/G21 -> #NAME? | H38: =H37/H21 -> #NAME? | I38: =I37/I21 -> #NAME? | ... AE38: =AE37/AE21 -> #NAME? | AI38: =AI37/AI21 -> #NAME? | AJ38: =AJ37/AJ21 -> #NAME? | AK38: =AK37/AK21 -> #NAME? | AL38: =AL37/AL21 -> #NAME? | AM38: =AM37/AM21 -> #NAME? | AN38: =AN37/AN21 -> #NAME? | AO38: =AO37/AO21 -> #NAME? | AP38: =AP37/AP21 -> #NAME? | ... CF38: =CF37/CF21 -> #NAME? | CG38: 0.16115369 | CH38: =CH37/CH21 -> #NAME? | CI38: =CI37/CI21 -> #NAME? | CJ38: =CJ37/CJ21 -> #NAME? | CK38: =CK37/CK21 -> #NAME? | CL38: =CL37/CL21 -> #NAME? | CM38: =AVERAGE(CI38:CL38) -> #NAME? | CN38: =AVERAGE(CJ38:CM38) -> #NAME? | CO38: =AVERAGE(CK38:CN38) -> #NAME? | CP38: =AVERAGE(CL38:CO38) -> #NAME? | CQ38: =AVERAGE(CM38:CP38) -> #NAME? | CR38: =AVERAGE(CN38:CQ38) -> #NAME? | CS38: =AVERAGE(CO38:CR38) -> #NAME? | CT38: =AVERAGE(CP38:CS38) -> #NAME? | ... DB38: =AVERAGE(CX38:DA38) -> #NAME? | DF38: 0.14150619
A39: EBITDA | B39: =B27-B37 -> #NAME? | C39: =C27-C37 -> #NAME? | D39: =D27-D37 -> #NAME? | E39: =E27-E37 -> #NAME? | F39: =F27-F37 -> #NAME? | G39: =G27-G37 -> #NAME? | H39: =H27-H37 -> #NAME? | I39: =I27-I37 -> #NAME? | ... AE39: =AE27-AE37 -> #NAME? | AI39: =AI27-AI37 -> #NAME? | AJ39: =AJ27-AJ37 -> #NAME? | AK39: =AK27-AK37 -> #NAME? | AL39: =AL27-AL37 -> #NAME? | AM39: =AM27-AM37 -> #NAME? | AN39: =AN27-AN37 -> #NAME? | AO39: =AO27-AO37 -> #NAME? | AP39: =AP27-AP37 -> #NAME? | ... CF39: =CF27-CF37 -> #NAME? | CG39: 13.229 | CH39: =CH27-CH37 -> #NAME? | CI39: =CI27-CI37 -> #NAME? | CJ39: =CJ27-CJ37 -> #NAME? | CK39: =CK27-CK37 -> #NAME? | CL39: =CL27-CL37 -> #NAME? | CM39: =CM27-CM37 -> #NAME? | CN39: =CN27-CN37 -> #NAME? | CO39: =CO27-CO37 -> #NAME? | ... DB39: =DB27-DB37 -> #NAME? | DF39: 94.538
A40: EBITDA Margins | B40: =B39/B21 -> #NAME? | C40: =C39/C21 -> #NAME? | D40: =D39/D21 -> #NAME? | E40: =E39/E21 -> #NAME? | F40: =F39/F21 -> #NAME? | G40: =G39/G21 -> #NAME? | H40: =H39/H21 -> #NAME? | I40: =I39/I21 -> #NAME? | ... AE40: =AE39/AE21 -> #NAME? | AI40: =AI39/AI21 -> #NAME? | AJ40: =AJ39/AJ21 -> #NAME? | AK40: =AK39/AK21 -> #NAME? | AL40: =AL39/AL21 -> #NAME? | AM40: =AM39/AM21 -> #NAME? | AN40: =AN39/AN21 -> #NAME? | AO40: =AO39/AO21 -> #NAME? | AP40: =AP39/AP21 -> #NAME? | ... CF40: =CF39/CF21 -> #NAME? | CG40: 0.12881584 | CH40: =CH39/CH21 -> #NAME? | CI40: =CI39/CI21 -> #NAME? | CJ40: =CJ39/CJ21 -> #NAME? | CK40: =CK39/CK21 -> #NAME? | CL40: =CL39/CL21 -> #NAME? | CM40: =CM39/CM21 -> #NAME? | CN40: =CN39/CN21 -> #NAME? | CO40: =CO39/CO21 -> #NAME? | ... DB40: =DB39/DB21 -> #NAME? | DF40: 0.14791809
A41: EBITDA YOY% | C41: =+IF(B39<0,1-C39/B39,C39/B39-1) -> #NAME? | D41: =+IF(C39<0,1-D39/C39,D39/C39-1) -> #NAME? | E41: =+IF(D39<0,1-E39/D39,E39/D39-1) -> #NAME? | F41: =+IF(E39<0,1-F39/E39,F39/E39-1) -> #NAME? | G41: =+IF(F39<0,1-G39/F39,G39/F39-1) -> #NAME? | H41: =+IF(G39<0,1-H39/G39,H39/G39-1) -> #NAME? | I41: =+IF(H39<0,1-I39/H39,I39/H39-1) -> #NAME? | J41: =+IF(I39<0,1-J39/I39,J39/I39-1) -> #NAME? | ... AE41: =+IF(AD39<0,1-AE39/AD39,AE39/AD39-1) -> #NAME? | AM41: =+IF(AI39<0,1-AM39/AI39,AM39/AI39-1) -> #NAME? | AN41: =+IF(AJ39<0,1-AN39/AJ39,AN39/AJ39-1) -> #NAME? | AO41: =+IF(AK39<0,1-AO39/AK39,AO39/AK39-1) -> #NAME? | AP41: =+IF(AL39<0,1-AP39/AL39,AP39/AL39-1) -> #NAME? | AQ41: =+IF(AM39<0,1-AQ39/AM39,AQ39/AM39-1) -> #NAME? | AR41: =+IF(AN39<0,1-AR39/AN39,AR39/AN39-1) -> #NAME? | AS41: =+IF(AO39<0,1-AS39/AO39,AS39/AO39-1) -> #NAME? | AT41: =+IF(AP39<0,1-AT39/AP39,AT39/AP39-1) -> #NAME? | ... CF41: =+IF(CB39<0,1-CF39/CB39,CF39/CB39-1) -> #NAME? | CG41: 0.25810747 | CH41: =+IF(CD39<0,1-CH39/CD39,CH39/CD39-1) -> #NAME? | CI41: =+IF(CE39<0,1-CI39/CE39,CI39/CE39-1) -> #NAME? | CJ41: =+IF(CF39<0,1-CJ39/CF39,CJ39/CF39-1) -> #NAME? | CK41: =+IF(CG39<0,1-CK39/CG39,CK39/CG39-1) -> #NAME? | CL41: =+IF(CH39<0,1-CL39/CH39,CL39/CH39-1) -> #NAME? | CM41: =+CM39/CI39-1 -> #NAME? | CN41: =+CN39/CJ39-1 -> #NAME? | CO41: =+CO39/CK39-1 -> #NAME? | CP41: =+CP39/CL39-1 -> #NAME? | CQ41: =+CQ39/CM39-1 -> #NAME? | CR41: =+CR39/CN39-1 -> #NAME? | CS41: =+CS39/CO39-1 -> #NAME? | CT41: =+CT39/CP39-1 -> #NAME? | ... DB41: =+DB39/CX39-1 -> #NAME? | DF41: 0.80214149
A42: EBITDA QOQ% | AJ42: =+IF(AI39<0,1-AJ39/AI39,AJ39/AI39-1) -> #NAME? | AK42: =+IF(AJ39<0,1-AK39/AJ39,AK39/AJ39-1) -> #NAME? | AL42: =+IF(AK39<0,1-AL39/AK39,AL39/AK39-1) -> #NAME? | AM42: =+IF(AL39<0,1-AM39/AL39,AM39/AL39-1) -> #NAME? | AN42: =+IF(AM39<0,1-AN39/AM39,AN39/AM39-1) -> #NAME? | AO42: =+IF(AN39<0,1-AO39/AN39,AO39/AN39-1) -> #NAME? | AP42: =+IF(AO39<0,1-AP39/AO39,AP39/AO39-1) -> #NAME? | AQ42: =+IF(AP39<0,1-AQ39/AP39,AQ39/AP39-1) -> #NAME? | ... CF42: =+IF(CE39<0,1-CF39/CE39,CF39/CE39-1) -> #NAME? | CG42: -0.051820528 | CH42: =+IF(CG39<0,1-CH39/CG39,CH39/CG39-1) -> #NAME? | CI42: =+IF(CH39<0,1-CI39/CH39,CI39/CH39-1) -> #NAME? | CJ42: =+IF(CI39>1,CJ39/CI39-1,1-CJ39/CI39) -> #NAME? | CK42: =+IF(CJ39>1,CK39/CJ39-1,1-CK39/CJ39) -> #NAME? | CL42: =+IF(CK39>1,CL39/CK39-1,1-CL39/CK39) -> #NAME? | CM42: =+CM39/CL39-1 -> #NAME? | CN42: =+CN39/CM39-1 -> #NAME? | CO42: =+CO39/CN39-1 -> #NAME? | CP42: =+CP39/CO39-1 -> #NAME? | CQ42: =+CQ39/CP39-1 -> #NAME? | CR42: =+CR39/CQ39-1 -> #NAME? | CS42: =+CS39/CR39-1 -> #NAME? | CT42: =+CT39/CS39-1 -> #NAME? | ... DB42: =+DB39/DA39-1 -> #NAME?
A43: Depreciation | B43: ='Annual Raw'!C27 -> #NAME? | C43: ='Annual Raw'!D27 -> #NAME? | D43: ='Annual Raw'!E27 -> #NAME? | E43: ='Annual Raw'!F27 -> #NAME? | F43: ='Annual Raw'!G27 -> #NAME? | G43: ='Annual Raw'!H27 -> #NAME? | H43: ='Annual Raw'!I27 -> #NAME? | I43: ='Annual Raw'!J27 -> #NAME? | ... AA43: ='Annual Raw'!AB27 -> #NAME? | AB43: =+SUM(CM43:CP43) -> #NAME? | AC43: =+SUM(CQ43:CT43) -> #NAME? | AD43: =+SUM(CU43:CX43) -> #NAME? | AE43: =+SUM(CY43:DB43) -> #NAME? | AI43: ='QTR Raw'!C28 -> #NAME? | AJ43: ='QTR Raw'!D28 -> #NAME? | AK43: ='QTR Raw'!E28 -> #NAME? | AL43: ='QTR Raw'!F28 -> #NAME? | AM43: ='QTR Raw'!G28 -> #NAME? | AN43: ='QTR Raw'!H28 -> #NAME? | AO43: ='QTR Raw'!I28 -> #NAME? | AP43: ='QTR Raw'!J28 -> #NAME? | ... CF43: ='QTR Raw'!AZ28 -> #NAME? | CG43: 1.089 | CH43: ='QTR Raw'!BB28 -> #NAME? | CI43: ='QTR Raw'!BC28 -> #NAME? | CJ43: ='QTR Raw'!BD28 -> #NAME? | CK43: ='QTR Raw'!BE28 -> #NAME? | CL43: ='QTR Raw'!BF28 -> #NAME? | CM43: =CM44*CL145 -> #NAME? | CN43: =CN44*CM145 -> #NAME? | CO43: =CO44*CN145 -> #NAME? | CP43: =CP44*CO145 -> #NAME? | CQ43: =CQ44*CP145 -> #NAME? | CR43: =CR44*CQ145 -> #NAME? | CS43: =CS44*CR145 -> #NAME? | CT43: =CT44*CS145 -> #NAME? | ... DB43: =DB44*DA145 -> #NAME? | DF43: 8.247
...

Sheet Sheet1
B1: Quarter | C1: Total Sales | D1: Direct Exports (Branded) | E1: Institutional Sales | F1: Third-Party & Tolling | G1: New Age (Pet/Nutra)
A2: =A1+1 -> 1 | B2: Q1 FY23 | C2: 47.5 | D2: 4.28 | E2: 0.95 | F2: 38.95 | G2: 3.33
A3: =A2+1 -> 2 | B3: Q2 FY23 | C3: 68.84 | D3: 7.57 | E3: 2.07 | F3: 53.01 | G3: 6.19 | J3: Quarter | K3: Q1 FY23 | L3: Q2 FY23 | M3: Q3 FY23 | N3: Q4 FY23 | O3: Q1 FY24 | P3: Q2 FY24 | Q3: Q3 FY24 | R3: Q4 FY24 | S3: Q1 FY25 | T3: Q2 FY25 | U3: Q3 FY25 | V3: Q4 FY25
A4: =A3+1 -> 3 | B4: Q3 FY23 | C4: 77.65 | D4: 9.32 | E4: 3.11 | F4: 56.68 | G4: 8.54 | J4: Total Sales | K4: 47.5 | L4: 68.84 | M4: 77.65 | N4: 79.8 | O4: 64.2 | P4: 78.7 | Q4: 87.2 | R4: 118 | S4: 79.12 | T4: 106.65 | U4: 102.9 | V4: 167.41
A5: =A4+1 -> 4 | B5: Q4 FY23 | C5: 79.8 | D5: 10.37 | E5: 3.99 | F5: 53.47 | G5: 11.97 | J5: Direct Exports (Branded) | K5: 4.28 | L5: 7.57 | M5: 9.32 | N5: 10.37 | O5: 9.63 | P5: 12.59 | Q5: 14.82 | R5: 22.42 | S5: 16.62 | T5: 24.53 | U5: 25.73 | V5: 41.85
A6: =A5+1 -> 5 | B6: Q1 FY24 | C6: 64.2 | D6: 9.63 | E6: 4.49 | F6: 39.16 | G6: 10.91 | J6: Institutional Sales | K6: 0.95 | L6: 2.07 | M6: 3.11 | N6: 3.99 | O6: 4.49 | P6: 5.51 | Q6: 6.1 | R6: 7.08 | S6: 6.33 | T6: 9.6 | U6: 10.29 | V6: 16.74
A7: =A6+1 -> 6 | B7: Q2 FY24 | C7: 78.7 | D7: 12.59 | E7: 5.51 | F7: 46.43 | G7: 14.17 | J7: Third-Party & Tolling | K7: 38.95 | L7: 53.01 | M7: 56.68 | N7: 53.47 | O7: 39.16 | P7: 46.43 | Q7: 48.83 | R7: 62.54 | S7: 36.39 | T7: 44.79 | U7: 36.02 | V7: 58.59
A8: =A7+1 -> 7 | B8: Q3 FY24 | C8: 87.2 | D8: 14.82 | E8: 6.1 | F8: 48.83 | G8: 17.44 | J8: New Age (Pet/Nutra) | K8: 3.33 | L8: 6.19 | M8: 8.54 | N8: 11.97 | O8: 10.91 | P8: 14.17 | Q8: 17.44 | R8: 25.96 | S8: 19.78 | T8: 27.73 | U8: 30.87 | V8: 50.22
A9: =A8+1 -> 8 | B9: Q4 FY24 | C9: 118 | D9: 22.42 | E9: 7.08 | F9: 62.54 | G9: 25.96
A10: =A9+1 -> 9 | B10: Q1 FY25 | C10: 79.12 | D10: 16.62 | E10: 6.33 | F10: 36.39 | G10: 19.78
A11: =A10+1 -> 10 | B11: Q2 FY25 | C11: 106.65 | D11: 24.53 | E11: 9.6 | F11: 44.79 | G11: 27.73
A12: =A11+1 -> 11 | B12: Q3 FY25 | C12: 102.9 | D12: 25.73 | E12: 10.29 | F12: 36.02 | G12: 30.87
A13: 1 | B13: Q4 FY25 | C13: 167.41 | D13: 41.85 | E13: 16.74 | F13: 58.59 | G13: 50.22

Sheet QTR Raw
A1: ='Annual Raw'!A1 -> 219412 | B1: X | C1: 201206 | D1: 201209 | E1: 201212 | F1: 201303 | G1: 201306 | H1: 201309 | I1: 201312 | J1: 201403 | K1: 201406 | L1: 201409 | M1: 201412 | N1: 201503 | O1: 201506 | P1: 201509 | Q1: 201512 | R1: 201603 | S1: 201606 | T1: 201609 | U1: 201612 | V1: 201703 | W1: 201706 | X1: 201709 | Y1: 201712 | Z1: 201803 | AA1: 201806 | AB1: 201809 | AC1: 201812 | AD1: 201903 | AE1: 201906 | AF1: 201909 | AG1: 201912 | AH1: 202003 | AI1: 202006 | AJ1: 202009 | AK1: 202012 | AL1: 202103 | AM1: 202106 | AN1: 202109 | AO1: 202112 | AP1: 202203 | AQ1: 202206 | AR1: 202209 | AS1: 202212 | AT1: 202303 | AU1: 202306 | AV1: 202309 | AW1: 202312 | AX1: 202403 | AY1: 202406 | AZ1: 202409 | BA1: 202412 | BB1: 202503 | BC1: 202506 | BD1: 202509 | BE1: 202512 | BF1: 202603 | BG1: 202606 | BH1: 202609 | BI1: 202612 | BJ1: 202703 | BK1: 202706 | BL1: 202709 | BM1: 202712 | BN1: 202803 | BO1: 202806 | BP1: 202809 | BQ1: 202812 | BR1: 202903 | BS1: 202906 | BT1: 202909 | BU1: 202912 | BV1: 203003
A3: Field Description | B3: Field Name
A4: Company Name | B4: CD_COMPNAME | C4: =_xll.EQNXTDZ(A1,B4,C1) -> #NAME?
A5: Date End | B5: QTR_DATE_END | C5: =_xll.EQNXTDZ($A$1,$B5,C$1,$B$1) -> #NAME? | D5: =_xll.EQNXTDZ($A$1,$B5,D$1,$B$1) -> #NAME? | E5: =_xll.EQNXTDZ($A$1,$B5,E$1,$B$1) -> #NAME? | F5: =_xll.EQNXTDZ($A$1,$B5,F$1,$B$1) -> #NAME? | G5: =_xll.EQNXTDZ($A$1,$B5,G$1,$B$1) -> #NAME? | H5: =_xll.EQNXTDZ($A$1,$B5,H$1,$B$1) -> #NAME? | I5: =_xll.EQNXTDZ($A$1,$B5,I$1,$B$1) -> #NAME? | J5: =_xll.EQNXTDZ($A$1,$B5,J$1,$B$1) -> #NAME? | ... BV5: =_xll.EQNXTDZ($A$1,$B5,BV$1,$B$1) -> #NAME?
A6: Gross Sales | B6: QTR_GROSS_SALE | C6: =_xll.EQNXTDZ($A$1,$B6,C$1,$B$1) -> #NAME? | D6: =_xll.EQNXTDZ($A$1,$B6,D$1,$B$1) -> #NAME? | E6: =_xll.EQNXTDZ($A$1,$B6,E$1,$B$1) -> #NAME? | F6: =_xll.EQNXTDZ($A$1,$B6,F$1,$B$1) -> #NAME? | G6: =_xll.EQNXTDZ($A$1,$B6,G$1,$B$1) -> #NAME? | H6: =_xll.EQNXTDZ($A$1,$B6,H$1,$B$1) -> #NAME? | I6: =_xll.EQNXTDZ($A$1,$B6,I$1,$B$1) -> #NAME? | J6: =_xll.EQNXTDZ($A$1,$B6,J$1,$B$1) -> #NAME? | ... BV6: =_xll.EQNXTDZ($A$1,$B6,BV$1,$B$1) -> #NAME?
A7: Less: Excise Duty | B7: QTR_EXCISE_DUTY | C7: =_xll.EQNXTDZ($A$1,$B7,C$1,$B$1) -> #NAME? | D7: =_xll.EQNXTDZ($A$1,$B7,D$1,$B$1) -> #NAME? | E7: =_xll.EQNXTDZ($A$1,$B7,E$1,$B$1) -> #NAME? | F7: =_xll.EQNXTDZ($A$1,$B7,F$1,$B$1) -> #NAME? | G7: =_xll.EQNXTDZ($A$1,$B7,G$1,$B$1) -> #NAME? | H7: =_xll.EQNXTDZ($A$1,$B7,H$1,$B$1) -> #NAME? | I7: =_xll.EQNXTDZ($A$1,$B7,I$1,$B$1) -> #NAME? | J7: =_xll.EQNXTDZ($A$1,$B7,J$1,$B$1) -> #NAME? | ... BV7: =_xll.EQNXTDZ($A$1,$B7,BV$1,$B$1) -> #NAME?
A8: Other operating income | B8: QTR_JOB_WORKS | C8: =_xll.EQNXTDZ($A$1,$B8,C$1,$B$1) -> #NAME? | D8: =_xll.EQNXTDZ($A$1,$B8,D$1,$B$1) -> #NAME? | E8: =_xll.EQNXTDZ($A$1,$B8,E$1,$B$1) -> #NAME? | F8: =_xll.EQNXTDZ($A$1,$B8,F$1,$B$1) -> #NAME? | G8: =_xll.EQNXTDZ($A$1,$B8,G$1,$B$1) -> #NAME? | H8: =_xll.EQNXTDZ($A$1,$B8,H$1,$B$1) -> #NAME? | I8: =_xll.EQNXTDZ($A$1,$B8,I$1,$B$1) -> #NAME? | J8: =_xll.EQNXTDZ($A$1,$B8,J$1,$B$1) -> #NAME? | ... BV8: =_xll.EQNXTDZ($A$1,$B8,BV$1,$B$1) -> #NAME?
A9: Net Sales & Other Operating Income | B9: QTR_NET_SALES | C9: =_xll.EQNXTDZ($A$1,$B9,C$1,$B$1) -> #NAME? | D9: =_xll.EQNXTDZ($A$1,$B9,D$1,$B$1) -> #NAME? | E9: =_xll.EQNXTDZ($A$1,$B9,E$1,$B$1) -> #NAME? | F9: =_xll.EQNXTDZ($A$1,$B9,F$1,$B$1) -> #NAME? | G9: =_xll.EQNXTDZ($A$1,$B9,G$1,$B$1) -> #NAME? | H9: =_xll.EQNXTDZ($A$1,$B9,H$1,$B$1) -> #NAME? | I9: =_xll.EQNXTDZ($A$1,$B9,I$1,$B$1) -> #NAME? | J9: =_xll.EQNXTDZ($A$1,$B9,J$1,$B$1) -> #NAME? | ... BV9: =_xll.EQNXTDZ($A$1,$B9,BV$1,$B$1) -> #NAME?
A10: (Increase) / Decrease In Stocks | B10: QTR_INC_DEC_INVENTORY | C10: =_xll.EQNXTDZ($A$1,$B10,C$1,$B$1) -> #NAME? | D10: =_xll.EQNXTDZ($A$1,$B10,D$1,$B$1) -> #NAME? | E10: =_xll.EQNXTDZ($A$1,$B10,E$1,$B$1) -> #NAME? | F10: =_xll.EQNXTDZ($A$1,$B10,F$1,$B$1) -> #NAME? | G10: =_xll.EQNXTDZ($A$1,$B10,G$1,$B$1) -> #NAME? | H10: =_xll.EQNXTDZ($A$1,$B10,H$1,$B$1) -> #NAME? | I10: =_xll.EQNXTDZ($A$1,$B10,I$1,$B$1) -> #NAME? | J10: =_xll.EQNXTDZ($A$1,$B10,J$1,$B$1) -> #NAME? | ... BV10: =_xll.EQNXTDZ($A$1,$B10,BV$1,$B$1) -> #NAME?
A11: Cost of Services & Raw Materials | B11: QTR_RAW_MATERIAL_COST | C11: =_xll.EQNXTDZ($A$1,$B11,C$1,$B$1) -> #NAME? | D11: =_xll.EQNXTDZ($A$1,$B11,D$1,$B$1) -> #NAME? | E11: =_xll.EQNXTDZ($A$1,$B11,E$1,$B$1) -> #NAME? | F11: =_xll.EQNXTDZ($A$1,$B11,F$1,$B$1) -> #NAME? | G11: =_xll.EQNXTDZ($A$1,$B11,G$1,$B$1) -> #NAME? | H11: =_xll.EQNXTDZ($A$1,$B11,H$1,$B$1) -> #NAME? | I11: =_xll.EQNXTDZ($A$1,$B11,I$1,$B$1) -> #NAME? | J11: =_xll.EQNXTDZ($A$1,$B11,J$1,$B$1) -> #NAME? | ... BV11: =_xll.EQNXTDZ($A$1,$B11,BV$1,$B$1) -> #NAME?
A12: Purchase of Finished Goods | B12: QTR_PURCHASE_FIN_GOOD | C12: =_xll.EQNXTDZ($A$1,$B12,C$1,$B$1) -> #NAME? | D12: =_xll.EQNXTDZ($A$1,$B12,D$1,$B$1) -> #NAME? | E12: =_xll.EQNXTDZ($A$1,$B12,E$1,$B$1) -> #NAME? | F12: =_xll.EQNXTDZ($A$1,$B12,F$1,$B$1) -> #NAME? | G12: =_xll.EQNXTDZ($A$1,$B12,G$1,$B$1) -> #NAME? | H12: =_xll.EQNXTDZ($A$1,$B12,H$1,$B$1) -> #NAME? | I12: =_xll.EQNXTDZ($A$1,$B12,I$1,$B$1) -> #NAME? | J12: =_xll.EQNXTDZ($A$1,$B12,J$1,$B$1) -> #NAME? | ... BV12: =_xll.EQNXTDZ($A$1,$B12,BV$1,$B$1) -> #NAME?
A13: Excise Duty | B13: QTR_EXCISE | C13: =_xll.EQNXTDZ($A$1,$B13,C$1,$B$1) -> #NAME? | D13: =_xll.EQNXTDZ($A$1,$B13,D$1,$B$1) -> #NAME? | E13: =_xll.EQNXTDZ($A$1,$B13,E$1,$B$1) -> #NAME? | F13: =_xll.EQNXTDZ($A$1,$B13,F$1,$B$1) -> #NAME? | G13: =_xll.EQNXTDZ($A$1,$B13,G$1,$B$1) -> #NAME? | H13: =_xll.EQNXTDZ($A$1,$B13,H$1,$B$1) -> #NAME? | I13: =_xll.EQNXTDZ($A$1,$B13,I$1,$B$1) -> #NAME? | J13: =_xll.EQNXTDZ($A$1,$B13,J$1,$B$1) -> #NAME? | ... BV13: =_xll.EQNXTDZ($A$1,$B13,BV$1,$B$1) -> #NAME?
A14: Operating & Manufacturing Expenses | B14: QTR_MFG_EXPS | C14: =_xll.EQNXTDZ($A$1,$B14,C$1,$B$1) -> #NAME? | D14: =_xll.EQNXTDZ($A$1,$B14,D$1,$B$1) -> #NAME? | E14: =_xll.EQNXTDZ($A$1,$B14,E$1,$B$1) -> #NAME? | F14: =_xll.EQNXTDZ($A$1,$B14,F$1,$B$1) -> #NAME? | G14: =_xll.EQNXTDZ($A$1,$B14,G$1,$B$1) -> #NAME? | H14: =_xll.EQNXTDZ($A$1,$B14,H$1,$B$1) -> #NAME? | I14: =_xll.EQNXTDZ($A$1,$B14,I$1,$B$1) -> #NAME? | J14: =_xll.EQNXTDZ($A$1,$B14,J$1,$B$1) -> #NAME? | ... BV14: =_xll.EQNXTDZ($A$1,$B14,BV$1,$B$1) -> #NAME?
A15: Electricity Power & Fuel Cost | B15: QTR_ELECTRICITY_POWER_FUEL | C15: =_xll.EQNXTDZ($A$1,$B15,C$1,$B$1) -> #NAME? | D15: =_xll.EQNXTDZ($A$1,$B15,D$1,$B$1) -> #NAME? | E15: =_xll.EQNXTDZ($A$1,$B15,E$1,$B$1) -> #NAME? | F15: =_xll.EQNXTDZ($A$1,$B15,F$1,$B$1) -> #NAME? | G15: =_xll.EQNXTDZ($A$1,$B15,G$1,$B$1) -> #NAME? | H15: =_xll.EQNXTDZ($A$1,$B15,H$1,$B$1) -> #NAME? | I15: =_xll.EQNXTDZ($A$1,$B15,I$1,$B$1) -> #NAME? | J15: =_xll.EQNXTDZ($A$1,$B15,J$1,$B$1) -> #NAME? | ... BV15: =_xll.EQNXTDZ($A$1,$B15,BV$1,$B$1) -> #NAME?
A16: Employee Cost | B16: QTR_EXPLOYEE_COST | C16: =_xll.EQNXTDZ($A$1,$B16,C$1,$B$1) -> #NAME? | D16: =_xll.EQNXTDZ($A$1,$B16,D$1,$B$1) -> #NAME? | E16: =_xll.EQNXTDZ($A$1,$B16,E$1,$B$1) -> #NAME? | F16: =_xll.EQNXTDZ($A$1,$B16,F$1,$B$1) -> #NAME? | G16: =_xll.EQNXTDZ($A$1,$B16,G$1,$B$1) -> #NAME? | H16: =_xll.EQNXTDZ($A$1,$B16,H$1,$B$1) -> #NAME? | I16: =_xll.EQNXTDZ($A$1,$B16,I$1,$B$1) -> #NAME? | J16: =_xll.EQNXTDZ($A$1,$B16,J$1,$B$1) -> #NAME? | ... BV16: =_xll.EQNXTDZ($A$1,$B16,BV$1,$B$1) -> #NAME?
... A42: Consolidated PAT(after extra items) | B42: QTR_CONS_PAT_EXITM | C42: =_xll.EQNXTDZ($A$1,$B42,C$1,$B$1) -> #NAME? | D42: =_xll.EQNXTDZ($A$1,$B42,D$1,$B$1) -> #NAME? | E42: =_xll.EQNXTDZ($A$1,$B42,E$1,$B$1) -> #NAME? | F42: =_xll.EQNXTDZ($A$1,$B42,F$1,$B$1) -> #NAME? | G42: =_xll.EQNXTDZ($A$1,$B42,G$1,$B$1) -> #NAME? | H42: =_xll.EQNXTDZ($A$1,$B42,H$1,$B$1) -> #NAME? | I42: =_xll.EQNXTDZ($A$1,$B42,I$1,$B$1) -> #NAME? | J42: =_xll.EQNXTDZ($A$1,$B42,J$1,$B$1) -> #NAME? | ... BV42: =_xll.EQNXTDZ($A$1,$B42,BV$1,$B$1) -> #NAME?
A44: Field Description | B44: Field Name
A45: Equity Capital | B45: QTR_EQUITY_CAP | C45: =_xll.EQNXTDZ($A$1,$B45,C$1,$B$1) -> #NAME? | D45: =_xll.EQNXTDZ($A$1,$B45,D$1,$B$1) -> #NAME? | E45: =_xll.EQNXTDZ($A$1,$B45,E$1,$B$1) -> #NAME? | F45: =_xll.EQNXTDZ($A$1,$B45,F$1,$B$1) -> #NAME? | G45: =_xll.EQNXTDZ($A$1,$B45,G$1,$B$1) -> #NAME? | H45: =_xll.EQNXTDZ($A$1,$B45,H$1,$B$1) -> #NAME? | I45: =_xll.EQNXTDZ($A$1,$B45,I$1,$B$1) -> #NAME? | J45: =_xll.EQNXTDZ($A$1,$B45,J$1,$B$1) -> #NAME? | ... BV45: =_xll.EQNXTDZ($A$1,$B45,BV$1,$B$1) -> #NAME?
A46: Face Value | B46: QTR_FV | C46: =_xll.EQNXTDZ($A$1,$B46,C$1,$B$1) -> #NAME? | D46: =_xll.EQNXTDZ($A$1,$B46,D$1,$B$1) -> #NAME? | E46: =_xll.EQNXTDZ($A$1,$B46,E$1,$B$1) -> #NAME? | F46: =_xll.EQNXTDZ($A$1,$B46,F$1,$B$1) -> #NAME? | G46: =_xll.EQNXTDZ($A$1,$B46,G$1,$B$1) -> #NAME? | H46: =_xll.EQNXTDZ($A$1,$B46,H$1,$B$1) -> #NAME? | I46: =_xll.EQNXTDZ($A$1,$B46,I$1,$B$1) -> #NAME? | J46: =_xll.EQNXTDZ($A$1,$B46,J$1,$B$1) -> #NAME? | ... BV46: =_xll.EQNXTDZ($A$1,$B46,BV$1,$B$1) -> #NAME?
A47: Month End | B47: BMONTH_MONTHEND | C47: =_xll.EQNXTDZ($A$1,$B47,C$5) -> #NAME? | D47: =_xll.EQNXTDZ($A$1,$B47,D$5) -> #NAME? | E47: =_xll.EQNXTDZ($A$1,$B47,E$5) -> #NAME? | F47: =_xll.EQNXTDZ($A$1,$B47,F$5) -> #NAME? | G47: =_xll.EQNXTDZ($A$1,$B47,G$5) -> #NAME? | H47: =_xll.EQNXTDZ($A$1,$B47,H$5) -> #NAME? | I47: =_xll.EQNXTDZ($A$1,$B47,I$5) -> #NAME? | J47: =_xll.EQNXTDZ($A$1,$B47,J$5) -> #NAME? | ... BV47: =_xll.EQNXTDZ($A$1,$B47,BV$5) -> #NAME?
A48: Close | B48: BMONTH_CLOSE | C48: =_xll.EQNXTDZ($A$1,$B48,C$5) -> #NAME? | D48: =_xll.EQNXTDZ($A$1,$B48,D$5) -> #NAME? | E48: =_xll.EQNXTDZ($A$1,$B48,E$5) -> #NAME? | F48: =_xll.EQNXTDZ($A$1,$B48,F$5) -> #NAME? | G48: =_xll.EQNXTDZ($A$1,$B48,G$5) -> #NAME? | H48: =_xll.EQNXTDZ($A$1,$B48,H$5) -> #NAME? | I48: =_xll.EQNXTDZ($A$1,$B48,I$5) -> #NAME? | J48: =_xll.EQNXTDZ($A$1,$B48,J$5) -> #NAME? | ... BV48: =_xll.EQNXTDZ($A$1,$B48,BV$5) -> #NAME?
A49: Total of Promoter and Promoter Group | B49: SHP_TPFTOTALPROMOTER | C49: =_xll.EQNXTDZ($A$1,$B49,C$5) -> #NAME? | D49: =_xll.EQNXTDZ($A$1,$B49,D$5) -> #NAME? | E49: =_xll.EQNXTDZ($A$1,$B49,E$5) -> #NAME? | F49: =_xll.EQNXTDZ($A$1,$B49,F$5) -> #NAME? | G49: =_xll.EQNXTDZ($A$1,$B49,G$5) -> #NAME? | H49: =_xll.EQNXTDZ($A$1,$B49,H$5) -> #NAME? | I49: =_xll.EQNXTDZ($A$1,$B49,I$5) -> #NAME? | J49: =_xll.EQNXTDZ($A$1,$B49,J$5) -> #NAME? | ... BV49: =_xll.EQNXTDZ($A$1,$B49,BV$5) -> #NAME?
A50: Total of Promoter and Promoter Group Pledged | B50: SHP_PSHFTOTALPROMOTER | C50: =_xll.EQNXTDZ($A$1,$B50,C$5) -> #NAME? | D50: =_xll.EQNXTDZ($A$1,$B50,D$5) -> #NAME? | E50: =_xll.EQNXTDZ($A$1,$B50,E$5) -> #NAME? | F50: =_xll.EQNXTDZ($A$1,$B50,F$5) -> #NAME? | G50: =_xll.EQNXTDZ($A$1,$B50,G$5) -> #NAME? | H50: =_xll.EQNXTDZ($A$1,$B50,H$5) -> #NAME? | I50: =_xll.EQNXTDZ($A$1,$B50,I$5) -> #NAME? | J50: =_xll.EQNXTDZ($A$1,$B50,J$5) -> #NAME? | ... BV50: =_xll.EQNXTDZ($A$1,$B50,BV$5) -> #NAME?
A54: Field Description | B54: Field Name | C54: =_xll.EQNXTDZ($A$1,$B54,C$5) -> #NAME? | D54: =_xll.EQNXTDZ($A$1,$B54,D$5) -> #NAME? | E54: =_xll.EQNXTDZ($A$1,$B54,E$5) -> #NAME? | F54: =_xll.EQNXTDZ($A$1,$B54,F$5) -> #NAME? | G54: =_xll.EQNXTDZ($A$1,$B54,G$5) -> #NAME? | H54: =_xll.EQNXTDZ($A$1,$B54,H$5) -> #NAME? | I54: =_xll.EQNXTDZ($A$1,$B54,I$5) -> #NAME? | J54: =_xll.EQNXTDZ($A$1,$B54,J$5) -> #NAME? | ... BV54: =_xll.EQNXTDZ($A$1,$B54,BV$5) -> #NAME?
A55: Year End | B55: QTRB_DATE_END | C55: =_xll.EQNXTDZ($A$1,$B55,C$5,$B$1) -> #NAME? | D55: =_xll.EQNXTDZ($A$1,$B55,D$5,$B$1) -> #NAME? | E55: =_xll.EQNXTDZ($A$1,$B55,E$5,$B$1) -> #NAME? | F55: =_xll.EQNXTDZ($A$1,$B55,F$5,$B$1) -> #NAME? | G55: =_xll.EQNXTDZ($A$1,$B55,G$5,$B$1) -> #NAME? | H55: =_xll.EQNXTDZ($A$1,$B55,H$5,$B$1) -> #NAME? | I55: =_xll.EQNXTDZ($A$1,$B55,I$5,$B$1) -> #NAME? | J55: =_xll.EQNXTDZ($A$1,$B55,J$5,$B$1) -> #NAME? | ... BV55: =_xll.EQNXTDZ($A$1,$B55,BV$5,$B$1) -> #NAME?
A56: Share Capital | B56: QTRB_SHARE_CAPITAL | C56: =_xll.EQNXTDZ($A$1,$B56,C$5,$B$1) -> #NAME? | D56: =_xll.EQNXTDZ($A$1,$B56,D$5,$B$1) -> #NAME? | E56: =_xll.EQNXTDZ($A$1,$B56,E$5,$B$1) -> #NAME? | F56: =_xll.EQNXTDZ($A$1,$B56,F$5,$B$1) -> #NAME? | G56: =_xll.EQNXTDZ($A$1,$B56,G$5,$B$1) -> #NAME? | H56: =_xll.EQNXTDZ($A$1,$B56,H$5,$B$1) -> #NAME? | I56: =_xll.EQNXTDZ($A$1,$B56,I$5,$B$1) -> #NAME? | J56: =_xll.EQNXTDZ($A$1,$B56,J$5,$B$1) -> #NAME? | ... BV56: =_xll.EQNXTDZ($A$1,$B56,BV$5,$B$1) -> #NAME?
A57: Share Warrants & outstandings | B57: QTRB_SHAREWARNDOUT | C57: =_xll.EQNXTDZ($A$1,$B57,C$5,$B$1) -> #NAME? | D57: =_xll.EQNXTDZ($A$1,$B57,D$5,$B$1) -> #NAME? | E57: =_xll.EQNXTDZ($A$1,$B57,E$5,$B$1) -> #NAME? | F57: =_xll.EQNXTDZ($A$1,$B57,F$5,$B$1) -> #NAME? | G57: =_xll.EQNXTDZ($A$1,$B57,G$5,$B$1) -> #NAME? | H57: =_xll.EQNXTDZ($A$1,$B57,H$5,$B$1) -> #NAME? | I57: =_xll.EQNXTDZ($A$1,$B57,I$5,$B$1) -> #NAME? | J57: =_xll.EQNXTDZ($A$1,$B57,J$5,$B$1) -> #NAME? | ... BV57: =_xll.EQNXTDZ($A$1,$B57,BV$5,$B$1) -> #NAME?
A58: Reserves & Surplus | B58: QTRB_RESERVE | C58: =_xll.EQNXTDZ($A$1,$B58,C$5,$B$1) -> #NAME? | D58: =_xll.EQNXTDZ($A$1,$B58,D$5,$B$1) -> #NAME? | E58: =_xll.EQNXTDZ($A$1,$B58,E$5,$B$1) -> #NAME? | F58: =_xll.EQNXTDZ($A$1,$B58,F$5,$B$1) -> #NAME? | G58: =_xll.EQNXTDZ($A$1,$B58,G$5,$B$1) -> #NAME? | H58: =_xll.EQNXTDZ($A$1,$B58,H$5,$B$1) -> #NAME? | I58: =_xll.EQNXTDZ($A$1,$B58,I$5,$B$1) -> #NAME? | J58: =_xll.EQNXTDZ($A$1,$B58,J$5,$B$1) -> #NAME? | ... BV58: =_xll.EQNXTDZ($A$1,$B58,BV$5,$B$1) -> #NAME?
A59: Shareholder's Funds | B59: QTRB_SHAREHODERS_FUNDS | C59: =_xll.EQNXTDZ($A$1,$B59,C$5,$B$1) -> #NAME? | D59: =_xll.EQNXTDZ($A$1,$B59,D$5,$B$1) -> #NAME? | E59: =_xll.EQNXTDZ($A$1,$B59,E$5,$B$1) -> #NAME? | F59: =_xll.EQNXTDZ($A$1,$B59,F$5,$B$1) -> #NAME? | G59: =_xll.EQNXTDZ($A$1,$B59,G$5,$B$1) -> #NAME? | H59: =_xll.EQNXTDZ($A$1,$B59,H$5,$B$1) -> #NAME? | I59: =_xll.EQNXTDZ($A$1,$B59,I$5,$B$1) -> #NAME? | J59: =_xll.EQNXTDZ($A$1,$B59,J$5,$B$1) -> #NAME? | ... BV59: =_xll.EQNXTDZ($A$1,$B59,BV$5,$B$1) -> #NAME?
A60: Minority Interest | B60: QTRB_MINORITY_INTEREST_BS | C60: =_xll.EQNXTDZ($A$1,$B60,C$5,$B$1) -> #NAME? | D60: =_xll.EQNXTDZ($A$1,$B60,D$5,$B$1) -> #NAME? | E60: =_xll.EQNXTDZ($A$1,$B60,E$5,$B$1) -> #NAME? | F60: =_xll.EQNXTDZ($A$1,$B60,F$5,$B$1) -> #NAME? | G60: =_xll.EQNXTDZ($A$1,$B60,G$5,$B$1) -> #NAME? | H60: =_xll.EQNXTDZ($A$1,$B60,H$5,$B$1) -> #NAME? | I60: =_xll.EQNXTDZ($A$1,$B60,I$5,$B$1) -> #NAME? | J60: =_xll.EQNXTDZ($A$1,$B60,J$5,$B$1) -> #NAME? | ... BV60: =_xll.EQNXTDZ($A$1,$B60,BV$5,$B$1) -> #NAME?
A61: Long Term Borrowings | B61: QTRB_TOTAL_DEBTS | C61: =_xll.EQNXTDZ($A$1,$B61,C$5,$B$1) -> #NAME? | D61: =_xll.EQNXTDZ($A$1,$B61,D$5,$B$1) -> #NAME? | E61: =_xll.EQNXTDZ($A$1,$B61,E$5,$B$1) -> #NAME? | F61: =_xll.EQNXTDZ($A$1,$B61,F$5,$B$1) -> #NAME? | G61: =_xll.EQNXTDZ($A$1,$B61,G$5,$B$1) -> #NAME? | H61: =_xll.EQNXTDZ($A$1,$B61,H$5,$B$1) -> #NAME? | I61: =_xll.EQNXTDZ($A$1,$B61,I$5,$B$1) -> #NAME? | J61: =_xll.EQNXTDZ($A$1,$B61,J$5,$B$1) -> #NAME? | ... BV61: =_xll.EQNXTDZ($A$1,$B61,BV$5,$B$1) -> #NAME?
A62: Secured Loans | B62: QTRB_SECURED_LOANS | C62: =_xll.EQNXTDZ($A$1,$B62,C$5,$B$1) -> #NAME? | D62: =_xll.EQNXTDZ($A$1,$B62,D$5,$B$1) -> #NAME? | E62: =_xll.EQNXTDZ($A$1,$B62,E$5,$B$1) -> #NAME? | F62: =_xll.EQNXTDZ($A$1,$B62,F$5,$B$1) -> #NAME? | G62: =_xll.EQNXTDZ($A$1,$B62,G$5,$B$1) -> #NAME? | H62: =_xll.EQNXTDZ($A$1,$B62,H$5,$B$1) -> #NAME? | I62: =_xll.EQNXTDZ($A$1,$B62,I$5,$B$1) -> #NAME? | J62: =_xll.EQNXTDZ($A$1,$B62,J$5,$B$1) -> #NAME? | ... BV62: =_xll.EQNXTDZ($A$1,$B62,BV$5,$B$1) -> #NAME?
A63: Unsecured Loans | B63: QTRB_UNSECURED_LOANS_NF | C63: =_xll.EQNXTDZ($A$1,$B63,C$5,$B$1) -> #NAME? | D63: =_xll.EQNXTDZ($A$1,$B63,D$5,$B$1) -> #NAME? | E63: =_xll.EQNXTDZ($A$1,$B63,E$5,$B$1) -> #NAME? | F63: =_xll.EQNXTDZ($A$1,$B63,F$5,$B$1) -> #NAME? | G63: =_xll.EQNXTDZ($A$1,$B63,G$5,$B$1) -> #NAME? | H63: =_xll.EQNXTDZ($A$1,$B63,H$5,$B$1) -> #NAME? | I63: =_xll.EQNXTDZ($A$1,$B63,I$5,$B$1) -> #NAME? | J63: =_xll.EQNXTDZ($A$1,$B63,J$5,$B$1) -> #NAME? | ... BV63: =_xll.EQNXTDZ($A$1,$B63,BV$5,$B$1) -> #NAME?
A64: Other Long Term Liabilities | B64: QTRB_OTHER_LT_LIABILITIES | C64: =_xll.EQNXTDZ($A$1,$B64,C$5,$B$1) -> #NAME? | D64: =_xll.EQNXTDZ($A$1,$B64,D$5,$B$1) -> #NAME? | E64: =_xll.EQNXTDZ($A$1,$B64,E$5,$B$1) -> #NAME? | F64: =_xll.EQNXTDZ($A$1,$B64,F$5,$B$1) -> #NAME? | G64: =_xll.EQNXTDZ($A$1,$B64,G$5,$B$1) -> #NAME? | H64: =_xll.EQNXTDZ($A$1,$B64,H$5,$B$1) -> #NAME? | I64: =_xll.EQNXTDZ($A$1,$B64,I$5,$B$1) -> #NAME? | J64: =_xll.EQNXTDZ($A$1,$B64,J$5,$B$1) -> #NAME? | ... BV64: =_xll.EQNXTDZ($A$1,$B64,BV$5,$B$1) -> #NAME?
A65: Long Term Trade Payables | B65: QTRB_LT_TRADE_PAYABLE | C65: =_xll.EQNXTDZ($A$1,$B65,C$5,$B$1) -> #NAME? | D65: =_xll.EQNXTDZ($A$1,$B65,D$5,$B$1) -> #NAME? | E65: =_xll.EQNXTDZ($A$1,$B65,E$5,$B$1) -> #NAME? | F65: =_xll.EQNXTDZ($A$1,$B65,F$5,$B$1) -> #NAME? | G65: =_xll.EQNXTDZ($A$1,$B65,G$5,$B$1) -> #NAME? | H65: =_xll.EQNXTDZ($A$1,$B65,H$5,$B$1) -> #NAME? | I65: =_xll.EQNXTDZ($A$1,$B65,I$5,$B$1) -> #NAME? | J65: =_xll.EQNXTDZ($A$1,$B65,J$5,$B$1) -> #NAME? | ... BV65: =_xll.EQNXTDZ($A$1,$B65,BV$5,$B$1) -> #NAME?
A66: Lont Term Provisions | B66: QTRB_LT_PROVISIONS | C66: =_xll.EQNXTDZ($A$1,$B66,C$5,$B$1) -> #NAME? | D66: =_xll.EQNXTDZ($A$1,$B66,D$5,$B$1) -> #NAME? | E66: =_xll.EQNXTDZ($A$1,$B66,E$5,$B$1) -> #NAME? | F66: =_xll.EQNXTDZ($A$1,$B66,F$5,$B$1) -> #NAME? | G66: =_xll.EQNXTDZ($A$1,$B66,G$5,$B$1) -> #NAME? | H66: =_xll.EQNXTDZ($A$1,$B66,H$5,$B$1) -> #NAME? | I66: =_xll.EQNXTDZ($A$1,$B66,I$5,$B$1) -> #NAME? | J66: =_xll.EQNXTDZ($A$1,$B66,J$5,$B$1) -> #NAME? | ... BV66: =_xll.EQNXTDZ($A$1,$B66,BV$5,$B$1) -> #NAME?
... A97: Total Assets | B97: QTRB_TOTAL_APPLICATIONS | C97: =_xll.EQNXTDZ($A$1,$B97,C$5,$B$1) -> #NAME? | D97: =_xll.EQNXTDZ($A$1,$B97,D$5,$B$1) -> #NAME? | E97: =_xll.EQNXTDZ($A$1,$B97,E$5,$B$1) -> #NAME? | F97: =_xll.EQNXTDZ($A$1,$B97,F$5,$B$1) -> #NAME? | G97: =_xll.EQNXTDZ($A$1,$B97,G$5,$B$1) -> #NAME? | H97: =_xll.EQNXTDZ($A$1,$B97,H$5,$B$1) -> #NAME? | I97: =_xll.EQNXTDZ($A$1,$B97,I$5,$B$1) -> #NAME? | J97: =_xll.EQNXTDZ($A$1,$B97,J$5,$B$1) -> #NAME? | ... BV97: =_xll.EQNXTDZ($A$1,$B97,BV$5,$B$1) -> #NAME?

Sheet Annual Raw
A1: 219412 | B1: X | C1: 200103 | D1: 200203 | E1: 200303 | F1: 200403 | G1: 200503 | H1: 200603 | I1: 200703 | J1: 200803 | K1: 200903 | L1: 201003 | M1: 201103 | N1: 201203 | O1: 201303 | P1: 201403 | Q1: 201503 | R1: 201603 | S1: 201703 | T1: 201803 | U1: 201903 | V1: 202003 | W1: 202103 | X1: 202203 | Y1: 202303 | Z1: 202403 | AA1: 202503 | AB1: 202603 | AC1: 202703 | AD1: 202803 | AE1: 202903 | AF1: 203003
A3: Field Description | B3: Field Name
A4: Company Name | B4: CD_COMPNAME | C4: =_xll.EQNXTDZ(A1,B4,"L") -> #NAME?
A5: Year End | B5: PL_YEAR_END | C5: =_xll.EQNXTDZ($A$1,$B5,C$1,$B$1) -> #NAME? | D5: =_xll.EQNXTDZ($A$1,$B5,D$1,$B$1) -> #NAME? | E5: =_xll.EQNXTDZ($A$1,$B5,E$1,$B$1) -> #NAME? | F5: =_xll.EQNXTDZ($A$1,$B5,F$1,$B$1) -> #NAME? | G5: =_xll.EQNXTDZ($A$1,$B5,G$1,$B$1) -> #NAME? | H5: =_xll.EQNXTDZ($A$1,$B5,H$1,$B$1) -> #NAME? | I5: =_xll.EQNXTDZ($A$1,$B5,I$1,$B$1) -> #NAME? | J5: =_xll.EQNXTDZ($A$1,$B5,J$1,$B$1) -> #NAME? | ... AF5: =_xll.EQNXTDZ($A$1,$B5,AF$1,$B$1) -> #NAME?
A6: Sales Turnover | B6: PL_TOTAL_GROSS_SALES | C6: =_xll.EQNXTDZ($A$1,$B6,C$1,$B$1) -> #NAME? | D6: =_xll.EQNXTDZ($A$1,$B6,D$1,$B$1) -> #NAME? | E6: =_xll.EQNXTDZ($A$1,$B6,E$1,$B$1) -> #NAME? | F6: =_xll.EQNXTDZ($A$1,$B6,F$1,$B$1) -> #NAME? | G6: =_xll.EQNXTDZ($A$1,$B6,G$1,$B$1) -> #NAME? | H6: =_xll.EQNXTDZ($A$1,$B6,H$1,$B$1) -> #NAME? | I6: =_xll.EQNXTDZ($A$1,$B6,I$1,$B$1) -> #NAME? | J6: =_xll.EQNXTDZ($A$1,$B6,J$1,$B$1) -> #NAME? | ... AF6: =_xll.EQNXTDZ($A$1,$B6,AF$1,$B$1) -> #NAME?
A7: Less: Inter divisional transfers | B7: PL_INTER_DIV_TRF | C7: =_xll.EQNXTDZ($A$1,$B7,C$1,$B$1) -> #NAME? | D7: =_xll.EQNXTDZ($A$1,$B7,D$1,$B$1) -> #NAME? | E7: =_xll.EQNXTDZ($A$1,$B7,E$1,$B$1) -> #NAME? | F7: =_xll.EQNXTDZ($A$1,$B7,F$1,$B$1) -> #NAME? | G7: =_xll.EQNXTDZ($A$1,$B7,G$1,$B$1) -> #NAME? | H7: =_xll.EQNXTDZ($A$1,$B7,H$1,$B$1) -> #NAME? | I7: =_xll.EQNXTDZ($A$1,$B7,I$1,$B$1) -> #NAME? | J7: =_xll.EQNXTDZ($A$1,$B7,J$1,$B$1) -> #NAME? | ... AF7: =_xll.EQNXTDZ($A$1,$B7,AF$1,$B$1) -> #NAME?
A8: Less: Sales Returns | B8: PL_SALES_RETURN | C8: =_xll.EQNXTDZ($A$1,$B8,C$1,$B$1) -> #NAME? | D8: =_xll.EQNXTDZ($A$1,$B8,D$1,$B$1) -> #NAME? | E8: =_xll.EQNXTDZ($A$1,$B8,E$1,$B$1) -> #NAME? | F8: =_xll.EQNXTDZ($A$1,$B8,F$1,$B$1) -> #NAME? | G8: =_xll.EQNXTDZ($A$1,$B8,G$1,$B$1) -> #NAME? | H8: =_xll.EQNXTDZ($A$1,$B8,H$1,$B$1) -> #NAME? | I8: =_xll.EQNXTDZ($A$1,$B8,I$1,$B$1) -> #NAME? | J8: =_xll.EQNXTDZ($A$1,$B8,J$1,$B$1) -> #NAME? | ... AF8: =_xll.EQNXTDZ($A$1,$B8,AF$1,$B$1) -> #NAME?
A9: Less: Excise | B9: PL_EXCISE | C9: =_xll.EQNXTDZ($A$1,$B9,C$1,$B$1) -> #NAME? | D9: =_xll.EQNXTDZ($A$1,$B9,D$1,$B$1) -> #NAME? | E9: =_xll.EQNXTDZ($A$1,$B9,E$1,$B$1) -> #NAME? | F9: =_xll.EQNXTDZ($A$1,$B9,F$1,$B$1) -> #NAME? | G9: =_xll.EQNXTDZ($A$1,$B9,G$1,$B$1) -> #NAME? | H9: =_xll.EQNXTDZ($A$1,$B9,H$1,$B$1) -> #NAME? | I9: =_xll.EQNXTDZ($A$1,$B9,I$1,$B$1) -> #NAME? | J9: =_xll.EQNXTDZ($A$1,$B9,J$1,$B$1) -> #NAME? | ... AF9: =_xll.EQNXTDZ($A$1,$B9,AF$1,$B$1) -> #NAME?
A10: Net Sales | B10: PL_NET_SALES | C10: =_xll.EQNXTDZ($A$1,$B10,C$1,$B$1) -> #NAME? | D10: =_xll.EQNXTDZ($A$1,$B10,D$1,$B$1) -> #NAME? | E10: =_xll.EQNXTDZ($A$1,$B10,E$1,$B$1) -> #NAME? | F10: =_xll.EQNXTDZ($A$1,$B10,F$1,$B$1) -> #NAME? | G10: =_xll.EQNXTDZ($A$1,$B10,G$1,$B$1) -> #NAME? | H10: =_xll.EQNXTDZ($A$1,$B10,H$1,$B$1) -> #NAME? | I10: =_xll.EQNXTDZ($A$1,$B10,I$1,$B$1) -> #NAME? | J10: =_xll.EQNXTDZ($A$1,$B10,J$1,$B$1) -> #NAME? | ... AF10: =_xll.EQNXTDZ($A$1,$B10,AF$1,$B$1) -> #NAME?
A11: Increase/Decrease in Stock | B11: PL_INC_DEC_INVENTORY | C11: =_xll.EQNXTDZ($A$1,$B11,C$1,$B$1) -> #NAME? | D11: =_xll.EQNXTDZ($A$1,$B11,D$1,$B$1) -> #NAME? | E11: =_xll.EQNXTDZ($A$1,$B11,E$1,$B$1) -> #NAME? | F11: =_xll.EQNXTDZ($A$1,$B11,F$1,$B$1) -> #NAME? | G11: =_xll.EQNXTDZ($A$1,$B11,G$1,$B$1) -> #NAME? | H11: =_xll.EQNXTDZ($A$1,$B11,H$1,$B$1) -> #NAME? | I11: =_xll.EQNXTDZ($A$1,$B11,I$1,$B$1) -> #NAME? | J11: =_xll.EQNXTDZ($A$1,$B11,J$1,$B$1) -> #NAME? | ... AF11: =_xll.EQNXTDZ($A$1,$B11,AF$1,$B$1) -> #NAME?
A12: Raw Material Consumed | B12: PL_RAW_MATRS_CONSUMED | C12: =_xll.EQNXTDZ($A$1,$B12,C$1,$B$1) -> #NAME? | D12: =_xll.EQNXTDZ($A$1,$B12,D$1,$B$1) -> #NAME? | E12: =_xll.EQNXTDZ($A$1,$B12,E$1,$B$1) -> #NAME? | F12: =_xll.EQNXTDZ($A$1,$B12,F$1,$B$1) -> #NAME? | G12: =_xll.EQNXTDZ($A$1,$B12,G$1,$B$1) -> #NAME? | H12: =_xll.EQNXTDZ($A$1,$B12,H$1,$B$1) -> #NAME? | I12: =_xll.EQNXTDZ($A$1,$B12,I$1,$B$1) -> #NAME? | J12: =_xll.EQNXTDZ($A$1,$B12,J$1,$B$1) -> #NAME? | ... AF12: =_xll.EQNXTDZ($A$1,$B12,AF$1,$B$1) -> #NAME?
