Workbook

Sheet Template
A1: =+'Annual Raw'!C4 -> Huhtamaki India Ltd. | B1: 36951 | C1: =EOMONTH(B1,12) -> 37346 | D1: 37591 | E1: =EOMONTH(D1,12) -> 37986 | F1: =EOMONTH(E1,12) -> 38352 | G1: =EOMONTH(F1,12) -> 38717 | H1: =EOMONTH(G1,12) -> 39082 | I1: =EOMONTH(H1,12) -> 39447 | J1: =EOMONTH(I1,12) -> 39813 | K1: =EOMONTH(J1,12) -> 40178 | L1: =EOMONTH(K1,12) -> 40543 | ... AE1: =EOMONTH(AD1,12) -> 47483 | AH1: QTR | AI1: 41061 | AJ1: 41153 | AK1: 41244 | AL1: 41334 | AM1: 41426 | AN1: 41518 | AO1: 41609 | AP1: 41699 | AQ1: 41791 | AR1: 41883 | AS1: 41974 | AT1: 42064 | AU1: 42156 | AV1: 42248 | AW1: 42339 | AX1: 42430 | AY1: 42522 | AZ1: 42614 | BA1: 42705 | BB1: 42795 | BC1: 42887 | BD1: 42979 | BE1: 43070 | BF1: 43160 | BG1: 43252 | BH1: 43344 | BI1: 43435 | BJ1: 43525 | BK1: 43617 | BL1: 43709 | BM1: 43800 | BN1: 43891 | BO1: 43983 | BP1: 44075 | BQ1: =EOMONTH(BP1,3) -> 44196 | BR1: =EOMONTH(BQ1,3) -> 44286 | BS1: =EOMONTH(BR1,3) -> 44377 | BT1: =EOMONTH(BS1,3) -> 44469 | BU1: =EOMONTH(BT1,3) -> 44561 | BV1: =EOMONTH(BU1,3) -> 44651 | BW1: =EOMONTH(BV1,3) -> 44742 | BX1: =EOMONTH(BW1,3) -> 44834 | ... DA1: =EOMONTH(CZ1,3) -> 47483 | DD1: HISTORICAL ESTIMATES | DE1: 46022
A2: Presentation Data (Start)
A6: Presentation Data (End)
A7: Profit & Loss- Annual (Start)
A8: Gross Revenue | B8: ='Annual Raw'!C6 -> 0 | C8: ='Annual Raw'!D6 -> 0 | D8: ='Annual Raw'!E6 -> 354.2851 | E8: ='Annual Raw'!F6 -> 416.1824 | F8: ='Annual Raw'!G6 -> 424.9527 | G8: ='Annual Raw'!H6 -> 468.3587 | H8: ='Annual Raw'!I6 -> 547.3669 | I8: ='Annual Raw'!J6 -> 607.7681 | ... AA8: ='Annual Raw'!AB6 -> 2488.1 | AB8: =+SUM(CL8:CO8) -> 2450.1155 | AC8: =+SUM(CP8:CS8) -> 2427.9481 | AD8: =+SUM(CT8:CW8) -> 2405.9096 | AE8: =+SUM(CX8:DA8) -> 2384.1383 | AI8: ='QTR Raw'!C6+'QTR Raw'!C8 -> 255.55 | AJ8: ='QTR Raw'!D6+'QTR Raw'!D8 -> 237.4 | AK8: ='QTR Raw'!E6+'QTR Raw'!E8 -> 245.25 | AL8: ='QTR Raw'!F6+'QTR Raw'!F8 -> 275.29 | AM8: ='QTR Raw'!G6+'QTR Raw'!G8 -> 296.68 | AN8: ='QTR Raw'!H6+'QTR Raw'!H8 -> 286.89 | AO8: ='QTR Raw'!I6+'QTR Raw'!I8 -> 299.86 | AP8: ='QTR Raw'!J6+'QTR Raw'!J8 -> 312.14 | ... CL8: ='QTR Raw'!BF6+'QTR Raw'!BF8 -> 613.1 | CM8: =+CI10+(CM11*CI10) -> 600.83916 | CN8: =+CJ10+(CN11*CJ10) -> 616.84908 | CO8: =+CK10+(CO11*CK10) -> 619.32722 | CP8: =+CL10+(CP11*CL10) -> 608.32519 | CQ8: =+CM10+(CQ11*CM10) -> 594.20932 | CR8: =+CN10+(CR11*CN10) -> 611.21016 | CS8: =+CO10+(CS11*CO10) -> 614.20344 | CT8: =+CP10+(CT11*CP10) -> 602.81424 | ... DA8: =+CW10+(DA11*CW10) -> 603.23332 | DE8: 2469.41
A9: Less: Exise Duty | B9: ='Annual Raw'!C7+'Annual Raw'!C8+'Annual Raw'!C9 -> 0 | C9: ='Annual Raw'!D7+'Annual Raw'!D8+'Annual Raw'!D9 -> 0 | D9: ='Annual Raw'!E7+'Annual Raw'!E8+'Annual Raw'!E9 -> 32.0978 | E9: ='Annual Raw'!F7+'Annual Raw'!F8+'Annual Raw'!F9 -> 33.5645 | F9: ='Annual Raw'!G7+'Annual Raw'!G8+'Annual Raw'!G9 -> 30.9316 | G9: ='Annual Raw'!H7+'Annual Raw'!H8+'Annual Raw'!H9 -> 35.4983 | H9: ='Annual Raw'!I7+'Annual Raw'!I8+'Annual Raw'!I9 -> 46.162 | I9: ='Annual Raw'!J7+'Annual Raw'!J8+'Annual Raw'!J9 -> 37.1807 | ... AA9: ='Annual Raw'!AB7+'Annual Raw'!AB8+'Annual Raw'!AB9 -> 18.69 | AB9: =+SUM(CL9:CO9) -> 0 | AC9: =+SUM(CP9:CS9) -> 0 | AD9: =+SUM(CT9:CW9) -> 0 | AE9: =+SUM(CX9:DA9) -> 0 | AI9: ='QTR Raw'!C21+'QTR Raw'!C20+'QTR Raw'!C19+'QTR Raw'!C13+'QTR Raw'!C7 -> 18.07 | AJ9: ='QTR Raw'!D21+'QTR Raw'!D20+'QTR Raw'!D19+'QTR Raw'!D13+'QTR Raw'!D7 -> 14.6 | AK9: ='QTR Raw'!E21+'QTR Raw'!E20+'QTR Raw'!E19+'QTR Raw'!E13+'QTR Raw'!E7 -> 16.1 | AL9: ='QTR Raw'!F21+'QTR Raw'!F20+'QTR Raw'!F19+'QTR Raw'!F13+'QTR Raw'!F7 -> 18.48 | AM9: ='QTR Raw'!G21+'QTR Raw'!G20+'QTR Raw'!G19+'QTR Raw'!G13+'QTR Raw'!G7 -> 20.13 | AN9: ='QTR Raw'!H21+'QTR Raw'!H20+'QTR Raw'!H19+'QTR Raw'!H13+'QTR Raw'!H7 -> 18.52 | AO9: ='QTR Raw'!I21+'QTR Raw'!I20+'QTR Raw'!I19+'QTR Raw'!I13+'QTR Raw'!I7 -> 18.54 | AP9: ='QTR Raw'!J21+'QTR Raw'!J20+'QTR Raw'!J19+'QTR Raw'!J13+'QTR Raw'!J7 -> 21.08 | ... CL9: ='QTR Raw'!BF21+'QTR Raw'!BF20+'QTR Raw'!BF19+'QTR Raw'!BF13+'QTR Raw'!BF7 -> 0 | DE9: 0
A10: Net Revenue | B10: =+B8-B9 -> 0 | C10: =+C8-C9 -> 0 | D10: =+D8-D9 -> 322.1873 | E10: =+E8-E9 -> 382.6179 | F10: =+F8-F9 -> 394.0211 | G10: =+G8-G9 -> 432.8604 | H10: =+H8-H9 -> 501.2049 | I10: =+I8-I9 -> 570.5874 | ... AE10: =+AE8-AE9 -> 2384.1383 | AI10: =+AI8-AI9 -> 237.48 | AJ10: =+AJ8-AJ9 -> 222.8 | AK10: =+AK8-AK9 -> 229.15 | AL10: =+AL8-AL9 -> 256.81 | AM10: =+AM8-AM9 -> 276.55 | AN10: =+AN8-AN9 -> 268.37 | AO10: =+AO8-AO9 -> 281.32 | AP10: =+AP8-AP9 -> 291.06 | ... DA10: =+DA8-DA9 -> 603.23332 | DE10: 2469.41
A11: Net Revenue YOY% | C11: =C10/B10-1 -> #DIV/0! | D11: =D10/C10-1 -> #DIV/0! | E11: =E10/D10-1 -> 0.18756357 | F11: =F10/E10-1 -> 0.029803101 | G11: =G10/F10-1 -> 0.098571625 | H11: =H10/G10-1 -> 0.1578904 | I11: =I10/H10-1 -> 0.13843141 | J11: =J10/I10-1 -> 0.072733818 | ... AE11: =AE10/AD10-1 -> -0.00904912 | AM11: =+IF(AI10<0,1-AM10/AI10,AM10/AI10-1) -> 0.16451912 | AN11: =+IF(AJ10<0,1-AN10/AJ10,AN10/AJ10-1) -> 0.20453321 | AO11: =+IF(AK10<0,1-AO10/AK10,AO10/AK10-1) -> 0.22766747 | AP11: =+IF(AL10<0,1-AP10/AL10,AP10/AL10-1) -> 0.13336708 | AQ11: =+IF(AM10<0,1-AQ10/AM10,AQ10/AM10-1) -> 0.11831495 | AR11: =+IF(AN10<0,1-AR10/AN10,AR10/AN10-1) -> 0.17133063 | AS11: =+IF(AO10<0,1-AS10/AO10,AS10/AO10-1) -> 0.10244561 | AT11: =+IF(AP10<0,1-AT10/AP10,AT10/AP10-1) -> 0.51982409 | ... CL11: =+IF(CH10<0,1-CL10/CH10,CL10/CH10-1) -> 0.0051973177 | CM11: =+AVERAGE(CI11:CL11) -> -0.018605499 | CN11: =+AVERAGE(CJ11:CM11) -> -0.012614915 | CO11: =+AVERAGE(CK11:CN11) -> -0.0051287974 | CP11: =+AVERAGE(CL11:CO11) -> -0.0077879734 | CQ11: =+AVERAGE(CM11:CP11) -> -0.011034296 | CR11: =+AVERAGE(CN11:CQ11) -> -0.0091414956 | CS11: =+AVERAGE(CO11:CR11) -> -0.0082731407 | CT11: =+AVERAGE(CP11:CS11) -> -0.0090592265 | ... DA11: =+AVERAGE(CW11:CZ11) -> -0.0090231557 | DE11: -0.020534036
A12: Net Revenue QOQ% | AJ12: =+IF(AI10<0,1-AJ10/AI10,AJ10/AI10-1) -> -0.061815732 | AK12: =+IF(AJ10<0,1-AK10/AJ10,AK10/AJ10-1) -> 0.028500898 | AL12: =+IF(AK10<0,1-AL10/AK10,AL10/AK10-1) -> 0.12070696 | AM12: =+IF(AL10<0,1-AM10/AL10,AM10/AL10-1) -> 0.076866166 | AN12: =+IF(AM10<0,1-AN10/AM10,AN10/AM10-1) -> -0.029578738 | AO12: =+IF(AN10<0,1-AO10/AN10,AO10/AN10-1) -> 0.048254276 | AP12: =+IF(AO10<0,1-AP10/AO10,AP10/AO10-1) -> 0.034622494 | AQ12: =+IF(AP10<0,1-AQ10/AP10,AQ10/AP10-1) -> 0.06256442 | ... CL12: =+IF(CK10<0,1-CL10/CK10,CL10/CK10-1) -> -0.015132044 | CM12: =+CM10/CL10-1 -> -0.019998115 | CN12: =+CN10/CM10-1 -> 0.026645947 | CO12: =+CO10/CN10-1 -> 0.0040174123 | CP12: =+CP10/CO10-1 -> -0.017764482 | CQ12: =+CQ10/CP10-1 -> -0.023204489 | CR12: =+CR10/CQ10-1 -> 0.028610865 | CS12: =+CS10/CR10-1 -> 0.0048972992 | CT12: =+CT10/CS10-1 -> -0.018543045 | ... DA12: =+DA10/CZ10-1 -> 0.0049303606
A13: Increase/Decrease in Stock | B13: ='Annual Raw'!C11 -> 0 | C13: ='Annual Raw'!D11 -> 0 | D13: ='Annual Raw'!E11 -> 1.5387 | E13: ='Annual Raw'!F11 -> -3.5805 | F13: ='Annual Raw'!G11 -> 0.9135 | G13: ='Annual Raw'!H11 -> -3.0595 | H13: ='Annual Raw'!I11 -> 0.1137 | I13: ='Annual Raw'!J11 -> -7.5251 | ... AA13: ='Annual Raw'!AB11 -> 10.15 | AB13: =+SUM(CL13:CO13) -> -26.24 | AC13: =+SUM(CP13:CS13) -> 0 | AD13: =+SUM(CT13:CW13) -> 0 | AE13: =+SUM(CX13:DA13) -> 0 | AI13: ='QTR Raw'!C10 -> -1.23 | AJ13: ='QTR Raw'!D10 -> -2.47 | AK13: ='QTR Raw'!E10 -> 2.45 | AL13: ='QTR Raw'!F10 -> -2.98 | AM13: ='QTR Raw'!G10 -> -2.74 | AN13: ='QTR Raw'!H10 -> 3 | AO13: ='QTR Raw'!I10 -> 5.15 | AP13: ='QTR Raw'!J10 -> -6.94 | ... CL13: ='QTR Raw'!BF10 -> -26.24 | DE13: 10.15
A14: Purchase of Finished Goods | B14: 0 | C14: 0 | D14: 0 | E14: 0 | F14: 0 | G14: 0 | H14: 0 | I14: 0 | J14: 0 | K14: 0 | L14: 0 | M14: 0 | N14: 0 | O14: 0 | P14: 0 | Q14: 0 | R14: 0 | S14: 0 | T14: 0 | U14: 0 | V14: 0 | W14: 0 | X14: 0 | Y14: 0 | Z14: 0 | AA14: 0 | AB14: =+SUM(CL14:CO14) -> 0 | AC14: =+SUM(CP14:CS14) -> 0 | AD14: =+SUM(CT14:CW14) -> 0 | AE14: =+SUM(CX14:DA14) -> 0 | AI14: ='QTR Raw'!C12 -> 0 | AJ14: ='QTR Raw'!D12 -> 0 | AK14: ='QTR Raw'!E12 -> 0 | AL14: ='QTR Raw'!F12 -> 0 | AM14: ='QTR Raw'!G12 -> 0 | AN14: ='QTR Raw'!H12 -> 0 | AO14: ='QTR Raw'!I12 -> 0 | AP14: ='QTR Raw'!J12 -> 0 | ... CL14: ='QTR Raw'!BF12 -> 0 | DE14: 0
A15: Raw Material Consumed | B15: ='Annual Raw'!C12 -> 0 | C15: ='Annual Raw'!D12 -> 0 | D15: ='Annual Raw'!E12 -> 203.7736 | E15: ='Annual Raw'!F12 -> 259.7068 | F15: ='Annual Raw'!G12 -> 266.155 | G15: ='Annual Raw'!H12 -> 297.6002 | H15: ='Annual Raw'!I12 -> 345.8754 | I15: ='Annual Raw'!J12 -> 409.0374 | ... AA15: ='Annual Raw'!AB12 -> 1620.07 | AB15: =+SUM(CL15:CO15) -> 1640.2056 | AC15: =+SUM(CP15:CS15) -> 1600.5461 | AD15: =+SUM(CT15:CW15) -> 1586.2078 | AE15: =+SUM(CX15:DA15) -> 1571.8796 | AI15: ='QTR Raw'!C11 -> 167.83 | AJ15: ='QTR Raw'!D11 -> 161.33 | AK15: ='QTR Raw'!E11 -> 153.51 | AL15: ='QTR Raw'!F11 -> 177.39 | AM15: ='QTR Raw'!G11 -> 193.29 | AN15: ='QTR Raw'!H11 -> 184.36 | AO15: ='QTR Raw'!I11 -> 194.83 | AP15: ='QTR Raw'!J11 -> 212.07 | ... CL15: ='QTR Raw'!BF11 -> 428.49 | CM15: =+CM10-CM16 -> 396.04076 | CN15: =+CN10-CN16 -> 407.11983 | CO15: =+CO10-CO16 -> 408.55496 | CP15: =+CP10-CP16 -> 400.72093 | CQ15: =+CQ10-CQ16 -> 391.81401 | CR15: =+CR10-CR16 -> 403.06099 | CS15: =+CS10-CS16 -> 404.9502 | CT15: =+CT10-CT16 -> 397.38605 | ... DA15: =+DA10-DA16 -> 397.71516 | DE15: 1620.07
A16: Gross Profit | B16: =B10-B13-B15-B14 -> 0 | C16: =C10-C13-C15-C14 -> 0 | D16: =D10-D13-D15-D14 -> 116.875 | E16: =E10-E13-E15-E14 -> 126.4916 | F16: =F10-F13-F15-F14 -> 126.9526 | G16: =G10-G13-G15-G14 -> 138.3197 | H16: =H10-H13-H15-H14 -> 155.2158 | I16: =I10-I13-I15-I14 -> 169.0751 | ... AE16: =AE10-AE13-AE15-AE14 -> 812.25869 | AI16: =AI10-AI13-AI15-AI14 -> 70.88 | AJ16: =AJ10-AJ13-AJ15-AJ14 -> 63.94 | AK16: =AK10-AK13-AK15-AK14 -> 73.19 | AL16: =AL10-AL13-AL15-AL14 -> 82.4 | AM16: =AM10-AM13-AM15-AM14 -> 86 | AN16: =AN10-AN13-AN15-AN14 -> 81.01 | AO16: =AO10-AO13-AO15-AO14 -> 81.34 | AP16: =AP10-AP13-AP15-AP14 -> 85.93 | ... CL16: =CL10-CL13-CL15-CL14 -> 210.85 | CM16: =+CM17*CM10 -> 204.79839 | CN16: =+CN17*CN10 -> 209.72925 | CO16: =+CO17*CO10 -> 210.77226 | CP16: =+CP17*CP10 -> 207.60427 | CQ16: =+CQ17*CQ10 -> 202.39531 | CR16: =+CR17*CR10 -> 208.14917 | CS16: =+CS17*CS10 -> 209.25324 | CT16: =+CT17*CT10 -> 205.42819 | ... DA16: =+DA17*DA10 -> 205.51817 | DE16: 839.19
A17: GP% | B17: =B16/B10 -> #DIV/0! | C17: =C16/C10 -> #DIV/0! | D17: =D16/D10 -> 0.36275483 | E17: =E16/E10 -> 0.33059509 | F17: =F16/F10 -> 0.32219747 | G17: =G16/G10 -> 0.31954806 | H17: =H16/H10 -> 0.30968532 | I17: =I16/I10 -> 0.29631762 | ... AE17: =AE16/AE10 -> 0.34069278 | AI17: =AI16/AI10 -> 0.29846724 | AJ17: =AJ16/AJ10 -> 0.28698384 | AK17: =AK16/AK10 -> 0.31939777 | AL17: =AL16/AL10 -> 0.32085978 | AM17: =AM16/AM10 -> 0.31097451 | AN17: =AN16/AN10 -> 0.30185937 | AO17: =AO16/AO10 -> 0.28913693 | AP17: =AP16/AP10 -> 0.29523122 | ... CL17: =CL16/CL10 -> 0.34390801 | CM17: =AVERAGE(CI17:CL17) -> 0.34085394 | CN17: =AVERAGE(CJ17:CM17) -> 0.34000091 | CO17: =AVERAGE(CK17:CN17) -> 0.34032456 | CP17: =AVERAGE(CL17:CO17) -> 0.34127185 | CQ17: =AVERAGE(CM17:CP17) -> 0.34061281 | CR17: =AVERAGE(CN17:CQ17) -> 0.34055253 | CS17: =AVERAGE(CO17:CR17) -> 0.34069044 | CT17: =AVERAGE(CP17:CS17) -> 0.34078191 | ... DA17: =AVERAGE(CW17:CZ17) -> 0.34069432 | DE17: 0.33983421
A18: GP YOY% | C18: =+IF(B16<0,1-C16/B16,C16/B16-1) -> #DIV/0! | D18: =+IF(C16<0,1-D16/C16,D16/C16-1) -> #DIV/0! | E18: =+IF(D16<0,1-E16/D16,E16/D16-1) -> 0.08228107 | F18: =+IF(E16<0,1-F16/E16,F16/E16-1) -> 0.0036445108 | G18: =+IF(F16<0,1-G16/F16,G16/F16-1) -> 0.089538143 | H18: =+IF(G16<0,1-H16/G16,H16/G16-1) -> 0.12215252 | I18: =+IF(H16<0,1-I16/H16,I16/H16-1) -> 0.089290523 | J18: =+IF(I16<0,1-J16/I16,J16/I16-1) -> 0.12870494 | ... AE18: =+IF(AD16<0,1-AE16/AD16,AE16/AD16-1) -> -0.0090802849 | AM18: =+IF(AI16<0,1-AM16/AI16,AM16/AI16-1) -> 0.21331828 | AN18: =+IF(AJ16<0,1-AN16/AJ16,AN16/AJ16-1) -> 0.26696903 | AO18: =+IF(AK16<0,1-AO16/AK16,AO16/AK16-1) -> 0.11135401 | AP18: =+IF(AL16<0,1-AP16/AL16,AP16/AL16-1) -> 0.042839806 | AQ18: =+IF(AM16<0,1-AQ16/AM16,AQ16/AM16-1) -> 0.029651163 | AR18: =+IF(AN16<0,1-AR16/AN16,AR16/AN16-1) -> 0.090606098 | AS18: =+IF(AO16<0,1-AS16/AO16,AS16/AO16-1) -> 0.10966314 | AT18: =+IF(AP16<0,1-AT16/AP16,AT16/AP16-1) -> 0.68893285 | ... CL18: =+IF(CH16<0,1-CL16/CH16,CL16/CH16-1) -> 0.017026818 | CM18: =+CM16/CI16-1 -> -0.028332346 | CN18: =+CN16/CJ16-1 -> -0.0088409753 | CO18: =+CO16/CK16-1 -> 0.0060728495 | CP18: =+CP16/CL16-1 -> -0.015393569 | CQ18: =+CQ16/CM16-1 -> -0.011733898 | CR18: =+CR16/CN16-1 -> -0.0075339088 | CS18: =+CS16/CO16-1 -> -0.0072069365 | CT18: =+CT16/CP16-1 -> -0.010481859 | ... DA18: =+DA16/CW16-1 -> -0.0090417417 | DE18: 0.073943256
A19: GP QOQ% | AJ19: =+IF(AI16<0,1-AJ16/AI16,AJ16/AI16-1) -> -0.097911964 | AK19: =+IF(AJ16<0,1-AK16/AJ16,AK16/AJ16-1) -> 0.14466688 | AL19: =+IF(AK16<0,1-AL16/AK16,AL16/AK16-1) -> 0.12583686 | AM19: =+IF(AL16<0,1-AM16/AL16,AM16/AL16-1) -> 0.04368932 | AN19: =+IF(AM16<0,1-AN16/AM16,AN16/AM16-1) -> -0.058023256 | AO19: =+IF(AN16<0,1-AO16/AN16,AO16/AN16-1) -> 0.0040735712 | AP19: =+IF(AO16<0,1-AP16/AO16,AP16/AO16-1) -> 0.056429801 | AQ19: =+IF(AP16<0,1-AQ16/AP16,AQ16/AP16-1) -> 0.030489934 | ... CL19: =+IF(CK16<0,1-CL16/CK16,CL16/CK16-1) -> 0.0064439141 | CM19: =+CM16/CL16-1 -> -0.028701013 | CN19: =+CN16/CM16-1 -> 0.024076646 | CO19: =+CO16/CN16-1 -> 0.0049731372 | CP19: =+CP16/CO16-1 -> -0.015030422 | CQ19: =+CQ16/CP16-1 -> -0.025090804 | CR19: =+CR16/CQ16-1 -> 0.028428824 | CS19: =+CS16/CR16-1 -> 0.0053042299 | CT19: =+CT16/CS16-1 -> -0.018279538 | ... DA19: =+DA16/CZ16-1 -> 0.0049440742
A20: Power & Fuel Cost | B20: ='Annual Raw'!C13 -> 0 | C20: ='Annual Raw'!D13 -> 0 | D20: ='Annual Raw'!E13 -> 10.014 | E20: ='Annual Raw'!F13 -> 12.0829 | F20: ='Annual Raw'!G13 -> 12.3519 | G20: ='Annual Raw'!H13 -> 15.2928 | H20: ='Annual Raw'!I13 -> 17.8088 | I20: ='Annual Raw'!J13 -> 16.9449 | ... AA20: ='Annual Raw'!AB13 -> 81.59 | AB20: =+SUM(CL20:CO20) -> 0 | AC20: =+SUM(CP20:CS20) -> 0 | AD20: =+SUM(CT20:CW20) -> 0 | AE20: =+SUM(CX20:DA20) -> 0 | AI20: ='QTR Raw'!C15 -> 0 | AJ20: ='QTR Raw'!D15 -> 0 | AK20: ='QTR Raw'!E15 -> 0 | AL20: ='QTR Raw'!F15 -> 0 | AM20: ='QTR Raw'!G15 -> 0 | AN20: ='QTR Raw'!H15 -> 0 | AO20: ='QTR Raw'!I15 -> 0 | AP20: ='QTR Raw'!J15 -> 0 | ... CL20: ='QTR Raw'!BF15 -> 0 | DE20: 0
A21: Selling and Distribution Expenses | B21: =('Annual Raw'!C18) -> 0 | C21: =('Annual Raw'!D18) -> 0 | D21: =('Annual Raw'!E18) -> 5.4636 | E21: =('Annual Raw'!F18) -> 6.3055 | F21: =('Annual Raw'!G18) -> 7.4863 | G21: =('Annual Raw'!H18) -> 9.3989 | H21: =('Annual Raw'!I18) -> 9.6156 | I21: =('Annual Raw'!J18) -> 12.6259 | ... AA21: =('Annual Raw'!AB18) -> 48.11 | AB21: =+SUM(CL21:CO21) -> 0 | AC21: =+SUM(CP21:CS21) -> 0 | AD21: =+SUM(CT21:CW21) -> 0 | AE21: =+SUM(CX21:DA21) -> 0 | AI21: ='QTR Raw'!C18 -> 0 | AJ21: ='QTR Raw'!D18 -> 0 | AK21: ='QTR Raw'!E18 -> 0 | AL21: ='QTR Raw'!F18 -> 0 | AM21: ='QTR Raw'!G18 -> 0 | AN21: ='QTR Raw'!H18 -> 0 | AO21: ='QTR Raw'!I18 -> 0 | AP21: ='QTR Raw'!J18 -> 0 | ... CL21: ='QTR Raw'!BF18 -> 0 | DE21: 0
A22: Other Manufacturing Expenses | B22: ='Annual Raw'!C15+'Annual Raw'!C16 -> 0 | C22: ='Annual Raw'!D15+'Annual Raw'!D16 -> 0 | D22: ='Annual Raw'!E15+'Annual Raw'!E16 -> 9.2349 | E22: ='Annual Raw'!F15+'Annual Raw'!F16 -> 11.8431 | F22: ='Annual Raw'!G15+'Annual Raw'!G16 -> 13.27 | G22: ='Annual Raw'!H15+'Annual Raw'!H16 -> 14.5692 | H22: ='Annual Raw'!I15+'Annual Raw'!I16 -> 20.0295 | I22: ='Annual Raw'!J15+'Annual Raw'!J16 -> 22.351 | ... AA22: ='Annual Raw'!AB15+'Annual Raw'!AB16 -> 130.14 | AB22: =+SUM(CL22:CO22) -> 382.8804 | AC22: =+SUM(CP22:CS22) -> 352.91369 | AD22: =+SUM(CT22:CW22) -> 326.11897 | AE22: =+SUM(CX22:DA22) -> 298.66355 | AI22: ='QTR Raw'!C14 -> 28.78 | AJ22: ='QTR Raw'!D14 -> 28.05 | AK22: ='QTR Raw'!E14 -> 31.03 | AL22: ='QTR Raw'!F14 -> 31.11 | AM22: ='QTR Raw'!G14 -> 32.84 | AN22: ='QTR Raw'!H14 -> 33.19 | AO22: ='QTR Raw'!I14 -> 35.19 | AP22: ='QTR Raw'!J14 -> 33.33 | ... CL22: ='QTR Raw'!BF14 -> 106.16 | CM22: =CM26-CM23 -> 82.032635 | CN22: =CN26-CN23 -> 96.383674 | CO22: =CO26-CO23 -> 98.304088 | CP22: =CP26-CP23 -> 92.77605 | CQ22: =CQ26-CQ23 -> 74.957773 | CR22: =CR26-CR23 -> 92.165269 | CS22: =CS26-CS23 -> 93.014599 | CT22: =CT26-CT23 -> 85.170143 | ... DA22: =DA26-DA23 -> 80.037274 | DE22: 389.42
A23: Employee Cost | B23: ='Annual Raw'!C14 -> 0 | C23: ='Annual Raw'!D14 -> 0 | D23: ='Annual Raw'!E14 -> 22.0504 | E23: ='Annual Raw'!F14 -> 26.0119 | F23: ='Annual Raw'!G14 -> 28.7538 | G23: ='Annual Raw'!H14 -> 30.7647 | H23: ='Annual Raw'!I14 -> 36.0581 | I23: ='Annual Raw'!J14 -> 41.7776 | ... AA23: ='Annual Raw'!AB14 -> 258.95 | AB23: =+SUM(CL23:CO23) -> 269.742 | AC23: =+SUM(CP23:CS23) -> 288.62394 | AD23: =+SUM(CT23:CW23) -> 308.82762 | AE23: =+SUM(CX23:DA23) -> 330.44555 | AI23: ='QTR Raw'!C16 -> 17.92 | AJ23: ='QTR Raw'!D16 -> 18.19 | AK23: ='QTR Raw'!E16 -> 18.34 | AL23: ='QTR Raw'!F16 -> 20.18 | AM23: ='QTR Raw'!G16 -> 22.05 | AN23: ='QTR Raw'!H16 -> 22.89 | AO23: ='QTR Raw'!I16 -> 18.98 | AP23: ='QTR Raw'!J16 -> 21.1 | ... CL23: ='QTR Raw'!BF16 -> 64.73 | CM23: =CI23*107% -> 76.1519 | CN23: =CJ23*107% -> 64.2535 | CO23: =CK23*107% -> 64.6066 | CP23: =CL23*107% -> 69.2611 | CQ23: =CM23*107% -> 81.482533 | CR23: =CN23*107% -> 68.751245 | CS23: =CO23*107% -> 69.129062 | CT23: =CP23*107% -> 74.109377 | ... DA23: =CW23*107% -> 79.145863 | DE23: 258.95
A24: General and Administration Expenses | B24: ='Annual Raw'!C17 -> 0 | C24: ='Annual Raw'!D17 -> 0 | D24: ='Annual Raw'!E17 -> 9.5995 | E24: ='Annual Raw'!F17 -> 9.5275 | F24: ='Annual Raw'!G17 -> 9.9198 | G24: ='Annual Raw'!H17 -> 9.9044 | H24: ='Annual Raw'!I17 -> 11.8175 | I24: ='Annual Raw'!J17 -> 13.9604 | ... AA24: ='Annual Raw'!AB17 -> 97.36 | AB24: =+SUM(CL24:CO24) -> 0 | AC24: =+SUM(CP24:CS24) -> 0 | AD24: =+SUM(CT24:CW24) -> 0 | AE24: =+SUM(CX24:DA24) -> 0 | AI24: ='QTR Raw'!C17 -> 0 | AJ24: ='QTR Raw'!D17 -> 0 | AK24: ='QTR Raw'!E17 -> 0 | AL24: ='QTR Raw'!F17 -> 0 | AM24: ='QTR Raw'!G17 -> 0 | AN24: ='QTR Raw'!H17 -> 0 | AO24: ='QTR Raw'!I17 -> 0 | AP24: ='QTR Raw'!J17 -> 0 | ... CL24: ='QTR Raw'!BF17 -> 0 | DE24: 0
A25: Miscellaneous Expenses | B25: ='Annual Raw'!C19-'Annual Raw'!C20 -> 0 | C25: ='Annual Raw'!D19-'Annual Raw'!D20 -> 0 | D25: ='Annual Raw'!E19-'Annual Raw'!E20 -> 4.4305 | E25: ='Annual Raw'!F19-'Annual Raw'!F20 -> 4.4523 | F25: ='Annual Raw'!G19-'Annual Raw'!G20 -> 4.3217 | G25: ='Annual Raw'!H19-'Annual Raw'!H20 -> 3.7147 | H25: ='Annual Raw'!I19-'Annual Raw'!I20 -> 4.8745 | I25: ='Annual Raw'!J19-'Annual Raw'!J20 -> 5.5657 | ... AA25: ='Annual Raw'!AB19-'Annual Raw'!AB20 -> 31.47 | AB25: =+SUM(CL25:CO25) -> 0 | AC25: =+SUM(CP25:CS25) -> 0 | AD25: =+SUM(CT25:CW25) -> 0 | AE25: =+SUM(CX25:DA25) -> 0 | DE25: 0
A26: Total Cost | B26: =+SUM(B20:B25) -> 0 | C26: =+SUM(C20:C25) -> 0 | D26: =+SUM(D20:D25) -> 60.7929 | E26: =+SUM(E20:E25) -> 70.2232 | F26: =+SUM(F20:F25) -> 76.1035 | G26: =+SUM(G20:G25) -> 83.6447 | H26: =+SUM(H20:H25) -> 100.204 | I26: =+SUM(I20:I25) -> 113.2255 | ... AE26: =+SUM(AE20:AE25) -> 629.1091 | AI26: =+SUM(AI20:AI25) -> 46.7 | AJ26: =+SUM(AJ20:AJ25) -> 46.24 | AK26: =+SUM(AK20:AK25) -> 49.37 | AL26: =+SUM(AL20:AL25) -> 51.29 | AM26: =+SUM(AM20:AM25) -> 54.89 | AN26: =+SUM(AN20:AN25) -> 56.08 | AO26: =+SUM(AO20:AO25) -> 54.17 | AP26: =+SUM(AP20:AP25) -> 54.43 | ... CL26: =+SUM(CL20:CL25) -> 170.89 | CM26: =CM27*CM10 -> 158.18454 | CN26: =CN27*CN10 -> 160.63717 | CO26: =CO27*CO10 -> 162.91069 | CP26: =CP27*CP10 -> 162.03715 | CQ26: =CQ27*CQ10 -> 156.44031 | CR26: =CR27*CR10 -> 160.91651 | CS26: =CS27*CS10 -> 162.14366 | CT26: =CT27*CT10 -> 159.27952 | ... DA26: =DA27*DA10 -> 159.18314 | DE26: 648.37
A27: Cost % | B27: =B26/B10 -> #DIV/0! | C27: =C26/C10 -> #DIV/0! | D27: =D26/D10 -> 0.18868807 | E27: =E26/E10 -> 0.18353349 | F27: =F26/F10 -> 0.19314575 | G27: =G26/G10 -> 0.19323713 | H27: =H26/H10 -> 0.19992622 | I27: =I26/I10 -> 0.19843673 | ... AE27: =AE26/AE10 -> 0.26387274 | AI27: =AI26/AI10 -> 0.19664814 | AJ27: =AJ26/AJ10 -> 0.20754039 | AK27: =AK26/AK10 -> 0.2154484 | AL27: =AL26/AL10 -> 0.19971964 | AM27: =AM26/AM10 -> 0.19848129 | AN27: =AN26/AN10 -> 0.20896523 | AO27: =AO26/AO10 -> 0.19255652 | AP27: =AP26/AP10 -> 0.18700612 | ... CL27: =CL26/CL10 -> 0.27873104 | CM27: =AVERAGE(CI27:CL27) -> 0.26327268 | CN27: =AVERAGE(CJ27:CM27) -> 0.26041568 | CO27: =AVERAGE(CK27:CN27) -> 0.26304461 | CP27: =AVERAGE(CL27:CO27) -> 0.266366 | CQ27: =AVERAGE(CM27:CP27) -> 0.26327474 | CR27: =AVERAGE(CN27:CQ27) -> 0.26327526 | CS27: =AVERAGE(CO27:CR27) -> 0.26399015 | CT27: =AVERAGE(CP27:CS27) -> 0.26422654 | ... DA27: =AVERAGE(CW27:CZ27) -> 0.26388319 | DE27: 0.26256069
A28: EBITDA | B28: =B16-B26 -> 0 | C28: =C16-C26 -> 0 | D28: =D16-D26 -> 56.0821 | E28: =E16-E26 -> 56.2684 | F28: =F16-F26 -> 50.8491 | G28: =G16-G26 -> 54.675 | H28: =H16-H26 -> 55.0118 | I28: =I16-I26 -> 55.8496 | ... AE28: =AE16-AE26 -> 183.1496 | AI28: =AI16-AI26 -> 24.18 | AJ28: =AJ16-AJ26 -> 17.7 | AK28: =AK16-AK26 -> 23.82 | AL28: =AL16-AL26 -> 31.11 | AM28: =AM16-AM26 -> 31.11 | AN28: =AN16-AN26 -> 24.93 | AO28: =AO16-AO26 -> 27.17 | AP28: =AP16-AP26 -> 31.5 | ... DA28: =DA16-DA26 -> 46.335032 | DE28: 190.82
A29: EBITDA Margins | B29: =B28/B10 -> #DIV/0! | C29: =C28/C10 -> #DIV/0! | D29: =D28/D10 -> 0.17406676 | E29: =E28/E10 -> 0.1470616 | F29: =F28/F10 -> 0.12905172 | G29: =G28/G10 -> 0.12631093 | H29: =H28/H10 -> 0.1097591 | I29: =I28/I10 -> 0.097880886 | ... AE29: =AE28/AE10 -> 0.07682004 | AI29: =AI28/AI10 -> 0.1018191 | AJ29: =AJ28/AJ10 -> 0.079443447 | AK29: =AK28/AK10 -> 0.10394938 | AL29: =AL28/AL10 -> 0.12114014 | AM29: =AM28/AM10 -> 0.11249322 | AN29: =AN28/AN10 -> 0.092894139 | AO29: =AO28/AO10 -> 0.096580407 | AP29: =AP28/AP10 -> 0.10822511 | ... DA29: =DA28/DA10 -> 0.076811128 | DE29: 0.077273519
A30: EBITDA YOY% | C30: =+IF(B28<0,1-C28/B28,C28/B28-1) -> #DIV/0! | D30: =+IF(C28<0,1-D28/C28,D28/C28-1) -> #DIV/0! | E30: =+IF(D28<0,1-E28/D28,E28/D28-1) -> 0.0033219155 | F30: =+IF(E28<0,1-F28/E28,F28/E28-1) -> -0.096311607 | G30: =+IF(F28<0,1-G28/F28,G28/F28-1) -> 0.07524027 | H30: =+IF(G28<0,1-H28/G28,H28/G28-1) -> 0.0061600366 | I30: =+IF(H28<0,1-I28/H28,I28/H28-1) -> 0.01522946 | J30: =+IF(I28<0,1-J28/I28,J28/I28-1) -> -0.11966424 | ... AE30: =+IF(AD28<0,1-AE28/AD28,AE28/AD28-1) -> -0.0086906208 | AM30: =+IF(AI28<0,1-AM28/AI28,AM28/AI28-1) -> 0.2866005 | AN30: =+IF(AJ28<0,1-AN28/AJ28,AN28/AJ28-1) -> 0.40847458 | AO30: =+IF(AK28<0,1-AO28/AK28,AO28/AK28-1) -> 0.14063812 | AP30: =+IF(AL28<0,1-AP28/AL28,AP28/AL28-1) -> 0.012536162 | AQ30: =+IF(AM28<0,1-AQ28/AM28,AQ28/AM28-1) -> 0.0099646416 | AR30: =+IF(AN28<0,1-AR28/AN28,AR28/AN28-1) -> 0.080625752 | AS30: =+IF(AO28<0,1-AS28/AO28,AS28/AO28-1) -> 0.054839897 | AT30: =+IF(AP28<0,1-AT28/AP28,AT28/AP28-1) -> 0.71777778 | ... CL30: =+IF(CH28<0,1-CL28/CH28,CL28/CH28-1) -> 0.031758327 | CM30: =+CM28/CI28-1 -> 0.094478892 | CN30: =+CN28/CJ28-1 -> -0.11513922 | CO30: =+CO28/CK28-1 -> -0.1140027 | CP30: =+CP28/CL28-1 -> 0.14031821 | CQ30: =+CQ28/CM28-1 -> -0.014134296 | CR30: =+CR28/CN28-1 -> -0.037876192 | CS30: =+CS28/CO28-1 -> -0.015711877 | CT30: =+CT28/CP28-1 -> 0.012762518 | ... DA30: =+DA28/CW28-1 -> -0.0085522284 | DE30: 0.69814007
A31: EBITDA QOQ% | AJ31: =+IF(AI28<0,1-AJ28/AI28,AJ28/AI28-1) -> -0.26799007 | AK31: =+IF(AJ28<0,1-AK28/AJ28,AK28/AJ28-1) -> 0.34576271 | AL31: =+IF(AK28<0,1-AL28/AK28,AL28/AK28-1) -> 0.30604534 | AM31: =+IF(AL28<0,1-AM28/AL28,AM28/AL28-1) -> 1.5543122e-15 | AN31: =+IF(AM28<0,1-AN28/AM28,AN28/AM28-1) -> -0.19864995 | AO31: =+IF(AN28<0,1-AO28/AN28,AO28/AN28-1) -> 0.089851584 | AP31: =+IF(AO28<0,1-AP28/AO28,AP28/AO28-1) -> 0.15936695 | AQ31: =+IF(AP28<0,1-AQ28/AP28,AQ28/AP28-1) -> -0.0025396825 | ... CI31: =+IF(CH28<0,1-CI28/CH28,CI28/CH28-1) -> 0.099664343 | CJ31: =+IF(CI28>1,CJ28/CI28-1,1-CJ28/CI28) -> 0.3026532 | CK31: =+IF(CJ28>1,CK28/CJ28-1,1-CK28/CJ28) -> -0.026315789 | CL31: =+IF(CK28>1,CL28/CK28-1,1-CL28/CK28) -> -0.26027397 | CM31: =+CM28/CL28-1 -> 0.16651291 | CN31: =+CN28/CM28-1 -> 0.053164876 | CO31: =+CO28/CN28-1 -> -0.025065183 | CP31: =+CP28/CO28-1 -> -0.047939466 | CQ31: =+CQ28/CP28-1 -> 0.0085124159 | CR31: =+CR28/CQ28-1 -> 0.027802262 | CS31: =+CS28/CR28-1 -> -0.0026057422 | CT31: =+CT28/CS28-1 -> -0.02039738 | ... DA31: =+DA28/CZ28-1 -> 0.0047628155
A32: Depreciation | B32: ='Annual Raw'!C27 -> 0 | C32: ='Annual Raw'!D27 -> 0 | D32: ='Annual Raw'!E27 -> 19.8197 | E32: ='Annual Raw'!F27 -> 21.5098 | F32: ='Annual Raw'!G27 -> 22.0886 | G32: ='Annual Raw'!H27 -> 24.936 | H32: ='Annual Raw'!I27 -> 23.059 | I32: ='Annual Raw'!J27 -> 28.8597 | ... AA32: ='Annual Raw'!AB27 -> 52.16 | AB32: =+SUM(CL32:CO32) -> 94.04 | AC32: =+SUM(CP32:CS32) -> 94.04 | AD32: =+SUM(CT32:CW32) -> 94.04 | AE32: =+SUM(CX32:DA32) -> 94.04 | AI32: ='QTR Raw'!C28 -> 8.64 | AJ32: ='QTR Raw'!D28 -> 8.74 | AK32: ='QTR Raw'!E28 -> 9.82 | AL32: ='QTR Raw'!F28 -> 10.26 | AM32: ='QTR Raw'!G28 -> 10.39 | AN32: ='QTR Raw'!H28 -> 10.6 | AO32: ='QTR Raw'!I28 -> 10.77 | AP32: ='QTR Raw'!J28 -> 10.93 | ... CL32: ='QTR Raw'!BF28 -> 23.51 | CM32: =CM33*CL134 -> 23.51 | CN32: =CN33*CM134 -> 23.51 | CO32: =CO33*CN134 -> 23.51 | CP32: =CP33*CO134 -> 23.51 | CQ32: =CQ33*CP134 -> 23.51 | CR32: =CR33*CQ134 -> 23.51 | CS32: =CS33*CR134 -> 23.51 | CT32: =CT33*CS134 -> 23.51 | ... DA32: =DA33*CZ134 -> 23.51 | DE32: 52.16
A33: Depreciation % of Net Block | B33: =+B32/B134 -> #DIV/0! | C33: =+C32/C134 -> #DIV/0! | D33: =+D32/D134 -> 0.18376399 | E33: =+E32/E134 -> 0.1966979 | F33: =+F32/F134 -> 0.16511397 | G33: =+G32/G134 -> 0.21377703 | H33: =+H32/H134 -> 0.20950804 | I33: =+I32/I134 -> 0.1623063 | ... AE33: =+AE32/AE134 -> 0.16860601 | AI33: =+AI32/AH134 -> #DIV/0! | AJ33: =+AJ32/AI134 -> 0.047319978 | AK33: =+AK32/AJ134 -> 0.053167298 | AL33: =+AL32/AK134 -> 0.045023697 | AM33: =+AM32/AL134 -> 0.045594172 | AN33: =+AN32/AM134 -> 0.046792919 | AO33: =+AO32/AN134 -> 0.047543372 | AP33: =+AP32/AO134 -> 0.048962953 | ... CE33: =+CE32/CD134 -> 0.02904292 | CF33: =+CF32/CE131 -> 0.023465773 | CG33: =+CG32/CF134 -> 0.026603527 | CH33: =+CH32/CG134 -> 0.023691192 | CI33: =+CI32/CH134 -> 0.024457233 | CJ33: =+CJ32/CI134 -> 0.022967279 | CK33: =+CK32/CJ134 -> 0.024347826 | CL33: =+CL32/CK134 -> 0.042151502 | CM33: =CL33 -> 0.042151502 | CN33: =CM33 -> 0.042151502 | CO33: =CN33 -> 0.042151502 | CP33: =CO33 -> 0.042151502 | CQ33: =CP33 -> 0.042151502 | CR33: =CQ33 -> 0.042151502 | CS33: =CR33 -> 0.042151502 | CT33: =CS33 -> 0.042151502 | ... DA33: =CZ33 -> 0.042151502 | DE33: 0.093518602
A34: EBIT | B34: =B28-B32 -> 0 | C34: =C28-C32 -> 0 | D34: =D28-D32 -> 36.2624 | E34: =E28-E32 -> 34.7586 | F34: =F28-F32 -> 28.7605 | G34: =G28-G32 -> 29.739 | H34: =H28-H32 -> 31.9528 | I34: =I28-I32 -> 26.9899 | ... AE34: =AE28-AE32 -> 89.109597 | AI34: =AI28-AI32 -> 15.54 | AJ34: =AJ28-AJ32 -> 8.96 | AK34: =AK28-AK32 -> 14 | AL34: =AL28-AL32 -> 20.85 | AM34: =AM28-AM32 -> 20.72 | AN34: =AN28-AN32 -> 14.33 | AO34: =AO28-AO32 -> 16.4 | AP34: =AP28-AP32 -> 20.57 | ... DA34: =DA28-DA32 -> 22.825032 | DE34: 138.66
A35: Other Income | B35: ='Annual Raw'!C23 -> 0 | C35: ='Annual Raw'!D23 -> 0 | D35: ='Annual Raw'!E23 -> 3.4891 | E35: ='Annual Raw'!F23 -> 4.4457 | F35: ='Annual Raw'!G23 -> 5.6584 | G35: ='Annual Raw'!H23 -> 9.6564 | H35: ='Annual Raw'!I23 -> 11.4766 | I35: ='Annual Raw'!J23 -> 11.822 | ... AA35: ='Annual Raw'!AB23 -> 35.22 | AB35: =+SUM(CL35:CO35) -> 22.12 | AC35: =+SUM(CP35:CS35) -> 0 | AD35: =+SUM(CT35:CW35) -> 0 | AE35: =+SUM(CX35:DA35) -> 0 | AI35: ='QTR Raw'!C23 -> 2.59 | AJ35: ='QTR Raw'!D23 -> 1.78 | AK35: ='QTR Raw'!E23 -> 1.72 | AL35: ='QTR Raw'!F23 -> 1.69 | AM35: ='QTR Raw'!G23 -> 2.01 | AN35: ='QTR Raw'!H23 -> 0.68 | AO35: ='QTR Raw'!I23 -> 0.77 | AP35: ='QTR Raw'!J23 -> 1.39 | ... CL35: ='QTR Raw'!BF23 -> 22.12 | DE35: 35.22
A36: Interest | B36: ='Annual Raw'!C25 -> 0 | C36: ='Annual Raw'!D25 -> 0 | D36: ='Annual Raw'!E25 -> 3.9831 | E36: ='Annual Raw'!F25 -> 1.2751 | F36: ='Annual Raw'!G25 -> 0.7696 | G36: ='Annual Raw'!H25 -> 0.705 | H36: ='Annual Raw'!I25 -> 0.6115 | I36: ='Annual Raw'!J25 -> 1.8473 | ... AA36: ='Annual Raw'!AB25 -> 17.31 | AB36: =+SUM(CL36:CO36) -> -68.548744 | AC36: =+SUM(CP36:CS36) -> -138.61989 | AD36: =+SUM(CT36:CW36) -> -198.55659 | AE36: =+SUM(CX36:DA36) -> -273.31789 | AI36: ='QTR Raw'!C25 -> 0 | AJ36: ='QTR Raw'!D25 -> 0 | AK36: ='QTR Raw'!E25 -> 0.57 | AL36: ='QTR Raw'!F25 -> 0.88 | AM36: ='QTR Raw'!G25 -> 0.95 | AN36: ='QTR Raw'!H25 -> 0.99 | AO36: ='QTR Raw'!I25 -> 0.93 | AP36: ='QTR Raw'!J25 -> 0.79 | ... CL36: ='QTR Raw'!BF25 -> 3.53 | CM36: =CM37*CL168 -> -21.137596 | CN36: =CN37*CM168 -> -24.48782 | CO36: =CO37*CN168 -> -26.453327 | CP36: =CP37*CO168 -> -29.261114 | CQ36: =CQ37*CP168 -> -32.90145 | CR36: =CR37*CQ168 -> -36.968917 | CS36: =CS37*CR168 -> -39.488405 | CT36: =CT37*CS168 -> -42.981769 | ... DA36: =DA37*CZ168 -> -76.001031 | DE36: 16.56
A37: Interest % of Debt | B37: =+B36/B128 -> #DIV/0! | C37: =+C36/C128 -> #DIV/0! | D37: =+D36/D128 -> 0.43410641 | E37: =+E36/E128 -> 0.12422548 | F37: =+F36/F128 -> 0.059105885 | G37: =+G36/G128 -> 0.043265602 | H37: =+H36/H128 -> 0.018105858 | I37: =+I36/I128 -> 0.027508536 | ... AE37: =+AE36/AE128 -> -2.6184891 | AI37: =(AI36-AI35)/AH168 -> #DIV/0! | AJ37: =(AJ36-AJ35)/AI168 -> 0.028200253 | AK37: =(AK36-AK35)/AJ168 -> 0.011174155 | AL37: =(AL36-AL35)/AK168 -> 0.030201342 | AM37: =(AM36-AM35)/AL168 -> 0.028781234 | AN37: =(AN36-AN35)/AM168 -> -0.045857988 | AO37: =(AO36-AO35)/AN168 -> -0.0035431149 | AP37: =(AP36-AP35)/AO168 -> 0.019940179 | ... CL37: =(CL36-CL35)/CK168 -> 0.078880103 | CM37: =+CL37 -> 0.078880103 | CN37: =+CM37 -> 0.078880103 | CO37: =+CN37 -> 0.078880103 | CP37: =+CO37 -> 0.078880103 | CQ37: =+CP37 -> 0.078880103 | CR37: =+CQ37 -> 0.078880103 | CS37: =+CR37 -> 0.078880103 | CT37: =+CS37 -> 0.078880103 | ... DA37: =+CZ37 -> 0.078880103 | DE37: 0.15865108
A38: PBT | B38: =B34+B35-B36 -> 0 | C38: =C34+C35-C36 -> 0 | D38: =D34+D35-D36 -> 35.7684 | E38: =E34+E35-E36 -> 37.9292 | F38: =F34+F35-F36 -> 33.6493 | G38: =G34+G35-G36 -> 38.6904 | H38: =H34+H35-H36 -> 42.8179 | I38: =I34+I35-I36 -> 36.9646 | ... AE38: =AE34+AE35-AE36 -> 362.42749 | AI38: =AI34+AI35-AI36 -> 18.13 | AJ38: =AJ34+AJ35-AJ36 -> 10.74 | AK38: =AK34+AK35-AK36 -> 15.15 | AL38: =AL34+AL35-AL36 -> 21.66 | AM38: =AM34+AM35-AM36 -> 21.78 | AN38: =AN34+AN35-AN36 -> 14.02 | AO38: =AO34+AO35-AO36 -> 16.24 | AP38: =AP34+AP35-AP36 -> 21.17 | ... DA38: =DA34+DA35-DA36 -> 98.826063 | DE38: 157.32
A39: Tax | B39: ='Annual Raw'!C30 -> 0 | C39: ='Annual Raw'!D30 -> 0 | D39: ='Annual Raw'!E30 -> 10.6214 | E39: ='Annual Raw'!F30 -> 10.0028 | F39: ='Annual Raw'!G30 -> 9.5394 | G39: ='Annual Raw'!H30 -> 10.2194 | H39: ='Annual Raw'!I30 -> 14.9674 | I39: ='Annual Raw'!J30 -> 5.4123 | ... AA39: ='Annual Raw'!AB30 -> 40.11 | AB39: =+SUM(CL39:CO39) -> 47.28934 | AC39: =+SUM(CP39:CS39) -> 60.377944 | AD39: =+SUM(CT39:CW39) -> 75.769042 | AE39: =+SUM(CX39:DA39) -> 94.929272 | AI39: ='QTR Raw'!C29 -> 4.77 | AJ39: ='QTR Raw'!D29 -> 1.96 | AK39: ='QTR Raw'!E29 -> 5.08 | AL39: ='QTR Raw'!F29 -> 5.5 | AM39: ='QTR Raw'!G29 -> 6.71 | AN39: ='QTR Raw'!H29 -> 4.78 | AO39: ='QTR Raw'!I29 -> 5.94 | AP39: ='QTR Raw'!J29 -> 5.07 | ... CL39: ='QTR Raw'!BF29 -> 9.44 | CM39: =+CM38*CM40 -> 11.476702 | CN39: =+CN38*CN40 -> 13.038429 | CO39: =+CO38*CO40 -> 13.33421 | CP39: =+CP38*CP40 -> 13.492597 | CQ39: =+CQ38*CQ40 -> 14.461951 | CR39: =+CR38*CR40 -> 15.88727 | CS39: =+CS38*CS40 -> 16.536126 | CT39: =+CT38*CT40 -> 17.19422 | ... DA39: =+DA38*DA40 -> 25.885911 | DE39: 40.11
A40: Tax Rate % | B40: =B39/B38 -> #DIV/0! | C40: =C39/C38 -> #DIV/0! | D40: =D39/D38 -> 0.29694926 | E40: =E39/E38 -> 0.26372294 | F40: =F39/F38 -> 0.28349475 | G40: =G39/G38 -> 0.2641327 | H40: =H39/H38 -> 0.34955941 | I40: =I39/I38 -> 0.14641847 | ... AE40: =AE39/AE38 -> 0.26192625 | AI40: =AI39/AI38 -> 0.26309983 | AJ40: =AJ39/AJ38 -> 0.18249534 | AK40: =AK39/AK38 -> 0.33531353 | AL40: =AL39/AL38 -> 0.25392428 | AM40: =AM39/AM38 -> 0.30808081 | AN40: =AN39/AN38 -> 0.34094151 | AO40: =AO39/AO38 -> 0.36576355 | AP40: =AP39/AP38 -> 0.23948984 | ... CL40: =CL39/CL38 -> 0.26940639 | CM40: =AVERAGE(CI40:CL40) -> 0.2594106 | CN40: =AVERAGE(CJ40:CM40) -> 0.26040455 | CO40: =AVERAGE(CK40:CN40) -> 0.26245912 | CP40: =AVERAGE(CL40:CO40) -> 0.26292017 | CQ40: =AVERAGE(CM40:CP40) -> 0.26129861 | CR40: =AVERAGE(CN40:CQ40) -> 0.26177061 | CS40: =AVERAGE(CO40:CR40) -> 0.26211213 | CT40: =AVERAGE(CP40:CS40) -> 0.26202538 | ... DA40: =AVERAGE(CW40:CZ40) -> 0.26193405 | DE40: 0.25495805
A41: PAT | B41: =B38-B39 -> 0 | C41: =C38-C39 -> 0 | D41: =D38-D39 -> 25.147 | E41: =E38-E39 -> 27.9264 | F41: =F38-F39 -> 24.1099 | G41: =G38-G39 -> 28.471 | H41: =H38-H39 -> 27.8505 | I41: =I38-I39 -> 31.5523 | ... AE41: =AE38-AE39 -> 267.49821 | AI41: =AI38-AI39 -> 13.36 | AJ41: =AJ38-AJ39 -> 8.78 | AK41: =AK38-AK39 -> 10.07 | AL41: =AL38-AL39 -> 16.16 | AM41: =AM38-AM39 -> 15.07 | AN41: =AN38-AN39 -> 9.24 | AO41: =AO38-AO39 -> 10.3 | AP41: =AP38-AP39 -> 16.1 | ... DA41: =DA38-DA39 -> 72.940152 | DE41: 117.21
A42: PAT % | B42: =+B41/B10 -> #DIV/0! | C42: =+C41/C10 -> #DIV/0! | D42: =+D41/D10 -> 0.078050873 | E42: =+E41/E10 -> 0.072987699 | F42: =+F41/F10 -> 0.061189363 | G42: =+G41/G10 -> 0.065774093 | H42: =+H41/H10 -> 0.055567094 | I42: =+I41/I10 -> 0.055297926 | ... AE42: =+AE41/AE10 -> 0.11219912 | AI42: =+AI41/AI10 -> 0.056257369 | AJ42: =+AJ41/AJ10 -> 0.03940754 | AK42: =+AK41/AK10 -> 0.043945014 | AL42: =+AL41/AL10 -> 0.062925899 | AM42: =+AM41/AM10 -> 0.054492858 | AN42: =+AN41/AN10 -> 0.034430078 | AO42: =+AO41/AO10 -> 0.03661311 | AP42: =+AP41/AP10 -> 0.055315055 | ... DA42: =+DA41/DA10 -> 0.12091532 | DE42: 0.047464779
A43: PAT YOY% | C43: =+IF(B41<0,1-C41/B41,C41/B41-1) -> #DIV/0! | D43: =+IF(C41<0,1-D41/C41,D41/C41-1) -> #DIV/0! | E43: =+IF(D41<0,1-E41/D41,E41/D41-1) -> 0.11052611 | F43: =+IF(E41<0,1-F41/E41,F41/E41-1) -> -0.1366628 | G43: =+IF(F41<0,1-G41/F41,G41/F41-1) -> 0.1808842 | H43: =+IF(G41<0,1-H41/G41,H41/G41-1) -> -0.021794106 | I43: =+IF(H41<0,1-I41/H41,I41/H41-1) -> 0.13291682 | J43: =+IF(I41<0,1-J41/I41,J41/I41-1) -> -0.32531701 | ... AE43: =+IF(AD41<0,1-AE41/AD41,AE41/AD41-1) -> 0.25290269 | AM43: =+IF(AI41<0,1-AM41/AI41,AM41/AI41-1) -> 0.12799401 | AN43: =+IF(AJ41<0,1-AN41/AJ41,AN41/AJ41-1) -> 0.0523918 | AO43: =+IF(AK41<0,1-AO41/AK41,AO41/AK41-1) -> 0.022840119 | AP43: =+IF(AL41<0,1-AP41/AL41,AP41/AL41-1) -> -0.0037128713 | AQ43: =+IF(AM41<0,1-AQ41/AM41,AQ41/AM41-1) -> 0.10218978 | AR43: =+IF(AN41<0,1-AR41/AN41,AR41/AN41-1) -> 0.49134199 | AS43: =+IF(AO41<0,1-AS41/AO41,AS41/AO41-1) -> 0.52815534 | AT43: =+IF(AP41<0,1-AT41/AP41,AT41/AP41-1) -> 0.32173913 | ... CL43: =+IF(CH41<0,1-CL41/CH41,CL41/CH41-1) -> 0.0047095761 | CM43: =+CM41/CI41-1 -> 0.3286598 | CN43: =+CN41/CJ41-1 -> 0.0071108762 | CO43: =+CO41/CK41-1 -> 0.23665648 | CP43: =+CP41/CL41-1 -> 0.47756375 | CQ43: =+CQ41/CM41-1 -> 0.24781968 | CR43: =+CR41/CN41-1 -> 0.20989812 | CS43: =+CS41/CO41-1 -> 0.24235385 | CT43: =+CT41/CP41-1 -> 0.2802487 | ... DA43: =+DA41/CW41-1 -> 0.25170474 | DE43: 1.0527145
...

Sheet QTR Raw
A1: ='Annual Raw'!A1 -> 109820 | B1: X | C1: 201206 | D1: 201209 | E1: 201212 | F1: 201303 | G1: 201306 | H1: 201309 | I1: 201312 | J1: 201403 | K1: 201406 | L1: 201409 | M1: 201412 | N1: 201503 | O1: 201506 | P1: 201509 | Q1: 201512 | R1: 201603 | S1: 201606 | T1: 201609 | U1: 201612 | V1: 201703 | W1: 201706 | X1: 201709 | Y1: 201712 | Z1: 201803 | AA1: 201806 | AB1: 201809 | AC1: 201812 | AD1: 201903 | AE1: 201906 | AF1: 201909 | AG1: 201912 | AH1: 202003 | AI1: 202006 | AJ1: 202009 | AK1: 202012 | AL1: 202103 | AM1: 202106 | AN1: 202109 | AO1: 202112 | AP1: 202203 | AQ1: 202206 | AR1: 202209 | AS1: 202212 | AT1: 202303 | AU1: 202306 | AV1: 202309 | AW1: 202312 | AX1: 202403 | AY1: 202406 | AZ1: 202409 | BA1: 202412 | BB1: 202503 | BC1: 202506 | BD1: 202509 | BE1: 202512 | BF1: 202603 | BG1: 202606 | BH1: 202609 | BI1: 202612 | BJ1: 202703 | BK1: 202706 | BL1: 202709 | BM1: 202712 | BN1: 202803 | BO1: 202806 | BP1: 202809 | BQ1: 202812 | BR1: 202903 | BS1: 202906 | BT1: 202909 | BU1: 202912
A3: Field Description | B3: Field Name
A4: Company Name | B4: CD_COMPNAME | C4: =_xll.EQNXTDZ(A1,B4,C1) -> Huhtamaki India Ltd.
A5: Date End | B5: QTR_DATE_END | C5: =_xll.EQNXTDZ($A$1,$B5,C$1,$B$1) -> 201206 | D5: =_xll.EQNXTDZ($A$1,$B5,D$1,$B$1) -> 201209 | E5: =_xll.EQNXTDZ($A$1,$B5,E$1,$B$1) -> 201212 | F5: =_xll.EQNXTDZ($A$1,$B5,F$1,$B$1) -> 201303 | G5: =_xll.EQNXTDZ($A$1,$B5,G$1,$B$1) -> 201306 | H5: =_xll.EQNXTDZ($A$1,$B5,H$1,$B$1) -> 201309 | I5: =_xll.EQNXTDZ($A$1,$B5,I$1,$B$1) -> 201312 | J5: =_xll.EQNXTDZ($A$1,$B5,J$1,$B$1) -> 201403 | ... BU5: =_xll.EQNXTDZ($A$1,$B5,BU$1,$B$1) -> 0
A6: Gross Sales | B6: QTR_GROSS_SALE | C6: =_xll.EQNXTDZ($A$1,$B6,C$1,$B$1) -> 253.76 | D6: =_xll.EQNXTDZ($A$1,$B6,D$1,$B$1) -> 235.39 | E6: =_xll.EQNXTDZ($A$1,$B6,E$1,$B$1) -> 243.41 | F6: =_xll.EQNXTDZ($A$1,$B6,F$1,$B$1) -> 273.21 | G6: =_xll.EQNXTDZ($A$1,$B6,G$1,$B$1) -> 294.64 | H6: =_xll.EQNXTDZ($A$1,$B6,H$1,$B$1) -> 282.76 | I6: =_xll.EQNXTDZ($A$1,$B6,I$1,$B$1) -> 297.41 | J6: =_xll.EQNXTDZ($A$1,$B6,J$1,$B$1) -> 309.59 | ... BU6: =_xll.EQNXTDZ($A$1,$B6,BU$1,$B$1) -> 0
A7: Less: Excise Duty | B7: QTR_EXCISE_DUTY | C7: =_xll.EQNXTDZ($A$1,$B7,C$1,$B$1) -> 16.98 | D7: =_xll.EQNXTDZ($A$1,$B7,D$1,$B$1) -> 14.36 | E7: =_xll.EQNXTDZ($A$1,$B7,E$1,$B$1) -> 15.86 | F7: =_xll.EQNXTDZ($A$1,$B7,F$1,$B$1) -> 18.48 | G7: =_xll.EQNXTDZ($A$1,$B7,G$1,$B$1) -> 18.9 | H7: =_xll.EQNXTDZ($A$1,$B7,H$1,$B$1) -> 17.45 | I7: =_xll.EQNXTDZ($A$1,$B7,I$1,$B$1) -> 18.39 | J7: =_xll.EQNXTDZ($A$1,$B7,J$1,$B$1) -> 20.56 | ... BU7: =_xll.EQNXTDZ($A$1,$B7,BU$1,$B$1) -> 0
A8: Other operating income | B8: QTR_JOB_WORKS | C8: =_xll.EQNXTDZ($A$1,$B8,C$1,$B$1) -> 1.79 | D8: =_xll.EQNXTDZ($A$1,$B8,D$1,$B$1) -> 2.01 | E8: =_xll.EQNXTDZ($A$1,$B8,E$1,$B$1) -> 1.84 | F8: =_xll.EQNXTDZ($A$1,$B8,F$1,$B$1) -> 2.08 | G8: =_xll.EQNXTDZ($A$1,$B8,G$1,$B$1) -> 2.04 | H8: =_xll.EQNXTDZ($A$1,$B8,H$1,$B$1) -> 4.13 | I8: =_xll.EQNXTDZ($A$1,$B8,I$1,$B$1) -> 2.45 | J8: =_xll.EQNXTDZ($A$1,$B8,J$1,$B$1) -> 2.55 | ... BU8: =_xll.EQNXTDZ($A$1,$B8,BU$1,$B$1) -> 0
A9: Net Sales & Other Operating Income | B9: QTR_NET_SALES | C9: =_xll.EQNXTDZ($A$1,$B9,C$1,$B$1) -> 238.57 | D9: =_xll.EQNXTDZ($A$1,$B9,D$1,$B$1) -> 223.04 | E9: =_xll.EQNXTDZ($A$1,$B9,E$1,$B$1) -> 229.39 | F9: =_xll.EQNXTDZ($A$1,$B9,F$1,$B$1) -> 256.81 | G9: =_xll.EQNXTDZ($A$1,$B9,G$1,$B$1) -> 277.78 | H9: =_xll.EQNXTDZ($A$1,$B9,H$1,$B$1) -> 269.44 | I9: =_xll.EQNXTDZ($A$1,$B9,I$1,$B$1) -> 281.47 | J9: =_xll.EQNXTDZ($A$1,$B9,J$1,$B$1) -> 291.58 | ... BU9: =_xll.EQNXTDZ($A$1,$B9,BU$1,$B$1) -> 0
A10: (Increase) / Decrease In Stocks | B10: QTR_INC_DEC_INVENTORY | C10: =_xll.EQNXTDZ($A$1,$B10,C$1,$B$1) -> -1.23 | D10: =_xll.EQNXTDZ($A$1,$B10,D$1,$B$1) -> -2.47 | E10: =_xll.EQNXTDZ($A$1,$B10,E$1,$B$1) -> 2.45 | F10: =_xll.EQNXTDZ($A$1,$B10,F$1,$B$1) -> -2.98 | G10: =_xll.EQNXTDZ($A$1,$B10,G$1,$B$1) -> -2.74 | H10: =_xll.EQNXTDZ($A$1,$B10,H$1,$B$1) -> 3 | I10: =_xll.EQNXTDZ($A$1,$B10,I$1,$B$1) -> 5.15 | J10: =_xll.EQNXTDZ($A$1,$B10,J$1,$B$1) -> -6.94 | ... BU10: =_xll.EQNXTDZ($A$1,$B10,BU$1,$B$1) -> 0
A11: Cost of Services & Raw Materials | B11: QTR_RAW_MATERIAL_COST | C11: =_xll.EQNXTDZ($A$1,$B11,C$1,$B$1) -> 167.83 | D11: =_xll.EQNXTDZ($A$1,$B11,D$1,$B$1) -> 161.33 | E11: =_xll.EQNXTDZ($A$1,$B11,E$1,$B$1) -> 153.51 | F11: =_xll.EQNXTDZ($A$1,$B11,F$1,$B$1) -> 177.39 | G11: =_xll.EQNXTDZ($A$1,$B11,G$1,$B$1) -> 193.29 | H11: =_xll.EQNXTDZ($A$1,$B11,H$1,$B$1) -> 184.36 | I11: =_xll.EQNXTDZ($A$1,$B11,I$1,$B$1) -> 194.83 | J11: =_xll.EQNXTDZ($A$1,$B11,J$1,$B$1) -> 212.07 | ... BU11: =_xll.EQNXTDZ($A$1,$B11,BU$1,$B$1) -> 0
A12: Purchase of Finished Goods | B12: QTR_PURCHASE_FIN_GOOD | C12: =_xll.EQNXTDZ($A$1,$B12,C$1,$B$1) -> 0 | D12: =_xll.EQNXTDZ($A$1,$B12,D$1,$B$1) -> 0 | E12: =_xll.EQNXTDZ($A$1,$B12,E$1,$B$1) -> 0 | F12: =_xll.EQNXTDZ($A$1,$B12,F$1,$B$1) -> 0 | G12: =_xll.EQNXTDZ($A$1,$B12,G$1,$B$1) -> 0 | H12: =_xll.EQNXTDZ($A$1,$B12,H$1,$B$1) -> 0 | I12: =_xll.EQNXTDZ($A$1,$B12,I$1,$B$1) -> 0 | J12: =_xll.EQNXTDZ($A$1,$B12,J$1,$B$1) -> 0 | ... BU12: =_xll.EQNXTDZ($A$1,$B12,BU$1,$B$1) -> 0
A13: Excise Duty | B13: QTR_EXCISE | C13: =_xll.EQNXTDZ($A$1,$B13,C$1,$B$1) -> 0 | D13: =_xll.EQNXTDZ($A$1,$B13,D$1,$B$1) -> 0 | E13: =_xll.EQNXTDZ($A$1,$B13,E$1,$B$1) -> 0 | F13: =_xll.EQNXTDZ($A$1,$B13,F$1,$B$1) -> 0 | G13: =_xll.EQNXTDZ($A$1,$B13,G$1,$B$1) -> 0 | H13: =_xll.EQNXTDZ($A$1,$B13,H$1,$B$1) -> 0 | I13: =_xll.EQNXTDZ($A$1,$B13,I$1,$B$1) -> 0 | J13: =_xll.EQNXTDZ($A$1,$B13,J$1,$B$1) -> 0 | ... BU13: =_xll.EQNXTDZ($A$1,$B13,BU$1,$B$1) -> 0
A14: Operating & Manufacturing Expenses | B14: QTR_MFG_EXPS | C14: =_xll.EQNXTDZ($A$1,$B14,C$1,$B$1) -> 28.78 | D14: =_xll.EQNXTDZ($A$1,$B14,D$1,$B$1) -> 28.05 | E14: =_xll.EQNXTDZ($A$1,$B14,E$1,$B$1) -> 31.03 | F14: =_xll.EQNXTDZ($A$1,$B14,F$1,$B$1) -> 31.11 | G14: =_xll.EQNXTDZ($A$1,$B14,G$1,$B$1) -> 32.84 | H14: =_xll.EQNXTDZ($A$1,$B14,H$1,$B$1) -> 33.19 | I14: =_xll.EQNXTDZ($A$1,$B14,I$1,$B$1) -> 35.19 | J14: =_xll.EQNXTDZ($A$1,$B14,J$1,$B$1) -> 33.33 | ... BU14: =_xll.EQNXTDZ($A$1,$B14,BU$1,$B$1) -> 0
A15: Electricity Power & Fuel Cost | B15: QTR_ELECTRICITY_POWER_FUEL | C15: =_xll.EQNXTDZ($A$1,$B15,C$1,$B$1) -> 0 | D15: =_xll.EQNXTDZ($A$1,$B15,D$1,$B$1) -> 0 | E15: =_xll.EQNXTDZ($A$1,$B15,E$1,$B$1) -> 0 | F15: =_xll.EQNXTDZ($A$1,$B15,F$1,$B$1) -> 0 | G15: =_xll.EQNXTDZ($A$1,$B15,G$1,$B$1) -> 0 | H15: =_xll.EQNXTDZ($A$1,$B15,H$1,$B$1) -> 0 | I15: =_xll.EQNXTDZ($A$1,$B15,I$1,$B$1) -> 0 | J15: =_xll.EQNXTDZ($A$1,$B15,J$1,$B$1) -> 0 | ... BU15: =_xll.EQNXTDZ($A$1,$B15,BU$1,$B$1) -> 0
A16: Employee Cost | B16: QTR_EXPLOYEE_COST | C16: =_xll.EQNXTDZ($A$1,$B16,C$1,$B$1) -> 17.92 | D16: =_xll.EQNXTDZ($A$1,$B16,D$1,$B$1) -> 18.19 | E16: =_xll.EQNXTDZ($A$1,$B16,E$1,$B$1) -> 18.34 | F16: =_xll.EQNXTDZ($A$1,$B16,F$1,$B$1) -> 20.18 | G16: =_xll.EQNXTDZ($A$1,$B16,G$1,$B$1) -> 22.05 | H16: =_xll.EQNXTDZ($A$1,$B16,H$1,$B$1) -> 22.89 | I16: =_xll.EQNXTDZ($A$1,$B16,I$1,$B$1) -> 18.98 | J16: =_xll.EQNXTDZ($A$1,$B16,J$1,$B$1) -> 21.1 | ... BU16: =_xll.EQNXTDZ($A$1,$B16,BU$1,$B$1) -> 0
... A42: Consolidated PAT(after extra items) | B42: QTR_CONS_PAT_EXITM | C42: =_xll.EQNXTDZ($A$1,$B42,C$1,$B$1) -> 13.36 | D42: =_xll.EQNXTDZ($A$1,$B42,D$1,$B$1) -> 8.78 | E42: =_xll.EQNXTDZ($A$1,$B42,E$1,$B$1) -> 10.03 | F42: =_xll.EQNXTDZ($A$1,$B42,F$1,$B$1) -> 15.63 | G42: =_xll.EQNXTDZ($A$1,$B42,G$1,$B$1) -> 14.77 | H42: =_xll.EQNXTDZ($A$1,$B42,H$1,$B$1) -> 9.15 | I42: =_xll.EQNXTDZ($A$1,$B42,I$1,$B$1) -> 16.66 | J42: =_xll.EQNXTDZ($A$1,$B42,J$1,$B$1) -> 16.92 | ... BU42: =_xll.EQNXTDZ($A$1,$B42,BU$1,$B$1) -> 0
A44: Field Description | B44: Field Name
A45: Equity Capital | B45: QTR_EQUITY_CAP | C45: =_xll.EQNXTDZ($A$1,$B45,C$1,$B$1) -> 12.54 | D45: =_xll.EQNXTDZ($A$1,$B45,D$1,$B$1) -> 12.54 | E45: =_xll.EQNXTDZ($A$1,$B45,E$1,$B$1) -> 12.54 | F45: =_xll.EQNXTDZ($A$1,$B45,F$1,$B$1) -> 12.54 | G45: =_xll.EQNXTDZ($A$1,$B45,G$1,$B$1) -> 12.54 | H45: =_xll.EQNXTDZ($A$1,$B45,H$1,$B$1) -> 12.54 | I45: =_xll.EQNXTDZ($A$1,$B45,I$1,$B$1) -> 12.54 | J45: =_xll.EQNXTDZ($A$1,$B45,J$1,$B$1) -> 12.54 | ... BU45: =_xll.EQNXTDZ($A$1,$B45,BU$1,$B$1) -> 0
A46: Face Value | B46: QTR_FV | C46: =_xll.EQNXTDZ($A$1,$B46,C$1,$B$1) -> 2 | D46: =_xll.EQNXTDZ($A$1,$B46,D$1,$B$1) -> 2 | E46: =_xll.EQNXTDZ($A$1,$B46,E$1,$B$1) -> 2 | F46: =_xll.EQNXTDZ($A$1,$B46,F$1,$B$1) -> 2 | G46: =_xll.EQNXTDZ($A$1,$B46,G$1,$B$1) -> 2 | H46: =_xll.EQNXTDZ($A$1,$B46,H$1,$B$1) -> 2 | I46: =_xll.EQNXTDZ($A$1,$B46,I$1,$B$1) -> 2 | J46: =_xll.EQNXTDZ($A$1,$B46,J$1,$B$1) -> 2 | ... BU46: =_xll.EQNXTDZ($A$1,$B46,BU$1,$B$1) -> 0
A47: Month End | B47: BMONTH_MONTHEND | C47: =_xll.EQNXTDZ($A$1,$B47,C$5) -> 201206 | D47: =_xll.EQNXTDZ($A$1,$B47,D$5) -> 201209 | E47: =_xll.EQNXTDZ($A$1,$B47,E$5) -> 201212 | F47: =_xll.EQNXTDZ($A$1,$B47,F$5) -> 201303 | G47: =_xll.EQNXTDZ($A$1,$B47,G$5) -> 201306 | H47: =_xll.EQNXTDZ($A$1,$B47,H$5) -> 201309 | I47: =_xll.EQNXTDZ($A$1,$B47,I$5) -> 201312 | J47: =_xll.EQNXTDZ($A$1,$B47,J$5) -> 201403 | ... BU47: =_xll.EQNXTDZ($A$1,$B47,BU$5) -> 0
A48: Close | B48: BMONTH_CLOSE | C48: =_xll.EQNXTDZ($A$1,$B48,C$5) -> 71.4 | D48: =_xll.EQNXTDZ($A$1,$B48,D$5) -> 71.65 | E48: =_xll.EQNXTDZ($A$1,$B48,E$5) -> 72.35 | F48: =_xll.EQNXTDZ($A$1,$B48,F$5) -> 62.15 | G48: =_xll.EQNXTDZ($A$1,$B48,G$5) -> 62.85 | H48: =_xll.EQNXTDZ($A$1,$B48,H$5) -> 60.1 | I48: =_xll.EQNXTDZ($A$1,$B48,I$5) -> 74.6 | J48: =_xll.EQNXTDZ($A$1,$B48,J$5) -> 89.5 | ... BU48: =_xll.EQNXTDZ($A$1,$B48,BU$5) -> 0
A49: Total of Promoter and Promoter Group | B49: SHP_TPFTOTALPROMOTER | C49: =_xll.EQNXTDZ($A$1,$B49,C$5) -> 63.7 | D49: =_xll.EQNXTDZ($A$1,$B49,D$5) -> 63.7 | E49: =_xll.EQNXTDZ($A$1,$B49,E$5) -> 63.7 | F49: =_xll.EQNXTDZ($A$1,$B49,F$5) -> 63.7 | G49: =_xll.EQNXTDZ($A$1,$B49,G$5) -> 63.7 | H49: =_xll.EQNXTDZ($A$1,$B49,H$5) -> 63.78 | I49: =_xll.EQNXTDZ($A$1,$B49,I$5) -> 63.78 | J49: =_xll.EQNXTDZ($A$1,$B49,J$5) -> 63.78 | ... BU49: =_xll.EQNXTDZ($A$1,$B49,BU$5) -> 0
A50: Total of Promoter and Promoter Group Pledged | B50: SHP_PSHFTOTALPROMOTER | C50: =_xll.EQNXTDZ($A$1,$B50,C$5) -> 0 | D50: =_xll.EQNXTDZ($A$1,$B50,D$5) -> 0 | E50: =_xll.EQNXTDZ($A$1,$B50,E$5) -> 0 | F50: =_xll.EQNXTDZ($A$1,$B50,F$5) -> 0 | G50: =_xll.EQNXTDZ($A$1,$B50,G$5) -> 0 | H50: =_xll.EQNXTDZ($A$1,$B50,H$5) -> 0 | I50: =_xll.EQNXTDZ($A$1,$B50,I$5) -> 0 | J50: =_xll.EQNXTDZ($A$1,$B50,J$5) -> 0 | ... BU50: =_xll.EQNXTDZ($A$1,$B50,BU$5) -> 0
A54: Field Description | B54: Field Name | C54: =_xll.EQNXTDZ($A$1,$B54,C$5) -> 0 | D54: =_xll.EQNXTDZ($A$1,$B54,D$5) -> 0 | E54: =_xll.EQNXTDZ($A$1,$B54,E$5) -> 0 | F54: =_xll.EQNXTDZ($A$1,$B54,F$5) -> 0 | G54: =_xll.EQNXTDZ($A$1,$B54,G$5) -> 0 | H54: =_xll.EQNXTDZ($A$1,$B54,H$5) -> 0 | I54: =_xll.EQNXTDZ($A$1,$B54,I$5) -> 0 | J54: =_xll.EQNXTDZ($A$1,$B54,J$5) -> 0 | ... BU54: =_xll.EQNXTDZ($A$1,$B54,BU$5) -> 0
A55: Year End | B55: QTRB_DATE_END | C55: =_xll.EQNXTDZ($A$1,$B55,C$5,$B$1) -> 201206 | D55: =_xll.EQNXTDZ($A$1,$B55,D$5,$B$1) -> 0 | E55: =_xll.EQNXTDZ($A$1,$B55,E$5,$B$1) -> 201212 | F55: =_xll.EQNXTDZ($A$1,$B55,F$5,$B$1) -> 0 | G55: =_xll.EQNXTDZ($A$1,$B55,G$5,$B$1) -> 201306 | H55: =_xll.EQNXTDZ($A$1,$B55,H$5,$B$1) -> 0 | I55: =_xll.EQNXTDZ($A$1,$B55,I$5,$B$1) -> 201312 | J55: =_xll.EQNXTDZ($A$1,$B55,J$5,$B$1) -> 0 | ... BU55: =_xll.EQNXTDZ($A$1,$B55,BU$5,$B$1) -> 0
A56: Share Capital | B56: QTRB_SHARE_CAPITAL | C56: =_xll.EQNXTDZ($A$1,$B56,C$5,$B$1) -> 12.54 | D56: =_xll.EQNXTDZ($A$1,$B56,D$5,$B$1) -> 0 | E56: =_xll.EQNXTDZ($A$1,$B56,E$5,$B$1) -> 12.54 | F56: =_xll.EQNXTDZ($A$1,$B56,F$5,$B$1) -> 0 | G56: =_xll.EQNXTDZ($A$1,$B56,G$5,$B$1) -> 12.54 | H56: =_xll.EQNXTDZ($A$1,$B56,H$5,$B$1) -> 0 | I56: =_xll.EQNXTDZ($A$1,$B56,I$5,$B$1) -> 12.54 | J56: =_xll.EQNXTDZ($A$1,$B56,J$5,$B$1) -> 0 | ... BU56: =_xll.EQNXTDZ($A$1,$B56,BU$5,$B$1) -> 0
A57: Share Warrants & outstandings | B57: QTRB_SHAREWARNDOUT | C57: =_xll.EQNXTDZ($A$1,$B57,C$5,$B$1) -> 0 | D57: =_xll.EQNXTDZ($A$1,$B57,D$5,$B$1) -> 0 | E57: =_xll.EQNXTDZ($A$1,$B57,E$5,$B$1) -> 0 | F57: =_xll.EQNXTDZ($A$1,$B57,F$5,$B$1) -> 0 | G57: =_xll.EQNXTDZ($A$1,$B57,G$5,$B$1) -> 0 | H57: =_xll.EQNXTDZ($A$1,$B57,H$5,$B$1) -> 0 | I57: =_xll.EQNXTDZ($A$1,$B57,I$5,$B$1) -> 0 | J57: =_xll.EQNXTDZ($A$1,$B57,J$5,$B$1) -> 0 | ... BU57: =_xll.EQNXTDZ($A$1,$B57,BU$5,$B$1) -> 0
A58: Reserves & Surplus | B58: QTRB_RESERVE | C58: =_xll.EQNXTDZ($A$1,$B58,C$5,$B$1) -> 342.57 | D58: =_xll.EQNXTDZ($A$1,$B58,D$5,$B$1) -> 0 | E58: =_xll.EQNXTDZ($A$1,$B58,E$5,$B$1) -> 342.42 | F58: =_xll.EQNXTDZ($A$1,$B58,F$5,$B$1) -> 0 | G58: =_xll.EQNXTDZ($A$1,$B58,G$5,$B$1) -> 372.7 | H58: =_xll.EQNXTDZ($A$1,$B58,H$5,$B$1) -> 0 | I58: =_xll.EQNXTDZ($A$1,$B58,I$5,$B$1) -> 378.26 | J58: =_xll.EQNXTDZ($A$1,$B58,J$5,$B$1) -> 0 | ... BU58: =_xll.EQNXTDZ($A$1,$B58,BU$5,$B$1) -> 0
A59: Shareholder's Funds | B59: QTRB_SHAREHODERS_FUNDS | C59: =_xll.EQNXTDZ($A$1,$B59,C$5,$B$1) -> 355.11 | D59: =_xll.EQNXTDZ($A$1,$B59,D$5,$B$1) -> 0 | E59: =_xll.EQNXTDZ($A$1,$B59,E$5,$B$1) -> 354.96 | F59: =_xll.EQNXTDZ($A$1,$B59,F$5,$B$1) -> 0 | G59: =_xll.EQNXTDZ($A$1,$B59,G$5,$B$1) -> 385.24 | H59: =_xll.EQNXTDZ($A$1,$B59,H$5,$B$1) -> 0 | I59: =_xll.EQNXTDZ($A$1,$B59,I$5,$B$1) -> 390.8 | J59: =_xll.EQNXTDZ($A$1,$B59,J$5,$B$1) -> 0 | ... BU59: =_xll.EQNXTDZ($A$1,$B59,BU$5,$B$1) -> 0
A60: Minority Interest | B60: QTRB_MINORITY_INTEREST_BS | C60: =_xll.EQNXTDZ($A$1,$B60,C$5,$B$1) -> 0 | D60: =_xll.EQNXTDZ($A$1,$B60,D$5,$B$1) -> 0 | E60: =_xll.EQNXTDZ($A$1,$B60,E$5,$B$1) -> 18.52 | F60: =_xll.EQNXTDZ($A$1,$B60,F$5,$B$1) -> 0 | G60: =_xll.EQNXTDZ($A$1,$B60,G$5,$B$1) -> 19.35 | H60: =_xll.EQNXTDZ($A$1,$B60,H$5,$B$1) -> 0 | I60: =_xll.EQNXTDZ($A$1,$B60,I$5,$B$1) -> 20.13 | J60: =_xll.EQNXTDZ($A$1,$B60,J$5,$B$1) -> 0 | ... BU60: =_xll.EQNXTDZ($A$1,$B60,BU$5,$B$1) -> 0
A61: Long Term Borrowings | B61: QTRB_TOTAL_DEBTS | C61: =_xll.EQNXTDZ($A$1,$B61,C$5,$B$1) -> 20.61 | D61: =_xll.EQNXTDZ($A$1,$B61,D$5,$B$1) -> 0 | E61: =_xll.EQNXTDZ($A$1,$B61,E$5,$B$1) -> 34.26 | F61: =_xll.EQNXTDZ($A$1,$B61,F$5,$B$1) -> 0 | G61: =_xll.EQNXTDZ($A$1,$B61,G$5,$B$1) -> 36.09 | H61: =_xll.EQNXTDZ($A$1,$B61,H$5,$B$1) -> 0 | I61: =_xll.EQNXTDZ($A$1,$B61,I$5,$B$1) -> 39.91 | J61: =_xll.EQNXTDZ($A$1,$B61,J$5,$B$1) -> 0 | ... BU61: =_xll.EQNXTDZ($A$1,$B61,BU$5,$B$1) -> 0
A62: Secured Loans | B62: QTRB_SECURED_LOANS | C62: =_xll.EQNXTDZ($A$1,$B62,C$5,$B$1) -> 0 | D62: =_xll.EQNXTDZ($A$1,$B62,D$5,$B$1) -> 0 | E62: =_xll.EQNXTDZ($A$1,$B62,E$5,$B$1) -> 0 | F62: =_xll.EQNXTDZ($A$1,$B62,F$5,$B$1) -> 0 | G62: =_xll.EQNXTDZ($A$1,$B62,G$5,$B$1) -> 0 | H62: =_xll.EQNXTDZ($A$1,$B62,H$5,$B$1) -> 0 | I62: =_xll.EQNXTDZ($A$1,$B62,I$5,$B$1) -> 0 | J62: =_xll.EQNXTDZ($A$1,$B62,J$5,$B$1) -> 0 | ... BU62: =_xll.EQNXTDZ($A$1,$B62,BU$5,$B$1) -> 0
A63: Unsecured Loans | B63: QTRB_UNSECURED_LOANS_NF | C63: =_xll.EQNXTDZ($A$1,$B63,C$5,$B$1) -> 20.61 | D63: =_xll.EQNXTDZ($A$1,$B63,D$5,$B$1) -> 0 | E63: =_xll.EQNXTDZ($A$1,$B63,E$5,$B$1) -> 34.26 | F63: =_xll.EQNXTDZ($A$1,$B63,F$5,$B$1) -> 0 | G63: =_xll.EQNXTDZ($A$1,$B63,G$5,$B$1) -> 36.09 | H63: =_xll.EQNXTDZ($A$1,$B63,H$5,$B$1) -> 0 | I63: =_xll.EQNXTDZ($A$1,$B63,I$5,$B$1) -> 39.91 | J63: =_xll.EQNXTDZ($A$1,$B63,J$5,$B$1) -> 0 | ... BU63: =_xll.EQNXTDZ($A$1,$B63,BU$5,$B$1) -> 0
A64: Other Long Term Liabilities | B64: QTRB_OTHER_LT_LIABILITIES | C64: =_xll.EQNXTDZ($A$1,$B64,C$5,$B$1) -> 0 | D64: =_xll.EQNXTDZ($A$1,$B64,D$5,$B$1) -> 0 | E64: =_xll.EQNXTDZ($A$1,$B64,E$5,$B$1) -> 0 | F64: =_xll.EQNXTDZ($A$1,$B64,F$5,$B$1) -> 0 | G64: =_xll.EQNXTDZ($A$1,$B64,G$5,$B$1) -> 0 | H64: =_xll.EQNXTDZ($A$1,$B64,H$5,$B$1) -> 0 | I64: =_xll.EQNXTDZ($A$1,$B64,I$5,$B$1) -> 0 | J64: =_xll.EQNXTDZ($A$1,$B64,J$5,$B$1) -> 0 | ... BU64: =_xll.EQNXTDZ($A$1,$B64,BU$5,$B$1) -> 0
A65: Long Term Trade Payables | B65: QTRB_LT_TRADE_PAYABLE | C65: =_xll.EQNXTDZ($A$1,$B65,C$5,$B$1) -> 0 | D65: =_xll.EQNXTDZ($A$1,$B65,D$5,$B$1) -> 0 | E65: =_xll.EQNXTDZ($A$1,$B65,E$5,$B$1) -> 0 | F65: =_xll.EQNXTDZ($A$1,$B65,F$5,$B$1) -> 0 | G65: =_xll.EQNXTDZ($A$1,$B65,G$5,$B$1) -> 0 | H65: =_xll.EQNXTDZ($A$1,$B65,H$5,$B$1) -> 0 | I65: =_xll.EQNXTDZ($A$1,$B65,I$5,$B$1) -> 0 | J65: =_xll.EQNXTDZ($A$1,$B65,J$5,$B$1) -> 0 | ... BU65: =_xll.EQNXTDZ($A$1,$B65,BU$5,$B$1) -> 0
A66: Lont Term Provisions | B66: QTRB_LT_PROVISIONS | C66: =_xll.EQNXTDZ($A$1,$B66,C$5,$B$1) -> 3.53 | D66: =_xll.EQNXTDZ($A$1,$B66,D$5,$B$1) -> 0 | E66: =_xll.EQNXTDZ($A$1,$B66,E$5,$B$1) -> 1.52 | F66: =_xll.EQNXTDZ($A$1,$B66,F$5,$B$1) -> 0 | G66: =_xll.EQNXTDZ($A$1,$B66,G$5,$B$1) -> 1.41 | H66: =_xll.EQNXTDZ($A$1,$B66,H$5,$B$1) -> 0 | I66: =_xll.EQNXTDZ($A$1,$B66,I$5,$B$1) -> 1.27 | J66: =_xll.EQNXTDZ($A$1,$B66,J$5,$B$1) -> 0 | ... BU66: =_xll.EQNXTDZ($A$1,$B66,BU$5,$B$1) -> 0
... A97: Total Assets | B97: QTRB_TOTAL_APPLICATIONS | C97: =_xll.EQNXTDZ($A$1,$B97,C$5,$B$1) -> 379.25 | D97: =_xll.EQNXTDZ($A$1,$B97,D$5,$B$1) -> 0 | E97: =_xll.EQNXTDZ($A$1,$B97,E$5,$B$1) -> 409.26 | F97: =_xll.EQNXTDZ($A$1,$B97,F$5,$B$1) -> 0 | G97: =_xll.EQNXTDZ($A$1,$B97,G$5,$B$1) -> 442.09 | H97: =_xll.EQNXTDZ($A$1,$B97,H$5,$B$1) -> 0 | I97: =_xll.EQNXTDZ($A$1,$B97,I$5,$B$1) -> 452.11 | J97: =_xll.EQNXTDZ($A$1,$B97,J$5,$B$1) -> 0 | ... BU97: =_xll.EQNXTDZ($A$1,$B97,BU$5,$B$1) -> 0

Sheet Annual Raw
A1: 109820 | B1: X | C1: 200003 | D1: 200103 | E1: 200212 | F1: 200312 | G1: 200412 | H1: 200512 | I1: 200612 | J1: 200712 | K1: 200812 | L1: 200912 | M1: 201012 | N1: 201112 | O1: 201212 | P1: 201312 | Q1: 201412 | R1: 201512 | S1: 201612 | T1: 201712 | U1: 201812 | V1: 201912 | W1: 202012 | X1: 202112 | Y1: 202212 | Z1: 202312 | AA1: 202412 | AB1: 202512 | AC1: 202612 | AD1: 202712 | AE1: 202812 | AF1: 202912 | AG1: 203012
A3: Field Description | B3: Field Name
A4: Company Name | B4: CD_COMPNAME | C4: =_xll.EQNXTDZ(A1,B4,"L") -> Huhtamaki India Ltd.
A5: Year End | B5: PL_YEAR_END | C5: =_xll.EQNXTDZ($A$1,$B5,C$1,$B$1) -> 0 | D5: =_xll.EQNXTDZ($A$1,$B5,D$1,$B$1) -> 0 | E5: =_xll.EQNXTDZ($A$1,$B5,E$1,$B$1) -> 200212 | F5: =_xll.EQNXTDZ($A$1,$B5,F$1,$B$1) -> 200312 | G5: =_xll.EQNXTDZ($A$1,$B5,G$1,$B$1) -> 200412 | H5: =_xll.EQNXTDZ($A$1,$B5,H$1,$B$1) -> 200512 | I5: =_xll.EQNXTDZ($A$1,$B5,I$1,$B$1) -> 200612 | J5: =_xll.EQNXTDZ($A$1,$B5,J$1,$B$1) -> 200712 | ... AG5: =_xll.EQNXTDZ($A$1,$B5,AG$1,$B$1) -> 0
A6: Sales Turnover | B6: PL_TOTAL_GROSS_SALES | C6: =_xll.EQNXTDZ($A$1,$B6,C$1,$B$1) -> 0 | D6: =_xll.EQNXTDZ($A$1,$B6,D$1,$B$1) -> 0 | E6: =_xll.EQNXTDZ($A$1,$B6,E$1,$B$1) -> 354.2851 | F6: =_xll.EQNXTDZ($A$1,$B6,F$1,$B$1) -> 416.1824 | G6: =_xll.EQNXTDZ($A$1,$B6,G$1,$B$1) -> 424.9527 | H6: =_xll.EQNXTDZ($A$1,$B6,H$1,$B$1) -> 468.3587 | I6: =_xll.EQNXTDZ($A$1,$B6,I$1,$B$1) -> 547.3669 | J6: =_xll.EQNXTDZ($A$1,$B6,J$1,$B$1) -> 607.7681 | ... AG6: =_xll.EQNXTDZ($A$1,$B6,AG$1,$B$1) -> 0
A7: Less: Inter divisional transfers | B7: PL_INTER_DIV_TRF | C7: =_xll.EQNXTDZ($A$1,$B7,C$1,$B$1) -> 0 | D7: =_xll.EQNXTDZ($A$1,$B7,D$1,$B$1) -> 0 | E7: =_xll.EQNXTDZ($A$1,$B7,E$1,$B$1) -> -25.2562 | F7: =_xll.EQNXTDZ($A$1,$B7,F$1,$B$1) -> -32.4669 | G7: =_xll.EQNXTDZ($A$1,$B7,G$1,$B$1) -> -34.2293 | H7: =_xll.EQNXTDZ($A$1,$B7,H$1,$B$1) -> -37.0204 | I7: =_xll.EQNXTDZ($A$1,$B7,I$1,$B$1) -> -38.8644 | J7: =_xll.EQNXTDZ($A$1,$B7,J$1,$B$1) -> -40.482 | ... AG7: =_xll.EQNXTDZ($A$1,$B7,AG$1,$B$1) -> 0
A8: Less: Sales Returns | B8: PL_SALES_RETURN | C8: =_xll.EQNXTDZ($A$1,$B8,C$1,$B$1) -> 0 | D8: =_xll.EQNXTDZ($A$1,$B8,D$1,$B$1) -> 0 | E8: =_xll.EQNXTDZ($A$1,$B8,E$1,$B$1) -> 3.6471 | F8: =_xll.EQNXTDZ($A$1,$B8,F$1,$B$1) -> 5.4856 | G8: =_xll.EQNXTDZ($A$1,$B8,G$1,$B$1) -> 5.2703 | H8: =_xll.EQNXTDZ($A$1,$B8,H$1,$B$1) -> 6.9714 | I8: =_xll.EQNXTDZ($A$1,$B8,I$1,$B$1) -> 6.6637 | J8: =_xll.EQNXTDZ($A$1,$B8,J$1,$B$1) -> 4.9824 | ... AG8: =_xll.EQNXTDZ($A$1,$B8,AG$1,$B$1) -> 0
A9: Less: Excise | B9: PL_EXCISE | C9: =_xll.EQNXTDZ($A$1,$B9,C$1,$B$1) -> 0 | D9: =_xll.EQNXTDZ($A$1,$B9,D$1,$B$1) -> 0 | E9: =_xll.EQNXTDZ($A$1,$B9,E$1,$B$1) -> 53.7069 | F9: =_xll.EQNXTDZ($A$1,$B9,F$1,$B$1) -> 60.5458 | G9: =_xll.EQNXTDZ($A$1,$B9,G$1,$B$1) -> 59.8906 | H9: =_xll.EQNXTDZ($A$1,$B9,H$1,$B$1) -> 65.5473 | I9: =_xll.EQNXTDZ($A$1,$B9,I$1,$B$1) -> 78.3627 | J9: =_xll.EQNXTDZ($A$1,$B9,J$1,$B$1) -> 72.6803 | ... AG9: =_xll.EQNXTDZ($A$1,$B9,AG$1,$B$1) -> 0
A10: Net Sales | B10: PL_NET_SALES | C10: =_xll.EQNXTDZ($A$1,$B10,C$1,$B$1) -> 0 | D10: =_xll.EQNXTDZ($A$1,$B10,D$1,$B$1) -> 0 | E10: =_xll.EQNXTDZ($A$1,$B10,E$1,$B$1) -> 322.1873 | F10: =_xll.EQNXTDZ($A$1,$B10,F$1,$B$1) -> 382.6179 | G10: =_xll.EQNXTDZ($A$1,$B10,G$1,$B$1) -> 394.0211 | H10: =_xll.EQNXTDZ($A$1,$B10,H$1,$B$1) -> 432.8604 | I10: =_xll.EQNXTDZ($A$1,$B10,I$1,$B$1) -> 501.2049 | J10: =_xll.EQNXTDZ($A$1,$B10,J$1,$B$1) -> 570.5874 | ... AG10: =_xll.EQNXTDZ($A$1,$B10,AG$1,$B$1) -> 0
A11: Increase/Decrease in Stock | B11: PL_INC_DEC_INVENTORY | C11: =_xll.EQNXTDZ($A$1,$B11,C$1,$B$1) -> 0 | D11: =_xll.EQNXTDZ($A$1,$B11,D$1,$B$1) -> 0 | E11: =_xll.EQNXTDZ($A$1,$B11,E$1,$B$1) -> 1.5387 | F11: =_xll.EQNXTDZ($A$1,$B11,F$1,$B$1) -> -3.5805 | G11: =_xll.EQNXTDZ($A$1,$B11,G$1,$B$1) -> 0.9135 | H11: =_xll.EQNXTDZ($A$1,$B11,H$1,$B$1) -> -3.0595 | I11: =_xll.EQNXTDZ($A$1,$B11,I$1,$B$1) -> 0.1137 | J11: =_xll.EQNXTDZ($A$1,$B11,J$1,$B$1) -> -7.5251 | ... AG11: =_xll.EQNXTDZ($A$1,$B11,AG$1,$B$1) -> 0
A12: Raw Material Consumed | B12: PL_RAW_MATRS_CONSUMED | C12: =_xll.EQNXTDZ($A$1,$B12,C$1,$B$1) -> 0 | D12: =_xll.EQNXTDZ($A$1,$B12,D$1,$B$1) -> 0 | E12: =_xll.EQNXTDZ($A$1,$B12,E$1,$B$1) -> 203.7736 | F12: =_xll.EQNXTDZ($A$1,$B12,F$1,$B$1) -> 259.7068 | G12: =_xll.EQNXTDZ($A$1,$B12,G$1,$B$1) -> 266.155 | H12: =_xll.EQNXTDZ($A$1,$B12,H$1,$B$1) -> 297.6002 | I12: =_xll.EQNXTDZ($A$1,$B12,I$1,$B$1) -> 345.8754 | J12: =_xll.EQNXTDZ($A$1,$B12,J$1,$B$1) -> 409.0374 | ... AG12: =_xll.EQNXTDZ($A$1,$B12,AG$1,$B$1) -> 0
A13: Power & Fuel Cost | B13: PL_POWER_FUEL | C13: =_xll.EQNXTDZ($A$1,$B13,C$1,$B$1) -> 0 | D13: =_xll.EQNXTDZ($A$1,$B13,D$1,$B$1) -> 0 | E13: =_xll.EQNXTDZ($A$1,$B13,E$1,$B$1) -> 10.014 | F13: =_xll.EQNXTDZ($A$1,$B13,F$1,$B$1) -> 12.0829 | G13: =_xll.EQNXTDZ($A$1,$B13,G$1,$B$1) -> 12.3519 | H13: =_xll.EQNXTDZ($A$1,$B13,H$1,$B$1) -> 15.2928 | I13: =_xll.EQNXTDZ($A$1,$B13,I$1,$B$1) -> 17.8088 | J13: =_xll.EQNXTDZ($A$1,$B13,J$1,$B$1) -> 16.9449 | ... AG13: =_xll.EQNXTDZ($A$1,$B13,AG$1,$B$1) -> 0
A14: Employee Cost | B14: PL_EMPLOYEES | C14: =_xll.EQNXTDZ($A$1,$B14,C$1,$B$1) -> 0 | D14: =_xll.EQNXTDZ($A$1,$B14,D$1,$B$1) -> 0 | E14: =_xll.EQNXTDZ($A$1,$B14,E$1,$B$1) -> 22.0504 | F14: =_xll.EQNXTDZ($A$1,$B14,F$1,$B$1) -> 26.0119 | G14: =_xll.EQNXTDZ($A$1,$B14,G$1,$B$1) -> 28.7538 | H14: =_xll.EQNXTDZ($A$1,$B14,H$1,$B$1) -> 30.7647 | I14: =_xll.EQNXTDZ($A$1,$B14,I$1,$B$1) -> 36.0581 | J14: =_xll.EQNXTDZ($A$1,$B14,J$1,$B$1) -> 41.7776 | ... AG14: =_xll.EQNXTDZ($A$1,$B14,AG$1,$B$1) -> 0
A15: Operating & Manufacturing Expenses | B15: PL_GEN_OTHER_MFG_EXPS | C15: =_xll.EQNXTDZ($A$1,$B15,C$1,$B$1) -> 0 | D15: =_xll.EQNXTDZ($A$1,$B15,D$1,$B$1) -> 0 | E15: =_xll.EQNXTDZ($A$1,$B15,E$1,$B$1) -> 9.2349 | F15: =_xll.EQNXTDZ($A$1,$B15,F$1,$B$1) -> 11.8431 | G15: =_xll.EQNXTDZ($A$1,$B15,G$1,$B$1) -> 13.27 | H15: =_xll.EQNXTDZ($A$1,$B15,H$1,$B$1) -> 14.5692 | I15: =_xll.EQNXTDZ($A$1,$B15,I$1,$B$1) -> 20.0295 | J15: =_xll.EQNXTDZ($A$1,$B15,J$1,$B$1) -> 22.351 | ... AG15: =_xll.EQNXTDZ($A$1,$B15,AG$1,$B$1) -> 0
A16: Cost of Software development | B16: PL_COST_SW | C16: =_xll.EQNXTDZ($A$1,$B16,C$1,$B$1) -> 0 | D16: =_xll.EQNXTDZ($A$1,$B16,D$1,$B$1) -> 0 | E16: =_xll.EQNXTDZ($A$1,$B16,E$1,$B$1) -> 0 | F16: =_xll.EQNXTDZ($A$1,$B16,F$1,$B$1) -> 0 | G16: =_xll.EQNXTDZ($A$1,$B16,G$1,$B$1) -> 0 | H16: =_xll.EQNXTDZ($A$1,$B16,H$1,$B$1) -> 0 | I16: =_xll.EQNXTDZ($A$1,$B16,I$1,$B$1) -> 0 | J16: =_xll.EQNXTDZ($A$1,$B16,J$1,$B$1) -> 0 | ... AG16: =_xll.EQNXTDZ($A$1,$B16,AG$1,$B$1) -> 0
... A36: Profit After Tax from Discontinued Operations | B36: PL_PAT_DIS_OP | C36: =_xll.EQNXTDZ($A$1,$B36,C$1,$B$1) -> 0 | D36: =_xll.EQNXTDZ($A$1,$B36,D$1,$B$1) -> 0 | E36: =_xll.EQNXTDZ($A$1,$B36,E$1,$B$1) -> 0 | F36: =_xll.EQNXTDZ($A$1,$B36,F$1,$B$1) -> 0 | G36: =_xll.EQNXTDZ($A$1,$B36,G$1,$B$1) -> 0 | H36: =_xll.EQNXTDZ($A$1,$B36,H$1,$B$1) -> 0 | I36: =_xll.EQNXTDZ($A$1,$B36,I$1,$B$1) -> 0 | J36: =_xll.EQNXTDZ($A$1,$B36,J$1,$B$1) -> 0 | ... AG36: =_xll.EQNXTDZ($A$1,$B36,AG$1,$B$1) -> 0
A39: Field Description | B39: Field Name
A40: Year End | B40: BS_YEAR_END | C40: =_xll.EQNXTDZ($A$1,$B40,C$1,$B$1) -> 0 | D40: =_xll.EQNXTDZ($A$1,$B40,D$1,$B$1) -> 0 | E40: =_xll.EQNXTDZ($A$1,$B40,E$1,$B$1) -> 200212 | F40: =_xll.EQNXTDZ($A$1,$B40,F$1,$B$1) -> 200312 | G40: =_xll.EQNXTDZ($A$1,$B40,G$1,$B$1) -> 200412 | H40: =_xll.EQNXTDZ($A$1,$B40,H$1,$B$1) -> 200512 | I40: =_xll.EQNXTDZ($A$1,$B40,I$1,$B$1) -> 200612 | J40: =_xll.EQNXTDZ($A$1,$B40,J$1,$B$1) -> 200712 | ... AG40: =_xll.EQNXTDZ($A$1,$B40,AG$1,$B$1) -> 0
