Workbook

Sheet Template
A1: =+'Annual Raw'!C4 -> ABB India Ltd. | B1: 37226 | C1: =EOMONTH(B1,12) -> 37621 | D1: =EOMONTH(C1,12) -> 37986 | E1: =EOMONTH(D1,12) -> 38352 | F1: =EOMONTH(E1,12) -> 38717 | G1: =EOMONTH(F1,12) -> 39082 | H1: =EOMONTH(G1,12) -> 39447 | I1: =EOMONTH(H1,12) -> 39813 | J1: =EOMONTH(I1,12) -> 40178 | ... AD1: =EOMONTH(AC1,12) -> 47483 | AG1: QTR | AH1: 41061 | AI1: 41153 | AJ1: 41244 | AK1: 41334 | AL1: 41426 | AM1: 41518 | AN1: 41609 | AO1: 41699 | AP1: 41791 | AQ1: 41883 | AR1: 41974 | AS1: 42064 | AT1: 42156 | AU1: 42248 | AV1: 42339 | AW1: 42430 | AX1: 42522 | AY1: 42614 | AZ1: 42705 | BA1: 42795 | BB1: 42887 | BC1: 42979 | BD1: 43070 | BE1: 43160 | BF1: 43252 | BG1: 43344 | BH1: 43435 | BI1: 43525 | BJ1: 43617 | BK1: 43709 | BL1: 43800 | BM1: 43891 | BN1: 43983 | BO1: 44075 | BP1: =EOMONTH(BO1,3) -> 44196 | BQ1: =EOMONTH(BP1,3) -> 44286 | BR1: =EOMONTH(BQ1,3) -> 44377 | BS1: =EOMONTH(BR1,3) -> 44469 | BT1: =EOMONTH(BS1,3) -> 44561 | BU1: =EOMONTH(BT1,3) -> 44651 | BV1: =EOMONTH(BU1,3) -> 44742 | BW1: =EOMONTH(BV1,3) -> 44834 | ... CZ1: =EOMONTH(CY1,3) -> 47483 | DB1: HISTORICAL ESTIMATES | DC1: 46022
A2: Presentation Data (Start)
A5: Order Book - Opening | U5: =+T8 -> 0 | V5: =+U8 -> 4114 | W5: =+V8 -> 4912 | X5: =+W8 -> 6468 | Y5: =+X8 -> 8404 | Z5: =+Y8 -> 9380 | AA5: =+Z8 -> 9709 | AB5: =+AA8 -> 12360.32 | ... AD5: =+AC8 -> 17770.987 | BP5: =+BO8 -> 4390 | BQ5: =+BP8 -> 4114 | BR5: =+BQ8 -> 4328 | BS5: =+BR8 -> 4583 | BT5: =+BS8 -> 4765 | BU5: =+BT8 -> 4912 | BV5: =+BU8 -> 5229 | BW5: =+BV8 -> 5995 | ... CZ5: =+CY8 -> 19118.974
A6: Order Book - Addition | U6: =+U8+U7-U5 -> 9934.95 | V6: =+V8+V7-V5 -> 7732 | W6: =+W8+W7-W5 -> 10123.53 | X6: =+X8+X7-X5 -> 12382.52 | Y6: =+Y8+Y7-Y5 -> 13164.31 | Z6: =+Z8+Z7-Z5 -> 13531.73 | AA6: =+AA8+AA7-AA5 -> 17137.516 | AB6: =+AB8+AB7-AB5 -> 19538.394 | ... AD6: =+AD8+AD7-AD5 -> 25507.537 | BP6: 1308 | BQ6: 1308 | BR6: 1689 | BS6: 1960.39 | BT6: 2248.5 | BU6: 2285.37 | BV6: 2818.51 | BW6: 2643.74 | BX6: 2375.91 | BY6: 3113.21 | BZ6: 3065.63 | CA6: 3050.19 | CB6: 3153.49 | CC6: 3611.36 | CD6: 3412.86 | CE6: 3390.16 | CF6: 2749.93 | CG6: 3737.56 | CH6: 3281.44 | CI6: 3233 | CJ6: 4096 | CK6: =+CK8+CK7-CK5 -> 4569.06 | CL6: =+CH6*(1+CL11) -> 3773.656 | CM6: =+CI6*(1+CM11) -> 3879.6 | CN6: =+CJ6*(1+CN11) -> 4915.2 | CO6: =+CK6*(1+CO11) -> 5274.9536 | CP6: =+CL6*(1+CP11) -> 4305.3598 | CQ6: =+CM6*(1+CQ11) -> 4419.1694 | CR6: =+CN6*(1+CR11) -> 5538.9111 | CS6: =+CO6*(1+CS11) -> 6000.4427 | ... CZ6: =+CV6*(1+CZ11) -> 7249.9721
A7: Order Book - Executed | U7: =+U18 -> 5820.95 | V7: =+V18 -> 6934 | W7: =+W18 -> 8567.53 | X7: =+X18 -> 10446.52 | Y7: =+Y18 -> 12188.31 | Z7: =+Z18 -> 13202.73 | AA7: =+AA18 -> 14486.196 | AB7: =+AB18 -> 17087.616 | ... AD7: =+AD18 -> 22645.674 | BP7: =+BP18 -> 1700.76 | BQ7: =+BQ18 -> 1629.15 | BR7: =+BR18 -> 1424.96 | BS7: =+BS18 -> 1778.39 | BT7: =+BT18 -> 2101.5 | BU7: =+BU18 -> 1974.86 | BV7: =+BV18 -> 2097.85 | BW7: =+BW18 -> 2119.74 | ... CK7: =+CK18 -> 3184.06 | CL7: =+CK8*CL10 -> 3703.3845 | CM7: =+CL8*CM10 -> 3768.5281 | CN7: =+CM8*CN10 -> 3830.223 | CO7: =+CN8*CO10 -> 4013.5473 | CP7: =+CO8*CP10 -> 4412.4484 | CQ7: =+CP8*CQ10 -> 4345.3423 | CR7: =+CQ8*CR10 -> 4316.2776 | CS7: =+CR8*CS10 -> 4577.7344 | ... CZ7: =+CY8*CZ10 -> 5736.0968
A8: Order Book - Closing | U8: =+BP8 -> 4114 | V8: =+BT8 -> 4912 | W8: =+BX8 -> 6468 | X8: =+CB8 -> 8404 | Y8: =+CF8 -> 9380 | Z8: =+CJ8 -> 9709 | AA8: =+CN8 -> 12360.32 | AB8: =+CR8 -> 14811.099 | AC8: =+CV8 -> 17770.987 | AD8: =+CZ8 -> 20632.849 | BO8: 4390 | BP8: 4114 | BQ8: 4328 | BR8: 4583 | BS8: 4765 | BT8: 4912 | BU8: 5229 | BV8: 5995 | BW8: 6519 | BX8: 6468 | BY8: 7170 | BZ8: 7727 | CA8: 8008 | CB8: 8404 | CC8: 8935 | CD8: 9517 | CE8: 9995 | CF8: 9380 | CG8: 9958 | CH8: 10064 | CI8: 9895 | CJ8: 9709 | CK8: 11094 | CL8: =+CL5+CL6-CL7 -> 11164.272 | CM8: =+CM5+CM6-CM7 -> 11275.343 | CN8: =+CN5+CN6-CN7 -> 12360.32 | CO8: =+CO5+CO6-CO7 -> 13621.727 | CP8: =+CP5+CP6-CP7 -> 13514.638 | CQ8: =+CQ5+CQ6-CQ7 -> 13588.465 | CR8: =+CR5+CR6-CR7 -> 14811.099 | CS8: =+CS5+CS6-CS7 -> 16233.807 | ... CZ8: =+CZ5+CZ6-CZ7 -> 20632.849
A10: Execution % Opening order book | V10: =+V7/U8 -> 1.6854643 | W10: =+W7/V8 -> 1.744204 | X10: =+X7/W8 -> 1.6151082 | Y10: =+Y7/X8 -> 1.4502987 | Z10: =+Z7/Y8 -> 1.4075405 | AA10: =+AA7/Z8 -> 1.4920379 | AB10: =+AB7/AA8 -> 1.3824573 | AC10: =+AC7/AB8 -> 1.298185 | AD10: =+AD7/AC8 -> 1.2743059 | BP10: =+BP7/BO8 -> 0.38741686 | BQ10: =+BQ7/BP8 -> 0.39600146 | BR10: =+BR7/BQ8 -> 0.32924214 | BS10: =+BS7/BR8 -> 0.38804058 | BT10: =+BT7/BS8 -> 0.44102833 | BU10: =+BU7/BT8 -> 0.40204805 | BV10: =+BV7/BU8 -> 0.40119526 | BW10: =+BW7/BV8 -> 0.35358465 | ... CK10: =+CK7/CJ8 -> 0.32794933 | CL10: =+AVERAGE(CH10:CK10) -> 0.33381869 | CM10: =+AVERAGE(CI10:CL10) -> 0.33755253 | CN10: =+AVERAGE(CJ10:CM10) -> 0.33969901 | CO10: =+AVERAGE(CK10:CN10)*0.97 -> 0.32471224 | CP10: =+AVERAGE(CL10:CO10)*0.97 -> 0.32392725 | CQ10: =+AVERAGE(CM10:CP10)*0.97 -> 0.32152857 | CR10: =+AVERAGE(CN10:CQ10)*0.97 -> 0.31764276 | CS10: =+AVERAGE(CO10:CR10)*0.96 -> 0.3090746 | CT10: =+AVERAGE(CP10:CS10)*0.96 -> 0.30532156 | CU10: =+AVERAGE(CQ10:CT10)*0.96 -> 0.3008562 | CV10: =+AVERAGE(CR10:CU10)*0.96 -> 0.29589483 | CW10: =+AVERAGE(CS10:CV10) -> 0.3027868 | CX10: =+AVERAGE(CT10:CW10) -> 0.30121485 | CY10: =+AVERAGE(CU10:CX10) -> 0.30018817 | CZ10: =+AVERAGE(CV10:CY10) -> 0.30002116
A11: Additions YOY% | V11: =+V6/U6-1 -> -0.2217374 | W11: =+W6/V6-1 -> 0.3093029 | X11: =+X6/W6-1 -> 0.22314252 | Y11: =+Y6/X6-1 -> 0.063136583 | Z11: =+Z6/Y6-1 -> 0.027910312 | AA11: =+AA6/Z6-1 -> 0.26646896 | AB11: =+AB6/AA6-1 -> 0.14009486 | AC11: =+AC6/AB6-1 -> 0.1355813 | AD11: =+AD6/AC6-1 -> 0.14963885 | BT11: =+BT6/BP6-1 -> 0.7190367 | BU11: =+BU6/BQ6-1 -> 0.74722477 | BV11: =+BV6/BR6-1 -> 0.66874482 | BW11: =+BW6/BS6-1 -> 0.3485786 | BX11: =+BX6/BT6-1 -> 0.056664443 | BY11: =+BY6/BU6-1 -> 0.36223456 | BZ11: =+BZ6/BV6-1 -> 0.087677532 | CA11: =+CA6/BW6-1 -> 0.15374053 | ... CK11: =+CK6/CG6-1 -> 0.22247134 | CL11: 0.15 | CM11: 0.2 | CN11: 0.2 | CO11: =+AVERAGE(CK11:CN11)*0.8 -> 0.15449427 | CP11: =+AVERAGE(CL11:CO11)*0.8 -> 0.14089885 | CQ11: =+AVERAGE(CM11:CP11)*0.8 -> 0.13907862 | CR11: =+AVERAGE(CN11:CQ11)*0.8 -> 0.12689435 | CS11: =+AVERAGE(CO11:CR11)*0.98 -> 0.13753469 | CT11: =+AVERAGE(CP11:CS11) -> 0.13610163 | CU11: =+AVERAGE(CQ11:CT11) -> 0.13490232 | CV11: =+AVERAGE(CR11:CU11) -> 0.13385825 | CW11: =+AVERAGE(CS11:CV11)+1% -> 0.14559922 | CX11: =+AVERAGE(CT11:CW11)+1% -> 0.14761536 | CY11: =+AVERAGE(CU11:CX11)+1% -> 0.15049379 | CZ11: =+AVERAGE(CV11:CY11)+1% -> 0.15439166
A14: Presentation Data (End)
A15: Profit & Loss- Annual (Start)
A16: Gross Revenue | B16: ='Annual Raw'!C6 -> 1041.599 | C16: ='Annual Raw'!D6 -> 1175.7576 | D16: ='Annual Raw'!E6 -> 1576.73 | E16: ='Annual Raw'!F6 -> 2445.7977 | F16: ='Annual Raw'!G6 -> 3199.9328 | G16: ='Annual Raw'!H6 -> 4604.5615 | H16: ='Annual Raw'!I6 -> 6383.2682 | I16: ='Annual Raw'!J6 -> 7340.2391 | ... Z16: ='Annual Raw'!AA6 -> 13280.31 | AA16: =+SUM(CK16:CN16) -> 14486.196 | AB16: =+SUM(CO16:CR16) -> 17087.616 | AC16: =+SUM(CS16:CV16) -> 19227.547 | AD16: =SUM(CW16:CZ16) -> 22645.674 | AH16: ='QTR Raw'!C6+'QTR Raw'!C8 -> 1883.79 | AI16: ='QTR Raw'!D6+'QTR Raw'!D8 -> 1808.61 | AJ16: ='QTR Raw'!E6+'QTR Raw'!E8 -> 2082.28 | AK16: ='QTR Raw'!F6+'QTR Raw'!F8 -> 1981.07 | AL16: ='QTR Raw'!G6+'QTR Raw'!G8 -> 1751.15 | AM16: ='QTR Raw'!H6+'QTR Raw'!H8 -> 1785.9 | AN16: ='QTR Raw'!I6+'QTR Raw'!I8 -> 2203.87 | AO16: ='QTR Raw'!J6+'QTR Raw'!J8 -> 1827.71 | ... CI16: ='QTR Raw'!BD6+'QTR Raw'!BD8 -> 3310.72 | CJ16: 3557.01 | CK16: ='QTR Raw'!BF6+'QTR Raw'!BF8 -> 3184.06 | CL16: =+CL7 -> 3703.3845 | CM16: =+CM7 -> 3768.5281 | CN16: =+CN7 -> 3830.223 | CO16: =+CO7 -> 4013.5473 | CP16: =+CP7 -> 4412.4484 | CQ16: =+CQ7 -> 4345.3423 | CR16: =+CR7 -> 4316.2776 | CS16: =+CS7 -> 4577.7344 | ... CZ16: =+CZ7 -> 5736.0968 | DC16: 0
A17: Less: Exise Duty | B17: ='Annual Raw'!C7+'Annual Raw'!C8+'Annual Raw'!C9 -> 0 | C17: ='Annual Raw'!D7+'Annual Raw'!D8+'Annual Raw'!D9 -> 0 | D17: ='Annual Raw'!E7+'Annual Raw'!E8+'Annual Raw'!E9 -> 108.3725 | E17: ='Annual Raw'!F7+'Annual Raw'!F8+'Annual Raw'!F9 -> 185.5751 | F17: ='Annual Raw'!G7+'Annual Raw'!G8+'Annual Raw'!G9 -> 236.8802 | G17: ='Annual Raw'!H7+'Annual Raw'!H8+'Annual Raw'!H9 -> 330.5522 | H17: ='Annual Raw'!I7+'Annual Raw'!I8+'Annual Raw'!I9 -> 452.9568 | I17: ='Annual Raw'!J7+'Annual Raw'!J8+'Annual Raw'!J9 -> 503.2076 | ... Z17: ='Annual Raw'!AA7+'Annual Raw'!AA8+'Annual Raw'!AA9 -> 77.58 | AA17: =+SUM(CK17:CN17) -> 0 | AB17: =+SUM(CO17:CR17) -> 0 | AC17: =+SUM(CS17:CV17) -> 0 | AD17: =SUM(CW17:CZ17) -> 0 | AH17: =+'QTR Raw'!C20+'QTR Raw'!C19+'QTR Raw'!C13+'QTR Raw'!C7 -> 0 | AI17: =+'QTR Raw'!D20+'QTR Raw'!D19+'QTR Raw'!D13+'QTR Raw'!D7 -> 0 | AJ17: =+'QTR Raw'!E20+'QTR Raw'!E19+'QTR Raw'!E13+'QTR Raw'!E7 -> 0 | AK17: =+'QTR Raw'!F20+'QTR Raw'!F19+'QTR Raw'!F13+'QTR Raw'!F7 -> 0 | AL17: =+'QTR Raw'!G20+'QTR Raw'!G19+'QTR Raw'!G13+'QTR Raw'!G7 -> 0 | AM17: =+'QTR Raw'!H20+'QTR Raw'!H19+'QTR Raw'!H13+'QTR Raw'!H7 -> 0 | AN17: =+'QTR Raw'!I20+'QTR Raw'!I19+'QTR Raw'!I13+'QTR Raw'!I7 -> 0 | AO17: =+'QTR Raw'!J20+'QTR Raw'!J19+'QTR Raw'!J13+'QTR Raw'!J7 -> 0 | ... CI17: =+'QTR Raw'!BD20+'QTR Raw'!BD19+'QTR Raw'!BD13+'QTR Raw'!BD7 -> 0 | CK17: =+'QTR Raw'!BF20+'QTR Raw'!BF19+'QTR Raw'!BF13+'QTR Raw'!BF7 -> 0 | DC17: 0
A18: Net Revenue | B18: =+B16-B17 -> 1041.599 | C18: =+C16-C17 -> 1175.7576 | D18: =+D16-D17 -> 1468.3575 | E18: =+E16-E17 -> 2260.2226 | F18: =+F16-F17 -> 2963.0526 | G18: =+G16-G17 -> 4274.0093 | H18: =+H16-H17 -> 5930.3114 | I18: =+I16-I17 -> 6837.0315 | ... AD18: =+AD16-AD17 -> 22645.674 | AH18: =+AH16-AH17 -> 1883.79 | AI18: =+AI16-AI17 -> 1808.61 | AJ18: =+AJ16-AJ17 -> 2082.28 | AK18: =+AK16-AK17 -> 1981.07 | AL18: =+AL16-AL17 -> 1751.15 | AM18: =+AM16-AM17 -> 1785.9 | AN18: =+AN16-AN17 -> 2203.87 | AO18: =+AO16-AO17 -> 1827.71 | ... CZ18: =+CZ16-CZ17 -> 5736.0968 | DC18: 0
A19: Net Revenue YOY% | C19: =C18/B18-1 -> 0.12880062 | D19: =D18/C18-1 -> 0.24886073 | E19: =E18/D18-1 -> 0.53928631 | F19: =F18/E18-1 -> 0.3109561 | G19: =G18/F18-1 -> 0.4424345 | H19: =H18/G18-1 -> 0.38752889 | I19: =I18/H18-1 -> 0.15289587 | J19: =J18/I18-1 -> -0.087732534 | ... AD19: =AD18/AC18-1 -> 0.17777243 | AL19: =+IF(AH18<0,1-AL18/AH18,AL18/AH18-1) -> -0.070411245 | AM19: =+IF(AI18<0,1-AM18/AI18,AM18/AI18-1) -> -0.012556604 | AN19: =+IF(AJ18<0,1-AN18/AJ18,AN18/AJ18-1) -> 0.058392723 | AO19: =+IF(AK18<0,1-AO18/AK18,AO18/AK18-1) -> -0.077412711 | AP19: =+IF(AL18<0,1-AP18/AL18,AP18/AL18-1) -> 0.040561916 | AQ19: =+IF(AM18<0,1-AQ18/AM18,AQ18/AM18-1) -> 0.03307576 | AR19: =+IF(AN18<0,1-AR18/AN18,AR18/AN18-1) -> 0.015672431 | AS19: =+IF(AO18<0,1-AS18/AO18,AS18/AO18-1) -> -0.0071893243 | ... CZ19: =+IF(CV18<0,1-CZ18/CV18,CZ18/CV18-1) -> 0.18787887 | DC19: #DIV/0!
A20: Net Revenue QOQ% | AI20: =+IF(AH18<0,1-AI18/AH18,AI18/AH18-1) -> -0.039908907 | AJ20: =+IF(AI18<0,1-AJ18/AI18,AJ18/AI18-1) -> 0.1513151 | AK20: =+IF(AJ18<0,1-AK18/AJ18,AK18/AJ18-1) -> -0.048605375 | AL20: =+IF(AK18<0,1-AL18/AK18,AL18/AK18-1) -> -0.11605849 | AM20: =+IF(AL18<0,1-AM18/AL18,AM18/AL18-1) -> 0.019844102 | AN20: =+IF(AM18<0,1-AN18/AM18,AN18/AM18-1) -> 0.23403886 | AO20: =+IF(AN18<0,1-AO18/AN18,AO18/AN18-1) -> -0.17068157 | AP20: =+IF(AO18<0,1-AP18/AO18,AP18/AO18-1) -> -0.0030256441 | ... CK20: =+IF(CJ18<0,1-CK18/CJ18,CK18/CJ18-1) -> -0.1048493 | CL20: =+CL18/CK18-1 -> 0.16310135 | CM20: =+CM18/CL18-1 -> 0.017590285 | CN20: =+CN18/CM18-1 -> 0.016371085 | CO20: =+CO18/CN18-1 -> 0.047862584 | CP20: =+CP18/CO18-1 -> 0.099388658 | CQ20: =+CQ18/CP18-1 -> -0.015208366 | CR20: =+CR18/CQ18-1 -> -0.0066886908 | CS20: =+CS18/CR18-1 -> 0.060574583 | ... CZ20: =+CZ18/CY18-1 -> 0.0017505197
A21: Increase/Decrease in Stock | B21: ='Annual Raw'!C11 -> 0.9139 | C21: ='Annual Raw'!D11 -> 5.4548 | D21: ='Annual Raw'!E11 -> 9.3257 | E21: ='Annual Raw'!F11 -> -23.5813 | F21: ='Annual Raw'!G11 -> -7.7979 | G21: ='Annual Raw'!H11 -> -53.0166 | H21: ='Annual Raw'!I11 -> -52.0728 | I21: ='Annual Raw'!J11 -> -73.7869 | ... Z21: ='Annual Raw'!AA11 -> -130.89 | AA21: =+SUM(CK21:CN21) -> -51.54 | AB21: =+SUM(CO21:CR21) -> 0 | AC21: =+SUM(CS21:CV21) -> 0 | AD21: =SUM(CW21:CZ21) -> 0 | AH21: ='QTR Raw'!C10 -> -6.98 | AI21: ='QTR Raw'!D10 -> -28.04 | AJ21: ='QTR Raw'!E10 -> 42.06 | AK21: ='QTR Raw'!F10 -> -24.13 | AL21: ='QTR Raw'!G10 -> 3.8 | AM21: ='QTR Raw'!H10 -> -17.94 | AN21: ='QTR Raw'!I10 -> 25.29 | AO21: ='QTR Raw'!J10 -> 10.39 | ... CI21: ='QTR Raw'!BD10 -> -34.29 | CJ21: 151.65 | CK21: ='QTR Raw'!BF10 -> -51.54 | DC21: 0
A22: Purchase of Finished Goods | B22: 0 | C22: 0 | D22: 0 | E22: 0 | F22: 0 | G22: 0 | H22: 0 | I22: 0 | J22: 0 | K22: 0 | L22: 0 | M22: 0 | N22: 0 | O22: 0 | P22: 0 | Q22: 0 | R22: 0 | S22: 0 | T22: 0 | U22: 0 | V22: 0 | W22: 0 | X22: 0 | Y22: 0 | Z22: 0 | AA22: =+SUM(CK22:CN22) -> 241.3 | AB22: =+SUM(CO22:CR22) -> 0 | AC22: =+SUM(CS22:CV22) -> 0 | AD22: =SUM(CW22:CZ22) -> 0 | AH22: ='QTR Raw'!C12 -> 62.16 | AI22: ='QTR Raw'!D12 -> 65.26 | AJ22: ='QTR Raw'!E12 -> 70.39 | AK22: ='QTR Raw'!F12 -> 49.09 | AL22: ='QTR Raw'!G12 -> 76.15 | AM22: ='QTR Raw'!H12 -> 85.97 | AN22: ='QTR Raw'!I12 -> 102.86 | AO22: ='QTR Raw'!J12 -> 82.33 | ... CI22: ='QTR Raw'!BD12 -> 240.26 | CJ22: 271.47 | CK22: ='QTR Raw'!BF12 -> 241.3 | DC22: 0
A23: Raw Material Consumed | B23: ='Annual Raw'!C12 -> 419.0008 | C23: ='Annual Raw'!D12 -> 467.2112 | D23: ='Annual Raw'!E12 -> 527.9141 | E23: ='Annual Raw'!F12 -> 719.4776 | F23: ='Annual Raw'!G12 -> 875.9128 | G23: ='Annual Raw'!H12 -> 1265.495 | H23: ='Annual Raw'!I12 -> 1577.0845 | I23: ='Annual Raw'!J12 -> 2083.501 | ... Z23: ='Annual Raw'!AA12 -> 7755.65 | AA23: =+SUM(CK23:CN23) -> 8227.2139 | AB23: =+SUM(CO23:CR23) -> 9937.5202 | AC23: =+SUM(CS23:CV23) -> 11183.228 | AD23: =SUM(CW23:CZ23) -> 13171.343 | AH23: ='QTR Raw'!C11 -> 1163.55 | AI23: ='QTR Raw'!D11 -> 1109.66 | AJ23: ='QTR Raw'!E11 -> 1312.81 | AK23: ='QTR Raw'!F11 -> 1277.21 | AL23: ='QTR Raw'!G11 -> 1004.15 | AM23: ='QTR Raw'!H11 -> 1063.55 | AN23: ='QTR Raw'!I11 -> 1284.28 | AO23: ='QTR Raw'!J11 -> 1033.35 | ... CI23: ='QTR Raw'!BD11 -> 1755.97 | CJ23: 1646.63 | CK23: ='QTR Raw'!BF11 -> 1644.22 | CL23: =+CL18-CL24 -> 2159.0102 | CM23: =+CM18-CM24 -> 2198.4201 | CN23: =+CN18-CN24 -> 2225.5636 | CO23: =+CO18-CO24 -> 2331.2562 | CP23: =+CP18-CP24 -> 2568.3165 | CQ23: =+CQ18-CQ24 -> 2528.2556 | CR23: =+CR18-CR24 -> 2509.6919 | CS23: =+CS18-CS24 -> 2662.1674 | ... CZ23: =+CZ18-CZ24 -> 3336.2257 | DC23: 0
A24: Gross Profit | B24: =B18-B21-B23-B22 -> 621.6843 | C24: =C18-C21-C23-C22 -> 703.0916 | D24: =D18-D21-D23-D22 -> 931.1177 | E24: =E18-E21-E23-E22 -> 1564.3263 | F24: =F18-F21-F23-F22 -> 2094.9377 | G24: =G18-G21-G23-G22 -> 3061.5309 | H24: =H18-H21-H23-H22 -> 4405.2997 | I24: =I18-I21-I23-I22 -> 4827.3174 | ... AD24: =AD18-AD21-AD23-AD22 -> 9474.3311 | AH24: =AH18-AH21-AH23-AH22 -> 665.06 | AI24: =AI18-AI21-AI23-AI22 -> 661.73 | AJ24: =AJ18-AJ21-AJ23-AJ22 -> 657.02 | AK24: =AK18-AK21-AK23-AK22 -> 678.9 | AL24: =AL18-AL21-AL23-AL22 -> 667.05 | AM24: =AM18-AM21-AM23-AM22 -> 654.32 | AN24: =AN18-AN21-AN23-AN22 -> 791.44 | AO24: =AO18-AO21-AO23-AO22 -> 701.64 | ... CK24: =CK18-CK21-CK23-CK22 -> 1350.08 | CL24: =+CL25*CL18 -> 1544.3743 | CM24: =+CM25*CM18 -> 1570.108 | CN24: =+CN25*CN18 -> 1604.6594 | CO24: =+CO25*CO18 -> 1682.2912 | CP24: =+CP25*CP18 -> 1844.1319 | CQ24: =+CQ25*CQ18 -> 1817.0867 | CR24: =+CR25*CR18 -> 1806.5858 | CS24: =+CS25*CS18 -> 1915.567 | ... CZ24: =+CZ25*CZ18 -> 2399.8711 | DC24: 0
A25: GP% | B25: =B24/B18 -> 0.5968557 | C25: =C24/C18 -> 0.59799027 | D25: =D24/D18 -> 0.63412194 | E25: =E24/E18 -> 0.69211161 | F25: =F24/F18 -> 0.70702008 | G25: =G24/G18 -> 0.71631358 | H25: =H24/H18 -> 0.74284458 | I25: =I24/I18 -> 0.70605458 | ... AD25: =AD24/AD18 -> 0.41837267 | AH25: =AH24/AH18 -> 0.3530436 | AI25: =AI24/AI18 -> 0.36587766 | AJ25: =AJ24/AJ18 -> 0.31552913 | AK25: =AK24/AK18 -> 0.34269359 | AL25: =AL24/AL18 -> 0.38092111 | AM25: =AM24/AM18 -> 0.3663811 | AN25: =AN24/AN18 -> 0.35911374 | AO25: =AO24/AO18 -> 0.38389022 | ... CK25: =CK24/CK18 -> 0.42401211 | CL25: =AVERAGE(CH25:CK25) -> 0.417017 | CM25: =AVERAGE(CI25:CL25) -> 0.41663693 | CN25: =AVERAGE(CJ25:CM25) -> 0.41894672 | CO25: =AVERAGE(CK25:CN25) -> 0.41915319 | CP25: =AVERAGE(CL25:CO25) -> 0.41793846 | CQ25: =AVERAGE(CM25:CP25) -> 0.41816883 | CR25: =AVERAGE(CN25:CQ25) -> 0.4185518 | CS25: =AVERAGE(CO25:CR25) -> 0.41845307 | ... CZ25: =AVERAGE(CV25:CY25) -> 0.41838051 | DC25: #DIV/0!
A26: GP YOY% | C26: =+IF(B24<0,1-C24/B24,C24/B24-1) -> 0.13094637 | D26: =+IF(C24<0,1-D24/C24,D24/C24-1) -> 0.32431919 | E26: =+IF(D24<0,1-E24/D24,E24/D24-1) -> 0.68005216 | F26: =+IF(E24<0,1-F24/E24,F24/E24-1) -> 0.33919483 | G26: =+IF(F24<0,1-G24/F24,G24/F24-1) -> 0.46139472 | H26: =+IF(G24<0,1-H24/G24,H24/G24-1) -> 0.43892054 | I26: =+IF(H24<0,1-I24/H24,I24/H24-1) -> 0.095797727 | J26: =+IF(I24<0,1-J24/I24,J24/I24-1) -> -0.085530071 | ... AD26: =+IF(AC24<0,1-AD24/AC24,AD24/AC24-1) -> 0.17776671 | AL26: =+IF(AH24<0,1-AL24/AH24,AL24/AH24-1) -> 0.0029922112 | AM26: =+IF(AI24<0,1-AM24/AI24,AM24/AI24-1) -> -0.011197921 | AN26: =+IF(AJ24<0,1-AN24/AJ24,AN24/AJ24-1) -> 0.20459042 | AO26: =+IF(AK24<0,1-AO24/AK24,AO24/AK24-1) -> 0.03349536 | AP26: =+IF(AL24<0,1-AP24/AL24,AP24/AL24-1) -> 0.021677535 | AQ26: =+IF(AM24<0,1-AQ24/AM24,AQ24/AM24-1) -> 0.074764641 | AR26: =+IF(AN24<0,1-AR24/AN24,AR24/AN24-1) -> 0.023236127 | AS26: =+IF(AO24<0,1-AS24/AO24,AS24/AO24-1) -> 0.041844821 | ... CK26: =+IF(CG24<0,1-CK24/CG24,CK24/CG24-1) -> -0.014425042 | CL26: =+CL24/CH24-1 -> 0.16202244 | CM26: =+CM24/CI24-1 -> 0.16409495 | CN26: =+CN24/CJ24-1 -> 0.078936673 | CO26: =+CO24/CK24-1 -> 0.24606777 | CP26: =+CP24/CL24-1 -> 0.19409648 | CQ26: =+CQ24/CM24-1 -> 0.15730046 | CR26: =+CR24/CN24-1 -> 0.12583756 | CS26: =+CS24/CO24-1 -> 0.13866554 | ... CZ26: =+CZ24/CV24-1 -> 0.18779099 | DC26: #DIV/0!
A27: GP QOQ% | AI27: =+IF(AH24<0,1-AI24/AH24,AI24/AH24-1) -> -0.005007067 | AJ27: =+IF(AI24<0,1-AJ24/AI24,AJ24/AI24-1) -> -0.0071177066 | AK27: =+IF(AJ24<0,1-AK24/AJ24,AK24/AJ24-1) -> 0.033301878 | AL27: =+IF(AK24<0,1-AL24/AK24,AL24/AK24-1) -> -0.017454706 | AM27: =+IF(AL24<0,1-AM24/AL24,AM24/AL24-1) -> -0.019084027 | AN27: =+IF(AM24<0,1-AN24/AM24,AN24/AM24-1) -> 0.20956107 | AO27: =+IF(AN24<0,1-AO24/AN24,AO24/AN24-1) -> -0.11346407 | AP27: =+IF(AO24<0,1-AP24/AO24,AP24/AO24-1) -> -0.028689926 | ... CK27: =+IF(CJ24<0,1-CK24/CJ24,CK24/CJ24-1) -> -0.092236731 | CL27: =+CL24/CK24-1 -> 0.14391318 | CM27: =+CM24/CL24-1 -> 0.016662856 | CN27: =+CN24/CM24-1 -> 0.022005728 | CO27: =+CO24/CN24-1 -> 0.048379005 | CP27: =+CP24/CO24-1 -> 0.096202568 | CQ27: =+CQ24/CP24-1 -> -0.014665555 | CR27: =+CR24/CQ24-1 -> -0.0057789823 | CS27: =+CS24/CR24-1 -> 0.060324409 | ... CZ27: =+CZ24/CY24-1 -> 0.0017589355
A28: Employee Cost | B28: ='Annual Raw'!C14 -> 112.5039 | C28: ='Annual Raw'!D14 -> 120.0603 | D28: ='Annual Raw'!E14 -> 115.2921 | E28: ='Annual Raw'!F14 -> 135.0213 | F28: ='Annual Raw'!G14 -> 176.864 | G28: ='Annual Raw'!H14 -> 238.5327 | H28: ='Annual Raw'!I14 -> 303.5365 | I28: ='Annual Raw'!J14 -> 400.3824 | ... Z28: ='Annual Raw'!AA14 -> 974.81 | AA28: =+SUM(CK28:CN28) -> 962.9976 | AB28: =+SUM(CO28:CR28) -> 1030.4074 | AC28: =+SUM(CS28:CV28) -> 1102.536 | AD28: =SUM(CW28:CZ28) -> 1179.7135 | AH28: ='QTR Raw'!C16 -> 175.29 | AI28: ='QTR Raw'!D16 -> 149.52 | AJ28: ='QTR Raw'!E16 -> 145.86 | AK28: ='QTR Raw'!F16 -> 170.24 | AL28: ='QTR Raw'!G16 -> 156.41 | AM28: ='QTR Raw'!H16 -> 162.65 | AN28: ='QTR Raw'!I16 -> 187.76 | AO28: ='QTR Raw'!J16 -> 168.14 | ... CI28: ='QTR Raw'!BD16 -> 222.25 | CJ28: =291.37-65.94 -> 225.43 | CK28: ='QTR Raw'!BF16 -> 252.86 | CL28: =CH28*107% -> 231.12 | CM28: =CI28*107% -> 237.8075 | CN28: =CJ28*107% -> 241.2101 | CO28: =CK28*107% -> 270.5602 | CP28: =CL28*107% -> 247.2984 | CQ28: =CM28*107% -> 254.45403 | CR28: =CN28*107% -> 258.09481 | CS28: =CO28*107% -> 289.49941 | ... CZ28: =CV28*107% -> 295.49274 | DC28: 0
A29: General and Administration Expenses | B29: ='Annual Raw'!C17 -> 63.0905 | C29: ='Annual Raw'!D17 -> 62.2025 | D29: ='Annual Raw'!E17 -> 66.7747 | E29: ='Annual Raw'!F17 -> 68.8673 | F29: ='Annual Raw'!G17 -> 89.4623 | G29: ='Annual Raw'!H17 -> 149.5943 | H29: ='Annual Raw'!I17 -> 199.0484 | I29: ='Annual Raw'!J17 -> 268.4378 | ... Z29: ='Annual Raw'!AA17 -> 1313.84 | AA29: =+SUM(CK29:CN29) -> 0 | AB29: =+SUM(CO29:CR29) -> 0 | AC29: =+SUM(CS29:CV29) -> 0 | AD29: =SUM(CW29:CZ29) -> 0 | AH29: ='QTR Raw'!C17 -> 0 | AI29: ='QTR Raw'!D17 -> 0 | AJ29: ='QTR Raw'!E17 -> 0 | AK29: ='QTR Raw'!F17 -> 0 | AL29: ='QTR Raw'!G17 -> 0 | AM29: ='QTR Raw'!H17 -> 0 | AN29: ='QTR Raw'!I17 -> 0 | AO29: ='QTR Raw'!J17 -> 0 | ... CI29: ='QTR Raw'!BD17 -> 0 | CK29: ='QTR Raw'!BF17 -> 0 | DC29: 0
A30: Miscellaneous Expenses | B30: ='Annual Raw'!C19-'Annual Raw'!C20 -> 41.7367 | C30: ='Annual Raw'!D19-'Annual Raw'!D20 -> 54.4336 | D30: ='Annual Raw'!E19-'Annual Raw'!E20 -> 58.5664 | E30: ='Annual Raw'!F19-'Annual Raw'!F20 -> 83.9485 | F30: ='Annual Raw'!G19-'Annual Raw'!G20 -> 121.5091 | G30: ='Annual Raw'!H19-'Annual Raw'!H20 -> 105.0291 | H30: ='Annual Raw'!I19-'Annual Raw'!I20 -> 163.0677 | I30: ='Annual Raw'!J19-'Annual Raw'!J20 -> 159.2586 | ... Z30: ='Annual Raw'!AA19-'Annual Raw'!AA20 -> 120.9 | AA30: =+SUM(CK30:CN30) -> 0 | AB30: =+SUM(CO30:CR30) -> 0 | AC30: =+SUM(CS30:CV30) -> 0 | AD30: =SUM(CW30:CZ30) -> 0 | AH30: =+'QTR Raw'!C21 -> 0 | AI30: =+'QTR Raw'!D21 -> 0 | AJ30: =+'QTR Raw'!E21 -> 0 | AK30: =+'QTR Raw'!F21 -> 0 | AL30: =+'QTR Raw'!G21 -> 0 | AM30: =+'QTR Raw'!H21 -> 0 | AN30: =+'QTR Raw'!I21 -> 0 | AO30: =+'QTR Raw'!J21 -> 0 | ... CI30: =+'QTR Raw'!BD21 -> 0 | CK30: =+'QTR Raw'!BF21 -> 0 | DC30: 0
A31: Other Manufacturing Expenses | B31: ='Annual Raw'!C15+'Annual Raw'!C16 -> 279.5401 | C31: ='Annual Raw'!D15+'Annual Raw'!D16 -> 320.9275 | D31: ='Annual Raw'!E15+'Annual Raw'!E16 -> 514.5465 | E31: ='Annual Raw'!F15+'Annual Raw'!F16 -> 1003.1039 | F31: ='Annual Raw'!G15+'Annual Raw'!G16 -> 1316.8397 | G31: ='Annual Raw'!H15+'Annual Raw'!H16 -> 2004.3239 | H31: ='Annual Raw'!I15+'Annual Raw'!I16 -> 2902.9148 | I31: ='Annual Raw'!J15+'Annual Raw'!J16 -> 3117.4154 | ... Z31: ='Annual Raw'!AA15+'Annual Raw'!AA16 -> 950.16 | AA31: =+SUM(CK31:CN31) -> 3065.7087 | AB31: =+SUM(CO31:CR31) -> 3547.1207 | AC31: =+SUM(CS31:CV31) -> 4178.4729 | AD31: =SUM(CW31:CZ31) -> 5050.9265 | AH31: ='QTR Raw'!C14 -> 383.78 | AI31: ='QTR Raw'!D14 -> 445.82 | AJ31: ='QTR Raw'!E14 -> 444.57 | AK31: ='QTR Raw'!F14 -> 401.5 | AL31: ='QTR Raw'!G14 -> 402.76 | AM31: ='QTR Raw'!H14 -> 386.25 | AN31: ='QTR Raw'!I14 -> 454.22 | AO31: ='QTR Raw'!J14 -> 407.78 | ... CI31: ='QTR Raw'!BD14 -> 626.14 | CJ31: =118.98+530.66 -> 649.64 | CK31: ='QTR Raw'!BF14 -> 688.82 | CL31: =CL34-CL28-CL29-CL30-CL32-CL33 -> 784.5436 | CM31: =CM34-CM28-CM29-CM30-CM32-CM33 -> 782.51388 | CN31: =CN34-CN28-CN29-CN30-CN32-CN33 -> 809.83124 | CO31: =CO34-CO28-CO29-CO30-CO32-CO33 -> 825.99433 | CP31: =CP34-CP28-CP29-CP30-CP32-CP33 -> 933.87987 | CQ31: =CQ34-CQ28-CQ29-CQ30-CQ32-CQ33 -> 901.77603 | CR31: =CR34-CR28-CR29-CR30-CR32-CR33 -> 885.47045 | CS31: =CS34-CS28-CS29-CS30-CS32-CS33 -> 961.79178 | ... CZ31: =CZ34-CZ28-CZ29-CZ30-CZ32-CZ33 -> 1284.8825 | DC31: 0
A32: Power & Fuel Cost | B32: ='Annual Raw'!C13 -> 9.3438 | C32: ='Annual Raw'!D13 -> 9.5228 | D32: ='Annual Raw'!E13 -> 9.1404 | E32: ='Annual Raw'!F13 -> 12.178 | F32: ='Annual Raw'!G13 -> 14.9088 | G32: ='Annual Raw'!H13 -> 19.0068 | H32: ='Annual Raw'!I13 -> 22.3333 | I32: ='Annual Raw'!J13 -> 27.4312 | ... Z32: ='Annual Raw'!AA13 -> 28.8 | AA32: =+SUM(CK32:CN32) -> 0 | AB32: =+SUM(CO32:CR32) -> 0 | AC32: =+SUM(CS32:CV32) -> 0 | AD32: =SUM(CW32:CZ32) -> 0 | AH32: ='QTR Raw'!C15 -> 0 | AI32: ='QTR Raw'!D15 -> 0 | AJ32: ='QTR Raw'!E15 -> 0 | AK32: ='QTR Raw'!F15 -> 0 | AL32: ='QTR Raw'!G15 -> 0 | AM32: ='QTR Raw'!H15 -> 0 | AN32: ='QTR Raw'!I15 -> 0 | AO32: ='QTR Raw'!J15 -> 0 | ... CI32: ='QTR Raw'!BD15 -> 0 | CK32: ='QTR Raw'!BF15 -> 0 | DC32: 0
A33: Selling and Distribution Expenses | B33: ='Annual Raw'!C18 -> 14.4992 | C33: ='Annual Raw'!D18 -> 16.6277 | D33: ='Annual Raw'!E18 -> 24.8867 | E33: ='Annual Raw'!F18 -> 42.8444 | F33: ='Annual Raw'!G18 -> 50.4217 | G33: ='Annual Raw'!H18 -> 63.7147 | H33: ='Annual Raw'!I18 -> 74.6586 | I33: ='Annual Raw'!J18 -> 65.5072 | ... Z33: ='Annual Raw'!AA18 -> 179.36 | AA33: =+SUM(CK33:CN33) -> 0 | AB33: =+SUM(CO33:CR33) -> 0 | AC33: =+SUM(CS33:CV33) -> 0 | AD33: =SUM(CW33:CZ33) -> 0 | AH33: ='QTR Raw'!C18 -> 0 | AI33: ='QTR Raw'!D18 -> 0 | AJ33: ='QTR Raw'!E18 -> 0 | AK33: ='QTR Raw'!F18 -> 0 | AL33: ='QTR Raw'!G18 -> 0 | AM33: ='QTR Raw'!H18 -> 0 | AN33: ='QTR Raw'!I18 -> 0 | AO33: ='QTR Raw'!J18 -> 0 | ... CI33: ='QTR Raw'!BD18 -> 0 | CK33: ='QTR Raw'!BF18 -> 0 | DC33: 0
A34: Total Cost | B34: =+SUM(B28:B33) -> 520.7142 | C34: =+SUM(C28:C33) -> 583.7744 | D34: =+SUM(D28:D33) -> 789.2068 | E34: =+SUM(E28:E33) -> 1345.9634 | F34: =+SUM(F28:F33) -> 1770.0056 | G34: =+SUM(G28:G33) -> 2580.2015 | H34: =+SUM(H28:H33) -> 3665.5593 | I34: =+SUM(I28:I33) -> 4038.4326 | ... AD34: =+SUM(AD28:AD33) -> 6230.64 | AH34: =+SUM(AH28:AH33) -> 559.07 | AI34: =+SUM(AI28:AI33) -> 595.34 | AJ34: =+SUM(AJ28:AJ33) -> 590.43 | AK34: =+SUM(AK28:AK33) -> 571.74 | AL34: =+SUM(AL28:AL33) -> 559.17 | AM34: =+SUM(AM28:AM33) -> 548.9 | AN34: =+SUM(AN28:AN33) -> 641.98 | AO34: =+SUM(AO28:AO33) -> 575.92 | ... CK34: =+SUM(CK28:CK33) -> 941.68 | CL34: =CL35*CL18 -> 1015.6636 | CM34: =CM35*CM18 -> 1020.3214 | CN34: =CN35*CN18 -> 1051.0413 | CO34: =CO35*CO18 -> 1096.5545 | CP34: =CP35*CP18 -> 1181.1783 | CQ34: =CQ35*CQ18 -> 1156.2301 | CR34: =CR35*CR18 -> 1143.5653 | CS34: =CS35*CS18 -> 1251.2912 | ... CZ34: =CZ35*CZ18 -> 1580.3752 | DC34: 0
A35: Cost % | B35: =B34/B18 -> 0.49991811 | C35: =C34/C18 -> 0.49650914 | D35: =D34/D18 -> 0.53747592 | E35: =E34/E18 -> 0.59550037 | F35: =F34/F18 -> 0.59735882 | G35: =G34/G18 -> 0.60369581 | H35: =H34/H18 -> 0.6181057 | I35: =I34/I18 -> 0.59067047 | ... AD35: =AD34/AD18 -> 0.27513599 | AH35: =AH34/AH18 -> 0.29677937 | AI35: =AI34/AI18 -> 0.32916992 | AJ35: =AJ34/AJ18 -> 0.28354976 | AK35: =AK34/AK18 -> 0.28860161 | AL35: =AL34/AL18 -> 0.31931588 | AM35: =AM34/AM18 -> 0.30735204 | AN35: =AN34/AN18 -> 0.29129667 | AO35: =AO34/AO18 -> 0.31510469 | ... CK35: =CK34/CK18 -> 0.2957482 | CL35: =AVERAGE(CH35:CK35)*1.01 -> 0.27425281 | CM35: =AVERAGE(CI35:CL35)*1.01 -> 0.27074798 | CN35: =AVERAGE(CJ35:CM35)*1.01 -> 0.27440735 | CO35: =AVERAGE(CK35:CN35)*0.98 -> 0.2732133 | CP35: =AVERAGE(CL35:CO35)*0.98 -> 0.26769225 | CQ35: =AVERAGE(CM35:CP35)*0.98 -> 0.26608492 | CR35: =AVERAGE(CN35:CQ35)*0.98 -> 0.26494247 | CS35: =AVERAGE(CO35:CR35)*1.02 -> 0.2733429 | CT35: =AVERAGE(CP35:CS35)*1.02 -> 0.27337595 | CU35: =AVERAGE(CQ35:CT35)*1.02 -> 0.27482529 | CV35: =AVERAGE(CR35:CU35)*1.02 -> 0.27705408 | CW35: =AVERAGE(CS35:CV35) -> 0.27464956 | CX35: =AVERAGE(CT35:CW35) -> 0.27497622 | CY35: =AVERAGE(CU35:CX35) -> 0.27537629 | CZ35: =AVERAGE(CV35:CY35) -> 0.27551404 | DC35: #DIV/0!
A36: EBITDA | B36: =B24-B34 -> 100.9701 | C36: =C24-C34 -> 119.3172 | D36: =D24-D34 -> 141.9109 | E36: =E24-E34 -> 218.3629 | F36: =F24-F34 -> 324.9321 | G36: =G24-G34 -> 481.3294 | H36: =H24-H34 -> 739.7404 | I36: =I24-I34 -> 788.8848 | ... AD36: =AD24-AD34 -> 3243.6911 | AH36: =AH24-AH34 -> 105.99 | AI36: =AI24-AI34 -> 66.39 | AJ36: =AJ24-AJ34 -> 66.59 | AK36: =AK24-AK34 -> 107.16 | AL36: =AL24-AL34 -> 107.88 | AM36: =AM24-AM34 -> 105.42 | AN36: =AN24-AN34 -> 149.46 | AO36: =AO24-AO34 -> 125.72 | ... CZ36: =CZ24-CZ34 -> 819.49592 | DC36: 0
A37: EBITDA Margins | B37: =B36/B18 -> 0.096937593 | C37: =C36/C18 -> 0.10148112 | D37: =D36/D18 -> 0.096646014 | E37: =E36/E18 -> 0.096611236 | F37: =F36/F18 -> 0.10966127 | G37: =G36/G18 -> 0.11261777 | H37: =H36/H18 -> 0.12473888 | I37: =I36/I18 -> 0.11538411 | ... AD37: =AD36/AD18 -> 0.14323668 | AH37: =AH36/AH18 -> 0.056264233 | AI37: =AI36/AI18 -> 0.036707748 | AJ37: =AJ36/AJ18 -> 0.031979369 | AK37: =AK36/AK18 -> 0.054091981 | AL37: =AL36/AL18 -> 0.061605231 | AM37: =AM36/AM18 -> 0.059029061 | AN37: =AN36/AN18 -> 0.067817067 | AO37: =AO36/AO18 -> 0.068785529 | ... CZ37: =CZ36/CZ18 -> 0.14286647 | DC37: #DIV/0!
A38: EBITDA YOY% | C38: =+IF(B36<0,1-C36/B36,C36/B36-1) -> 0.18170825 | D38: =+IF(C36<0,1-D36/C36,D36/C36-1) -> 0.18935828 | E38: =+IF(D36<0,1-E36/D36,E36/D36-1) -> 0.5387324 | F38: =+IF(E36<0,1-F36/E36,F36/E36-1) -> 0.48803712 | G38: =+IF(F36<0,1-G36/F36,G36/F36-1) -> 0.48132302 | H38: =+IF(G36<0,1-H36/G36,H36/G36-1) -> 0.53686935 | I38: =+IF(H36<0,1-I36/H36,I36/H36-1) -> 0.066434657 | J38: =+IF(I36<0,1-J36/I36,J36/I36-1) -> -0.30575313 | ... AD38: =+IF(AC36<0,1-AD36/AC36,AD36/AC36-1) -> 0.17384262 | AL38: =+IF(AH36<0,1-AL36/AH36,AL36/AH36-1) -> 0.017831871 | AM38: =+IF(AI36<0,1-AM36/AI36,AM36/AI36-1) -> 0.58788974 | AN38: =+IF(AJ36<0,1-AN36/AJ36,AN36/AJ36-1) -> 1.2444812 | AO38: =+IF(AK36<0,1-AO36/AK36,AO36/AK36-1) -> 0.17319895 | AP38: =+IF(AL36<0,1-AP36/AL36,AP36/AL36-1) -> 0.16620319 | AQ38: =+IF(AM36<0,1-AQ36/AM36,AQ36/AM36-1) -> 0.17748055 | AR38: =+IF(AN36<0,1-AR36/AN36,AR36/AN36-1) -> 0.20453633 | AS38: =+IF(AO36<0,1-AS36/AO36,AS36/AO36-1) -> 0.14222081 | ... CK38: =+IF(CG36<0,1-CK36/CG36,CK36/CG36-1) -> -0.27019299 | CL38: =+CL36/CH36-1 -> 0.27680143 | CM38: =+CM36/CI36-1 -> 0.098716213 | CN38: =+CN36/CJ36-1 -> -0.095676159 | CO38: =+CO36/CK36-1 -> 0.43422295 | CP38: =+CP36/CL36-1 -> 0.25390623 | CQ38: =+CQ36/CM36-1 -> 0.2020239 | CR38: =+CR36/CN36-1 -> 0.19761372 | CS38: =+CS36/CO36-1 -> 0.13408612 | ... CZ38: =+CZ36/CV36-1 -> 0.20056036 | DC38: #DIV/0!
A39: EBITDA QOQ% | AI39: =+IF(AH36<0,1-AI36/AH36,AI36/AH36-1) -> -0.37362015 | AJ39: =+IF(AI36<0,1-AJ36/AI36,AJ36/AI36-1) -> 0.0030125019 | AK39: =+IF(AJ36<0,1-AK36/AJ36,AK36/AJ36-1) -> 0.60925064 | AL39: =+IF(AK36<0,1-AL36/AK36,AL36/AK36-1) -> 0.006718925 | AM39: =+IF(AL36<0,1-AM36/AL36,AM36/AL36-1) -> -0.022803115 | AN39: =+IF(AM36<0,1-AN36/AM36,AN36/AM36-1) -> 0.41775754 | AO39: =+IF(AN36<0,1-AO36/AN36,AO36/AN36-1) -> -0.15883849 | AP39: =+IF(AO36<0,1-AP36/AO36,AP36/AO36-1) -> 0.00071587655 | ... CH39: =+IF(CG36<0,1-CH36/CG36,CH36/CG36-1) -> -0.26002502 | CI39: =+IF(CH36>1,CI36/CH36-1,1-CI36/CH36) -> 0.2084088 | CJ39: =+IF(CI36>1,CJ36/CI36-1,1-CJ36/CI36) -> 0.22342573 | CK39: =+IF(CJ36>1,CK36/CJ36-1,1-CK36/CJ36) -> -0.33288685 | CL39: =+CL36/CK36-1 -> 0.29459036 | CM39: =+CM36/CL36-1 -> 0.039862825 | CN39: =+CN36/CM36-1 -> 0.0069688967 | CO39: =+CO36/CN36-1 -> 0.058015888 | CP39: =+CP36/CO36-1 -> 0.13182885 | CQ39: =+CQ36/CP36-1 -> -0.0031631223 | CR39: =+CR36/CQ36-1 -> 0.0032743694 | CS39: =+CS36/CR36-1 -> 0.0018932769 | ... CZ39: =+CZ36/CY36-1 -> 0.00081017802
A40: Depreciation | B40: ='Annual Raw'!C27 -> 18.2483 | C40: ='Annual Raw'!D27 -> 18.3223 | D40: ='Annual Raw'!E27 -> 18.435 | E40: ='Annual Raw'!F27 -> 20.3597 | F40: ='Annual Raw'!G27 -> 23.1407 | G40: ='Annual Raw'!H27 -> 26.4675 | H40: ='Annual Raw'!I27 -> 32.4057 | I40: ='Annual Raw'!J27 -> 36.6805 | ... Z40: ='Annual Raw'!AA27 -> 145.53 | AA40: =+SUM(CK40:CN40) -> 163.75452 | AB40: =+SUM(CO40:CR40) -> 161.58798 | AC40: =+SUM(CS40:CV40) -> 161.32508 | AD40: =SUM(CW40:CZ40) -> 161.1057 | AH40: ='QTR Raw'!C28 -> 23.13 | AI40: ='QTR Raw'!D28 -> 24.03 | AJ40: ='QTR Raw'!E28 -> 24.59 | AK40: ='QTR Raw'!F28 -> 24.63 | AL40: ='QTR Raw'!G28 -> 25.95 | AM40: ='QTR Raw'!H28 -> 25.73 | AN40: ='QTR Raw'!I28 -> 27 | AO40: ='QTR Raw'!J28 -> 27.41 | ... CI40: ='QTR Raw'!BD28 -> 36.59 | CJ40: 39.64 | CK40: ='QTR Raw'!BF28 -> 42.36 | CL40: =CL41*CK142 -> 40.486024 | CM40: =CM41*CL142 -> 40.464523 | CN40: =CN41*CM142 -> 40.443972 | CO40: =CO41*CN142 -> 40.424331 | CP40: =CP41*CO142 -> 40.405559 | CQ40: =CQ41*CP142 -> 40.387618 | CR40: =CR41*CQ142 -> 40.37047 | CS40: =CS41*CR142 -> 40.35408 | ... CZ40: =CZ41*CY142 -> 40.257956 | DC40: 0
A41: Depreciation % of Net Block | B41: =+B40/B142 -> 0.11681058 | C41: =+C40/C142 -> 0.12736954 | D41: =+D40/D142 -> 0.1154104 | E41: =+E40/E142 -> 0.10715367 | F41: =+F40/F142 -> 0.10209383 | G41: =+G40/G142 -> 0.086165052 | H41: =+H40/H142 -> 0.092080011 | I41: =+I40/I142 -> 0.067201019 | ... AD41: =+AD40/AD142 -> 0.17693094 | AH41: =+AH40/AG142 -> #DIV/0! | AI41: =+AI40/AH142 -> #DIV/0! | AJ41: =+AJ40/AI142 -> -1.0233042 | AK41: =+AK40/AJ142 -> 0.018233639 | AL41: =+AL40/AK142 -> 0.019567627 | AM41: =+AM40/AL142 -> 0.018284277 | AN41: =+AN40/AM142 -> 0.019544115 | AO41: =+AO40/AN142 -> 0.01904795 | ... CI41: =+CI40/CH142 -> 0.035395405 | CJ41: =CI41 -> 0.035395405 | CK41: =+CK40/CJ142 -> 0.044239285 | CL41: =+CK41 -> 0.044239285 | CM41: =+CL41 -> 0.044239285 | CN41: =+CM41 -> 0.044239285 | CO41: =+CN41 -> 0.044239285 | CP41: =+CO41 -> 0.044239285 | CQ41: =+CP41 -> 0.044239285 | CR41: =+CQ41 -> 0.044239285 | CS41: =+CR41 -> 0.044239285 | ... CZ41: =+CY41 -> 0.044239285 | DC41: #DIV/0!
A42: EBIT | B42: =B36-B40 -> 82.7218 | C42: =C36-C40 -> 100.9949 | D42: =D36-D40 -> 123.4759 | E42: =E36-E40 -> 198.0032 | F42: =F36-F40 -> 301.7914 | G42: =G36-G40 -> 454.8619 | H42: =H36-H40 -> 707.3347 | I42: =I36-I40 -> 752.2043 | ... AD42: =AD36-AD40 -> 3082.5854 | AH42: =AH36-AH40 -> 82.86 | AI42: =AI36-AI40 -> 42.36 | AJ42: =AJ36-AJ40 -> 42 | AK42: =AK36-AK40 -> 82.53 | AL42: =AL36-AL40 -> 81.93 | AM42: =AM36-AM40 -> 79.69 | AN42: =AN36-AN40 -> 122.46 | AO42: =AO36-AO40 -> 98.31 | ... CZ42: =CZ36-CZ40 -> 779.23796 | DC42: 0
A43: Other Income | B43: ='Annual Raw'!C23 -> 14.5845 | C43: ='Annual Raw'!D23 -> 27.8675 | D43: ='Annual Raw'!E23 -> 34.6994 | E43: ='Annual Raw'!F23 -> 45.5203 | F43: ='Annual Raw'!G23 -> 51.0857 | G43: ='Annual Raw'!H23 -> 78.4399 | H43: ='Annual Raw'!I23 -> 71.0454 | I43: ='Annual Raw'!J23 -> 130.4192 | ... Z43: ='Annual Raw'!AA23 -> 385.26 | AA43: =+SUM(CK43:CN43) -> 99.64 | AB43: =+SUM(CO43:CR43) -> 0 | AC43: =+SUM(CS43:CV43) -> 0 | AD43: =SUM(CW43:CZ43) -> 0 | AH43: ='QTR Raw'!C23 -> 1.42 | AI43: ='QTR Raw'!D23 -> 0.95 | AJ43: ='QTR Raw'!E23 -> 2.82 | AK43: ='QTR Raw'!F23 -> 1.54 | AL43: ='QTR Raw'!G23 -> 3.84 | AM43: ='QTR Raw'!H23 -> 0.92 | AN43: ='QTR Raw'!I23 -> 0.69 | AO43: ='QTR Raw'!J23 -> 1.13 | ... CI43: ='QTR Raw'!BD23 -> 83.95 | CJ43: 76.33 | CK43: ='QTR Raw'!BF23 -> 99.64 | DC43: 0
A44: Interest | B44: ='Annual Raw'!C25 -> 12.2274 | C44: ='Annual Raw'!D25 -> 5.8942 | D44: ='Annual Raw'!E25 -> 5.2826 | E44: ='Annual Raw'!F25 -> 7.0035 | F44: ='Annual Raw'!G25 -> 13.4001 | G44: ='Annual Raw'!H25 -> 10.0956 | H44: ='Annual Raw'!I25 -> 21.9232 | I44: ='Annual Raw'!J25 -> 49.3795 | ... Z44: ='Annual Raw'!AA25 -> 19.89 | AA44: =+SUM(CK44:CN44) -> -348.16173 | AB44: =+SUM(CO44:CR44) -> -560.27913 | AC44: =+SUM(CS44:CV44) -> -685.14545 | AD44: =SUM(CW44:CZ44) -> -823.73665 | AH44: ='QTR Raw'!C25 -> 7.65 | AI44: ='QTR Raw'!D25 -> 11.72 | AJ44: ='QTR Raw'!E25 -> 18.47 | AK44: ='QTR Raw'!F25 -> 19.75 | AL44: ='QTR Raw'!G25 -> 25.6 | AM44: ='QTR Raw'!H25 -> 26.99 | AN44: ='QTR Raw'!I25 -> 28.79 | AO44: ='QTR Raw'!J25 -> 22.07 | ... CI44: ='QTR Raw'!BD25 -> 5.64 | CJ44: 5.35 | CK44: ='QTR Raw'!BF25 -> 3.81 | CL44: =CL45*CK176 -> -112.05587 | CM44: =CM45*CL176 -> -116.74354 | CN44: =CN45*CM176 -> -123.17232 | CO44: =CO45*CN176 -> -129.72542 | CP44: =CP45*CO176 -> -136.25287 | CQ44: =CQ45*CP176 -> -143.0063 | CR44: =CR45*CQ176 -> -151.29455 | CS44: =CS45*CR176 -> -159.56827 | ... CZ44: =CZ45*CY176 -> -220.52766 | DC44: 0
A45: Interest % of Debt | B45: =+B44/B136 -> 1.1325127 | C45: =+C44/C136 -> 0.47649922 | D45: =+D44/D136 -> 0.52281747 | E45: =+E44/E136 -> 4.6902625 | F45: =+F44/F136 -> 4.914402 | G45: =+G44/G136 -> 6.5314097 | H45: =+H44/H136 -> 38.733569 | I45: =+I44/I136 -> 2444.5297 | ... AD45: =+AD44/AD136 -> #DIV/0! | AH45: =(AH44-AH43)/AG176 -> #DIV/0! | AI45: =(AI44-AI43)/AH176 -> #DIV/0! | AJ45: =(AJ44-AJ43)/AI176 -> -0.34471366 | AK45: =(AK44-AK43)/AJ176 -> 0.075635488 | AL45: =(AL44-AL43)/AK176 -> 0.21311662 | AM45: =(AM44-AM43)/AL176 -> 0.041849937 | AN45: =(AN44-AN43)/AM176 -> 0.04716603 | AO45: =(AO44-AO43)/AN176 -> 0.069006426 | ... CK45: =(CK44-CK43)/CJ176 -> 0.015727336 | CL45: 0.014 | CM45: =+CL45 -> 0.014 | CN45: =+CM45 -> 0.014 | CO45: =+CN45 -> 0.014 | CP45: =+CO45 -> 0.014 | CQ45: =+CP45 -> 0.014 | CR45: =+CQ45 -> 0.014 | CS45: =+CR45 -> 0.014 | CT45: =+CS45 -> 0.014 | ... CZ45: =+CY45 -> 0.014 | DC45: #DIV/0!
...

Sheet QTR Raw
A1: ='Annual Raw'!A1 -> 100002 | B1: X | C1: 201206 | D1: 201209 | E1: 201212 | F1: 201303 | G1: 201306 | H1: 201309 | I1: 201312 | J1: 201403 | K1: 201406 | L1: 201409 | M1: 201412 | N1: 201503 | O1: 201506 | P1: 201509 | Q1: 201512 | R1: 201603 | S1: 201606 | T1: 201609 | U1: 201612 | V1: 201703 | W1: 201706 | X1: 201709 | Y1: 201712 | Z1: 201803 | AA1: 201806 | AB1: 201809 | AC1: 201812 | AD1: 201903 | AE1: 201906 | AF1: 201909 | AG1: 201912 | AH1: 202003 | AI1: 202006 | AJ1: 202009 | AK1: 202012 | AL1: 202103 | AM1: 202106 | AN1: 202109 | AO1: 202112 | AP1: 202203 | AQ1: 202206 | AR1: 202209 | AS1: 202212 | AT1: 202303 | AU1: 202306 | AV1: 202309 | AW1: 202312 | AX1: 202403 | AY1: 202406 | AZ1: 202409 | BA1: 202412 | BB1: 202503 | BC1: 202506 | BD1: 202509 | BE1: 202512 | BF1: 202603 | BG1: 202606 | BH1: 202609 | BI1: 202612 | BJ1: 202703 | BK1: 202706 | BL1: 202709 | BM1: 202712 | BN1: 202803 | BO1: 202806 | BP1: 202809 | BQ1: 202812 | BR1: 202903 | BS1: 202906 | BT1: 202909 | BU1: 202912 | BV1: 203003
A3: Field Description | B3: Field Name
A4: Company Name | B4: CD_COMPNAME | C4: =_xll.EQNXTDZ(A1,B4,C1) -> ABB India Ltd.
A5: Date End | B5: QTR_DATE_END | C5: =_xll.EQNXTDZ($A$1,$B5,C$1,$B$1) -> 201206 | D5: =_xll.EQNXTDZ($A$1,$B5,D$1,$B$1) -> 201209 | E5: =_xll.EQNXTDZ($A$1,$B5,E$1,$B$1) -> 201212 | F5: =_xll.EQNXTDZ($A$1,$B5,F$1,$B$1) -> 201303 | G5: =_xll.EQNXTDZ($A$1,$B5,G$1,$B$1) -> 201306 | H5: =_xll.EQNXTDZ($A$1,$B5,H$1,$B$1) -> 201309 | I5: =_xll.EQNXTDZ($A$1,$B5,I$1,$B$1) -> 201312 | J5: =_xll.EQNXTDZ($A$1,$B5,J$1,$B$1) -> 201403 | ... BV5: =_xll.EQNXTDZ($A$1,$B5,BV$1,$B$1) -> 0
A6: Gross Sales | B6: QTR_GROSS_SALE | C6: =_xll.EQNXTDZ($A$1,$B6,C$1,$B$1) -> 1858.45 | D6: =_xll.EQNXTDZ($A$1,$B6,D$1,$B$1) -> 1786.06 | E6: =_xll.EQNXTDZ($A$1,$B6,E$1,$B$1) -> 2052.76 | F6: =_xll.EQNXTDZ($A$1,$B6,F$1,$B$1) -> 1964.36 | G6: =_xll.EQNXTDZ($A$1,$B6,G$1,$B$1) -> 1729.95 | H6: =_xll.EQNXTDZ($A$1,$B6,H$1,$B$1) -> 1762.4 | I6: =_xll.EQNXTDZ($A$1,$B6,I$1,$B$1) -> 2174.91 | J6: =_xll.EQNXTDZ($A$1,$B6,J$1,$B$1) -> 1809.98 | ... BV6: =_xll.EQNXTDZ($A$1,$B6,BV$1,$B$1) -> 0
A7: Less: Excise Duty | B7: QTR_EXCISE_DUTY | C7: =_xll.EQNXTDZ($A$1,$B7,C$1,$B$1) -> 0 | D7: =_xll.EQNXTDZ($A$1,$B7,D$1,$B$1) -> 0 | E7: =_xll.EQNXTDZ($A$1,$B7,E$1,$B$1) -> 0 | F7: =_xll.EQNXTDZ($A$1,$B7,F$1,$B$1) -> 0 | G7: =_xll.EQNXTDZ($A$1,$B7,G$1,$B$1) -> 0 | H7: =_xll.EQNXTDZ($A$1,$B7,H$1,$B$1) -> 0 | I7: =_xll.EQNXTDZ($A$1,$B7,I$1,$B$1) -> 0 | J7: =_xll.EQNXTDZ($A$1,$B7,J$1,$B$1) -> 0 | ... BV7: =_xll.EQNXTDZ($A$1,$B7,BV$1,$B$1) -> 0
A8: Other operating income | B8: QTR_JOB_WORKS | C8: =_xll.EQNXTDZ($A$1,$B8,C$1,$B$1) -> 25.34 | D8: =_xll.EQNXTDZ($A$1,$B8,D$1,$B$1) -> 22.55 | E8: =_xll.EQNXTDZ($A$1,$B8,E$1,$B$1) -> 29.52 | F8: =_xll.EQNXTDZ($A$1,$B8,F$1,$B$1) -> 16.71 | G8: =_xll.EQNXTDZ($A$1,$B8,G$1,$B$1) -> 21.2 | H8: =_xll.EQNXTDZ($A$1,$B8,H$1,$B$1) -> 23.5 | I8: =_xll.EQNXTDZ($A$1,$B8,I$1,$B$1) -> 28.96 | J8: =_xll.EQNXTDZ($A$1,$B8,J$1,$B$1) -> 17.73 | ... BV8: =_xll.EQNXTDZ($A$1,$B8,BV$1,$B$1) -> 0
A9: Net Sales & Other Operating Income | B9: QTR_NET_SALES | C9: =_xll.EQNXTDZ($A$1,$B9,C$1,$B$1) -> 1883.79 | D9: =_xll.EQNXTDZ($A$1,$B9,D$1,$B$1) -> 1808.61 | E9: =_xll.EQNXTDZ($A$1,$B9,E$1,$B$1) -> 2082.28 | F9: =_xll.EQNXTDZ($A$1,$B9,F$1,$B$1) -> 1981.07 | G9: =_xll.EQNXTDZ($A$1,$B9,G$1,$B$1) -> 1751.15 | H9: =_xll.EQNXTDZ($A$1,$B9,H$1,$B$1) -> 1785.9 | I9: =_xll.EQNXTDZ($A$1,$B9,I$1,$B$1) -> 2203.87 | J9: =_xll.EQNXTDZ($A$1,$B9,J$1,$B$1) -> 1827.71 | ... BV9: =_xll.EQNXTDZ($A$1,$B9,BV$1,$B$1) -> 0
A10: (Increase) / Decrease In Stocks | B10: QTR_INC_DEC_INVENTORY | C10: =_xll.EQNXTDZ($A$1,$B10,C$1,$B$1) -> -6.98 | D10: =_xll.EQNXTDZ($A$1,$B10,D$1,$B$1) -> -28.04 | E10: =_xll.EQNXTDZ($A$1,$B10,E$1,$B$1) -> 42.06 | F10: =_xll.EQNXTDZ($A$1,$B10,F$1,$B$1) -> -24.13 | G10: =_xll.EQNXTDZ($A$1,$B10,G$1,$B$1) -> 3.8 | H10: =_xll.EQNXTDZ($A$1,$B10,H$1,$B$1) -> -17.94 | I10: =_xll.EQNXTDZ($A$1,$B10,I$1,$B$1) -> 25.29 | J10: =_xll.EQNXTDZ($A$1,$B10,J$1,$B$1) -> 10.39 | ... BV10: =_xll.EQNXTDZ($A$1,$B10,BV$1,$B$1) -> 0
A11: Cost of Services & Raw Materials | B11: QTR_RAW_MATERIAL_COST | C11: =_xll.EQNXTDZ($A$1,$B11,C$1,$B$1) -> 1163.55 | D11: =_xll.EQNXTDZ($A$1,$B11,D$1,$B$1) -> 1109.66 | E11: =_xll.EQNXTDZ($A$1,$B11,E$1,$B$1) -> 1312.81 | F11: =_xll.EQNXTDZ($A$1,$B11,F$1,$B$1) -> 1277.21 | G11: =_xll.EQNXTDZ($A$1,$B11,G$1,$B$1) -> 1004.15 | H11: =_xll.EQNXTDZ($A$1,$B11,H$1,$B$1) -> 1063.55 | I11: =_xll.EQNXTDZ($A$1,$B11,I$1,$B$1) -> 1284.28 | J11: =_xll.EQNXTDZ($A$1,$B11,J$1,$B$1) -> 1033.35 | ... BV11: =_xll.EQNXTDZ($A$1,$B11,BV$1,$B$1) -> 0
A12: Purchase of Finished Goods | B12: QTR_PURCHASE_FIN_GOOD | C12: =_xll.EQNXTDZ($A$1,$B12,C$1,$B$1) -> 62.16 | D12: =_xll.EQNXTDZ($A$1,$B12,D$1,$B$1) -> 65.26 | E12: =_xll.EQNXTDZ($A$1,$B12,E$1,$B$1) -> 70.39 | F12: =_xll.EQNXTDZ($A$1,$B12,F$1,$B$1) -> 49.09 | G12: =_xll.EQNXTDZ($A$1,$B12,G$1,$B$1) -> 76.15 | H12: =_xll.EQNXTDZ($A$1,$B12,H$1,$B$1) -> 85.97 | I12: =_xll.EQNXTDZ($A$1,$B12,I$1,$B$1) -> 102.86 | J12: =_xll.EQNXTDZ($A$1,$B12,J$1,$B$1) -> 82.33 | ... BV12: =_xll.EQNXTDZ($A$1,$B12,BV$1,$B$1) -> 0
A13: Excise Duty | B13: QTR_EXCISE | C13: =_xll.EQNXTDZ($A$1,$B13,C$1,$B$1) -> 0 | D13: =_xll.EQNXTDZ($A$1,$B13,D$1,$B$1) -> 0 | E13: =_xll.EQNXTDZ($A$1,$B13,E$1,$B$1) -> 0 | F13: =_xll.EQNXTDZ($A$1,$B13,F$1,$B$1) -> 0 | G13: =_xll.EQNXTDZ($A$1,$B13,G$1,$B$1) -> 0 | H13: =_xll.EQNXTDZ($A$1,$B13,H$1,$B$1) -> 0 | I13: =_xll.EQNXTDZ($A$1,$B13,I$1,$B$1) -> 0 | J13: =_xll.EQNXTDZ($A$1,$B13,J$1,$B$1) -> 0 | ... BV13: =_xll.EQNXTDZ($A$1,$B13,BV$1,$B$1) -> 0
A14: Operating & Manufacturing Expenses | B14: QTR_MFG_EXPS | C14: =_xll.EQNXTDZ($A$1,$B14,C$1,$B$1) -> 383.78 | D14: =_xll.EQNXTDZ($A$1,$B14,D$1,$B$1) -> 445.82 | E14: =_xll.EQNXTDZ($A$1,$B14,E$1,$B$1) -> 444.57 | F14: =_xll.EQNXTDZ($A$1,$B14,F$1,$B$1) -> 401.5 | G14: =_xll.EQNXTDZ($A$1,$B14,G$1,$B$1) -> 402.76 | H14: =_xll.EQNXTDZ($A$1,$B14,H$1,$B$1) -> 386.25 | I14: =_xll.EQNXTDZ($A$1,$B14,I$1,$B$1) -> 454.22 | J14: =_xll.EQNXTDZ($A$1,$B14,J$1,$B$1) -> 407.78 | ... BV14: =_xll.EQNXTDZ($A$1,$B14,BV$1,$B$1) -> 0
A15: Electricity Power & Fuel Cost | B15: QTR_ELECTRICITY_POWER_FUEL | C15: =_xll.EQNXTDZ($A$1,$B15,C$1,$B$1) -> 0 | D15: =_xll.EQNXTDZ($A$1,$B15,D$1,$B$1) -> 0 | E15: =_xll.EQNXTDZ($A$1,$B15,E$1,$B$1) -> 0 | F15: =_xll.EQNXTDZ($A$1,$B15,F$1,$B$1) -> 0 | G15: =_xll.EQNXTDZ($A$1,$B15,G$1,$B$1) -> 0 | H15: =_xll.EQNXTDZ($A$1,$B15,H$1,$B$1) -> 0 | I15: =_xll.EQNXTDZ($A$1,$B15,I$1,$B$1) -> 0 | J15: =_xll.EQNXTDZ($A$1,$B15,J$1,$B$1) -> 0 | ... BV15: =_xll.EQNXTDZ($A$1,$B15,BV$1,$B$1) -> 0
A16: Employee Cost | B16: QTR_EXPLOYEE_COST | C16: =_xll.EQNXTDZ($A$1,$B16,C$1,$B$1) -> 175.29 | D16: =_xll.EQNXTDZ($A$1,$B16,D$1,$B$1) -> 149.52 | E16: =_xll.EQNXTDZ($A$1,$B16,E$1,$B$1) -> 145.86 | F16: =_xll.EQNXTDZ($A$1,$B16,F$1,$B$1) -> 170.24 | G16: =_xll.EQNXTDZ($A$1,$B16,G$1,$B$1) -> 156.41 | H16: =_xll.EQNXTDZ($A$1,$B16,H$1,$B$1) -> 162.65 | I16: =_xll.EQNXTDZ($A$1,$B16,I$1,$B$1) -> 187.76 | J16: =_xll.EQNXTDZ($A$1,$B16,J$1,$B$1) -> 168.14 | ... BV16: =_xll.EQNXTDZ($A$1,$B16,BV$1,$B$1) -> 0
... A42: Consolidated PAT(after extra items) | B42: QTR_CONS_PAT_EXITM | C42: =_xll.EQNXTDZ($A$1,$B42,C$1,$B$1) -> 51.63 | D42: =_xll.EQNXTDZ($A$1,$B42,D$1,$B$1) -> 21.37 | E42: =_xll.EQNXTDZ($A$1,$B42,E$1,$B$1) -> 16.77 | F42: =_xll.EQNXTDZ($A$1,$B42,F$1,$B$1) -> 43.06 | G42: =_xll.EQNXTDZ($A$1,$B42,G$1,$B$1) -> 39.63 | H42: =_xll.EQNXTDZ($A$1,$B42,H$1,$B$1) -> 38.03 | I42: =_xll.EQNXTDZ($A$1,$B42,I$1,$B$1) -> 58.59 | J42: =_xll.EQNXTDZ($A$1,$B42,J$1,$B$1) -> 51.68 | ... BV42: =_xll.EQNXTDZ($A$1,$B42,BV$1,$B$1) -> 0
A44: Field Description | B44: Field Name
A45: Equity Capital | B45: QTR_EQUITY_CAP | C45: =_xll.EQNXTDZ($A$1,$B45,C$1,$B$1) -> 42.38 | D45: =_xll.EQNXTDZ($A$1,$B45,D$1,$B$1) -> 42.38 | E45: =_xll.EQNXTDZ($A$1,$B45,E$1,$B$1) -> 42.38 | F45: =_xll.EQNXTDZ($A$1,$B45,F$1,$B$1) -> 42.38 | G45: =_xll.EQNXTDZ($A$1,$B45,G$1,$B$1) -> 42.38 | H45: =_xll.EQNXTDZ($A$1,$B45,H$1,$B$1) -> 42.38 | I45: =_xll.EQNXTDZ($A$1,$B45,I$1,$B$1) -> 42.38 | J45: =_xll.EQNXTDZ($A$1,$B45,J$1,$B$1) -> 42.38 | ... BV45: =_xll.EQNXTDZ($A$1,$B45,BV$1,$B$1) -> 0
A46: Face Value | B46: QTR_FV | C46: =_xll.EQNXTDZ($A$1,$B46,C$1,$B$1) -> 2 | D46: =_xll.EQNXTDZ($A$1,$B46,D$1,$B$1) -> 2 | E46: =_xll.EQNXTDZ($A$1,$B46,E$1,$B$1) -> 2 | F46: =_xll.EQNXTDZ($A$1,$B46,F$1,$B$1) -> 2 | G46: =_xll.EQNXTDZ($A$1,$B46,G$1,$B$1) -> 2 | H46: =_xll.EQNXTDZ($A$1,$B46,H$1,$B$1) -> 2 | I46: =_xll.EQNXTDZ($A$1,$B46,I$1,$B$1) -> 2 | J46: =_xll.EQNXTDZ($A$1,$B46,J$1,$B$1) -> 2 | ... BV46: =_xll.EQNXTDZ($A$1,$B46,BV$1,$B$1) -> 0
A47: Month End | B47: BMONTH_MONTHEND | C47: =_xll.EQNXTDZ($A$1,$B47,C$5) -> 201206 | D47: =_xll.EQNXTDZ($A$1,$B47,D$5) -> 201209 | E47: =_xll.EQNXTDZ($A$1,$B47,E$5) -> 201212 | F47: =_xll.EQNXTDZ($A$1,$B47,F$5) -> 201303 | G47: =_xll.EQNXTDZ($A$1,$B47,G$5) -> 201306 | H47: =_xll.EQNXTDZ($A$1,$B47,H$5) -> 201309 | I47: =_xll.EQNXTDZ($A$1,$B47,I$5) -> 201312 | J47: =_xll.EQNXTDZ($A$1,$B47,J$5) -> 201403 | ... BV47: =_xll.EQNXTDZ($A$1,$B47,BV$5) -> 0
A48: Close | B48: BMONTH_CLOSE | C48: =_xll.EQNXTDZ($A$1,$B48,C$5) -> 800.8 | D48: =_xll.EQNXTDZ($A$1,$B48,D$5) -> 797.75 | E48: =_xll.EQNXTDZ($A$1,$B48,E$5) -> 700.4 | F48: =_xll.EQNXTDZ($A$1,$B48,F$5) -> 489.2 | G48: =_xll.EQNXTDZ($A$1,$B48,G$5) -> 610.85 | H48: =_xll.EQNXTDZ($A$1,$B48,H$5) -> 543.9 | I48: =_xll.EQNXTDZ($A$1,$B48,I$5) -> 692.8 | J48: =_xll.EQNXTDZ($A$1,$B48,J$5) -> 849.95 | ... BV48: =_xll.EQNXTDZ($A$1,$B48,BV$5) -> 0
A49: Total of Promoter and Promoter Group | B49: SHP_TPFTOTALPROMOTER | C49: =_xll.EQNXTDZ($A$1,$B49,C$5) -> 75 | D49: =_xll.EQNXTDZ($A$1,$B49,D$5) -> 75 | E49: =_xll.EQNXTDZ($A$1,$B49,E$5) -> 75 | F49: =_xll.EQNXTDZ($A$1,$B49,F$5) -> 75 | G49: =_xll.EQNXTDZ($A$1,$B49,G$5) -> 75 | H49: =_xll.EQNXTDZ($A$1,$B49,H$5) -> 75 | I49: =_xll.EQNXTDZ($A$1,$B49,I$5) -> 75 | J49: =_xll.EQNXTDZ($A$1,$B49,J$5) -> 75 | ... BV49: =_xll.EQNXTDZ($A$1,$B49,BV$5) -> 0
A50: Total of Promoter and Promoter Group Pledged | B50: SHP_PSHFTOTALPROMOTER | C50: =_xll.EQNXTDZ($A$1,$B50,C$5) -> 0 | D50: =_xll.EQNXTDZ($A$1,$B50,D$5) -> 0 | E50: =_xll.EQNXTDZ($A$1,$B50,E$5) -> 0 | F50: =_xll.EQNXTDZ($A$1,$B50,F$5) -> 0 | G50: =_xll.EQNXTDZ($A$1,$B50,G$5) -> 0 | H50: =_xll.EQNXTDZ($A$1,$B50,H$5) -> 0 | I50: =_xll.EQNXTDZ($A$1,$B50,I$5) -> 0 | J50: =_xll.EQNXTDZ($A$1,$B50,J$5) -> 0 | ... BV50: =_xll.EQNXTDZ($A$1,$B50,BV$5) -> 0
A54: Field Description | B54: Field Name | C54: =_xll.EQNXTDZ($A$1,$B54,C$5) -> 0 | D54: =_xll.EQNXTDZ($A$1,$B54,D$5) -> 0 | E54: =_xll.EQNXTDZ($A$1,$B54,E$5) -> 0 | F54: =_xll.EQNXTDZ($A$1,$B54,F$5) -> 0 | G54: =_xll.EQNXTDZ($A$1,$B54,G$5) -> 0 | H54: =_xll.EQNXTDZ($A$1,$B54,H$5) -> 0 | I54: =_xll.EQNXTDZ($A$1,$B54,I$5) -> 0 | J54: =_xll.EQNXTDZ($A$1,$B54,J$5) -> 0 | ... BV54: =_xll.EQNXTDZ($A$1,$B54,BV$5) -> 0
A55: Year End | B55: QTRB_DATE_END | C55: =_xll.EQNXTDZ($A$1,$B55,C$5,$B$1) -> 201206 | D55: =_xll.EQNXTDZ($A$1,$B55,D$5,$B$1) -> 0 | E55: =_xll.EQNXTDZ($A$1,$B55,E$5,$B$1) -> 201212 | F55: =_xll.EQNXTDZ($A$1,$B55,F$5,$B$1) -> 0 | G55: =_xll.EQNXTDZ($A$1,$B55,G$5,$B$1) -> 201306 | H55: =_xll.EQNXTDZ($A$1,$B55,H$5,$B$1) -> 0 | I55: =_xll.EQNXTDZ($A$1,$B55,I$5,$B$1) -> 201312 | J55: =_xll.EQNXTDZ($A$1,$B55,J$5,$B$1) -> 0 | ... BV55: =_xll.EQNXTDZ($A$1,$B55,BV$5,$B$1) -> 0
A56: Share Capital | B56: QTRB_SHARE_CAPITAL | C56: =_xll.EQNXTDZ($A$1,$B56,C$5,$B$1) -> 42.38 | D56: =_xll.EQNXTDZ($A$1,$B56,D$5,$B$1) -> 0 | E56: =_xll.EQNXTDZ($A$1,$B56,E$5,$B$1) -> 42.38 | F56: =_xll.EQNXTDZ($A$1,$B56,F$5,$B$1) -> 0 | G56: =_xll.EQNXTDZ($A$1,$B56,G$5,$B$1) -> 42.38 | H56: =_xll.EQNXTDZ($A$1,$B56,H$5,$B$1) -> 0 | I56: =_xll.EQNXTDZ($A$1,$B56,I$5,$B$1) -> 42.38 | J56: =_xll.EQNXTDZ($A$1,$B56,J$5,$B$1) -> 0 | ... BV56: =_xll.EQNXTDZ($A$1,$B56,BV$5,$B$1) -> 0
A57: Share Warrants & outstandings | B57: QTRB_SHAREWARNDOUT | C57: =_xll.EQNXTDZ($A$1,$B57,C$5,$B$1) -> 0 | D57: =_xll.EQNXTDZ($A$1,$B57,D$5,$B$1) -> 0 | E57: =_xll.EQNXTDZ($A$1,$B57,E$5,$B$1) -> 0 | F57: =_xll.EQNXTDZ($A$1,$B57,F$5,$B$1) -> 0 | G57: =_xll.EQNXTDZ($A$1,$B57,G$5,$B$1) -> 0 | H57: =_xll.EQNXTDZ($A$1,$B57,H$5,$B$1) -> 0 | I57: =_xll.EQNXTDZ($A$1,$B57,I$5,$B$1) -> 0 | J57: =_xll.EQNXTDZ($A$1,$B57,J$5,$B$1) -> 0 | ... BV57: =_xll.EQNXTDZ($A$1,$B57,BV$5,$B$1) -> 0
A58: Reserves & Surplus | B58: QTRB_RESERVE | C58: =_xll.EQNXTDZ($A$1,$B58,C$5,$B$1) -> 2591.41 | D58: =_xll.EQNXTDZ($A$1,$B58,D$5,$B$1) -> 0 | E58: =_xll.EQNXTDZ($A$1,$B58,E$5,$B$1) -> 2559.26 | F58: =_xll.EQNXTDZ($A$1,$B58,F$5,$B$1) -> 0 | G58: =_xll.EQNXTDZ($A$1,$B58,G$5,$B$1) -> 2615.36 | H58: =_xll.EQNXTDZ($A$1,$B58,H$5,$B$1) -> 0 | I58: =_xll.EQNXTDZ($A$1,$B58,I$5,$B$1) -> 2635.18 | J58: =_xll.EQNXTDZ($A$1,$B58,J$5,$B$1) -> 0 | ... BV58: =_xll.EQNXTDZ($A$1,$B58,BV$5,$B$1) -> 0
A59: Shareholder's Funds | B59: QTRB_SHAREHODERS_FUNDS | C59: =_xll.EQNXTDZ($A$1,$B59,C$5,$B$1) -> 2633.79 | D59: =_xll.EQNXTDZ($A$1,$B59,D$5,$B$1) -> 0 | E59: =_xll.EQNXTDZ($A$1,$B59,E$5,$B$1) -> 2601.64 | F59: =_xll.EQNXTDZ($A$1,$B59,F$5,$B$1) -> 0 | G59: =_xll.EQNXTDZ($A$1,$B59,G$5,$B$1) -> 2657.74 | H59: =_xll.EQNXTDZ($A$1,$B59,H$5,$B$1) -> 0 | I59: =_xll.EQNXTDZ($A$1,$B59,I$5,$B$1) -> 2677.56 | J59: =_xll.EQNXTDZ($A$1,$B59,J$5,$B$1) -> 0 | ... BV59: =_xll.EQNXTDZ($A$1,$B59,BV$5,$B$1) -> 0
A60: Minority Interest | B60: QTRB_MINORITY_INTEREST_BS | C60: =_xll.EQNXTDZ($A$1,$B60,C$5,$B$1) -> 0 | D60: =_xll.EQNXTDZ($A$1,$B60,D$5,$B$1) -> 0 | E60: =_xll.EQNXTDZ($A$1,$B60,E$5,$B$1) -> 0 | F60: =_xll.EQNXTDZ($A$1,$B60,F$5,$B$1) -> 0 | G60: =_xll.EQNXTDZ($A$1,$B60,G$5,$B$1) -> 0 | H60: =_xll.EQNXTDZ($A$1,$B60,H$5,$B$1) -> 0 | I60: =_xll.EQNXTDZ($A$1,$B60,I$5,$B$1) -> 0 | J60: =_xll.EQNXTDZ($A$1,$B60,J$5,$B$1) -> 0 | ... BV60: =_xll.EQNXTDZ($A$1,$B60,BV$5,$B$1) -> 0
A61: Long Term Borrowings | B61: QTRB_TOTAL_DEBTS | C61: =_xll.EQNXTDZ($A$1,$B61,C$5,$B$1) -> 0 | D61: =_xll.EQNXTDZ($A$1,$B61,D$5,$B$1) -> 0 | E61: =_xll.EQNXTDZ($A$1,$B61,E$5,$B$1) -> 0 | F61: =_xll.EQNXTDZ($A$1,$B61,F$5,$B$1) -> 0 | G61: =_xll.EQNXTDZ($A$1,$B61,G$5,$B$1) -> 0 | H61: =_xll.EQNXTDZ($A$1,$B61,H$5,$B$1) -> 0 | I61: =_xll.EQNXTDZ($A$1,$B61,I$5,$B$1) -> 0 | J61: =_xll.EQNXTDZ($A$1,$B61,J$5,$B$1) -> 0 | ... BV61: =_xll.EQNXTDZ($A$1,$B61,BV$5,$B$1) -> 0
A62: Secured Loans | B62: QTRB_SECURED_LOANS | C62: =_xll.EQNXTDZ($A$1,$B62,C$5,$B$1) -> 0 | D62: =_xll.EQNXTDZ($A$1,$B62,D$5,$B$1) -> 0 | E62: =_xll.EQNXTDZ($A$1,$B62,E$5,$B$1) -> 0 | F62: =_xll.EQNXTDZ($A$1,$B62,F$5,$B$1) -> 0 | G62: =_xll.EQNXTDZ($A$1,$B62,G$5,$B$1) -> 0 | H62: =_xll.EQNXTDZ($A$1,$B62,H$5,$B$1) -> 0 | I62: =_xll.EQNXTDZ($A$1,$B62,I$5,$B$1) -> 0 | J62: =_xll.EQNXTDZ($A$1,$B62,J$5,$B$1) -> 0 | ... BV62: =_xll.EQNXTDZ($A$1,$B62,BV$5,$B$1) -> 0
A63: Unsecured Loans | B63: QTRB_UNSECURED_LOANS_NF | C63: =_xll.EQNXTDZ($A$1,$B63,C$5,$B$1) -> 0 | D63: =_xll.EQNXTDZ($A$1,$B63,D$5,$B$1) -> 0 | E63: =_xll.EQNXTDZ($A$1,$B63,E$5,$B$1) -> 0 | F63: =_xll.EQNXTDZ($A$1,$B63,F$5,$B$1) -> 0 | G63: =_xll.EQNXTDZ($A$1,$B63,G$5,$B$1) -> 0 | H63: =_xll.EQNXTDZ($A$1,$B63,H$5,$B$1) -> 0 | I63: =_xll.EQNXTDZ($A$1,$B63,I$5,$B$1) -> 0 | J63: =_xll.EQNXTDZ($A$1,$B63,J$5,$B$1) -> 0 | ... BV63: =_xll.EQNXTDZ($A$1,$B63,BV$5,$B$1) -> 0
A64: Other Long Term Liabilities | B64: QTRB_OTHER_LT_LIABILITIES | C64: =_xll.EQNXTDZ($A$1,$B64,C$5,$B$1) -> 3.84 | D64: =_xll.EQNXTDZ($A$1,$B64,D$5,$B$1) -> 0 | E64: =_xll.EQNXTDZ($A$1,$B64,E$5,$B$1) -> 3.89 | F64: =_xll.EQNXTDZ($A$1,$B64,F$5,$B$1) -> 0 | G64: =_xll.EQNXTDZ($A$1,$B64,G$5,$B$1) -> 4.04 | H64: =_xll.EQNXTDZ($A$1,$B64,H$5,$B$1) -> 0 | I64: =_xll.EQNXTDZ($A$1,$B64,I$5,$B$1) -> 4.17 | J64: =_xll.EQNXTDZ($A$1,$B64,J$5,$B$1) -> 0 | ... BV64: =_xll.EQNXTDZ($A$1,$B64,BV$5,$B$1) -> 0
A65: Long Term Trade Payables | B65: QTRB_LT_TRADE_PAYABLE | C65: =_xll.EQNXTDZ($A$1,$B65,C$5,$B$1) -> 0 | D65: =_xll.EQNXTDZ($A$1,$B65,D$5,$B$1) -> 0 | E65: =_xll.EQNXTDZ($A$1,$B65,E$5,$B$1) -> 5.71 | F65: =_xll.EQNXTDZ($A$1,$B65,F$5,$B$1) -> 0 | G65: =_xll.EQNXTDZ($A$1,$B65,G$5,$B$1) -> 0 | H65: =_xll.EQNXTDZ($A$1,$B65,H$5,$B$1) -> 0 | I65: =_xll.EQNXTDZ($A$1,$B65,I$5,$B$1) -> 0 | J65: =_xll.EQNXTDZ($A$1,$B65,J$5,$B$1) -> 0 | ... BV65: =_xll.EQNXTDZ($A$1,$B65,BV$5,$B$1) -> 0
A66: Lont Term Provisions | B66: QTRB_LT_PROVISIONS | C66: =_xll.EQNXTDZ($A$1,$B66,C$5,$B$1) -> 5.71 | D66: =_xll.EQNXTDZ($A$1,$B66,D$5,$B$1) -> 0 | E66: =_xll.EQNXTDZ($A$1,$B66,E$5,$B$1) -> 0 | F66: =_xll.EQNXTDZ($A$1,$B66,F$5,$B$1) -> 0 | G66: =_xll.EQNXTDZ($A$1,$B66,G$5,$B$1) -> 5.71 | H66: =_xll.EQNXTDZ($A$1,$B66,H$5,$B$1) -> 0 | I66: =_xll.EQNXTDZ($A$1,$B66,I$5,$B$1) -> 18.11 | J66: =_xll.EQNXTDZ($A$1,$B66,J$5,$B$1) -> 0 | ... BV66: =_xll.EQNXTDZ($A$1,$B66,BV$5,$B$1) -> 0
... A97: Total Assets | B97: QTRB_TOTAL_APPLICATIONS | C97: =_xll.EQNXTDZ($A$1,$B97,C$5,$B$1) -> 2643.34 | D97: =_xll.EQNXTDZ($A$1,$B97,D$5,$B$1) -> 0 | E97: =_xll.EQNXTDZ($A$1,$B97,E$5,$B$1) -> 2611.24 | F97: =_xll.EQNXTDZ($A$1,$B97,F$5,$B$1) -> 0 | G97: =_xll.EQNXTDZ($A$1,$B97,G$5,$B$1) -> 2667.49 | H97: =_xll.EQNXTDZ($A$1,$B97,H$5,$B$1) -> 0 | I97: =_xll.EQNXTDZ($A$1,$B97,I$5,$B$1) -> 2699.84 | J97: =_xll.EQNXTDZ($A$1,$B97,J$5,$B$1) -> 0 | ... BV97: =_xll.EQNXTDZ($A$1,$B97,BV$5,$B$1) -> 0

Sheet Annual Raw
A1: 100002 | B1: X | C1: 200112 | D1: 200212 | E1: 200312 | F1: 200412 | G1: 200512 | H1: 200612 | I1: 200712 | J1: 200812 | K1: 200912 | L1: 201012 | M1: 201112 | N1: 201212 | O1: 201312 | P1: 201412 | Q1: 201512 | R1: 201612 | S1: 201712 | T1: 201812 | U1: 201912 | V1: 202012 | W1: 202112 | X1: 202212 | Y1: 202312 | Z1: 202412 | AA1: 202512 | AB1: 202612 | AC1: 202712 | AD1: 202812 | AE1: 202912 | AF1: 203012
A3: Field Description | B3: Field Name
A4: Company Name | B4: CD_COMPNAME | C4: =_xll.EQNXTDZ(A1,B4,"L") -> ABB India Ltd.
A5: Year End | B5: PL_YEAR_END | C5: =_xll.EQNXTDZ($A$1,$B5,C$1,$B$1) -> 200112 | D5: =_xll.EQNXTDZ($A$1,$B5,D$1,$B$1) -> 200212 | E5: =_xll.EQNXTDZ($A$1,$B5,E$1,$B$1) -> 200312 | F5: =_xll.EQNXTDZ($A$1,$B5,F$1,$B$1) -> 200412 | G5: =_xll.EQNXTDZ($A$1,$B5,G$1,$B$1) -> 200512 | H5: =_xll.EQNXTDZ($A$1,$B5,H$1,$B$1) -> 200612 | I5: =_xll.EQNXTDZ($A$1,$B5,I$1,$B$1) -> 200712 | J5: =_xll.EQNXTDZ($A$1,$B5,J$1,$B$1) -> 200812 | ... AF5: =_xll.EQNXTDZ($A$1,$B5,AF$1,$B$1) -> 0
A6: Sales Turnover | B6: PL_TOTAL_GROSS_SALES | C6: =_xll.EQNXTDZ($A$1,$B6,C$1,$B$1) -> 1041.599 | D6: =_xll.EQNXTDZ($A$1,$B6,D$1,$B$1) -> 1175.7576 | E6: =_xll.EQNXTDZ($A$1,$B6,E$1,$B$1) -> 1576.73 | F6: =_xll.EQNXTDZ($A$1,$B6,F$1,$B$1) -> 2445.7977 | G6: =_xll.EQNXTDZ($A$1,$B6,G$1,$B$1) -> 3199.9328 | H6: =_xll.EQNXTDZ($A$1,$B6,H$1,$B$1) -> 4604.5615 | I6: =_xll.EQNXTDZ($A$1,$B6,I$1,$B$1) -> 6383.2682 | J6: =_xll.EQNXTDZ($A$1,$B6,J$1,$B$1) -> 7340.2391 | ... AF6: =_xll.EQNXTDZ($A$1,$B6,AF$1,$B$1) -> 0
A7: Less: Inter divisional transfers | B7: PL_INTER_DIV_TRF | C7: =_xll.EQNXTDZ($A$1,$B7,C$1,$B$1) -> 0 | D7: =_xll.EQNXTDZ($A$1,$B7,D$1,$B$1) -> 0 | E7: =_xll.EQNXTDZ($A$1,$B7,E$1,$B$1) -> 0 | F7: =_xll.EQNXTDZ($A$1,$B7,F$1,$B$1) -> 0 | G7: =_xll.EQNXTDZ($A$1,$B7,G$1,$B$1) -> 0 | H7: =_xll.EQNXTDZ($A$1,$B7,H$1,$B$1) -> 0 | I7: =_xll.EQNXTDZ($A$1,$B7,I$1,$B$1) -> 0 | J7: =_xll.EQNXTDZ($A$1,$B7,J$1,$B$1) -> 0 | ... AF7: =_xll.EQNXTDZ($A$1,$B7,AF$1,$B$1) -> 0
A8: Less: Sales Returns | B8: PL_SALES_RETURN | C8: =_xll.EQNXTDZ($A$1,$B8,C$1,$B$1) -> 0 | D8: =_xll.EQNXTDZ($A$1,$B8,D$1,$B$1) -> 0 | E8: =_xll.EQNXTDZ($A$1,$B8,E$1,$B$1) -> 0 | F8: =_xll.EQNXTDZ($A$1,$B8,F$1,$B$1) -> 0 | G8: =_xll.EQNXTDZ($A$1,$B8,G$1,$B$1) -> 0 | H8: =_xll.EQNXTDZ($A$1,$B8,H$1,$B$1) -> 0 | I8: =_xll.EQNXTDZ($A$1,$B8,I$1,$B$1) -> 0 | J8: =_xll.EQNXTDZ($A$1,$B8,J$1,$B$1) -> 0 | ... AF8: =_xll.EQNXTDZ($A$1,$B8,AF$1,$B$1) -> 0
A9: Less: Excise | B9: PL_EXCISE | C9: =_xll.EQNXTDZ($A$1,$B9,C$1,$B$1) -> 0 | D9: =_xll.EQNXTDZ($A$1,$B9,D$1,$B$1) -> 0 | E9: =_xll.EQNXTDZ($A$1,$B9,E$1,$B$1) -> 108.3725 | F9: =_xll.EQNXTDZ($A$1,$B9,F$1,$B$1) -> 185.5751 | G9: =_xll.EQNXTDZ($A$1,$B9,G$1,$B$1) -> 236.8802 | H9: =_xll.EQNXTDZ($A$1,$B9,H$1,$B$1) -> 330.5522 | I9: =_xll.EQNXTDZ($A$1,$B9,I$1,$B$1) -> 452.9568 | J9: =_xll.EQNXTDZ($A$1,$B9,J$1,$B$1) -> 503.2076 | ... AF9: =_xll.EQNXTDZ($A$1,$B9,AF$1,$B$1) -> 0
A10: Net Sales | B10: PL_NET_SALES | C10: =_xll.EQNXTDZ($A$1,$B10,C$1,$B$1) -> 1041.599 | D10: =_xll.EQNXTDZ($A$1,$B10,D$1,$B$1) -> 1175.7576 | E10: =_xll.EQNXTDZ($A$1,$B10,E$1,$B$1) -> 1468.3575 | F10: =_xll.EQNXTDZ($A$1,$B10,F$1,$B$1) -> 2260.2226 | G10: =_xll.EQNXTDZ($A$1,$B10,G$1,$B$1) -> 2963.0526 | H10: =_xll.EQNXTDZ($A$1,$B10,H$1,$B$1) -> 4274.0093 | I10: =_xll.EQNXTDZ($A$1,$B10,I$1,$B$1) -> 5930.3114 | J10: =_xll.EQNXTDZ($A$1,$B10,J$1,$B$1) -> 6837.0315 | ... AF10: =_xll.EQNXTDZ($A$1,$B10,AF$1,$B$1) -> 0
A11: Increase/Decrease in Stock | B11: PL_INC_DEC_INVENTORY | C11: =_xll.EQNXTDZ($A$1,$B11,C$1,$B$1) -> 0.9139 | D11: =_xll.EQNXTDZ($A$1,$B11,D$1,$B$1) -> 5.4548 | E11: =_xll.EQNXTDZ($A$1,$B11,E$1,$B$1) -> 9.3257 | F11: =_xll.EQNXTDZ($A$1,$B11,F$1,$B$1) -> -23.5813 | G11: =_xll.EQNXTDZ($A$1,$B11,G$1,$B$1) -> -7.7979 | H11: =_xll.EQNXTDZ($A$1,$B11,H$1,$B$1) -> -53.0166 | I11: =_xll.EQNXTDZ($A$1,$B11,I$1,$B$1) -> -52.0728 | J11: =_xll.EQNXTDZ($A$1,$B11,J$1,$B$1) -> -73.7869 | ... AF11: =_xll.EQNXTDZ($A$1,$B11,AF$1,$B$1) -> 0
A12: Raw Material Consumed | B12: PL_RAW_MATRS_CONSUMED | C12: =_xll.EQNXTDZ($A$1,$B12,C$1,$B$1) -> 419.0008 | D12: =_xll.EQNXTDZ($A$1,$B12,D$1,$B$1) -> 467.2112 | E12: =_xll.EQNXTDZ($A$1,$B12,E$1,$B$1) -> 527.9141 | F12: =_xll.EQNXTDZ($A$1,$B12,F$1,$B$1) -> 719.4776 | G12: =_xll.EQNXTDZ($A$1,$B12,G$1,$B$1) -> 875.9128 | H12: =_xll.EQNXTDZ($A$1,$B12,H$1,$B$1) -> 1265.495 | I12: =_xll.EQNXTDZ($A$1,$B12,I$1,$B$1) -> 1577.0845 | J12: =_xll.EQNXTDZ($A$1,$B12,J$1,$B$1) -> 2083.501 | ... AF12: =_xll.EQNXTDZ($A$1,$B12,AF$1,$B$1) -> 0
A13: Power & Fuel Cost | B13: PL_POWER_FUEL | C13: =_xll.EQNXTDZ($A$1,$B13,C$1,$B$1) -> 9.3438 | D13: =_xll.EQNXTDZ($A$1,$B13,D$1,$B$1) -> 9.5228 | E13: =_xll.EQNXTDZ($A$1,$B13,E$1,$B$1) -> 9.1404 | F13: =_xll.EQNXTDZ($A$1,$B13,F$1,$B$1) -> 12.178 | G13: =_xll.EQNXTDZ($A$1,$B13,G$1,$B$1) -> 14.9088 | H13: =_xll.EQNXTDZ($A$1,$B13,H$1,$B$1) -> 19.0068 | I13: =_xll.EQNXTDZ($A$1,$B13,I$1,$B$1) -> 22.3333 | J13: =_xll.EQNXTDZ($A$1,$B13,J$1,$B$1) -> 27.4312 | ... AF13: =_xll.EQNXTDZ($A$1,$B13,AF$1,$B$1) -> 0
A14: Employee Cost | B14: PL_EMPLOYEES | C14: =_xll.EQNXTDZ($A$1,$B14,C$1,$B$1) -> 112.5039 | D14: =_xll.EQNXTDZ($A$1,$B14,D$1,$B$1) -> 120.0603 | E14: =_xll.EQNXTDZ($A$1,$B14,E$1,$B$1) -> 115.2921 | F14: =_xll.EQNXTDZ($A$1,$B14,F$1,$B$1) -> 135.0213 | G14: =_xll.EQNXTDZ($A$1,$B14,G$1,$B$1) -> 176.864 | H14: =_xll.EQNXTDZ($A$1,$B14,H$1,$B$1) -> 238.5327 | I14: =_xll.EQNXTDZ($A$1,$B14,I$1,$B$1) -> 303.5365 | J14: =_xll.EQNXTDZ($A$1,$B14,J$1,$B$1) -> 400.3824 | ... AF14: =_xll.EQNXTDZ($A$1,$B14,AF$1,$B$1) -> 0
A15: Operating & Manufacturing Expenses | B15: PL_GEN_OTHER_MFG_EXPS | C15: =_xll.EQNXTDZ($A$1,$B15,C$1,$B$1) -> 279.5401 | D15: =_xll.EQNXTDZ($A$1,$B15,D$1,$B$1) -> 320.9275 | E15: =_xll.EQNXTDZ($A$1,$B15,E$1,$B$1) -> 514.5465 | F15: =_xll.EQNXTDZ($A$1,$B15,F$1,$B$1) -> 1003.1039 | G15: =_xll.EQNXTDZ($A$1,$B15,G$1,$B$1) -> 1316.8397 | H15: =_xll.EQNXTDZ($A$1,$B15,H$1,$B$1) -> 2004.3239 | I15: =_xll.EQNXTDZ($A$1,$B15,I$1,$B$1) -> 2902.9148 | J15: =_xll.EQNXTDZ($A$1,$B15,J$1,$B$1) -> 3117.4154 | ... AF15: =_xll.EQNXTDZ($A$1,$B15,AF$1,$B$1) -> 0
A16: Cost of Software development | B16: PL_COST_SW | C16: =_xll.EQNXTDZ($A$1,$B16,C$1,$B$1) -> 0 | D16: =_xll.EQNXTDZ($A$1,$B16,D$1,$B$1) -> 0 | E16: =_xll.EQNXTDZ($A$1,$B16,E$1,$B$1) -> 0 | F16: =_xll.EQNXTDZ($A$1,$B16,F$1,$B$1) -> 0 | G16: =_xll.EQNXTDZ($A$1,$B16,G$1,$B$1) -> 0 | H16: =_xll.EQNXTDZ($A$1,$B16,H$1,$B$1) -> 0 | I16: =_xll.EQNXTDZ($A$1,$B16,I$1,$B$1) -> 0 | J16: =_xll.EQNXTDZ($A$1,$B16,J$1,$B$1) -> 0 | ... AF16: =_xll.EQNXTDZ($A$1,$B16,AF$1,$B$1) -> 0
