Workbook

Sheet Template
A1: =+'Annual Raw'!C4 -> Adani Energy Solutions Ltd. | B1: 36951 | C1: =EOMONTH(B1,12) -> 37346 | D1: =EOMONTH(C1,12) -> 37711 | E1: =EOMONTH(D1,12) -> 38077 | F1: =EOMONTH(E1,12) -> 38442 | G1: =EOMONTH(F1,12) -> 38807 | H1: =EOMONTH(G1,12) -> 39172 | I1: =EOMONTH(H1,12) -> 39538 | J1: =EOMONTH(I1,12) -> 39903 | ... AE1: =EOMONTH(AD1,12) -> 47573 | AH1: QTR | AI1: 41061 | AJ1: 41153 | AK1: 41244 | AL1: 41334 | AM1: 41426 | AN1: 41518 | AO1: 41609 | AP1: 41699 | AQ1: 41791 | AR1: 41883 | AS1: 41974 | AT1: 42064 | AU1: 42156 | AV1: 42248 | AW1: 42339 | AX1: 42430 | AY1: 42522 | AZ1: 42614 | BA1: 42705 | BB1: 42795 | BC1: 42887 | BD1: 42979 | BE1: 43070 | BF1: 43160 | BG1: 43252 | BH1: 43344 | BI1: 43435 | BJ1: 43525 | BK1: 43617 | BL1: 43709 | BM1: 43800 | BN1: 43891 | BO1: 43983 | BP1: 44075 | BQ1: =EOMONTH(BP1,3) -> 44196 | BR1: =EOMONTH(BQ1,3) -> 44286 | BS1: =EOMONTH(BR1,3) -> 44377 | BT1: =EOMONTH(BS1,3) -> 44469 | BU1: =EOMONTH(BT1,3) -> 44561 | BV1: =EOMONTH(BU1,3) -> 44651 | BW1: =EOMONTH(BV1,3) -> 44742 | BX1: =EOMONTH(BW1,3) -> 44834 | ... DB1: =EOMONTH(DA1,3) -> 47573 | DE1: HISTORICAL ESTIMATES | DF1: 46112 | DG1: 46112
A2: Presentation Data (Start)
A4: Unit metrics
A5: Distribution unit metrics
A6: MU solds | W6: =SUM(BS6:BV6) -> 7955 | X6: =SUM(BW6:BZ6) -> 9051 | Y6: =SUM(CA6:CD6) -> 9916 | Z6: =SUM(CE6:CH6) -> 10558 | AA6: =CL6 -> 2508 | AB6: =CP6 -> 2583.24 | AC6: =CT6 -> 2673.6534 | AD6: =CX6 -> 2774.9451 | AE6: =DB6 -> 2888.7403 | BR6: 1873 | BS6: 2036 | BT6: 1975 | BU6: 2060 | BV6: 1884 | BW6: 2560 | BX6: 2233 | BY6: 2169 | BZ6: 2089 | CA6: 2754 | CB6: 2446 | CC6: 2489 | CD6: =9916-SUM(CA6:CC6) -> 2227 | CE6: 2962 | CF6: 2609 | CG6: 2574 | CH6: =10558-SUM(CE6:CG6) -> 2413 | CI6: 2939 | CJ6: 2650 | CK6: =8076-SUM(CI6:CJ6) -> 2487 | CL6: 2508 | CM6: =CI6*(1+CM11) -> 3027.17 | CN6: =CJ6*(1+CN11) -> 2729.5 | CO6: =CK6*(1+CO11) -> 2561.61 | CP6: =CL6*(1+CP11) -> 2583.24 | CQ6: =CM6*(1+CQ11) -> 3133.1209 | CR6: =CN6*(1+CR11) -> 2825.0325 | CS6: =CO6*(1+CS11) -> 2651.2663 | CT6: =CP6*(1+CT11) -> 2673.6534 | ... DB6: =CX6*(1+DB11) -> 2888.7403 | DG6: 2508
A7: Revenue per MU sold (in cr) | W7: =W25*10/W6 -> 8.7571087 | X7: =X25*10/X6 -> 9.4927743 | Y7: =Y25*10/Y6 -> 10.258945 | Z7: =Z25*10/Z6 -> 11.618185 | AA7: =AA25*10/AA6 -> 49.644139 | AB7: =AB25*10/AB6 -> 49.99706 | AC7: =AC25*10/AC6 -> 50.560001 | AD7: =AD25*10/AD6 -> 51.071509 | AE7: =AE25*10/AE6 -> 51.60437 | BR7: =BR25*10/BR6 -> 8.3054992 | BS7: =BS25*10/BS6 -> 8.555501 | BT7: =BT25*10/BT6 -> 8.559038 | BU7: =BU25*10/BU6 -> 8.7246602 | BV7: =BV25*10/BV6 -> 9.2180998 | BW7: =BW25*10/BW6 -> 8.6435156 | BX7: =BX25*10/BX6 -> 9.6904165 | BY7: =BY25*10/BY6 -> 9.6996312 | ... CL7: =CL25*10/CL6 -> 11.439394 | CM7: =CI7*(1+CM12) -> 11.600558 | CN7: =CJ7*(1+CN12) -> 11.974977 | CO7: =CK7*(1+CO12) -> 12.700454 | CP7: =CL7*(1+CP12) -> 11.438174 | CQ7: =CM7*(1+CQ12) -> 11.748536 | CR7: =CN7*(1+CR12) -> 12.121636 | CS7: =CO7*(1+CS12) -> 12.838055 | CT7: =CP7*(1+CT12) -> 11.542392 | ... DB7: =CX7*(1+DB12) -> 11.807892 | DG7: 12.480901
A8: Transmission availability | W8: =AVERAGE(BS8:BV8) -> 0.9999 | X8: =AVERAGE(BW8:BZ8) -> 0.9999 | Y8: =AVERAGE(CA8:CD8) -> 0.996525 | Z8: =AVERAGE(CE8:CH8) -> 0.993075 | AA8: =AVERAGE(CI8:CL8) -> 0.9947 | AB8: =AVERAGE(CM8:CP8) -> 0.99437773 | AC8: =AVERAGE(CQ8:CT8) -> 0.99432689 | AD8: =AVERAGE(CQ8:CT8) -> 0.99432689 | AE8: =AVERAGE(CY8:DB8) -> 0.99431995 | BR8: 0.9999 | BS8: 0.9999 | BT8: 0.9999 | BU8: 0.9999 | BV8: 0.9999 | BW8: 0.9999 | BX8: 0.9999 | BY8: 0.9999 | BZ8: 0.9999 | CA8: 0.9966 | CB8: 0.9947 | CC8: 0.9969 | CD8: 0.9979 | CE8: 0.997 | CF8: 0.9891 | CG8: 0.991 | CH8: 0.9952 | CI8: 0.9964 | CJ8: 0.9946 | CK8: 0.9936 | CL8: 0.9942 | CM8: =AVERAGE(CI8:CL8) -> 0.9947 | CN8: =AVERAGE(CJ8:CM8) -> 0.994275 | CO8: =AVERAGE(CK8:CN8) -> 0.99419375 | CP8: =AVERAGE(CL8:CO8) -> 0.99434219 | CQ8: =AVERAGE(CM8:CP8) -> 0.99437773 | CR8: =AVERAGE(CN8:CQ8) -> 0.99429717 | CS8: =AVERAGE(CO8:CR8) -> 0.99430271 | CT8: =AVERAGE(CP8:CS8) -> 0.99432995 | ... DB8: =AVERAGE(CX8:DA8) -> 0.99432043 | DG8: 0.9942
A10: Growth % Y-o-Y
A11: MU solds % | X11: =X6/W6-1 -> 0.13777498 | Y11: =Y6/X6-1 -> 0.09556955 | Z11: =Z6/Y6-1 -> 0.064743848 | AA11: =AA6/Z6-1 -> -0.76245501 | AB11: =AB6/AA6-1 -> 0.03 | AC11: =AC6/AB6-1 -> 0.035 | AD11: =AD6/AC6-1 -> 0.037885126 | AE11: =AE6/AD6-1 -> 0.041008078 | BV11: =BV6/BR6-1 -> 0.0058729311 | BW11: =BW6/BS6-1 -> 0.25736739 | BX11: =BX6/BT6-1 -> 0.13063291 | BY11: =BY6/BU6-1 -> 0.052912621 | BZ11: =BZ6/BV6-1 -> 0.10881104 | CA11: =CA6/BW6-1 -> 0.07578125 | CB11: =CB6/BX6-1 -> 0.095387371 | CC11: =CC6/BY6-1 -> 0.14753343 | ... CL11: =CL6/CH6-1 -> 0.039370079 | CM11: 0.03 | CN11: 0.03 | CO11: 0.03 | CP11: 0.03 | CQ11: 0.035 | CR11: =+CQ11 -> 0.035 | CS11: =+CR11 -> 0.035 | CT11: =+CS11 -> 0.035 | CU11: =+CT11*1.02 -> 0.0357 | CV11: =+CU11*1.02 -> 0.036414 | CW11: =+CV11*1.02 -> 0.03714228 | CX11: =+CW11*1.02 -> 0.037885126 | CY11: =+CX11*1.02 -> 0.038642828 | CZ11: =+CY11*1.02 -> 0.039415685 | DA11: =+CZ11*1.02 -> 0.040203998 | DB11: =+DA11*1.02 -> 0.041008078 | DG11: 0.039370079
A12: Revenue per MU sold % | X12: =X7/W7-1 -> 0.084007812 | Y12: =Y7/X7-1 -> 0.080710953 | Z12: =Z7/Y7-1 -> 0.13249317 | AA12: =AA7/Z7-1 -> 3.2729684 | AB12: =AB7/AA7-1 -> 0.0071090218 | AC12: =AC7/AB7-1 -> 0.011259482 | AD12: =AD7/AC7-1 -> 0.010116856 | AE12: =AE7/AD7-1 -> 0.010433611 | BV12: =BV7/BR7-1 -> 0.10987908 | BW12: =BW7/BS7-1 -> 0.010287491 | BX12: =BX7/BT7-1 -> 0.13218524 | BY12: =BY7/BU7-1 -> 0.11174888 | BZ12: =BZ7/BV7-1 -> 0.096480611 | CA12: =CA7/BW7-1 -> 0.15009333 | CB12: =CB7/BX7-1 -> 0.04614405 | CC12: =CC7/BY7-1 -> 0.060330336 | ... CL12: =CL7/CH7-1 -> -0.050511061 | CM12: =AVERAGE(CI12:CL12)*1.12 -> 0.014751932 | CN12: =AVERAGE(CJ12:CM12)*1.12 -> 0.01778724 | CO12: =AVERAGE(CK12:CN12)*1.12 -> 0.017591146 | CP12: =AVERAGE(CL12:CO12)*1.12 -> -0.00010660809 | CQ12: =AVERAGE(CM12:CP12)*1.02 -> 0.012756046 | CR12: =AVERAGE(CN12:CQ12)*1.02 -> 0.012247095 | CS12: =AVERAGE(CO12:CR12)*1.02 -> 0.010834358 | CT12: =AVERAGE(CP12:CS12)*1.02 -> 0.0091113773 | CU12: =AVERAGE(CQ12:CT12)*1.03 -> 0.011574336 | CV12: =AVERAGE(CR12:CU12)*1.03 -> 0.011270045 | CW12: =AVERAGE(CS12:CV12)*1.03 -> 0.011018455 | CX12: =AVERAGE(CT12:CW12)*1.03 -> 0.01106586 | CY12: =AVERAGE(CU12:CX12)*1.03 -> 0.011569139 | CZ12: =AVERAGE(CV12:CY12)*1.03 -> 0.011567801 | DA12: =AVERAGE(CW12:CZ12)*1.03 -> 0.011644473 | DB12: =AVERAGE(CX12:DA12)*1.03 -> 0.011805673 | DG12: 0.03593575
A14: Transmission unit Metrics
A15: Transmission network length (CKM) | U15: =BN15 -> 14740 | V15: =BR15 -> 17276 | W15: =BV15 -> 18795 | X15: =BZ15 -> 19779 | Y15: =CD15 -> 20509 | Z15: =CH15 -> 26696 | AA15: =CL15 -> 27949 | AB15: =CP15 -> 29511 | AC15: =CT15 -> 30401 | AD15: =CX15 -> 32801 | AE15: =DB15 -> 34001 | BL15: 14738 | BM15: 14738 | BN15: 14740 | BO15: 14814 | BP15: 14837 | BQ15: 15487 | BR15: 17276 | BS15: 18801 | BT15: 18336 | BU15: 18567 | BV15: 18795 | BW15: 18795 | BX15: 18795 | BY15: 18795 | BZ15: 19779 | CA15: 19778 | CB15: 19862 | CC15: 20422 | CD15: 20509 | CE15: 21187 | CF15: 23269 | CG15: 25778 | CH15: 26696 | CI15: 26696 | CJ15: 26705 | CK15: 27901 | CL15: 27949 | CM15: =+CL15 -> 27949 | CN15: =+CM15+260 -> 28209 | CO15: =+CN15+658+644 -> 29511 | CP15: =+CO15 -> 29511 | CQ15: =+CP15+740 -> 30251 | CR15: =+CQ15 -> 30251 | CS15: =+CR15 -> 30251 | CT15: =+CS15+150 -> 30401 | CU15: =+CT15 -> 30401 | CV15: =+CU15 -> 30401 | CW15: =+CV15+2400 -> 32801 | CX15: =+CW15 -> 32801 | CY15: =+CX15 -> 32801 | CZ15: =+CY15 -> 32801 | DA15: =CZ15+1200 -> 34001 | DB15: =DA15 -> 34001 | DG15: 27949
A16: Power transmission capacity (MVA) | U16: =BN16 -> 27280 | V16: =BR16 -> 30905 | W16: =BV16 -> 40001 | X16: =BZ16 -> 46001 | Y16: =CD16 -> 57011 | Z16: =CH16 -> 90236 | AA16: =CL16 -> 123175 | AB16: =CP16 -> 138675 | AC16: =CT16 -> 147475 | AD16: =CX16 -> 169375 | AE16: =DB16 -> 186950 | BL16: 27280 | BM16: 27280 | BN16: 27280 | BO16: 27280 | BP16: 30905 | BQ16: 36766 | BR16: 30905 | BS16: 36766 | BT16: 36766 | BU16: 38641 | BV16: 40001 | BW16: 40001 | BX16: 40001 | BY16: 40001 | BZ16: 46001 | CA16: 46001 | CB16: 53161 | CC16: 54661 | CD16: 57011 | CE16: 57186 | CF16: 70686 | CG16: 84186 | CH16: 90236 | CI16: 93236 | CJ16: 97236 | CK16: 118175 | CL16: 123175 | CM16: =+CL16 -> 123175 | CN16: =+CM16+6000 -> 129175 | CO16: =+CN16+9500 -> 138675 | CP16: =CO16 -> 138675 | CQ16: =+CP16+2800 -> 141475 | CR16: =+CQ16 -> 141475 | CS16: =+CR16 -> 141475 | CT16: =+CS16+6000 -> 147475 | CU16: =+CT16 -> 147475 | CV16: =+CU16 -> 147475 | CW16: =+CV16+21900 -> 169375 | CX16: =+CW16 -> 169375 | CY16: =+CX16 -> 169375 | CZ16: =+CY16 -> 169375 | DA16: =CZ16+5400 -> 174775 | DB16: =DA16+9175+3000 -> 186950 | DG16: 123175
A17: Revenue Per MVA (in cr) | U17: =U26/U16 -> 0.10318915 | V17: =V26/V16 -> 0.10102119 | W17: =W26/W16 -> 0.086731082 | X17: =X26/X16 -> 0.085762483 | Y17: =Y26/Y16 -> 0.089704443 | Z17: =Z26/Z16 -> 0.092320027 | AA17: =AA26/AA16 -> 0.07975547 | AB17: =AB26/AB16 -> 0.08748011 | ... AE17: =AE26/AE16 -> 0.090123051 | BL17: =BL26/BL16 -> 0.024719575 | BM17: =BM26/BM16 -> 0.024880865 | BN17: =BN26/BN16 -> 0.029094575 | BO17: =BO26/BO16 -> 0.036991935 | BP17: =BP26/BP16 -> 0.022275684 | BQ17: =BQ26/BQ16 -> 0.019155198 | BR17: =BR26/BR16 -> 0.023304643 | BS17: =BS26/BS16 -> 0.028424359 | ... CL17: =CL26/CL16 -> 0.023032271 | CM17: =AVERAGE(CI17:CL17)*1.01 -> 0.023086087 | CN17: =AVERAGE(CJ17:CM17)*1.01 -> 0.022989308 | CO17: =AVERAGE(CK17:CN17)*1.01 -> 0.022635364 | CP17: =AVERAGE(CL17:CO17)*1.01 -> 0.023165115 | CQ17: =AVERAGE(CM17:CP17)*1.03 -> 0.023658038 | CR17: =AVERAGE(CN17:CQ17)*1.03 -> 0.023805315 | CS17: =AVERAGE(CO17:CR17)*1.03 -> 0.024015437 | CT17: =AVERAGE(CP17:CS17)*1.03 -> 0.024370805 | CU17: =AVERAGE(CQ17:CT17)*1.02 -> 0.024441647 | CV17: =AVERAGE(CR17:CU17)*1.02 -> 0.024641467 | CW17: =AVERAGE(CS17:CV17)*1.02 -> 0.024854686 | CX17: =AVERAGE(CT17:CW17)*1.02 -> 0.025068694 | CY17: =AVERAGE(CU17:CX17)*0.98 -> 0.024256591 | CZ17: =AVERAGE(CV17:CY17)*0.98 -> 0.024211252 | DA17: =AVERAGE(CW17:CZ17)*0.98 -> 0.02410585 | DB17: =AVERAGE(CX17:DA17)*0.98 -> 0.023922385 | DG17: 0.020537339
A18: Average System Availibity | V18: =AVERAGE(BO18:BR18) -> 0.99855 | W18: =AVERAGE(BS18:BV18) -> 0.9965 | X18: =AVERAGE(BW18:BZ18) -> 0.995975 | Y18: =AVERAGE(CA18:CD18) -> 0.997 | Z18: =AVERAGE(CE18:CH18) -> 0.996975 | AA18: =AVERAGE(CI18:CL18) -> 0.997325 | AB18: =AVERAGE(CM18:CP18) -> 0.99725713 | AC18: =AVERAGE(CQ18:CT18) -> 0.99726447 | AD18: =AVERAGE(CQ18:CT18) -> 0.99726447 | AE18: =AVERAGE(CY18:DB18) -> 0.99726976 | BL18: 99.8 | BM18: 0.9959 | BN18: 0.9961 | BO18: 0.9987 | BP18: 0.999 | BQ18: 0.9983 | BR18: 0.9982 | BS18: 0.9985 | BT18: 0.9936 | BU18: 0.9969 | BV18: 0.997 | BW18: 0.9918 | BX18: 0.9976 | BY18: 0.9975 | BZ18: 0.997 | CA18: 0.9977 | CB18: 0.9974 | CC18: 0.9967 | CD18: 0.9962 | CE18: 0.997 | CF18: 0.997 | CG18: 0.9971 | CH18: 0.9968 | CI18: 0.9983 | CJ18: 0.9963 | CK18: 0.997 | CL18: 0.9977 | CM18: =AVERAGE(CI18:CL18) -> 0.997325 | CN18: =AVERAGE(CJ18:CM18) -> 0.99708125 | CO18: =AVERAGE(CK18:CN18) -> 0.99727656 | CP18: =AVERAGE(CL18:CO18) -> 0.9973457 | CQ18: =AVERAGE(CM18:CP18) -> 0.99725713 | CR18: =AVERAGE(CN18:CQ18) -> 0.99724016 | CS18: =AVERAGE(CO18:CR18) -> 0.99727989 | CT18: =AVERAGE(CP18:CS18) -> 0.99728072 | ... DB18: =AVERAGE(CX18:DA18) -> 0.99727002 | DG18: 0.9977
A20: Meter unit metrics
A21: cumlative meters Installed (in mn) | Y21: =CD21 -> 0 | Z21: =CH21 -> 3.13 | AA21: =CL21 -> 10.13 | AB21: =CP21 -> 17.73 | AC21: =CT21 -> 29.01 | AD21: =CX21 -> 34.45 | AE21: =DB21 -> 42.61 | CF21: 0.68 | CG21: 1 | CH21: 3.13 | CI21: 5.54 | CJ21: 7.37 | CK21: 9.25 | CL21: 10.13 | CM21: =CL21+1.9 -> 12.03 | CN21: =CM21+1.9 -> 13.93 | CO21: =CN21+1.9 -> 15.83 | CP21: =CO21+1.9 -> 17.73 | CQ21: =CP21+2.82 -> 20.55 | CR21: =CQ21+2.82 -> 23.37 | CS21: =CR21+2.82 -> 26.19 | CT21: =CS21+2.82 -> 29.01 | CU21: =CT21+1.36 -> 30.37 | CV21: =CU21+1.36 -> 31.73 | CW21: =CV21+1.36 -> 33.09 | CX21: =CW21+1.36 -> 34.45 | CY21: =CX21+2.04 -> 36.49 | CZ21: =CY21+2.04 -> 38.53 | DA21: =CZ21+2.04 -> 40.57 | DB21: =DA21+2.04 -> 42.61 | DG21: 10.13
A22: Revenue per meter (in cr) | Z22: =Z28*10/Z21 -> 5291.5016 | AA22: =0+(AA28*10/AA21) -> 3528.8154 | AB22: =0+(AB28*10/AB21) -> 3554.3064 | AC22: =0+(AC28*10/AC21) -> 3683.4679 | AD22: =0+(AD28*10/AD21) -> 4236.4793 | AE22: =0+(AE28*10/AE21) -> 4380.8085 | CF22: =CF28*10/CF21 -> 3576.0294 | CG22: =CG28*10/CG21 -> 4784.8 | CH22: =CH28*10/CH21 -> 2691.4696 | CI22: =CI28*10/CI21 -> 1760.9386 | CJ22: =CJ28*10/CJ21 -> 1106.0109 | CK22: =CK28*10/CK21 -> 873.51351 | CL22: =CL28*10/CL21 -> 963.47483 | CM22: =AVERAGE(CI22:CL22) -> 1175.9845 | CN22: =AVERAGE(CJ22:CM22) -> 1029.7459 | CO22: =AVERAGE(CK22:CN22) -> 1010.6797 | CP22: =AVERAGE(CL22:CO22) -> 1044.9712 | CQ22: =AVERAGE(CM22:CP22)*1.02 -> 1086.6522 | CR22: =AVERAGE(CN22:CQ22)*1.02 -> 1063.8725 | CS22: =AVERAGE(CO22:CR22)*1.02 -> 1072.5748 | CT22: =AVERAGE(CP22:CS22)*1.02 -> 1088.358 | CU22: =AVERAGE(CQ22:CT22)*1.03 -> 1110.2003 | CV22: =AVERAGE(CR22:CU22)*1.03 -> 1116.264 | CW22: =AVERAGE(CS22:CV22)*1.03 -> 1129.7548 | CX22: =AVERAGE(CT22:CW22)*1.03 -> 1144.4786 | CY22: =AVERAGE(CU22:CX22)*1.03 -> 1158.9296 | CZ22: =AVERAGE(CV22:CY22)*1.03 -> 1171.4774 | DA22: =AVERAGE(CW22:CZ22)*1.03 -> 1185.6949 | DB22: =AVERAGE(CX22:DA22)*1.03 -> 1200.0995 | DG22: 1045.1891
A24: Revenue Breakup - Segment wise
A25: Distribution | S25: =SUM(BC25:BF25) -> 0 | T25: =SUM(BG25:BJ25) -> 4351.75 | U25: =SUM(BK25:BN25) -> 7676.35 | V25: =SUM(BO25:BR25) -> 6047.64 | W25: =SUM(BS25:BV25) -> 6966.28 | X25: =SUM(BW25:BZ25) -> 8591.91 | Y25: =SUM(CA25:CD25) -> 10172.77 | Z25: =SUM(CE25:CH25) -> 12266.48 | AA25: =SUM(CI25:CL25) -> 12450.75 | AB25: =SUM(CM25:CP25) -> 12915.441 | AC25: =SUM(CQ25:CT25) -> 13517.992 | AD25: =SUM(CU25:CX25) -> 14172.063 | AE25: =SUM(CY25:DB25) -> 14907.162 | BH25: 649.93 | BI25: 2005.94 | BJ25: 1695.88 | BK25: 2189.42 | BL25: 1913.6 | BM25: 1892.91 | BN25: 1680.42 | BO25: 1437.02 | BP25: 1467.16 | BQ25: 1587.84 | BR25: 1555.62 | BS25: 1741.9 | BT25: 1690.41 | BU25: 1797.28 | BV25: 1736.69 | BW25: 2212.74 | BX25: 2163.87 | BY25: 2103.85 | BZ25: 2111.45 | CA25: 2737.71 | CB25: 2479.65 | CC25: 2559.89 | CD25: 2395.52 | CE25: 3372.94 | CF25: 3013.95 | CG25: 2972.42 | CH25: 2907.17 | CI25: 3359.84 | CJ25: 3117.91 | CK25: 3104 | CL25: 2869 | CM25: =CM7*CM6*CM8/10 -> 3493.0743 | CN25: =CN7*CN6*CN8/10 -> 3249.8575 | CO25: =CO7*CO6*CO8/10 -> 3234.4712 | CP25: =CP7*CP6*CP8/10 -> 2938.0375 | CQ25: =CQ7*CQ6*CQ8/10 -> 3660.263 | CR25: =CR7*CR6*CR8/10 -> 3404.8728 | CS25: =CS7*CS6*CS8/10 -> 3384.3185 | CT25: =CT7*CT6*CT8/10 -> 3068.5376 | ... DB25: =DB7*DB6*DB8/10 -> 3391.6203 | DG25: 3112.0547
A26: Transmission | S26: =SUM(BC26:BF26) -> 3131.8 | T26: =SUM(BG26:BJ26) -> 2192.88 | U26: =SUM(BK26:BN26) -> 2815 | V26: =SUM(BO26:BR26) -> 3122.06 | W26: =SUM(BS26:BV26) -> 3469.33 | X26: =SUM(BW26:BZ26) -> 3945.16 | Y26: =SUM(CA26:CD26) -> 5114.14 | Z26: =SUM(CE26:CH26) -> 8330.59 | AA26: =SUM(CI26:CL26) -> 9823.88 | AB26: =SUM(CM26:CP26) -> 12131.304 | AC26: =SUM(CQ26:CT26) -> 13669.056 | AD26: =SUM(CU26:CX26) -> 15651.442 | AE26: =SUM(CY26:DB26) -> 16848.504 | AZ26: 498.37 | BA26: 508.03 | BB26: 508.99 | BC26: 497.09 | BD26: 506.71 | BE26: 1540.48 | BF26: 587.52 | BG26: 552.76 | BH26: 476.56 | BI26: 577.73 | BJ26: 585.83 | BK26: 668.2 | BL26: 674.35 | BM26: 678.75 | BN26: 793.7 | BO26: 1009.14 | BP26: 688.43 | BQ26: 704.26 | BR26: 720.23 | BS26: 1045.05 | BT26: 788.81 | BU26: 816.07 | BV26: 819.4 | BW26: 835.94 | BX26: 868.2 | BY26: 1173.18 | BZ26: 1067.84 | CA26: 926.19 | CB26: 1017.35 | CC26: 1264.54 | CD26: 1906.06 | CE26: 1746.18 | CF26: 2302.95 | CG26: 2034.76 | CH26: 2246.7 | CI26: 2188.19 | CJ26: 2371.69 | CK26: 2427 | CL26: 2837 | CM26: =CM16*CM17*CM18 -> 2836.022 | CN26: =CN16*CN17*CN18 -> 2960.9763 | CO26: =CO16*CO17*CO18 -> 3130.4103 | CP26: =CP16*CP17*CP18 -> 3203.8956 | CQ26: =CQ16*CQ17*CQ18 -> 3337.8404 | CR26: =CR16*CR17*CR18 -> 3358.5622 | CS26: =CS16*CS17*CS18 -> 3388.3421 | CT26: =CT16*CT17*CT18 -> 3584.3112 | ... DB26: =DB16*DB17*DB18 -> 4460.0806 | DG26: 2523.8684
A27: Trading | S27: =SUM(BC27:BF27) -> 815.78 | T27: =SUM(BG27:BJ27) -> 755.43 | U27: =SUM(BK27:BN27) -> 924.61 | V27: =SUM(BO27:BR27) -> 756.63 | W27: =SUM(BS27:BV27) -> 821.91 | X27: =SUM(BW27:BZ27) -> 755.65 | Y27: =SUM(CA27:CD27) -> 1029.59 | Z27: =SUM(CE27:CH27) -> 1380.44 | AA27: =SUM(CI27:CL27) -> 1091.071 | AB27: =SUM(CM27:CP27) -> 1145.6245 | AC27: =SUM(CQ27:CT27) -> 1191.4495 | AD27: =SUM(CU27:CX27) -> 1239.1075 | AE27: =SUM(CY27:DB27) -> 1288.6718 | AZ27: 184.33 | BA27: 221.19 | BB27: 326.53 | BC27: 112.23 | BD27: 239.32 | BE27: 241.81 | BF27: 222.42 | BG27: 67.94 | BH27: 264.24 | BI27: =246.3-86.9 -> 159.4 | BJ27: 263.85 | BK27: 0.46 | BL27: 5.45 | BM27: 205.86 | BN27: 712.84 | BO27: 0.35 | BP27: 0.6 | BQ27: 304.92 | BR27: 450.76 | BS27: 42.7 | BT27: 62.22 | BU27: 298.35 | BV27: 418.64 | BW27: 83.2 | BX27: 219.41 | BY27: 274.67 | BZ27: 178.37 | CA27: 0.01 | CB27: 176.87 | CC27: 738.3 | CD27: 114.41 | CE27: 167.27 | CF27: 490.29 | CG27: 344.6 | CH27: 378.28 | CI27: 209.71 | CJ27: 200.361 | CK27: 255 | CL27: 426 | CM27: =CI27*(1+CM37) -> 220.1955 | CN27: =CJ27*(1+CN37) -> 210.37905 | CO27: =CK27*(1+CO37) -> 267.75 | CP27: =CL27*(1+CP37) -> 447.3 | CQ27: =CM27*(1+CQ37) -> 229.00332 | CR27: =CN27*(1+CR37) -> 218.79421 | CS27: =CO27*(1+CS37) -> 278.46 | CT27: =CP27*(1+CT37) -> 465.192 | ... DB27: =CX27*(1+DB37) -> 503.15167 | DG27: 397.194
A28: Smart Meter | S28: =SUM(BC28:BF28) -> 0 | T28: =SUM(BG28:BJ28) -> 0 | U28: =SUM(BK28:BN28) -> 0 | V28: =SUM(BO28:BR28) -> 0 | W28: =SUM(BS28:BV28) -> 0 | X28: =SUM(BW28:BZ28) -> 0 | Y28: =SUM(CA28:CD28) -> 290.86 | Z28: =SUM(CE28:CH28) -> 1656.24 | AA28: =SUM(CI28:CL28) -> 3574.69 | AB28: =SUM(CM28:CP28) -> 6301.7853 | AC28: =SUM(CQ28:CT28) -> 10685.74 | AD28: =SUM(CU28:CX28) -> 14594.671 | AE28: =SUM(CY28:DB28) -> 18666.625 | CD28: 290.86 | CE28: 92.16 | CF28: 243.17 | CG28: 478.48 | CH28: 842.43 | CI28: 975.56 | CJ28: =181.64+633.49 -> 815.13 | CK28: 808 | CL28: 976 | CM28: =CM22*CM21/10 -> 1414.7093 | CN28: =CN22*CN21/10 -> 1434.4361 | CO28: =CO22*CO21/10 -> 1599.9059 | CP28: =CP22*CP21/10 -> 1852.734 | CQ28: =CQ22*CQ21/10 -> 2233.0703 | CR28: =CR22*CR21/10 -> 2486.27 | CS28: =CS22*CS21/10 -> 2809.0734 | CT28: =CT22*CT21/10 -> 3157.3267 | ... DB28: =DB22*DB21/10 -> 5113.624 | DG28: 1058.7765
A29: Others | S29: =SUM(BC29:BF29) -> 0 | T29: =SUM(BG29:BJ29) -> 0 | U29: =SUM(BK29:BN29) -> 0 | V29: =SUM(BO29:BR29) -> 0 | W29: =SUM(BS29:BV29) -> 0 | X29: =SUM(BW29:BZ29) -> 0 | Y29: =SUM(CA29:CD29) -> 0 | Z29: =SUM(CE29:CH29) -> 133.34 | AA29: =SUM(CI29:CL29) -> 648.2 | AB29: =SUM(CM29:CP29) -> 648.2 | AC29: =SUM(CQ29:CT29) -> 648.2 | AD29: =SUM(CU29:CX29) -> 648.2 | AE29: =SUM(CY29:DB29) -> 648.2 | CF29: 133.34 | CI29: 85.98 | CJ29: 90.22 | CK29: 137 | CL29: 335 | CM29: =CI29*(1+CM39) -> 85.98 | CN29: =CJ29*(1+CN39) -> 90.22 | CO29: =CK29*(1+CO39) -> 137 | CP29: =CL29*(1+CP39) -> 335 | CQ29: =CM29*(1+CQ39) -> 85.98 | CR29: =CN29*(1+CR39) -> 90.22 | CS29: =CO29*(1+CS39) -> 137 | CT29: =CP29*(1+CT39) -> 335 | ... DB29: =CX29*(1+DB39) -> 335 | DG29: 50
A30: Others (b/f) | S30: =SUM(BC30:BF30) -> 0 | T30: =SUM(BG30:BJ30) -> 0 | U30: =SUM(BK30:BN30) -> 0 | V30: =SUM(BO30:BR30) -> 0 | W30: =SUM(BS30:BV30) -> 0 | X30: =SUM(BW30:BZ30) -> 0 | Y30: =SUM(CA30:CD30) -> 0 | Z30: =SUM(CE30:CH30) -> 0 | AA30: =SUM(CI30:CL30) -> -1.08 | AB30: =SUM(CM30:CP30) -> 0 | AC30: =SUM(CQ30:CT30) -> 0 | AD30: =SUM(CU30:CX30) -> 0 | AE30: =SUM(CY30:DB30) -> 0 | CK30: -1.35 | CL30: 0.27 | CM30: 0 | CN30: 0 | CO30: 0 | CP30: 0 | CQ30: 0 | CR30: 0 | CS30: 0 | CT30: 0 | CU30: 0 | CV30: 0 | CW30: 0 | CX30: 0 | CY30: 0 | CZ30: 0 | DA30: 0 | DB30: 0 | DG30: 0
A31: Total | S31: =SUM(S25:S30) -> 3947.58 | T31: =SUM(T25:T30) -> 7300.06 | U31: =SUM(U25:U30) -> 11415.96 | V31: =SUM(V25:V30) -> 9926.33 | W31: =SUM(W25:W30) -> 11257.52 | X31: =SUM(X25:X30) -> 13292.72 | Y31: =SUM(Y25:Y30) -> 16607.36 | Z31: =SUM(Z25:Z30) -> 23767.09 | ... AE31: =SUM(AE25:AE30) -> 52359.163 | AZ31: =SUM(AZ25:AZ30) -> 682.7 | BA31: =SUM(BA25:BA30) -> 729.22 | BB31: =SUM(BB25:BB30) -> 835.52 | BC31: =SUM(BC25:BC30) -> 609.32 | BD31: =SUM(BD25:BD30) -> 746.03 | BE31: =SUM(BE25:BE30) -> 1782.29 | BF31: =SUM(BF25:BF30) -> 809.94 | BG31: =SUM(BG25:BG30) -> 620.7 | ... DB31: =SUM(DB25:DB30) -> 13803.477 | DG31: 7141.8936
A32: Checksum | S32: =S61-S31 -> -3.1 | T32: =T61-T31 -> 5.39 | U32: =U61-U31 -> 0 | V32: =V61-V31 -> 0 | W32: =W61-W31 -> 0 | X32: =X61-X31 -> 0 | Y32: =Y61-Y31 -> 0 | Z32: =Z61-Z31 -> 0 | ... AE32: =AE61-AE31 -> 0 | AZ32: =AZ61-AZ31 -> 0 | BA32: =BA61-BA31 -> 0 | BB32: =BB61-BB31 -> -0.9 | BC32: =BC61-BC31 -> -0.84 | BD32: =BD61-BD31 -> -0.95 | BE32: =BE61-BE31 -> -1.31 | BF32: =BF61-BF31 -> 0 | BG32: =BG61-BG31 -> 0 | ... DB32: =DB61-DB31 -> 0 | DG32: 0
A34: Revenue Growth % Y-o-Y
A35: Distribution % | U35: =U25/T25-1 -> 0.76396852 | V35: =V25/U25-1 -> -0.21217245 | W35: =W25/V25-1 -> 0.15190058 | X35: =X25/W25-1 -> 0.23335697 | Y35: =Y25/X25-1 -> 0.18399401 | Z35: =Z25/Y25-1 -> 0.20581513 | AA35: =AA25/Z25-1 -> 0.015022239 | AB35: =AB25/AA25-1 -> 0.037322292 | ... AE35: =AE25/AD25-1 -> 0.051869552 | BM35: =BM25/BI25-1 -> -0.056347647 | BN35: =BN25/BJ25-1 -> -0.0091162111 | BO35: =BO25/BK25-1 -> -0.34365266 | BP35: =BP25/BL25-1 -> -0.23329849 | BQ35: =BQ25/BM25-1 -> -0.16116456 | BR35: =BR25/BN25-1 -> -0.074267147 | BS35: =BS25/BO25-1 -> 0.21216128 | BT35: =BT25/BP25-1 -> 0.15216473 | ... DB35: =DB25/CX25-1 -> 0.053295832 | DG35: 0.070475643
A36: Transmission % | T36: =T26/S26-1 -> -0.29980203 | U36: =U26/T26-1 -> 0.28369997 | V36: =V26/U26-1 -> 0.10907993 | W36: =W26/V26-1 -> 0.11123105 | X36: =X26/W26-1 -> 0.13715328 | Y36: =Y26/X26-1 -> 0.29630737 | Z36: =Z26/Y26-1 -> 0.62893272 | AA36: =AA26/Z26-1 -> 0.17925381 | ... AE36: =AE26/AD26-1 -> 0.076482527 | BD36: =BD26/AZ26-1 -> 0.016734555 | BE36: =BE26/BA26-1 -> 2.0322619 | BF36: =BF26/BB26-1 -> 0.15428594 | BG36: =BG26/BC26-1 -> 0.11199179 | BH36: =BH26/BD26-1 -> -0.05950149 | BI36: =BI26/BE26-1 -> -0.62496754 | BJ36: =BJ26/BF26-1 -> -0.0028764978 | BK36: =BK26/BG26-1 -> 0.2088429 | ... DB36: =DB26/CX26-1 -> 0.053291202 | DG36: 0.1233669
A37: Trading % | T37: =T27/S27-1 -> -0.073978278 | U37: =U27/T27-1 -> 0.22395192 | V37: =V27/U27-1 -> -0.1816766 | W37: =W27/V27-1 -> 0.086277309 | X37: =X27/W27-1 -> -0.080617099 | Y37: =Y27/X27-1 -> 0.36252233 | Z37: =Z27/Y27-1 -> 0.34076671 | AA37: =AA27/Z27-1 -> -0.20962085 | ... AE37: =AE27/AD27-1 -> 0.04 | BD37: =BD27/AZ27-1 -> 0.29832366 | BE37: =BE27/BA27-1 -> 0.093223021 | BF37: =BF27/BB27-1 -> -0.31883747 | BG37: =BG27/BC27-1 -> -0.39463602 | BH37: =BH27/BD27-1 -> 0.10412836 | BI37: =BI27/BE27-1 -> -0.34080476 | BJ37: =BJ27/BF27-1 -> 0.18626922 | BK37: =BK27/BG27-1 -> -0.99322932 | ... CK37: =CK27/CG27-1 -> -0.26001161 | CL37: 0.05 | CM37: 0.05 | CN37: 0.05 | CO37: 0.05 | CP37: 0.05 | CQ37: 0.04 | CR37: 0.04 | CS37: 0.04 | CT37: 0.04 | CU37: 0.04 | CV37: 0.04 | CW37: 0.04 | CX37: 0.04 | CY37: 0.04 | CZ37: 0.04 | DA37: 0.04 | DB37: 0.04 | DG37: 0.05
A38: Smart Meter % | Z38: =Z28/Y28-1 -> 4.6942859 | AA38: =AA28/Z28-1 -> 1.1583164 | AB38: =AB28/AA28-1 -> 0.76289 | AC38: =AC28/AB28-1 -> 0.69566876 | AD38: =AD28/AC28-1 -> 0.36580813 | AE38: =AE28/AD28-1 -> 0.27900278 | CH38: =CH28/CD28-1 -> 1.8963419 | CI38: =CI28/CE28-1 -> 9.5855035 | CJ38: =CJ28/CF28-1 -> 2.3520994 | CK38: =CK28/CG28-1 -> 0.68868082 | CL38: =CL28/CH28-1 -> 0.15855323 | CM38: =CM28/CI28-1 -> 0.45015099 | CN38: =CN28/CJ28-1 -> 0.75976354 | CO38: =CO28/CK28-1 -> 0.9800816 | ... DB38: =DB28/CX28-1 -> 0.29697585 | DG38: 0.25681245
A39: Others % | AA39: =AA29/Z29-1 -> 3.8612569 | AB39: =AB29/AA29-1 -> 0 | AC39: =AC29/AB29-1 -> 0 | AD39: =AD29/AC29-1 -> 0 | AE39: =AE29/AD29-1 -> 0 | CJ39: =CJ29/CF29-1 -> -0.32338383 | CL39: 0 | CM39: 0 | CN39: 0 | CO39: 0 | CP39: 0 | CQ39: 0 | CR39: 0 | CS39: 0 | CT39: 0 | CU39: 0 | CV39: 0 | CW39: 0 | CX39: 0 | CY39: 0 | CZ39: 0 | DA39: 0 | DB39: 0 | DG39: 0
A41: EBITDA - Segment Wise
A42: Distribution - EBITDA | W42: =SUM(BS42:BV42) -> 0 | X42: =SUM(BW42:BZ42) -> 1895 | Y42: =SUM(CA42:CD42) -> 2339 | Z42: =SUM(CE42:CH42) -> 1864 | AA42: =SUM(CI42:CL42) -> 2090 | AB42: =SUM(CM42:CP42) -> 2685.1513 | AC42: =SUM(CQ42:CT42) -> 3003.0483 | AD42: =SUM(CU42:CX42) -> 3172.3451 | AE42: =SUM(CY42:DB42) -> 3342.2674 | BW42: 516 | BY42: 545 | BZ42: 834 | CA42: 516 | CB42: 516 | CC42: 677 | CD42: 630 | CE42: -79 | CF42: 588 | CG42: 482 | CH42: 873 | CI42: =1486-SUM(CJ42:CK42) -> 497 | CJ42: 492 | CK42: 497 | CL42: 604 | CM42: =CM25*CM51 -> 695.43967 | CN42: =CN25*CN51 -> 688.589 | CO42: =CO25*CO51 -> 664.37342 | CP42: =CP25*CP51 -> 636.74925 | CQ42: =CQ25*CQ51 -> 792.83865 | CR42: =CR25*CR51 -> 753.02569 | CS42: =CS25*CS51 -> 756.6441 | CT42: =CT25*CT51 -> 700.53984 | ... DB42: =DB25*DB51 -> 760.83068
A43: Transmission - EBITDA | W43: =SUM(BS43:BV43) -> 0 | X43: =SUM(BW43:BZ43) -> 3112 | Y43: =SUM(CA43:CD43) -> 3865 | Z43: =SUM(CE43:CH43) -> 5449 | AA43: =SUM(CI43:CL43) -> 5126 | AB43: =SUM(CM43:CP43) -> 6403.7424 | AC43: =SUM(CQ43:CT43) -> 7403.3865 | AD43: =SUM(CU43:CX43) -> 8491.4519 | AE43: =SUM(CY43:DB43) -> 9144.0792 | BW43: 810 | BY43: 1163 | BZ43: 1139 | CA43: 862 | CB43: 810 | CC43: 1055 | CD43: 1138 | CE43: 1707 | CF43: 1278 | CG43: 1138 | CH43: 1326 | CI43: 1213 | CJ43: 1322 | CK43: 1291 | CL43: 1300 | CM43: =CM26*CM52 -> 1518.6266 | CN43: =CN26*CN52 -> 1571.5745 | CO43: =CO26*CO52 -> 1640.6503 | CP43: =CP26*CP52 -> 1672.8911 | CQ43: =CQ26*CQ52 -> 1798.0389 | CR43: =CR26*CR52 -> 1811.9467 | CS43: =CS26*CS52 -> 1835.5633 | CT43: =CT26*CT52 -> 1957.8377 | ... DB43: =DB26*DB52 -> 2421.036
A44: Trading - EBITDA | W44: =SUM(BS44:BV44) -> 0 | X44: =SUM(BW44:BZ44) -> 0 | Y44: =SUM(CA44:CD44) -> 0 | Z44: =SUM(CE44:CH44) -> 26 | AA44: =SUM(CI44:CL44) -> 84 | AB44: =SUM(CM44:CP44) -> 105.99374 | AC44: =SUM(CQ44:CT44) -> 117.75884 | AD44: =SUM(CU44:CX44) -> 122.8324 | AE44: =SUM(CY44:DB44) -> 127.85405 | CE44: 1 | CF44: 0 | CG44: 1 | CH44: 24 | CI44: =52-SUM(CJ44:CK44) -> 17 | CJ44: 12 | CK44: 23 | CL44: 32 | CM44: =CM27*CM53 -> 19.061756 | CN44: =CN27*CN53 -> 18.501405 | CO44: =CO27*CO53 -> 25.424473 | CP44: =CP27*CP53 -> 43.006105 | CQ44: =CQ27*CQ53 -> 21.768891 | CR44: =CR27*CR53 -> 21.281493 | CS44: =CS27*CS53 -> 27.760067 | CT44: =CT27*CT53 -> 46.948386 | ... DB44: =DB27*DB53 -> 49.935029
A45: Smart Meter - EBITDA | W45: =SUM(BS45:BV45) -> 0 | X45: =SUM(BW45:BZ45) -> 0 | Y45: =SUM(CA45:CD45) -> 0 | Z45: =SUM(CE45:CH45) -> 150 | AA45: =SUM(CI45:CL45) -> 548 | AB45: =SUM(CM45:CP45) -> 1205.3147 | AC45: =SUM(CQ45:CT45) -> 2184.292 | AD45: =SUM(CU45:CX45) -> 3000.7588 | AE45: =SUM(CY45:DB45) -> 3843.2819 | CE45: 21 | CF45: 25 | CG45: 35 | CH45: 69 | CI45: 62 | CJ45: 116 | CK45: 156 | CL45: 214 | CM45: =CM28*CM54 -> 232.78809 | CN45: =CN28*CN54 -> 272.25186 | CO45: =CO28*CO54 -> 322.65187 | CP45: =CP28*CP54 -> 377.62288 | CQ45: =CQ28*CQ54 -> 436.91643 | CR45: =CR28*CR54 -> 506.37317 | CS45: =CS28*CS54 -> 582.15097 | CT45: =CT28*CT54 -> 658.85148 | ... DB45: =DB28*DB54 -> 1053.106
A46: Other (b/f) - EBITDA | W46: =SUM(BS46:BV46) -> 0 | X46: =SUM(BW46:BZ46) -> -522.59 | Y46: =SUM(CA46:CD46) -> -492.8 | Z46: =SUM(CE46:CH46) -> -421.9 | AA46: =SUM(CI46:CL46) -> 138.69 | AB46: =SUM(CM46:CP46) -> 154.42685 | AC46: =SUM(CQ46:CT46) -> 153.99463 | AD46: =SUM(CU46:CX46) -> 153.92052 | AE46: =SUM(CY46:DB46) -> 153.91979 | BW46: -118.07 | BZ46: -404.52 | CA46: -108.7 | CB46: 24.14 | CC46: -261.36 | CD46: -146.88 | CE46: 1 | CF46: -175.86 | CG46: 5 | CH46: -252.04 | CI46: 21.69 | CJ46: 12 | CK46: 28 | CL46: 77 | CM46: =CM29*CM55 -> 20.194692 | CN46: =CN29*CN55 -> 20.798307 | CO46: =CO29*CO55 -> 32.182523 | CP46: =CP29*CP55 -> 81.251325 | CQ46: =CQ29*CQ55 -> 20.286948 | CR46: =CR29*CR55 -> 21.3116 | CS46: =CS29*CS55 -> 32.556939 | CT46: =CT29*CT55 -> 79.839148 | ... DB46: =DB29*DB55 -> 79.551744
X47: =SUM(X42:X46) -> 4484.41 | Y47: =SUM(Y42:Y46) -> 5711.2 | Z47: =SUM(Z42:Z46) -> 7067.1 | AA47: =SUM(AA42:AA46) -> 7986.69 | AB47: =SUM(AB42:AB46) -> 10554.629 | AC47: =SUM(AC42:AC46) -> 12862.48 | AD47: =SUM(AD42:AD46) -> 14941.309 | AE47: =SUM(AE42:AE46) -> 16611.402 | BW47: =SUM(BW42:BW46) -> 1207.93 | BX47: =SUM(BX42:BX46) -> 0 | BY47: =SUM(BY42:BY46) -> 1708 | BZ47: =SUM(BZ42:BZ46) -> 1568.48 | CA47: =SUM(CA42:CA46) -> 1269.3 | CB47: =SUM(CB42:CB46) -> 1350.14 | CC47: =SUM(CC42:CC46) -> 1470.64 | CD47: =SUM(CD42:CD46) -> 1621.12 | ... DB47: =SUM(DB42:DB46) -> 4364.4595
...

Sheet QTR Raw
A1: ='Annual Raw'!A1 -> 271875 | B1: X | C1: 201206 | D1: 201209 | E1: 201212 | F1: 201303 | G1: 201306 | H1: 201309 | I1: 201312 | J1: 201403 | K1: 201406 | L1: 201409 | M1: 201412 | N1: 201503 | O1: 201506 | P1: 201509 | Q1: 201512 | R1: 201603 | S1: 201606 | T1: 201609 | U1: 201612 | V1: 201703 | W1: 201706 | X1: 201709 | Y1: 201712 | Z1: 201803 | AA1: 201806 | AB1: 201809 | AC1: 201812 | AD1: 201903 | AE1: 201906 | AF1: 201909 | AG1: 201912 | AH1: 202003 | AI1: 202006 | AJ1: 202009 | AK1: 202012 | AL1: 202103 | AM1: 202106 | AN1: 202109 | AO1: 202112 | AP1: 202203 | AQ1: 202206 | AR1: 202209 | AS1: 202212 | AT1: 202303 | AU1: 202306 | AV1: 202309 | AW1: 202312 | AX1: 202403 | AY1: 202406 | AZ1: 202409 | BA1: 202412 | BB1: 202503 | BC1: 202506 | BD1: 202509 | BE1: 202512 | BF1: 202603 | BG1: 202606 | BH1: 202609 | BI1: 202612 | BJ1: 202703 | BK1: 202706 | BL1: 202709 | BM1: 202712 | BN1: 202803 | BO1: 202806 | BP1: 202809 | BQ1: 202812 | BR1: 202903 | BS1: 202906 | BT1: 202909 | BU1: 202912 | BV1: 203003
A3: Field Description | B3: Field Name
A4: Company Name | B4: CD_COMPNAME | C4: =_xll.EQNXTDZ(A1,B4,C1) -> Adani Energy Solutions Ltd.
A5: Date End | B5: QTR_DATE_END | C5: =_xll.EQNXTDZ($A$1,$B5,C$1,$B$1) -> 0 | D5: =_xll.EQNXTDZ($A$1,$B5,D$1,$B$1) -> 0 | E5: =_xll.EQNXTDZ($A$1,$B5,E$1,$B$1) -> 0 | F5: =_xll.EQNXTDZ($A$1,$B5,F$1,$B$1) -> 0 | G5: =_xll.EQNXTDZ($A$1,$B5,G$1,$B$1) -> 0 | H5: =_xll.EQNXTDZ($A$1,$B5,H$1,$B$1) -> 0 | I5: =_xll.EQNXTDZ($A$1,$B5,I$1,$B$1) -> 0 | J5: =_xll.EQNXTDZ($A$1,$B5,J$1,$B$1) -> 0 | ... BV5: =_xll.EQNXTDZ($A$1,$B5,BV$1,$B$1) -> 0
A6: Gross Sales | B6: QTR_GROSS_SALE | C6: =_xll.EQNXTDZ($A$1,$B6,C$1,$B$1) -> 0 | D6: =_xll.EQNXTDZ($A$1,$B6,D$1,$B$1) -> 0 | E6: =_xll.EQNXTDZ($A$1,$B6,E$1,$B$1) -> 0 | F6: =_xll.EQNXTDZ($A$1,$B6,F$1,$B$1) -> 0 | G6: =_xll.EQNXTDZ($A$1,$B6,G$1,$B$1) -> 0 | H6: =_xll.EQNXTDZ($A$1,$B6,H$1,$B$1) -> 0 | I6: =_xll.EQNXTDZ($A$1,$B6,I$1,$B$1) -> 0 | J6: =_xll.EQNXTDZ($A$1,$B6,J$1,$B$1) -> 0 | ... BV6: =_xll.EQNXTDZ($A$1,$B6,BV$1,$B$1) -> 0
A7: Less: Excise Duty | B7: QTR_EXCISE_DUTY | C7: =_xll.EQNXTDZ($A$1,$B7,C$1,$B$1) -> 0 | D7: =_xll.EQNXTDZ($A$1,$B7,D$1,$B$1) -> 0 | E7: =_xll.EQNXTDZ($A$1,$B7,E$1,$B$1) -> 0 | F7: =_xll.EQNXTDZ($A$1,$B7,F$1,$B$1) -> 0 | G7: =_xll.EQNXTDZ($A$1,$B7,G$1,$B$1) -> 0 | H7: =_xll.EQNXTDZ($A$1,$B7,H$1,$B$1) -> 0 | I7: =_xll.EQNXTDZ($A$1,$B7,I$1,$B$1) -> 0 | J7: =_xll.EQNXTDZ($A$1,$B7,J$1,$B$1) -> 0 | ... BV7: =_xll.EQNXTDZ($A$1,$B7,BV$1,$B$1) -> 0
A8: Other operating income | B8: QTR_JOB_WORKS | C8: =_xll.EQNXTDZ($A$1,$B8,C$1,$B$1) -> 0 | D8: =_xll.EQNXTDZ($A$1,$B8,D$1,$B$1) -> 0 | E8: =_xll.EQNXTDZ($A$1,$B8,E$1,$B$1) -> 0 | F8: =_xll.EQNXTDZ($A$1,$B8,F$1,$B$1) -> 0 | G8: =_xll.EQNXTDZ($A$1,$B8,G$1,$B$1) -> 0 | H8: =_xll.EQNXTDZ($A$1,$B8,H$1,$B$1) -> 0 | I8: =_xll.EQNXTDZ($A$1,$B8,I$1,$B$1) -> 0 | J8: =_xll.EQNXTDZ($A$1,$B8,J$1,$B$1) -> 0 | ... BV8: =_xll.EQNXTDZ($A$1,$B8,BV$1,$B$1) -> 0
A9: Net Sales & Other Operating Income | B9: QTR_NET_SALES | C9: =_xll.EQNXTDZ($A$1,$B9,C$1,$B$1) -> 0 | D9: =_xll.EQNXTDZ($A$1,$B9,D$1,$B$1) -> 0 | E9: =_xll.EQNXTDZ($A$1,$B9,E$1,$B$1) -> 0 | F9: =_xll.EQNXTDZ($A$1,$B9,F$1,$B$1) -> 0 | G9: =_xll.EQNXTDZ($A$1,$B9,G$1,$B$1) -> 0 | H9: =_xll.EQNXTDZ($A$1,$B9,H$1,$B$1) -> 0 | I9: =_xll.EQNXTDZ($A$1,$B9,I$1,$B$1) -> 0 | J9: =_xll.EQNXTDZ($A$1,$B9,J$1,$B$1) -> 0 | ... BV9: =_xll.EQNXTDZ($A$1,$B9,BV$1,$B$1) -> 0
A10: (Increase) / Decrease In Stocks | B10: QTR_INC_DEC_INVENTORY | C10: =_xll.EQNXTDZ($A$1,$B10,C$1,$B$1) -> 0 | D10: =_xll.EQNXTDZ($A$1,$B10,D$1,$B$1) -> 0 | E10: =_xll.EQNXTDZ($A$1,$B10,E$1,$B$1) -> 0 | F10: =_xll.EQNXTDZ($A$1,$B10,F$1,$B$1) -> 0 | G10: =_xll.EQNXTDZ($A$1,$B10,G$1,$B$1) -> 0 | H10: =_xll.EQNXTDZ($A$1,$B10,H$1,$B$1) -> 0 | I10: =_xll.EQNXTDZ($A$1,$B10,I$1,$B$1) -> 0 | J10: =_xll.EQNXTDZ($A$1,$B10,J$1,$B$1) -> 0 | ... BV10: =_xll.EQNXTDZ($A$1,$B10,BV$1,$B$1) -> 0
A11: Cost of Services & Raw Materials | B11: QTR_RAW_MATERIAL_COST | C11: =_xll.EQNXTDZ($A$1,$B11,C$1,$B$1) -> 0 | D11: =_xll.EQNXTDZ($A$1,$B11,D$1,$B$1) -> 0 | E11: =_xll.EQNXTDZ($A$1,$B11,E$1,$B$1) -> 0 | F11: =_xll.EQNXTDZ($A$1,$B11,F$1,$B$1) -> 0 | G11: =_xll.EQNXTDZ($A$1,$B11,G$1,$B$1) -> 0 | H11: =_xll.EQNXTDZ($A$1,$B11,H$1,$B$1) -> 0 | I11: =_xll.EQNXTDZ($A$1,$B11,I$1,$B$1) -> 0 | J11: =_xll.EQNXTDZ($A$1,$B11,J$1,$B$1) -> 0 | ... BV11: =_xll.EQNXTDZ($A$1,$B11,BV$1,$B$1) -> 0
A12: Purchase of Finished Goods | B12: QTR_PURCHASE_FIN_GOOD | C12: =_xll.EQNXTDZ($A$1,$B12,C$1,$B$1) -> 0 | D12: =_xll.EQNXTDZ($A$1,$B12,D$1,$B$1) -> 0 | E12: =_xll.EQNXTDZ($A$1,$B12,E$1,$B$1) -> 0 | F12: =_xll.EQNXTDZ($A$1,$B12,F$1,$B$1) -> 0 | G12: =_xll.EQNXTDZ($A$1,$B12,G$1,$B$1) -> 0 | H12: =_xll.EQNXTDZ($A$1,$B12,H$1,$B$1) -> 0 | I12: =_xll.EQNXTDZ($A$1,$B12,I$1,$B$1) -> 0 | J12: =_xll.EQNXTDZ($A$1,$B12,J$1,$B$1) -> 0 | ... BV12: =_xll.EQNXTDZ($A$1,$B12,BV$1,$B$1) -> 0
A13: Excise Duty | B13: QTR_EXCISE | C13: =_xll.EQNXTDZ($A$1,$B13,C$1,$B$1) -> 0 | D13: =_xll.EQNXTDZ($A$1,$B13,D$1,$B$1) -> 0 | E13: =_xll.EQNXTDZ($A$1,$B13,E$1,$B$1) -> 0 | F13: =_xll.EQNXTDZ($A$1,$B13,F$1,$B$1) -> 0 | G13: =_xll.EQNXTDZ($A$1,$B13,G$1,$B$1) -> 0 | H13: =_xll.EQNXTDZ($A$1,$B13,H$1,$B$1) -> 0 | I13: =_xll.EQNXTDZ($A$1,$B13,I$1,$B$1) -> 0 | J13: =_xll.EQNXTDZ($A$1,$B13,J$1,$B$1) -> 0 | ... BV13: =_xll.EQNXTDZ($A$1,$B13,BV$1,$B$1) -> 0
A14: Operating & Manufacturing Expenses | B14: QTR_MFG_EXPS | C14: =_xll.EQNXTDZ($A$1,$B14,C$1,$B$1) -> 0 | D14: =_xll.EQNXTDZ($A$1,$B14,D$1,$B$1) -> 0 | E14: =_xll.EQNXTDZ($A$1,$B14,E$1,$B$1) -> 0 | F14: =_xll.EQNXTDZ($A$1,$B14,F$1,$B$1) -> 0 | G14: =_xll.EQNXTDZ($A$1,$B14,G$1,$B$1) -> 0 | H14: =_xll.EQNXTDZ($A$1,$B14,H$1,$B$1) -> 0 | I14: =_xll.EQNXTDZ($A$1,$B14,I$1,$B$1) -> 0 | J14: =_xll.EQNXTDZ($A$1,$B14,J$1,$B$1) -> 0 | ... BV14: =_xll.EQNXTDZ($A$1,$B14,BV$1,$B$1) -> 0
A15: Electricity Power & Fuel Cost | B15: QTR_ELECTRICITY_POWER_FUEL | C15: =_xll.EQNXTDZ($A$1,$B15,C$1,$B$1) -> 0 | D15: =_xll.EQNXTDZ($A$1,$B15,D$1,$B$1) -> 0 | E15: =_xll.EQNXTDZ($A$1,$B15,E$1,$B$1) -> 0 | F15: =_xll.EQNXTDZ($A$1,$B15,F$1,$B$1) -> 0 | G15: =_xll.EQNXTDZ($A$1,$B15,G$1,$B$1) -> 0 | H15: =_xll.EQNXTDZ($A$1,$B15,H$1,$B$1) -> 0 | I15: =_xll.EQNXTDZ($A$1,$B15,I$1,$B$1) -> 0 | J15: =_xll.EQNXTDZ($A$1,$B15,J$1,$B$1) -> 0 | ... BV15: =_xll.EQNXTDZ($A$1,$B15,BV$1,$B$1) -> 0
A16: Employee Cost | B16: QTR_EXPLOYEE_COST | C16: =_xll.EQNXTDZ($A$1,$B16,C$1,$B$1) -> 0 | D16: =_xll.EQNXTDZ($A$1,$B16,D$1,$B$1) -> 0 | E16: =_xll.EQNXTDZ($A$1,$B16,E$1,$B$1) -> 0 | F16: =_xll.EQNXTDZ($A$1,$B16,F$1,$B$1) -> 0 | G16: =_xll.EQNXTDZ($A$1,$B16,G$1,$B$1) -> 0 | H16: =_xll.EQNXTDZ($A$1,$B16,H$1,$B$1) -> 0 | I16: =_xll.EQNXTDZ($A$1,$B16,I$1,$B$1) -> 0 | J16: =_xll.EQNXTDZ($A$1,$B16,J$1,$B$1) -> 0 | ... BV16: =_xll.EQNXTDZ($A$1,$B16,BV$1,$B$1) -> 0
... A42: Consolidated PAT(after extra items) | B42: QTR_CONS_PAT_EXITM | C42: =_xll.EQNXTDZ($A$1,$B42,C$1,$B$1) -> 0 | D42: =_xll.EQNXTDZ($A$1,$B42,D$1,$B$1) -> 0 | E42: =_xll.EQNXTDZ($A$1,$B42,E$1,$B$1) -> 0 | F42: =_xll.EQNXTDZ($A$1,$B42,F$1,$B$1) -> 0 | G42: =_xll.EQNXTDZ($A$1,$B42,G$1,$B$1) -> 0 | H42: =_xll.EQNXTDZ($A$1,$B42,H$1,$B$1) -> 0 | I42: =_xll.EQNXTDZ($A$1,$B42,I$1,$B$1) -> 0 | J42: =_xll.EQNXTDZ($A$1,$B42,J$1,$B$1) -> 0 | ... BV42: =_xll.EQNXTDZ($A$1,$B42,BV$1,$B$1) -> 0
A44: Field Description | B44: Field Name
A45: Equity Capital | B45: QTR_EQUITY_CAP | C45: =_xll.EQNXTDZ($A$1,$B45,C$1,$B$1) -> 0 | D45: =_xll.EQNXTDZ($A$1,$B45,D$1,$B$1) -> 0 | E45: =_xll.EQNXTDZ($A$1,$B45,E$1,$B$1) -> 0 | F45: =_xll.EQNXTDZ($A$1,$B45,F$1,$B$1) -> 0 | G45: =_xll.EQNXTDZ($A$1,$B45,G$1,$B$1) -> 0 | H45: =_xll.EQNXTDZ($A$1,$B45,H$1,$B$1) -> 0 | I45: =_xll.EQNXTDZ($A$1,$B45,I$1,$B$1) -> 0 | J45: =_xll.EQNXTDZ($A$1,$B45,J$1,$B$1) -> 0 | ... BV45: =_xll.EQNXTDZ($A$1,$B45,BV$1,$B$1) -> 0
A46: Face Value | B46: QTR_FV | C46: =_xll.EQNXTDZ($A$1,$B46,C$1,$B$1) -> 0 | D46: =_xll.EQNXTDZ($A$1,$B46,D$1,$B$1) -> 0 | E46: =_xll.EQNXTDZ($A$1,$B46,E$1,$B$1) -> 0 | F46: =_xll.EQNXTDZ($A$1,$B46,F$1,$B$1) -> 0 | G46: =_xll.EQNXTDZ($A$1,$B46,G$1,$B$1) -> 0 | H46: =_xll.EQNXTDZ($A$1,$B46,H$1,$B$1) -> 0 | I46: =_xll.EQNXTDZ($A$1,$B46,I$1,$B$1) -> 0 | J46: =_xll.EQNXTDZ($A$1,$B46,J$1,$B$1) -> 0 | ... BV46: =_xll.EQNXTDZ($A$1,$B46,BV$1,$B$1) -> 0
A47: Month End | B47: BMONTH_MONTHEND | C47: =_xll.EQNXTDZ($A$1,$B47,C$5) -> 0 | D47: =_xll.EQNXTDZ($A$1,$B47,D$5) -> 0 | E47: =_xll.EQNXTDZ($A$1,$B47,E$5) -> 0 | F47: =_xll.EQNXTDZ($A$1,$B47,F$5) -> 0 | G47: =_xll.EQNXTDZ($A$1,$B47,G$5) -> 0 | H47: =_xll.EQNXTDZ($A$1,$B47,H$5) -> 0 | I47: =_xll.EQNXTDZ($A$1,$B47,I$5) -> 0 | J47: =_xll.EQNXTDZ($A$1,$B47,J$5) -> 0 | ... BV47: =_xll.EQNXTDZ($A$1,$B47,BV$5) -> 0
A48: Close | B48: BMONTH_CLOSE | C48: =_xll.EQNXTDZ($A$1,$B48,C$5) -> 0 | D48: =_xll.EQNXTDZ($A$1,$B48,D$5) -> 0 | E48: =_xll.EQNXTDZ($A$1,$B48,E$5) -> 0 | F48: =_xll.EQNXTDZ($A$1,$B48,F$5) -> 0 | G48: =_xll.EQNXTDZ($A$1,$B48,G$5) -> 0 | H48: =_xll.EQNXTDZ($A$1,$B48,H$5) -> 0 | I48: =_xll.EQNXTDZ($A$1,$B48,I$5) -> 0 | J48: =_xll.EQNXTDZ($A$1,$B48,J$5) -> 0 | ... BV48: =_xll.EQNXTDZ($A$1,$B48,BV$5) -> 0
A49: Total of Promoter and Promoter Group | B49: SHP_TPFTOTALPROMOTER | C49: =_xll.EQNXTDZ($A$1,$B49,C$5) -> 0 | D49: =_xll.EQNXTDZ($A$1,$B49,D$5) -> 0 | E49: =_xll.EQNXTDZ($A$1,$B49,E$5) -> 0 | F49: =_xll.EQNXTDZ($A$1,$B49,F$5) -> 0 | G49: =_xll.EQNXTDZ($A$1,$B49,G$5) -> 0 | H49: =_xll.EQNXTDZ($A$1,$B49,H$5) -> 0 | I49: =_xll.EQNXTDZ($A$1,$B49,I$5) -> 0 | J49: =_xll.EQNXTDZ($A$1,$B49,J$5) -> 0 | ... BV49: =_xll.EQNXTDZ($A$1,$B49,BV$5) -> 0
A50: Total of Promoter and Promoter Group Pledged | B50: SHP_PSHFTOTALPROMOTER | C50: =_xll.EQNXTDZ($A$1,$B50,C$5) -> 0 | D50: =_xll.EQNXTDZ($A$1,$B50,D$5) -> 0 | E50: =_xll.EQNXTDZ($A$1,$B50,E$5) -> 0 | F50: =_xll.EQNXTDZ($A$1,$B50,F$5) -> 0 | G50: =_xll.EQNXTDZ($A$1,$B50,G$5) -> 0 | H50: =_xll.EQNXTDZ($A$1,$B50,H$5) -> 0 | I50: =_xll.EQNXTDZ($A$1,$B50,I$5) -> 0 | J50: =_xll.EQNXTDZ($A$1,$B50,J$5) -> 0 | ... BV50: =_xll.EQNXTDZ($A$1,$B50,BV$5) -> 0
A54: Field Description | B54: Field Name | C54: =_xll.EQNXTDZ($A$1,$B54,C$5) -> 0 | D54: =_xll.EQNXTDZ($A$1,$B54,D$5) -> 0 | E54: =_xll.EQNXTDZ($A$1,$B54,E$5) -> 0 | F54: =_xll.EQNXTDZ($A$1,$B54,F$5) -> 0 | G54: =_xll.EQNXTDZ($A$1,$B54,G$5) -> 0 | H54: =_xll.EQNXTDZ($A$1,$B54,H$5) -> 0 | I54: =_xll.EQNXTDZ($A$1,$B54,I$5) -> 0 | J54: =_xll.EQNXTDZ($A$1,$B54,J$5) -> 0 | ... BV54: =_xll.EQNXTDZ($A$1,$B54,BV$5) -> 0
A55: Year End | B55: QTRB_DATE_END | C55: =_xll.EQNXTDZ($A$1,$B55,C$5,$B$1) -> 0 | D55: =_xll.EQNXTDZ($A$1,$B55,D$5,$B$1) -> 0 | E55: =_xll.EQNXTDZ($A$1,$B55,E$5,$B$1) -> 0 | F55: =_xll.EQNXTDZ($A$1,$B55,F$5,$B$1) -> 0 | G55: =_xll.EQNXTDZ($A$1,$B55,G$5,$B$1) -> 0 | H55: =_xll.EQNXTDZ($A$1,$B55,H$5,$B$1) -> 0 | I55: =_xll.EQNXTDZ($A$1,$B55,I$5,$B$1) -> 0 | J55: =_xll.EQNXTDZ($A$1,$B55,J$5,$B$1) -> 0 | ... BV55: =_xll.EQNXTDZ($A$1,$B55,BV$5,$B$1) -> 0
A56: Share Capital | B56: QTRB_SHARE_CAPITAL | C56: =_xll.EQNXTDZ($A$1,$B56,C$5,$B$1) -> 0 | D56: =_xll.EQNXTDZ($A$1,$B56,D$5,$B$1) -> 0 | E56: =_xll.EQNXTDZ($A$1,$B56,E$5,$B$1) -> 0 | F56: =_xll.EQNXTDZ($A$1,$B56,F$5,$B$1) -> 0 | G56: =_xll.EQNXTDZ($A$1,$B56,G$5,$B$1) -> 0 | H56: =_xll.EQNXTDZ($A$1,$B56,H$5,$B$1) -> 0 | I56: =_xll.EQNXTDZ($A$1,$B56,I$5,$B$1) -> 0 | J56: =_xll.EQNXTDZ($A$1,$B56,J$5,$B$1) -> 0 | ... BV56: =_xll.EQNXTDZ($A$1,$B56,BV$5,$B$1) -> 0
A57: Share Warrants & outstandings | B57: QTRB_SHAREWARNDOUT | C57: =_xll.EQNXTDZ($A$1,$B57,C$5,$B$1) -> 0 | D57: =_xll.EQNXTDZ($A$1,$B57,D$5,$B$1) -> 0 | E57: =_xll.EQNXTDZ($A$1,$B57,E$5,$B$1) -> 0 | F57: =_xll.EQNXTDZ($A$1,$B57,F$5,$B$1) -> 0 | G57: =_xll.EQNXTDZ($A$1,$B57,G$5,$B$1) -> 0 | H57: =_xll.EQNXTDZ($A$1,$B57,H$5,$B$1) -> 0 | I57: =_xll.EQNXTDZ($A$1,$B57,I$5,$B$1) -> 0 | J57: =_xll.EQNXTDZ($A$1,$B57,J$5,$B$1) -> 0 | ... BV57: =_xll.EQNXTDZ($A$1,$B57,BV$5,$B$1) -> 0
A58: Reserves & Surplus | B58: QTRB_RESERVE | C58: =_xll.EQNXTDZ($A$1,$B58,C$5,$B$1) -> 0 | D58: =_xll.EQNXTDZ($A$1,$B58,D$5,$B$1) -> 0 | E58: =_xll.EQNXTDZ($A$1,$B58,E$5,$B$1) -> 0 | F58: =_xll.EQNXTDZ($A$1,$B58,F$5,$B$1) -> 0 | G58: =_xll.EQNXTDZ($A$1,$B58,G$5,$B$1) -> 0 | H58: =_xll.EQNXTDZ($A$1,$B58,H$5,$B$1) -> 0 | I58: =_xll.EQNXTDZ($A$1,$B58,I$5,$B$1) -> 0 | J58: =_xll.EQNXTDZ($A$1,$B58,J$5,$B$1) -> 0 | ... BV58: =_xll.EQNXTDZ($A$1,$B58,BV$5,$B$1) -> 0
A59: Shareholder's Funds | B59: QTRB_SHAREHODERS_FUNDS | C59: =_xll.EQNXTDZ($A$1,$B59,C$5,$B$1) -> 0 | D59: =_xll.EQNXTDZ($A$1,$B59,D$5,$B$1) -> 0 | E59: =_xll.EQNXTDZ($A$1,$B59,E$5,$B$1) -> 0 | F59: =_xll.EQNXTDZ($A$1,$B59,F$5,$B$1) -> 0 | G59: =_xll.EQNXTDZ($A$1,$B59,G$5,$B$1) -> 0 | H59: =_xll.EQNXTDZ($A$1,$B59,H$5,$B$1) -> 0 | I59: =_xll.EQNXTDZ($A$1,$B59,I$5,$B$1) -> 0 | J59: =_xll.EQNXTDZ($A$1,$B59,J$5,$B$1) -> 0 | ... BV59: =_xll.EQNXTDZ($A$1,$B59,BV$5,$B$1) -> 0
A60: Minority Interest | B60: QTRB_MINORITY_INTEREST_BS | C60: =_xll.EQNXTDZ($A$1,$B60,C$5,$B$1) -> 0 | D60: =_xll.EQNXTDZ($A$1,$B60,D$5,$B$1) -> 0 | E60: =_xll.EQNXTDZ($A$1,$B60,E$5,$B$1) -> 0 | F60: =_xll.EQNXTDZ($A$1,$B60,F$5,$B$1) -> 0 | G60: =_xll.EQNXTDZ($A$1,$B60,G$5,$B$1) -> 0 | H60: =_xll.EQNXTDZ($A$1,$B60,H$5,$B$1) -> 0 | I60: =_xll.EQNXTDZ($A$1,$B60,I$5,$B$1) -> 0 | J60: =_xll.EQNXTDZ($A$1,$B60,J$5,$B$1) -> 0 | ... BV60: =_xll.EQNXTDZ($A$1,$B60,BV$5,$B$1) -> 0
A61: Long Term Borrowings | B61: QTRB_TOTAL_DEBTS | C61: =_xll.EQNXTDZ($A$1,$B61,C$5,$B$1) -> 0 | D61: =_xll.EQNXTDZ($A$1,$B61,D$5,$B$1) -> 0 | E61: =_xll.EQNXTDZ($A$1,$B61,E$5,$B$1) -> 0 | F61: =_xll.EQNXTDZ($A$1,$B61,F$5,$B$1) -> 0 | G61: =_xll.EQNXTDZ($A$1,$B61,G$5,$B$1) -> 0 | H61: =_xll.EQNXTDZ($A$1,$B61,H$5,$B$1) -> 0 | I61: =_xll.EQNXTDZ($A$1,$B61,I$5,$B$1) -> 0 | J61: =_xll.EQNXTDZ($A$1,$B61,J$5,$B$1) -> 0 | ... BV61: =_xll.EQNXTDZ($A$1,$B61,BV$5,$B$1) -> 0
A62: Secured Loans | B62: QTRB_SECURED_LOANS | C62: =_xll.EQNXTDZ($A$1,$B62,C$5,$B$1) -> 0 | D62: =_xll.EQNXTDZ($A$1,$B62,D$5,$B$1) -> 0 | E62: =_xll.EQNXTDZ($A$1,$B62,E$5,$B$1) -> 0 | F62: =_xll.EQNXTDZ($A$1,$B62,F$5,$B$1) -> 0 | G62: =_xll.EQNXTDZ($A$1,$B62,G$5,$B$1) -> 0 | H62: =_xll.EQNXTDZ($A$1,$B62,H$5,$B$1) -> 0 | I62: =_xll.EQNXTDZ($A$1,$B62,I$5,$B$1) -> 0 | J62: =_xll.EQNXTDZ($A$1,$B62,J$5,$B$1) -> 0 | ... BV62: =_xll.EQNXTDZ($A$1,$B62,BV$5,$B$1) -> 0
A63: Unsecured Loans | B63: QTRB_UNSECURED_LOANS_NF | C63: =_xll.EQNXTDZ($A$1,$B63,C$5,$B$1) -> 0 | D63: =_xll.EQNXTDZ($A$1,$B63,D$5,$B$1) -> 0 | E63: =_xll.EQNXTDZ($A$1,$B63,E$5,$B$1) -> 0 | F63: =_xll.EQNXTDZ($A$1,$B63,F$5,$B$1) -> 0 | G63: =_xll.EQNXTDZ($A$1,$B63,G$5,$B$1) -> 0 | H63: =_xll.EQNXTDZ($A$1,$B63,H$5,$B$1) -> 0 | I63: =_xll.EQNXTDZ($A$1,$B63,I$5,$B$1) -> 0 | J63: =_xll.EQNXTDZ($A$1,$B63,J$5,$B$1) -> 0 | ... BV63: =_xll.EQNXTDZ($A$1,$B63,BV$5,$B$1) -> 0
A64: Other Long Term Liabilities | B64: QTRB_OTHER_LT_LIABILITIES | C64: =_xll.EQNXTDZ($A$1,$B64,C$5,$B$1) -> 0 | D64: =_xll.EQNXTDZ($A$1,$B64,D$5,$B$1) -> 0 | E64: =_xll.EQNXTDZ($A$1,$B64,E$5,$B$1) -> 0 | F64: =_xll.EQNXTDZ($A$1,$B64,F$5,$B$1) -> 0 | G64: =_xll.EQNXTDZ($A$1,$B64,G$5,$B$1) -> 0 | H64: =_xll.EQNXTDZ($A$1,$B64,H$5,$B$1) -> 0 | I64: =_xll.EQNXTDZ($A$1,$B64,I$5,$B$1) -> 0 | J64: =_xll.EQNXTDZ($A$1,$B64,J$5,$B$1) -> 0 | ... BV64: =_xll.EQNXTDZ($A$1,$B64,BV$5,$B$1) -> 0
A65: Long Term Trade Payables | B65: QTRB_LT_TRADE_PAYABLE | C65: =_xll.EQNXTDZ($A$1,$B65,C$5,$B$1) -> 0 | D65: =_xll.EQNXTDZ($A$1,$B65,D$5,$B$1) -> 0 | E65: =_xll.EQNXTDZ($A$1,$B65,E$5,$B$1) -> 0 | F65: =_xll.EQNXTDZ($A$1,$B65,F$5,$B$1) -> 0 | G65: =_xll.EQNXTDZ($A$1,$B65,G$5,$B$1) -> 0 | H65: =_xll.EQNXTDZ($A$1,$B65,H$5,$B$1) -> 0 | I65: =_xll.EQNXTDZ($A$1,$B65,I$5,$B$1) -> 0 | J65: =_xll.EQNXTDZ($A$1,$B65,J$5,$B$1) -> 0 | ... BV65: =_xll.EQNXTDZ($A$1,$B65,BV$5,$B$1) -> 0
A66: Lont Term Provisions | B66: QTRB_LT_PROVISIONS | C66: =_xll.EQNXTDZ($A$1,$B66,C$5,$B$1) -> 0 | D66: =_xll.EQNXTDZ($A$1,$B66,D$5,$B$1) -> 0 | E66: =_xll.EQNXTDZ($A$1,$B66,E$5,$B$1) -> 0 | F66: =_xll.EQNXTDZ($A$1,$B66,F$5,$B$1) -> 0 | G66: =_xll.EQNXTDZ($A$1,$B66,G$5,$B$1) -> 0 | H66: =_xll.EQNXTDZ($A$1,$B66,H$5,$B$1) -> 0 | I66: =_xll.EQNXTDZ($A$1,$B66,I$5,$B$1) -> 0 | J66: =_xll.EQNXTDZ($A$1,$B66,J$5,$B$1) -> 0 | ... BV66: =_xll.EQNXTDZ($A$1,$B66,BV$5,$B$1) -> 0
... A97: Total Assets | B97: QTRB_TOTAL_APPLICATIONS | C97: =_xll.EQNXTDZ($A$1,$B97,C$5,$B$1) -> 0 | D97: =_xll.EQNXTDZ($A$1,$B97,D$5,$B$1) -> 0 | E97: =_xll.EQNXTDZ($A$1,$B97,E$5,$B$1) -> 0 | F97: =_xll.EQNXTDZ($A$1,$B97,F$5,$B$1) -> 0 | G97: =_xll.EQNXTDZ($A$1,$B97,G$5,$B$1) -> 0 | H97: =_xll.EQNXTDZ($A$1,$B97,H$5,$B$1) -> 0 | I97: =_xll.EQNXTDZ($A$1,$B97,I$5,$B$1) -> 0 | J97: =_xll.EQNXTDZ($A$1,$B97,J$5,$B$1) -> 0 | ... BV97: =_xll.EQNXTDZ($A$1,$B97,BV$5,$B$1) -> 0

Sheet Annual Raw
A1: 271875 | B1: X | C1: 200103 | D1: 200203 | E1: 200303 | F1: 200403 | G1: 200503 | H1: 200603 | I1: 200703 | J1: 200803 | K1: 200903 | L1: 201003 | M1: 201103 | N1: 201203 | O1: 201303 | P1: 201403 | Q1: 201503 | R1: 201603 | S1: 201703 | T1: 201803 | U1: 201903 | V1: 202003 | W1: 202103 | X1: 202203 | Y1: 202303 | Z1: 202403 | AA1: 202503 | AB1: 202603 | AC1: 202703 | AD1: 202803 | AE1: 202903 | AF1: 203003
A3: Field Description | B3: Field Name
A4: Company Name | B4: CD_COMPNAME | C4: =_xll.EQNXTDZ(A1,B4,"L") -> Adani Energy Solutions Ltd.
A5: Year End | B5: PL_YEAR_END | C5: =_xll.EQNXTDZ($A$1,$B5,C$1,$B$1) -> 0 | D5: =_xll.EQNXTDZ($A$1,$B5,D$1,$B$1) -> 0 | E5: =_xll.EQNXTDZ($A$1,$B5,E$1,$B$1) -> 0 | F5: =_xll.EQNXTDZ($A$1,$B5,F$1,$B$1) -> 0 | G5: =_xll.EQNXTDZ($A$1,$B5,G$1,$B$1) -> 0 | H5: =_xll.EQNXTDZ($A$1,$B5,H$1,$B$1) -> 0 | I5: =_xll.EQNXTDZ($A$1,$B5,I$1,$B$1) -> 0 | J5: =_xll.EQNXTDZ($A$1,$B5,J$1,$B$1) -> 0 | ... AF5: =_xll.EQNXTDZ($A$1,$B5,AF$1,$B$1) -> 0
A6: Sales Turnover | B6: PL_TOTAL_GROSS_SALES | C6: =_xll.EQNXTDZ($A$1,$B6,C$1,$B$1) -> 0 | D6: =_xll.EQNXTDZ($A$1,$B6,D$1,$B$1) -> 0 | E6: =_xll.EQNXTDZ($A$1,$B6,E$1,$B$1) -> 0 | F6: =_xll.EQNXTDZ($A$1,$B6,F$1,$B$1) -> 0 | G6: =_xll.EQNXTDZ($A$1,$B6,G$1,$B$1) -> 0 | H6: =_xll.EQNXTDZ($A$1,$B6,H$1,$B$1) -> 0 | I6: =_xll.EQNXTDZ($A$1,$B6,I$1,$B$1) -> 0 | J6: =_xll.EQNXTDZ($A$1,$B6,J$1,$B$1) -> 0 | ... AF6: =_xll.EQNXTDZ($A$1,$B6,AF$1,$B$1) -> 0
A7: Less: Inter divisional transfers | B7: PL_INTER_DIV_TRF | C7: =_xll.EQNXTDZ($A$1,$B7,C$1,$B$1) -> 0 | D7: =_xll.EQNXTDZ($A$1,$B7,D$1,$B$1) -> 0 | E7: =_xll.EQNXTDZ($A$1,$B7,E$1,$B$1) -> 0 | F7: =_xll.EQNXTDZ($A$1,$B7,F$1,$B$1) -> 0 | G7: =_xll.EQNXTDZ($A$1,$B7,G$1,$B$1) -> 0 | H7: =_xll.EQNXTDZ($A$1,$B7,H$1,$B$1) -> 0 | I7: =_xll.EQNXTDZ($A$1,$B7,I$1,$B$1) -> 0 | J7: =_xll.EQNXTDZ($A$1,$B7,J$1,$B$1) -> 0 | ... AF7: =_xll.EQNXTDZ($A$1,$B7,AF$1,$B$1) -> 0
A8: Less: Sales Returns | B8: PL_SALES_RETURN | C8: =_xll.EQNXTDZ($A$1,$B8,C$1,$B$1) -> 0 | D8: =_xll.EQNXTDZ($A$1,$B8,D$1,$B$1) -> 0 | E8: =_xll.EQNXTDZ($A$1,$B8,E$1,$B$1) -> 0 | F8: =_xll.EQNXTDZ($A$1,$B8,F$1,$B$1) -> 0 | G8: =_xll.EQNXTDZ($A$1,$B8,G$1,$B$1) -> 0 | H8: =_xll.EQNXTDZ($A$1,$B8,H$1,$B$1) -> 0 | I8: =_xll.EQNXTDZ($A$1,$B8,I$1,$B$1) -> 0 | J8: =_xll.EQNXTDZ($A$1,$B8,J$1,$B$1) -> 0 | ... AF8: =_xll.EQNXTDZ($A$1,$B8,AF$1,$B$1) -> 0
A9: Less: Excise | B9: PL_EXCISE | C9: =_xll.EQNXTDZ($A$1,$B9,C$1,$B$1) -> 0 | D9: =_xll.EQNXTDZ($A$1,$B9,D$1,$B$1) -> 0 | E9: =_xll.EQNXTDZ($A$1,$B9,E$1,$B$1) -> 0 | F9: =_xll.EQNXTDZ($A$1,$B9,F$1,$B$1) -> 0 | G9: =_xll.EQNXTDZ($A$1,$B9,G$1,$B$1) -> 0 | H9: =_xll.EQNXTDZ($A$1,$B9,H$1,$B$1) -> 0 | I9: =_xll.EQNXTDZ($A$1,$B9,I$1,$B$1) -> 0 | J9: =_xll.EQNXTDZ($A$1,$B9,J$1,$B$1) -> 0 | ... AF9: =_xll.EQNXTDZ($A$1,$B9,AF$1,$B$1) -> 0
A10: Net Sales | B10: PL_NET_SALES | C10: =_xll.EQNXTDZ($A$1,$B10,C$1,$B$1) -> 0 | D10: =_xll.EQNXTDZ($A$1,$B10,D$1,$B$1) -> 0 | E10: =_xll.EQNXTDZ($A$1,$B10,E$1,$B$1) -> 0 | F10: =_xll.EQNXTDZ($A$1,$B10,F$1,$B$1) -> 0 | G10: =_xll.EQNXTDZ($A$1,$B10,G$1,$B$1) -> 0 | H10: =_xll.EQNXTDZ($A$1,$B10,H$1,$B$1) -> 0 | I10: =_xll.EQNXTDZ($A$1,$B10,I$1,$B$1) -> 0 | J10: =_xll.EQNXTDZ($A$1,$B10,J$1,$B$1) -> 0 | ... AF10: =_xll.EQNXTDZ($A$1,$B10,AF$1,$B$1) -> 0
A11: Increase/Decrease in Stock | B11: PL_INC_DEC_INVENTORY | C11: =_xll.EQNXTDZ($A$1,$B11,C$1,$B$1) -> 0 | D11: =_xll.EQNXTDZ($A$1,$B11,D$1,$B$1) -> 0 | E11: =_xll.EQNXTDZ($A$1,$B11,E$1,$B$1) -> 0 | F11: =_xll.EQNXTDZ($A$1,$B11,F$1,$B$1) -> 0 | G11: =_xll.EQNXTDZ($A$1,$B11,G$1,$B$1) -> 0 | H11: =_xll.EQNXTDZ($A$1,$B11,H$1,$B$1) -> 0 | I11: =_xll.EQNXTDZ($A$1,$B11,I$1,$B$1) -> 0 | J11: =_xll.EQNXTDZ($A$1,$B11,J$1,$B$1) -> 0 | ... AF11: =_xll.EQNXTDZ($A$1,$B11,AF$1,$B$1) -> 0
A12: Raw Material Consumed | B12: PL_RAW_MATRS_CONSUMED | C12: =_xll.EQNXTDZ($A$1,$B12,C$1,$B$1) -> 0 | D12: =_xll.EQNXTDZ($A$1,$B12,D$1,$B$1) -> 0 | E12: =_xll.EQNXTDZ($A$1,$B12,E$1,$B$1) -> 0 | F12: =_xll.EQNXTDZ($A$1,$B12,F$1,$B$1) -> 0 | G12: =_xll.EQNXTDZ($A$1,$B12,G$1,$B$1) -> 0 | H12: =_xll.EQNXTDZ($A$1,$B12,H$1,$B$1) -> 0 | I12: =_xll.EQNXTDZ($A$1,$B12,I$1,$B$1) -> 0 | J12: =_xll.EQNXTDZ($A$1,$B12,J$1,$B$1) -> 0 | ... AF12: =_xll.EQNXTDZ($A$1,$B12,AF$1,$B$1) -> 0
A13: Power & Fuel Cost | B13: PL_POWER_FUEL | C13: =_xll.EQNXTDZ($A$1,$B13,C$1,$B$1) -> 0 | D13: =_xll.EQNXTDZ($A$1,$B13,D$1,$B$1) -> 0 | E13: =_xll.EQNXTDZ($A$1,$B13,E$1,$B$1) -> 0 | F13: =_xll.EQNXTDZ($A$1,$B13,F$1,$B$1) -> 0 | G13: =_xll.EQNXTDZ($A$1,$B13,G$1,$B$1) -> 0 | H13: =_xll.EQNXTDZ($A$1,$B13,H$1,$B$1) -> 0 | I13: =_xll.EQNXTDZ($A$1,$B13,I$1,$B$1) -> 0 | J13: =_xll.EQNXTDZ($A$1,$B13,J$1,$B$1) -> 0 | ... AF13: =_xll.EQNXTDZ($A$1,$B13,AF$1,$B$1) -> 0
A14: Employee Cost | B14: PL_EMPLOYEES | C14: =_xll.EQNXTDZ($A$1,$B14,C$1,$B$1) -> 0 | D14: =_xll.EQNXTDZ($A$1,$B14,D$1,$B$1) -> 0 | E14: =_xll.EQNXTDZ($A$1,$B14,E$1,$B$1) -> 0 | F14: =_xll.EQNXTDZ($A$1,$B14,F$1,$B$1) -> 0 | G14: =_xll.EQNXTDZ($A$1,$B14,G$1,$B$1) -> 0 | H14: =_xll.EQNXTDZ($A$1,$B14,H$1,$B$1) -> 0 | I14: =_xll.EQNXTDZ($A$1,$B14,I$1,$B$1) -> 0 | J14: =_xll.EQNXTDZ($A$1,$B14,J$1,$B$1) -> 0 | ... AF14: =_xll.EQNXTDZ($A$1,$B14,AF$1,$B$1) -> 0
A15: Operating & Manufacturing Expenses | B15: PL_GEN_OTHER_MFG_EXPS | C15: =_xll.EQNXTDZ($A$1,$B15,C$1,$B$1) -> 0 | D15: =_xll.EQNXTDZ($A$1,$B15,D$1,$B$1) -> 0 | E15: =_xll.EQNXTDZ($A$1,$B15,E$1,$B$1) -> 0 | F15: =_xll.EQNXTDZ($A$1,$B15,F$1,$B$1) -> 0 | G15: =_xll.EQNXTDZ($A$1,$B15,G$1,$B$1) -> 0 | H15: =_xll.EQNXTDZ($A$1,$B15,H$1,$B$1) -> 0 | I15: =_xll.EQNXTDZ($A$1,$B15,I$1,$B$1) -> 0 | J15: =_xll.EQNXTDZ($A$1,$B15,J$1,$B$1) -> 0 | ... AF15: =_xll.EQNXTDZ($A$1,$B15,AF$1,$B$1) -> 0
A16: Cost of Software development | B16: PL_COST_SW | C16: =_xll.EQNXTDZ($A$1,$B16,C$1,$B$1) -> 0 | D16: =_xll.EQNXTDZ($A$1,$B16,D$1,$B$1) -> 0 | E16: =_xll.EQNXTDZ($A$1,$B16,E$1,$B$1) -> 0 | F16: =_xll.EQNXTDZ($A$1,$B16,F$1,$B$1) -> 0 | G16: =_xll.EQNXTDZ($A$1,$B16,G$1,$B$1) -> 0 | H16: =_xll.EQNXTDZ($A$1,$B16,H$1,$B$1) -> 0 | I16: =_xll.EQNXTDZ($A$1,$B16,I$1,$B$1) -> 0 | J16: =_xll.EQNXTDZ($A$1,$B16,J$1,$B$1) -> 0 | ... AF16: =_xll.EQNXTDZ($A$1,$B16,AF$1,$B$1) -> 0
... A36: Profit After Tax from Discontinued Operations | B36: PL_PAT_DIS_OP | C36: =_xll.EQNXTDZ($A$1,$B36,C$1,$B$1) -> 0 | D36: =_xll.EQNXTDZ($A$1,$B36,D$1,$B$1) -> 0 | E36: =_xll.EQNXTDZ($A$1,$B36,E$1,$B$1) -> 0 | F36: =_xll.EQNXTDZ($A$1,$B36,F$1,$B$1) -> 0 | G36: =_xll.EQNXTDZ($A$1,$B36,G$1,$B$1) -> 0 | H36: =_xll.EQNXTDZ($A$1,$B36,H$1,$B$1) -> 0 | I36: =_xll.EQNXTDZ($A$1,$B36,I$1,$B$1) -> 0 | J36: =_xll.EQNXTDZ($A$1,$B36,J$1,$B$1) -> 0 | ... AF36: =_xll.EQNXTDZ($A$1,$B36,AF$1,$B$1) -> 0
A39: Field Description | B39: Field Name
A40: Year End | B40: BS_YEAR_END | C40: =_xll.EQNXTDZ($A$1,$B40,C$1,$B$1) -> 0 | D40: =_xll.EQNXTDZ($A$1,$B40,D$1,$B$1) -> 0 | E40: =_xll.EQNXTDZ($A$1,$B40,E$1,$B$1) -> 0 | F40: =_xll.EQNXTDZ($A$1,$B40,F$1,$B$1) -> 0 | G40: =_xll.EQNXTDZ($A$1,$B40,G$1,$B$1) -> 0 | H40: =_xll.EQNXTDZ($A$1,$B40,H$1,$B$1) -> 0 | I40: =_xll.EQNXTDZ($A$1,$B40,I$1,$B$1) -> 0 | J40: =_xll.EQNXTDZ($A$1,$B40,J$1,$B$1) -> 0 | ... AF40: =_xll.EQNXTDZ($A$1,$B40,AF$1,$B$1) -> 0
A41: Share Capital | B41: BS_SHARE_CAPITAL | C41: =_xll.EQNXTDZ($A$1,$B41,C$1,$B$1) -> 0 | D41: =_xll.EQNXTDZ($A$1,$B41,D$1,$B$1) -> 0 | E41: =_xll.EQNXTDZ($A$1,$B41,E$1,$B$1) -> 0 | F41: =_xll.EQNXTDZ($A$1,$B41,F$1,$B$1) -> 0 | G41: =_xll.EQNXTDZ($A$1,$B41,G$1,$B$1) -> 0 | H41: =_xll.EQNXTDZ($A$1,$B41,H$1,$B$1) -> 0 | I41: =_xll.EQNXTDZ($A$1,$B41,I$1,$B$1) -> 0 | J41: =_xll.EQNXTDZ($A$1,$B41,J$1,$B$1) -> 0 | ... AF41: =_xll.EQNXTDZ($A$1,$B41,AF$1,$B$1) -> 0
A42: Share Warrants & Outstandings | B42: BS_SHAREWROUTST | C42: =_xll.EQNXTDZ($A$1,$B42,C$1,$B$1) -> 0 | D42: =_xll.EQNXTDZ($A$1,$B42,D$1,$B$1) -> 0 | E42: =_xll.EQNXTDZ($A$1,$B42,E$1,$B$1) -> 0 | F42: =_xll.EQNXTDZ($A$1,$B42,F$1,$B$1) -> 0 | G42: =_xll.EQNXTDZ($A$1,$B42,G$1,$B$1) -> 0 | H42: =_xll.EQNXTDZ($A$1,$B42,H$1,$B$1) -> 0 | I42: =_xll.EQNXTDZ($A$1,$B42,I$1,$B$1) -> 0 | J42: =_xll.EQNXTDZ($A$1,$B42,J$1,$B$1) -> 0 | ... AF42: =_xll.EQNXTDZ($A$1,$B42,AF$1,$B$1) -> 0
A43: Total Reserves | B43: BS_RESERVE | C43: =_xll.EQNXTDZ($A$1,$B43,C$1,$B$1) -> 0 | D43: =_xll.EQNXTDZ($A$1,$B43,D$1,$B$1) -> 0 | E43: =_xll.EQNXTDZ($A$1,$B43,E$1,$B$1) -> 0 | F43: =_xll.EQNXTDZ($A$1,$B43,F$1,$B$1) -> 0 | G43: =_xll.EQNXTDZ($A$1,$B43,G$1,$B$1) -> 0 | H43: =_xll.EQNXTDZ($A$1,$B43,H$1,$B$1) -> 0 | I43: =_xll.EQNXTDZ($A$1,$B43,I$1,$B$1) -> 0 | J43: =_xll.EQNXTDZ($A$1,$B43,J$1,$B$1) -> 0 | ... AF43: =_xll.EQNXTDZ($A$1,$B43,AF$1,$B$1) -> 0
A44: Shareholder's Funds | B44: BS_SHAREHODERS_FUNDS | C44: =_xll.EQNXTDZ($A$1,$B44,C$1,$B$1) -> 0 | D44: =_xll.EQNXTDZ($A$1,$B44,D$1,$B$1) -> 0 | E44: =_xll.EQNXTDZ($A$1,$B44,E$1,$B$1) -> 0 | F44: =_xll.EQNXTDZ($A$1,$B44,F$1,$B$1) -> 0 | G44: =_xll.EQNXTDZ($A$1,$B44,G$1,$B$1) -> 0 | H44: =_xll.EQNXTDZ($A$1,$B44,H$1,$B$1) -> 0 | I44: =_xll.EQNXTDZ($A$1,$B44,I$1,$B$1) -> 0 | J44: =_xll.EQNXTDZ($A$1,$B44,J$1,$B$1) -> 0 | ... AF44: =_xll.EQNXTDZ($A$1,$B44,AF$1,$B$1) -> 0
A45: Minority Interest | B45: BS_MINORITY_INTEREST | C45: =_xll.EQNXTDZ($A$1,$B45,C$1,$B$1) -> 0 | D45: =_xll.EQNXTDZ($A$1,$B45,D$1,$B$1) -> 0 | E45: =_xll.EQNXTDZ($A$1,$B45,E$1,$B$1) -> 0 | F45: =_xll.EQNXTDZ($A$1,$B45,F$1,$B$1) -> 0 | G45: =_xll.EQNXTDZ($A$1,$B45,G$1,$B$1) -> 0 | H45: =_xll.EQNXTDZ($A$1,$B45,H$1,$B$1) -> 0 | I45: =_xll.EQNXTDZ($A$1,$B45,I$1,$B$1) -> 0 | J45: =_xll.EQNXTDZ($A$1,$B45,J$1,$B$1) -> 0 | ... AF45: =_xll.EQNXTDZ($A$1,$B45,AF$1,$B$1) -> 0
A46: Long-Term Borrowings | B46: BS_LTRM_BORROWING | C46: =_xll.EQNXTDZ($A$1,$B46,C$1,$B$1) -> 0 | D46: =_xll.EQNXTDZ($A$1,$B46,D$1,$B$1) -> 0 | E46: =_xll.EQNXTDZ($A$1,$B46,E$1,$B$1) -> 0 | F46: =_xll.EQNXTDZ($A$1,$B46,F$1,$B$1) -> 0 | G46: =_xll.EQNXTDZ($A$1,$B46,G$1,$B$1) -> 0 | H46: =_xll.EQNXTDZ($A$1,$B46,H$1,$B$1) -> 0 | I46: =_xll.EQNXTDZ($A$1,$B46,I$1,$B$1) -> 0 | J46: =_xll.EQNXTDZ($A$1,$B46,J$1,$B$1) -> 0 | ... AF46: =_xll.EQNXTDZ($A$1,$B46,AF$1,$B$1) -> 0
A47: Secured Loans | B47: BS_SECURED_LOANS | C47: =_xll.EQNXTDZ($A$1,$B47,C$1,$B$1) -> 0 | D47: =_xll.EQNXTDZ($A$1,$B47,D$1,$B$1) -> 0 | E47: =_xll.EQNXTDZ($A$1,$B47,E$1,$B$1) -> 0 | F47: =_xll.EQNXTDZ($A$1,$B47,F$1,$B$1) -> 0 | G47: =_xll.EQNXTDZ($A$1,$B47,G$1,$B$1) -> 0 | H47: =_xll.EQNXTDZ($A$1,$B47,H$1,$B$1) -> 0 | I47: =_xll.EQNXTDZ($A$1,$B47,I$1,$B$1) -> 0 | J47: =_xll.EQNXTDZ($A$1,$B47,J$1,$B$1) -> 0 | ... AF47: =_xll.EQNXTDZ($A$1,$B47,AF$1,$B$1) -> 0
A48: Unsecured Loans | B48: BS_UNSECURED_LOANS_NF | C48: =_xll.EQNXTDZ($A$1,$B48,C$1,$B$1) -> 0 | D48: =_xll.EQNXTDZ($A$1,$B48,D$1,$B$1) -> 0 | E48: =_xll.EQNXTDZ($A$1,$B48,E$1,$B$1) -> 0 | F48: =_xll.EQNXTDZ($A$1,$B48,F$1,$B$1) -> 0 | G48: =_xll.EQNXTDZ($A$1,$B48,G$1,$B$1) -> 0 | H48: =_xll.EQNXTDZ($A$1,$B48,H$1,$B$1) -> 0 | I48: =_xll.EQNXTDZ($A$1,$B48,I$1,$B$1) -> 0 | J48: =_xll.EQNXTDZ($A$1,$B48,J$1,$B$1) -> 0 | ... AF48: =_xll.EQNXTDZ($A$1,$B48,AF$1,$B$1) -> 0
A49: Deferred Tax Assets / Liabilities | B49: BS_NET_DEF_TAX_NF | C49: =_xll.EQNXTDZ($A$1,$B49,C$1,$B$1) -> 0 | D49: =_xll.EQNXTDZ($A$1,$B49,D$1,$B$1) -> 0 | E49: =_xll.EQNXTDZ($A$1,$B49,E$1,$B$1) -> 0 | F49: =_xll.EQNXTDZ($A$1,$B49,F$1,$B$1) -> 0 | G49: =_xll.EQNXTDZ($A$1,$B49,G$1,$B$1) -> 0 | H49: =_xll.EQNXTDZ($A$1,$B49,H$1,$B$1) -> 0 | I49: =_xll.EQNXTDZ($A$1,$B49,I$1,$B$1) -> 0 | J49: =_xll.EQNXTDZ($A$1,$B49,J$1,$B$1) -> 0 | ... AF49: =_xll.EQNXTDZ($A$1,$B49,AF$1,$B$1) -> 0
A50: Other Long Term Liabilities | B50: BS_OTH_LT_LIAB | C50: =_xll.EQNXTDZ($A$1,$B50,C$1,$B$1) -> 0 | D50: =_xll.EQNXTDZ($A$1,$B50,D$1,$B$1) -> 0 | E50: =_xll.EQNXTDZ($A$1,$B50,E$1,$B$1) -> 0 | F50: =_xll.EQNXTDZ($A$1,$B50,F$1,$B$1) -> 0 | G50: =_xll.EQNXTDZ($A$1,$B50,G$1,$B$1) -> 0 | H50: =_xll.EQNXTDZ($A$1,$B50,H$1,$B$1) -> 0 | I50: =_xll.EQNXTDZ($A$1,$B50,I$1,$B$1) -> 0 | J50: =_xll.EQNXTDZ($A$1,$B50,J$1,$B$1) -> 0 | ... AF50: =_xll.EQNXTDZ($A$1,$B50,AF$1,$B$1) -> 0
A51: Long Term Trade Payables | B51: BS_LT_TRADE_PAYABLES | C51: =_xll.EQNXTDZ($A$1,$B51,C$1,$B$1) -> 0 | D51: =_xll.EQNXTDZ($A$1,$B51,D$1,$B$1) -> 0 | E51: =_xll.EQNXTDZ($A$1,$B51,E$1,$B$1) -> 0 | F51: =_xll.EQNXTDZ($A$1,$B51,F$1,$B$1) -> 0 | G51: =_xll.EQNXTDZ($A$1,$B51,G$1,$B$1) -> 0 | H51: =_xll.EQNXTDZ($A$1,$B51,H$1,$B$1) -> 0 | I51: =_xll.EQNXTDZ($A$1,$B51,I$1,$B$1) -> 0 | J51: =_xll.EQNXTDZ($A$1,$B51,J$1,$B$1) -> 0 | ... AF51: =_xll.EQNXTDZ($A$1,$B51,AF$1,$B$1) -> 0
... A99: Estimated Capital Contracts Remaining | B99: BS_ESTIMATED_CAPITAL_CONTRACT | C99: =_xll.EQNXTDZ($A$1,$B99,C$1,$B$1) -> 0 | D99: =_xll.EQNXTDZ($A$1,$B99,D$1,$B$1) -> 0 | E99: =_xll.EQNXTDZ($A$1,$B99,E$1,$B$1) -> 0 | F99: =_xll.EQNXTDZ($A$1,$B99,F$1,$B$1) -> 0 | G99: =_xll.EQNXTDZ($A$1,$B99,G$1,$B$1) -> 0 | H99: =_xll.EQNXTDZ($A$1,$B99,H$1,$B$1) -> 0 | I99: =_xll.EQNXTDZ($A$1,$B99,I$1,$B$1) -> 0 | J99: =_xll.EQNXTDZ($A$1,$B99,J$1,$B$1) -> 0 | ... AF99: =_xll.EQNXTDZ($A$1,$B99,AF$1,$B$1) -> 0
A103: Field Description | B103: Field Name
A104: Equity Paid Up | B104: BS_EQUITY_PAIDUP | C104: =_xll.EQNXTDZ($A$1,$B104,C$1,$B$1) -> 0 | D104: =_xll.EQNXTDZ($A$1,$B104,D$1,$B$1) -> 0 | E104: =_xll.EQNXTDZ($A$1,$B104,E$1,$B$1) -> 0 | F104: =_xll.EQNXTDZ($A$1,$B104,F$1,$B$1) -> 0 | G104: =_xll.EQNXTDZ($A$1,$B104,G$1,$B$1) -> 0 | H104: =_xll.EQNXTDZ($A$1,$B104,H$1,$B$1) -> 0 | I104: =_xll.EQNXTDZ($A$1,$B104,I$1,$B$1) -> 0 | J104: =_xll.EQNXTDZ($A$1,$B104,J$1,$B$1) -> 0 | ... AF104: =_xll.EQNXTDZ($A$1,$B104,AF$1,$B$1) -> 0
A105: Face Value | B105: BS_FACE_VALUE | C105: =_xll.EQNXTDZ($A$1,$B105,C$1,$B$1) -> 0 | D105: =_xll.EQNXTDZ($A$1,$B105,D$1,$B$1) -> 0 | E105: =_xll.EQNXTDZ($A$1,$B105,E$1,$B$1) -> 0 | F105: =_xll.EQNXTDZ($A$1,$B105,F$1,$B$1) -> 0 | G105: =_xll.EQNXTDZ($A$1,$B105,G$1,$B$1) -> 0 | H105: =_xll.EQNXTDZ($A$1,$B105,H$1,$B$1) -> 0 | I105: =_xll.EQNXTDZ($A$1,$B105,I$1,$B$1) -> 0 | J105: =_xll.EQNXTDZ($A$1,$B105,J$1,$B$1) -> 0 | ... AF105: =_xll.EQNXTDZ($A$1,$B105,AF$1,$B$1) -> 0
A106: Close Price (Unit Curr.) | B106: FH_YEAR_PRICE | C106: =_xll.EQNXTDZ($A$1,$B106,C$1,$B$1) -> 0 | D106: =_xll.EQNXTDZ($A$1,$B106,D$1,$B$1) -> 0 | E106: =_xll.EQNXTDZ($A$1,$B106,E$1,$B$1) -> 0 | F106: =_xll.EQNXTDZ($A$1,$B106,F$1,$B$1) -> 0 | G106: =_xll.EQNXTDZ($A$1,$B106,G$1,$B$1) -> 0 | H106: =_xll.EQNXTDZ($A$1,$B106,H$1,$B$1) -> 0 | I106: =_xll.EQNXTDZ($A$1,$B106,I$1,$B$1) -> 0 | J106: =_xll.EQNXTDZ($A$1,$B106,J$1,$B$1) -> 0 | ... AF106: =_xll.EQNXTDZ($A$1,$B106,AF$1,$B$1) -> 0
A107: High Price (Unit Curr.) | B107: FH_HIGH | C107: =_xll.EQNXTDZ($A$1,$B107,C$1,$B$1) -> 0 | D107: =_xll.EQNXTDZ($A$1,$B107,D$1,$B$1) -> 0 | E107: =_xll.EQNXTDZ($A$1,$B107,E$1,$B$1) -> 0 | F107: =_xll.EQNXTDZ($A$1,$B107,F$1,$B$1) -> 0 | G107: =_xll.EQNXTDZ($A$1,$B107,G$1,$B$1) -> 0 | H107: =_xll.EQNXTDZ($A$1,$B107,H$1,$B$1) -> 0 | I107: =_xll.EQNXTDZ($A$1,$B107,I$1,$B$1) -> 0 | J107: =_xll.EQNXTDZ($A$1,$B107,J$1,$B$1) -> 0 | ... AF107: =_xll.EQNXTDZ($A$1,$B107,AF$1,$B$1) -> 0
