Workbook

Sheet Template
A1: =+'Annual Raw'!C4 -> Archean Chemical Industries Ltd. | B1: 36951 | C1: =EOMONTH(B1,12) -> 37346 | D1: =EOMONTH(C1,12) -> 37711 | E1: =EOMONTH(D1,12) -> 38077 | F1: =EOMONTH(E1,12) -> 38442 | G1: =EOMONTH(F1,12) -> 38807 | H1: =EOMONTH(G1,12) -> 39172 | I1: =EOMONTH(H1,12) -> 39538 | J1: =EOMONTH(I1,12) -> 39903 | ... AE1: =EOMONTH(AD1,12) -> 47573 | AH1: QTR | AI1: 41061 | AJ1: 41153 | AK1: 41244 | AL1: 41334 | AM1: 41426 | AN1: 41518 | AO1: 41609 | AP1: 41699 | AQ1: 41791 | AR1: 41883 | AS1: 41974 | AT1: 42064 | AU1: 42156 | AV1: 42248 | AW1: 42339 | AX1: 42430 | AY1: 42522 | AZ1: 42614 | BA1: 42705 | BB1: 42795 | BC1: 42887 | BD1: 42979 | BE1: 43070 | BF1: 43160 | BG1: 43252 | BH1: 43344 | BI1: 43435 | BJ1: 43525 | BK1: 43617 | BL1: 43709 | BM1: 43800 | BN1: 43891 | BO1: 43983 | BP1: 44075 | BQ1: =EOMONTH(BP1,3) -> 44196 | BR1: =EOMONTH(BQ1,3) -> 44286 | BS1: =EOMONTH(BR1,3) -> 44377 | BT1: =EOMONTH(BS1,3) -> 44469 | BU1: =EOMONTH(BT1,3) -> 44561 | BV1: =EOMONTH(BU1,3) -> 44651 | BW1: =EOMONTH(BV1,3) -> 44742 | BX1: =EOMONTH(BW1,3) -> 44834 | ... DB1: =EOMONTH(DA1,3) -> 47573 | DE1: HISTORICAL ESTIMATES | DF1: 46112
A2: Presentation Data (Start)
A6: Presentation Data (End)
A7: Profit & Loss- Annual (Start)
A8: Gross Revenue | B8: ='Annual Raw'!C6 -> 0 | C8: ='Annual Raw'!D6 -> 0 | D8: ='Annual Raw'!E6 -> 0 | E8: ='Annual Raw'!F6 -> 0 | F8: ='Annual Raw'!G6 -> 0 | G8: ='Annual Raw'!H6 -> 0 | H8: ='Annual Raw'!I6 -> 0 | I8: ='Annual Raw'!J6 -> 0 | ... AA8: ='Annual Raw'!AB6 -> 1081.0507 | AB8: =+SUM(CM8:CP8) -> 1310.3951 | AC8: =+SUM(CQ8:CT8) -> 1451.8195 | AD8: =+SUM(CU8:CX8) -> 1608.2275 | AE8: =+SUM(CY8:DB8) -> 1781.582 | AI8: ='QTR Raw'!C6+'QTR Raw'!C8 -> 0 | AJ8: ='QTR Raw'!D6+'QTR Raw'!D8 -> 0 | AK8: ='QTR Raw'!E6+'QTR Raw'!E8 -> 0 | AL8: ='QTR Raw'!F6+'QTR Raw'!F8 -> 0 | AM8: ='QTR Raw'!G6+'QTR Raw'!G8 -> 0 | AN8: ='QTR Raw'!H6+'QTR Raw'!H8 -> 0 | AO8: ='QTR Raw'!I6+'QTR Raw'!I8 -> 0 | AP8: ='QTR Raw'!J6+'QTR Raw'!J8 -> 0 | ... CK8: ='QTR Raw'!BE6+'QTR Raw'!BE8 -> 254.565 | CL8: =+CH10+(CL11*CH10) -> 398.4675 | CM8: =+CI10+(CM11*CI10) -> 332.41375 | CN8: =+CJ10+(CN11*CJ10) -> 251.28268 | CO8: =+CK10+(CO11*CK10) -> 281.18714 | CP8: =+CL10+(CP11*CL10) -> 445.51152 | CQ8: =+CM10+(CQ11*CM10) -> 368.75174 | CR8: =+CN10+(CR11*CN10) -> 277.01229 | CS8: =+CO10+(CS11*CO10) -> 311.72054 | ... DB8: =+CX10+(DB11*CX10) -> 606.82331 | DF8: 1081.0507
A9: Less: Exise Duty | B9: ='Annual Raw'!C7+'Annual Raw'!C8+'Annual Raw'!C9 -> 0 | C9: ='Annual Raw'!D7+'Annual Raw'!D8+'Annual Raw'!D9 -> 0 | D9: ='Annual Raw'!E7+'Annual Raw'!E8+'Annual Raw'!E9 -> 0 | E9: ='Annual Raw'!F7+'Annual Raw'!F8+'Annual Raw'!F9 -> 0 | F9: ='Annual Raw'!G7+'Annual Raw'!G8+'Annual Raw'!G9 -> 0 | G9: ='Annual Raw'!H7+'Annual Raw'!H8+'Annual Raw'!H9 -> 0 | H9: ='Annual Raw'!I7+'Annual Raw'!I8+'Annual Raw'!I9 -> 0 | I9: ='Annual Raw'!J7+'Annual Raw'!J8+'Annual Raw'!J9 -> 0 | ... AA9: ='Annual Raw'!AB7+'Annual Raw'!AB8+'Annual Raw'!AB9 -> 0 | AB9: =+SUM(CM9:CP9) -> 0 | AC9: =+SUM(CQ9:CT9) -> 0 | AD9: =+SUM(CU9:CX9) -> 0 | AE9: =+SUM(CY9:DB9) -> 0 | AI9: =+'QTR Raw'!C20+'QTR Raw'!C19+'QTR Raw'!C13+'QTR Raw'!C7 -> 0 | AJ9: =+'QTR Raw'!D20+'QTR Raw'!D19+'QTR Raw'!D13+'QTR Raw'!D7 -> 0 | AK9: =+'QTR Raw'!E20+'QTR Raw'!E19+'QTR Raw'!E13+'QTR Raw'!E7 -> 0 | AL9: =+'QTR Raw'!F20+'QTR Raw'!F19+'QTR Raw'!F13+'QTR Raw'!F7 -> 0 | AM9: =+'QTR Raw'!G20+'QTR Raw'!G19+'QTR Raw'!G13+'QTR Raw'!G7 -> 0 | AN9: =+'QTR Raw'!H20+'QTR Raw'!H19+'QTR Raw'!H13+'QTR Raw'!H7 -> 0 | AO9: =+'QTR Raw'!I20+'QTR Raw'!I19+'QTR Raw'!I13+'QTR Raw'!I7 -> 0 | AP9: =+'QTR Raw'!J20+'QTR Raw'!J19+'QTR Raw'!J13+'QTR Raw'!J7 -> 0 | ... CK9: =+'QTR Raw'!BE20+'QTR Raw'!BE19+'QTR Raw'!BE13+'QTR Raw'!BE7 -> 0 | DF9: 0
A10: Net Revenue | B10: =+B8-B9 -> 0 | C10: =+C8-C9 -> 0 | D10: =+D8-D9 -> 0 | E10: =+E8-E9 -> 0 | F10: =+F8-F9 -> 0 | G10: =+G8-G9 -> 0 | H10: =+H8-H9 -> 0 | I10: =+I8-I9 -> 0 | ... AE10: =+AE8-AE9 -> 1781.582 | AI10: =+AI8-AI9 -> 0 | AJ10: =+AJ8-AJ9 -> 0 | AK10: =+AK8-AK9 -> 0 | AL10: =+AL8-AL9 -> 0 | AM10: =+AM8-AM9 -> 0 | AN10: =+AN8-AN9 -> 0 | AO10: =+AO8-AO9 -> 0 | AP10: =+AP8-AP9 -> 0 | ... DB10: =+DB8-DB9 -> 606.82331 | DF10: 1081.0507
A11: Net Revenue YOY% | C11: =C10/B10-1 -> #DIV/0! | D11: =D10/C10-1 -> #DIV/0! | E11: =E10/D10-1 -> #DIV/0! | F11: =F10/E10-1 -> #DIV/0! | G11: =G10/F10-1 -> #DIV/0! | H11: =H10/G10-1 -> #DIV/0! | I11: =I10/H10-1 -> #DIV/0! | J11: =J10/I10-1 -> #DIV/0! | ... AE11: =AE10/AD10-1 -> 0.10779227 | AM11: =+IF(AI10<0,1-AM10/AI10,AM10/AI10-1) -> #DIV/0! | AN11: =+IF(AJ10<0,1-AN10/AJ10,AN10/AJ10-1) -> #DIV/0! | AO11: =+IF(AK10<0,1-AO10/AK10,AO10/AK10-1) -> #DIV/0! | AP11: =+IF(AL10<0,1-AP10/AL10,AP10/AL10-1) -> #DIV/0! | AQ11: =+IF(AM10<0,1-AQ10/AM10,AQ10/AM10-1) -> #DIV/0! | AR11: =+IF(AN10<0,1-AR10/AN10,AR10/AN10-1) -> #DIV/0! | AS11: =+IF(AO10<0,1-AS10/AO10,AS10/AO10-1) -> #DIV/0! | AT11: =+IF(AP10<0,1-AT10/AP10,AT10/AP10-1) -> #DIV/0! | ... CK11: =+IF(CG10<0,1-CK10/CG10,CK10/CG10-1) -> 0.050645084 | CL11: =+AVERAGE(CH11:CK11) -> 0.15304982 | CM11: =+AVERAGE(CI11:CL11) -> 0.13700537 | CN11: =+AVERAGE(CJ11:CM11) -> 0.077615442 | CO11: =+AVERAGE(CK11:CN11) -> 0.10457893 | CP11: =+AVERAGE(CL11:CO11) -> 0.11806239 | CQ11: =+AVERAGE(CM11:CP11) -> 0.10931553 | CR11: =+AVERAGE(CN11:CQ11) -> 0.10239307 | CS11: =+AVERAGE(CO11:CR11) -> 0.10858748 | ... DB11: =+AVERAGE(CX11:DA11) -> 0.10784251 | DF11: 0.038455439
A12: Net Revenue QOQ% | AJ12: =+IF(AI10<0,1-AJ10/AI10,AJ10/AI10-1) -> #DIV/0! | AK12: =+IF(AJ10<0,1-AK10/AJ10,AK10/AJ10-1) -> #DIV/0! | AL12: =+IF(AK10<0,1-AL10/AK10,AL10/AK10-1) -> #DIV/0! | AM12: =+IF(AL10<0,1-AM10/AL10,AM10/AL10-1) -> #DIV/0! | AN12: =+IF(AM10<0,1-AN10/AM10,AN10/AM10-1) -> #DIV/0! | AO12: =+IF(AN10<0,1-AO10/AN10,AO10/AN10-1) -> #DIV/0! | AP12: =+IF(AO10<0,1-AP10/AO10,AP10/AO10-1) -> #DIV/0! | AQ12: =+IF(AP10<0,1-AQ10/AP10,AQ10/AP10-1) -> #DIV/0! | ... CK12: =+IF(CJ10<0,1-CK10/CJ10,CK10/CJ10-1) -> 0.09169154 | CL12: =+CL10/CK10-1 -> 0.56528783 | CM12: =+CM10/CL10-1 -> -0.16576946 | CN12: =+CN10/CM10-1 -> -0.24406654 | CO12: =+CO10/CN10-1 -> 0.11900723 | CP12: =+CP10/CO10-1 -> 0.58439511 | CQ12: =+CQ10/CP10-1 -> -0.17229584 | CR12: =+CR10/CQ10-1 -> -0.24878379 | CS12: =+CS10/CR10-1 -> 0.12529499 | ... DB12: =+DB10/DA10-1 -> 0.58558389
A13: Increase/Decrease in Stock | B13: ='Annual Raw'!C11 -> 0 | C13: ='Annual Raw'!D11 -> 0 | D13: ='Annual Raw'!E11 -> 0 | E13: ='Annual Raw'!F11 -> 0 | F13: ='Annual Raw'!G11 -> 0 | G13: ='Annual Raw'!H11 -> 0 | H13: ='Annual Raw'!I11 -> 0 | I13: ='Annual Raw'!J11 -> 0 | ... AA13: ='Annual Raw'!AB11 -> -39.9347 | AB13: =+SUM(CM13:CP13) -> 0 | AC13: =+SUM(CQ13:CT13) -> 0 | AD13: =+SUM(CU13:CX13) -> 0 | AE13: =+SUM(CY13:DB13) -> 0 | AI13: ='QTR Raw'!C10 -> 0 | AJ13: ='QTR Raw'!D10 -> 0 | AK13: ='QTR Raw'!E10 -> 0 | AL13: ='QTR Raw'!F10 -> 0 | AM13: ='QTR Raw'!G10 -> 0 | AN13: ='QTR Raw'!H10 -> 0 | AO13: ='QTR Raw'!I10 -> 0 | AP13: ='QTR Raw'!J10 -> 0 | ... CK13: ='QTR Raw'!BE10 -> -16.359 | DF13: -39.9347
A14: Purchase of Finished Goods | B14: 0 | C14: 0 | D14: 0 | E14: 0 | F14: 0 | G14: 0 | H14: 0 | I14: 0 | J14: 0 | K14: 0 | L14: 0 | M14: 0 | N14: 0 | O14: 0 | P14: 0 | Q14: 0 | R14: 0 | S14: 0 | T14: 0 | U14: 0 | V14: 0 | W14: 0 | X14: 0 | Y14: 0 | Z14: 0 | AA14: 0 | AB14: =+SUM(CM14:CP14) -> 0 | AC14: =+SUM(CQ14:CT14) -> 0 | AD14: =+SUM(CU14:CX14) -> 0 | AE14: =+SUM(CY14:DB14) -> 0 | AI14: ='QTR Raw'!C12 -> 0 | AJ14: ='QTR Raw'!D12 -> 0 | AK14: ='QTR Raw'!E12 -> 0 | AL14: ='QTR Raw'!F12 -> 0 | AM14: ='QTR Raw'!G12 -> 0 | AN14: ='QTR Raw'!H12 -> 0 | AO14: ='QTR Raw'!I12 -> 0 | AP14: ='QTR Raw'!J12 -> 0 | ... CK14: ='QTR Raw'!BE12 -> 0 | DF14: 0
A15: Raw Material Consumed | B15: ='Annual Raw'!C12 -> 0 | C15: ='Annual Raw'!D12 -> 0 | D15: ='Annual Raw'!E12 -> 0 | E15: ='Annual Raw'!F12 -> 0 | F15: ='Annual Raw'!G12 -> 0 | G15: ='Annual Raw'!H12 -> 0 | H15: ='Annual Raw'!I12 -> 0 | I15: ='Annual Raw'!J12 -> 0 | ... AA15: ='Annual Raw'!AB12 -> 104.2016 | AB15: =+SUM(CM15:CP15) -> 28.040136 | AC15: =+SUM(CQ15:CT15) -> 29.076109 | AD15: =+SUM(CU15:CX15) -> 32.019503 | AE15: =+SUM(CY15:DB15) -> 35.477519 | AI15: ='QTR Raw'!C11 -> 0 | AJ15: ='QTR Raw'!D11 -> 0 | AK15: ='QTR Raw'!E11 -> 0 | AL15: ='QTR Raw'!F11 -> 0 | AM15: ='QTR Raw'!G11 -> 0 | AN15: ='QTR Raw'!H11 -> 0 | AO15: ='QTR Raw'!I11 -> 0 | AP15: ='QTR Raw'!J11 -> 0 | ... CK15: ='QTR Raw'!BE11 -> 15.425 | CL15: =+CL10-CL16 -> 12.03959 | CM15: =+CM10-CM16 -> 9.5848473 | CN15: =+CN10-CN16 -> 3.5137505 | CO15: =+CO10-CO16 -> 4.8760013 | CP15: =+CP10-CP16 -> 10.065537 | CQ15: =+CQ10-CQ16 -> 7.6286741 | CR15: =+CR10-CR16 -> 5.1666304 | CS15: =+CS10-CS16 -> 6.177762 | ... DB15: =+DB10-DB16 -> 12.093567 | DF15: 104.2016
A16: Gross Profit | B16: =B10-B13-B15-B14 -> 0 | C16: =C10-C13-C15-C14 -> 0 | D16: =D10-D13-D15-D14 -> 0 | E16: =E10-E13-E15-E14 -> 0 | F16: =F10-F13-F15-F14 -> 0 | G16: =G10-G13-G15-G14 -> 0 | H16: =H10-H13-H15-H14 -> 0 | I16: =I10-I13-I15-I14 -> 0 | ... AE16: =AE10-AE13-AE15-AE14 -> 1746.1045 | AI16: =AI10-AI13-AI15-AI14 -> 0 | AJ16: =AJ10-AJ13-AJ15-AJ14 -> 0 | AK16: =AK10-AK13-AK15-AK14 -> 0 | AL16: =AL10-AL13-AL15-AL14 -> 0 | AM16: =AM10-AM13-AM15-AM14 -> 0 | AN16: =AN10-AN13-AN15-AN14 -> 0 | AO16: =AO10-AO13-AO15-AO14 -> 0 | AP16: =AP10-AP13-AP15-AP14 -> 0 | ... CK16: =CK10-CK13-CK15-CK14 -> 255.499 | CL16: =+CL17*CL10 -> 386.42791 | CM16: =+CM17*CM10 -> 322.82891 | CN16: =+CN17*CN10 -> 247.76893 | CO16: =+CO17*CO10 -> 276.31113 | CP16: =+CP17*CP10 -> 435.44599 | CQ16: =+CQ17*CQ10 -> 361.12307 | CR16: =+CR17*CR10 -> 271.84565 | CS16: =+CS17*CS10 -> 305.54278 | ... DB16: =+DB17*DB10 -> 594.72974 | DF16: 1016.7838
A17: GP% | B17: =B16/B10 -> #DIV/0! | C17: =C16/C10 -> #DIV/0! | D17: =D16/D10 -> #DIV/0! | E17: =E16/E10 -> #DIV/0! | F17: =F16/F10 -> #DIV/0! | G17: =G16/G10 -> #DIV/0! | H17: =H16/H10 -> #DIV/0! | I17: =I16/I10 -> #DIV/0! | ... AE17: =AE16/AE10 -> 0.98008651 | AI17: =AI16/AI10 -> #DIV/0! | AJ17: =AJ16/AJ10 -> #DIV/0! | AK17: =AK16/AK10 -> #DIV/0! | AL17: =AL16/AL10 -> #DIV/0! | AM17: =AM16/AM10 -> #DIV/0! | AN17: =AN16/AN10 -> #DIV/0! | AO17: =AO16/AO10 -> #DIV/0! | AP17: =AP16/AP10 -> #DIV/0! | ... CK17: =CK16/CK10 -> 1.003669 | CL17: =AVERAGE(CH17:CK17) -> 0.96978526 | CM17: =AVERAGE(CI17:CL17) -> 0.97116591 | CN17: =AVERAGE(CJ17:CM17) -> 0.98601674 | CO17: =AVERAGE(CK17:CN17) -> 0.98265923 | CP17: =AVERAGE(CL17:CO17) -> 0.97740679 | CQ17: =AVERAGE(CM17:CP17) -> 0.97931217 | CR17: =AVERAGE(CN17:CQ17) -> 0.98134873 | CS17: =AVERAGE(CO17:CR17) -> 0.98018173 | ... DB17: =AVERAGE(CX17:DA17) -> 0.98007069 | DF17: 0.94055145
A18: GP YOY% | C18: =+IF(B16<0,1-C16/B16,C16/B16-1) -> #DIV/0! | D18: =+IF(C16<0,1-D16/C16,D16/C16-1) -> #DIV/0! | E18: =+IF(D16<0,1-E16/D16,E16/D16-1) -> #DIV/0! | F18: =+IF(E16<0,1-F16/E16,F16/E16-1) -> #DIV/0! | G18: =+IF(F16<0,1-G16/F16,G16/F16-1) -> #DIV/0! | H18: =+IF(G16<0,1-H16/G16,H16/G16-1) -> #DIV/0! | I18: =+IF(H16<0,1-I16/H16,I16/H16-1) -> #DIV/0! | J18: =+IF(I16<0,1-J16/I16,J16/I16-1) -> #DIV/0! | ... AE18: =+IF(AD16<0,1-AE16/AD16,AE16/AD16-1) -> 0.10778811 | AM18: =+IF(AI16<0,1-AM16/AI16,AM16/AI16-1) -> #DIV/0! | AN18: =+IF(AJ16<0,1-AN16/AJ16,AN16/AJ16-1) -> #DIV/0! | AO18: =+IF(AK16<0,1-AO16/AK16,AO16/AK16-1) -> #DIV/0! | AP18: =+IF(AL16<0,1-AP16/AL16,AP16/AL16-1) -> #DIV/0! | AQ18: =+IF(AM16<0,1-AQ16/AM16,AQ16/AM16-1) -> #DIV/0! | AR18: =+IF(AN16<0,1-AR16/AN16,AR16/AN16-1) -> #DIV/0! | AS18: =+IF(AO16<0,1-AS16/AO16,AS16/AO16-1) -> #DIV/0! | AT18: =+IF(AP16<0,1-AT16/AP16,AT16/AP16-1) -> #DIV/0! | ... CL18: =+IF(CH16<0,1-CL16/CH16,CL16/CH16-1) -> 0.15965365 | CM18: =+CM16/CI16-1 -> 0.21108375 | CN18: =+CN16/CJ16-1 -> 0.063135006 | CO18: =+CO16/CK16-1 -> 0.081456811 | CP18: =+CP16/CL16-1 -> 0.12684922 | CQ18: =+CQ16/CM16-1 -> 0.11862061 | CR18: =+CR16/CN16-1 -> 0.097174114 | CS18: =+CS16/CO16-1 -> 0.10579249 | CT18: =+CT16/CP16-1 -> 0.1120367 | ... DB18: =+DB16/CX16-1 -> 0.10792297 | DF18: -0.030537506
A19: GP QOQ% | AJ19: =+IF(AI16<0,1-AJ16/AI16,AJ16/AI16-1) -> #DIV/0! | AK19: =+IF(AJ16<0,1-AK16/AJ16,AK16/AJ16-1) -> #DIV/0! | AL19: =+IF(AK16<0,1-AL16/AK16,AL16/AK16-1) -> #DIV/0! | AM19: =+IF(AL16<0,1-AM16/AL16,AM16/AL16-1) -> #DIV/0! | AN19: =+IF(AM16<0,1-AN16/AM16,AN16/AM16-1) -> #DIV/0! | AO19: =+IF(AN16<0,1-AO16/AN16,AO16/AN16-1) -> #DIV/0! | AP19: =+IF(AO16<0,1-AP16/AO16,AP16/AO16-1) -> #DIV/0! | AQ19: =+IF(AP16<0,1-AQ16/AP16,AQ16/AP16-1) -> #DIV/0! | ... CL19: =+IF(CK16<0,1-CL16/CK16,CL16/CK16-1) -> 0.51244391 | CM19: =+CM16/CL16-1 -> -0.1645818 | CN19: =+CN16/CM16-1 -> -0.23250699 | CO19: =+CO16/CN16-1 -> 0.11519687 | CP19: =+CP16/CO16-1 -> 0.57592631 | CQ19: =+CQ16/CP16-1 -> -0.17068229 | CR19: =+CR16/CQ16-1 -> -0.24722157 | CS19: =+CS16/CR16-1 -> 0.12395681 | CT19: =+CT16/CS16-1 -> 0.58482529 | ... DB19: =+DB16/DA16-1 -> 0.58559513
A20: Employee Cost | B20: ='Annual Raw'!C14 -> 0 | C20: ='Annual Raw'!D14 -> 0 | D20: ='Annual Raw'!E14 -> 0 | E20: ='Annual Raw'!F14 -> 0 | F20: ='Annual Raw'!G14 -> 0 | G20: ='Annual Raw'!H14 -> 0 | H20: ='Annual Raw'!I14 -> 0 | I20: ='Annual Raw'!J14 -> 0 | ... AA20: ='Annual Raw'!AB14 -> 74.1867 | AB20: =+SUM(CM20:CP20) -> 79.018976 | AC20: =+SUM(CQ20:CT20) -> 84.550304 | AD20: =+SUM(CU20:CX20) -> 90.468825 | AE20: =+SUM(CY20:DB20) -> 96.801643 | AI20: ='QTR Raw'!C16 -> 0 | AJ20: ='QTR Raw'!D16 -> 0 | AK20: ='QTR Raw'!E16 -> 0 | AL20: ='QTR Raw'!F16 -> 0 | AM20: ='QTR Raw'!G16 -> 0 | AN20: ='QTR Raw'!H16 -> 0 | AO20: ='QTR Raw'!I16 -> 0 | AP20: ='QTR Raw'!J16 -> 0 | ... CK20: ='QTR Raw'!BE16 -> 17.301 | CL20: =CH20*107% -> 20.96451 | CM20: =CI20*107% -> 20.0411 | CN20: =CJ20*107% -> 18.03378 | CO20: =CK20*107% -> 18.51207 | CP20: =CL20*107% -> 22.432026 | CQ20: =CM20*107% -> 21.443977 | CR20: =CN20*107% -> 19.296145 | CS20: =CO20*107% -> 19.807915 | ... DB20: =CX20*107% -> 27.480196 | DF20: 74.1867
A21: General and Administration Expenses | B21: ='Annual Raw'!C17 -> 0 | C21: ='Annual Raw'!D17 -> 0 | D21: ='Annual Raw'!E17 -> 0 | E21: ='Annual Raw'!F17 -> 0 | F21: ='Annual Raw'!G17 -> 0 | G21: ='Annual Raw'!H17 -> 0 | H21: ='Annual Raw'!I17 -> 0 | I21: ='Annual Raw'!J17 -> 0 | ... AA21: ='Annual Raw'!AB17 -> 58.0667 | AB21: =+SUM(CM21:CP21) -> 0 | AC21: =+SUM(CQ21:CT21) -> 0 | AD21: =+SUM(CU21:CX21) -> 0 | AE21: =+SUM(CY21:DB21) -> 0 | AI21: ='QTR Raw'!C17 -> 0 | AJ21: ='QTR Raw'!D17 -> 0 | AK21: ='QTR Raw'!E17 -> 0 | AL21: ='QTR Raw'!F17 -> 0 | AM21: ='QTR Raw'!G17 -> 0 | AN21: ='QTR Raw'!H17 -> 0 | AO21: ='QTR Raw'!I17 -> 0 | AP21: ='QTR Raw'!J17 -> 0 | ... CK21: ='QTR Raw'!BE17 -> 0 | DF21: 58.0667
A22: Miscellaneous Expenses | B22: ='Annual Raw'!C19-'Annual Raw'!C20 -> 0 | C22: ='Annual Raw'!D19-'Annual Raw'!D20 -> 0 | D22: ='Annual Raw'!E19-'Annual Raw'!E20 -> 0 | E22: ='Annual Raw'!F19-'Annual Raw'!F20 -> 0 | F22: ='Annual Raw'!G19-'Annual Raw'!G20 -> 0 | G22: ='Annual Raw'!H19-'Annual Raw'!H20 -> 0 | H22: ='Annual Raw'!I19-'Annual Raw'!I20 -> 0 | I22: ='Annual Raw'!J19-'Annual Raw'!J20 -> 0 | ... AA22: ='Annual Raw'!AB19-'Annual Raw'!AB20 -> 12.6905 | AB22: =+SUM(CM22:CP22) -> 0 | AC22: =+SUM(CQ22:CT22) -> 0 | AD22: =+SUM(CU22:CX22) -> 0 | AE22: =+SUM(CY22:DB22) -> 0 | AI22: =+'QTR Raw'!C21 -> 0 | AJ22: =+'QTR Raw'!D21 -> 0 | AK22: =+'QTR Raw'!E21 -> 0 | AL22: =+'QTR Raw'!F21 -> 0 | AM22: =+'QTR Raw'!G21 -> 0 | AN22: =+'QTR Raw'!H21 -> 0 | AO22: =+'QTR Raw'!I21 -> 0 | AP22: =+'QTR Raw'!J21 -> 0 | ... CK22: =+'QTR Raw'!BE21 -> 0 | DF22: 12.6905
A23: Other Manufacturing Expenses | B23: ='Annual Raw'!C15+'Annual Raw'!C16 -> 0 | C23: ='Annual Raw'!D15+'Annual Raw'!D16 -> 0 | D23: ='Annual Raw'!E15+'Annual Raw'!E16 -> 0 | E23: ='Annual Raw'!F15+'Annual Raw'!F16 -> 0 | F23: ='Annual Raw'!G15+'Annual Raw'!G16 -> 0 | G23: ='Annual Raw'!H15+'Annual Raw'!H16 -> 0 | H23: ='Annual Raw'!I15+'Annual Raw'!I16 -> 0 | I23: ='Annual Raw'!J15+'Annual Raw'!J16 -> 0 | ... AA23: ='Annual Raw'!AB15+'Annual Raw'!AB16 -> 48.1256 | AB23: =+SUM(CM23:CP23) -> 880.90293 | AC23: =+SUM(CQ23:CT23) -> 982.30868 | AD23: =+SUM(CU23:CX23) -> 1091.7357 | AE23: =+SUM(CY23:DB23) -> 1212.8514 | AI23: ='QTR Raw'!C14 -> 0 | AJ23: ='QTR Raw'!D14 -> 0 | AK23: ='QTR Raw'!E14 -> 0 | AL23: ='QTR Raw'!F14 -> 0 | AM23: ='QTR Raw'!G14 -> 0 | AN23: ='QTR Raw'!H14 -> 0 | AO23: ='QTR Raw'!I14 -> 0 | AP23: ='QTR Raw'!J14 -> 0 | ... CK23: ='QTR Raw'!BE14 -> 183.803 | CL23: =CL26-CL20-CL21-CL22-CL24-CL25 -> 265.37369 | CM23: =CM26-CM20-CM21-CM22-CM24-CM25 -> 219.64816 | CN23: =CN26-CN20-CN21-CN22-CN24-CN25 -> 167.95533 | CO23: =CO26-CO20-CO21-CO22-CO24-CO25 -> 190.25569 | CP23: =CP26-CP20-CP21-CP22-CP24-CP25 -> 303.04375 | CQ23: =CQ26-CQ20-CQ21-CQ22-CQ24-CQ25 -> 249.05697 | CR23: =CR26-CR20-CR21-CR22-CR24-CR25 -> 184.77431 | CS23: =CS26-CS20-CS21-CS22-CS24-CS25 -> 209.56073 | ... DB23: =DB26-DB20-DB21-DB22-DB24-DB25 -> 418.58136 | DF23: 48.1256
A24: Power & Fuel Cost | B24: ='Annual Raw'!C13 -> 0 | C24: ='Annual Raw'!D13 -> 0 | D24: ='Annual Raw'!E13 -> 0 | E24: ='Annual Raw'!F13 -> 0 | F24: ='Annual Raw'!G13 -> 0 | G24: ='Annual Raw'!H13 -> 0 | H24: ='Annual Raw'!I13 -> 0 | I24: ='Annual Raw'!J13 -> 0 | ... AA24: ='Annual Raw'!AB13 -> 96.3439 | AB24: =+SUM(CM24:CP24) -> 0 | AC24: =+SUM(CQ24:CT24) -> 0 | AD24: =+SUM(CU24:CX24) -> 0 | AE24: =+SUM(CY24:DB24) -> 0 | AI24: ='QTR Raw'!C15 -> 0 | AJ24: ='QTR Raw'!D15 -> 0 | AK24: ='QTR Raw'!E15 -> 0 | AL24: ='QTR Raw'!F15 -> 0 | AM24: ='QTR Raw'!G15 -> 0 | AN24: ='QTR Raw'!H15 -> 0 | AO24: ='QTR Raw'!I15 -> 0 | AP24: ='QTR Raw'!J15 -> 0 | ... CK24: ='QTR Raw'!BE15 -> 0 | DF24: 96.3439
A25: Selling and Distribution Expenses | B25: ='Annual Raw'!C18 -> 0 | C25: ='Annual Raw'!D18 -> 0 | D25: ='Annual Raw'!E18 -> 0 | E25: ='Annual Raw'!F18 -> 0 | F25: ='Annual Raw'!G18 -> 0 | G25: ='Annual Raw'!H18 -> 0 | H25: ='Annual Raw'!I18 -> 0 | I25: ='Annual Raw'!J18 -> 0 | ... AA25: ='Annual Raw'!AB18 -> 488.5882 | AB25: =+SUM(CM25:CP25) -> 0 | AC25: =+SUM(CQ25:CT25) -> 0 | AD25: =+SUM(CU25:CX25) -> 0 | AE25: =+SUM(CY25:DB25) -> 0 | AI25: ='QTR Raw'!C18 -> 0 | AJ25: ='QTR Raw'!D18 -> 0 | AK25: ='QTR Raw'!E18 -> 0 | AL25: ='QTR Raw'!F18 -> 0 | AM25: ='QTR Raw'!G18 -> 0 | AN25: ='QTR Raw'!H18 -> 0 | AO25: ='QTR Raw'!I18 -> 0 | AP25: ='QTR Raw'!J18 -> 0 | ... CK25: ='QTR Raw'!BE18 -> 0 | DF25: 488.5882
A26: Total Cost | B26: =+SUM(B20:B25) -> 0 | C26: =+SUM(C20:C25) -> 0 | D26: =+SUM(D20:D25) -> 0 | E26: =+SUM(E20:E25) -> 0 | F26: =+SUM(F20:F25) -> 0 | G26: =+SUM(G20:G25) -> 0 | H26: =+SUM(H20:H25) -> 0 | I26: =+SUM(I20:I25) -> 0 | ... AE26: =+SUM(AE20:AE25) -> 1309.653 | AI26: =+SUM(AI20:AI25) -> 0 | AJ26: =+SUM(AJ20:AJ25) -> 0 | AK26: =+SUM(AK20:AK25) -> 0 | AL26: =+SUM(AL20:AL25) -> 0 | AM26: =+SUM(AM20:AM25) -> 0 | AN26: =+SUM(AN20:AN25) -> 0 | AO26: =+SUM(AO20:AO25) -> 0 | AP26: =+SUM(AP20:AP25) -> 0 | ... CK26: =+SUM(CK20:CK25) -> 201.104 | CL26: =CL27*CL10 -> 286.3382 | CM26: =CM27*CM10 -> 239.68926 | CN26: =CN27*CN10 -> 185.98911 | CO26: =CO27*CO10 -> 208.76776 | CP26: =CP27*CP10 -> 325.47578 | CQ26: =CQ27*CQ10 -> 270.50094 | CR26: =CR27*CR10 -> 204.07046 | CS26: =CS27*CS10 -> 229.36865 | ... DB26: =DB27*DB10 -> 446.06155 | DF26: 778.0016
A27: Cost % | B27: =B26/B10 -> #DIV/0! | C27: =C26/C10 -> #DIV/0! | D27: =D26/D10 -> #DIV/0! | E27: =E26/E10 -> #DIV/0! | F27: =F26/F10 -> #DIV/0! | G27: =G26/G10 -> #DIV/0! | H27: =H26/H10 -> #DIV/0! | I27: =I26/I10 -> #DIV/0! | ... AE27: =AE26/AE10 -> 0.73510677 | AI27: =AI26/AI10 -> #DIV/0! | AJ27: =AJ26/AJ10 -> #DIV/0! | AK27: =AK26/AK10 -> #DIV/0! | AL27: =AL26/AL10 -> #DIV/0! | AM27: =AM26/AM10 -> #DIV/0! | AN27: =AN26/AN10 -> #DIV/0! | AO27: =AO26/AO10 -> #DIV/0! | AP27: =AP26/AP10 -> #DIV/0! | ... CK27: =CK26/CK10 -> 0.78999077 | CL27: =AVERAGE(CH27:CK27) -> 0.71859865 | CM27: =AVERAGE(CI27:CL27) -> 0.72105697 | CN27: =AVERAGE(CJ27:CM27) -> 0.74015891 | CO27: =AVERAGE(CK27:CN27) -> 0.74245133 | CP27: =AVERAGE(CL27:CO27) -> 0.73056646 | CQ27: =AVERAGE(CM27:CP27) -> 0.73355842 | CR27: =AVERAGE(CN27:CQ27) -> 0.73668378 | CS27: =AVERAGE(CO27:CR27) -> 0.735815 | ... DB27: =AVERAGE(CX27:DA27) -> 0.7350765 | DF27: 0.7196717
A28: EBITDA | B28: =B16-B26 -> 0 | C28: =C16-C26 -> 0 | D28: =D16-D26 -> 0 | E28: =E16-E26 -> 0 | F28: =F16-F26 -> 0 | G28: =G16-G26 -> 0 | H28: =H16-H26 -> 0 | I28: =I16-I26 -> 0 | ... AE28: =AE16-AE26 -> 436.4515 | AI28: =AI16-AI26 -> 0 | AJ28: =AJ16-AJ26 -> 0 | AK28: =AK16-AK26 -> 0 | AL28: =AL16-AL26 -> 0 | AM28: =AM16-AM26 -> 0 | AN28: =AN16-AN26 -> 0 | AO28: =AO16-AO26 -> 0 | AP28: =AP16-AP26 -> 0 | ... DB28: =DB16-DB26 -> 148.66819 | DF28: 238.7822
A29: EBITDA Margins | B29: =B28/B10 -> #DIV/0! | C29: =C28/C10 -> #DIV/0! | D29: =D28/D10 -> #DIV/0! | E29: =E28/E10 -> #DIV/0! | F29: =F28/F10 -> #DIV/0! | G29: =G28/G10 -> #DIV/0! | H29: =H28/H10 -> #DIV/0! | I29: =I28/I10 -> #DIV/0! | ... AE29: =AE28/AE10 -> 0.24497974 | AI29: =AI28/AI10 -> #DIV/0! | AJ29: =AJ28/AJ10 -> #DIV/0! | AK29: =AK28/AK10 -> #DIV/0! | AL29: =AL28/AL10 -> #DIV/0! | AM29: =AM28/AM10 -> #DIV/0! | AN29: =AN28/AN10 -> #DIV/0! | AO29: =AO28/AO10 -> #DIV/0! | AP29: =AP28/AP10 -> #DIV/0! | ... DB29: =DB28/DB10 -> 0.2449942 | DF29: 0.22087974
A30: EBITDA YOY% | C30: =+IF(B28<0,1-C28/B28,C28/B28-1) -> #DIV/0! | D30: =+IF(C28<0,1-D28/C28,D28/C28-1) -> #DIV/0! | E30: =+IF(D28<0,1-E28/D28,E28/D28-1) -> #DIV/0! | F30: =+IF(E28<0,1-F28/E28,F28/E28-1) -> #DIV/0! | G30: =+IF(F28<0,1-G28/F28,G28/F28-1) -> #DIV/0! | H30: =+IF(G28<0,1-H28/G28,H28/G28-1) -> #DIV/0! | I30: =+IF(H28<0,1-I28/H28,I28/H28-1) -> #DIV/0! | J30: =+IF(I28<0,1-J28/I28,J28/I28-1) -> #DIV/0! | ... AE30: =+IF(AD28<0,1-AE28/AD28,AE28/AD28-1) -> 0.10773508 | AM30: =+IF(AI28<0,1-AM28/AI28,AM28/AI28-1) -> #DIV/0! | AN30: =+IF(AJ28<0,1-AN28/AJ28,AN28/AJ28-1) -> #DIV/0! | AO30: =+IF(AK28<0,1-AO28/AK28,AO28/AK28-1) -> #DIV/0! | AP30: =+IF(AL28<0,1-AP28/AL28,AP28/AL28-1) -> #DIV/0! | AQ30: =+IF(AM28<0,1-AQ28/AM28,AQ28/AM28-1) -> #DIV/0! | AR30: =+IF(AN28<0,1-AR28/AN28,AR28/AN28-1) -> #DIV/0! | AS30: =+IF(AO28<0,1-AS28/AO28,AS28/AO28-1) -> #DIV/0! | AT30: =+IF(AP28<0,1-AT28/AP28,AT28/AP28-1) -> #DIV/0! | ... CL30: =+IF(CH28<0,1-CL28/CH28,CL28/CH28-1) -> 0.13359574 | CM30: =+CM28/CI28-1 -> 0.064623608 | CN30: =+CN28/CJ28-1 -> -0.01310201 | CO30: =+CO28/CK28-1 -> 0.24172025 | CP30: =+CP28/CL28-1 -> 0.098716503 | CQ30: =+CQ28/CM28-1 -> 0.089998832 | CR30: =+CR28/CN28-1 -> 0.097044372 | CS30: =+CS28/CO28-1 -> 0.12778095 | CT30: =+CT28/CP28-1 -> 0.10314407 | ... DB30: =+DB28/CX28-1 -> 0.10753477 | DF30: -0.23992088
A31: EBITDA QOQ% | AJ31: =+IF(AI28<0,1-AJ28/AI28,AJ28/AI28-1) -> #DIV/0! | AK31: =+IF(AJ28<0,1-AK28/AJ28,AK28/AJ28-1) -> #DIV/0! | AL31: =+IF(AK28<0,1-AL28/AK28,AL28/AK28-1) -> #DIV/0! | AM31: =+IF(AL28<0,1-AM28/AL28,AM28/AL28-1) -> #DIV/0! | AN31: =+IF(AM28<0,1-AN28/AM28,AN28/AM28-1) -> #DIV/0! | AO31: =+IF(AN28<0,1-AO28/AN28,AO28/AN28-1) -> #DIV/0! | AP31: =+IF(AO28<0,1-AP28/AO28,AP28/AO28-1) -> #DIV/0! | AQ31: =+IF(AP28<0,1-AQ28/AP28,AQ28/AP28-1) -> #DIV/0! | ... CI31: =+IF(CH28<0,1-CI28/CH28,CI28/CH28-1) -> -0.11553446 | CJ31: =+IF(CI28>1,CJ28/CI28-1,1-CJ28/CI28) -> -0.19839166 | CK31: =+IF(CJ28>1,CK28/CJ28-1,1-CK28/CJ28) -> -0.13107029 | CL31: =+IF(CK28<0,1-CL28/CK28,CL28/CK28-1) -> 0.84005336 | CM31: =+CM28/CL28-1 -> -0.1693486 | CN31: =+CN28/CM28-1 -> -0.25691516 | CO31: =+CO28/CN28-1 -> 0.093291938 | CP31: =+CP28/CO28-1 -> 0.62814209 | CQ31: =+CQ28/CP28-1 -> -0.17593933 | CR31: =+CR28/CQ28-1 -> -0.25211201 | CS31: =+CS28/CR28-1 -> 0.12392338 | CT31: =+CT28/CS28-1 -> 0.59257459 | ... DB31: =+DB28/DA28-1 -> 0.58567584
A32: Depreciation | B32: ='Annual Raw'!C27 -> 0 | C32: ='Annual Raw'!D27 -> 0 | D32: ='Annual Raw'!E27 -> 0 | E32: ='Annual Raw'!F27 -> 0 | F32: ='Annual Raw'!G27 -> 0 | G32: ='Annual Raw'!H27 -> 0 | H32: ='Annual Raw'!I27 -> 0 | I32: ='Annual Raw'!J27 -> 0 | ... AA32: ='Annual Raw'!AB27 -> 92.8887 | AB32: =+SUM(CM32:CP32) -> 88.613347 | AC32: =+SUM(CQ32:CT32) -> 82.417753 | AD32: =+SUM(CU32:CX32) -> 76.655337 | AE32: =+SUM(CY32:DB32) -> 71.295814 | AI32: ='QTR Raw'!C28 -> 0 | AJ32: ='QTR Raw'!D28 -> 0 | AK32: ='QTR Raw'!E28 -> 0 | AL32: ='QTR Raw'!F28 -> 0 | AM32: ='QTR Raw'!G28 -> 0 | AN32: ='QTR Raw'!H28 -> 0 | AO32: ='QTR Raw'!I28 -> 0 | AP32: ='QTR Raw'!J28 -> 0 | ... CK32: ='QTR Raw'!BE28 -> 23.599 | CL32: =CL33*CK134 -> 23.175228 | CM32: =CM33*CL134 -> 22.759065 | CN32: =CN33*CM134 -> 22.350375 | CO32: =CO33*CN134 -> 21.949025 | CP32: =CP33*CO134 -> 21.554881 | CQ32: =CQ33*CP134 -> 21.167816 | CR32: =CR33*CQ134 -> 20.787701 | CS32: =CS33*CR134 -> 20.414411 | ... DB32: =DB33*DA134 -> 17.342453 | DF32: 92.8887
A33: Depreciation % of Net Block | B33: =+B32/B134 -> #DIV/0! | C33: =+C32/C134 -> #DIV/0! | D33: =+D32/D134 -> #DIV/0! | E33: =+E32/E134 -> #DIV/0! | F33: =+F32/F134 -> #DIV/0! | G33: =+G32/G134 -> #DIV/0! | H33: =+H32/H134 -> #DIV/0! | I33: =+I32/I134 -> #DIV/0! | ... AE33: =+AE32/AE134 -> 0.07517305 | AI33: =+AI32/AH134 -> #DIV/0! | AJ33: =+AJ32/AI134 -> #DIV/0! | AK33: =+AK32/AJ134 -> #DIV/0! | AL33: =+AL32/AK134 -> #DIV/0! | AM33: =+AM32/AL134 -> #DIV/0! | AN33: =+AN32/AM134 -> #DIV/0! | AO33: =+AO32/AN134 -> #DIV/0! | AP33: =+AP32/AO134 -> #DIV/0! | ... CK33: =+CK32/CJ134 -> 0.017957219 | CL33: =CK33 -> 0.017957219 | CM33: =CL33 -> 0.017957219 | CN33: =CM33 -> 0.017957219 | CO33: =CN33 -> 0.017957219 | CP33: =CO33 -> 0.017957219 | CQ33: =CP33 -> 0.017957219 | CR33: =CQ33 -> 0.017957219 | CS33: =CR33 -> 0.017957219 | ... DB33: =DA33 -> 0.017957219 | DF33: 0.06715547
A34: EBIT | B34: =B28-B32 -> 0 | C34: =C28-C32 -> 0 | D34: =D28-D32 -> 0 | E34: =E28-E32 -> 0 | F34: =F28-F32 -> 0 | G34: =G28-G32 -> 0 | H34: =H28-H32 -> 0 | I34: =I28-I32 -> 0 | ... AE34: =AE28-AE32 -> 365.15569 | AI34: =AI28-AI32 -> 0 | AJ34: =AJ28-AJ32 -> 0 | AK34: =AK28-AK32 -> 0 | AL34: =AL28-AL32 -> 0 | AM34: =AM28-AM32 -> 0 | AN34: =AN28-AN32 -> 0 | AO34: =AO28-AO32 -> 0 | AP34: =AP28-AP32 -> 0 | ... DB34: =DB28-DB32 -> 131.32574 | DF34: 145.8935
A35: Other Income | B35: ='Annual Raw'!C23 -> 0 | C35: ='Annual Raw'!D23 -> 0 | D35: ='Annual Raw'!E23 -> 0 | E35: ='Annual Raw'!F23 -> 0 | F35: ='Annual Raw'!G23 -> 0 | G35: ='Annual Raw'!H23 -> 0 | H35: ='Annual Raw'!I23 -> 0 | I35: ='Annual Raw'!J23 -> 0 | ... AA35: ='Annual Raw'!AB23 -> 26.9491 | AB35: =+SUM(CM35:CP35) -> 0 | AC35: =+SUM(CQ35:CT35) -> 0 | AD35: =+SUM(CU35:CX35) -> 0 | AE35: =+SUM(CY35:DB35) -> 0 | AI35: ='QTR Raw'!C23 -> 0 | AJ35: ='QTR Raw'!D23 -> 0 | AK35: ='QTR Raw'!E23 -> 0 | AL35: ='QTR Raw'!F23 -> 0 | AM35: ='QTR Raw'!G23 -> 0 | AN35: ='QTR Raw'!H23 -> 0 | AO35: ='QTR Raw'!I23 -> 0 | AP35: ='QTR Raw'!J23 -> 0 | ... CK35: ='QTR Raw'!BE23 -> 6.953 | DF35: 26.9491
A36: Interest | B36: ='Annual Raw'!C25 -> 0 | C36: ='Annual Raw'!D25 -> 0 | D36: ='Annual Raw'!E25 -> 0 | E36: ='Annual Raw'!F25 -> 0 | F36: ='Annual Raw'!G25 -> 0 | G36: ='Annual Raw'!H25 -> 0 | H36: ='Annual Raw'!I25 -> 0 | I36: ='Annual Raw'!J25 -> 0 | ... AA36: ='Annual Raw'!AB25 -> 25.7468 | AB36: =+SUM(CM36:CP36) -> 11.982464 | AC36: =+SUM(CQ36:CT36) -> 67.100296 | AD36: =+SUM(CU36:CX36) -> 116.08886 | AE36: =+SUM(CY36:DB36) -> 160.63756 | AI36: ='QTR Raw'!C25 -> 0 | AJ36: ='QTR Raw'!D25 -> 0 | AK36: ='QTR Raw'!E25 -> 0 | AL36: ='QTR Raw'!F25 -> 0 | AM36: ='QTR Raw'!G25 -> 0 | AN36: ='QTR Raw'!H25 -> 0 | AO36: ='QTR Raw'!I25 -> 0 | AP36: ='QTR Raw'!J25 -> 0 | ... CK36: ='QTR Raw'!BE25 -> 4.42 | CL36: =CL37*CK168 -> -1.8730739 | CM36: =CM37*CL168 -> -16.197838 | CN36: =CN37*CM168 -> -0.71232344 | CO36: =CO37*CN168 -> 14.867014 | CP36: =CP37*CO168 -> 14.025611 | CQ36: =CQ37*CP168 -> -3.5817768 | CR36: =CR37*CQ168 -> 13.124408 | CS36: =CS37*CR168 -> 29.735499 | ... DB36: =DB37*DA168 -> 51.813901 | DF36: 25.7468
A37: Interest % of Debt | B37: =+B36/B128 -> #DIV/0! | C37: =+C36/C128 -> #DIV/0! | D37: =+D36/D128 -> #DIV/0! | E37: =+E36/E128 -> #DIV/0! | F37: =+F36/F128 -> #DIV/0! | G37: =+G36/G128 -> #DIV/0! | H37: =+H36/H128 -> #DIV/0! | I37: =+I36/I128 -> #DIV/0! | ... AE37: =+AE36/AE128 -> 0.76239582 | AI37: =(AI36-AI35)/AH168 -> #DIV/0! | AJ37: =(AJ36-AJ35)/AI168 -> #DIV/0! | AK37: =(AK36-AK35)/AJ168 -> #DIV/0! | AL37: =(AL36-AL35)/AK168 -> #DIV/0! | AM37: =(AM36-AM35)/AL168 -> #DIV/0! | AN37: =(AN36-AN35)/AM168 -> #DIV/0! | AO37: =(AO36-AO35)/AN168 -> #DIV/0! | AP37: =(AP36-AP35)/AO168 -> #DIV/0! | ... CK37: =(CK36-CK35)/CJ168 -> -0.078588936 | CL37: =+CK37 -> -0.078588936 | CM37: =+CL37 -> -0.078588936 | CN37: =+CM37 -> -0.078588936 | CO37: =+CN37 -> -0.078588936 | CP37: =+CO37 -> -0.078588936 | CQ37: =+CP37 -> -0.078588936 | CR37: =+CQ37 -> -0.078588936 | CS37: =+CR37 -> -0.078588936 | ... DB37: =+DA37 -> -0.078588936 | DF37: 0.063569489
A38: PBT | B38: =B34+B35-B36 -> 0 | C38: =C34+C35-C36 -> 0 | D38: =D34+D35-D36 -> 0 | E38: =E34+E35-E36 -> 0 | F38: =F34+F35-F36 -> 0 | G38: =G34+G35-G36 -> 0 | H38: =H34+H35-H36 -> 0 | I38: =I34+I35-I36 -> 0 | ... AE38: =AE34+AE35-AE36 -> 204.51813 | AI38: =AI34+AI35-AI36 -> 0 | AJ38: =AJ34+AJ35-AJ36 -> 0 | AK38: =AK34+AK35-AK36 -> 0 | AL38: =AL34+AL35-AL36 -> 0 | AM38: =AM34+AM35-AM36 -> 0 | AN38: =AN34+AN35-AN36 -> 0 | AO38: =AO34+AO35-AO36 -> 0 | AP38: =AP34+AP35-AP36 -> 0 | ... DB38: =DB34+DB35-DB36 -> 79.511837 | DF38: 147.0958
A39: Tax | B39: ='Annual Raw'!C30 -> 0 | C39: ='Annual Raw'!D30 -> 0 | D39: ='Annual Raw'!E30 -> 0 | E39: ='Annual Raw'!F30 -> 0 | F39: ='Annual Raw'!G30 -> 0 | G39: ='Annual Raw'!H30 -> 0 | H39: ='Annual Raw'!I30 -> 0 | I39: ='Annual Raw'!J30 -> 0 | ... AA39: ='Annual Raw'!AB30 -> 41.6878 | AB39: =+SUM(CM39:CP39) -> 63.017937 | AC39: =+SUM(CQ39:CT39) -> 58.47474 | AD39: =+SUM(CU39:CX39) -> 57.013425 | AE39: =+SUM(CY39:DB39) -> 57.936449 | AI39: ='QTR Raw'!C29 -> 0 | AJ39: ='QTR Raw'!D29 -> 0 | AK39: ='QTR Raw'!E29 -> 0 | AL39: ='QTR Raw'!F29 -> 0 | AM39: ='QTR Raw'!G29 -> 0 | AN39: ='QTR Raw'!H29 -> 0 | AO39: ='QTR Raw'!I29 -> 0 | AP39: ='QTR Raw'!J29 -> 0 | ... CK39: ='QTR Raw'!BE29 -> 9.33 | CL39: =+CL38*CL40 -> 22.463479 | CM39: =+CM38*CM40 -> 21.926528 | CN39: =+CN38*CN40 -> 11.276875 | CO39: =+CO38*CO40 -> 8.6981785 | CP39: =+CP38*CP40 -> 21.116355 | CQ39: =+CQ38*CQ40 -> 20.709226 | CR39: =+CR38*CR40 -> 9.5782729 | CS39: =+CS38*CS40 -> 7.3735607 | ... DB39: =+DB38*DB40 -> 22.524676 | DF39: 41.6878
A40: Tax Rate % | B40: =B39/B38 -> #DIV/0! | C40: =C39/C38 -> #DIV/0! | D40: =D39/D38 -> #DIV/0! | E40: =E39/E38 -> #DIV/0! | F40: =F39/F38 -> #DIV/0! | G40: =G39/G38 -> #DIV/0! | H40: =H39/H38 -> #DIV/0! | I40: =I39/I38 -> #DIV/0! | ... AE40: =AE39/AE38 -> 0.28328271 | AI40: =AI39/AI38 -> #DIV/0! | AJ40: =AJ39/AJ38 -> #DIV/0! | AK40: =AK39/AK38 -> #DIV/0! | AL40: =AL39/AL38 -> #DIV/0! | AM40: =AM39/AM38 -> #DIV/0! | AN40: =AN39/AN38 -> #DIV/0! | AO40: =AO39/AO38 -> #DIV/0! | AP40: =AP39/AP38 -> #DIV/0! | ... CK40: =CK39/CK38 -> 0.27993639 | CL40: =AVERAGE(CH40:CK40) -> 0.28511459 | CM40: =AVERAGE(CI40:CL40) -> 0.28632775 | CN40: =AVERAGE(CJ40:CM40) -> 0.28092627 | CO40: =AVERAGE(CK40:CN40) -> 0.28307625 | CP40: =AVERAGE(CL40:CO40) -> 0.28386121 | CQ40: =AVERAGE(CM40:CP40) -> 0.28354787 | CR40: =AVERAGE(CN40:CQ40) -> 0.2828529 | CS40: =AVERAGE(CO40:CR40) -> 0.28333456 | ... DB40: =AVERAGE(CX40:DA40) -> 0.28328708 | DF40: 0.28340578
A41: PAT | B41: =B38-B39 -> 0 | C41: =C38-C39 -> 0 | D41: =D38-D39 -> 0 | E41: =E38-E39 -> 0 | F41: =F38-F39 -> 0 | G41: =G38-G39 -> 0 | H41: =H38-H39 -> 0 | I41: =I38-I39 -> 0 | ... AE41: =AE38-AE39 -> 146.58168 | AI41: =AI38-AI39 -> 0 | AJ41: =AJ38-AJ39 -> 0 | AK41: =AK38-AK39 -> 0 | AL41: =AL38-AL39 -> 0 | AM41: =AM38-AM39 -> 0 | AN41: =AN38-AN39 -> 0 | AO41: =AO38-AO39 -> 0 | AP41: =AP38-AP39 -> 0 | ... DB41: =DB38-DB39 -> 56.98716 | DF41: 105.408
A42: PAT % | B42: =+B41/B10 -> #DIV/0! | C42: =+C41/C10 -> #DIV/0! | D42: =+D41/D10 -> #DIV/0! | E42: =+E41/E10 -> #DIV/0! | F42: =+F41/F10 -> #DIV/0! | G42: =+G41/G10 -> #DIV/0! | H42: =+H41/H10 -> #DIV/0! | I42: =+I41/I10 -> #DIV/0! | ... AE42: =+AE41/AE10 -> 0.082276132 | AI42: =+AI41/AI10 -> #DIV/0! | AJ42: =+AJ41/AJ10 -> #DIV/0! | AK42: =+AK41/AK10 -> #DIV/0! | AL42: =+AL41/AL10 -> #DIV/0! | AM42: =+AM41/AM10 -> #DIV/0! | AN42: =+AN41/AN10 -> #DIV/0! | AO42: =+AO41/AO10 -> #DIV/0! | AP42: =+AP41/AP10 -> #DIV/0! | ... DB42: =+DB41/DB10 -> 0.093910632 | DF42: 0.09750514
A43: PAT YOY% | C43: =+IF(B41<0,1-C41/B41,C41/B41-1) -> #DIV/0! | D43: =+IF(C41<0,1-D41/C41,D41/C41-1) -> #DIV/0! | E43: =+IF(D41<0,1-E41/D41,E41/D41-1) -> #DIV/0! | F43: =+IF(E41<0,1-F41/E41,F41/E41-1) -> #DIV/0! | G43: =+IF(F41<0,1-G41/F41,G41/F41-1) -> #DIV/0! | H43: =+IF(G41<0,1-H41/G41,H41/G41-1) -> #DIV/0! | I43: =+IF(H41<0,1-I41/H41,I41/H41-1) -> #DIV/0! | J43: =+IF(I41<0,1-J41/I41,J41/I41-1) -> #DIV/0! | ... AE43: =+IF(AD41<0,1-AE41/AD41,AE41/AD41-1) -> 0.016193145 | AM43: =+IF(AI41<0,1-AM41/AI41,AM41/AI41-1) -> #DIV/0! | AN43: =+IF(AJ41<0,1-AN41/AJ41,AN41/AJ41-1) -> #DIV/0! | AO43: =+IF(AK41<0,1-AO41/AK41,AO41/AK41-1) -> #DIV/0! | AP43: =+IF(AL41<0,1-AP41/AL41,AP41/AL41-1) -> #DIV/0! | AQ43: =+IF(AM41<0,1-AQ41/AM41,AQ41/AM41-1) -> #DIV/0! | AR43: =+IF(AN41<0,1-AR41/AN41,AR41/AN41-1) -> #DIV/0! | AS43: =+IF(AO41<0,1-AS41/AO41,AS41/AO41-1) -> #DIV/0! | AT43: =+IF(AP41<0,1-AT41/AP41,AT41/AP41-1) -> #DIV/0! | ... CL43: =+IF(CH41<0,1-CL41/CH41,CL41/CH41-1) -> 0.04798715 | CM43: =+CM41/CI41-1 -> 0.36139639 | CN43: =+CN41/CJ41-1 -> -0.0060300728 | CO43: =+CO41/CK41-1 -> -0.082080268 | CP43: =+CP41/CL41-1 -> -0.054163502 | CQ43: =+CQ41/CM41-1 -> -0.042542687 | CR43: =+CR41/CN41-1 -> -0.15867274 | CS43: =+CS41/CO41-1 -> -0.1533648 | CT43: =+CT41/CP41-1 -> -0.012089523 | ... DB43: =+DB41/CX41-1 -> 0.055562338 | DF43: -0.47902313
...

Sheet QTR Raw
A1: ='Annual Raw'!A1 -> 293601 | B1: X | C1: 201206 | D1: 201209 | E1: 201212 | F1: 201303 | G1: 201306 | H1: 201309 | I1: 201312 | J1: 201403 | K1: 201406 | L1: 201409 | M1: 201412 | N1: 201503 | O1: 201506 | P1: 201509 | Q1: 201512 | R1: 201603 | S1: 201606 | T1: 201609 | U1: 201612 | V1: 201703 | W1: 201706 | X1: 201709 | Y1: 201712 | Z1: 201803 | AA1: 201806 | AB1: 201809 | AC1: 201812 | AD1: 201903 | AE1: 201906 | AF1: 201909 | AG1: 201912 | AH1: 202003 | AI1: 202006 | AJ1: 202009 | AK1: 202012 | AL1: 202103 | AM1: 202106 | AN1: 202109 | AO1: 202112 | AP1: 202203 | AQ1: 202206 | AR1: 202209 | AS1: 202212 | AT1: 202303 | AU1: 202306 | AV1: 202309 | AW1: 202312 | AX1: 202403 | AY1: 202406 | AZ1: 202409 | BA1: 202412 | BB1: 202503 | BC1: 202506 | BD1: 202509 | BE1: 202512 | BF1: 202603 | BG1: 202606 | BH1: 202609 | BI1: 202612 | BJ1: 202703 | BK1: 202706 | BL1: 202709 | BM1: 202712 | BN1: 202803 | BO1: 202806 | BP1: 202809 | BQ1: 202812 | BR1: 202903 | BS1: 202906 | BT1: 202909 | BU1: 202912 | BV1: 203003
A3: Field Description | B3: Field Name
A4: Company Name | B4: CD_COMPNAME | C4: =_xll.EQNXTDZ(A1,B4,C1) -> Archean Chemical Industries Ltd.
A5: Date End | B5: QTR_DATE_END | C5: =_xll.EQNXTDZ($A$1,$B5,C$1,$B$1) -> 0 | D5: =_xll.EQNXTDZ($A$1,$B5,D$1,$B$1) -> 0 | E5: =_xll.EQNXTDZ($A$1,$B5,E$1,$B$1) -> 0 | F5: =_xll.EQNXTDZ($A$1,$B5,F$1,$B$1) -> 0 | G5: =_xll.EQNXTDZ($A$1,$B5,G$1,$B$1) -> 0 | H5: =_xll.EQNXTDZ($A$1,$B5,H$1,$B$1) -> 0 | I5: =_xll.EQNXTDZ($A$1,$B5,I$1,$B$1) -> 0 | J5: =_xll.EQNXTDZ($A$1,$B5,J$1,$B$1) -> 0 | ... BV5: =_xll.EQNXTDZ($A$1,$B5,BV$1,$B$1) -> 0
A6: Gross Sales | B6: QTR_GROSS_SALE | C6: =_xll.EQNXTDZ($A$1,$B6,C$1,$B$1) -> 0 | D6: =_xll.EQNXTDZ($A$1,$B6,D$1,$B$1) -> 0 | E6: =_xll.EQNXTDZ($A$1,$B6,E$1,$B$1) -> 0 | F6: =_xll.EQNXTDZ($A$1,$B6,F$1,$B$1) -> 0 | G6: =_xll.EQNXTDZ($A$1,$B6,G$1,$B$1) -> 0 | H6: =_xll.EQNXTDZ($A$1,$B6,H$1,$B$1) -> 0 | I6: =_xll.EQNXTDZ($A$1,$B6,I$1,$B$1) -> 0 | J6: =_xll.EQNXTDZ($A$1,$B6,J$1,$B$1) -> 0 | ... BV6: =_xll.EQNXTDZ($A$1,$B6,BV$1,$B$1) -> 0
A7: Less: Excise Duty | B7: QTR_EXCISE_DUTY | C7: =_xll.EQNXTDZ($A$1,$B7,C$1,$B$1) -> 0 | D7: =_xll.EQNXTDZ($A$1,$B7,D$1,$B$1) -> 0 | E7: =_xll.EQNXTDZ($A$1,$B7,E$1,$B$1) -> 0 | F7: =_xll.EQNXTDZ($A$1,$B7,F$1,$B$1) -> 0 | G7: =_xll.EQNXTDZ($A$1,$B7,G$1,$B$1) -> 0 | H7: =_xll.EQNXTDZ($A$1,$B7,H$1,$B$1) -> 0 | I7: =_xll.EQNXTDZ($A$1,$B7,I$1,$B$1) -> 0 | J7: =_xll.EQNXTDZ($A$1,$B7,J$1,$B$1) -> 0 | ... BV7: =_xll.EQNXTDZ($A$1,$B7,BV$1,$B$1) -> 0
A8: Other operating income | B8: QTR_JOB_WORKS | C8: =_xll.EQNXTDZ($A$1,$B8,C$1,$B$1) -> 0 | D8: =_xll.EQNXTDZ($A$1,$B8,D$1,$B$1) -> 0 | E8: =_xll.EQNXTDZ($A$1,$B8,E$1,$B$1) -> 0 | F8: =_xll.EQNXTDZ($A$1,$B8,F$1,$B$1) -> 0 | G8: =_xll.EQNXTDZ($A$1,$B8,G$1,$B$1) -> 0 | H8: =_xll.EQNXTDZ($A$1,$B8,H$1,$B$1) -> 0 | I8: =_xll.EQNXTDZ($A$1,$B8,I$1,$B$1) -> 0 | J8: =_xll.EQNXTDZ($A$1,$B8,J$1,$B$1) -> 0 | ... BV8: =_xll.EQNXTDZ($A$1,$B8,BV$1,$B$1) -> 0
A9: Net Sales & Other Operating Income | B9: QTR_NET_SALES | C9: =_xll.EQNXTDZ($A$1,$B9,C$1,$B$1) -> 0 | D9: =_xll.EQNXTDZ($A$1,$B9,D$1,$B$1) -> 0 | E9: =_xll.EQNXTDZ($A$1,$B9,E$1,$B$1) -> 0 | F9: =_xll.EQNXTDZ($A$1,$B9,F$1,$B$1) -> 0 | G9: =_xll.EQNXTDZ($A$1,$B9,G$1,$B$1) -> 0 | H9: =_xll.EQNXTDZ($A$1,$B9,H$1,$B$1) -> 0 | I9: =_xll.EQNXTDZ($A$1,$B9,I$1,$B$1) -> 0 | J9: =_xll.EQNXTDZ($A$1,$B9,J$1,$B$1) -> 0 | ... BV9: =_xll.EQNXTDZ($A$1,$B9,BV$1,$B$1) -> 0
A10: (Increase) / Decrease In Stocks | B10: QTR_INC_DEC_INVENTORY | C10: =_xll.EQNXTDZ($A$1,$B10,C$1,$B$1) -> 0 | D10: =_xll.EQNXTDZ($A$1,$B10,D$1,$B$1) -> 0 | E10: =_xll.EQNXTDZ($A$1,$B10,E$1,$B$1) -> 0 | F10: =_xll.EQNXTDZ($A$1,$B10,F$1,$B$1) -> 0 | G10: =_xll.EQNXTDZ($A$1,$B10,G$1,$B$1) -> 0 | H10: =_xll.EQNXTDZ($A$1,$B10,H$1,$B$1) -> 0 | I10: =_xll.EQNXTDZ($A$1,$B10,I$1,$B$1) -> 0 | J10: =_xll.EQNXTDZ($A$1,$B10,J$1,$B$1) -> 0 | ... BV10: =_xll.EQNXTDZ($A$1,$B10,BV$1,$B$1) -> 0
A11: Cost of Services & Raw Materials | B11: QTR_RAW_MATERIAL_COST | C11: =_xll.EQNXTDZ($A$1,$B11,C$1,$B$1) -> 0 | D11: =_xll.EQNXTDZ($A$1,$B11,D$1,$B$1) -> 0 | E11: =_xll.EQNXTDZ($A$1,$B11,E$1,$B$1) -> 0 | F11: =_xll.EQNXTDZ($A$1,$B11,F$1,$B$1) -> 0 | G11: =_xll.EQNXTDZ($A$1,$B11,G$1,$B$1) -> 0 | H11: =_xll.EQNXTDZ($A$1,$B11,H$1,$B$1) -> 0 | I11: =_xll.EQNXTDZ($A$1,$B11,I$1,$B$1) -> 0 | J11: =_xll.EQNXTDZ($A$1,$B11,J$1,$B$1) -> 0 | ... BV11: =_xll.EQNXTDZ($A$1,$B11,BV$1,$B$1) -> 0
A12: Purchase of Finished Goods | B12: QTR_PURCHASE_FIN_GOOD | C12: =_xll.EQNXTDZ($A$1,$B12,C$1,$B$1) -> 0 | D12: =_xll.EQNXTDZ($A$1,$B12,D$1,$B$1) -> 0 | E12: =_xll.EQNXTDZ($A$1,$B12,E$1,$B$1) -> 0 | F12: =_xll.EQNXTDZ($A$1,$B12,F$1,$B$1) -> 0 | G12: =_xll.EQNXTDZ($A$1,$B12,G$1,$B$1) -> 0 | H12: =_xll.EQNXTDZ($A$1,$B12,H$1,$B$1) -> 0 | I12: =_xll.EQNXTDZ($A$1,$B12,I$1,$B$1) -> 0 | J12: =_xll.EQNXTDZ($A$1,$B12,J$1,$B$1) -> 0 | ... BV12: =_xll.EQNXTDZ($A$1,$B12,BV$1,$B$1) -> 0
A13: Excise Duty | B13: QTR_EXCISE | C13: =_xll.EQNXTDZ($A$1,$B13,C$1,$B$1) -> 0 | D13: =_xll.EQNXTDZ($A$1,$B13,D$1,$B$1) -> 0 | E13: =_xll.EQNXTDZ($A$1,$B13,E$1,$B$1) -> 0 | F13: =_xll.EQNXTDZ($A$1,$B13,F$1,$B$1) -> 0 | G13: =_xll.EQNXTDZ($A$1,$B13,G$1,$B$1) -> 0 | H13: =_xll.EQNXTDZ($A$1,$B13,H$1,$B$1) -> 0 | I13: =_xll.EQNXTDZ($A$1,$B13,I$1,$B$1) -> 0 | J13: =_xll.EQNXTDZ($A$1,$B13,J$1,$B$1) -> 0 | ... BV13: =_xll.EQNXTDZ($A$1,$B13,BV$1,$B$1) -> 0
A14: Operating & Manufacturing Expenses | B14: QTR_MFG_EXPS | C14: =_xll.EQNXTDZ($A$1,$B14,C$1,$B$1) -> 0 | D14: =_xll.EQNXTDZ($A$1,$B14,D$1,$B$1) -> 0 | E14: =_xll.EQNXTDZ($A$1,$B14,E$1,$B$1) -> 0 | F14: =_xll.EQNXTDZ($A$1,$B14,F$1,$B$1) -> 0 | G14: =_xll.EQNXTDZ($A$1,$B14,G$1,$B$1) -> 0 | H14: =_xll.EQNXTDZ($A$1,$B14,H$1,$B$1) -> 0 | I14: =_xll.EQNXTDZ($A$1,$B14,I$1,$B$1) -> 0 | J14: =_xll.EQNXTDZ($A$1,$B14,J$1,$B$1) -> 0 | ... BV14: =_xll.EQNXTDZ($A$1,$B14,BV$1,$B$1) -> 0
A15: Electricity Power & Fuel Cost | B15: QTR_ELECTRICITY_POWER_FUEL | C15: =_xll.EQNXTDZ($A$1,$B15,C$1,$B$1) -> 0 | D15: =_xll.EQNXTDZ($A$1,$B15,D$1,$B$1) -> 0 | E15: =_xll.EQNXTDZ($A$1,$B15,E$1,$B$1) -> 0 | F15: =_xll.EQNXTDZ($A$1,$B15,F$1,$B$1) -> 0 | G15: =_xll.EQNXTDZ($A$1,$B15,G$1,$B$1) -> 0 | H15: =_xll.EQNXTDZ($A$1,$B15,H$1,$B$1) -> 0 | I15: =_xll.EQNXTDZ($A$1,$B15,I$1,$B$1) -> 0 | J15: =_xll.EQNXTDZ($A$1,$B15,J$1,$B$1) -> 0 | ... BV15: =_xll.EQNXTDZ($A$1,$B15,BV$1,$B$1) -> 0
A16: Employee Cost | B16: QTR_EXPLOYEE_COST | C16: =_xll.EQNXTDZ($A$1,$B16,C$1,$B$1) -> 0 | D16: =_xll.EQNXTDZ($A$1,$B16,D$1,$B$1) -> 0 | E16: =_xll.EQNXTDZ($A$1,$B16,E$1,$B$1) -> 0 | F16: =_xll.EQNXTDZ($A$1,$B16,F$1,$B$1) -> 0 | G16: =_xll.EQNXTDZ($A$1,$B16,G$1,$B$1) -> 0 | H16: =_xll.EQNXTDZ($A$1,$B16,H$1,$B$1) -> 0 | I16: =_xll.EQNXTDZ($A$1,$B16,I$1,$B$1) -> 0 | J16: =_xll.EQNXTDZ($A$1,$B16,J$1,$B$1) -> 0 | ... BV16: =_xll.EQNXTDZ($A$1,$B16,BV$1,$B$1) -> 0
... A42: Consolidated PAT(after extra items) | B42: QTR_CONS_PAT_EXITM | C42: =_xll.EQNXTDZ($A$1,$B42,C$1,$B$1) -> 0 | D42: =_xll.EQNXTDZ($A$1,$B42,D$1,$B$1) -> 0 | E42: =_xll.EQNXTDZ($A$1,$B42,E$1,$B$1) -> 0 | F42: =_xll.EQNXTDZ($A$1,$B42,F$1,$B$1) -> 0 | G42: =_xll.EQNXTDZ($A$1,$B42,G$1,$B$1) -> 0 | H42: =_xll.EQNXTDZ($A$1,$B42,H$1,$B$1) -> 0 | I42: =_xll.EQNXTDZ($A$1,$B42,I$1,$B$1) -> 0 | J42: =_xll.EQNXTDZ($A$1,$B42,J$1,$B$1) -> 0 | ... BV42: =_xll.EQNXTDZ($A$1,$B42,BV$1,$B$1) -> 0
A44: Field Description | B44: Field Name
A45: Equity Capital | B45: QTR_EQUITY_CAP | C45: =_xll.EQNXTDZ($A$1,$B45,C$1,$B$1) -> 0 | D45: =_xll.EQNXTDZ($A$1,$B45,D$1,$B$1) -> 0 | E45: =_xll.EQNXTDZ($A$1,$B45,E$1,$B$1) -> 0 | F45: =_xll.EQNXTDZ($A$1,$B45,F$1,$B$1) -> 0 | G45: =_xll.EQNXTDZ($A$1,$B45,G$1,$B$1) -> 0 | H45: =_xll.EQNXTDZ($A$1,$B45,H$1,$B$1) -> 0 | I45: =_xll.EQNXTDZ($A$1,$B45,I$1,$B$1) -> 0 | J45: =_xll.EQNXTDZ($A$1,$B45,J$1,$B$1) -> 0 | ... BV45: =_xll.EQNXTDZ($A$1,$B45,BV$1,$B$1) -> 0
A46: Face Value | B46: QTR_FV | C46: =_xll.EQNXTDZ($A$1,$B46,C$1,$B$1) -> 0 | D46: =_xll.EQNXTDZ($A$1,$B46,D$1,$B$1) -> 0 | E46: =_xll.EQNXTDZ($A$1,$B46,E$1,$B$1) -> 0 | F46: =_xll.EQNXTDZ($A$1,$B46,F$1,$B$1) -> 0 | G46: =_xll.EQNXTDZ($A$1,$B46,G$1,$B$1) -> 0 | H46: =_xll.EQNXTDZ($A$1,$B46,H$1,$B$1) -> 0 | I46: =_xll.EQNXTDZ($A$1,$B46,I$1,$B$1) -> 0 | J46: =_xll.EQNXTDZ($A$1,$B46,J$1,$B$1) -> 0 | ... BV46: =_xll.EQNXTDZ($A$1,$B46,BV$1,$B$1) -> 0
A47: Month End | B47: BMONTH_MONTHEND | C47: =_xll.EQNXTDZ($A$1,$B47,C$5) -> 0 | D47: =_xll.EQNXTDZ($A$1,$B47,D$5) -> 0 | E47: =_xll.EQNXTDZ($A$1,$B47,E$5) -> 0 | F47: =_xll.EQNXTDZ($A$1,$B47,F$5) -> 0 | G47: =_xll.EQNXTDZ($A$1,$B47,G$5) -> 0 | H47: =_xll.EQNXTDZ($A$1,$B47,H$5) -> 0 | I47: =_xll.EQNXTDZ($A$1,$B47,I$5) -> 0 | J47: =_xll.EQNXTDZ($A$1,$B47,J$5) -> 0 | ... BV47: =_xll.EQNXTDZ($A$1,$B47,BV$5) -> 0
A48: Close | B48: BMONTH_CLOSE | C48: =_xll.EQNXTDZ($A$1,$B48,C$5) -> 0 | D48: =_xll.EQNXTDZ($A$1,$B48,D$5) -> 0 | E48: =_xll.EQNXTDZ($A$1,$B48,E$5) -> 0 | F48: =_xll.EQNXTDZ($A$1,$B48,F$5) -> 0 | G48: =_xll.EQNXTDZ($A$1,$B48,G$5) -> 0 | H48: =_xll.EQNXTDZ($A$1,$B48,H$5) -> 0 | I48: =_xll.EQNXTDZ($A$1,$B48,I$5) -> 0 | J48: =_xll.EQNXTDZ($A$1,$B48,J$5) -> 0 | ... BV48: =_xll.EQNXTDZ($A$1,$B48,BV$5) -> 0
A49: Total of Promoter and Promoter Group | B49: SHP_TPFTOTALPROMOTER | C49: =_xll.EQNXTDZ($A$1,$B49,C$5) -> 0 | D49: =_xll.EQNXTDZ($A$1,$B49,D$5) -> 0 | E49: =_xll.EQNXTDZ($A$1,$B49,E$5) -> 0 | F49: =_xll.EQNXTDZ($A$1,$B49,F$5) -> 0 | G49: =_xll.EQNXTDZ($A$1,$B49,G$5) -> 0 | H49: =_xll.EQNXTDZ($A$1,$B49,H$5) -> 0 | I49: =_xll.EQNXTDZ($A$1,$B49,I$5) -> 0 | J49: =_xll.EQNXTDZ($A$1,$B49,J$5) -> 0 | ... BV49: =_xll.EQNXTDZ($A$1,$B49,BV$5) -> 0
A50: Total of Promoter and Promoter Group Pledged | B50: SHP_PSHFTOTALPROMOTER | C50: =_xll.EQNXTDZ($A$1,$B50,C$5) -> 0 | D50: =_xll.EQNXTDZ($A$1,$B50,D$5) -> 0 | E50: =_xll.EQNXTDZ($A$1,$B50,E$5) -> 0 | F50: =_xll.EQNXTDZ($A$1,$B50,F$5) -> 0 | G50: =_xll.EQNXTDZ($A$1,$B50,G$5) -> 0 | H50: =_xll.EQNXTDZ($A$1,$B50,H$5) -> 0 | I50: =_xll.EQNXTDZ($A$1,$B50,I$5) -> 0 | J50: =_xll.EQNXTDZ($A$1,$B50,J$5) -> 0 | ... BV50: =_xll.EQNXTDZ($A$1,$B50,BV$5) -> 0
A54: Field Description | B54: Field Name | C54: =_xll.EQNXTDZ($A$1,$B54,C$5) -> 0 | D54: =_xll.EQNXTDZ($A$1,$B54,D$5) -> 0 | E54: =_xll.EQNXTDZ($A$1,$B54,E$5) -> 0 | F54: =_xll.EQNXTDZ($A$1,$B54,F$5) -> 0 | G54: =_xll.EQNXTDZ($A$1,$B54,G$5) -> 0 | H54: =_xll.EQNXTDZ($A$1,$B54,H$5) -> 0 | I54: =_xll.EQNXTDZ($A$1,$B54,I$5) -> 0 | J54: =_xll.EQNXTDZ($A$1,$B54,J$5) -> 0 | ... BV54: =_xll.EQNXTDZ($A$1,$B54,BV$5) -> 0
A55: Year End | B55: QTRB_DATE_END | C55: =_xll.EQNXTDZ($A$1,$B55,C$5,$B$1) -> 0 | D55: =_xll.EQNXTDZ($A$1,$B55,D$5,$B$1) -> 0 | E55: =_xll.EQNXTDZ($A$1,$B55,E$5,$B$1) -> 0 | F55: =_xll.EQNXTDZ($A$1,$B55,F$5,$B$1) -> 0 | G55: =_xll.EQNXTDZ($A$1,$B55,G$5,$B$1) -> 0 | H55: =_xll.EQNXTDZ($A$1,$B55,H$5,$B$1) -> 0 | I55: =_xll.EQNXTDZ($A$1,$B55,I$5,$B$1) -> 0 | J55: =_xll.EQNXTDZ($A$1,$B55,J$5,$B$1) -> 0 | ... BV55: =_xll.EQNXTDZ($A$1,$B55,BV$5,$B$1) -> 0
A56: Share Capital | B56: QTRB_SHARE_CAPITAL | C56: =_xll.EQNXTDZ($A$1,$B56,C$5,$B$1) -> 0 | D56: =_xll.EQNXTDZ($A$1,$B56,D$5,$B$1) -> 0 | E56: =_xll.EQNXTDZ($A$1,$B56,E$5,$B$1) -> 0 | F56: =_xll.EQNXTDZ($A$1,$B56,F$5,$B$1) -> 0 | G56: =_xll.EQNXTDZ($A$1,$B56,G$5,$B$1) -> 0 | H56: =_xll.EQNXTDZ($A$1,$B56,H$5,$B$1) -> 0 | I56: =_xll.EQNXTDZ($A$1,$B56,I$5,$B$1) -> 0 | J56: =_xll.EQNXTDZ($A$1,$B56,J$5,$B$1) -> 0 | ... BV56: =_xll.EQNXTDZ($A$1,$B56,BV$5,$B$1) -> 0
A57: Share Warrants & outstandings | B57: QTRB_SHAREWARNDOUT | C57: =_xll.EQNXTDZ($A$1,$B57,C$5,$B$1) -> 0 | D57: =_xll.EQNXTDZ($A$1,$B57,D$5,$B$1) -> 0 | E57: =_xll.EQNXTDZ($A$1,$B57,E$5,$B$1) -> 0 | F57: =_xll.EQNXTDZ($A$1,$B57,F$5,$B$1) -> 0 | G57: =_xll.EQNXTDZ($A$1,$B57,G$5,$B$1) -> 0 | H57: =_xll.EQNXTDZ($A$1,$B57,H$5,$B$1) -> 0 | I57: =_xll.EQNXTDZ($A$1,$B57,I$5,$B$1) -> 0 | J57: =_xll.EQNXTDZ($A$1,$B57,J$5,$B$1) -> 0 | ... BV57: =_xll.EQNXTDZ($A$1,$B57,BV$5,$B$1) -> 0
A58: Reserves & Surplus | B58: QTRB_RESERVE | C58: =_xll.EQNXTDZ($A$1,$B58,C$5,$B$1) -> 0 | D58: =_xll.EQNXTDZ($A$1,$B58,D$5,$B$1) -> 0 | E58: =_xll.EQNXTDZ($A$1,$B58,E$5,$B$1) -> 0 | F58: =_xll.EQNXTDZ($A$1,$B58,F$5,$B$1) -> 0 | G58: =_xll.EQNXTDZ($A$1,$B58,G$5,$B$1) -> 0 | H58: =_xll.EQNXTDZ($A$1,$B58,H$5,$B$1) -> 0 | I58: =_xll.EQNXTDZ($A$1,$B58,I$5,$B$1) -> 0 | J58: =_xll.EQNXTDZ($A$1,$B58,J$5,$B$1) -> 0 | ... BV58: =_xll.EQNXTDZ($A$1,$B58,BV$5,$B$1) -> 0
A59: Shareholder's Funds | B59: QTRB_SHAREHODERS_FUNDS | C59: =_xll.EQNXTDZ($A$1,$B59,C$5,$B$1) -> 0 | D59: =_xll.EQNXTDZ($A$1,$B59,D$5,$B$1) -> 0 | E59: =_xll.EQNXTDZ($A$1,$B59,E$5,$B$1) -> 0 | F59: =_xll.EQNXTDZ($A$1,$B59,F$5,$B$1) -> 0 | G59: =_xll.EQNXTDZ($A$1,$B59,G$5,$B$1) -> 0 | H59: =_xll.EQNXTDZ($A$1,$B59,H$5,$B$1) -> 0 | I59: =_xll.EQNXTDZ($A$1,$B59,I$5,$B$1) -> 0 | J59: =_xll.EQNXTDZ($A$1,$B59,J$5,$B$1) -> 0 | ... BV59: =_xll.EQNXTDZ($A$1,$B59,BV$5,$B$1) -> 0
A60: Minority Interest | B60: QTRB_MINORITY_INTEREST_BS | C60: =_xll.EQNXTDZ($A$1,$B60,C$5,$B$1) -> 0 | D60: =_xll.EQNXTDZ($A$1,$B60,D$5,$B$1) -> 0 | E60: =_xll.EQNXTDZ($A$1,$B60,E$5,$B$1) -> 0 | F60: =_xll.EQNXTDZ($A$1,$B60,F$5,$B$1) -> 0 | G60: =_xll.EQNXTDZ($A$1,$B60,G$5,$B$1) -> 0 | H60: =_xll.EQNXTDZ($A$1,$B60,H$5,$B$1) -> 0 | I60: =_xll.EQNXTDZ($A$1,$B60,I$5,$B$1) -> 0 | J60: =_xll.EQNXTDZ($A$1,$B60,J$5,$B$1) -> 0 | ... BV60: =_xll.EQNXTDZ($A$1,$B60,BV$5,$B$1) -> 0
A61: Long Term Borrowings | B61: QTRB_TOTAL_DEBTS | C61: =_xll.EQNXTDZ($A$1,$B61,C$5,$B$1) -> 0 | D61: =_xll.EQNXTDZ($A$1,$B61,D$5,$B$1) -> 0 | E61: =_xll.EQNXTDZ($A$1,$B61,E$5,$B$1) -> 0 | F61: =_xll.EQNXTDZ($A$1,$B61,F$5,$B$1) -> 0 | G61: =_xll.EQNXTDZ($A$1,$B61,G$5,$B$1) -> 0 | H61: =_xll.EQNXTDZ($A$1,$B61,H$5,$B$1) -> 0 | I61: =_xll.EQNXTDZ($A$1,$B61,I$5,$B$1) -> 0 | J61: =_xll.EQNXTDZ($A$1,$B61,J$5,$B$1) -> 0 | ... BV61: =_xll.EQNXTDZ($A$1,$B61,BV$5,$B$1) -> 0
A62: Secured Loans | B62: QTRB_SECURED_LOANS | C62: =_xll.EQNXTDZ($A$1,$B62,C$5,$B$1) -> 0 | D62: =_xll.EQNXTDZ($A$1,$B62,D$5,$B$1) -> 0 | E62: =_xll.EQNXTDZ($A$1,$B62,E$5,$B$1) -> 0 | F62: =_xll.EQNXTDZ($A$1,$B62,F$5,$B$1) -> 0 | G62: =_xll.EQNXTDZ($A$1,$B62,G$5,$B$1) -> 0 | H62: =_xll.EQNXTDZ($A$1,$B62,H$5,$B$1) -> 0 | I62: =_xll.EQNXTDZ($A$1,$B62,I$5,$B$1) -> 0 | J62: =_xll.EQNXTDZ($A$1,$B62,J$5,$B$1) -> 0 | ... BV62: =_xll.EQNXTDZ($A$1,$B62,BV$5,$B$1) -> 0
A63: Unsecured Loans | B63: QTRB_UNSECURED_LOANS_NF | C63: =_xll.EQNXTDZ($A$1,$B63,C$5,$B$1) -> 0 | D63: =_xll.EQNXTDZ($A$1,$B63,D$5,$B$1) -> 0 | E63: =_xll.EQNXTDZ($A$1,$B63,E$5,$B$1) -> 0 | F63: =_xll.EQNXTDZ($A$1,$B63,F$5,$B$1) -> 0 | G63: =_xll.EQNXTDZ($A$1,$B63,G$5,$B$1) -> 0 | H63: =_xll.EQNXTDZ($A$1,$B63,H$5,$B$1) -> 0 | I63: =_xll.EQNXTDZ($A$1,$B63,I$5,$B$1) -> 0 | J63: =_xll.EQNXTDZ($A$1,$B63,J$5,$B$1) -> 0 | ... BV63: =_xll.EQNXTDZ($A$1,$B63,BV$5,$B$1) -> 0
A64: Other Long Term Liabilities | B64: QTRB_OTHER_LT_LIABILITIES | C64: =_xll.EQNXTDZ($A$1,$B64,C$5,$B$1) -> 0 | D64: =_xll.EQNXTDZ($A$1,$B64,D$5,$B$1) -> 0 | E64: =_xll.EQNXTDZ($A$1,$B64,E$5,$B$1) -> 0 | F64: =_xll.EQNXTDZ($A$1,$B64,F$5,$B$1) -> 0 | G64: =_xll.EQNXTDZ($A$1,$B64,G$5,$B$1) -> 0 | H64: =_xll.EQNXTDZ($A$1,$B64,H$5,$B$1) -> 0 | I64: =_xll.EQNXTDZ($A$1,$B64,I$5,$B$1) -> 0 | J64: =_xll.EQNXTDZ($A$1,$B64,J$5,$B$1) -> 0 | ... BV64: =_xll.EQNXTDZ($A$1,$B64,BV$5,$B$1) -> 0
A65: Long Term Trade Payables | B65: QTRB_LT_TRADE_PAYABLE | C65: =_xll.EQNXTDZ($A$1,$B65,C$5,$B$1) -> 0 | D65: =_xll.EQNXTDZ($A$1,$B65,D$5,$B$1) -> 0 | E65: =_xll.EQNXTDZ($A$1,$B65,E$5,$B$1) -> 0 | F65: =_xll.EQNXTDZ($A$1,$B65,F$5,$B$1) -> 0 | G65: =_xll.EQNXTDZ($A$1,$B65,G$5,$B$1) -> 0 | H65: =_xll.EQNXTDZ($A$1,$B65,H$5,$B$1) -> 0 | I65: =_xll.EQNXTDZ($A$1,$B65,I$5,$B$1) -> 0 | J65: =_xll.EQNXTDZ($A$1,$B65,J$5,$B$1) -> 0 | ... BV65: =_xll.EQNXTDZ($A$1,$B65,BV$5,$B$1) -> 0
A66: Lont Term Provisions | B66: QTRB_LT_PROVISIONS | C66: =_xll.EQNXTDZ($A$1,$B66,C$5,$B$1) -> 0 | D66: =_xll.EQNXTDZ($A$1,$B66,D$5,$B$1) -> 0 | E66: =_xll.EQNXTDZ($A$1,$B66,E$5,$B$1) -> 0 | F66: =_xll.EQNXTDZ($A$1,$B66,F$5,$B$1) -> 0 | G66: =_xll.EQNXTDZ($A$1,$B66,G$5,$B$1) -> 0 | H66: =_xll.EQNXTDZ($A$1,$B66,H$5,$B$1) -> 0 | I66: =_xll.EQNXTDZ($A$1,$B66,I$5,$B$1) -> 0 | J66: =_xll.EQNXTDZ($A$1,$B66,J$5,$B$1) -> 0 | ... BV66: =_xll.EQNXTDZ($A$1,$B66,BV$5,$B$1) -> 0
... A97: Total Assets | B97: QTRB_TOTAL_APPLICATIONS | C97: =_xll.EQNXTDZ($A$1,$B97,C$5,$B$1) -> 0 | D97: =_xll.EQNXTDZ($A$1,$B97,D$5,$B$1) -> 0 | E97: =_xll.EQNXTDZ($A$1,$B97,E$5,$B$1) -> 0 | F97: =_xll.EQNXTDZ($A$1,$B97,F$5,$B$1) -> 0 | G97: =_xll.EQNXTDZ($A$1,$B97,G$5,$B$1) -> 0 | H97: =_xll.EQNXTDZ($A$1,$B97,H$5,$B$1) -> 0 | I97: =_xll.EQNXTDZ($A$1,$B97,I$5,$B$1) -> 0 | J97: =_xll.EQNXTDZ($A$1,$B97,J$5,$B$1) -> 0 | ... BV97: =_xll.EQNXTDZ($A$1,$B97,BV$5,$B$1) -> 0

Sheet Annual Raw
A1: 293601 | B1: X | C1: 200103 | D1: 200203 | E1: 200303 | F1: 200403 | G1: 200503 | H1: 200603 | I1: 200703 | J1: 200803 | K1: 200903 | L1: 201003 | M1: 201103 | N1: 201203 | O1: 201303 | P1: 201403 | Q1: 201503 | R1: 201603 | S1: 201703 | T1: 201803 | U1: 201903 | V1: 202003 | W1: 202103 | X1: 202203 | Y1: 202303 | Z1: 202403 | AA1: 202503 | AB1: 202603 | AC1: 202703 | AD1: 202803 | AE1: 202903 | AF1: 203003
A3: Field Description | B3: Field Name
A4: Company Name | B4: CD_COMPNAME | C4: =_xll.EQNXTDZ(A1,B4,"L") -> Archean Chemical Industries Ltd.
A5: Year End | B5: PL_YEAR_END | C5: =_xll.EQNXTDZ($A$1,$B5,C$1,$B$1) -> 0 | D5: =_xll.EQNXTDZ($A$1,$B5,D$1,$B$1) -> 0 | E5: =_xll.EQNXTDZ($A$1,$B5,E$1,$B$1) -> 0 | F5: =_xll.EQNXTDZ($A$1,$B5,F$1,$B$1) -> 0 | G5: =_xll.EQNXTDZ($A$1,$B5,G$1,$B$1) -> 0 | H5: =_xll.EQNXTDZ($A$1,$B5,H$1,$B$1) -> 0 | I5: =_xll.EQNXTDZ($A$1,$B5,I$1,$B$1) -> 0 | J5: =_xll.EQNXTDZ($A$1,$B5,J$1,$B$1) -> 0 | ... AF5: =_xll.EQNXTDZ($A$1,$B5,AF$1,$B$1) -> 0
A6: Sales Turnover | B6: PL_TOTAL_GROSS_SALES | C6: =_xll.EQNXTDZ($A$1,$B6,C$1,$B$1) -> 0 | D6: =_xll.EQNXTDZ($A$1,$B6,D$1,$B$1) -> 0 | E6: =_xll.EQNXTDZ($A$1,$B6,E$1,$B$1) -> 0 | F6: =_xll.EQNXTDZ($A$1,$B6,F$1,$B$1) -> 0 | G6: =_xll.EQNXTDZ($A$1,$B6,G$1,$B$1) -> 0 | H6: =_xll.EQNXTDZ($A$1,$B6,H$1,$B$1) -> 0 | I6: =_xll.EQNXTDZ($A$1,$B6,I$1,$B$1) -> 0 | J6: =_xll.EQNXTDZ($A$1,$B6,J$1,$B$1) -> 0 | ... AF6: =_xll.EQNXTDZ($A$1,$B6,AF$1,$B$1) -> 0
A7: Less: Inter divisional transfers | B7: PL_INTER_DIV_TRF | C7: =_xll.EQNXTDZ($A$1,$B7,C$1,$B$1) -> 0 | D7: =_xll.EQNXTDZ($A$1,$B7,D$1,$B$1) -> 0 | E7: =_xll.EQNXTDZ($A$1,$B7,E$1,$B$1) -> 0 | F7: =_xll.EQNXTDZ($A$1,$B7,F$1,$B$1) -> 0 | G7: =_xll.EQNXTDZ($A$1,$B7,G$1,$B$1) -> 0 | H7: =_xll.EQNXTDZ($A$1,$B7,H$1,$B$1) -> 0 | I7: =_xll.EQNXTDZ($A$1,$B7,I$1,$B$1) -> 0 | J7: =_xll.EQNXTDZ($A$1,$B7,J$1,$B$1) -> 0 | ... AF7: =_xll.EQNXTDZ($A$1,$B7,AF$1,$B$1) -> 0
A8: Less: Sales Returns | B8: PL_SALES_RETURN | C8: =_xll.EQNXTDZ($A$1,$B8,C$1,$B$1) -> 0 | D8: =_xll.EQNXTDZ($A$1,$B8,D$1,$B$1) -> 0 | E8: =_xll.EQNXTDZ($A$1,$B8,E$1,$B$1) -> 0 | F8: =_xll.EQNXTDZ($A$1,$B8,F$1,$B$1) -> 0 | G8: =_xll.EQNXTDZ($A$1,$B8,G$1,$B$1) -> 0 | H8: =_xll.EQNXTDZ($A$1,$B8,H$1,$B$1) -> 0 | I8: =_xll.EQNXTDZ($A$1,$B8,I$1,$B$1) -> 0 | J8: =_xll.EQNXTDZ($A$1,$B8,J$1,$B$1) -> 0 | ... AF8: =_xll.EQNXTDZ($A$1,$B8,AF$1,$B$1) -> 0
A9: Less: Excise | B9: PL_EXCISE | C9: =_xll.EQNXTDZ($A$1,$B9,C$1,$B$1) -> 0 | D9: =_xll.EQNXTDZ($A$1,$B9,D$1,$B$1) -> 0 | E9: =_xll.EQNXTDZ($A$1,$B9,E$1,$B$1) -> 0 | F9: =_xll.EQNXTDZ($A$1,$B9,F$1,$B$1) -> 0 | G9: =_xll.EQNXTDZ($A$1,$B9,G$1,$B$1) -> 0 | H9: =_xll.EQNXTDZ($A$1,$B9,H$1,$B$1) -> 0 | I9: =_xll.EQNXTDZ($A$1,$B9,I$1,$B$1) -> 0 | J9: =_xll.EQNXTDZ($A$1,$B9,J$1,$B$1) -> 0 | ... AF9: =_xll.EQNXTDZ($A$1,$B9,AF$1,$B$1) -> 0
A10: Net Sales | B10: PL_NET_SALES | C10: =_xll.EQNXTDZ($A$1,$B10,C$1,$B$1) -> 0 | D10: =_xll.EQNXTDZ($A$1,$B10,D$1,$B$1) -> 0 | E10: =_xll.EQNXTDZ($A$1,$B10,E$1,$B$1) -> 0 | F10: =_xll.EQNXTDZ($A$1,$B10,F$1,$B$1) -> 0 | G10: =_xll.EQNXTDZ($A$1,$B10,G$1,$B$1) -> 0 | H10: =_xll.EQNXTDZ($A$1,$B10,H$1,$B$1) -> 0 | I10: =_xll.EQNXTDZ($A$1,$B10,I$1,$B$1) -> 0 | J10: =_xll.EQNXTDZ($A$1,$B10,J$1,$B$1) -> 0 | ... AF10: =_xll.EQNXTDZ($A$1,$B10,AF$1,$B$1) -> 0
A11: Increase/Decrease in Stock | B11: PL_INC_DEC_INVENTORY | C11: =_xll.EQNXTDZ($A$1,$B11,C$1,$B$1) -> 0 | D11: =_xll.EQNXTDZ($A$1,$B11,D$1,$B$1) -> 0 | E11: =_xll.EQNXTDZ($A$1,$B11,E$1,$B$1) -> 0 | F11: =_xll.EQNXTDZ($A$1,$B11,F$1,$B$1) -> 0 | G11: =_xll.EQNXTDZ($A$1,$B11,G$1,$B$1) -> 0 | H11: =_xll.EQNXTDZ($A$1,$B11,H$1,$B$1) -> 0 | I11: =_xll.EQNXTDZ($A$1,$B11,I$1,$B$1) -> 0 | J11: =_xll.EQNXTDZ($A$1,$B11,J$1,$B$1) -> 0 | ... AF11: =_xll.EQNXTDZ($A$1,$B11,AF$1,$B$1) -> 0
A12: Raw Material Consumed | B12: PL_RAW_MATRS_CONSUMED | C12: =_xll.EQNXTDZ($A$1,$B12,C$1,$B$1) -> 0 | D12: =_xll.EQNXTDZ($A$1,$B12,D$1,$B$1) -> 0 | E12: =_xll.EQNXTDZ($A$1,$B12,E$1,$B$1) -> 0 | F12: =_xll.EQNXTDZ($A$1,$B12,F$1,$B$1) -> 0 | G12: =_xll.EQNXTDZ($A$1,$B12,G$1,$B$1) -> 0 | H12: =_xll.EQNXTDZ($A$1,$B12,H$1,$B$1) -> 0 | I12: =_xll.EQNXTDZ($A$1,$B12,I$1,$B$1) -> 0 | J12: =_xll.EQNXTDZ($A$1,$B12,J$1,$B$1) -> 0 | ... AF12: =_xll.EQNXTDZ($A$1,$B12,AF$1,$B$1) -> 0
A13: Power & Fuel Cost | B13: PL_POWER_FUEL | C13: =_xll.EQNXTDZ($A$1,$B13,C$1,$B$1) -> 0 | D13: =_xll.EQNXTDZ($A$1,$B13,D$1,$B$1) -> 0 | E13: =_xll.EQNXTDZ($A$1,$B13,E$1,$B$1) -> 0 | F13: =_xll.EQNXTDZ($A$1,$B13,F$1,$B$1) -> 0 | G13: =_xll.EQNXTDZ($A$1,$B13,G$1,$B$1) -> 0 | H13: =_xll.EQNXTDZ($A$1,$B13,H$1,$B$1) -> 0 | I13: =_xll.EQNXTDZ($A$1,$B13,I$1,$B$1) -> 0 | J13: =_xll.EQNXTDZ($A$1,$B13,J$1,$B$1) -> 0 | ... AF13: =_xll.EQNXTDZ($A$1,$B13,AF$1,$B$1) -> 0
A14: Employee Cost | B14: PL_EMPLOYEES | C14: =_xll.EQNXTDZ($A$1,$B14,C$1,$B$1) -> 0 | D14: =_xll.EQNXTDZ($A$1,$B14,D$1,$B$1) -> 0 | E14: =_xll.EQNXTDZ($A$1,$B14,E$1,$B$1) -> 0 | F14: =_xll.EQNXTDZ($A$1,$B14,F$1,$B$1) -> 0 | G14: =_xll.EQNXTDZ($A$1,$B14,G$1,$B$1) -> 0 | H14: =_xll.EQNXTDZ($A$1,$B14,H$1,$B$1) -> 0 | I14: =_xll.EQNXTDZ($A$1,$B14,I$1,$B$1) -> 0 | J14: =_xll.EQNXTDZ($A$1,$B14,J$1,$B$1) -> 0 | ... AF14: =_xll.EQNXTDZ($A$1,$B14,AF$1,$B$1) -> 0
A15: Operating & Manufacturing Expenses | B15: PL_GEN_OTHER_MFG_EXPS | C15: =_xll.EQNXTDZ($A$1,$B15,C$1,$B$1) -> 0 | D15: =_xll.EQNXTDZ($A$1,$B15,D$1,$B$1) -> 0 | E15: =_xll.EQNXTDZ($A$1,$B15,E$1,$B$1) -> 0 | F15: =_xll.EQNXTDZ($A$1,$B15,F$1,$B$1) -> 0 | G15: =_xll.EQNXTDZ($A$1,$B15,G$1,$B$1) -> 0 | H15: =_xll.EQNXTDZ($A$1,$B15,H$1,$B$1) -> 0 | I15: =_xll.EQNXTDZ($A$1,$B15,I$1,$B$1) -> 0 | J15: =_xll.EQNXTDZ($A$1,$B15,J$1,$B$1) -> 0 | ... AF15: =_xll.EQNXTDZ($A$1,$B15,AF$1,$B$1) -> 0
A16: Cost of Software development | B16: PL_COST_SW | C16: =_xll.EQNXTDZ($A$1,$B16,C$1,$B$1) -> 0 | D16: =_xll.EQNXTDZ($A$1,$B16,D$1,$B$1) -> 0 | E16: =_xll.EQNXTDZ($A$1,$B16,E$1,$B$1) -> 0 | F16: =_xll.EQNXTDZ($A$1,$B16,F$1,$B$1) -> 0 | G16: =_xll.EQNXTDZ($A$1,$B16,G$1,$B$1) -> 0 | H16: =_xll.EQNXTDZ($A$1,$B16,H$1,$B$1) -> 0 | I16: =_xll.EQNXTDZ($A$1,$B16,I$1,$B$1) -> 0 | J16: =_xll.EQNXTDZ($A$1,$B16,J$1,$B$1) -> 0 | ... AF16: =_xll.EQNXTDZ($A$1,$B16,AF$1,$B$1) -> 0
... A36: Profit After Tax from Discontinued Operations | B36: PL_PAT_DIS_OP | C36: =_xll.EQNXTDZ($A$1,$B36,C$1,$B$1) -> 0 | D36: =_xll.EQNXTDZ($A$1,$B36,D$1,$B$1) -> 0 | E36: =_xll.EQNXTDZ($A$1,$B36,E$1,$B$1) -> 0 | F36: =_xll.EQNXTDZ($A$1,$B36,F$1,$B$1) -> 0 | G36: =_xll.EQNXTDZ($A$1,$B36,G$1,$B$1) -> 0 | H36: =_xll.EQNXTDZ($A$1,$B36,H$1,$B$1) -> 0 | I36: =_xll.EQNXTDZ($A$1,$B36,I$1,$B$1) -> 0 | J36: =_xll.EQNXTDZ($A$1,$B36,J$1,$B$1) -> 0 | ... AF36: =_xll.EQNXTDZ($A$1,$B36,AF$1,$B$1) -> 0
A39: Field Description | B39: Field Name
A40: Year End | B40: BS_YEAR_END | C40: =_xll.EQNXTDZ($A$1,$B40,C$1,$B$1) -> 0 | D40: =_xll.EQNXTDZ($A$1,$B40,D$1,$B$1) -> 0 | E40: =_xll.EQNXTDZ($A$1,$B40,E$1,$B$1) -> 0 | F40: =_xll.EQNXTDZ($A$1,$B40,F$1,$B$1) -> 0 | G40: =_xll.EQNXTDZ($A$1,$B40,G$1,$B$1) -> 0 | H40: =_xll.EQNXTDZ($A$1,$B40,H$1,$B$1) -> 0 | I40: =_xll.EQNXTDZ($A$1,$B40,I$1,$B$1) -> 0 | J40: =_xll.EQNXTDZ($A$1,$B40,J$1,$B$1) -> 0 | ... AF40: =_xll.EQNXTDZ($A$1,$B40,AF$1,$B$1) -> 0
A41: Share Capital | B41: BS_SHARE_CAPITAL | C41: =_xll.EQNXTDZ($A$1,$B41,C$1,$B$1) -> 0 | D41: =_xll.EQNXTDZ($A$1,$B41,D$1,$B$1) -> 0 | E41: =_xll.EQNXTDZ($A$1,$B41,E$1,$B$1) -> 0 | F41: =_xll.EQNXTDZ($A$1,$B41,F$1,$B$1) -> 0 | G41: =_xll.EQNXTDZ($A$1,$B41,G$1,$B$1) -> 0 | H41: =_xll.EQNXTDZ($A$1,$B41,H$1,$B$1) -> 0 | I41: =_xll.EQNXTDZ($A$1,$B41,I$1,$B$1) -> 0 | J41: =_xll.EQNXTDZ($A$1,$B41,J$1,$B$1) -> 0 | ... AF41: =_xll.EQNXTDZ($A$1,$B41,AF$1,$B$1) -> 0
A42: Share Warrants & Outstandings | B42: BS_SHAREWROUTST | C42: =_xll.EQNXTDZ($A$1,$B42,C$1,$B$1) -> 0 | D42: =_xll.EQNXTDZ($A$1,$B42,D$1,$B$1) -> 0 | E42: =_xll.EQNXTDZ($A$1,$B42,E$1,$B$1) -> 0 | F42: =_xll.EQNXTDZ($A$1,$B42,F$1,$B$1) -> 0 | G42: =_xll.EQNXTDZ($A$1,$B42,G$1,$B$1) -> 0 | H42: =_xll.EQNXTDZ($A$1,$B42,H$1,$B$1) -> 0 | I42: =_xll.EQNXTDZ($A$1,$B42,I$1,$B$1) -> 0 | J42: =_xll.EQNXTDZ($A$1,$B42,J$1,$B$1) -> 0 | ... AF42: =_xll.EQNXTDZ($A$1,$B42,AF$1,$B$1) -> 0
A43: Total Reserves | B43: BS_RESERVE | C43: =_xll.EQNXTDZ($A$1,$B43,C$1,$B$1) -> 0 | D43: =_xll.EQNXTDZ($A$1,$B43,D$1,$B$1) -> 0 | E43: =_xll.EQNXTDZ($A$1,$B43,E$1,$B$1) -> 0 | F43: =_xll.EQNXTDZ($A$1,$B43,F$1,$B$1) -> 0 | G43: =_xll.EQNXTDZ($A$1,$B43,G$1,$B$1) -> 0 | H43: =_xll.EQNXTDZ($A$1,$B43,H$1,$B$1) -> 0 | I43: =_xll.EQNXTDZ($A$1,$B43,I$1,$B$1) -> 0 | J43: =_xll.EQNXTDZ($A$1,$B43,J$1,$B$1) -> 0 | ... AF43: =_xll.EQNXTDZ($A$1,$B43,AF$1,$B$1) -> 0
A44: Shareholder's Funds | B44: BS_SHAREHODERS_FUNDS | C44: =_xll.EQNXTDZ($A$1,$B44,C$1,$B$1) -> 0 | D44: =_xll.EQNXTDZ($A$1,$B44,D$1,$B$1) -> 0 | E44: =_xll.EQNXTDZ($A$1,$B44,E$1,$B$1) -> 0 | F44: =_xll.EQNXTDZ($A$1,$B44,F$1,$B$1) -> 0 | G44: =_xll.EQNXTDZ($A$1,$B44,G$1,$B$1) -> 0 | H44: =_xll.EQNXTDZ($A$1,$B44,H$1,$B$1) -> 0 | I44: =_xll.EQNXTDZ($A$1,$B44,I$1,$B$1) -> 0 | J44: =_xll.EQNXTDZ($A$1,$B44,J$1,$B$1) -> 0 | ... AF44: =_xll.EQNXTDZ($A$1,$B44,AF$1,$B$1) -> 0
A45: Minority Interest | B45: BS_MINORITY_INTEREST | C45: =_xll.EQNXTDZ($A$1,$B45,C$1,$B$1) -> 0 | D45: =_xll.EQNXTDZ($A$1,$B45,D$1,$B$1) -> 0 | E45: =_xll.EQNXTDZ($A$1,$B45,E$1,$B$1) -> 0 | F45: =_xll.EQNXTDZ($A$1,$B45,F$1,$B$1) -> 0 | G45: =_xll.EQNXTDZ($A$1,$B45,G$1,$B$1) -> 0 | H45: =_xll.EQNXTDZ($A$1,$B45,H$1,$B$1) -> 0 | I45: =_xll.EQNXTDZ($A$1,$B45,I$1,$B$1) -> 0 | J45: =_xll.EQNXTDZ($A$1,$B45,J$1,$B$1) -> 0 | ... AF45: =_xll.EQNXTDZ($A$1,$B45,AF$1,$B$1) -> 0
A46: Long-Term Borrowings | B46: BS_LTRM_BORROWING | C46: =_xll.EQNXTDZ($A$1,$B46,C$1,$B$1) -> 0 | D46: =_xll.EQNXTDZ($A$1,$B46,D$1,$B$1) -> 0 | E46: =_xll.EQNXTDZ($A$1,$B46,E$1,$B$1) -> 0 | F46: =_xll.EQNXTDZ($A$1,$B46,F$1,$B$1) -> 0 | G46: =_xll.EQNXTDZ($A$1,$B46,G$1,$B$1) -> 0 | H46: =_xll.EQNXTDZ($A$1,$B46,H$1,$B$1) -> 0 | I46: =_xll.EQNXTDZ($A$1,$B46,I$1,$B$1) -> 0 | J46: =_xll.EQNXTDZ($A$1,$B46,J$1,$B$1) -> 0 | ... AF46: =_xll.EQNXTDZ($A$1,$B46,AF$1,$B$1) -> 0
