Workbook

Sheet Template
A1: =+'Annual Raw'!C4 -> Balaji Amines Ltd. | B1: 36951 | C1: =EOMONTH(B1,12) -> 37346 | D1: =EOMONTH(C1,12) -> 37711 | E1: =EOMONTH(D1,12) -> 38077 | F1: =EOMONTH(E1,12) -> 38442 | G1: =EOMONTH(F1,12) -> 38807 | H1: =EOMONTH(G1,12) -> 39172 | I1: =EOMONTH(H1,12) -> 39538 | J1: =EOMONTH(I1,12) -> 39903 | ... AE1: =EOMONTH(AD1,12) -> 47573 | AH1: QTR | AI1: 41061 | AJ1: 41153 | AK1: 41244 | AL1: 41334 | AM1: 41426 | AN1: 41518 | AO1: 41609 | AP1: 41699 | AQ1: 41791 | AR1: 41883 | AS1: 41974 | AT1: 42064 | AU1: 42156 | AV1: 42248 | AW1: 42339 | AX1: 42430 | AY1: 42522 | AZ1: 42614 | BA1: 42705 | BB1: 42795 | BC1: 42887 | BD1: 42979 | BE1: 43070 | BF1: 43160 | BG1: 43252 | BH1: 43344 | BI1: 43435 | BJ1: 43525 | BK1: 43617 | BL1: 43709 | BM1: 43800 | BN1: 43891 | BO1: 43983 | BP1: 44075 | BQ1: =EOMONTH(BP1,3) -> 44196 | BR1: =EOMONTH(BQ1,3) -> 44286 | BS1: =EOMONTH(BR1,3) -> 44377 | BT1: =EOMONTH(BS1,3) -> 44469 | BU1: =EOMONTH(BT1,3) -> 44561 | BV1: =EOMONTH(BU1,3) -> 44651 | BW1: =EOMONTH(BV1,3) -> 44742 | BX1: =EOMONTH(BW1,3) -> 44834 | ... DB1: =EOMONTH(DA1,3) -> 47573 | DE1: HISTORICAL ESTIMATES | DF1: 46112
A2: Presentation Data (Start)
A3: Aliphatic amine capacity | W3: 112500 | X3: 112500 | Y3: 112500 | Z3: =Y3+40000 -> 152500 | AA3: =Z3 -> 152500 | AB3: =+SUM(CM3:CP3) -> 152500 | AC3: =+SUM(CQ3:CT3) -> 152500 | AD3: =+SUM(CU3:CX3) -> 152500 | AE3: =+SUM(CY3:DB3) -> 152500 | BS3: =BT3 -> 28125 | BT3: =BU3 -> 28125 | BU3: =BV3 -> 28125 | BV3: =W3/4 -> 28125 | BW3: =BX3 -> 28125 | BX3: =BY3 -> 28125 | BY3: =BZ3 -> 28125 | BZ3: =X3/4 -> 28125 | CA3: =CB3 -> 28125 | CB3: =CC3 -> 28125 | CC3: =CD3 -> 28125 | CD3: =Y3/4 -> 28125 | CE3: =CF3 -> 38125 | CF3: =CG3 -> 38125 | CG3: =CH3 -> 38125 | CH3: =Z3/4 -> 38125 | CI3: =CJ3 -> 38125 | CJ3: =CK3 -> 38125 | CK3: =CL3 -> 38125 | CL3: =AA3/4 -> 38125 | CM3: =CL3 -> 38125 | CN3: =CM3 -> 38125 | CO3: =CN3 -> 38125 | CP3: =CO3 -> 38125 | CQ3: =CP3 -> 38125 | CR3: =CQ3 -> 38125 | CS3: =CR3 -> 38125 | CT3: =CS3 -> 38125 | ... DB3: =DA3 -> 38125
A4: Amine Derivative Cpacity | W4: 61100 | X4: 61100 | Y4: 69000 | Z4: 69000 | AA4: 76000 | AB4: =+SUM(CM4:CP4) -> 76000 | AC4: =+SUM(CQ4:CT4) -> 76000 | AD4: =+SUM(CU4:CX4) -> 76000 | AE4: =+SUM(CY4:DB4) -> 76000 | BS4: =BT4 -> 15275 | BT4: =BU4 -> 15275 | BU4: =BV4 -> 15275 | BV4: =W4/4 -> 15275 | BW4: =BX4 -> 15275 | BX4: =BY4 -> 15275 | BY4: =BZ4 -> 15275 | BZ4: =X4/4 -> 15275 | CA4: =CB4 -> 17250 | CB4: =CC4 -> 17250 | CC4: =CD4 -> 17250 | CD4: =Y4/4 -> 17250 | CE4: =CF4 -> 17250 | CF4: =CG4 -> 17250 | CG4: =CH4 -> 17250 | CH4: =Z4/4 -> 17250 | CI4: =CJ4 -> 19000 | CJ4: =CK4 -> 19000 | CK4: =CL4 -> 19000 | CL4: =AA4/4 -> 19000 | CM4: =CL4 -> 19000 | CN4: =CM4 -> 19000 | CO4: =CN4 -> 19000 | CP4: =CO4 -> 19000 | CQ4: =CP4 -> 19000 | CR4: =CQ4 -> 19000 | CS4: =CR4 -> 19000 | CT4: =CS4 -> 19000 | ... DB4: =DA4 -> 19000
A5: Speciality chemical Capacity | W5: 37500 | X5: =X6-X3-X4 -> 63600 | Y5: =Y6-Y3-Y4 -> 63600 | Z5: =Z6-Z3-Z4 -> 63600 | AA5: =AA6-AA3-AA4 -> 65100 | AB5: =+SUM(CM5:CP5) -> 176850 | AC5: =+SUM(CQ5:CT5) -> 194100 | AD5: =+SUM(CU5:CX5) -> 208100 | AE5: =+SUM(CY5:DB5) -> 208100 | BS5: =BT5 -> 9375 | BT5: =BU5 -> 9375 | BU5: =BV5 -> 9375 | BV5: =W5/4 -> 9375 | BW5: =BX5 -> 15900 | BX5: =BY5 -> 15900 | BY5: =BZ5 -> 15900 | BZ5: =X5/4 -> 15900 | CA5: =CB5 -> 15900 | CB5: =CC5 -> 15900 | CC5: =CD5 -> 15900 | CD5: =Y5/4 -> 15900 | CE5: =CF5 -> 15900 | CF5: =CG5 -> 15900 | CG5: =CH5 -> 15900 | CH5: =Z5/4 -> 15900 | CI5: =CJ5 -> 16275 | CJ5: =CK5 -> 16275 | CK5: =CL5 -> 16275 | CL5: =AA5/4 -> 16275 | CM5: =CM6-CM3-CM4 -> 41275 | CN5: =CN6-CN3-CN4 -> 43525 | CO5: =CO6-CO3-CO4 -> 43525 | CP5: =CP6-CP3-CP4 -> 48525 | CQ5: =CQ6-CQ3-CQ4 -> 48525 | CR5: =CR6-CR3-CR4 -> 48525 | CS5: =CS6-CS3-CS4 -> 48525 | CT5: =CT6-CT3-CT4 -> 48525 | ... DB5: =DB6-DB3-DB4 -> 52025
A6: Capacity | W6: 211100 | X6: 237200 | Y6: 245100 | Z6: 285100 | AA6: 293600 | AB6: =+SUM(CM6:CP6) -> 405350 | AC6: =+SUM(CQ6:CT6) -> 422600 | AD6: =+SUM(CU6:CX6) -> 436600 | AE6: =+SUM(CY6:DB6) -> 436600 | BS6: =BT6 -> 52775 | BT6: =BU6 -> 52775 | BU6: =BV6 -> 52775 | BV6: =W6/4 -> 52775 | BW6: =BX6 -> 59300 | BX6: =BY6 -> 59300 | BY6: =BZ6 -> 59300 | BZ6: =X6/4 -> 59300 | CA6: =CB6 -> 61275 | CB6: =CC6 -> 61275 | CC6: =CD6 -> 61275 | CD6: =Y6/4 -> 61275 | CE6: =CF6 -> 71275 | CF6: =CG6 -> 71275 | CG6: =CH6 -> 71275 | CH6: =Z6/4 -> 71275 | CI6: =CJ6 -> 73400 | CJ6: =CK6 -> 73400 | CK6: =CL6 -> 73400 | CL6: =AA6/4 -> 73400 | CM6: =CL6+25000 -> 98400 | CN6: =CM6+2250 -> 100650 | CO6: =CN6 -> 100650 | CP6: =CO6+5000 -> 105650 | CQ6: =CP6 -> 105650 | CR6: =CQ6 -> 105650 | CS6: =CR6 -> 105650 | CT6: =CS6 -> 105650 | CU6: =CT6+3500 -> 109150 | CV6: =CU6 -> 109150 | CW6: =CV6 -> 109150 | CX6: =CW6 -> 109150 | CY6: =CX6 -> 109150 | CZ6: =CY6 -> 109150 | DA6: =CZ6 -> 109150 | DB6: =DA6 -> 109150
A7: Utilisation | W7: =+W12/W6 -> 0.54641876 | X7: =+X12/X6 -> 0.46587268 | Y7: =+Y12/Y6 -> 0.44602203 | Z7: =+Z12/Z6 -> 0.3661417 | AA7: =+AA12/AA6 -> 0.36434264 | AB7: =+AB12/AB6 -> 0.31206646 | AC7: =+AC12/AC6 -> 0.39358856 | AD7: =+AD12/AD6 -> 0.4579656 | AE7: =+AE12/AE6 -> 0.55487631 | BS7: =BS12/BS6 -> 0.4168072 | BT7: =BT12/BT6 -> 0.44725722 | BU7: =BU12/BU6 -> 0.52276646 | BV7: =BV12/BV6 -> 0.64007579 | BW7: =BW12/BW6 -> 0.46134907 | BX7: =BX12/BX6 -> 0.48052277 | BY7: =BY12/BY6 -> 0.4746543 | BZ7: =BZ12/BZ6 -> 0.44696459 | ... DB7: =DB12/DB6 -> 0.58258961
BS8: =BS12-BS11-BS10-BS9 -> 0 | BT8: =BT12-BT11-BT10-BT9 -> 0 | BU8: =BU12-BU11-BU10-BU9 -> 0 | BV8: =BV12-BV11-BV10-BV9 -> 0 | BW8: =BW12-BW11-BW10-BW9 -> 0 | BX8: =BX12-BX11-BX10-BX9 -> 0 | BY8: =BY12-BY11-BY10-BY9 -> 0
A9: Amines | U9: =SUM(BK9:BN9) -> 18331 | V9: =SUM(BO9:BR9) -> 20049 | W9: =SUM(BS9:BV9) -> 24999 | X9: =SUM(BW9:BZ9) -> 25789 | Y9: =SUM(CA9:CD9) -> 31459 | Z9: =SUM(CE9:CH9) -> 30848 | AA9: =SUM(CI9:CL9) -> 29997 | AB9: =+SUM(CM9:CP9) -> 32096.79 | AC9: =+SUM(CQ9:CT9) -> 34343.565 | AD9: =+SUM(CU9:CX9) -> 36747.615 | AE9: =+SUM(CY9:DB9) -> 39319.948 | BK9: 4280 | BL9: 4631 | BM9: 4500 | BN9: 4920 | BO9: 4153 | BP9: 5094 | BQ9: 4952 | BR9: 5850 | BS9: 5394 | BT9: 5861 | BU9: 6460 | BV9: 7284 | BW9: 6736 | BX9: 6312 | BY9: 6082 | BZ9: 6659 | CA9: 6754 | CB9: 8092 | CC9: 7703 | CD9: 8910 | CE9: 7401 | CF9: 7616 | CG9: 7515 | CH9: 8316 | CI9: 7573 | CJ9: 7685 | CK9: 6993 | CL9: 7746 | CM9: =CI9*(1+CM17) -> 8103.11 | CN9: =CJ9*(1+CN17) -> 8222.95 | CO9: =CK9*(1+CO17) -> 7482.51 | CP9: =CL9*(1+CP17) -> 8288.22 | CQ9: =CM9*(1+CQ17) -> 8670.3277 | CR9: =CN9*(1+CR17) -> 8798.5565 | CS9: =CO9*(1+CS17) -> 8006.2857 | CT9: =CP9*(1+CT17) -> 8868.3954 | ... DB9: =CX9*(1+DB17) -> 10153.426 | DF9: 8800
A10: Amines Derivatives | U10: =SUM(BK10:BN10) -> 36024 | V10: =SUM(BO10:BR10) -> 39545 | W10: =SUM(BS10:BV10) -> 37171 | X10: =SUM(BW10:BZ10) -> 33091 | Y10: =SUM(CA10:CD10) -> 37480 | Z10: =SUM(CE10:CH10) -> 34182 | AA10: =SUM(CI10:CL10) -> 34640 | AB10: =+SUM(CM10:CP10) -> 38104 | AC10: =+SUM(CQ10:CT10) -> 41914.4 | AD10: =+SUM(CU10:CX10) -> 46105.84 | AE10: =+SUM(CY10:DB10) -> 50716.424 | BK10: 8500 | BL10: 9024 | BM10: 9060 | BN10: 9440 | BO10: 8277 | BP10: 9916 | BQ10: 10812 | BR10: 10540 | BS10: 9587 | BT10: 8261 | BU10: 9912 | BV10: 9411 | BW10: 8131 | BX10: 7766 | BY10: 8587 | BZ10: 8607 | CA10: 8288 | CB10: 10236 | CC10: 9280 | CD10: 9676 | CE10: 8299 | CF10: 8685 | CG10: 8809 | CH10: 8389 | CI10: 8108 | CJ10: 8374 | CK10: 9223 | CL10: 8935 | CM10: =CI10*(1+CM18) -> 8918.8 | CN10: =CJ10*(1+CN18) -> 9211.4 | CO10: =CK10*(1+CO18) -> 10145.3 | CP10: =CL10*(1+CP18) -> 9828.5 | CQ10: =CM10*(1+CQ18) -> 9810.68 | CR10: =CN10*(1+CR18) -> 10132.54 | CS10: =CO10*(1+CS18) -> 11159.83 | CT10: =CP10*(1+CT18) -> 10811.35 | ... DB10: =CX10*(1+DB18) -> 13081.734 | DF10: 9400
A11: Specialty Chemicals | U11: =SUM(BK11:BN11) -> 30476 | V11: =+V12-V9-V10 -> 46463 | W11: =+W12-W9-W10 -> 53179 | X11: =SUM(BW11:BZ11) -> 51625 | Y11: =SUM(CA11:CD11) -> 40381 | Z11: =SUM(CE11:CH11) -> 39357 | AA11: =SUM(CI11:CL11) -> 42334 | AB11: =+SUM(CM11:CP11) -> 56295.35 | AC11: =+SUM(CQ11:CT11) -> 90072.56 | AD11: =+SUM(CU11:CX11) -> 117094.33 | AE11: =+SUM(CY11:DB11) -> 152222.63 | BK11: 7370 | BL11: 7720 | BM11: 7600 | BN11: 7786 | BO11: 9824 | BP11: 8140 | BQ11: 12589 | BR11: 12157 | BS11: 7016 | BT11: 9482 | BU11: 11217 | BV11: 17085 | BW11: 12491 | BX11: 14417 | BY11: 13478 | BZ11: 11239 | CA11: 11778 | CB11: 9285 | CC11: 9920 | CD11: 9398 | CE11: 12371 | CF11: 10046 | CG11: 7773 | CH11: 9167 | CI11: 11889 | CJ11: 10107 | CK11: 9678 | CL11: 10660 | CM11: =CI11*(1+CM19) -> 13672.35 | CN11: =CJ11*(1+CN19) -> 14149.8 | CO11: =CK11*(1+CO19) -> 13549.2 | CP11: =CL11*(1+CP19) -> 14924 | CQ11: =CM11*(1+CQ19) -> 21875.76 | CR11: =CN11*(1+CR19) -> 22639.68 | CS11: =CO11*(1+CS19) -> 21678.72 | CT11: =CP11*(1+CT19) -> 23878.4 | ... DB11: =CX11*(1+DB19) -> 40354.496 | DF11: 12300
A12: Volume MT | T12: 79776 | U12: =U9+U10+U11 -> 84831 | V12: 106057 | W12: 115349 | X12: =X9+X10+X11 -> 110505 | Y12: =Y9+Y10+Y11 -> 109320 | Z12: =Z9+Z10+Z11 -> 104387 | AA12: =AA9+AA10+AA11 -> 106971 | AB12: =AB9+AB10+AB11 -> 126496.14 | AC12: =AC9+AC10+AC11 -> 166330.53 | AD12: =AD9+AD10+AD11 -> 199947.78 | AE12: =AE9+AE10+AE11 -> 242259 | BG12: 21678 | BH12: 17426 | BI12: 19128 | BJ12: 21543 | BK12: =BK9+BK10+BK11 -> 20150 | BL12: =BL9+BL10+BL11 -> 21375 | BM12: =BM9+BM10+BM11 -> 21160 | BN12: =BN9+BN10+BN11 -> 22146 | BO12: =BO9+BO10+BO11 -> 22254 | BP12: =BP9+BP10+BP11 -> 23150 | BQ12: =BQ9+BQ10+BQ11 -> 28353 | BR12: =BR9+BR10+BR11 -> 28547 | ... CB12: =CB9+CB10+CB11 -> 27613 | CC12: 26903 | CD12: 27975 | CE12: 28071 | CF12: 26348 | CG12: 24097 | CH12: =CH9+CH10+CH11 -> 25872 | CI12: =CI9+CI10+CI11 -> 27570 | CJ12: =CJ9+CJ10+CJ11 -> 26166 | CK12: =CK9+CK10+CK11 -> 25894 | CL12: =CL9+CL10+CL11 -> 27341 | CM12: =CM9+CM10+CM11 -> 30694.26 | CN12: =CN9+CN10+CN11 -> 31584.15 | CO12: =CO9+CO10+CO11 -> 31177.01 | ... DB12: =DB9+DB10+DB11 -> 63589.655 | DF12: 30500
A13: YOY% | V13: =V12/U12-1 -> 0.25021513 | W13: =W12/V12-1 -> 0.087613265 | X13: =X12/W12-1 -> -0.041994296 | Y13: =Y12/X12-1 -> -0.010723497 | Z13: =Z12/Y12-1 -> -0.045124405 | AA13: =AA12/Z12-1 -> 0.02475404 | AB13: =AB12/AA12-1 -> 0.18252741 | AC13: =AC12/AB12-1 -> 0.31490594 | ... AE13: =AE12/AD12-1 -> 0.21161133 | BK13: =BK12/BG12-1 -> -0.070486207 | BL13: =BL12/BH12-1 -> 0.2266154 | BM13: =BM12/BI12-1 -> 0.1062317 | BN13: =BN12/BJ12-1 -> 0.027990531 | BO13: =BO12/BK12-1 -> 0.10441687 | BP13: =BP12/BL12-1 -> 0.083040936 | BQ13: =BQ12/BM12-1 -> 0.33993384 | BR13: =BR12/BN12-1 -> 0.28903639 | ... DB13: =DB12/CX12-1 -> 0.21299701 | DF13: 0.17888064
A14: Subsidiary Volume | V14: =+V12-94687 -> 11370 | W14: =+W12-98179 -> 17170 | X14: =+X12-89231 -> 21274 | Y14: =+Y12-96596 -> 12724 | Z14: =+Z12-98086 -> 6301 | AA14: =+AA12-98622 -> 8349 | AB14: =+SUM(CM14:CP14) -> 9288 | AC14: =+SUM(CQ14:CT14) -> 15875 | AD14: =+SUM(CU14:CX14) -> 21500 | AE14: =+SUM(CY14:DB14) -> 26000 | CE14: =+CE12+CF12+CG12-74039 -> 4477 | CF14: =+CF12-25041 -> 1307 | CG14: =+CG12-23447 -> 650 | CH14: =+CH12-24047 -> 1825 | CI14: =+CI12+CJ12+CK12-73227 -> 6403 | CJ14: =+CJ12-24523 -> 1643 | CK14: =+CK12-23856 -> 2038 | CL14: =+CL12-25394 -> 1947 | CM14: =+CL14 -> 1947 | CN14: =+CM14 -> 1947 | CO14: =+CN14 -> 1947 | CP14: =+CO14+(3750*40%) -> 3447 | CQ14: =2000+(3750*40%) -> 3500 | CR14: =2000+(3750*50%) -> 3875 | CS14: =2000+(3750*60%) -> 4250 | CT14: =2000+(3750*60%) -> 4250 | CU14: =2000+(3750*80%) -> 5000 | CV14: =2000+(3750*80%) -> 5000 | CW14: =2000+(3750*80%) -> 5000 | CX14: =+CW14+1500 -> 6500 | CY14: =+CX14 -> 6500 | CZ14: =+CY14 -> 6500 | DA14: =+CZ14 -> 6500 | DB14: =+DA14 -> 6500
A16: Growth
A17: Amines vol growth | V17: =V9/U9-1 -> 0.093721019 | W17: =W9/V9-1 -> 0.24689511 | X17: =X9/W9-1 -> 0.031601264 | Y17: =Y9/X9-1 -> 0.21986118 | Z17: =Z9/Y9-1 -> -0.019422105 | AA17: =AA9/Z9-1 -> -0.027586878 | AB17: =AB9/AA9-1 -> 0.07 | AC17: =AC9/AB9-1 -> 0.07 | ... AE17: =AE9/AD9-1 -> 0.07 | BO17: =BO9/BK9-1 -> -0.029672897 | BP17: =BP9/BL9-1 -> 0.099978406 | BQ17: =BQ9/BM9-1 -> 0.10044444 | BR17: =BR9/BN9-1 -> 0.18902439 | BS17: =BS9/BO9-1 -> 0.29882013 | BT17: =BT9/BP9-1 -> 0.1505693 | BU17: =BU9/BQ9-1 -> 0.30452342 | BV17: =BV9/BR9-1 -> 0.24512821 | ... CL17: =CL9/CH9-1 -> -0.068542569 | CM17: 0.07 | CN17: 0.07 | CO17: 0.07 | CP17: 0.07 | CQ17: 0.07 | CR17: 0.07 | CS17: 0.07 | CT17: 0.07 | CU17: 0.07 | CV17: 0.07 | CW17: 0.07 | CX17: 0.07 | CY17: 0.07 | CZ17: 0.07 | DA17: 0.07 | DB17: 0.07
A18: Amines Derivatives vol growth | V18: =V10/U10-1 -> 0.097740395 | W18: =W10/V10-1 -> -0.060032874 | X18: =X10/W10-1 -> -0.10976299 | Y18: =Y10/X10-1 -> 0.13263425 | Z18: =Z10/Y10-1 -> -0.087993597 | AA18: =AA10/Z10-1 -> 0.013398865 | AB18: =AB10/AA10-1 -> 0.1 | AC18: =AC10/AB10-1 -> 0.1 | ... AE18: =AE10/AD10-1 -> 0.1 | BO18: =BO10/BK10-1 -> -0.026235294 | BP18: =BP10/BL10-1 -> 0.098847518 | BQ18: =BQ10/BM10-1 -> 0.19337748 | BR18: =BR10/BN10-1 -> 0.11652542 | BS18: =BS10/BO10-1 -> 0.1582699 | BT18: =BT10/BP10-1 -> -0.16690198 | BU18: =BU10/BQ10-1 -> -0.083240844 | BV18: =BV10/BR10-1 -> -0.10711575 | ... CL18: =CL10/CH10-1 -> 0.065085231 | CM18: 0.1 | CN18: 0.1 | CO18: 0.1 | CP18: 0.1 | CQ18: 0.1 | CR18: 0.1 | CS18: 0.1 | CT18: 0.1 | CU18: 0.1 | CV18: 0.1 | CW18: 0.1 | CX18: 0.1 | CY18: 0.1 | CZ18: 0.1 | DA18: 0.1 | DB18: 0.1
A19: Specialty Chemicals vol growth | V19: =V11/U11-1 -> 0.52457672 | W19: =W11/V11-1 -> 0.14454512 | X19: =X11/W11-1 -> -0.029222061 | Y19: =Y11/X11-1 -> -0.21780145 | Z19: =Z11/Y11-1 -> -0.025358461 | AA19: =AA11/Z11-1 -> 0.075640928 | AB19: =AB11/AA11-1 -> 0.32979048 | AC19: =AC11/AB11-1 -> 0.6 | ... AE19: =AE11/AD11-1 -> 0.3 | BO19: =BO11/BK11-1 -> 0.33297151 | BP19: =BP11/BL11-1 -> 0.054404145 | BQ19: =BQ11/BM11-1 -> 0.65644737 | BR19: =BR11/BN11-1 -> 0.56139224 | BS19: =BS11/BO11-1 -> -0.28583062 | BT19: =BT11/BP11-1 -> 0.16486486 | BU19: =BU11/BQ11-1 -> -0.10898403 | BV19: =BV11/BR11-1 -> 0.40536317 | ... CL19: =CL11/CH11-1 -> 0.1628668 | CM19: 0.15 | CN19: 0.4 | CO19: 0.4 | CP19: 0.4 | CQ19: 0.6 | CR19: 0.6 | CS19: 0.6 | CT19: 0.6 | CU19: 0.3 | CV19: 0.3 | CW19: 0.3 | CX19: 0.3 | CY19: 0.3 | CZ19: 0.3 | DA19: 0.3 | DB19: 0.3
A21: Realisation MT | T21: =T59*10^7/T12 -> 118212.4 | U21: =U59*10^7/U12 -> 110310.13 | V21: =V59*10^7/V12 -> 123655.69 | W21: =W59*10^7/W12 -> 201378.74 | X21: =X59*10^7/X12 -> 213148.33 | Y21: =Y59*10^7/Y12 -> 150156.7 | Z21: =Z59*10^7/Z12 -> 133837.01 | AA21: =AA59*10^7/AA12 -> 120737.84 | ... AE21: =AE59*10^7/AE12 -> 233154.08 | BG21: =BG59*10^7/BG12 -> 119885.14 | BH21: =BH59*10^7/BH12 -> 124148.4 | BI21: =BI59*10^7/BI12 -> 124850.48 | BJ21: =BJ59*10^7/BJ12 -> 105194.73 | BK21: =BK59*10^7/BK12 -> 110658.56 | BL21: =BL59*10^7/BL12 -> 106317.19 | BM21: =BM59*10^7/BM12 -> 107521.27 | BN21: =BN59*10^7/BN12 -> 116511.79 | ... CL21: =CL59*10^7/CL12 -> 144393.4 | CM21: =CI21+(CI21*CM22) -> 149471.22 | CN21: =CJ21+(CJ21*CN22) -> 149673.16 | CO21: =CK21+(CK21*CO22) -> 147136.85 | CP21: =CL21+(CL21*CP22) -> 166052.41 | CQ21: =CM21+(CM21*CQ22) -> 171891.9 | CR21: =CN21+(CN21*CR22) -> 172124.14 | CS21: =CO21+(CO21*CS22) -> 169207.37 | CT21: =CP21+(CP21*CT22) -> 190960.27 | ... DB21: =CX21+(CX21*DB22) -> 252544.96 | DF21: 144516
A22: YOY% | V22: =V21/U21-1 -> 0.12098217 | W22: =W21/V21-1 -> 0.62854411 | X22: =X21/W21-1 -> 0.058445051 | Y22: =Y21/X21-1 -> -0.29552956 | Z22: =Z21/Y21-1 -> -0.10868437 | AA22: =AA21/Z21-1 -> -0.097874085 | AB22: =AB21/AA21-1 -> 0.26950508 | AC22: =AC21/AB21-1 -> 0.15010046 | ... AE22: =AE21/AD21-1 -> 0.15004412 | BK22: =BK21/BG21-1 -> -0.076961802 | BL22: =BL21/BH21-1 -> -0.14362816 | BM22: =BM21/BI21-1 -> -0.13879974 | BN22: =BN21/BJ21-1 -> 0.107582 | BO22: =BO21/BK21-1 -> -0.094816872 | BP22: =BP21/BL21-1 -> 0.14732677 | BQ22: =BQ21/BM21-1 -> 0.2862736 | BR22: =BR21/BN21-1 -> 0.24481747 | ... CL22: =CL21/CH21-1 -> 0.05910109 | CM22: 0.15 | CN22: 0.15 | CO22: 0.15 | CP22: 0.15 | CQ22: 0.15 | CR22: 0.15 | CS22: 0.15 | CT22: 0.15 | CU22: 0.15 | CV22: 0.15 | CW22: 0.15 | CX22: 0.15 | CY22: 0.15 | CZ22: 0.15 | DA22: 0.15 | DB22: 0.15
A24: Unit Matrix per kg
A25: Sales | T25: =T21/1000 -> 118.2124 | U25: =U21/1000 -> 110.31013 | V25: =V21/1000 -> 123.65569 | W25: =W21/1000 -> 201.37874 | X25: =X21/1000 -> 213.14833 | Y25: =Y21/1000 -> 150.1567 | Z25: =Z21/1000 -> 133.83701 | AA25: =AA21/1000 -> 120.73784 | ... AE25: =AE21/1000 -> 233.15408 | BG25: =BG21/1000 -> 119.88514 | BH25: =BH21/1000 -> 124.1484 | BI25: =BI21/1000 -> 124.85048 | BJ25: =BJ21/1000 -> 105.19473 | BK25: =BK21/1000 -> 110.65856 | BL25: =BL21/1000 -> 106.31719 | BM25: =BM21/1000 -> 107.52127 | BN25: =BN21/1000 -> 116.51179 | ... DB25: =DB21/1000 -> 252.54496
A26: Raw Mat | T26: =T25-T27 -> 64.60046 | U26: =U25-U27 -> 60.571087 | V26: =V25-V27 -> 59.426167 | W26: =W25-W27 -> 105.98497 | X26: =X25-X27 -> 112.73594 | Y26: =Y25-Y27 -> 82.619704 | Z26: =Z25-Z27 -> 74.784523 | AA26: =AA25-AA27 -> 66.356648 | ... AE26: =AE25-AE27 -> 128.04362 | BG26: =BG25-BG27 -> 65.14946 | BH26: =BH25-BH27 -> 65.316768 | BI26: =BI25-BI27 -> 72.905688 | BJ26: =BJ25-BJ27 -> 56.097572 | BK26: =BK25-BK27 -> 64.626799 | BL26: =BL25-BL27 -> 58.277427 | BM26: =BM25-BM27 -> 57.562854 | BN26: =BN25-BN27 -> 61.968753 | ... DB26: =DB25-DB27 -> 138.68952
A27: GP | T27: =T65*10^7/T12/1000 -> 53.611944 | U27: =U65*10^7/U12/1000 -> 49.73904 | V27: =V65*10^7/V12/1000 -> 64.229518 | W27: =W65*10^7/W12/1000 -> 95.39377 | X27: =X65*10^7/X12/1000 -> 100.41239 | Y27: =Y65*10^7/Y12/1000 -> 67.536992 | Z27: =Z65*10^7/Z12/1000 -> 59.052487 | AA27: =AA65*10^7/AA12/1000 -> 54.381187 | ... AE27: =AE65*10^7/AE12/1000 -> 105.11046 | BG27: =BG65*10^7/BG12/1000 -> 54.735677 | BH27: =BH65*10^7/BH12/1000 -> 58.831631 | BI27: =BI65*10^7/BI12/1000 -> 51.944793 | BJ27: =BJ65*10^7/BJ12/1000 -> 49.097155 | BK27: =BK65*10^7/BK12/1000 -> 46.031762 | BL27: =BL65*10^7/BL12/1000 -> 48.039766 | BM27: =BM65*10^7/BM12/1000 -> 49.958412 | BN27: =BN65*10^7/BN12/1000 -> 54.543033 | ... DB27: =DB65*10^7/DB12/1000 -> 113.85544
A28: Other Cost | T28: =T27-T29 -> 29.600352 | U28: =U27-U29 -> 28.816871 | V28: =V27-V29 -> 29.537107 | W28: =W27-W29 -> 41.412496 | X28: =X27-X29 -> 45.291453 | Y28: =Y27-Y29 -> 37.923591 | Z28: =Z27-Z29 -> 36.813071 | AA28: =AA27-AA29 -> 31.266409 | ... AE28: =AE27-AE29 -> 55.167502 | BG28: =BG27-BG29 -> 27.670449 | BH28: =BH27-BH29 -> 33.127511 | BI28: =BI27-BI29 -> 29.677959 | BJ28: =BJ27-BJ29 -> 27.117393 | BK28: =BK27-BK29 -> 27.415385 | BL28: =BL27-BL29 -> 27.096608 | BM28: =BM27-BM29 -> 29.714083 | BN28: =BN27-BN29 -> 29.422469 | ... DB28: =DB27-DB29 -> 59.750727
A29: EBIDTA | T29: =T77*10^7/T12/1000 -> 24.011592 | U29: =U77*10^7/U12/1000 -> 20.922168 | V29: =V77*10^7/V12/1000 -> 34.692411 | W29: =W77*10^7/W12/1000 -> 53.981274 | X29: =X77*10^7/X12/1000 -> 55.120936 | Y29: =Y77*10^7/Y12/1000 -> 29.613401 | Z29: =Z77*10^7/Z12/1000 -> 22.239417 | AA29: =AA77*10^7/AA12/1000 -> 23.114779 | ... AE29: =AE77*10^7/AE12/1000 -> 49.942957 | BG29: =BG77*10^7/BG12/1000 -> 27.065227 | BH29: =BH77*10^7/BH12/1000 -> 25.70412 | BI29: =BI77*10^7/BI12/1000 -> 22.266834 | BJ29: =BJ77*10^7/BJ12/1000 -> 21.979761 | BK29: =BK77*10^7/BK12/1000 -> 18.616377 | BL29: =BL77*10^7/BL12/1000 -> 20.943158 | BM29: =BM77*10^7/BM12/1000 -> 20.244329 | BN29: =BN77*10^7/BN12/1000 -> 25.120564 | ... DB29: =DB77*10^7/DB12/1000 -> 54.104711
A32: Standalone Sales | T32: 949.83162 | U32: 919.0541 | V32: 1227.7795 | W32: 1920.6656 | X32: 1726.2831 | Y32: 1337.8444 | Z32: 1273.5923 | AA32: 1291 | CE32: 332.84 | CF32: 319.96 | CG32: 299.23 | CH32: 321.56 | CI32: 319.38 | CJ32: 309.2 | CK32: 301.2 | CL32: 361.77
A33: Standalone GP | T33: 427.63499 | U33: 407.88629 | V33: 605.0869 | W33: 847.6005 | X33: 721.1757 | Y33: 582.3397 | Z33: 567.2438 | AA33: =+AA32-726.56+16.76 -> 581.2 | CE33: 145.96 | CF33: 143.64 | CG33: 135.11 | CH33: 142.53 | CI33: 138.54 | CJ33: 132.67 | CK33: 133.04 | CL33: 171.62
A34: Standalone EBIDTA | T34: 191.55097 | U34: 175.85258 | V34: 321.9886 | W34: 440.9547 | X34: 329.6126 | Y34: 246.5493 | Z34: 226.4104 | AA34: 247.26 | CE34: 58.88 | CF34: 57.83 | CG34: 51.66 | CH34: 58.05 | CI34: 56.47 | CJ34: 50.01 | CK34: 54.7 | CL34: 86.08
A35: Standalone PAT | T35: 118.07628 | U35: 113.75306 | V35: 231.711 | W35: 307.941 | X35: 227.5422 | Y35: 171.3041 | Z35: 156.2127 | AA35: 165.53 | CE35: 40.52 | CF35: 40.4 | CG35: 35.69 | CH35: 39.6 | CI35: 39.8 | CJ35: 31.45 | CK35: 32.42 | CL35: 61.87
A36: Standalone GM | T36: =+T33/T32 -> 0.45022189 | U36: =+U33/U32 -> 0.44381096 | V36: =+V33/V32 -> 0.49283027 | W36: =+W33/W32 -> 0.44130561 | X36: =+X33/X32 -> 0.41776213 | Y36: =+Y33/Y32 -> 0.43528209 | Z36: =+Z33/Z32 -> 0.44538884 | AA36: =+AA33/AA32 -> 0.45019365 | CE36: =+CE33/CE32 -> 0.43852902 | CF36: =+CF33/CF32 -> 0.44893112 | CG36: =+CG33/CG32 -> 0.45152558 | CH36: =+CH33/CH32 -> 0.44324543 | CI36: =+CI33/CI32 -> 0.43377794 | CJ36: =+CJ33/CJ32 -> 0.42907503 | CK36: =+CK33/CK32 -> 0.44169987 | CL36: =+CL33/CL32 -> 0.47438981
A37: Standalone EBIDTA Margins | T37: =+T34/T32 -> 0.20166834 | U37: =+U34/U32 -> 0.19134084 | V37: =+V34/V32 -> 0.26225279 | W37: =+W34/W32 -> 0.22958432 | X37: =+X34/X32 -> 0.19093774 | Y37: =+Y34/Y32 -> 0.18428847 | Z37: =+Z34/Z32 -> 0.17777306 | AA37: =+AA34/AA32 -> 0.19152595 | CE37: =+CE34/CE32 -> 0.17690181 | CF37: =+CF34/CF32 -> 0.18074134 | CG37: =+CG34/CG32 -> 0.17264312 | CH37: =+CH34/CH32 -> 0.18052618 | CI37: =+CI34/CI32 -> 0.17681132 | CJ37: =+CJ34/CJ32 -> 0.16173997 | CK37: =+CK34/CK32 -> 0.18160691 | CL37: =+CL34/CL32 -> 0.23794123
A39: Subsidiary Sales | T39: =+T57-T32 -> -6.780348 | U39: =+U57-U32 -> 16.717735 | V39: =+V57-V32 -> 83.6756 | W39: =+W57-W32 -> 405.589 | X39: =+X57-X32 -> 633.152 | Y39: =+Y57-Y32 -> 304.6916 | Z39: =+Z57-Z32 -> 127.1083 | AA39: =+AA57-AA32 -> 3.111 | AB39: =+SUM(CM39:CP39) -> 222.396 | AC39: =+SUM(CQ39:CT39) -> 617.616 | AD39: =+SUM(CU39:CX39) -> 955.116 | AE39: =+SUM(CY39:DB39) -> 1225.116 | CE39: =+CE57-CE32 -> 51.906 | CF39: =+CF57-CF32 -> 26.923 | CG39: =+CG57-CG32 -> 13.498 | CH39: =+CH57-CH32 -> 31.168 | CI39: =+CI57-CI32 -> 38.961 | CJ39: =+CJ57-CJ32 -> 31.352 | CK39: =+CK57-CK32 -> 30.101 | CL39: =+CL57-CL32 -> 33.016 | CM39: =+(1947*170/10^4) -> 33.099 | CN39: =+(1947*170/10^4) -> 33.099 | CO39: =+(1947*170/10^4) -> 33.099 | CP39: =+(1947*170/10^4)+(CP14-1947)*600/10^4 -> 123.099 | CQ39: =+(1947*170/10^4)+(CQ14-1947)*600/10^4 -> 126.279 | CR39: =+(1947*170/10^4)+(CR14-1947)*600/10^4 -> 148.779 | CS39: =+(1947*170/10^4)+(CS14-1947)*600/10^4 -> 171.279 | CT39: =+(1947*170/10^4)+(CT14-1947)*600/10^4 -> 171.279 | CU39: =+(1947*170/10^4)+(CU14-1947)*600/10^4 -> 216.279 | CV39: =+(1947*170/10^4)+(CV14-1947)*600/10^4 -> 216.279 | CW39: =+(1947*170/10^4)+(CW14-1947)*600/10^4 -> 216.279 | ... DB39: =+(1947*170/10^4)+(DB14-1947)*600/10^4 -> 306.279
A40: Subsidiary GP | T40: =+T65-T33 -> 0.0596589 | U40: =+U65-U33 -> 14.05496 | V40: =+V65-V33 -> 76.1121 | W40: =+W65-W33 -> 252.7571 | X40: =+X65-X33 -> 388.4314 | Y40: =+Y65-Y33 -> 155.9747 | Z40: =+Z65-Z33 -> 49.1874 | AA40: =+AA65-AA33 -> 0.521 | AB40: =+SUM(CM40:CP40) -> 0 | AC40: =+SUM(CQ40:CT40) -> 0 | AD40: =+SUM(CU40:CX40) -> 0 | AE40: =+SUM(CY40:DB40) -> 0 | CE40: =+CE65-CE33 -> 21.741 | CF40: =+CF65-CF33 -> 15.234 | CG40: =+CG65-CG33 -> 0.021 | CH40: =+CH65-CH33 -> 12.194 | CI40: =+CI65-CI33 -> 7.789 | CJ40: =+CJ65-CJ33 -> 22.832 | CK40: =+CK65-CK33 -> 14.502 | CL40: =+CL65-CL33 -> 2.13
A41: Subsidiary EBIDTA | T41: =+T77-T34 -> 0.003908 | U41: =+U77-U34 -> 1.6322637 | V41: =+V77-V34 -> 45.9487 | W41: =+W77-W34 -> 181.7139 | X41: =+X77-X34 -> 279.5013 | Y41: =+Y77-Y34 -> 77.1844 | Z41: =+Z77-Z34 -> 5.7402 | AA41: =+AA77-AA34 -> 0.0011 | AB41: =+SUM(CM41:CP41) -> 48.92712 | AC41: =+SUM(CQ41:CT41) -> 135.87552 | AD41: =+SUM(CU41:CX41) -> 210.12552 | AE41: =+SUM(CY41:DB41) -> 269.52552 | CE41: =+CE77-CE34 -> 7.214 | CF41: =+CF77-CF34 -> 2.858 | CG41: =+CG77-CG34 -> -5.956 | CH41: =+CH77-CH34 -> 1.613 | CI41: =+CI77-CI34 -> -1.775 | CJ41: =+CJ77-CJ34 -> 9.804 | CK41: =+CK77-CK34 -> 1.975 | CL41: =+CL77-CL34 -> 8.169 | CM41: =+CM39*22% -> 7.28178 | CN41: =+CN39*22% -> 7.28178 | CO41: =+CO39*22% -> 7.28178 | CP41: =+CP39*22% -> 27.08178 | CQ41: =+CQ39*22% -> 27.78138 | CR41: =+CR39*22% -> 32.73138 | CS41: =+CS39*22% -> 37.68138 | CT41: =+CT39*22% -> 37.68138 | ... DB41: =+DB39*22% -> 67.38138
A42: Subsidiary Int Dep tax | CE42: =+CE41-CE43 -> 2.175 | CF42: =+CF41-CF43 -> 1.804 | CG42: =+CG41-CG43 -> -1.403 | CH42: =+CH41-CH43 -> 0.773 | CI42: =+CI41-CI43 -> 1.497 | CJ42: =+CJ41-CJ43 -> 4.152 | CK42: =+CK41-CK43 -> 3.637 | CL42: =+CL41-CL43 -> 5.271 | ... DB42: =+DB41-DB43 -> 30.6279
A43: Subsidiary PAT | T43: =+T90-T35 -> -0.9877521 | U43: =+U90-U35 -> -16.282793 | V43: =+V90-V35 -> 11.7846 | W43: =+W90-W35 -> 109.9597 | X43: =+X90-X35 -> 178.1408 | Y43: =+Y90-Y35 -> 60.9989 | Z43: =+Z90-Z35 -> 2.3787 | AA43: =+AA90-AA35 -> -0.0017 | AB43: =+SUM(CM43:CP43) -> 26.68752 | AC43: =+SUM(CQ43:CT43) -> 74.11392 | AD43: =+SUM(CU43:CX43) -> 114.61392 | AE43: =+SUM(CY43:DB43) -> 147.01392 | CE43: =+CE90-CE35 -> 5.039 | CF43: =+CF90-CF35 -> 1.054 | CG43: =+CG90-CG35 -> -4.553 | CH43: =+CH90-CH35 -> 0.84 | CI43: =+CI90-CI35 -> -3.272 | CJ43: =+CJ90-CJ35 -> 5.652 | CK43: =+CK90-CK35 -> -1.662 | CL43: =+CL90-CL35 -> 2.898 | CM43: =+CM39*12% -> 3.97188 | CN43: =+CN39*12% -> 3.97188 | CO43: =+CO39*12% -> 3.97188 | CP43: =+CP39*12% -> 14.77188 | CQ43: =+CQ39*12% -> 15.15348 | CR43: =+CR39*12% -> 17.85348 | CS43: =+CS39*12% -> 20.55348 | CT43: =+CT39*12% -> 20.55348 | ... DB43: =+DB39*12% -> 36.75348
A44: Minority Int | T44: =+T94 -> 0.4444885 | U44: =+U94 -> 7.3272567 | V44: =+V94 -> -5.3031 | W44: =+W94 -> -49.4819 | X44: =+X94 -> -80.163 | Y44: =+Y94 -> -27.4494 | Z44: =+Z94 -> -1.0704 | AA44: =+AA94 -> 0 | AB44: =+SUM(CM44:CP44) -> -12.009384 | AC44: =+SUM(CQ44:CT44) -> -33.351264 | AD44: =+SUM(CU44:CX44) -> -51.576264 | AE44: =+SUM(CY44:DB44) -> -66.156264 | CE44: =+CE94 -> -2.266 | CF44: =+CF94 -> -0.474 | CG44: =+CG94 -> 2.047 | CH44: =+CH94 -> -0.378 | CI44: =+CI94 -> 1.473 | CJ44: =+CJ94 -> -2.543 | CK44: =+CK94 -> 0.676 | CL44: =+CL94 -> -1.562 | CM44: =+CM43*CM45 -> -1.787346 | CN44: =+CN43*CN45 -> -1.787346 | CO44: =+CO43*CO45 -> -1.787346 | CP44: =+CP43*CP45 -> -6.647346 | CQ44: =+CQ43*CQ45 -> -6.819066 | CR44: =+CR43*CR45 -> -8.034066 | CS44: =+CS43*CS45 -> -9.249066 | CT44: =+CT43*CT45 -> -9.249066 | ... DB44: =+DB43*DB45 -> -16.539066
A45: Minority Int % | T45: =+T44/T43 -> -0.45000006 | U45: =+U44/U43 -> -0.45 | V45: =+V44/V43 -> -0.45000255 | W45: =+W44/W43 -> -0.45000032 | X45: =+X44/X43 -> -0.44999798 | Y45: =+Y44/Y43 -> -0.44999828 | Z45: =+Z44/Z43 -> -0.44999369 | AA45: =+AA44/AA43 -> 0 | ... AE45: =+AE44/AE43 -> -0.45 | CE45: =+CE44/CE43 -> -0.4496924 | CF45: =+CF44/CF43 -> -0.44971537 | CG45: =+CG44/CG43 -> -0.44959367 | CH45: =+CH44/CH43 -> -0.45 | CI45: =+CI44/CI43 -> -0.45018337 | CJ45: =+CJ44/CJ43 -> -0.44992923 | CK45: =+CK44/CK43 -> -0.40673887 | CL45: =+CL44/CL43 -> -0.53899241 | CM45: -0.45 | CN45: -0.45 | CO45: -0.45 | CP45: -0.45 | CQ45: -0.45 | CR45: -0.45 | CS45: -0.45 | CT45: -0.45 | CU45: -0.45 | CV45: -0.45 | CW45: -0.45 | CX45: -0.45 | CY45: -0.45 | CZ45: -0.45 | DA45: -0.45 | DB45: -0.45
A46: Subsidiary GM | T46: =+T40/T39 -> -0.0087987962 | U46: =+U40/U39 -> 0.84072158 | V46: =+V40/V39 -> 0.90960925 | W46: =+W40/W39 -> 0.62318529 | X46: =+X40/X39 -> 0.61348839 | Y46: =+Y40/Y39 -> 0.51191008 | Z46: =+Z40/Z39 -> 0.38697237 | AA46: =+AA40/AA39 -> 0.16747027 | ... AE46: =+AE40/AE39 -> 0 | CE46: =+CE40/CE39 -> 0.41885331 | CF46: =+CF40/CF39 -> 0.5658359 | CG46: =+CG40/CG39 -> 0.001555786 | CH46: =+CH40/CH39 -> 0.3912346 | CI46: =+CI40/CI39 -> 0.19991787 | CJ46: =+CJ40/CJ39 -> 0.728247 | CK46: =+CK40/CK39 -> 0.48177801 | CL46: =+CL40/CL39 -> 0.064514175
...

Sheet data
A1: Plant / Product | B1: Investment | C1: Estimated Annual Revenue Contribution
A2: HCN & Sodium Cyanide | B2: ₹750 Cr | C2: ₹1,100 – ₹1,500 Cr
A3: Methyl Amines (Unit IV) | B3: Part of prior CAPEX | C3: ₹300 – ₹400 Cr
A4: Dimethyl Ether (DME) | B4: Part of prior CAPEX | C4: ₹200 – ₹300 Cr
A5: Specialty Derivatives (NBPT/EDTA) | B5: Integrated | C5: ₹150 – ₹250 Cr
A9: Segments | B9: Amines | C9: Amine Derivatives | D9: Speciality Chemicals | G9: Spec Chem Products | I9: Application
A10: Products | B10: • Mono Methyl Amine (MMA) | C10: Di-Methyl Acetamide (DMAC) | D10: • Morpholine | G10: EDA (Ethyldiamine) | I10: Pesticides, Polymers
B11: • Di-Methyl Amine (DMA) | C11: • Di-Methyl Amine Hydrochloride (DMA HCL) | D11: • Acetonitrile | G11: Piprazine | I11: Pharma, Oilfield
B12: • Tri-Methyl Amine (TMA) | C12: • Tri-Methyl Amine Hydrochloride (TMA HCL) | D12: • Dimethylformamide (DMF) | G12: Diethyltriamine | I12: Coatings, Polymers, Pharma
B13: • Mono-Ethyl Amine (MEA) | C13: • Mono-Methyl Amine Hydrochloride (MMA HCL) | D13: • N-Ethyl-2-Pyrrolidone (NEP) | G13: Mixture of amines | I13: Multiple Industries
B14: • Di-Ethyl Amine (DEA) | C14: • Di-Ethyl Amine Hydrochloride (DEA HCL) | D14: • 2-Pyrrolidone (2-P)
B15: • Tri-Ethyl Amine (TEA) | C15: • Tri-Ethyl Amine Hydrochloride (TEA HCL) | D15: • Gamma Butyrolactone,
B16: • Di-Methyl Amino Ethanol (DMAE) | C16: • Mono-Ethyl Amine Hydrochloride (MEA HCL) | D16: • N-Methyl-Pyrrolidone (NMP)
B17: • Di-Ethyl Amino Ethanol (DEAE) | C17: • Di-Methyl Urea (DMU) | D17: • Pharmapure Povidone (PVP K30 & PVP K25)
C18: • Choline Chloride
A20: End User | B20: Pharma, Agro, Dyestuff intermediates, Agro, Rubber Chemicals, Rocket Fuel | C20: Pharma, Pesticides, Speciality Chem, Animal Poultry feed, Performance chem | D20: Water treatment chemicals, Solvents
A21: Clientele | B21: Jubilant Life science, Dr reddy, Aurobindo, Hetero | C21: Sun Pharma, Venkys, Kores, USV, Wanburry | D21: HP, IOC, Hikal, Mylan, Zydus
A23: 3. Key Raw Materials (The "Cost" Side) | G23: Reporting Segment | H23: FY22 | I23: FY23 | J23: FY24 | K23: FY25 | L23: FY26 (Current)
A24: Since raw materials make up 60-70% of their total cost, tracking these is non-negotiable for margin forecasting. | G24: Aliphatic Amines (Methyl & Ethyl) | H24: 112500 | I24: 112500 | J24: 112500 | K24: 152500 | L24: 152500
A25: Methanol: The single most important raw material for the Methyl Amines and DMF chain. | G25: Amine Derivatives (DMAHCL, etc.) | H25: 31000 | I25: 31000 | J25: 45000 | K25: 45000 | L25: 45000
A26: Note: Methanol prices are often correlated with global Natural Gas prices. | G26: Specialty Chemicals (DMC, Acetonitrile) | H26: 37500 | I26: 45330 | J26: 45330 | K26: 54330 | L26: 54330
A27: Ammonia: The critical nitrogen source for all amines. | G27: Total Nameplate Capacity (MTPA) | H27: 181000 | I27: 188830 | J27: 202830 | K27: 251830 | L27: 251830
A28: Note: Ammonia prices are highly volatile and linked to global Fertilizer demand.
A29: Ethyl Alcohol (Ethanol): The primary input for the Ethyl Amines chain.
A30: Note: In India, this is influenced by Government Sugar/Ethanol policies.

Sheet Concall
A2: DME - unit 4 expected to comission in 1QFY27. applcation in Aerosol and replacement of LPG
A3: N methyl morphine project - capacity of 5000 MT - commisiion in FY27
A4: Balaji speciality - 750 crs project - hydrogen cyanide, sodium cyanide, EDTA, and advanced chemical products
A5: at unit 1 - brownfield project of including DETA, Teta, PIP, AEEA and AEP during first half of FY27 | M5: Capacity - MT | O5: Price
A6: Unit 2 - greenfield in chincholi to mfg HCN, Nacn expected to commission in 4QFY27 | L6: DME | M6: 100000 | O6: 110 | P6: =M6*O6/10^4 -> 1100
A7: Current standalone capacity 293,000 MT. DMF and Methyl amines running at lower utilisatons | L7: NMM | M7: 5000 | O7: 250 | P7: =M7*O7/10^4 -> 125
A8: Expecting vol growth of 25 to 30% from current levels and EBIDTA margins to sustain at 22-23% | L8: Acetonitrile | M8: 9000 | O8: 220 | P8: =M8*O8/10^4 -> 198
A9: if current situation remians we will rach 3000 crs of sales | M9: =SUM(M6:M8) -> 114000 | P9: =SUM(P6:P8) -> 1423
A10: DME - aerosl industry uses 40,000 to 50,000 MT of gases other industry who will use this are baking, bukb and ceramic industry
A11: EDA- 280 to 300 prices currently it also reached 400
A12: Ammoia and methanol - prices are up but availability is not the issue
A13: In DME transport permission is still left which will take 1 months time. After that being a new product can have teething issues. FY27 - 30% utilisation, FY 28 60-80%. Conservative price of 80 rs with 80% utilisation. Have reached to all potential customers bcoz its a gas, have ordered 100 cyclinders of 500 kg each once thos trials are successful we will receive permision
A14: Capex: balaji speciality - total 750 crs of capex - in first phase will spend 350 -400 crs already spent 110 crs rest 280 crs will be spent in this year.
A15: Vol growth for FY27 - 10-15% vol growth on consol basis
A16: Battery chemical product currently offtake has not happened due to mfg pushing their timeline. Its running at 22-25% utilisation and giving to pharma and agrochem
A21: Capacity | N21: 2000 | P21: 1000
A22: Unit 1 | B22: Per Day - MT | C22: MT Pa
A23: EDA | B23: 82 | C23: =+B23*365 -> 29930 | E23: 150 | F23: =+C23*E23/10^4 -> 448.95
A24: Tetra | B24: 10 | C24: =+B24*365 -> 3650
A25: pipra | B25: 10 | C25: =+B25*365 -> 3650 | H25: =1500*13% -> 195
H26: =+H25/2 -> 97.5
A28: Unit 3
A29: MA | B29: 100 | C29: =+B29*365 -> 36500 | E29: 400 | F29: =+C29*E29/10^4*50% -> 730
A30: NMP | B30: 50 | C30: =+B30*365 -> 18250 | F30: =+C30*E30/10^4 -> 0
A31: GBL | B31: 15 | C31: =+B31*365 -> 5475 | F31: =+C31*E31/10^4 -> 0
A32: PVPK 30 | B32: 3 | C32: =+B32*365 -> 1095 | F32: =+C32*E32/10^4 -> 0
A33: DMF | B33: 100 | C33: =+B33*365 -> 36500 | E33: 90 | F33: =+C33*E33/10^4 -> 328.5
A34: DMA HCL | B34: 70 | C34: =+B34*365 -> 25550 | F34: =+C34*E34/10^4 -> 0
A35: ACN | B35: 50 | C35: =+B35*365 -> 18250 | E35: 220 | F35: =+C35*E35/10^4 -> 401.5
A37: Unit 4
A38: DMC | B38: 50 | C38: =+B38*365 -> 18250
A39: MA | B39: 200 | C39: =+B39*365 -> 73000 | E39: 400 | F39: =+C39*E39/10^4*50% -> 1460
A40: N Butyl Amine | B40: 40 | C40: =+B40*365 -> 14600 | F40: =+C40*E40/10^4 -> 0
A41: Ethyl Amine | B41: 130 | C41: =+B41*365 -> 47450 | E41: 80 | F41: =+C41*E41/10^4 -> 379.6
A42: DME | B42: 275 | C42: =+B42*365 -> 100375 | E42: 100 | F42: =+C42*E42/10^4 -> 1003.75
F43: =+C43*E43/10^4 -> 0
A44: Unit 4 New | F44: =+C44*E44/10^4 -> 0
A45: Sodium cyanide | B45: 28 | C45: =+B45*365 -> 10220 | E45: 600 | F45: =+C45*E45/10^4 -> 613.2
A46: EDTA | B46: 14 | C46: =+B46*365 -> 5110 | E46: 600 | F46: =+C46*E46/10^4 -> 306.6
F48: =SUM(F23:F47) -> 5672.1
...

Sheet QTR Raw
A1: ='Annual Raw'!A1 -> 130999 | B1: X | C1: 201206 | D1: 201209 | E1: 201212 | F1: 201303 | G1: 201306 | H1: 201309 | I1: 201312 | J1: 201403 | K1: 201406 | L1: 201409 | M1: 201412 | N1: 201503 | O1: 201506 | P1: 201509 | Q1: 201512 | R1: 201603 | S1: 201606 | T1: 201609 | U1: 201612 | V1: 201703 | W1: 201706 | X1: 201709 | Y1: 201712 | Z1: 201803 | AA1: 201806 | AB1: 201809 | AC1: 201812 | AD1: 201903 | AE1: 201906 | AF1: 201909 | AG1: 201912 | AH1: 202003 | AI1: 202006 | AJ1: 202009 | AK1: 202012 | AL1: 202103 | AM1: 202106 | AN1: 202109 | AO1: 202112 | AP1: 202203 | AQ1: 202206 | AR1: 202209 | AS1: 202212 | AT1: 202303 | AU1: 202306 | AV1: 202309 | AW1: 202312 | AX1: 202403 | AY1: 202406 | AZ1: 202409 | BA1: 202412 | BB1: 202503 | BC1: 202506 | BD1: 202509 | BE1: 202512 | BF1: 202603 | BG1: 202606 | BH1: 202609 | BI1: 202612 | BJ1: 202703 | BK1: 202706 | BL1: 202709 | BM1: 202712 | BN1: 202803 | BO1: 202806 | BP1: 202809 | BQ1: 202812 | BR1: 202903 | BS1: 202906 | BT1: 202909 | BU1: 202912 | BV1: 203003
A3: Field Description | B3: Field Name
A4: Company Name | B4: CD_COMPNAME | C4: =_xll.EQNXTDZ(A1,B4,C1) -> Balaji Amines Ltd.
A5: Date End | B5: QTR_DATE_END | C5: =_xll.EQNXTDZ($A$1,$B5,C$1,$B$1) -> 201206 | D5: =_xll.EQNXTDZ($A$1,$B5,D$1,$B$1) -> 201209 | E5: =_xll.EQNXTDZ($A$1,$B5,E$1,$B$1) -> 201212 | F5: =_xll.EQNXTDZ($A$1,$B5,F$1,$B$1) -> 201303 | G5: =_xll.EQNXTDZ($A$1,$B5,G$1,$B$1) -> 201306 | H5: =_xll.EQNXTDZ($A$1,$B5,H$1,$B$1) -> 201309 | I5: =_xll.EQNXTDZ($A$1,$B5,I$1,$B$1) -> 201312 | J5: =_xll.EQNXTDZ($A$1,$B5,J$1,$B$1) -> 201403 | ... BV5: =_xll.EQNXTDZ($A$1,$B5,BV$1,$B$1) -> 0
A6: Gross Sales | B6: QTR_GROSS_SALE | C6: =_xll.EQNXTDZ($A$1,$B6,C$1,$B$1) -> 136.559 | D6: =_xll.EQNXTDZ($A$1,$B6,D$1,$B$1) -> 126.011 | E6: =_xll.EQNXTDZ($A$1,$B6,E$1,$B$1) -> 107.746 | F6: =_xll.EQNXTDZ($A$1,$B6,F$1,$B$1) -> 141.48 | G6: =_xll.EQNXTDZ($A$1,$B6,G$1,$B$1) -> 140.1 | H6: =_xll.EQNXTDZ($A$1,$B6,H$1,$B$1) -> 161.014 | I6: =_xll.EQNXTDZ($A$1,$B6,I$1,$B$1) -> 137.51 | J6: =_xll.EQNXTDZ($A$1,$B6,J$1,$B$1) -> 171.5 | ... BV6: =_xll.EQNXTDZ($A$1,$B6,BV$1,$B$1) -> 0
A7: Less: Excise Duty | B7: QTR_EXCISE_DUTY | C7: =_xll.EQNXTDZ($A$1,$B7,C$1,$B$1) -> 0 | D7: =_xll.EQNXTDZ($A$1,$B7,D$1,$B$1) -> 0 | E7: =_xll.EQNXTDZ($A$1,$B7,E$1,$B$1) -> 0 | F7: =_xll.EQNXTDZ($A$1,$B7,F$1,$B$1) -> 0 | G7: =_xll.EQNXTDZ($A$1,$B7,G$1,$B$1) -> 0 | H7: =_xll.EQNXTDZ($A$1,$B7,H$1,$B$1) -> 0 | I7: =_xll.EQNXTDZ($A$1,$B7,I$1,$B$1) -> 0 | J7: =_xll.EQNXTDZ($A$1,$B7,J$1,$B$1) -> 0 | ... BV7: =_xll.EQNXTDZ($A$1,$B7,BV$1,$B$1) -> 0
A8: Other operating income | B8: QTR_JOB_WORKS | C8: =_xll.EQNXTDZ($A$1,$B8,C$1,$B$1) -> 0 | D8: =_xll.EQNXTDZ($A$1,$B8,D$1,$B$1) -> 0 | E8: =_xll.EQNXTDZ($A$1,$B8,E$1,$B$1) -> 0 | F8: =_xll.EQNXTDZ($A$1,$B8,F$1,$B$1) -> 0 | G8: =_xll.EQNXTDZ($A$1,$B8,G$1,$B$1) -> 0 | H8: =_xll.EQNXTDZ($A$1,$B8,H$1,$B$1) -> 0 | I8: =_xll.EQNXTDZ($A$1,$B8,I$1,$B$1) -> 0 | J8: =_xll.EQNXTDZ($A$1,$B8,J$1,$B$1) -> 0 | ... BV8: =_xll.EQNXTDZ($A$1,$B8,BV$1,$B$1) -> 0
A9: Net Sales & Other Operating Income | B9: QTR_NET_SALES | C9: =_xll.EQNXTDZ($A$1,$B9,C$1,$B$1) -> 136.559 | D9: =_xll.EQNXTDZ($A$1,$B9,D$1,$B$1) -> 126.011 | E9: =_xll.EQNXTDZ($A$1,$B9,E$1,$B$1) -> 107.746 | F9: =_xll.EQNXTDZ($A$1,$B9,F$1,$B$1) -> 141.48 | G9: =_xll.EQNXTDZ($A$1,$B9,G$1,$B$1) -> 140.1 | H9: =_xll.EQNXTDZ($A$1,$B9,H$1,$B$1) -> 161.014 | I9: =_xll.EQNXTDZ($A$1,$B9,I$1,$B$1) -> 137.51 | J9: =_xll.EQNXTDZ($A$1,$B9,J$1,$B$1) -> 171.5 | ... BV9: =_xll.EQNXTDZ($A$1,$B9,BV$1,$B$1) -> 0
A10: (Increase) / Decrease In Stocks | B10: QTR_INC_DEC_INVENTORY | C10: =_xll.EQNXTDZ($A$1,$B10,C$1,$B$1) -> 9.242 | D10: =_xll.EQNXTDZ($A$1,$B10,D$1,$B$1) -> -4.729 | E10: =_xll.EQNXTDZ($A$1,$B10,E$1,$B$1) -> 5.027 | F10: =_xll.EQNXTDZ($A$1,$B10,F$1,$B$1) -> 15.49 | G10: =_xll.EQNXTDZ($A$1,$B10,G$1,$B$1) -> 2.69 | H10: =_xll.EQNXTDZ($A$1,$B10,H$1,$B$1) -> -15.333 | I10: =_xll.EQNXTDZ($A$1,$B10,I$1,$B$1) -> -14.51 | J10: =_xll.EQNXTDZ($A$1,$B10,J$1,$B$1) -> 4.7 | ... BV10: =_xll.EQNXTDZ($A$1,$B10,BV$1,$B$1) -> 0
A11: Cost of Services & Raw Materials | B11: QTR_RAW_MATERIAL_COST | C11: =_xll.EQNXTDZ($A$1,$B11,C$1,$B$1) -> 74.989 | D11: =_xll.EQNXTDZ($A$1,$B11,D$1,$B$1) -> 78.647 | E11: =_xll.EQNXTDZ($A$1,$B11,E$1,$B$1) -> 60.731 | F11: =_xll.EQNXTDZ($A$1,$B11,F$1,$B$1) -> 72.8 | G11: =_xll.EQNXTDZ($A$1,$B11,G$1,$B$1) -> 87.46 | H11: =_xll.EQNXTDZ($A$1,$B11,H$1,$B$1) -> 111.359 | I11: =_xll.EQNXTDZ($A$1,$B11,I$1,$B$1) -> 100.15 | J11: =_xll.EQNXTDZ($A$1,$B11,J$1,$B$1) -> 104.45 | ... BV11: =_xll.EQNXTDZ($A$1,$B11,BV$1,$B$1) -> 0
A12: Purchase of Finished Goods | B12: QTR_PURCHASE_FIN_GOOD | C12: =_xll.EQNXTDZ($A$1,$B12,C$1,$B$1) -> 0 | D12: =_xll.EQNXTDZ($A$1,$B12,D$1,$B$1) -> 0 | E12: =_xll.EQNXTDZ($A$1,$B12,E$1,$B$1) -> 0 | F12: =_xll.EQNXTDZ($A$1,$B12,F$1,$B$1) -> 0 | G12: =_xll.EQNXTDZ($A$1,$B12,G$1,$B$1) -> 0 | H12: =_xll.EQNXTDZ($A$1,$B12,H$1,$B$1) -> 0 | I12: =_xll.EQNXTDZ($A$1,$B12,I$1,$B$1) -> 0 | J12: =_xll.EQNXTDZ($A$1,$B12,J$1,$B$1) -> 0 | ... BV12: =_xll.EQNXTDZ($A$1,$B12,BV$1,$B$1) -> 0
A13: Excise Duty | B13: QTR_EXCISE | C13: =_xll.EQNXTDZ($A$1,$B13,C$1,$B$1) -> 0 | D13: =_xll.EQNXTDZ($A$1,$B13,D$1,$B$1) -> 0 | E13: =_xll.EQNXTDZ($A$1,$B13,E$1,$B$1) -> 0 | F13: =_xll.EQNXTDZ($A$1,$B13,F$1,$B$1) -> 0 | G13: =_xll.EQNXTDZ($A$1,$B13,G$1,$B$1) -> 0 | H13: =_xll.EQNXTDZ($A$1,$B13,H$1,$B$1) -> 0 | I13: =_xll.EQNXTDZ($A$1,$B13,I$1,$B$1) -> 0 | J13: =_xll.EQNXTDZ($A$1,$B13,J$1,$B$1) -> 0 | ... BV13: =_xll.EQNXTDZ($A$1,$B13,BV$1,$B$1) -> 0
A14: Operating & Manufacturing Expenses | B14: QTR_MFG_EXPS | C14: =_xll.EQNXTDZ($A$1,$B14,C$1,$B$1) -> 24.746 | D14: =_xll.EQNXTDZ($A$1,$B14,D$1,$B$1) -> 24.727 | E14: =_xll.EQNXTDZ($A$1,$B14,E$1,$B$1) -> 20.889 | F14: =_xll.EQNXTDZ($A$1,$B14,F$1,$B$1) -> 31.01 | G14: =_xll.EQNXTDZ($A$1,$B14,G$1,$B$1) -> 22.73 | H14: =_xll.EQNXTDZ($A$1,$B14,H$1,$B$1) -> 32.531 | I14: =_xll.EQNXTDZ($A$1,$B14,I$1,$B$1) -> 27.14 | J14: =_xll.EQNXTDZ($A$1,$B14,J$1,$B$1) -> 34.95 | ... BV14: =_xll.EQNXTDZ($A$1,$B14,BV$1,$B$1) -> 0
A15: Electricity Power & Fuel Cost | B15: QTR_ELECTRICITY_POWER_FUEL | C15: =_xll.EQNXTDZ($A$1,$B15,C$1,$B$1) -> 0 | D15: =_xll.EQNXTDZ($A$1,$B15,D$1,$B$1) -> 0 | E15: =_xll.EQNXTDZ($A$1,$B15,E$1,$B$1) -> 0 | F15: =_xll.EQNXTDZ($A$1,$B15,F$1,$B$1) -> 0 | G15: =_xll.EQNXTDZ($A$1,$B15,G$1,$B$1) -> 0 | H15: =_xll.EQNXTDZ($A$1,$B15,H$1,$B$1) -> 0 | I15: =_xll.EQNXTDZ($A$1,$B15,I$1,$B$1) -> 0 | J15: =_xll.EQNXTDZ($A$1,$B15,J$1,$B$1) -> 0 | ... BV15: =_xll.EQNXTDZ($A$1,$B15,BV$1,$B$1) -> 0
A16: Employee Cost | B16: QTR_EXPLOYEE_COST | C16: =_xll.EQNXTDZ($A$1,$B16,C$1,$B$1) -> 4.582 | D16: =_xll.EQNXTDZ($A$1,$B16,D$1,$B$1) -> 4.299 | E16: =_xll.EQNXTDZ($A$1,$B16,E$1,$B$1) -> 4.581 | F16: =_xll.EQNXTDZ($A$1,$B16,F$1,$B$1) -> 4.54 | G16: =_xll.EQNXTDZ($A$1,$B16,G$1,$B$1) -> 4.52 | H16: =_xll.EQNXTDZ($A$1,$B16,H$1,$B$1) -> 4.698 | I16: =_xll.EQNXTDZ($A$1,$B16,I$1,$B$1) -> 5.29 | J16: =_xll.EQNXTDZ($A$1,$B16,J$1,$B$1) -> 6.27 | ... BV16: =_xll.EQNXTDZ($A$1,$B16,BV$1,$B$1) -> 0
... A42: Consolidated PAT(after extra items) | B42: QTR_CONS_PAT_EXITM | C42: =_xll.EQNXTDZ($A$1,$B42,C$1,$B$1) -> 9.367 | D42: =_xll.EQNXTDZ($A$1,$B42,D$1,$B$1) -> 8.891 | E42: =_xll.EQNXTDZ($A$1,$B42,E$1,$B$1) -> 7.193 | F42: =_xll.EQNXTDZ($A$1,$B42,F$1,$B$1) -> 5.7 | G42: =_xll.EQNXTDZ($A$1,$B42,G$1,$B$1) -> 8.51 | H42: =_xll.EQNXTDZ($A$1,$B42,H$1,$B$1) -> 11.735 | I42: =_xll.EQNXTDZ($A$1,$B42,I$1,$B$1) -> 4.2 | J42: =_xll.EQNXTDZ($A$1,$B42,J$1,$B$1) -> 9.09 | ... BV42: =_xll.EQNXTDZ($A$1,$B42,BV$1,$B$1) -> 0
A44: Field Description | B44: Field Name
A45: Equity Capital | B45: QTR_EQUITY_CAP | C45: =_xll.EQNXTDZ($A$1,$B45,C$1,$B$1) -> 6.48 | D45: =_xll.EQNXTDZ($A$1,$B45,D$1,$B$1) -> 6.48 | E45: =_xll.EQNXTDZ($A$1,$B45,E$1,$B$1) -> 6.48 | F45: =_xll.EQNXTDZ($A$1,$B45,F$1,$B$1) -> 6.48 | G45: =_xll.EQNXTDZ($A$1,$B45,G$1,$B$1) -> 6.48 | H45: =_xll.EQNXTDZ($A$1,$B45,H$1,$B$1) -> 6.48 | I45: =_xll.EQNXTDZ($A$1,$B45,I$1,$B$1) -> 6.48 | J45: =_xll.EQNXTDZ($A$1,$B45,J$1,$B$1) -> 6.48 | ... BV45: =_xll.EQNXTDZ($A$1,$B45,BV$1,$B$1) -> 0
A46: Face Value | B46: QTR_FV | C46: =_xll.EQNXTDZ($A$1,$B46,C$1,$B$1) -> 2 | D46: =_xll.EQNXTDZ($A$1,$B46,D$1,$B$1) -> 2 | E46: =_xll.EQNXTDZ($A$1,$B46,E$1,$B$1) -> 2 | F46: =_xll.EQNXTDZ($A$1,$B46,F$1,$B$1) -> 2 | G46: =_xll.EQNXTDZ($A$1,$B46,G$1,$B$1) -> 2 | H46: =_xll.EQNXTDZ($A$1,$B46,H$1,$B$1) -> 2 | I46: =_xll.EQNXTDZ($A$1,$B46,I$1,$B$1) -> 2 | J46: =_xll.EQNXTDZ($A$1,$B46,J$1,$B$1) -> 2 | ... BV46: =_xll.EQNXTDZ($A$1,$B46,BV$1,$B$1) -> 0
A47: Month End | B47: BMONTH_MONTHEND | C47: =_xll.EQNXTDZ($A$1,$B47,C$5) -> 201206 | D47: =_xll.EQNXTDZ($A$1,$B47,D$5) -> 201209 | E47: =_xll.EQNXTDZ($A$1,$B47,E$5) -> 201212 | F47: =_xll.EQNXTDZ($A$1,$B47,F$5) -> 201303 | G47: =_xll.EQNXTDZ($A$1,$B47,G$5) -> 201306 | H47: =_xll.EQNXTDZ($A$1,$B47,H$5) -> 201309 | I47: =_xll.EQNXTDZ($A$1,$B47,I$5) -> 201312 | J47: =_xll.EQNXTDZ($A$1,$B47,J$5) -> 201403 | ... BV47: =_xll.EQNXTDZ($A$1,$B47,BV$5) -> 0
A48: Close | B48: BMONTH_CLOSE | C48: =_xll.EQNXTDZ($A$1,$B48,C$5) -> 37.9 | D48: =_xll.EQNXTDZ($A$1,$B48,D$5) -> 58.95 | E48: =_xll.EQNXTDZ($A$1,$B48,E$5) -> 54.1 | F48: =_xll.EQNXTDZ($A$1,$B48,F$5) -> 35.2 | G48: =_xll.EQNXTDZ($A$1,$B48,G$5) -> 33.45 | H48: =_xll.EQNXTDZ($A$1,$B48,H$5) -> 32.15 | I48: =_xll.EQNXTDZ($A$1,$B48,I$5) -> 49.8 | J48: =_xll.EQNXTDZ($A$1,$B48,J$5) -> 39.95 | ... BV48: =_xll.EQNXTDZ($A$1,$B48,BV$5) -> 0
A49: Total of Promoter and Promoter Group | B49: SHP_TPFTOTALPROMOTER | C49: =_xll.EQNXTDZ($A$1,$B49,C$5) -> 53.87 | D49: =_xll.EQNXTDZ($A$1,$B49,D$5) -> 53.87 | E49: =_xll.EQNXTDZ($A$1,$B49,E$5) -> 53.87 | F49: =_xll.EQNXTDZ($A$1,$B49,F$5) -> 53.93 | G49: =_xll.EQNXTDZ($A$1,$B49,G$5) -> 53.99 | H49: =_xll.EQNXTDZ($A$1,$B49,H$5) -> 54.24 | I49: =_xll.EQNXTDZ($A$1,$B49,I$5) -> 54.34 | J49: =_xll.EQNXTDZ($A$1,$B49,J$5) -> 54.34 | ... BV49: =_xll.EQNXTDZ($A$1,$B49,BV$5) -> 0
A50: Total of Promoter and Promoter Group Pledged | B50: SHP_PSHFTOTALPROMOTER | C50: =_xll.EQNXTDZ($A$1,$B50,C$5) -> 38.57 | D50: =_xll.EQNXTDZ($A$1,$B50,D$5) -> 38.57 | E50: =_xll.EQNXTDZ($A$1,$B50,E$5) -> 38.57 | F50: =_xll.EQNXTDZ($A$1,$B50,F$5) -> 38.53 | G50: =_xll.EQNXTDZ($A$1,$B50,G$5) -> 38.48 | H50: =_xll.EQNXTDZ($A$1,$B50,H$5) -> 38.3 | I50: =_xll.EQNXTDZ($A$1,$B50,I$5) -> 38.24 | J50: =_xll.EQNXTDZ($A$1,$B50,J$5) -> 38.24 | ... BV50: =_xll.EQNXTDZ($A$1,$B50,BV$5) -> 0
A54: Field Description | B54: Field Name | C54: =_xll.EQNXTDZ($A$1,$B54,C$5) -> 0 | D54: =_xll.EQNXTDZ($A$1,$B54,D$5) -> 0 | E54: =_xll.EQNXTDZ($A$1,$B54,E$5) -> 0 | F54: =_xll.EQNXTDZ($A$1,$B54,F$5) -> 0 | G54: =_xll.EQNXTDZ($A$1,$B54,G$5) -> 0 | H54: =_xll.EQNXTDZ($A$1,$B54,H$5) -> 0 | I54: =_xll.EQNXTDZ($A$1,$B54,I$5) -> 0 | J54: =_xll.EQNXTDZ($A$1,$B54,J$5) -> 0 | ... BV54: =_xll.EQNXTDZ($A$1,$B54,BV$5) -> 0
A55: Year End | B55: QTRB_DATE_END | C55: =_xll.EQNXTDZ($A$1,$B55,C$5,$B$1) -> 0 | D55: =_xll.EQNXTDZ($A$1,$B55,D$5,$B$1) -> 201209 | E55: =_xll.EQNXTDZ($A$1,$B55,E$5,$B$1) -> 0 | F55: =_xll.EQNXTDZ($A$1,$B55,F$5,$B$1) -> 201303 | G55: =_xll.EQNXTDZ($A$1,$B55,G$5,$B$1) -> 0 | H55: =_xll.EQNXTDZ($A$1,$B55,H$5,$B$1) -> 201309 | I55: =_xll.EQNXTDZ($A$1,$B55,I$5,$B$1) -> 0 | J55: =_xll.EQNXTDZ($A$1,$B55,J$5,$B$1) -> 201403 | ... BV55: =_xll.EQNXTDZ($A$1,$B55,BV$5,$B$1) -> 0
A56: Share Capital | B56: QTRB_SHARE_CAPITAL | C56: =_xll.EQNXTDZ($A$1,$B56,C$5,$B$1) -> 0 | D56: =_xll.EQNXTDZ($A$1,$B56,D$5,$B$1) -> 6.48 | E56: =_xll.EQNXTDZ($A$1,$B56,E$5,$B$1) -> 0 | F56: =_xll.EQNXTDZ($A$1,$B56,F$5,$B$1) -> 6.48 | G56: =_xll.EQNXTDZ($A$1,$B56,G$5,$B$1) -> 0 | H56: =_xll.EQNXTDZ($A$1,$B56,H$5,$B$1) -> 6.48 | I56: =_xll.EQNXTDZ($A$1,$B56,I$5,$B$1) -> 0 | J56: =_xll.EQNXTDZ($A$1,$B56,J$5,$B$1) -> 6.48 | ... BV56: =_xll.EQNXTDZ($A$1,$B56,BV$5,$B$1) -> 0
A57: Share Warrants & outstandings | B57: QTRB_SHAREWARNDOUT | C57: =_xll.EQNXTDZ($A$1,$B57,C$5,$B$1) -> 0 | D57: =_xll.EQNXTDZ($A$1,$B57,D$5,$B$1) -> 0 | E57: =_xll.EQNXTDZ($A$1,$B57,E$5,$B$1) -> 0 | F57: =_xll.EQNXTDZ($A$1,$B57,F$5,$B$1) -> 0 | G57: =_xll.EQNXTDZ($A$1,$B57,G$5,$B$1) -> 0 | H57: =_xll.EQNXTDZ($A$1,$B57,H$5,$B$1) -> 0 | I57: =_xll.EQNXTDZ($A$1,$B57,I$5,$B$1) -> 0 | J57: =_xll.EQNXTDZ($A$1,$B57,J$5,$B$1) -> 0 | ... BV57: =_xll.EQNXTDZ($A$1,$B57,BV$5,$B$1) -> 0
A58: Reserves & Surplus | B58: QTRB_RESERVE | C58: =_xll.EQNXTDZ($A$1,$B58,C$5,$B$1) -> 0 | D58: =_xll.EQNXTDZ($A$1,$B58,D$5,$B$1) -> 157.973 | E58: =_xll.EQNXTDZ($A$1,$B58,E$5,$B$1) -> 0 | F58: =_xll.EQNXTDZ($A$1,$B58,F$5,$B$1) -> 166 | G58: =_xll.EQNXTDZ($A$1,$B58,G$5,$B$1) -> 0 | H58: =_xll.EQNXTDZ($A$1,$B58,H$5,$B$1) -> 186.229 | I58: =_xll.EQNXTDZ($A$1,$B58,I$5,$B$1) -> 0 | J58: =_xll.EQNXTDZ($A$1,$B58,J$5,$B$1) -> 195.76 | ... BV58: =_xll.EQNXTDZ($A$1,$B58,BV$5,$B$1) -> 0
A59: Shareholder's Funds | B59: QTRB_SHAREHODERS_FUNDS | C59: =_xll.EQNXTDZ($A$1,$B59,C$5,$B$1) -> 0 | D59: =_xll.EQNXTDZ($A$1,$B59,D$5,$B$1) -> 164.453 | E59: =_xll.EQNXTDZ($A$1,$B59,E$5,$B$1) -> 0 | F59: =_xll.EQNXTDZ($A$1,$B59,F$5,$B$1) -> 172.48 | G59: =_xll.EQNXTDZ($A$1,$B59,G$5,$B$1) -> 0 | H59: =_xll.EQNXTDZ($A$1,$B59,H$5,$B$1) -> 192.709 | I59: =_xll.EQNXTDZ($A$1,$B59,I$5,$B$1) -> 0 | J59: =_xll.EQNXTDZ($A$1,$B59,J$5,$B$1) -> 202.24 | ... BV59: =_xll.EQNXTDZ($A$1,$B59,BV$5,$B$1) -> 0
A60: Minority Interest | B60: QTRB_MINORITY_INTEREST_BS | C60: =_xll.EQNXTDZ($A$1,$B60,C$5,$B$1) -> 0 | D60: =_xll.EQNXTDZ($A$1,$B60,D$5,$B$1) -> 0 | E60: =_xll.EQNXTDZ($A$1,$B60,E$5,$B$1) -> 0 | F60: =_xll.EQNXTDZ($A$1,$B60,F$5,$B$1) -> 0 | G60: =_xll.EQNXTDZ($A$1,$B60,G$5,$B$1) -> 0 | H60: =_xll.EQNXTDZ($A$1,$B60,H$5,$B$1) -> 0 | I60: =_xll.EQNXTDZ($A$1,$B60,I$5,$B$1) -> 0 | J60: =_xll.EQNXTDZ($A$1,$B60,J$5,$B$1) -> 0 | ... BV60: =_xll.EQNXTDZ($A$1,$B60,BV$5,$B$1) -> 0
A61: Long Term Borrowings | B61: QTRB_TOTAL_DEBTS | C61: =_xll.EQNXTDZ($A$1,$B61,C$5,$B$1) -> 0 | D61: =_xll.EQNXTDZ($A$1,$B61,D$5,$B$1) -> 99.499 | E61: =_xll.EQNXTDZ($A$1,$B61,E$5,$B$1) -> 0 | F61: =_xll.EQNXTDZ($A$1,$B61,F$5,$B$1) -> 103.73 | G61: =_xll.EQNXTDZ($A$1,$B61,G$5,$B$1) -> 0 | H61: =_xll.EQNXTDZ($A$1,$B61,H$5,$B$1) -> 101.011 | I61: =_xll.EQNXTDZ($A$1,$B61,I$5,$B$1) -> 0 | J61: =_xll.EQNXTDZ($A$1,$B61,J$5,$B$1) -> 85.95 | ... BV61: =_xll.EQNXTDZ($A$1,$B61,BV$5,$B$1) -> 0
A62: Secured Loans | B62: QTRB_SECURED_LOANS | C62: =_xll.EQNXTDZ($A$1,$B62,C$5,$B$1) -> 0 | D62: =_xll.EQNXTDZ($A$1,$B62,D$5,$B$1) -> 0 | E62: =_xll.EQNXTDZ($A$1,$B62,E$5,$B$1) -> 0 | F62: =_xll.EQNXTDZ($A$1,$B62,F$5,$B$1) -> 0 | G62: =_xll.EQNXTDZ($A$1,$B62,G$5,$B$1) -> 0 | H62: =_xll.EQNXTDZ($A$1,$B62,H$5,$B$1) -> 0 | I62: =_xll.EQNXTDZ($A$1,$B62,I$5,$B$1) -> 0 | J62: =_xll.EQNXTDZ($A$1,$B62,J$5,$B$1) -> 0 | ... BV62: =_xll.EQNXTDZ($A$1,$B62,BV$5,$B$1) -> 0
A63: Unsecured Loans | B63: QTRB_UNSECURED_LOANS_NF | C63: =_xll.EQNXTDZ($A$1,$B63,C$5,$B$1) -> 0 | D63: =_xll.EQNXTDZ($A$1,$B63,D$5,$B$1) -> 99.499 | E63: =_xll.EQNXTDZ($A$1,$B63,E$5,$B$1) -> 0 | F63: =_xll.EQNXTDZ($A$1,$B63,F$5,$B$1) -> 103.73 | G63: =_xll.EQNXTDZ($A$1,$B63,G$5,$B$1) -> 0 | H63: =_xll.EQNXTDZ($A$1,$B63,H$5,$B$1) -> 101.011 | I63: =_xll.EQNXTDZ($A$1,$B63,I$5,$B$1) -> 0 | J63: =_xll.EQNXTDZ($A$1,$B63,J$5,$B$1) -> 85.95 | ... BV63: =_xll.EQNXTDZ($A$1,$B63,BV$5,$B$1) -> 0
A64: Other Long Term Liabilities | B64: QTRB_OTHER_LT_LIABILITIES | C64: =_xll.EQNXTDZ($A$1,$B64,C$5,$B$1) -> 0 | D64: =_xll.EQNXTDZ($A$1,$B64,D$5,$B$1) -> 2.511 | E64: =_xll.EQNXTDZ($A$1,$B64,E$5,$B$1) -> 0 | F64: =_xll.EQNXTDZ($A$1,$B64,F$5,$B$1) -> 5.85 | G64: =_xll.EQNXTDZ($A$1,$B64,G$5,$B$1) -> 0 | H64: =_xll.EQNXTDZ($A$1,$B64,H$5,$B$1) -> 3.548 | I64: =_xll.EQNXTDZ($A$1,$B64,I$5,$B$1) -> 0 | J64: =_xll.EQNXTDZ($A$1,$B64,J$5,$B$1) -> 5.04 | ... BV64: =_xll.EQNXTDZ($A$1,$B64,BV$5,$B$1) -> 0
A65: Long Term Trade Payables | B65: QTRB_LT_TRADE_PAYABLE | C65: =_xll.EQNXTDZ($A$1,$B65,C$5,$B$1) -> 0 | D65: =_xll.EQNXTDZ($A$1,$B65,D$5,$B$1) -> 0 | E65: =_xll.EQNXTDZ($A$1,$B65,E$5,$B$1) -> 0 | F65: =_xll.EQNXTDZ($A$1,$B65,F$5,$B$1) -> 0 | G65: =_xll.EQNXTDZ($A$1,$B65,G$5,$B$1) -> 0 | H65: =_xll.EQNXTDZ($A$1,$B65,H$5,$B$1) -> 0 | I65: =_xll.EQNXTDZ($A$1,$B65,I$5,$B$1) -> 0 | J65: =_xll.EQNXTDZ($A$1,$B65,J$5,$B$1) -> 0 | ... BV65: =_xll.EQNXTDZ($A$1,$B65,BV$5,$B$1) -> 0
A66: Lont Term Provisions | B66: QTRB_LT_PROVISIONS | C66: =_xll.EQNXTDZ($A$1,$B66,C$5,$B$1) -> 0 | D66: =_xll.EQNXTDZ($A$1,$B66,D$5,$B$1) -> 0 | E66: =_xll.EQNXTDZ($A$1,$B66,E$5,$B$1) -> 0 | F66: =_xll.EQNXTDZ($A$1,$B66,F$5,$B$1) -> 0 | G66: =_xll.EQNXTDZ($A$1,$B66,G$5,$B$1) -> 0 | H66: =_xll.EQNXTDZ($A$1,$B66,H$5,$B$1) -> 0 | I66: =_xll.EQNXTDZ($A$1,$B66,I$5,$B$1) -> 0 | J66: =_xll.EQNXTDZ($A$1,$B66,J$5,$B$1) -> 0 | ... BV66: =_xll.EQNXTDZ($A$1,$B66,BV$5,$B$1) -> 0
... A97: Total Assets | B97: QTRB_TOTAL_APPLICATIONS | C97: =_xll.EQNXTDZ($A$1,$B97,C$5,$B$1) -> 0 | D97: =_xll.EQNXTDZ($A$1,$B97,D$5,$B$1) -> 266.463 | E97: =_xll.EQNXTDZ($A$1,$B97,E$5,$B$1) -> 0 | F97: =_xll.EQNXTDZ($A$1,$B97,F$5,$B$1) -> 282.053 | G97: =_xll.EQNXTDZ($A$1,$B97,G$5,$B$1) -> 0 | H97: =_xll.EQNXTDZ($A$1,$B97,H$5,$B$1) -> 297.27 | I97: =_xll.EQNXTDZ($A$1,$B97,I$5,$B$1) -> 0 | J97: =_xll.EQNXTDZ($A$1,$B97,J$5,$B$1) -> 293.23 | ... BV97: =_xll.EQNXTDZ($A$1,$B97,BV$5,$B$1) -> 0

Sheet Annual Raw
A1: 130999 | B1: X | C1: 200103 | D1: 200203 | E1: 200303 | F1: 200403 | G1: 200503 | H1: 200603 | I1: 200703 | J1: 200803 | K1: 200903 | L1: 201003 | M1: 201103 | N1: 201203 | O1: 201303 | P1: 201403 | Q1: 201503 | R1: 201603 | S1: 201703 | T1: 201803 | U1: 201903 | V1: 202003 | W1: 202103 | X1: 202203 | Y1: 202303 | Z1: 202403 | AA1: 202503 | AB1: 202603 | AC1: 202703 | AD1: 202803 | AE1: 202903 | AF1: 203003
A3: Field Description | B3: Field Name
A4: Company Name | B4: CD_COMPNAME | C4: =_xll.EQNXTDZ(A1,B4,"L") -> Balaji Amines Ltd.
A5: Year End | B5: PL_YEAR_END | C5: =_xll.EQNXTDZ($A$1,$B5,C$1,$B$1) -> 200103 | D5: =_xll.EQNXTDZ($A$1,$B5,D$1,$B$1) -> 200203 | E5: =_xll.EQNXTDZ($A$1,$B5,E$1,$B$1) -> 200303 | F5: =_xll.EQNXTDZ($A$1,$B5,F$1,$B$1) -> 200403 | G5: =_xll.EQNXTDZ($A$1,$B5,G$1,$B$1) -> 200503 | H5: =_xll.EQNXTDZ($A$1,$B5,H$1,$B$1) -> 200603 | I5: =_xll.EQNXTDZ($A$1,$B5,I$1,$B$1) -> 200703 | J5: =_xll.EQNXTDZ($A$1,$B5,J$1,$B$1) -> 200803 | ... AF5: =_xll.EQNXTDZ($A$1,$B5,AF$1,$B$1) -> 0
A6: Sales Turnover | B6: PL_TOTAL_GROSS_SALES | C6: =_xll.EQNXTDZ($A$1,$B6,C$1,$B$1) -> 29.322553 | D6: =_xll.EQNXTDZ($A$1,$B6,D$1,$B$1) -> 41.153086 | E6: =_xll.EQNXTDZ($A$1,$B6,E$1,$B$1) -> 50.679308 | F6: =_xll.EQNXTDZ($A$1,$B6,F$1,$B$1) -> 81.990468 | G6: =_xll.EQNXTDZ($A$1,$B6,G$1,$B$1) -> 99.190306 | H6: =_xll.EQNXTDZ($A$1,$B6,H$1,$B$1) -> 145.89401 | I6: =_xll.EQNXTDZ($A$1,$B6,I$1,$B$1) -> 197.29384 | J6: =_xll.EQNXTDZ($A$1,$B6,J$1,$B$1) -> 239.67648 | ... AF6: =_xll.EQNXTDZ($A$1,$B6,AF$1,$B$1) -> 0
A7: Less: Inter divisional transfers | B7: PL_INTER_DIV_TRF | C7: =_xll.EQNXTDZ($A$1,$B7,C$1,$B$1) -> 0 | D7: =_xll.EQNXTDZ($A$1,$B7,D$1,$B$1) -> 0 | E7: =_xll.EQNXTDZ($A$1,$B7,E$1,$B$1) -> 0 | F7: =_xll.EQNXTDZ($A$1,$B7,F$1,$B$1) -> 0 | G7: =_xll.EQNXTDZ($A$1,$B7,G$1,$B$1) -> 0 | H7: =_xll.EQNXTDZ($A$1,$B7,H$1,$B$1) -> 0 | I7: =_xll.EQNXTDZ($A$1,$B7,I$1,$B$1) -> 0 | J7: =_xll.EQNXTDZ($A$1,$B7,J$1,$B$1) -> 0 | ... AF7: =_xll.EQNXTDZ($A$1,$B7,AF$1,$B$1) -> 0
A8: Less: Sales Returns | B8: PL_SALES_RETURN | C8: =_xll.EQNXTDZ($A$1,$B8,C$1,$B$1) -> 0 | D8: =_xll.EQNXTDZ($A$1,$B8,D$1,$B$1) -> 0 | E8: =_xll.EQNXTDZ($A$1,$B8,E$1,$B$1) -> 0 | F8: =_xll.EQNXTDZ($A$1,$B8,F$1,$B$1) -> 0 | G8: =_xll.EQNXTDZ($A$1,$B8,G$1,$B$1) -> 0 | H8: =_xll.EQNXTDZ($A$1,$B8,H$1,$B$1) -> 0 | I8: =_xll.EQNXTDZ($A$1,$B8,I$1,$B$1) -> 0 | J8: =_xll.EQNXTDZ($A$1,$B8,J$1,$B$1) -> 0 | ... AF8: =_xll.EQNXTDZ($A$1,$B8,AF$1,$B$1) -> 0
A9: Less: Excise | B9: PL_EXCISE | C9: =_xll.EQNXTDZ($A$1,$B9,C$1,$B$1) -> 3.1924889 | D9: =_xll.EQNXTDZ($A$1,$B9,D$1,$B$1) -> 4.57874 | E9: =_xll.EQNXTDZ($A$1,$B9,E$1,$B$1) -> 5.5724934 | F9: =_xll.EQNXTDZ($A$1,$B9,F$1,$B$1) -> 11.084474 | G9: =_xll.EQNXTDZ($A$1,$B9,G$1,$B$1) -> 11.463434 | H9: =_xll.EQNXTDZ($A$1,$B9,H$1,$B$1) -> 17.280035 | I9: =_xll.EQNXTDZ($A$1,$B9,I$1,$B$1) -> 21.788731 | J9: =_xll.EQNXTDZ($A$1,$B9,J$1,$B$1) -> 21.856958 | ... AF9: =_xll.EQNXTDZ($A$1,$B9,AF$1,$B$1) -> 0
A10: Net Sales | B10: PL_NET_SALES | C10: =_xll.EQNXTDZ($A$1,$B10,C$1,$B$1) -> 26.130064 | D10: =_xll.EQNXTDZ($A$1,$B10,D$1,$B$1) -> 36.574346 | E10: =_xll.EQNXTDZ($A$1,$B10,E$1,$B$1) -> 45.106815 | F10: =_xll.EQNXTDZ($A$1,$B10,F$1,$B$1) -> 70.905994 | G10: =_xll.EQNXTDZ($A$1,$B10,G$1,$B$1) -> 87.726873 | H10: =_xll.EQNXTDZ($A$1,$B10,H$1,$B$1) -> 128.61398 | I10: =_xll.EQNXTDZ($A$1,$B10,I$1,$B$1) -> 175.50511 | J10: =_xll.EQNXTDZ($A$1,$B10,J$1,$B$1) -> 217.81952 | ... AF10: =_xll.EQNXTDZ($A$1,$B10,AF$1,$B$1) -> 0
A11: Increase/Decrease in Stock | B11: PL_INC_DEC_INVENTORY | C11: =_xll.EQNXTDZ($A$1,$B11,C$1,$B$1) -> -0.4594177 | D11: =_xll.EQNXTDZ($A$1,$B11,D$1,$B$1) -> 0.6528199 | E11: =_xll.EQNXTDZ($A$1,$B11,E$1,$B$1) -> 0.0706961 | F11: =_xll.EQNXTDZ($A$1,$B11,F$1,$B$1) -> -2.8792667 | G11: =_xll.EQNXTDZ($A$1,$B11,G$1,$B$1) -> -4.1421282 | H11: =_xll.EQNXTDZ($A$1,$B11,H$1,$B$1) -> -0.9728324 | I11: =_xll.EQNXTDZ($A$1,$B11,I$1,$B$1) -> -8.98609 | J11: =_xll.EQNXTDZ($A$1,$B11,J$1,$B$1) -> 9.3914083 | ... AF11: =_xll.EQNXTDZ($A$1,$B11,AF$1,$B$1) -> 0
A12: Raw Material Consumed | B12: PL_RAW_MATRS_CONSUMED | C12: =_xll.EQNXTDZ($A$1,$B12,C$1,$B$1) -> 13.941152 | D12: =_xll.EQNXTDZ($A$1,$B12,D$1,$B$1) -> 16.707095 | E12: =_xll.EQNXTDZ($A$1,$B12,E$1,$B$1) -> 22.226833 | F12: =_xll.EQNXTDZ($A$1,$B12,F$1,$B$1) -> 42.588878 | G12: =_xll.EQNXTDZ($A$1,$B12,G$1,$B$1) -> 56.728602 | H12: =_xll.EQNXTDZ($A$1,$B12,H$1,$B$1) -> 77.304028 | I12: =_xll.EQNXTDZ($A$1,$B12,I$1,$B$1) -> 113.90762 | J12: =_xll.EQNXTDZ($A$1,$B12,J$1,$B$1) -> 125.69363 | ... AF12: =_xll.EQNXTDZ($A$1,$B12,AF$1,$B$1) -> 0
A13: Power & Fuel Cost | B13: PL_POWER_FUEL | C13: =_xll.EQNXTDZ($A$1,$B13,C$1,$B$1) -> 3.7361172 | D13: =_xll.EQNXTDZ($A$1,$B13,D$1,$B$1) -> 3.9301357 | E13: =_xll.EQNXTDZ($A$1,$B13,E$1,$B$1) -> 4.7636879 | F13: =_xll.EQNXTDZ($A$1,$B13,F$1,$B$1) -> 7.1645533 | G13: =_xll.EQNXTDZ($A$1,$B13,G$1,$B$1) -> 9.0957375 | H13: =_xll.EQNXTDZ($A$1,$B13,H$1,$B$1) -> 11.449297 | I13: =_xll.EQNXTDZ($A$1,$B13,I$1,$B$1) -> 15.132046 | J13: =_xll.EQNXTDZ($A$1,$B13,J$1,$B$1) -> 17.365087 | ... AF13: =_xll.EQNXTDZ($A$1,$B13,AF$1,$B$1) -> 0
A14: Employee Cost | B14: PL_EMPLOYEES | C14: =_xll.EQNXTDZ($A$1,$B14,C$1,$B$1) -> 0.8771284 | D14: =_xll.EQNXTDZ($A$1,$B14,D$1,$B$1) -> 0.9991958 | E14: =_xll.EQNXTDZ($A$1,$B14,E$1,$B$1) -> 1.1901778 | F14: =_xll.EQNXTDZ($A$1,$B14,F$1,$B$1) -> 1.6467427 | G14: =_xll.EQNXTDZ($A$1,$B14,G$1,$B$1) -> 2.2550053 | H14: =_xll.EQNXTDZ($A$1,$B14,H$1,$B$1) -> 2.9508445 | I14: =_xll.EQNXTDZ($A$1,$B14,I$1,$B$1) -> 3.4899674 | J14: =_xll.EQNXTDZ($A$1,$B14,J$1,$B$1) -> 4.0490099 | ... AF14: =_xll.EQNXTDZ($A$1,$B14,AF$1,$B$1) -> 0
A15: Operating & Manufacturing Expenses | B15: PL_GEN_OTHER_MFG_EXPS | C15: =_xll.EQNXTDZ($A$1,$B15,C$1,$B$1) -> 1.6168982 | D15: =_xll.EQNXTDZ($A$1,$B15,D$1,$B$1) -> 2.4421327 | E15: =_xll.EQNXTDZ($A$1,$B15,E$1,$B$1) -> 3.6772316 | F15: =_xll.EQNXTDZ($A$1,$B15,F$1,$B$1) -> 4.4617804 | G15: =_xll.EQNXTDZ($A$1,$B15,G$1,$B$1) -> 6.3403451 | H15: =_xll.EQNXTDZ($A$1,$B15,H$1,$B$1) -> 9.6007268 | I15: =_xll.EQNXTDZ($A$1,$B15,I$1,$B$1) -> 13.704348 | J15: =_xll.EQNXTDZ($A$1,$B15,J$1,$B$1) -> 16.88892 | ... AF15: =_xll.EQNXTDZ($A$1,$B15,AF$1,$B$1) -> 0
A16: Cost of Software development | B16: PL_COST_SW | C16: =_xll.EQNXTDZ($A$1,$B16,C$1,$B$1) -> 0 | D16: =_xll.EQNXTDZ($A$1,$B16,D$1,$B$1) -> 0 | E16: =_xll.EQNXTDZ($A$1,$B16,E$1,$B$1) -> 0 | F16: =_xll.EQNXTDZ($A$1,$B16,F$1,$B$1) -> 0 | G16: =_xll.EQNXTDZ($A$1,$B16,G$1,$B$1) -> 0 | H16: =_xll.EQNXTDZ($A$1,$B16,H$1,$B$1) -> 0 | I16: =_xll.EQNXTDZ($A$1,$B16,I$1,$B$1) -> 0 | J16: =_xll.EQNXTDZ($A$1,$B16,J$1,$B$1) -> 0 | ... AF16: =_xll.EQNXTDZ($A$1,$B16,AF$1,$B$1) -> 0
... A36: Profit After Tax from Discontinued Operations | B36: PL_PAT_DIS_OP | C36: =_xll.EQNXTDZ($A$1,$B36,C$1,$B$1) -> 0 | D36: =_xll.EQNXTDZ($A$1,$B36,D$1,$B$1) -> 0 | E36: =_xll.EQNXTDZ($A$1,$B36,E$1,$B$1) -> 0 | F36: =_xll.EQNXTDZ($A$1,$B36,F$1,$B$1) -> 0 | G36: =_xll.EQNXTDZ($A$1,$B36,G$1,$B$1) -> 0 | H36: =_xll.EQNXTDZ($A$1,$B36,H$1,$B$1) -> 0 | I36: =_xll.EQNXTDZ($A$1,$B36,I$1,$B$1) -> 0 | J36: =_xll.EQNXTDZ($A$1,$B36,J$1,$B$1) -> 0 | ... AF36: =_xll.EQNXTDZ($A$1,$B36,AF$1,$B$1) -> 0
A39: Field Description | B39: Field Name
A40: Year End | B40: BS_YEAR_END | C40: =_xll.EQNXTDZ($A$1,$B40,C$1,$B$1) -> 200103 | D40: =_xll.EQNXTDZ($A$1,$B40,D$1,$B$1) -> 200203 | E40: =_xll.EQNXTDZ($A$1,$B40,E$1,$B$1) -> 200303 | F40: =_xll.EQNXTDZ($A$1,$B40,F$1,$B$1) -> 200403 | G40: =_xll.EQNXTDZ($A$1,$B40,G$1,$B$1) -> 200503 | H40: =_xll.EQNXTDZ($A$1,$B40,H$1,$B$1) -> 200603 | I40: =_xll.EQNXTDZ($A$1,$B40,I$1,$B$1) -> 200703 | J40: =_xll.EQNXTDZ($A$1,$B40,J$1,$B$1) -> 200803 | ... AF40: =_xll.EQNXTDZ($A$1,$B40,AF$1,$B$1) -> 0
A41: Share Capital | B41: BS_SHARE_CAPITAL | C41: =_xll.EQNXTDZ($A$1,$B41,C$1,$B$1) -> 2.9838 | D41: =_xll.EQNXTDZ($A$1,$B41,D$1,$B$1) -> 2.9838 | E41: =_xll.EQNXTDZ($A$1,$B41,E$1,$B$1) -> 2.9867 | F41: =_xll.EQNXTDZ($A$1,$B41,F$1,$B$1) -> 3.0001 | G41: =_xll.EQNXTDZ($A$1,$B41,G$1,$B$1) -> 3.0001 | H41: =_xll.EQNXTDZ($A$1,$B41,H$1,$B$1) -> 3.0001 | I41: =_xll.EQNXTDZ($A$1,$B41,I$1,$B$1) -> 6.4802 | J41: =_xll.EQNXTDZ($A$1,$B41,J$1,$B$1) -> 6.4802 | ... AF41: =_xll.EQNXTDZ($A$1,$B41,AF$1,$B$1) -> 0
