Workbook

Sheet Template
A1: =+'Annual Raw'!B2 -> CreditAccess Grameen Ltd. | B1: =+EOMONTH(C1,-12) -> 36981 | C1: =+EOMONTH(D1,-12) -> 37346 | D1: =+EOMONTH(E1,-12) -> 37711 | E1: =+EOMONTH(F1,-12) -> 38077 | F1: =+EOMONTH(G1,-12) -> 38442 | G1: =+EOMONTH(H1,-12) -> 38807 | H1: =+EOMONTH(I1,-12) -> 39172 | I1: =+EOMONTH(J1,-12) -> 39538 | ... N1: =+EOMONTH(O1,-12) -> 41364 | O1: 41699 | P1: 42064 | Q1: 42430 | R1: 42795 | S1: 43160 | T1: 43525 | U1: 43891 | V1: 44256 | W1: 44621 | X1: 44986 | Y1: 45352 | Z1: 45717 | AA1: 46082 | AB1: 46447 | AC1: 46813 | AD1: 47178 | AE1: 47543 | AG1: Quarterly | AH1: 42185 | AI1: =+EOMONTH(AH1,3) -> 42277 | AJ1: =+EOMONTH(AI1,3) -> 42369 | AK1: =+EOMONTH(AJ1,3) -> 42460 | AL1: =+EOMONTH(AK1,3) -> 42551 | AM1: =+EOMONTH(AL1,3) -> 42643 | AN1: =+EOMONTH(AM1,3) -> 42735 | AO1: =+EOMONTH(AN1,3) -> 42825 | AP1: =+EOMONTH(AO1,3) -> 42916 | ... CO1: =+EOMONTH(CN1,3) -> 47573 | CS1: HISTORICAL ESTIMATES | CT1: 46082
A2: Presentation Data (Start)
A4: Average eq | D4: =AVERAGE(C106:D106) -> 0 | E4: =AVERAGE(D106:E106) -> 0 | F4: =AVERAGE(E106:F106) -> 0 | G4: =AVERAGE(F106:G106) -> 0 | H4: =AVERAGE(G106:H106) -> 0 | I4: =AVERAGE(H106:I106) -> 0 | J4: =AVERAGE(I106:J106) -> 10.898666 | K4: =AVERAGE(J106:K106) -> 36.020155 | ... X4: =AVERAGE(W106:X106) -> 4636.925 | Y4: =+AVERAGE(BN4:BQ4) -> 5810.6812 | Z4: =+AVERAGE(BR4:BU4) -> 6901.9788 | AA4: =+AVERAGE(BV4:BY4) -> 7249.03 | AB4: =+AVERAGE(BZ4:CC4) -> 8542.4144 | AC4: =+AVERAGE(CD4:CG4) -> 10367.377 | AD4: =+AVERAGE(CH4:CK4) -> 12646.611 | AE4: =+AVERAGE(CL4:CO4) -> 15282.819 | AH4: =AVERAGE(AG106:AH106) -> 0 | AI4: =AVERAGE(AH106:AI106) -> 0 | AJ4: =AVERAGE(AI106:AJ106) -> 0 | AK4: =AVERAGE(AJ106:AK106) -> 0 | AL4: =AVERAGE(AK106:AL106) -> 0 | AM4: =AVERAGE(AL106:AM106) -> 0 | AN4: =AVERAGE(AM106:AN106) -> 0 | AO4: =AVERAGE(AN106:AO106) -> 0 | ... CO4: =AVERAGE(CN106:CO106) -> 16351.026
A5: Average assets | D5: =AVERAGE(C115:D115) -> 0 | E5: =AVERAGE(D115:E115) -> 0 | F5: =AVERAGE(E115:F115) -> 0 | G5: =AVERAGE(F115:G115) -> 0 | H5: =AVERAGE(G115:H115) -> 0 | I5: =AVERAGE(H115:I115) -> 0 | J5: =AVERAGE(I115:J115) -> 105.52 | K5: =AVERAGE(J115:K115) -> 253.71033 | ... X5: =AVERAGE(W115:X115) -> 19253.4 | Y5: =+AVERAGE(BN5:BQ5) -> 13942.493 | Z5: =+AVERAGE(BR5:BU5) -> 20977.406 | AA5: =+AVERAGE(BV5:BY5) -> 26836.186 | AB5: =+AVERAGE(BZ5:CC5) -> 31306.233 | AC5: =+AVERAGE(CD5:CG5) -> 35988.795 | AD5: =+AVERAGE(CH5:CK5) -> 41482.759 | AE5: =+AVERAGE(CL5:CO5) -> 47736.938 | AH5: =AVERAGE(AG115:AH115) -> 0 | AI5: =AVERAGE(AH115:AI115) -> 0 | AJ5: =AVERAGE(AI115:AJ115) -> 0 | AK5: =AVERAGE(AJ115:AK115) -> 0 | AL5: =AVERAGE(AK115:AL115) -> 0 | AM5: =AVERAGE(AL115:AM115) -> 0 | AN5: =AVERAGE(AM115:AN115) -> 0 | AO5: =AVERAGE(AN115:AO115) -> 0 | ... CO5: =AVERAGE(CN115:CO115) -> 50771.079
A7: Growth (%) | D7: =+D5/C5-1 -> #DIV/0! | E7: =+E5/D5-1 -> #DIV/0! | F7: =+F5/E5-1 -> #DIV/0! | G7: =+G5/F5-1 -> #DIV/0! | H7: =+H5/G5-1 -> #DIV/0! | I7: =+I5/H5-1 -> #DIV/0! | J7: =+J5/I5-1 -> #DIV/0! | K7: =+K5/J5-1 -> 1.4043815 | ... AE7: =+AE5/AD5-1 -> 0.15076574 | AL7: =AL5/AH5-1 -> #DIV/0! | AM7: =AM5/AI5-1 -> #DIV/0! | AN7: =AN5/AJ5-1 -> #DIV/0! | AO7: =AO5/AK5-1 -> #DIV/0! | AP7: =AP5/AL5-1 -> #DIV/0! | AQ7: =AQ5/AM5-1 -> #DIV/0! | AR7: =AR5/AN5-1 -> #DIV/0! | AS7: =AS5/AO5-1 -> #DIV/0! | ... CO7: =CO5/CK5-1 -> 0.14977219
A9: Leverage | D9: =D114/D106 -> #DIV/0! | E9: =E114/E106 -> #DIV/0! | F9: =F114/F106 -> #DIV/0! | G9: =G114/G106 -> #DIV/0! | H9: =H114/H106 -> #DIV/0! | I9: =I114/I106 -> #DIV/0! | J9: =J114/J106 -> 8.6819187 | K9: =K114/K106 -> 4.8989469 | ... AE9: =AE114/AE106 -> 2.1848042 | AH9: =AH114/AH106 -> #DIV/0! | AI9: =AI114/AI106 -> #DIV/0! | AJ9: =AJ114/AJ106 -> #DIV/0! | AK9: =AK114/AK106 -> #DIV/0! | AL9: =AL114/AL106 -> #DIV/0! | AM9: =AM114/AM106 -> #DIV/0! | AN9: =AN114/AN106 -> #DIV/0! | AO9: =AO114/AO106 -> #DIV/0! | ... CO9: =CO114/CO106 -> 2.1848042
A12: Interest Income | D12: =D35/C5 -> #DIV/0! | E12: =E35/D5 -> #DIV/0! | F12: =F35/E5 -> #DIV/0! | G12: =G35/F5 -> #DIV/0! | H12: =H35/G5 -> #DIV/0! | I12: =I35/H5 -> #DIV/0! | J12: =J35/I5 -> #DIV/0! | K12: =K35/J5 -> 0.46160639 | ... AE12: =AE35/AD5 -> 0.28673392 | AI12: =AI35/AH5 -> #DIV/0! | AJ12: =AJ35/AI5 -> #DIV/0! | AK12: =AK35/AJ5 -> #DIV/0! | AL12: =AL35/AK5 -> #DIV/0! | AM12: =AM35/AL5 -> #DIV/0! | AN12: =AN35/AM5 -> #DIV/0! | AO12: =AO35/AN5 -> #DIV/0! | AP12: =AP35/AO5 -> #DIV/0! | ... BX12: =BX35/BW5 -> 0.05737934 | BY12: =+AVERAGE(BU12:BX12)*1.08 -> 0.061221758 | BZ12: =+AVERAGE(BV12:BY12) -> 0.058161849 | CA12: =+AVERAGE(BW12:BZ12)*1.05 -> 0.061708412 | CB12: =+AVERAGE(BX12:CA12)*1.05 -> 0.062598732 | CC12: =+AVERAGE(BY12:CB12)*1.05 -> 0.063968822 | CD12: =+AVERAGE(BZ12:CC12)*1.02 -> 0.062841643 | CE12: =+AVERAGE(CA12:CD12)*1.02 -> 0.06403499 | CF12: =+AVERAGE(CB12:CE12)*1.02 -> 0.064628268 | CG12: =+AVERAGE(CC12:CF12)*1.02 -> 0.065145799 | CH12: =+AVERAGE(CD12:CG12) -> 0.064162675 | CI12: =+AVERAGE(CE12:CH12) -> 0.064492933 | CJ12: =+AVERAGE(CF12:CI12) -> 0.064607419 | CK12: =+AVERAGE(CG12:CJ12) -> 0.064602207 | CL12: =+AVERAGE(CH12:CK12) -> 0.064466308 | CM12: =+AVERAGE(CI12:CL12) -> 0.064542217 | CN12: =+AVERAGE(CJ12:CM12) -> 0.064554538 | CO12: =+AVERAGE(CK12:CN12) -> 0.064541317
A13: Interest Expenses | D13: =D36/C5 -> #DIV/0! | E13: =E36/D5 -> #DIV/0! | F13: =F36/E5 -> #DIV/0! | G13: =G36/F5 -> #DIV/0! | H13: =H36/G5 -> #DIV/0! | I13: =I36/H5 -> #DIV/0! | J13: =J36/I5 -> #DIV/0! | K13: =K36/J5 -> 0.17918624 | ... AE13: =AE36/AD5 -> 0.080821382 | AI13: =AI36/AH5 -> #DIV/0! | AJ13: =AJ36/AI5 -> #DIV/0! | AK13: =AK36/AJ5 -> #DIV/0! | AL13: =AL36/AK5 -> #DIV/0! | AM13: =AM36/AL5 -> #DIV/0! | AN13: =AN36/AM5 -> #DIV/0! | AO13: =AO36/AN5 -> #DIV/0! | AP13: =AP36/AO5 -> #DIV/0! | ... BX13: =BX36/BW5 -> 0.017684145 | BY13: =+AVERAGE(BU13:BX13) -> 0.018345618 | BZ13: =+AVERAGE(BV13:BY13) -> 0.018234348 | CA13: =+AVERAGE(BW13:BZ13) -> 0.018200899 | CB13: =+AVERAGE(BX13:CA13) -> 0.018116252 | CC13: =+AVERAGE(BY13:CB13) -> 0.018224279 | CD13: =+AVERAGE(BZ13:CC13) -> 0.018193945 | CE13: =+AVERAGE(CA13:CD13) -> 0.018183844 | CF13: =+AVERAGE(CB13:CE13) -> 0.01817958 | ... CO13: =+AVERAGE(CK13:CN13) -> 0.018188393
A14: NII | D14: =D12-D13 -> #DIV/0! | E14: =E12-E13 -> #DIV/0! | F14: =F12-F13 -> #DIV/0! | G14: =G12-G13 -> #DIV/0! | H14: =H12-H13 -> #DIV/0! | I14: =I12-I13 -> #DIV/0! | J14: =J12-J13 -> #DIV/0! | K14: =K12-K13 -> 0.28242015 | ... AE14: =AE12-AE13 -> 0.20591254 | AI14: =AI12-AI13 -> #DIV/0! | AJ14: =AJ12-AJ13 -> #DIV/0! | AK14: =AK12-AK13 -> #DIV/0! | AL14: =AL12-AL13 -> #DIV/0! | AM14: =AM12-AM13 -> #DIV/0! | AN14: =AN12-AN13 -> #DIV/0! | AO14: =AO12-AO13 -> #DIV/0! | AP14: =AP12-AP13 -> #DIV/0! | ... CO14: =CO12-CO13 -> 0.046352925
A15: Others income | D15: =D38/C5 -> #DIV/0! | E15: =E38/D5 -> #DIV/0! | F15: =F38/E5 -> #DIV/0! | G15: =G38/F5 -> #DIV/0! | H15: =H38/G5 -> #DIV/0! | I15: =I38/H5 -> #DIV/0! | J15: =J38/I5 -> #DIV/0! | K15: =K38/J5 -> 0.010219392 | ... AE15: =AE38/AD5 -> 0.00015396803 | AI15: =AI38/AH5 -> #DIV/0! | AJ15: =AJ38/AI5 -> #DIV/0! | AK15: =AK38/AJ5 -> #DIV/0! | AL15: =AL38/AK5 -> #DIV/0! | AM15: =AM38/AL5 -> #DIV/0! | AN15: =AN38/AM5 -> #DIV/0! | AO15: =AO38/AN5 -> #DIV/0! | AP15: =AP38/AO5 -> #DIV/0! | ... BX15: =BX38/BW5 -> 3.4649128e-05 | BY15: =BX15 -> 3.4649128e-05 | BZ15: =BY15 -> 3.4649128e-05 | CA15: =BZ15 -> 3.4649128e-05 | CB15: =CA15 -> 3.4649128e-05 | CC15: =CB15 -> 3.4649128e-05 | CD15: =CC15 -> 3.4649128e-05 | CE15: =CD15 -> 3.4649128e-05 | CF15: =CE15 -> 3.4649128e-05 | ... CO15: =CN15 -> 3.4649128e-05
A16: Other non-operating income
A17: Total income | D17: =D14+D15+D16 -> #DIV/0! | E17: =E14+E15+E16 -> #DIV/0! | F17: =F14+F15+F16 -> #DIV/0! | G17: =G14+G15+G16 -> #DIV/0! | H17: =H14+H15+H16 -> #DIV/0! | I17: =I14+I15+I16 -> #DIV/0! | J17: =J14+J15+J16 -> #DIV/0! | K17: =K14+K15+K16 -> 0.29263954 | ... AE17: =AE14+AE15+AE16 -> 0.20606651 | AI17: =AI14+AI15+AI16 -> #DIV/0! | AJ17: =AJ14+AJ15+AJ16 -> #DIV/0! | AK17: =AK14+AK15+AK16 -> #DIV/0! | AL17: =AL14+AL15+AL16 -> #DIV/0! | AM17: =AM14+AM15+AM16 -> #DIV/0! | AN17: =AN14+AN15+AN16 -> #DIV/0! | AO17: =AO14+AO15+AO16 -> #DIV/0! | AP17: =AP14+AP15+AP16 -> #DIV/0! | ... CO17: =CO14+CO15+CO16 -> 0.046387574
A18: TC | D18: =D46/C5 -> #DIV/0! | E18: =E46/D5 -> #DIV/0! | F18: =F46/E5 -> #DIV/0! | G18: =G46/F5 -> #DIV/0! | H18: =H46/G5 -> #DIV/0! | I18: =I46/H5 -> #DIV/0! | J18: =J46/I5 -> #DIV/0! | K18: =K46/J5 -> 0.23044208 | ... AE18: =AE46/AD5 -> 0.055484314 | AI18: =AI46/AH5 -> #DIV/0! | AJ18: =AJ46/AI5 -> #DIV/0! | AK18: =AK46/AJ5 -> #DIV/0! | AL18: =AL46/AK5 -> #DIV/0! | AM18: =AM46/AL5 -> #DIV/0! | AN18: =AN46/AM5 -> #DIV/0! | AO18: =AO46/AN5 -> #DIV/0! | AP18: =AP46/AO5 -> #DIV/0! | ... BX18: =BX46/BW5 -> 0.013531639 | BY18: =BX18 -> 0.013531639 | BZ18: =BY18*0.99 -> 0.013396323 | CA18: =BZ18*0.99 -> 0.01326236 | CB18: =CA18*0.99 -> 0.013129736 | CC18: =CB18*0.99 -> 0.012998439 | CD18: =CC18*0.99 -> 0.012868454 | CE18: =CD18*0.99 -> 0.01273977 | CF18: =CE18*0.99 -> 0.012612372 | CG18: =CF18*0.99 -> 0.012486248 | CH18: =CG18 -> 0.012486248 | CI18: =CH18 -> 0.012486248 | CJ18: =CI18 -> 0.012486248 | CK18: =CJ18 -> 0.012486248 | CL18: =CK18 -> 0.012486248 | CM18: =CL18 -> 0.012486248 | CN18: =CM18 -> 0.012486248 | CO18: =CN18 -> 0.012486248
A19: PPP | D19: =D17-D18 -> #DIV/0! | E19: =E17-E18 -> #DIV/0! | F19: =F17-F18 -> #DIV/0! | G19: =G17-G18 -> #DIV/0! | H19: =H17-H18 -> #DIV/0! | I19: =I17-I18 -> #DIV/0! | J19: =J17-J18 -> #DIV/0! | K19: =K17-K18 -> 0.062197455 | ... AE19: =AE17-AE18 -> 0.15058219 | AI19: =AI17-AI18 -> #DIV/0! | AJ19: =AJ17-AJ18 -> #DIV/0! | AK19: =AK17-AK18 -> #DIV/0! | AL19: =AL17-AL18 -> #DIV/0! | AM19: =AM17-AM18 -> #DIV/0! | AN19: =AN17-AN18 -> #DIV/0! | AO19: =AO17-AO18 -> #DIV/0! | AP19: =AP17-AP18 -> #DIV/0! | ... CO19: =CO17-CO18 -> 0.033901325
A20: Provision | D20: =D49/C5 -> #DIV/0! | E20: =E49/D5 -> #DIV/0! | F20: =F49/E5 -> #DIV/0! | G20: =G49/F5 -> #DIV/0! | H20: =H49/G5 -> #DIV/0! | I20: =I49/H5 -> #DIV/0! | J20: =J49/I5 -> #DIV/0! | K20: =K49/J5 -> 0.044368303 | ... AE20: =AE49/AD5 -> 0.058605364 | AI20: =AI49/AH5 -> #DIV/0! | AJ20: =AJ49/AI5 -> #DIV/0! | AK20: =AK49/AJ5 -> #DIV/0! | AL20: =AL49/AK5 -> #DIV/0! | AM20: =AM49/AL5 -> #DIV/0! | AN20: =AN49/AM5 -> #DIV/0! | AO20: =AO49/AN5 -> #DIV/0! | AP20: =AP49/AO5 -> #DIV/0! | ... BX20: =BX49/BW5 -> 0.013188613 | BY20: =BX20 -> 0.013188613 | BZ20: =BY20 -> 0.013188613 | CA20: =BZ20 -> 0.013188613 | CB20: =CA20 -> 0.013188613 | CC20: =CB20 -> 0.013188613 | CD20: =CC20 -> 0.013188613 | CE20: =CD20 -> 0.013188613 | CF20: =CE20 -> 0.013188613 | ... CO20: =CN20 -> 0.013188613
A21: PBT | D21: =D19-D20 -> #DIV/0! | E21: =E19-E20 -> #DIV/0! | F21: =F19-F20 -> #DIV/0! | G21: =G19-G20 -> #DIV/0! | H21: =H19-H20 -> #DIV/0! | I21: =I19-I20 -> #DIV/0! | J21: =J19-J20 -> #DIV/0! | K21: =K19-K20 -> 0.017829152 | ... AE21: =AE19-AE20 -> 0.091976829 | AI21: =AI19-AI20 -> #DIV/0! | AJ21: =AJ19-AJ20 -> #DIV/0! | AK21: =AK19-AK20 -> #DIV/0! | AL21: =AL19-AL20 -> #DIV/0! | AM21: =AM19-AM20 -> #DIV/0! | AN21: =AN19-AN20 -> #DIV/0! | AO21: =AO19-AO20 -> #DIV/0! | AP21: =AP19-AP20 -> #DIV/0! | ... CO21: =CO19-CO20 -> 0.020712713
A22: Tax | D22: =D51/C5 -> #DIV/0! | E22: =E51/D5 -> #DIV/0! | F22: =F51/E5 -> #DIV/0! | G22: =G51/F5 -> #DIV/0! | H22: =H51/G5 -> #DIV/0! | I22: =I51/H5 -> #DIV/0! | J22: =J51/I5 -> #DIV/0! | K22: =K51/J5 -> 0.0088673788 | ... AE22: =AE51/AD5 -> 0.023913975 | AI22: =AI51/AH5 -> #DIV/0! | AJ22: =AJ51/AI5 -> #DIV/0! | AK22: =AK51/AJ5 -> #DIV/0! | AL22: =AL51/AK5 -> #DIV/0! | AM22: =AM51/AL5 -> #DIV/0! | AN22: =AN51/AM5 -> #DIV/0! | AO22: =AO51/AN5 -> #DIV/0! | AP22: =AP51/AO5 -> #DIV/0! | ... CO22: =CO51/CN5 -> 0.0053853053
A23: PAT | D23: =D21-D22 -> #DIV/0! | E23: =E21-E22 -> #DIV/0! | F23: =F21-F22 -> #DIV/0! | G23: =G21-G22 -> #DIV/0! | H23: =H21-H22 -> #DIV/0! | I23: =I21-I22 -> #DIV/0! | J23: =J21-J22 -> #DIV/0! | K23: =K21-K22 -> 0.0089617732 | ... AE23: =AE21-AE22 -> 0.068062853 | AI23: =AI21-AI22 -> #DIV/0! | AJ23: =AJ21-AJ22 -> #DIV/0! | AK23: =AK21-AK22 -> #DIV/0! | AL23: =AL21-AL22 -> #DIV/0! | AM23: =AM21-AM22 -> #DIV/0! | AN23: =AN21-AN22 -> #DIV/0! | AO23: =AO21-AO22 -> #DIV/0! | AP23: =AP21-AP22 -> #DIV/0! | ... CO23: =CO21-CO22 -> 0.015327407
A26: Loan Book
A27: Opening | S27: =AS27 -> 4075 | T27: =S30 -> 4974.66 | U27: =T30 -> 7159 | V27: =U30 -> 9896 | W27: =V30 -> 13587 | X27: =W30 -> 16599 | Y27: =X30 -> 21031 | Z27: =Y30 -> 26714 | AA27: =Z30 -> 25948 | AR27: =AQ30 -> 3937 | AS27: =AR30 -> 4075 | AT27: =AS30 -> 4974.66 | AU27: =AT30 -> 5498 | AV27: =AU30 -> 5794 | AW27: =AV30 -> 6085 | AX27: =AW30 -> 7159 | AY27: =AX30 -> 7619 | ... BY27: =BX30 -> 26566
A28: Addition | S28: =SUM(AQ28:AS28) -> 4402 | T28: =SUM(AT28:AW28) -> 8221 | U28: =SUM(AX28:BA28) -> 10389 | V28: =SUM(BB28:BE28) -> 9641 | W28: =SUM(BF28:BI28) -> 12833 | X28: =SUM(BJ28:BM28) -> 18539 | Y28: =SUM(BN28:BQ28) -> 23134 | Z28: =SUM(BR28:BU28) -> 20437 | AA28: =SUM(BV28:BY28) -> 24860 | AQ28: 1195 | AR28: 1296 | AS28: 1911 | AT28: 1616 | AU28: 1571 | AV28: 1762 | AW28: 3272 | AX28: 2310 | AY28: 2186 | AZ28: 2977 | BA28: 2916 | BB28: 46 | BC28: 1420 | BD28: 4032 | BE28: 4143 | BF28: 907 | BG28: 3412 | BH28: 3866 | BI28: 4648 | BJ28: 2146 | BK28: 4375 | BL28: 4847 | BM28: 7171 | BN28: 4771 | BO28: 4966 | BP28: 5344 | BQ28: 8053 | BR28: 4476 | BS28: 4404 | BT28: 5085 | BU28: 6472 | BV28: 5458 | BW28: 5322 | BX28: 5767 | BY28: 8313
A29: Repayment | S29: =S27+S28-S30 -> 3502.34 | T29: =T27+T28-T30 -> 6036.66 | U29: =U27+U28-U30 -> 7652 | V29: =V27+V28-V30 -> 5950 | W29: =W27+W28-W30 -> 9821 | X29: =X27+X28-X30 -> 14107 | Y29: =Y27+Y28-Y30 -> 17451 | Z29: =Z27+Z28-Z30 -> 21203 | AA29: =AA27+AA28-AA30 -> 21218 | AQ29: =AQ27+AQ28-AQ30 -> -2742 | AR29: =AR27+AR28-AR30 -> 1158 | AS29: =AS27+AS28-AS30 -> 1011.34 | AT29: =AT27+AT28-AT30 -> 1092.66 | AU29: =AU27+AU28-AU30 -> 1275 | AV29: =AV27+AV28-AV30 -> 1471 | AW29: =AW27+AW28-AW30 -> 2198 | AX29: =AX27+AX28-AX30 -> 1850 | ... BY29: =BY27+BY28-BY30 -> 5289
A30: Closing | S30: =AS30 -> 4974.66 | T30: =AW30 -> 7159 | U30: =BA30 -> 9896 | V30: =BE30 -> 13587 | W30: =BI30 -> 16599 | X30: =BM30 -> 21031 | Y30: =BQ30 -> 26714 | Z30: =BU30 -> 25948 | AA30: =BY30 -> 29590 | AQ30: 3937 | AR30: 4075 | AS30: 4974.66 | AT30: 5498 | AU30: 5794 | AV30: 6085 | AW30: 7159 | AX30: 7619 | AY30: 7905 | AZ30: 8873 | BA30: 9896 | BB30: 11724 | BC30: 11183 | BD30: 12321 | BE30: 13587 | BF30: 12664 | BG30: 13333 | BH30: 14587 | BI30: 16599 | BJ30: 15615 | BK30: 16539 | BL30: 17786 | BM30: 21031 | BN30: 21814 | BO30: 22488 | BP30: 23382 | BQ30: 26714 | BR30: 26304 | BS30: 25133 | BT30: 24810 | BU30: 25948 | BV30: 26055 | BW30: 25904 | BX30: 26566 | BY30: 29590
A33: Presentation Data (End)
A34: Profit & Loss- Annual (Start)
A35: Interest Income | B35: =+'Annual Raw'!C14 -> 0 | C35: =+'Annual Raw'!D14 -> 0 | D35: =+'Annual Raw'!E14 -> 0 | E35: =+'Annual Raw'!F14 -> 0 | F35: =+'Annual Raw'!G14 -> 0 | G35: =+'Annual Raw'!H14 -> 0 | H35: =+'Annual Raw'!I14 -> 0 | I35: =+'Annual Raw'!J14 -> 0 | ... AA35: =+'Annual Raw'!AB14 -> 6058.92 | AB35: =SUM(BZ35:CC35) -> 7450.3332 | AC35: =SUM(CD35:CG35) -> 8915.9888 | AD35: =SUM(CH35:CK35) -> 10322.511 | AE35: =SUM(CL35:CO35) -> 11894.514 | AH35: =+'QTR Raw'!D13 -> 0 | AI35: =+'QTR Raw'!E13 -> 0 | AJ35: =+'QTR Raw'!F13 -> 0 | AK35: =+'QTR Raw'!G13 -> 0 | AL35: =+'QTR Raw'!H13 -> 0 | AM35: =+'QTR Raw'!I13 -> 0 | AN35: =+'QTR Raw'!J13 -> 0 | AO35: =+'QTR Raw'!K13 -> 0 | ... BY35: =+'QTR Raw'!AU13 -> 1597.27 | BZ35: =BZ12*BY5 -> 1679.8189 | CA35: =CA12*BZ5 -> 1872.6136 | CB35: =CB12*CA5 -> 1904.52 | CC35: =CC12*CB5 -> 1993.3806 | CD35: =CD12*CC5 -> 2092.1715 | CE35: =CE12*CD5 -> 2227.0419 | CF35: =CF12*CE5 -> 2259.5634 | CG35: =CG12*CF5 -> 2337.2121 | ... CO35: =CO12*CN5 -> 3074.1222 | CT35: 6058.92
A36: Interest exp | B36: =+'Annual Raw'!C29 -> 0 | C36: =+'Annual Raw'!D29 -> 0 | D36: =+'Annual Raw'!E29 -> 0 | E36: =+'Annual Raw'!F29 -> 0 | F36: =+'Annual Raw'!G29 -> 0 | G36: =+'Annual Raw'!H29 -> 0 | H36: =+'Annual Raw'!I29 -> 0 | I36: =+'Annual Raw'!J29 -> 0 | ... AA36: =+'Annual Raw'!AB29 -> 1905.13 | AB36: =SUM(BZ36:CC36) -> 2198.0423 | AC36: =SUM(CD36:CG36) -> 2526.5267 | AD36: =SUM(CH36:CK36) -> 2912.098 | AE36: =SUM(CL36:CO36) -> 3352.6939 | AH36: =+'QTR Raw'!D14+'QTR Raw'!D33 -> 0 | AI36: =+'QTR Raw'!E14+'QTR Raw'!E33 -> 0 | AJ36: =+'QTR Raw'!F14+'QTR Raw'!F33 -> 0 | AK36: =+'QTR Raw'!G14+'QTR Raw'!G33 -> 0 | AL36: =+'QTR Raw'!H14+'QTR Raw'!H33 -> 0 | AM36: =+'QTR Raw'!I14+'QTR Raw'!I33 -> 0 | AN36: =+'QTR Raw'!J14+'QTR Raw'!J33 -> 0 | AO36: =+'QTR Raw'!K14+'QTR Raw'!K33 -> 0 | ... BY36: =+'QTR Raw'!AU14+'QTR Raw'!AU33 -> 478.05 | BZ36: =BZ13*BY5 -> 526.64079 | CA36: =CA13*BZ5 -> 552.32748 | CB36: =CB13*CA5 -> 551.17356 | CC36: =CC13*CB5 -> 567.90048 | CD36: =CD13*CC5 -> 605.72657 | CE36: =CE13*CD5 -> 632.4071 | CF36: =CF13*CE5 -> 635.60288 | CG36: =CG13*CF5 -> 652.79016 | ... CO36: =CO13*CN5 -> 866.31856 | CT36: 1899.07
A37: NII | B37: =B35-B36 -> 0 | C37: =C35-C36 -> 0 | D37: =D35-D36 -> 0 | E37: =E35-E36 -> 0 | F37: =F35-F36 -> 0 | G37: =G35-G36 -> 0 | H37: =H35-H36 -> 0 | I37: =I35-I36 -> 0 | ... AE37: =AE35-AE36 -> 8541.8202 | AH37: =AH35-AH36 -> 0 | AI37: =AI35-AI36 -> 0 | AJ37: =AJ35-AJ36 -> 0 | AK37: =AK35-AK36 -> 0 | AL37: =AL35-AL36 -> 0 | AM37: =AM35-AM36 -> 0 | AN37: =AN35-AN36 -> 0 | AO37: =AO35-AO36 -> 0 | ... CO37: =CO35-CO36 -> 2207.8036 | CT37: 4159.85
A38: Other Income | B38: =+'Annual Raw'!C27 -> 0 | C38: =+'Annual Raw'!D27 -> 0 | D38: =+'Annual Raw'!E27 -> 0 | E38: =+'Annual Raw'!F27 -> 0 | F38: =+'Annual Raw'!G27 -> 0 | G38: =+'Annual Raw'!H27 -> 0 | H38: =+'Annual Raw'!I27 -> 0 | I38: =+'Annual Raw'!J27 -> 0 | ... AA38: =+'Annual Raw'!AB27 -> 3.62 | AB38: =SUM(BZ38:CC38) -> 4.1860989 | AC38: =SUM(CD38:CG38) -> 4.8131231 | AD38: =SUM(CH38:CK38) -> 5.5477096 | AE38: =SUM(CL38:CO38) -> 6.3870187 | AH38: =+'QTR Raw'!D32 -> 0 | AI38: =+'QTR Raw'!E32 -> 0 | AJ38: =+'QTR Raw'!F32 -> 0 | AK38: =+'QTR Raw'!G32 -> 0 | AL38: =+'QTR Raw'!H32 -> 0 | AM38: =+'QTR Raw'!I32 -> 0 | AN38: =+'QTR Raw'!J32 -> 0 | AO38: =+'QTR Raw'!K32 -> 0 | ... BY38: =+'QTR Raw'!AU32 -> 1.31 | BZ38: =BZ15*BY5 -> 1.0007292 | CA38: =CA15*BZ5 -> 1.0514681 | CB38: =CB15*CA5 -> 1.054174 | CC38: =CC15*CB5 -> 1.0797275 | CD38: =CD15*CC5 -> 1.153565 | CE38: =CE15*CD5 -> 1.2050452 | CF38: =CF15*CE5 -> 1.2114188 | CG38: =CG15*CF5 -> 1.2430941 | ... CO38: =CO15*CN5 -> 1.6503483 | CT38: 3.62
A39: TI | B39: =B37+B38 -> 0 | C39: =C37+C38 -> 0 | D39: =D37+D38 -> 0 | E39: =E37+E38 -> 0 | F39: =F37+F38 -> 0 | G39: =G37+G38 -> 0 | H39: =H37+H38 -> 0 | I39: =I37+I38 -> 0 | ... AE39: =AE37+AE38 -> 8548.2072 | AH39: =AH37+AH38 -> 0 | AI39: =AI37+AI38 -> 0 | AJ39: =AJ37+AJ38 -> 0 | AK39: =AK37+AK38 -> 0 | AL39: =AL37+AL38 -> 0 | AM39: =AM37+AM38 -> 0 | AN39: =AN37+AN38 -> 0 | AO39: =AO37+AO38 -> 0 | ... CO39: =CO37+CO38 -> 2209.454 | CT39: 4163.47
A40: YOY% | C40: =+IF(B39<0,1-C39/B39,C39/B39-1) -> #DIV/0! | D40: =+IF(C39<0,1-D39/C39,D39/C39-1) -> #DIV/0! | E40: =+IF(D39<0,1-E39/D39,E39/D39-1) -> #DIV/0! | F40: =+IF(E39<0,1-F39/E39,F39/E39-1) -> #DIV/0! | G40: =+IF(F39<0,1-G39/F39,G39/F39-1) -> #DIV/0! | H40: =+IF(G39<0,1-H39/G39,H39/G39-1) -> #DIV/0! | I40: =+IF(H39<0,1-I39/H39,I39/H39-1) -> #DIV/0! | J40: =+IF(I39<0,1-J39/I39,J39/I39-1) -> #DIV/0! | ... AE40: =+IF(AD39<0,1-AE39/AD39,AE39/AD39-1) -> 0.15267703 | AL40: =+IF(AH39<0,1-AL39/AH39,AL39/AH39-1) -> #DIV/0! | AM40: =+IF(AI39<0,1-AM39/AI39,AM39/AI39-1) -> #DIV/0! | AN40: =+IF(AJ39<0,1-AN39/AJ39,AN39/AJ39-1) -> #DIV/0! | AO40: =+IF(AK39<0,1-AO39/AK39,AO39/AK39-1) -> #DIV/0! | AP40: =+IF(AL39<0,1-AP39/AL39,AP39/AL39-1) -> #DIV/0! | AQ40: =+IF(AM39<0,1-AQ39/AM39,AQ39/AM39-1) -> #DIV/0! | AR40: =+IF(AN39<0,1-AR39/AN39,AR39/AN39-1) -> #DIV/0! | AS40: =+IF(AO39<0,1-AS39/AO39,AS39/AO39-1) -> #DIV/0! | ... CO40: =+IF(CK39<0,1-CO39/CK39,CO39/CK39-1) -> 0.14957908 | CT40: 0.09531564
A41: Employee Cost | B41: =+'Annual Raw'!C18 -> 0 | C41: =+'Annual Raw'!D18 -> 0 | D41: =+'Annual Raw'!E18 -> 0 | E41: =+'Annual Raw'!F18 -> 0 | F41: =+'Annual Raw'!G18 -> 0 | G41: =+'Annual Raw'!H18 -> 0 | H41: =+'Annual Raw'!I18 -> 0 | I41: =+'Annual Raw'!J18 -> 0 | ... AA41: =+'Annual Raw'!AB18 -> 879.09 | AB41: =SUM(BZ41:CC41) -> 1593.8883 | AC41: =SUM(CD41:CG41) -> 1760.4207 | AD41: =SUM(CH41:CK41) -> 1999.1868 | AE41: =SUM(CL41:CO41) -> 2301.6424 | AH41: =+'QTR Raw'!D20 -> 0 | AI41: =+'QTR Raw'!E20 -> 0 | AJ41: =+'QTR Raw'!F20 -> 0 | AK41: =+'QTR Raw'!G20 -> 0 | AL41: =+'QTR Raw'!H20 -> 0 | AM41: =+'QTR Raw'!I20 -> 0 | AN41: =+'QTR Raw'!J20 -> 0 | AO41: =+'QTR Raw'!K20 -> 0 | ... BY41: =+'QTR Raw'!AU20 -> 211.71 | BZ41: =BZ18*BY5 -> 386.90992 | CA41: =CA18*BZ5 -> 402.46175 | CB41: =CB18*CA5 -> 399.46249 | CC41: =CC18*CB5 -> 405.05412 | CD41: =CD18*CC5 -> 428.42632 | CE41: =CE18*CD5 -> 443.07028 | CF41: =CF18*CE5 -> 440.95958 | CG41: =CG18*CF5 -> 447.96457 | ... CO41: =CO18*CN5 -> 594.72373 | CT41: 879.09
A42: Operating & Establishment Expenses | B42: =+'Annual Raw'!C19+'Annual Raw'!C20+'Annual Raw'!C21+'Annual Raw'!C17+'Annual Raw'!C16+'Annual Raw'!C15-'Annual Raw'!C24 -> 0 | C42: =+'Annual Raw'!D19+'Annual Raw'!D20+'Annual Raw'!D21+'Annual Raw'!D17+'Annual Raw'!D16+'Annual Raw'!D15-'Annual Raw'!D24 -> 0 | D42: =+'Annual Raw'!E19+'Annual Raw'!E20+'Annual Raw'!E21+'Annual Raw'!E17+'Annual Raw'!E16+'Annual Raw'!E15-'Annual Raw'!E24 -> 0 | E42: =+'Annual Raw'!F19+'Annual Raw'!F20+'Annual Raw'!F21+'Annual Raw'!F17+'Annual Raw'!F16+'Annual Raw'!F15-'Annual Raw'!F24 -> 0 | F42: =+'Annual Raw'!G19+'Annual Raw'!G20+'Annual Raw'!G21+'Annual Raw'!G17+'Annual Raw'!G16+'Annual Raw'!G15-'Annual Raw'!G24 -> 0 | G42: =+'Annual Raw'!H19+'Annual Raw'!H20+'Annual Raw'!H21+'Annual Raw'!H17+'Annual Raw'!H16+'Annual Raw'!H15-'Annual Raw'!H24 -> 0 | H42: =+'Annual Raw'!I19+'Annual Raw'!I20+'Annual Raw'!I21+'Annual Raw'!I17+'Annual Raw'!I16+'Annual Raw'!I15-'Annual Raw'!I24 -> 0 | I42: =+'Annual Raw'!J19+'Annual Raw'!J20+'Annual Raw'!J21+'Annual Raw'!J17+'Annual Raw'!J16+'Annual Raw'!J15-'Annual Raw'!J24 -> 0 | ... AA42: =+'Annual Raw'!AB19+'Annual Raw'!AB20+'Annual Raw'!AB21+'Annual Raw'!AB17+'Annual Raw'!AB16+'Annual Raw'!AB15-'Annual Raw'!AB24 -> 373.11 | AB42: =SUM(BZ42:CC42) -> 0 | AC42: =SUM(CD42:CG42) -> 0 | AD42: =SUM(CH42:CK42) -> 0 | AE42: =SUM(CL42:CO42) -> 0 | AH42: =+'QTR Raw'!D15+'QTR Raw'!D21+'QTR Raw'!D17+'QTR Raw'!D18+'QTR Raw'!D19+'QTR Raw'!D16+'QTR Raw'!D25 -> 0 | AI42: =+'QTR Raw'!E15+'QTR Raw'!E21+'QTR Raw'!E17+'QTR Raw'!E18+'QTR Raw'!E19+'QTR Raw'!E16+'QTR Raw'!E25 -> 0 | AJ42: =+'QTR Raw'!F15+'QTR Raw'!F21+'QTR Raw'!F17+'QTR Raw'!F18+'QTR Raw'!F19+'QTR Raw'!F16+'QTR Raw'!F25 -> 0 | AK42: =+'QTR Raw'!G15+'QTR Raw'!G21+'QTR Raw'!G17+'QTR Raw'!G18+'QTR Raw'!G19+'QTR Raw'!G16+'QTR Raw'!G25 -> 0 | AL42: =+'QTR Raw'!H15+'QTR Raw'!H21+'QTR Raw'!H17+'QTR Raw'!H18+'QTR Raw'!H19+'QTR Raw'!H16+'QTR Raw'!H25 -> 0 | AM42: =+'QTR Raw'!I15+'QTR Raw'!I21+'QTR Raw'!I17+'QTR Raw'!I18+'QTR Raw'!I19+'QTR Raw'!I16+'QTR Raw'!I25 -> 0 | AN42: =+'QTR Raw'!J15+'QTR Raw'!J21+'QTR Raw'!J17+'QTR Raw'!J18+'QTR Raw'!J19+'QTR Raw'!J16+'QTR Raw'!J25 -> 0 | AO42: =+'QTR Raw'!K15+'QTR Raw'!K21+'QTR Raw'!K17+'QTR Raw'!K18+'QTR Raw'!K19+'QTR Raw'!K16+'QTR Raw'!K25 -> 0 | ... BY42: =+'QTR Raw'!AU15+'QTR Raw'!AU21+'QTR Raw'!AU17+'QTR Raw'!AU18+'QTR Raw'!AU19+'QTR Raw'!AU16+'QTR Raw'!AU25 -> 112.82 | CT42: 412.69
A43: Depreciation | B43: =+'Annual Raw'!C31 -> 0 | C43: =+'Annual Raw'!D31 -> 0 | D43: =+'Annual Raw'!E31 -> 0 | E43: =+'Annual Raw'!F31 -> 0 | F43: =+'Annual Raw'!G31 -> 0 | G43: =+'Annual Raw'!H31 -> 0 | H43: =+'Annual Raw'!I31 -> 0 | I43: =+'Annual Raw'!J31 -> 0 | ... AA43: =+'Annual Raw'!AB31 -> 63.08 | AB43: =SUM(BZ43:CC43) -> 0 | AC43: =SUM(CD43:CG43) -> 0 | AD43: =SUM(CH43:CK43) -> 0 | AE43: =SUM(CL43:CO43) -> 0 | AH43: =+'QTR Raw'!D37 -> 0 | AI43: =+'QTR Raw'!E37 -> 0 | AJ43: =+'QTR Raw'!F37 -> 0 | AK43: =+'QTR Raw'!G37 -> 0 | AL43: =+'QTR Raw'!H37 -> 0 | AM43: =+'QTR Raw'!I37 -> 0 | AN43: =+'QTR Raw'!J37 -> 0 | AO43: =+'QTR Raw'!K37 -> 0 | ... BY43: =+'QTR Raw'!AU37 -> 15.69 | CT43: 63.09
A44: Advertisement & Sales Promotion | B44: =+'Annual Raw'!C22 -> 0 | C44: =+'Annual Raw'!D22 -> 0 | D44: =+'Annual Raw'!E22 -> 0 | E44: =+'Annual Raw'!F22 -> 0 | F44: =+'Annual Raw'!G22 -> 0 | G44: =+'Annual Raw'!H22 -> 0 | H44: =+'Annual Raw'!I22 -> 0 | I44: =+'Annual Raw'!J22 -> 0 | ... AA44: =+'Annual Raw'!AB22 -> 3.2 | AB44: =SUM(BZ44:CC44) -> 0 | AC44: =SUM(CD44:CG44) -> 0 | AD44: =SUM(CH44:CK44) -> 0 | AE44: =SUM(CL44:CO44) -> 0 | AH44: =+'QTR Raw'!D22 -> 0 | AI44: =+'QTR Raw'!E22 -> 0 | AJ44: =+'QTR Raw'!F22 -> 0 | AK44: =+'QTR Raw'!G22 -> 0 | AL44: =+'QTR Raw'!H22 -> 0 | AM44: =+'QTR Raw'!I22 -> 0 | AN44: =+'QTR Raw'!J22 -> 0 | AO44: =+'QTR Raw'!K22 -> 0 | ... BY44: =+'QTR Raw'!AU22 -> 0 | CT44: 0
A45: Other Expenses | AH45: =+'QTR Raw'!D23+'QTR Raw'!D24+'QTR Raw'!D26 -> 0 | AI45: =+'QTR Raw'!E23+'QTR Raw'!E24+'QTR Raw'!E26 -> 0 | AJ45: =+'QTR Raw'!F23+'QTR Raw'!F24+'QTR Raw'!F26 -> 0 | AK45: =+'QTR Raw'!G23+'QTR Raw'!G24+'QTR Raw'!G26 -> 0 | AL45: =+'QTR Raw'!H23+'QTR Raw'!H24+'QTR Raw'!H26 -> 0 | AM45: =+'QTR Raw'!I23+'QTR Raw'!I24+'QTR Raw'!I26 -> 0 | AN45: =+'QTR Raw'!J23+'QTR Raw'!J24+'QTR Raw'!J26 -> 0 | AO45: =+'QTR Raw'!K23+'QTR Raw'!K24+'QTR Raw'!K26 -> 0 | ... BY45: =+'QTR Raw'!AU23+'QTR Raw'!AU24+'QTR Raw'!AU26 -> 0
A46: TC | B46: =SUM(B41:B45) -> 0 | C46: =SUM(C41:C45) -> 0 | D46: =SUM(D41:D45) -> 0 | E46: =SUM(E41:E45) -> 0 | F46: =SUM(F41:F45) -> 0 | G46: =SUM(G41:G45) -> 0 | H46: =SUM(H41:H45) -> 0 | I46: =SUM(I41:I45) -> 0 | ... AE46: =SUM(AE41:AE45) -> 2301.6424 | AH46: =SUM(AH41:AH45) -> 0 | AI46: =SUM(AI41:AI45) -> 0 | AJ46: =SUM(AJ41:AJ45) -> 0 | AK46: =SUM(AK41:AK45) -> 0 | AL46: =SUM(AL41:AL45) -> 0 | AM46: =SUM(AM41:AM45) -> 0 | AN46: =SUM(AN41:AN45) -> 0 | AO46: =SUM(AO41:AO45) -> 0 | ... CO46: =SUM(CO41:CO45) -> 594.72373 | CT46: 1354.87
A47: PPP | B47: =+B39-B46 -> 0 | C47: =+C39-C46 -> 0 | D47: =+D39-D46 -> 0 | E47: =+E39-E46 -> 0 | F47: =+F39-F46 -> 0 | G47: =+G39-G46 -> 0 | H47: =+H39-H46 -> 0 | I47: =+I39-I46 -> 0 | ... AE47: =+AE39-AE46 -> 6246.5648 | AH47: =+AH39-AH46 -> 0 | AI47: =+AI39-AI46 -> 0 | AJ47: =+AJ39-AJ46 -> 0 | AK47: =+AK39-AK46 -> 0 | AL47: =+AL39-AL46 -> 0 | AM47: =+AM39-AM46 -> 0 | AN47: =+AN39-AN46 -> 0 | AO47: =+AO39-AO46 -> 0 | ... CO47: =+CO39-CO46 -> 1614.7302 | CT47: 2808.6
A48: YOY% | C48: =+IF(B47<0,1-C47/B47,C47/B47-1) -> #DIV/0! | D48: =+IF(C47<0,1-D47/C47,D47/C47-1) -> #DIV/0! | E48: =+IF(D47<0,1-E47/D47,E47/D47-1) -> #DIV/0! | F48: =+IF(E47<0,1-F47/E47,F47/E47-1) -> #DIV/0! | G48: =+IF(F47<0,1-G47/F47,G47/F47-1) -> #DIV/0! | H48: =+IF(G47<0,1-H47/G47,H47/G47-1) -> #DIV/0! | I48: =+IF(H47<0,1-I47/H47,I47/H47-1) -> #DIV/0! | J48: =+IF(I47<0,1-J47/I47,J47/I47-1) -> #DIV/0! | ... AE48: =+IF(AD47<0,1-AE47/AD47,AE47/AD47-1) -> 0.15318921 | AL48: =+IF(AH47<0,1-AL47/AH47,AL47/AH47-1) -> #DIV/0! | AM48: =+IF(AI47<0,1-AM47/AI47,AM47/AI47-1) -> #DIV/0! | AN48: =+IF(AJ47<0,1-AN47/AJ47,AN47/AJ47-1) -> #DIV/0! | AO48: =+IF(AK47<0,1-AO47/AK47,AO47/AK47-1) -> #DIV/0! | AP48: =+IF(AL47<0,1-AP47/AL47,AP47/AL47-1) -> #DIV/0! | AQ48: =+IF(AM47<0,1-AQ47/AM47,AQ47/AM47-1) -> #DIV/0! | AR48: =+IF(AN47<0,1-AR47/AN47,AR47/AN47-1) -> #DIV/0! | AS48: =+IF(AO47<0,1-AS47/AO47,AS47/AO47-1) -> #DIV/0! | ... CO48: =+IF(CK47<0,1-CO47/CK47,CO47/CK47-1) -> 0.14903404 | CT48: 0.053199987
A49: Provisions and Contingencies | B49: =+'Annual Raw'!C23 -> 0 | C49: =+'Annual Raw'!D23 -> 0 | D49: =+'Annual Raw'!E23 -> 0 | E49: =+'Annual Raw'!F23 -> 0 | F49: =+'Annual Raw'!G23 -> 0 | G49: =+'Annual Raw'!H23 -> 0 | H49: =+'Annual Raw'!I23 -> 0 | I49: =+'Annual Raw'!J23 -> 0 | ... AA49: =+'Annual Raw'!AB23 -> 1805.73 | AB49: =SUM(BZ49:CC49) -> 1593.3688 | AC49: =SUM(CD49:CG49) -> 1832.0351 | AD49: =SUM(CH49:CK49) -> 2111.6432 | AE49: =SUM(CL49:CO49) -> 2431.1122 | AH49: =+'QTR Raw'!D36+'QTR Raw'!D27 -> 0 | AI49: =+'QTR Raw'!E36+'QTR Raw'!E27 -> 0 | AJ49: =+'QTR Raw'!F36+'QTR Raw'!F27 -> 0 | AK49: =+'QTR Raw'!G36+'QTR Raw'!G27 -> 0 | AL49: =+'QTR Raw'!H36+'QTR Raw'!H27 -> 0 | AM49: =+'QTR Raw'!I36+'QTR Raw'!I27 -> 0 | AN49: =+'QTR Raw'!J36+'QTR Raw'!J27 -> 0 | AO49: =+'QTR Raw'!K36+'QTR Raw'!K27 -> 0 | ... BY49: =+'QTR Raw'!AU36+'QTR Raw'!AU27 -> 335.31 | BZ49: =BZ20*BY5 -> 380.91088 | CA49: =CA20*BZ5 -> 400.22382 | CB49: =CB20*CA5 -> 401.25378 | CC49: =CC20*CB5 -> 410.98029 | CD49: =CD20*CC5 -> 439.08528 | CE49: =CE20*CD5 -> 458.68038 | CF49: =CF20*CE5 -> 461.10638 | CG49: =CG20*CF5 -> 473.16305 | ... CO49: =CO20*CN5 -> 628.17756 | CT49: 1775.4
...

Sheet Share price Daily
A1: =_xll.EQNXTH(B1,"[ADJC];[ADJH];[ADJL];[ADJO];[UCLS];[VOLUME]","2015-Jan-01","Y","All traded days","Asc") -> EQNXTH | B1: =+'Annual Raw'!A1 -> 221842 | L1: =_xll.EQNXTH(B1,"[NADJC];[NADJH];[NADJLOW];[NADJOPEN];[NUCLOSE];[NVOLUME]","2015-Jan-01","Y","All traded days","Asc") -> EQNXTH
A2: CreditAccess Grameen Ltd. | L2: CreditAccess Grameen Ltd.
A3: DATE | B3: ADJHIGH | C3: ADJCLOSE | D3: ADJLOW | E3: ADJOPEN | F3: CLOSE | G3: VOLUME | L3: DATE | M3: ADJCLOSE | N3: ADJHIGH | O3: ADJLOW | P3: ADJOPEN | Q3: CLOSE | R3: VOLUME
A4: 43335 | B4: 423.3 | C4: 420.8 | D4: 385 | E4: 385 | F4: 420.8 | G4: 1983509 | L4: 43335 | M4: 422.05 | N4: 426.9 | O4: 385 | P4: 390 | Q4: 422.05 | R4: 11600387
A5: 43336 | B5: 418 | C5: 406.65 | D5: 401.85 | E5: 418 | F5: 406.65 | G5: 189848 | L5: 43336 | M5: 406.8 | N5: 420 | O5: 401.75 | P5: 418 | Q5: 406.8 | R5: 785983
A6: 43339 | B6: 407.7 | C6: 400.1 | D6: 394.9 | E6: 407.7 | F6: 400.1 | G6: 61425 | L6: 43339 | M6: 400.25 | N6: 406 | O6: 395 | P6: 406 | Q6: 400.25 | R6: 411202
A7: 43340 | B7: 408 | C7: 396.2 | D7: 395.05 | E7: 399.8 | F7: 396.2 | G7: 60926 | L7: 43340 | M7: 395.8 | N7: 408 | O7: 395 | P7: 397.1 | Q7: 395.8 | R7: 370390
A8: 43341 | B8: 399.45 | C8: 392.25 | D8: 388.2 | E8: 393.1 | F8: 392.25 | G8: 19157 | L8: 43341 | M8: 392.75 | N8: 400 | O8: 389 | P8: 395.8 | Q8: 392.75 | R8: 212493
A9: 43342 | B9: 395 | C9: 380.6 | D9: 374.05 | E9: 388 | F9: 380.6 | G9: 40436 | L9: 43342 | M9: 380.35 | N9: 392 | O9: 373.1 | P9: 388 | Q9: 380.35 | R9: 296385
A10: 43343 | B10: 387.6 | C10: 384.05 | D10: 375.55 | E10: 380 | F10: 384.05 | G10: 31279 | L10: 43343 | M10: 384.95 | N10: 389 | O10: 375.95 | P10: 380.1 | Q10: 384.95 | R10: 256303
A11: 43346 | B11: 387.25 | C11: 381.3 | D11: 380.7 | E11: 385 | F11: 381.3 | G11: 11575 | L11: 43346 | M11: 381.1 | N11: 387.85 | O11: 380.3 | P11: 386.5 | Q11: 381.1 | R11: 80770
A12: 43347 | B12: 383.8 | C12: 380.1 | D12: 375.1 | E12: 383.8 | F12: 380.1 | G12: 62065 | L12: 43347 | M12: 380.3 | N12: 382 | O12: 375.05 | P12: 378.05 | Q12: 380.3 | R12: 162888
A13: 43348 | B13: 380 | C13: 375.7 | D13: 374.1 | E13: 380 | F13: 375.7 | G13: 20987 | L13: 43348 | M13: 376.1 | N13: 380 | O13: 373.4 | P13: 378 | Q13: 376.1 | R13: 183808
A14: 43349 | B14: 394.5 | C14: 383.95 | D14: 376.55 | E14: 376.55 | F14: 383.95 | G14: 23116 | L14: 43349 | M14: 382.65 | N14: 395 | O14: 375 | P14: 375 | Q14: 382.65 | R14: 106322
A15: 43350 | B15: 388.55 | C15: 383.45 | D15: 380.6 | E15: 385 | F15: 383.45 | G15: 6312 | L15: 43350 | M15: 385.25 | N15: 388.65 | O15: 384 | P15: 385 | Q15: 385.25 | R15: 144584
... A2722: 46010 | B2722: 939 | C2722: 932.5 | D2722: 906.25 | E2722: 910.9 | F2722: 932.5 | G2722: 8862 | L2722: 46010 | M2722: 936.6 | N2722: 938.9 | O2722: 905 | P2722: 905 | Q2722: 936.6 | R2722: 296202

Sheet Annual Raw
A1: 221842 | C1: 200103 | D1: 200203 | E1: 200303 | F1: 200403 | G1: 200503 | H1: 200603 | I1: 200703 | J1: 200803 | K1: 200903 | L1: 201003 | M1: 201103 | N1: 201203 | O1: 201303 | P1: 201403 | Q1: 201503 | R1: 201603 | S1: 201703 | T1: 201803 | U1: 201903 | V1: 202003 | W1: 202103 | X1: 202203 | Y1: 202303 | Z1: 202403 | AA1: 202503 | AB1: 202603 | AC1: 202703 | AD1: 202803 | AE1: 202903 | AF1: 203003
B2: {=_xll.EQNXTDZ($A$1,$B3,C$2)} -> CreditAccess Grameen Ltd.
A3: Company Name | B3: CD_COMPNAME
A4: Field Description | B4: Field Name
A5: No of Months | B5: BPL_NO_MONTHS | C5: {=_xll.EQNXTDZ($A$1,$B5,C$1,$B$1)} -> 0 | D5: {=_xll.EQNXTDZ($A$1,$B5,D$1,$B$1)} -> 0 | E5: {=_xll.EQNXTDZ($A$1,$B5,E$1,$B$1)} -> 0 | F5: {=_xll.EQNXTDZ($A$1,$B5,F$1,$B$1)} -> 0 | G5: {=_xll.EQNXTDZ($A$1,$B5,G$1,$B$1)} -> 0 | H5: {=_xll.EQNXTDZ($A$1,$B5,H$1,$B$1)} -> 0 | I5: {=_xll.EQNXTDZ($A$1,$B5,I$1,$B$1)} -> 0 | J5: {=_xll.EQNXTDZ($A$1,$B5,J$1,$B$1)} -> 0 | ... AF5: {=_xll.EQNXTDZ($A$1,$B5,AF$1,$B$1)} -> 0
A6: Year end date | B6: BPL_YEAR_ENDDATE | C6: {=_xll.EQNXTDZ($A$1,$B6,C$1,$B$1)} -> 0 | D6: {=_xll.EQNXTDZ($A$1,$B6,D$1,$B$1)} -> 0 | E6: {=_xll.EQNXTDZ($A$1,$B6,E$1,$B$1)} -> 0 | F6: {=_xll.EQNXTDZ($A$1,$B6,F$1,$B$1)} -> 0 | G6: {=_xll.EQNXTDZ($A$1,$B6,G$1,$B$1)} -> 0 | H6: {=_xll.EQNXTDZ($A$1,$B6,H$1,$B$1)} -> 0 | I6: {=_xll.EQNXTDZ($A$1,$B6,I$1,$B$1)} -> 0 | J6: {=_xll.EQNXTDZ($A$1,$B6,J$1,$B$1)} -> 0 | ... AF6: {=_xll.EQNXTDZ($A$1,$B6,AF$1,$B$1)} -> 0
A8: Field Description | B8: Field Name
A9: Year End | B9: PL_YEAR_END | C9: {=_xll.EQNXTDZ($A$1,$B9,C$1,$B$1)} -> 0 | D9: {=_xll.EQNXTDZ($A$1,$B9,D$1,$B$1)} -> 0 | E9: {=_xll.EQNXTDZ($A$1,$B9,E$1,$B$1)} -> 0 | F9: {=_xll.EQNXTDZ($A$1,$B9,F$1,$B$1)} -> 0 | G9: {=_xll.EQNXTDZ($A$1,$B9,G$1,$B$1)} -> 0 | H9: {=_xll.EQNXTDZ($A$1,$B9,H$1,$B$1)} -> 0 | I9: {=_xll.EQNXTDZ($A$1,$B9,I$1,$B$1)} -> 0 | J9: {=_xll.EQNXTDZ($A$1,$B9,J$1,$B$1)} -> 0 | ... AF9: {=_xll.EQNXTDZ($A$1,$B9,AF$1,$B$1)} -> 0
A10: Year | B10: PL_YEAR | C10: {=_xll.EQNXTDZ($A$1,$B10,C$1,$B$1)} -> 0 | D10: {=_xll.EQNXTDZ($A$1,$B10,D$1,$B$1)} -> 0 | E10: {=_xll.EQNXTDZ($A$1,$B10,E$1,$B$1)} -> 0 | F10: {=_xll.EQNXTDZ($A$1,$B10,F$1,$B$1)} -> 0 | G10: {=_xll.EQNXTDZ($A$1,$B10,G$1,$B$1)} -> 0 | H10: {=_xll.EQNXTDZ($A$1,$B10,H$1,$B$1)} -> 0 | I10: {=_xll.EQNXTDZ($A$1,$B10,I$1,$B$1)} -> 0 | J10: {=_xll.EQNXTDZ($A$1,$B10,J$1,$B$1)} -> 0 | ... AF10: {=_xll.EQNXTDZ($A$1,$B10,AF$1,$B$1)} -> 0
A11: Year end date | B11: PL_YEAR_ENDDATE | C11: {=_xll.EQNXTDZ($A$1,$B11,C$1,$B$1)} -> 0 | D11: {=_xll.EQNXTDZ($A$1,$B11,D$1,$B$1)} -> 0 | E11: {=_xll.EQNXTDZ($A$1,$B11,E$1,$B$1)} -> 0 | F11: {=_xll.EQNXTDZ($A$1,$B11,F$1,$B$1)} -> 0 | G11: {=_xll.EQNXTDZ($A$1,$B11,G$1,$B$1)} -> 0 | H11: {=_xll.EQNXTDZ($A$1,$B11,H$1,$B$1)} -> 0 | I11: {=_xll.EQNXTDZ($A$1,$B11,I$1,$B$1)} -> 0 | J11: {=_xll.EQNXTDZ($A$1,$B11,J$1,$B$1)} -> 0 | ... AF11: {=_xll.EQNXTDZ($A$1,$B11,AF$1,$B$1)} -> 0
A12: No of Months | B12: PL_NO_MONTHS | C12: {=_xll.EQNXTDZ($A$1,$B12,C$1,$B$1)} -> 0 | D12: {=_xll.EQNXTDZ($A$1,$B12,D$1,$B$1)} -> 0 | E12: {=_xll.EQNXTDZ($A$1,$B12,E$1,$B$1)} -> 0 | F12: {=_xll.EQNXTDZ($A$1,$B12,F$1,$B$1)} -> 0 | G12: {=_xll.EQNXTDZ($A$1,$B12,G$1,$B$1)} -> 0 | H12: {=_xll.EQNXTDZ($A$1,$B12,H$1,$B$1)} -> 0 | I12: {=_xll.EQNXTDZ($A$1,$B12,I$1,$B$1)} -> 0 | J12: {=_xll.EQNXTDZ($A$1,$B12,J$1,$B$1)} -> 0 | ... AF12: {=_xll.EQNXTDZ($A$1,$B12,AF$1,$B$1)} -> 0
A13: Sales Turnover | B13: PL_TOTAL_GROSS_SALES | C13: {=_xll.EQNXTDZ($A$1,$B13,C$1,$B$1)} -> 0 | D13: {=_xll.EQNXTDZ($A$1,$B13,D$1,$B$1)} -> 0 | E13: {=_xll.EQNXTDZ($A$1,$B13,E$1,$B$1)} -> 0 | F13: {=_xll.EQNXTDZ($A$1,$B13,F$1,$B$1)} -> 0 | G13: {=_xll.EQNXTDZ($A$1,$B13,G$1,$B$1)} -> 0 | H13: {=_xll.EQNXTDZ($A$1,$B13,H$1,$B$1)} -> 0 | I13: {=_xll.EQNXTDZ($A$1,$B13,I$1,$B$1)} -> 0 | J13: {=_xll.EQNXTDZ($A$1,$B13,J$1,$B$1)} -> 0 | ... AF13: {=_xll.EQNXTDZ($A$1,$B13,AF$1,$B$1)} -> 0
A14: Net Sales | B14: PL_NET_SALES | C14: {=_xll.EQNXTDZ($A$1,$B14,C$1,$B$1)} -> 0 | D14: {=_xll.EQNXTDZ($A$1,$B14,D$1,$B$1)} -> 0 | E14: {=_xll.EQNXTDZ($A$1,$B14,E$1,$B$1)} -> 0 | F14: {=_xll.EQNXTDZ($A$1,$B14,F$1,$B$1)} -> 0 | G14: {=_xll.EQNXTDZ($A$1,$B14,G$1,$B$1)} -> 0 | H14: {=_xll.EQNXTDZ($A$1,$B14,H$1,$B$1)} -> 0 | I14: {=_xll.EQNXTDZ($A$1,$B14,I$1,$B$1)} -> 0 | J14: {=_xll.EQNXTDZ($A$1,$B14,J$1,$B$1)} -> 0 | ... AF14: {=_xll.EQNXTDZ($A$1,$B14,AF$1,$B$1)} -> 0
A15: Increase/Decrease in Stock | B15: PL_INC_DEC_INVENTORY | C15: {=_xll.EQNXTDZ($A$1,$B15,C$1,$B$1)} -> 0 | D15: {=_xll.EQNXTDZ($A$1,$B15,D$1,$B$1)} -> 0 | E15: {=_xll.EQNXTDZ($A$1,$B15,E$1,$B$1)} -> 0 | F15: {=_xll.EQNXTDZ($A$1,$B15,F$1,$B$1)} -> 0 | G15: {=_xll.EQNXTDZ($A$1,$B15,G$1,$B$1)} -> 0 | H15: {=_xll.EQNXTDZ($A$1,$B15,H$1,$B$1)} -> 0 | I15: {=_xll.EQNXTDZ($A$1,$B15,I$1,$B$1)} -> 0 | J15: {=_xll.EQNXTDZ($A$1,$B15,J$1,$B$1)} -> 0 | ... AF15: {=_xll.EQNXTDZ($A$1,$B15,AF$1,$B$1)} -> 0
A16: Raw Material Consumed | B16: PL_RAW_MATRS_CONSUMED | C16: {=_xll.EQNXTDZ($A$1,$B16,C$1,$B$1)} -> 0 | D16: {=_xll.EQNXTDZ($A$1,$B16,D$1,$B$1)} -> 0 | E16: {=_xll.EQNXTDZ($A$1,$B16,E$1,$B$1)} -> 0 | F16: {=_xll.EQNXTDZ($A$1,$B16,F$1,$B$1)} -> 0 | G16: {=_xll.EQNXTDZ($A$1,$B16,G$1,$B$1)} -> 0 | H16: {=_xll.EQNXTDZ($A$1,$B16,H$1,$B$1)} -> 0 | I16: {=_xll.EQNXTDZ($A$1,$B16,I$1,$B$1)} -> 0 | J16: {=_xll.EQNXTDZ($A$1,$B16,J$1,$B$1)} -> 0 | ... AF16: {=_xll.EQNXTDZ($A$1,$B16,AF$1,$B$1)} -> 0
A17: Power & Fuel Cost | B17: PL_POWER_FUEL | C17: {=_xll.EQNXTDZ($A$1,$B17,C$1,$B$1)} -> 0 | D17: {=_xll.EQNXTDZ($A$1,$B17,D$1,$B$1)} -> 0 | E17: {=_xll.EQNXTDZ($A$1,$B17,E$1,$B$1)} -> 0 | F17: {=_xll.EQNXTDZ($A$1,$B17,F$1,$B$1)} -> 0 | G17: {=_xll.EQNXTDZ($A$1,$B17,G$1,$B$1)} -> 0 | H17: {=_xll.EQNXTDZ($A$1,$B17,H$1,$B$1)} -> 0 | I17: {=_xll.EQNXTDZ($A$1,$B17,I$1,$B$1)} -> 0 | J17: {=_xll.EQNXTDZ($A$1,$B17,J$1,$B$1)} -> 0 | ... AF17: {=_xll.EQNXTDZ($A$1,$B17,AF$1,$B$1)} -> 0
A18: Employee Cost | B18: PL_EMPLOYEES | C18: {=_xll.EQNXTDZ($A$1,$B18,C$1,$B$1)} -> 0 | D18: {=_xll.EQNXTDZ($A$1,$B18,D$1,$B$1)} -> 0 | E18: {=_xll.EQNXTDZ($A$1,$B18,E$1,$B$1)} -> 0 | F18: {=_xll.EQNXTDZ($A$1,$B18,F$1,$B$1)} -> 0 | G18: {=_xll.EQNXTDZ($A$1,$B18,G$1,$B$1)} -> 0 | H18: {=_xll.EQNXTDZ($A$1,$B18,H$1,$B$1)} -> 0 | I18: {=_xll.EQNXTDZ($A$1,$B18,I$1,$B$1)} -> 0 | J18: {=_xll.EQNXTDZ($A$1,$B18,J$1,$B$1)} -> 0 | ... AF18: {=_xll.EQNXTDZ($A$1,$B18,AF$1,$B$1)} -> 0
A19: Operating & Manufacturing Expenses | B19: PL_GEN_OTHER_MFG_EXPS | C19: {=_xll.EQNXTDZ($A$1,$B19,C$1,$B$1)} -> 0 | D19: {=_xll.EQNXTDZ($A$1,$B19,D$1,$B$1)} -> 0 | E19: {=_xll.EQNXTDZ($A$1,$B19,E$1,$B$1)} -> 0 | F19: {=_xll.EQNXTDZ($A$1,$B19,F$1,$B$1)} -> 0 | G19: {=_xll.EQNXTDZ($A$1,$B19,G$1,$B$1)} -> 0 | H19: {=_xll.EQNXTDZ($A$1,$B19,H$1,$B$1)} -> 0 | I19: {=_xll.EQNXTDZ($A$1,$B19,I$1,$B$1)} -> 0 | J19: {=_xll.EQNXTDZ($A$1,$B19,J$1,$B$1)} -> 0 | ... AF19: {=_xll.EQNXTDZ($A$1,$B19,AF$1,$B$1)} -> 0
A20: Cost of Software development | B20: PL_COST_SW | C20: {=_xll.EQNXTDZ($A$1,$B20,C$1,$B$1)} -> 0 | D20: {=_xll.EQNXTDZ($A$1,$B20,D$1,$B$1)} -> 0 | E20: {=_xll.EQNXTDZ($A$1,$B20,E$1,$B$1)} -> 0 | F20: {=_xll.EQNXTDZ($A$1,$B20,F$1,$B$1)} -> 0 | G20: {=_xll.EQNXTDZ($A$1,$B20,G$1,$B$1)} -> 0 | H20: {=_xll.EQNXTDZ($A$1,$B20,H$1,$B$1)} -> 0 | I20: {=_xll.EQNXTDZ($A$1,$B20,I$1,$B$1)} -> 0 | J20: {=_xll.EQNXTDZ($A$1,$B20,J$1,$B$1)} -> 0 | ... AF20: {=_xll.EQNXTDZ($A$1,$B20,AF$1,$B$1)} -> 0
... A49: Consolidated Net Profit | B49: PLC_CONSOLIDATED_NETPROFIT | C49: {=_xll.EQNXTDZ($A$1,$B49,C$1,$B$1)} -> 0 | D49: {=_xll.EQNXTDZ($A$1,$B49,D$1,$B$1)} -> 0 | E49: {=_xll.EQNXTDZ($A$1,$B49,E$1,$B$1)} -> 0 | F49: {=_xll.EQNXTDZ($A$1,$B49,F$1,$B$1)} -> 0 | G49: {=_xll.EQNXTDZ($A$1,$B49,G$1,$B$1)} -> 0 | H49: {=_xll.EQNXTDZ($A$1,$B49,H$1,$B$1)} -> 0 | I49: {=_xll.EQNXTDZ($A$1,$B49,I$1,$B$1)} -> 0 | J49: {=_xll.EQNXTDZ($A$1,$B49,J$1,$B$1)} -> 0 | ... AF49: {=_xll.EQNXTDZ($A$1,$B49,AF$1,$B$1)} -> 0
A51: Field Description | B51: Field Name
A52: Equity Paid Up | B52: FH_EQUITY_PAIDUP | C52: {=_xll.EQNXTDZ($A$1,$B52,C$1,$B$1)} -> 0 | D52: {=_xll.EQNXTDZ($A$1,$B52,D$1,$B$1)} -> 0 | E52: {=_xll.EQNXTDZ($A$1,$B52,E$1,$B$1)} -> 0 | F52: {=_xll.EQNXTDZ($A$1,$B52,F$1,$B$1)} -> 0 | G52: {=_xll.EQNXTDZ($A$1,$B52,G$1,$B$1)} -> 0 | H52: {=_xll.EQNXTDZ($A$1,$B52,H$1,$B$1)} -> 0 | I52: {=_xll.EQNXTDZ($A$1,$B52,I$1,$B$1)} -> 0 | J52: {=_xll.EQNXTDZ($A$1,$B52,J$1,$B$1)} -> 0 | ... AF52: {=_xll.EQNXTDZ($A$1,$B52,AF$1,$B$1)} -> 0
A53: Reserves and Surplus | B53: FH_RESERVE | C53: {=_xll.EQNXTDZ($A$1,$B53,C$1,$B$1)} -> 0 | D53: {=_xll.EQNXTDZ($A$1,$B53,D$1,$B$1)} -> 0 | E53: {=_xll.EQNXTDZ($A$1,$B53,E$1,$B$1)} -> 0 | F53: {=_xll.EQNXTDZ($A$1,$B53,F$1,$B$1)} -> 0 | G53: {=_xll.EQNXTDZ($A$1,$B53,G$1,$B$1)} -> 0 | H53: {=_xll.EQNXTDZ($A$1,$B53,H$1,$B$1)} -> 0 | I53: {=_xll.EQNXTDZ($A$1,$B53,I$1,$B$1)} -> 0 | J53: {=_xll.EQNXTDZ($A$1,$B53,J$1,$B$1)} -> 0 | ... AF53: {=_xll.EQNXTDZ($A$1,$B53,AF$1,$B$1)} -> 0
A54: Net Worth | B54: FH_NET_WORTH | C54: {=_xll.EQNXTDZ($A$1,$B54,C$1,$B$1)} -> 0 | D54: {=_xll.EQNXTDZ($A$1,$B54,D$1,$B$1)} -> 0 | E54: {=_xll.EQNXTDZ($A$1,$B54,E$1,$B$1)} -> 0 | F54: {=_xll.EQNXTDZ($A$1,$B54,F$1,$B$1)} -> 0 | G54: {=_xll.EQNXTDZ($A$1,$B54,G$1,$B$1)} -> 0 | H54: {=_xll.EQNXTDZ($A$1,$B54,H$1,$B$1)} -> 0 | I54: {=_xll.EQNXTDZ($A$1,$B54,I$1,$B$1)} -> 0 | J54: {=_xll.EQNXTDZ($A$1,$B54,J$1,$B$1)} -> 0 | ... AF54: {=_xll.EQNXTDZ($A$1,$B54,AF$1,$B$1)} -> 0
A55: Total Debt | B55: FH_TOTAL_DEBTS | C55: {=_xll.EQNXTDZ($A$1,$B55,C$1,$B$1)} -> 0 | D55: {=_xll.EQNXTDZ($A$1,$B55,D$1,$B$1)} -> 0 | E55: {=_xll.EQNXTDZ($A$1,$B55,E$1,$B$1)} -> 0 | F55: {=_xll.EQNXTDZ($A$1,$B55,F$1,$B$1)} -> 0 | G55: {=_xll.EQNXTDZ($A$1,$B55,G$1,$B$1)} -> 0 | H55: {=_xll.EQNXTDZ($A$1,$B55,H$1,$B$1)} -> 0 | I55: {=_xll.EQNXTDZ($A$1,$B55,I$1,$B$1)} -> 0 | J55: {=_xll.EQNXTDZ($A$1,$B55,J$1,$B$1)} -> 0 | ... AF55: {=_xll.EQNXTDZ($A$1,$B55,AF$1,$B$1)} -> 0
A56: Deposits | B56: FH_DEPOSITS | C56: {=_xll.EQNXTDZ($A$1,$B56,C$1,$B$1)} -> 0 | D56: {=_xll.EQNXTDZ($A$1,$B56,D$1,$B$1)} -> 0 | E56: {=_xll.EQNXTDZ($A$1,$B56,E$1,$B$1)} -> 0 | F56: {=_xll.EQNXTDZ($A$1,$B56,F$1,$B$1)} -> 0 | G56: {=_xll.EQNXTDZ($A$1,$B56,G$1,$B$1)} -> 0 | H56: {=_xll.EQNXTDZ($A$1,$B56,H$1,$B$1)} -> 0 | I56: {=_xll.EQNXTDZ($A$1,$B56,I$1,$B$1)} -> 0 | J56: {=_xll.EQNXTDZ($A$1,$B56,J$1,$B$1)} -> 0 | ... AF56: {=_xll.EQNXTDZ($A$1,$B56,AF$1,$B$1)} -> 0
A57: Borrowings | B57: FH_BORROWINGS | C57: {=_xll.EQNXTDZ($A$1,$B57,C$1,$B$1)} -> 0 | D57: {=_xll.EQNXTDZ($A$1,$B57,D$1,$B$1)} -> 0 | E57: {=_xll.EQNXTDZ($A$1,$B57,E$1,$B$1)} -> 0 | F57: {=_xll.EQNXTDZ($A$1,$B57,F$1,$B$1)} -> 0 | G57: {=_xll.EQNXTDZ($A$1,$B57,G$1,$B$1)} -> 0 | H57: {=_xll.EQNXTDZ($A$1,$B57,H$1,$B$1)} -> 0 | I57: {=_xll.EQNXTDZ($A$1,$B57,I$1,$B$1)} -> 0 | J57: {=_xll.EQNXTDZ($A$1,$B57,J$1,$B$1)} -> 0 | ... AF57: {=_xll.EQNXTDZ($A$1,$B57,AF$1,$B$1)} -> 0
A58: Month End | B58: BMONTH_MONTHEND | C58: {=_xll.EQNXTDZ($A$1,$B58,C$1,$B$1)} -> 0 | D58: {=_xll.EQNXTDZ($A$1,$B58,D$1,$B$1)} -> 0 | E58: {=_xll.EQNXTDZ($A$1,$B58,E$1,$B$1)} -> 0 | F58: {=_xll.EQNXTDZ($A$1,$B58,F$1,$B$1)} -> 0 | G58: {=_xll.EQNXTDZ($A$1,$B58,G$1,$B$1)} -> 0 | H58: {=_xll.EQNXTDZ($A$1,$B58,H$1,$B$1)} -> 0 | I58: {=_xll.EQNXTDZ($A$1,$B58,I$1,$B$1)} -> 0 | J58: {=_xll.EQNXTDZ($A$1,$B58,J$1,$B$1)} -> 0 | ... AF58: {=_xll.EQNXTDZ($A$1,$B58,AF$1,$B$1)} -> 0
A59: Close Price (Unit Curr.) | B59: FH_YEAR_PRICE | C59: {=_xll.EQNXTDZ($A$1,$B59,C$1,$B$1)} -> 0 | D59: {=_xll.EQNXTDZ($A$1,$B59,D$1,$B$1)} -> 0 | E59: {=_xll.EQNXTDZ($A$1,$B59,E$1,$B$1)} -> 0 | F59: {=_xll.EQNXTDZ($A$1,$B59,F$1,$B$1)} -> 0 | G59: {=_xll.EQNXTDZ($A$1,$B59,G$1,$B$1)} -> 0 | H59: {=_xll.EQNXTDZ($A$1,$B59,H$1,$B$1)} -> 0 | I59: {=_xll.EQNXTDZ($A$1,$B59,I$1,$B$1)} -> 0 | J59: {=_xll.EQNXTDZ($A$1,$B59,J$1,$B$1)} -> 0 | ... AF59: {=_xll.EQNXTDZ($A$1,$B59,AF$1,$B$1)} -> 0
A60: High Price (Unit Curr.) | B60: FH_HIGH | C60: {=_xll.EQNXTDZ($A$1,$B60,C$1,$B$1)} -> 0 | D60: {=_xll.EQNXTDZ($A$1,$B60,D$1,$B$1)} -> 0 | E60: {=_xll.EQNXTDZ($A$1,$B60,E$1,$B$1)} -> 0 | F60: {=_xll.EQNXTDZ($A$1,$B60,F$1,$B$1)} -> 0 | G60: {=_xll.EQNXTDZ($A$1,$B60,G$1,$B$1)} -> 0 | H60: {=_xll.EQNXTDZ($A$1,$B60,H$1,$B$1)} -> 0 | I60: {=_xll.EQNXTDZ($A$1,$B60,I$1,$B$1)} -> 0 | J60: {=_xll.EQNXTDZ($A$1,$B60,J$1,$B$1)} -> 0 | ... AF60: {=_xll.EQNXTDZ($A$1,$B60,AF$1,$B$1)} -> 0
A61: Low Price (Unit Curr.) | B61: FH_LOW | C61: {=_xll.EQNXTDZ($A$1,$B61,C$1,$B$1)} -> 0 | D61: {=_xll.EQNXTDZ($A$1,$B61,D$1,$B$1)} -> 0 | E61: {=_xll.EQNXTDZ($A$1,$B61,E$1,$B$1)} -> 0 | F61: {=_xll.EQNXTDZ($A$1,$B61,F$1,$B$1)} -> 0 | G61: {=_xll.EQNXTDZ($A$1,$B61,G$1,$B$1)} -> 0 | H61: {=_xll.EQNXTDZ($A$1,$B61,H$1,$B$1)} -> 0 | I61: {=_xll.EQNXTDZ($A$1,$B61,I$1,$B$1)} -> 0 | J61: {=_xll.EQNXTDZ($A$1,$B61,J$1,$B$1)} -> 0 | ... AF61: {=_xll.EQNXTDZ($A$1,$B61,AF$1,$B$1)} -> 0
A62: Month end date | B62: BMONTH_CLOSEDATE | C62: {=_xll.EQNXTDZ($A$1,$B62,C$1,$B$1)} -> 0 | D62: {=_xll.EQNXTDZ($A$1,$B62,D$1,$B$1)} -> 0 | E62: {=_xll.EQNXTDZ($A$1,$B62,E$1,$B$1)} -> 0 | F62: {=_xll.EQNXTDZ($A$1,$B62,F$1,$B$1)} -> 0 | G62: {=_xll.EQNXTDZ($A$1,$B62,G$1,$B$1)} -> 0 | H62: {=_xll.EQNXTDZ($A$1,$B62,H$1,$B$1)} -> 0 | I62: {=_xll.EQNXTDZ($A$1,$B62,I$1,$B$1)} -> 0 | J62: {=_xll.EQNXTDZ($A$1,$B62,J$1,$B$1)} -> 0 | ... AF62: {=_xll.EQNXTDZ($A$1,$B62,AF$1,$B$1)} -> 0
A63: Volume ('000) | B63: BMONTH_VOLUME | C63: {=_xll.EQNXTDZ($A$1,$B63,C$1,$B$1)} -> 0 | D63: {=_xll.EQNXTDZ($A$1,$B63,D$1,$B$1)} -> 0 | E63: {=_xll.EQNXTDZ($A$1,$B63,E$1,$B$1)} -> 0 | F63: {=_xll.EQNXTDZ($A$1,$B63,F$1,$B$1)} -> 0 | G63: {=_xll.EQNXTDZ($A$1,$B63,G$1,$B$1)} -> 0 | H63: {=_xll.EQNXTDZ($A$1,$B63,H$1,$B$1)} -> 0 | I63: {=_xll.EQNXTDZ($A$1,$B63,I$1,$B$1)} -> 0 | J63: {=_xll.EQNXTDZ($A$1,$B63,J$1,$B$1)} -> 0 | ... AF63: {=_xll.EQNXTDZ($A$1,$B63,AF$1,$B$1)} -> 0
... A68: NIM_Reported (%) | B68: RBI_NIMAR | C68: {=_xll.EQNXTDZ($A$1,$B68,C$1,$B$1)} -> 0 | D68: {=_xll.EQNXTDZ($A$1,$B68,D$1,$B$1)} -> 0 | E68: {=_xll.EQNXTDZ($A$1,$B68,E$1,$B$1)} -> 0 | F68: {=_xll.EQNXTDZ($A$1,$B68,F$1,$B$1)} -> 0 | G68: {=_xll.EQNXTDZ($A$1,$B68,G$1,$B$1)} -> 0 | H68: {=_xll.EQNXTDZ($A$1,$B68,H$1,$B$1)} -> 0 | I68: {=_xll.EQNXTDZ($A$1,$B68,I$1,$B$1)} -> 0 | J68: {=_xll.EQNXTDZ($A$1,$B68,J$1,$B$1)} -> 0 | ... AF68: {=_xll.EQNXTDZ($A$1,$B68,AF$1,$B$1)} -> 0
A70: Assets | C70: =+C85+C104+C106-C107-C108+C110+C111+C113+C114+C115+C116+C117+C119+C120+C121+C122+C123+C124+C125+C105+C112 -> 0 | D70: =+D85+D104+D106-D107-D108+D110+D111+D113+D114+D115+D116+D117+D119+D120+D121+D122+D123+D124+D125+D105+D112 -> 0 | E70: =+E85+E104+E106-E107-E108+E110+E111+E113+E114+E115+E116+E117+E119+E120+E121+E122+E123+E124+E125+E105+E112 -> 0 | F70: =+F85+F104+F106-F107-F108+F110+F111+F113+F114+F115+F116+F117+F119+F120+F121+F122+F123+F124+F125+F105+F112 -> 0 | G70: =+G85+G104+G106-G107-G108+G110+G111+G113+G114+G115+G116+G117+G119+G120+G121+G122+G123+G124+G125+G105+G112 -> 0 | H70: =+H85+H104+H106-H107-H108+H110+H111+H113+H114+H115+H116+H117+H119+H120+H121+H122+H123+H124+H125+H105+H112 -> 0 | I70: =+I85+I104+I106-I107-I108+I110+I111+I113+I114+I115+I116+I117+I119+I120+I121+I122+I123+I124+I125+I105+I112 -> 0 | J70: =+J85+J104+J106-J107-J108+J110+J111+J113+J114+J115+J116+J117+J119+J120+J121+J122+J123+J124+J125+J105+J112 -> 0 | ... AF70: =+AF85+AF104+AF106-AF107-AF108+AF110+AF111+AF113+AF114+AF115+AF116+AF117+AF119+AF120+AF121+AF122+AF123+AF124+AF125+AF105+AF112 -> 0
A71: Liab | C71: =+C77+C78+C79+C81+C82+C83+C84+C86+C87+C88+C89+C90+C91+C93+C94+C99+C100+C101 -> 0 | D71: =+D77+D78+D79+D81+D82+D83+D84+D86+D87+D88+D89+D90+D91+D93+D94+D99+D100+D101 -> 0 | E71: =+E77+E78+E79+E81+E82+E83+E84+E86+E87+E88+E89+E90+E91+E93+E94+E99+E100+E101 -> 0 | F71: =+F77+F78+F79+F81+F82+F83+F84+F86+F87+F88+F89+F90+F91+F93+F94+F99+F100+F101 -> 0 | G71: =+G77+G78+G79+G81+G82+G83+G84+G86+G87+G88+G89+G90+G91+G93+G94+G99+G100+G101 -> 0 | H71: =+H77+H78+H79+H81+H82+H83+H84+H86+H87+H88+H89+H90+H91+H93+H94+H99+H100+H101 -> 0 | I71: =+I77+I78+I79+I81+I82+I83+I84+I86+I87+I88+I89+I90+I91+I93+I94+I99+I100+I101 -> 0 | J71: =+J77+J78+J79+J81+J82+J83+J84+J86+J87+J88+J89+J90+J91+J93+J94+J99+J100+J101 -> 0 | ... AF71: =+AF77+AF78+AF79+AF81+AF82+AF83+AF84+AF86+AF87+AF88+AF89+AF90+AF91+AF93+AF94+AF99+AF100+AF101 -> 0
A72: Field Description | B72: Field Name
A73: Year End | B73: BBS_YEAR_END | C73: {=_xll.EQNXTDZ($A$1,$B73,C$1,$B$1)} -> 0 | D73: {=_xll.EQNXTDZ($A$1,$B73,D$1,$B$1)} -> 0 | E73: {=_xll.EQNXTDZ($A$1,$B73,E$1,$B$1)} -> 0 | F73: {=_xll.EQNXTDZ($A$1,$B73,F$1,$B$1)} -> 0 | G73: {=_xll.EQNXTDZ($A$1,$B73,G$1,$B$1)} -> 0 | H73: {=_xll.EQNXTDZ($A$1,$B73,H$1,$B$1)} -> 0 | I73: {=_xll.EQNXTDZ($A$1,$B73,I$1,$B$1)} -> 0 | J73: {=_xll.EQNXTDZ($A$1,$B73,J$1,$B$1)} -> 0 | ... AF73: {=_xll.EQNXTDZ($A$1,$B73,AF$1,$B$1)} -> 0
A74: Year | B74: BBS_YEAR | C74: {=_xll.EQNXTDZ($A$1,$B74,C$1,$B$1)} -> 0 | D74: {=_xll.EQNXTDZ($A$1,$B74,D$1,$B$1)} -> 0 | E74: {=_xll.EQNXTDZ($A$1,$B74,E$1,$B$1)} -> 0 | F74: {=_xll.EQNXTDZ($A$1,$B74,F$1,$B$1)} -> 0 | G74: {=_xll.EQNXTDZ($A$1,$B74,G$1,$B$1)} -> 0 | H74: {=_xll.EQNXTDZ($A$1,$B74,H$1,$B$1)} -> 0 | I74: {=_xll.EQNXTDZ($A$1,$B74,I$1,$B$1)} -> 0 | J74: {=_xll.EQNXTDZ($A$1,$B74,J$1,$B$1)} -> 0 | ... AF74: {=_xll.EQNXTDZ($A$1,$B74,AF$1,$B$1)} -> 0
A75: No of Months | B75: BBS_NO_MONTHS | C75: {=_xll.EQNXTDZ($A$1,$B75,C$1,$B$1)} -> 0 | D75: {=_xll.EQNXTDZ($A$1,$B75,D$1,$B$1)} -> 0 | E75: {=_xll.EQNXTDZ($A$1,$B75,E$1,$B$1)} -> 0 | F75: {=_xll.EQNXTDZ($A$1,$B75,F$1,$B$1)} -> 0 | G75: {=_xll.EQNXTDZ($A$1,$B75,G$1,$B$1)} -> 0 | H75: {=_xll.EQNXTDZ($A$1,$B75,H$1,$B$1)} -> 0 | I75: {=_xll.EQNXTDZ($A$1,$B75,I$1,$B$1)} -> 0 | J75: {=_xll.EQNXTDZ($A$1,$B75,J$1,$B$1)} -> 0 | ... AF75: {=_xll.EQNXTDZ($A$1,$B75,AF$1,$B$1)} -> 0
...

Sheet QTR Raw
A1: =+'Annual Raw'!A1 -> 221842 | B1: X | C1: 201503 | D1: 201506 | E1: 201509 | F1: 201512 | G1: 201603 | H1: 201606 | I1: 201609 | J1: 201612 | K1: 201703 | L1: 201706 | M1: 201709 | N1: 201712 | O1: 201803 | P1: 201806 | Q1: 201809 | R1: 201812 | S1: 201903 | T1: 201906 | U1: 201909 | V1: 201912 | W1: 202003 | X1: 202006 | Y1: 202009 | Z1: 202012 | AA1: 202103 | AB1: 202106 | AC1: 202109 | AD1: 202112 | AE1: 202203 | AF1: 202206 | AG1: 202209 | AH1: 202212 | AI1: 202303 | AJ1: 202306 | AK1: 202309 | AL1: 202312 | AM1: 202403 | AN1: 202406 | AO1: 202409 | AP1: 202412 | AQ1: 202503 | AR1: 202506 | AS1: 202509 | AT1: 202512 | AU1: 202603 | AV1: 202606 | AW1: 202609 | AX1: 202612 | AY1: 202703 | AZ1: 202706 | BA1: 202709 | BB1: 202712 | BC1: 202803 | BD1: 202806 | BE1: 202809 | BF1: 202812 | BG1: 202903 | BH1: 202906 | BI1: 202909 | BJ1: 202912 | BK1: 203003
A4: Field Description | B4: Field Name
A5: Date End | B5: BQTR_DATE_END | C5: {=+_xll.EQNXTDZ($A$1,$B5,C$1,$B$1)} -> 0 | D5: {=+_xll.EQNXTDZ($A$1,$B5,D$1,$B$1)} -> 0 | E5: {=+_xll.EQNXTDZ($A$1,$B5,E$1,$B$1)} -> 0 | F5: {=+_xll.EQNXTDZ($A$1,$B5,F$1,$B$1)} -> 0 | G5: {=+_xll.EQNXTDZ($A$1,$B5,G$1,$B$1)} -> 0 | H5: {=+_xll.EQNXTDZ($A$1,$B5,H$1,$B$1)} -> 0 | I5: {=+_xll.EQNXTDZ($A$1,$B5,I$1,$B$1)} -> 0 | J5: {=+_xll.EQNXTDZ($A$1,$B5,J$1,$B$1)} -> 0 | ... BK5: {=+_xll.EQNXTDZ($A$1,$B5,BK$1,$B$1)} -> 0
A6: Field Description | B6: Field Name
A7: Date End | B7: QTR_DATE_END | C7: {=+_xll.EQNXTDZ($A$1,$B7,C$1,$B$1)} -> 0 | D7: {=+_xll.EQNXTDZ($A$1,$B7,D$1,$B$1)} -> 0 | E7: {=+_xll.EQNXTDZ($A$1,$B7,E$1,$B$1)} -> 0 | F7: {=+_xll.EQNXTDZ($A$1,$B7,F$1,$B$1)} -> 0 | G7: {=+_xll.EQNXTDZ($A$1,$B7,G$1,$B$1)} -> 0 | H7: {=+_xll.EQNXTDZ($A$1,$B7,H$1,$B$1)} -> 0 | I7: {=+_xll.EQNXTDZ($A$1,$B7,I$1,$B$1)} -> 0 | J7: {=+_xll.EQNXTDZ($A$1,$B7,J$1,$B$1)} -> 0 | ... BK7: {=+_xll.EQNXTDZ($A$1,$B7,BK$1,$B$1)} -> 0
A8: Gross Sales | B8: QTR_GROSS_SALE | C8: {=+_xll.EQNXTDZ($A$1,$B8,C$1,$B$1)} -> 0 | D8: {=+_xll.EQNXTDZ($A$1,$B8,D$1,$B$1)} -> 0 | E8: {=+_xll.EQNXTDZ($A$1,$B8,E$1,$B$1)} -> 0 | F8: {=+_xll.EQNXTDZ($A$1,$B8,F$1,$B$1)} -> 0 | G8: {=+_xll.EQNXTDZ($A$1,$B8,G$1,$B$1)} -> 0 | H8: {=+_xll.EQNXTDZ($A$1,$B8,H$1,$B$1)} -> 0 | I8: {=+_xll.EQNXTDZ($A$1,$B8,I$1,$B$1)} -> 0 | J8: {=+_xll.EQNXTDZ($A$1,$B8,J$1,$B$1)} -> 0 | ... BK8: {=+_xll.EQNXTDZ($A$1,$B8,BK$1,$B$1)} -> 0
A9: Net Sales | B9: QTR_OTHER_NETSALES | C9: {=+_xll.EQNXTDZ($A$1,$B9,C$1,$B$1)} -> 0 | D9: {=+_xll.EQNXTDZ($A$1,$B9,D$1,$B$1)} -> 0 | E9: {=+_xll.EQNXTDZ($A$1,$B9,E$1,$B$1)} -> 0 | F9: {=+_xll.EQNXTDZ($A$1,$B9,F$1,$B$1)} -> 0 | G9: {=+_xll.EQNXTDZ($A$1,$B9,G$1,$B$1)} -> 0 | H9: {=+_xll.EQNXTDZ($A$1,$B9,H$1,$B$1)} -> 0 | I9: {=+_xll.EQNXTDZ($A$1,$B9,I$1,$B$1)} -> 0 | J9: {=+_xll.EQNXTDZ($A$1,$B9,J$1,$B$1)} -> 0 | ... BK9: {=+_xll.EQNXTDZ($A$1,$B9,BK$1,$B$1)} -> 0
A10: Share of Associates | B10: QTR_SHARE_ASSOCIATE_REVENUE | C10: {=+_xll.EQNXTDZ($A$1,$B10,C$1,$B$1)} -> 0 | D10: {=+_xll.EQNXTDZ($A$1,$B10,D$1,$B$1)} -> 0 | E10: {=+_xll.EQNXTDZ($A$1,$B10,E$1,$B$1)} -> 0 | F10: {=+_xll.EQNXTDZ($A$1,$B10,F$1,$B$1)} -> 0 | G10: {=+_xll.EQNXTDZ($A$1,$B10,G$1,$B$1)} -> 0 | H10: {=+_xll.EQNXTDZ($A$1,$B10,H$1,$B$1)} -> 0 | I10: {=+_xll.EQNXTDZ($A$1,$B10,I$1,$B$1)} -> 0 | J10: {=+_xll.EQNXTDZ($A$1,$B10,J$1,$B$1)} -> 0 | ... BK10: {=+_xll.EQNXTDZ($A$1,$B10,BK$1,$B$1)} -> 0
A11: Other operating income | B11: QTR_JOB_WORKS | C11: {=+_xll.EQNXTDZ($A$1,$B11,C$1,$B$1)} -> 0 | D11: {=+_xll.EQNXTDZ($A$1,$B11,D$1,$B$1)} -> 0 | E11: {=+_xll.EQNXTDZ($A$1,$B11,E$1,$B$1)} -> 0 | F11: {=+_xll.EQNXTDZ($A$1,$B11,F$1,$B$1)} -> 0 | G11: {=+_xll.EQNXTDZ($A$1,$B11,G$1,$B$1)} -> 0 | H11: {=+_xll.EQNXTDZ($A$1,$B11,H$1,$B$1)} -> 0 | I11: {=+_xll.EQNXTDZ($A$1,$B11,I$1,$B$1)} -> 0 | J11: {=+_xll.EQNXTDZ($A$1,$B11,J$1,$B$1)} -> 0 | ... BK11: {=+_xll.EQNXTDZ($A$1,$B11,BK$1,$B$1)} -> 0
A12: Income on Investments | B12: QTR_INC_INV | C12: {=+_xll.EQNXTDZ($A$1,$B12,C$1,$B$1)} -> 0 | D12: {=+_xll.EQNXTDZ($A$1,$B12,D$1,$B$1)} -> 0 | E12: {=+_xll.EQNXTDZ($A$1,$B12,E$1,$B$1)} -> 0 | F12: {=+_xll.EQNXTDZ($A$1,$B12,F$1,$B$1)} -> 0 | G12: {=+_xll.EQNXTDZ($A$1,$B12,G$1,$B$1)} -> 0 | H12: {=+_xll.EQNXTDZ($A$1,$B12,H$1,$B$1)} -> 0 | I12: {=+_xll.EQNXTDZ($A$1,$B12,I$1,$B$1)} -> 0 | J12: {=+_xll.EQNXTDZ($A$1,$B12,J$1,$B$1)} -> 0 | ... BK12: {=+_xll.EQNXTDZ($A$1,$B12,BK$1,$B$1)} -> 0
A13: Net Sales & Other Operating Income | B13: QTR_NET_SALES | C13: {=+_xll.EQNXTDZ($A$1,$B13,C$1,$B$1)} -> 0 | D13: {=+_xll.EQNXTDZ($A$1,$B13,D$1,$B$1)} -> 0 | E13: {=+_xll.EQNXTDZ($A$1,$B13,E$1,$B$1)} -> 0 | F13: {=+_xll.EQNXTDZ($A$1,$B13,F$1,$B$1)} -> 0 | G13: {=+_xll.EQNXTDZ($A$1,$B13,G$1,$B$1)} -> 0 | H13: {=+_xll.EQNXTDZ($A$1,$B13,H$1,$B$1)} -> 0 | I13: {=+_xll.EQNXTDZ($A$1,$B13,I$1,$B$1)} -> 0 | J13: {=+_xll.EQNXTDZ($A$1,$B13,J$1,$B$1)} -> 0 | ... BK13: {=+_xll.EQNXTDZ($A$1,$B13,BK$1,$B$1)} -> 0
A14: Interest Expended | B14: QTR_INTEREST_EX | C14: {=+_xll.EQNXTDZ($A$1,$B14,C$1,$B$1)} -> 0 | D14: {=+_xll.EQNXTDZ($A$1,$B14,D$1,$B$1)} -> 0 | E14: {=+_xll.EQNXTDZ($A$1,$B14,E$1,$B$1)} -> 0 | F14: {=+_xll.EQNXTDZ($A$1,$B14,F$1,$B$1)} -> 0 | G14: {=+_xll.EQNXTDZ($A$1,$B14,G$1,$B$1)} -> 0 | H14: {=+_xll.EQNXTDZ($A$1,$B14,H$1,$B$1)} -> 0 | I14: {=+_xll.EQNXTDZ($A$1,$B14,I$1,$B$1)} -> 0 | J14: {=+_xll.EQNXTDZ($A$1,$B14,J$1,$B$1)} -> 0 | ... BK14: {=+_xll.EQNXTDZ($A$1,$B14,BK$1,$B$1)} -> 0
A15: Operating & Manufacturing Expenses | B15: QTR_MFG_EXPS | C15: {=+_xll.EQNXTDZ($A$1,$B15,C$1,$B$1)} -> 0 | D15: {=+_xll.EQNXTDZ($A$1,$B15,D$1,$B$1)} -> 0 | E15: {=+_xll.EQNXTDZ($A$1,$B15,E$1,$B$1)} -> 0 | F15: {=+_xll.EQNXTDZ($A$1,$B15,F$1,$B$1)} -> 0 | G15: {=+_xll.EQNXTDZ($A$1,$B15,G$1,$B$1)} -> 0 | H15: {=+_xll.EQNXTDZ($A$1,$B15,H$1,$B$1)} -> 0 | I15: {=+_xll.EQNXTDZ($A$1,$B15,I$1,$B$1)} -> 0 | J15: {=+_xll.EQNXTDZ($A$1,$B15,J$1,$B$1)} -> 0 | ... BK15: {=+_xll.EQNXTDZ($A$1,$B15,BK$1,$B$1)} -> 0
A16: (Increase) / Decrease In Stocks | B16: QTR_INC_DEC_INVENTORY | C16: {=+_xll.EQNXTDZ($A$1,$B16,C$1,$B$1)} -> 0 | D16: {=+_xll.EQNXTDZ($A$1,$B16,D$1,$B$1)} -> 0 | E16: {=+_xll.EQNXTDZ($A$1,$B16,E$1,$B$1)} -> 0 | F16: {=+_xll.EQNXTDZ($A$1,$B16,F$1,$B$1)} -> 0 | G16: {=+_xll.EQNXTDZ($A$1,$B16,G$1,$B$1)} -> 0 | H16: {=+_xll.EQNXTDZ($A$1,$B16,H$1,$B$1)} -> 0 | I16: {=+_xll.EQNXTDZ($A$1,$B16,I$1,$B$1)} -> 0 | J16: {=+_xll.EQNXTDZ($A$1,$B16,J$1,$B$1)} -> 0 | ... BK16: {=+_xll.EQNXTDZ($A$1,$B16,BK$1,$B$1)} -> 0
A17: Cost of Services & Raw Materials | B17: QTR_RAW_MATERIAL_COST | C17: {=+_xll.EQNXTDZ($A$1,$B17,C$1,$B$1)} -> 0 | D17: {=+_xll.EQNXTDZ($A$1,$B17,D$1,$B$1)} -> 0 | E17: {=+_xll.EQNXTDZ($A$1,$B17,E$1,$B$1)} -> 0 | F17: {=+_xll.EQNXTDZ($A$1,$B17,F$1,$B$1)} -> 0 | G17: {=+_xll.EQNXTDZ($A$1,$B17,G$1,$B$1)} -> 0 | H17: {=+_xll.EQNXTDZ($A$1,$B17,H$1,$B$1)} -> 0 | I17: {=+_xll.EQNXTDZ($A$1,$B17,I$1,$B$1)} -> 0 | J17: {=+_xll.EQNXTDZ($A$1,$B17,J$1,$B$1)} -> 0 | ... BK17: {=+_xll.EQNXTDZ($A$1,$B17,BK$1,$B$1)} -> 0
A18: Purchase of Finished Goods | B18: QTR_PURCHASE_FIN_GOOD | C18: {=+_xll.EQNXTDZ($A$1,$B18,C$1,$B$1)} -> 0 | D18: {=+_xll.EQNXTDZ($A$1,$B18,D$1,$B$1)} -> 0 | E18: {=+_xll.EQNXTDZ($A$1,$B18,E$1,$B$1)} -> 0 | F18: {=+_xll.EQNXTDZ($A$1,$B18,F$1,$B$1)} -> 0 | G18: {=+_xll.EQNXTDZ($A$1,$B18,G$1,$B$1)} -> 0 | H18: {=+_xll.EQNXTDZ($A$1,$B18,H$1,$B$1)} -> 0 | I18: {=+_xll.EQNXTDZ($A$1,$B18,I$1,$B$1)} -> 0 | J18: {=+_xll.EQNXTDZ($A$1,$B18,J$1,$B$1)} -> 0 | ... BK18: {=+_xll.EQNXTDZ($A$1,$B18,BK$1,$B$1)} -> 0
... A47: Face Value | B47: QTR_FV | C47: {=+_xll.EQNXTDZ($A$1,$B47,C$1,$B$1)} -> 0 | D47: {=+_xll.EQNXTDZ($A$1,$B47,D$1,$B$1)} -> 0 | E47: {=+_xll.EQNXTDZ($A$1,$B47,E$1,$B$1)} -> 0 | F47: {=+_xll.EQNXTDZ($A$1,$B47,F$1,$B$1)} -> 0 | G47: {=+_xll.EQNXTDZ($A$1,$B47,G$1,$B$1)} -> 0 | H47: {=+_xll.EQNXTDZ($A$1,$B47,H$1,$B$1)} -> 0 | I47: {=+_xll.EQNXTDZ($A$1,$B47,I$1,$B$1)} -> 0 | J47: {=+_xll.EQNXTDZ($A$1,$B47,J$1,$B$1)} -> 0 | ... BK47: {=+_xll.EQNXTDZ($A$1,$B47,BK$1,$B$1)} -> 0
A49: Field Description | B49: Field Name
A50: Equity Paid Up | B50: QTR_EQUITY_CAP | C50: {=+_xll.EQNXTDZ($A$1,$B50,C$1,$B$1)} -> 0 | D50: {=+_xll.EQNXTDZ($A$1,$B50,D$1,$B$1)} -> 0 | E50: {=+_xll.EQNXTDZ($A$1,$B50,E$1,$B$1)} -> 0 | F50: {=+_xll.EQNXTDZ($A$1,$B50,F$1,$B$1)} -> 0 | G50: {=+_xll.EQNXTDZ($A$1,$B50,G$1,$B$1)} -> 0 | H50: {=+_xll.EQNXTDZ($A$1,$B50,H$1,$B$1)} -> 0 | I50: {=+_xll.EQNXTDZ($A$1,$B50,I$1,$B$1)} -> 0 | J50: {=+_xll.EQNXTDZ($A$1,$B50,J$1,$B$1)} -> 0 | ... BK50: {=+_xll.EQNXTDZ($A$1,$B50,BK$1,$B$1)} -> 0
A51: Face value | B51: QTR_FV | C51: {=+_xll.EQNXTDZ($A$1,$B51,C$1,$B$1)} -> 0 | D51: {=+_xll.EQNXTDZ($A$1,$B51,D$1,$B$1)} -> 0 | E51: {=+_xll.EQNXTDZ($A$1,$B51,E$1,$B$1)} -> 0 | F51: {=+_xll.EQNXTDZ($A$1,$B51,F$1,$B$1)} -> 0 | G51: {=+_xll.EQNXTDZ($A$1,$B51,G$1,$B$1)} -> 0 | H51: {=+_xll.EQNXTDZ($A$1,$B51,H$1,$B$1)} -> 0 | I51: {=+_xll.EQNXTDZ($A$1,$B51,I$1,$B$1)} -> 0 | J51: {=+_xll.EQNXTDZ($A$1,$B51,J$1,$B$1)} -> 0 | ... BK51: {=+_xll.EQNXTDZ($A$1,$B51,BK$1,$B$1)} -> 0
A54: Share Capital | B54: QTRB_SHARE_CAPITAL | C54: {=+_xll.EQNXTDZ($A$1,$B54,C$1,$B$1)} -> 0 | D54: {=+_xll.EQNXTDZ($A$1,$B54,D$1,$B$1)} -> 0 | E54: {=+_xll.EQNXTDZ($A$1,$B54,E$1,$B$1)} -> 0 | F54: {=+_xll.EQNXTDZ($A$1,$B54,F$1,$B$1)} -> 0 | G54: {=+_xll.EQNXTDZ($A$1,$B54,G$1,$B$1)} -> 0 | H54: {=+_xll.EQNXTDZ($A$1,$B54,H$1,$B$1)} -> 0 | I54: {=+_xll.EQNXTDZ($A$1,$B54,I$1,$B$1)} -> 0 | J54: {=+_xll.EQNXTDZ($A$1,$B54,J$1,$B$1)} -> 0 | ... BK54: {=+_xll.EQNXTDZ($A$1,$B54,BK$1,$B$1)} -> 0
A55: Share Warrants & outstandings | B55: QTRB_SHAREWARNDOUT | C55: {=+_xll.EQNXTDZ($A$1,$B55,C$1,$B$1)} -> 0 | D55: {=+_xll.EQNXTDZ($A$1,$B55,D$1,$B$1)} -> 0 | E55: {=+_xll.EQNXTDZ($A$1,$B55,E$1,$B$1)} -> 0 | F55: {=+_xll.EQNXTDZ($A$1,$B55,F$1,$B$1)} -> 0 | G55: {=+_xll.EQNXTDZ($A$1,$B55,G$1,$B$1)} -> 0 | H55: {=+_xll.EQNXTDZ($A$1,$B55,H$1,$B$1)} -> 0 | I55: {=+_xll.EQNXTDZ($A$1,$B55,I$1,$B$1)} -> 0 | J55: {=+_xll.EQNXTDZ($A$1,$B55,J$1,$B$1)} -> 0 | ... BK55: {=+_xll.EQNXTDZ($A$1,$B55,BK$1,$B$1)} -> 0
A56: Reserves & Surplus | B56: QTRB_RESERVE | C56: {=+_xll.EQNXTDZ($A$1,$B56,C$1,$B$1)} -> 0 | D56: {=+_xll.EQNXTDZ($A$1,$B56,D$1,$B$1)} -> 0 | E56: {=+_xll.EQNXTDZ($A$1,$B56,E$1,$B$1)} -> 0 | F56: {=+_xll.EQNXTDZ($A$1,$B56,F$1,$B$1)} -> 0 | G56: {=+_xll.EQNXTDZ($A$1,$B56,G$1,$B$1)} -> 0 | H56: {=+_xll.EQNXTDZ($A$1,$B56,H$1,$B$1)} -> 0 | I56: {=+_xll.EQNXTDZ($A$1,$B56,I$1,$B$1)} -> 0 | J56: {=+_xll.EQNXTDZ($A$1,$B56,J$1,$B$1)} -> 0 | ... BK56: {=+_xll.EQNXTDZ($A$1,$B56,BK$1,$B$1)} -> 0
A57: Shareholder's Funds | B57: QTRB_SHAREHODERS_FUNDS | C57: {=+_xll.EQNXTDZ($A$1,$B57,C$1,$B$1)} -> 0 | D57: {=+_xll.EQNXTDZ($A$1,$B57,D$1,$B$1)} -> 0 | E57: {=+_xll.EQNXTDZ($A$1,$B57,E$1,$B$1)} -> 0 | F57: {=+_xll.EQNXTDZ($A$1,$B57,F$1,$B$1)} -> 0 | G57: {=+_xll.EQNXTDZ($A$1,$B57,G$1,$B$1)} -> 0 | H57: {=+_xll.EQNXTDZ($A$1,$B57,H$1,$B$1)} -> 0 | I57: {=+_xll.EQNXTDZ($A$1,$B57,I$1,$B$1)} -> 0 | J57: {=+_xll.EQNXTDZ($A$1,$B57,J$1,$B$1)} -> 0 | ... BK57: {=+_xll.EQNXTDZ($A$1,$B57,BK$1,$B$1)} -> 0
