Workbook

Sheet Template
A1: =+'Annual Raw'!C4 -> Inox India Ltd. | B1: 36951 | C1: =EOMONTH(B1,12) -> 37346 | D1: =EOMONTH(C1,12) -> 37711 | E1: =EOMONTH(D1,12) -> 38077 | F1: =EOMONTH(E1,12) -> 38442 | G1: =EOMONTH(F1,12) -> 38807 | H1: =EOMONTH(G1,12) -> 39172 | I1: =EOMONTH(H1,12) -> 39538 | J1: =EOMONTH(I1,12) -> 39903 | ... AE1: =EOMONTH(AD1,12) -> 47573 | AH1: QTR | AI1: 41061 | AJ1: 41153 | AK1: 41244 | AL1: 41334 | AM1: 41426 | AN1: 41518 | AO1: 41609 | AP1: 41699 | AQ1: 41791 | AR1: 41883 | AS1: 41974 | AT1: 42064 | AU1: 42156 | AV1: 42248 | AW1: 42339 | AX1: 42430 | AY1: 42522 | AZ1: 42614 | BA1: 42705 | BB1: 42795 | BC1: 42887 | BD1: 42979 | BE1: 43070 | BF1: 43160 | BG1: 43252 | BH1: 43344 | BI1: 43435 | BJ1: 43525 | BK1: 43617 | BL1: 43709 | BM1: 43800 | BN1: 43891 | BO1: 43983 | BP1: 44075 | BQ1: =EOMONTH(BP1,3) -> 44196 | BR1: =EOMONTH(BQ1,3) -> 44286 | BS1: =EOMONTH(BR1,3) -> 44377 | BT1: =EOMONTH(BS1,3) -> 44469 | BU1: =EOMONTH(BT1,3) -> 44561 | BV1: =EOMONTH(BU1,3) -> 44651 | BW1: =EOMONTH(BV1,3) -> 44742 | BX1: =EOMONTH(BW1,3) -> 44834 | ... DB1: =EOMONTH(DA1,3) -> 47573 | DE1: HISTORICAL ESTIMATES | DF1: 46112
A2: Presentation Data (Start)
Z3: =+Z5/Y5-1 -> 0.11957211
A4: Sales Break up
A5: Industrial Gas | W5: 620 | X5: 685 | Y5: =(Y$41+Y$66)*63% -> 733.73152 | Z5: =(Z$41+Z$66)*61% -> 821.46534 | CC5: 214 | CD5: 162 | CE5: 188 | CF5: 188 | CG5: 231 | CH5: 225 | CI5: 165 | CJ5: 212 | CK5: 261 | CL5: 237 | CM5: =+CI5*(1+CM12) -> 186.45 | CN5: =+CJ5*(1+CN12) -> 239.56 | CO5: =+CK5*(1+CO12) -> 294.93 | CP5: =+CL5*(1+CP12) -> 267.81 | CQ5: =+CM5*(1+CQ12) -> 210.6885 | CR5: =+CN5*(1+CR12) -> 270.7028 | CS5: =+CO5*(1+CS12) -> 333.2709 | CT5: =+CP5*(1+CT12) -> 302.6253 | ... DB5: =+CX5*(1+DB12) -> 386.42225 | DF5: 254.25
A6: LNG | W6: 126 | X6: 240 | Y6: =(Y$41+Y$66)*28% -> 326.1029 | Z6: =(Z$41+Z$66)*17% -> 228.93296 | CC6: 73 | CD6: 74 | CE6: 46 | CF6: 62 | CG6: 50 | CH6: 74 | CI6: 102 | CJ6: 93 | CK6: 107 | CL6: 155
A7: Cryo Scientific | W7: 36 | X7: 41 | Y7: =(Y$41+Y$66)*7% -> 81.525724 | Z7: =(Z$41+Z$66)*17% -> 228.93296 | CC7: 6 | CD7: 42 | CE7: 63 | CF7: 57 | CG7: 45 | CH7: 63 | CI7: 67 | CJ7: 49 | CK7: 55 | CL7: 56
A8: Others | W8: 21 | X8: 20 | Y8: =(Y$41+Y$66)*2% -> 23.293064 | Z8: =(Z$41+Z$66)*5% -> 67.333225 | CC8: 6 | CD8: 10 | CE8: 5 | CF8: 13 | CG8: 16 | CH8: 21 | CI8: 18 | CJ8: 15 | CK8: 13 | CL8: 27
A9: Total | W9: =SUM(W5:W8) -> 803 | X9: =SUM(X5:X8) -> 986 | Y9: =SUM(Y5:Y8) -> 1164.6532 | Z9: =SUM(Z5:Z8) -> 1346.6645 | CC9: =SUM(CC5:CC8) -> 299 | CD9: =SUM(CD5:CD8) -> 288 | CE9: =SUM(CE5:CE8) -> 302 | CF9: =SUM(CF5:CF8) -> 320 | CG9: =SUM(CG5:CG8) -> 342 | CH9: =SUM(CH5:CH8) -> 383 | CI9: =SUM(CI5:CI8) -> 352 | CJ9: =SUM(CJ5:CJ8) -> 369 | ... CL9: =SUM(CL5:CL8) -> 475
A10: check sum | W10: =W39+W66-W9 -> 0.713 | X10: =X39+X66-X9 -> 0.0816 | Y10: =Y39+Y66-Y9 -> 0 | Z10: =Z39+Z66-Z9 -> 0 | CC10: =CC39+CC66-CC9 -> -3.575 | CD10: =CD39+CD66-CD9 -> -0.3 | CE10: =CE39+CE66-CE9 -> -0.221 | CF10: =CF39+CF66-CF9 -> 0.003 | CG10: =CG39+CG66-CG9 -> 0.348 | CH10: =CH39+CH66-CH9 -> -0.465 | CI10: =CI39+CI66-CI9 -> 0.293 | CJ10: =CJ39+CJ66-CJ9 -> 0.073 | ... CL10: =CL39+CL66-CL9 -> 0.243
X12: =X5/W5-1 -> 0.10483871 | Y12: =Y5/X5-1 -> 0.071140899 | Z12: =Z5/Y5-1 -> 0.11957211 | CG12: =+CG5/CC5-1 -> 0.079439252 | CH12: =+CH5/CD5-1 -> 0.38888889 | CI12: =+CI5/CE5-1 -> -0.12234043 | CJ12: =+CJ5/CF5-1 -> 0.12765957 | CK12: =+CK5/CG5-1 -> 0.12987013 | CL12: =+CL5/CH5-1 -> 0.053333333 | CM12: 0.13 | CN12: 0.13 | CO12: 0.13 | CP12: 0.13 | CQ12: 0.13 | CR12: 0.13 | CS12: 0.13 | CT12: 0.13 | CU12: 0.13 | CV12: 0.13 | CW12: 0.13 | CX12: 0.13 | CY12: 0.13 | CZ12: 0.13 | DA12: 0.13 | DB12: 0.13 | DF12: 0.13
X13: =X6/W6-1 -> 0.9047619 | Y13: =Y6/X6-1 -> 0.35876207 | Z13: =Z6/Y6-1 -> -0.29797322 | CG13: =+CG6/CC6-1 -> -0.31506849 | CH13: =+CH6/CD6-1 -> 0 | CI13: =+CI6/CE6-1 -> 1.2173913 | CJ13: =+CJ6/CF6-1 -> 0.5 | CK13: =+CK6/CG6-1 -> 1.14 | CL13: =+CL6/CH6-1 -> 1.0945946
X14: =X7/W7-1 -> 0.13888889 | Y14: =Y7/X7-1 -> 0.98843229 | Z14: =Z7/Y7-1 -> 1.8081071 | CG14: =+CG7/CC7-1 -> 6.5 | CH14: =+CH7/CD7-1 -> 0.5 | CI14: =+CI7/CE7-1 -> 0.063492063 | CJ14: =+CJ7/CF7-1 -> -0.14035088 | CK14: =+CK7/CG7-1 -> 0.22222222 | CL14: =+CL7/CH7-1 -> -0.11111111
A16: Exports Crs | Y16: =Y39*Y17 -> 623.33783 | Z16: =SUM(CE16:CH16) -> 705.48 | CC16: 149.5 | CD16: 141.12 | CE16: 163.08 | CF16: 166.4 | CG16: 171 | CH16: 205 | CI16: 198 | CJ16: 211 | CK16: 271 | CL16: 291
A17: exports as % of sales | Y17: 0.55 | Z17: =Z16/Z39 -> 0.54018476 | CC17: =CC16/CC39 -> 0.5142865 | CD17: =CD16/CD39 -> 0.51036683 | CE17: =CE16/CE39 -> 0.55018387 | CF17: =CF16/CF39 -> 0.54279218 | CG17: =CG16/CG39 -> 0.51254844 | CH17: =CH16/CH39 -> 0.55495698 | CI17: =CI16/CI39 -> 0.58299767 | CJ17: =CJ16/CJ39 -> 0.58901693 | ... CL17: =CL16/CL39 -> 0.63171057
A19: OB break up
A20: Industrial Gas | W20: 509 | X20: 502 | Y20: 593 | Z20: =+CH20 -> 631 | CC20: 520 | CD20: 593 | CE20: 557 | CF20: 637 | CG20: 596 | CH20: 631 | CI20: 648 | CJ20: 674 | CK20: 630 | CL20: 738
A21: LNG | W21: 190 | X21: 358 | Y21: 222 | Z21: =+CH21 -> 486 | CC21: 241 | CD21: 222 | CE21: 254 | CF21: 291 | CG21: 485 | CH21: 486 | CI21: 469 | CJ21: 454 | CK21: 446 | CL21: 422
A22: Cryo Scientific | W22: 159 | X22: 143 | Y22: 272 | Z22: =+CH22 -> 234 | CC22: 282 | CD22: 272 | CE22: 294 | CF22: 250 | CG22: =CG24-CG21-CG20 -> 260 | CH22: 234 | CI22: 334 | CJ22: 340 | CK22: 362 | CL22: 329
A23: others | CH23: 5 | CI23: 6 | CJ23: 17 | CK23: 19 | CL23: 25
A24: Total OB - crs | V24: 620 | W24: 858 | X24: 1003 | Y24: 1087 | Z24: 1356 | CB24: 1037 | CC24: 1043 | CD24: =Y24 -> 1087 | CE24: 1105 | CF24: 1178 | CG24: 1341 | CH24: =SUM(CH20:CH23) -> 1356 | CI24: =SUM(CI20:CI23) -> 1457 | CJ24: =SUM(CJ20:CJ23) -> 1485 | CK24: =SUM(CK20:CK23) -> 1457 | CL24: =SUM(CL20:CL23) -> 1514
A26: OP | W26: =V24 -> 620 | X26: =W29 -> 858 | Y26: =X29 -> 1003 | Z26: =Y29 -> 1087 | AA26: =Z29 -> 1356 | AB26: =AA29 -> 1514 | AC26: =AB29 -> 2015.5256 | AD26: =AC29 -> 2614.5712 | AE26: =AD29 -> 3284.9314 | CB26: =CA24 -> 0 | CC26: =CB24 -> 1037 | CD26: =CC24 -> 1043 | CE26: =CD24 -> 1087 | CF26: =CE24 -> 1105 | CG26: =CF24 -> 1178 | CH26: =CG24 -> 1341 | CI26: =CH24 -> 1356 | ... CK26: =CJ24 -> 1485 | CL26: =+CK29 -> 1457 | CM26: =+CL29 -> 1514 | CN26: =+CM29 -> 1699.3502 | CO26: =+CN29 -> 1760.6777 | CP26: =+CO29 -> 1825.2747 | CQ26: =+CP29 -> 2015.5256 | CR26: =+CQ29 -> 2246.9179 | CS26: =+CR29 -> 2312.438 | ... DB26: =+DA29 -> 3658.5795 | DF26: 1457
A27: Additions | W27: =W29+W28-W26 -> 1020.711 | X27: =X29+X28-X26 -> 1110.9003 | Y27: =Y29+Y28-Y26 -> 1217.3415 | Z27: =Z29+Z28-Z26 -> 1574.9976 | AA27: =AA29+AA28-AA26 -> 1745.0629 | AB27: =AB29+AB28-AB26 -> 2333.8586 | AC27: =AC29+AC28-AC26 -> 2915.6112 | AD27: =AD29+AD28-AD26 -> 3427.3299 | AE27: =AE29+AE28-AE26 -> 3986.0479 | CB27: =CB29+CB28-CB26 -> 1294.65 | CC27: =CC29+CC28-CC26 -> 296.694 | CD27: =CD29+CD28-CD26 -> 320.507 | CE27: =CE29+CE28-CE26 -> 314.41 | CF27: =CF29+CF28-CF26 -> 379.563 | CG27: =CG29+CG28-CG26 -> 496.627 | CH27: =CH29+CH28-CH26 -> 384.398 | CI27: =CI29+CI28-CI26 -> 440.624 | ... CL27: =CL29+CL28-CL26 -> 517.654 | CM27: =+CI27*(1+CM32) -> 593.37139 | CN27: =+CJ27*(1+CN32) -> 520.113 | CO27: =+CK27*(1+CO32) -> 539.42009 | CP27: =+CL27*(1+CP32) -> 680.95416 | CQ27: =+CM27*(1+CQ32) -> 763.71076 | CR27: =+CN27*(1+CR32) -> 655.98425 | CS27: =+CO27*(1+CS32) -> 667.65266 | CT27: =+CP27*(1+CT32) -> 828.26358 | ... DB27: =+CX27*(1+DB32) -> 1120.3192 | DF27: 480.4975
A28: Executions | W28: =W39 -> 782.711 | X28: =X39 -> 965.9003 | Y28: =Y39 -> 1133.3415 | Z28: =Z39 -> 1305.9976 | AA28: =AA39 -> 1587.0629 | AB28: =AB39 -> 1832.3331 | AC28: =AC39 -> 2316.5656 | AD28: =AD39 -> 2756.9697 | AE28: =AE39 -> 3366.0586 | CB28: =CB39 -> 257.65 | CC28: =CC39 -> 290.694 | CD28: =CD39 -> 276.507 | CE28: =CE39 -> 296.41 | CF28: =CF39 -> 306.563 | CG28: =CG39 -> 333.627 | CH28: =CH39 -> 369.398 | CI28: =CI39 -> 339.624 | ... CL28: =CL39 -> 460.654 | CM28: =+CM26*CM33 -> 408.02123 | CN28: =+CN26*CN33 -> 458.78547 | CO28: =+CO26*CO33 -> 474.82308 | CP28: =+CP26*CP33 -> 490.70328 | CQ28: =+CQ26*CQ33 -> 532.31843 | CR28: =+CR26*CR33 -> 590.46415 | CS28: =+CS26*CS33 -> 603.60943 | CT28: =+CT26*CT33 -> 590.17359 | ... DB28: =+DB26*DB33 -> 873.97802 | DF28: 422.53
A29: Closing | V29: =V24 -> 620 | W29: =W24 -> 858 | X29: =X24 -> 1003 | Y29: =Y24 -> 1087 | Z29: =Z24 -> 1356 | AA29: =CL29 -> 1514 | AB29: =CP29 -> 2015.5256 | AC29: =CT29 -> 2614.5712 | AD29: =CX29 -> 3284.9314 | AE29: =DB29 -> 3904.9207 | CB29: =CB24 -> 1037 | CC29: =CC24 -> 1043 | CD29: =CD24 -> 1087 | CE29: =CE24 -> 1105 | CF29: =CF24 -> 1178 | CG29: =CG24 -> 1341 | CH29: =CH24 -> 1356 | CI29: =CI24 -> 1457 | ... CL29: =CL24 -> 1514 | CM29: =+CM26+CM27-CM28 -> 1699.3502 | CN29: =+CN26+CN27-CN28 -> 1760.6777 | CO29: =+CO26+CO27-CO28 -> 1825.2747 | CP29: =+CP26+CP27-CP28 -> 2015.5256 | CQ29: =+CQ26+CQ27-CQ28 -> 2246.9179 | CR29: =+CR26+CR27-CR28 -> 2312.438 | CS29: =+CS26+CS27-CS28 -> 2376.4812 | CT29: =+CT26+CT27-CT28 -> 2614.5712 | ... DB29: =+DB26+DB27-DB28 -> 3904.9207 | DF29: 1514.9675
A31: OB Growth | W31: =W29/V29-1 -> 0.38387097 | X31: =X29/W29-1 -> 0.16899767 | Y31: =Y29/X29-1 -> 0.083748754 | Z31: =Z29/Y29-1 -> 0.2474701 | AA31: =AA29/Z29-1 -> 0.11651917 | AB31: =AB29/AA29-1 -> 0.33125864 | AC31: =AC29/AB29-1 -> 0.2972156 | AD31: =AD29/AC29-1 -> 0.25639392 | AE31: =AE29/AD29-1 -> 0.18873737 | CF31: =CF29/CB29-1 -> 0.13596914 | CG31: =CG29/CC29-1 -> 0.28571429 | CH31: =CH29/CD29-1 -> 0.2474701 | CI31: =CI29/CE29-1 -> 0.31855204 | CJ31: =CJ29/CF29-1 -> 0.26061121 | CK31: =CK29/CG29-1 -> 0.08650261 | CL31: =CL29/CH29-1 -> 0.11651917 | CM31: =CM29/CI29-1 -> 0.16633505 | ... DB31: =DB29/CX29-1 -> 0.18873737 | DF31: 0.11723267
A32: Addition Growth | X32: =+X27/W27-1 -> 0.088359291 | Y32: =+Y27/X27-1 -> 0.095815259 | Z32: =+Z27/Y27-1 -> 0.29380096 | AA32: =+AA27/Z27-1 -> 0.10797813 | AB32: =+AB27/AA27-1 -> 0.33740661 | AC32: =+AC27/AB27-1 -> 0.24926642 | AD32: =+AD27/AC27-1 -> 0.1755099 | AE32: =+AE27/AD27-1 -> 0.16301846 | CF32: =+CF27/CB27-1 -> -0.70682192 | CG32: =+CG27/CC27-1 -> 0.67386937 | CH32: =+CH27/CD27-1 -> 0.19934354 | CI32: =+CI27/CE27-1 -> 0.40143125 | CJ32: =+CJ27/CF27-1 -> 0.017549129 | CK32: =+CK27/CG27-1 -> -0.19343693 | CL32: =+CL27/CH27-1 -> 0.34666153 | CM32: =+CL32 -> 0.34666153 | CN32: =+CM32 -> 0.34666153 | CO32: =+CN32 -> 0.34666153 | CP32: =+CO32*0.91 -> 0.315462 | CQ32: =+CP32*0.91 -> 0.28707042 | CR32: =+CQ32*0.91 -> 0.26123408 | CS32: =+CR32*0.91 -> 0.23772301 | CT32: =+CS32*0.91 -> 0.21632794 | CU32: =+CT32*0.91 -> 0.19685843 | CV32: =+CU32*0.91 -> 0.17914117 | CW32: =+CV32*0.91 -> 0.16301846 | CX32: =+CW32 -> 0.16301846 | CY32: =+CX32 -> 0.16301846 | CZ32: =+CY32 -> 0.16301846 | DA32: =+CZ32 -> 0.16301846 | DB32: =+DA32 -> 0.16301846 | DF32: 0.25
A33: Execution % | X33: =+X39/X26 -> 1.1257579 | Y33: =+Y39/Y26 -> 1.1299516 | Z33: =+Z39/Z26 -> 1.2014697 | AA33: =+AA39/AA26 -> 1.1704004 | AB33: =+AB39/AB26 -> 1.2102596 | AC33: =+AC39/AC26 -> 1.1493606 | AD33: =+AD39/AD26 -> 1.0544634 | AE33: =+AE39/AE26 -> 1.0246968 | CC33: =CC28/CB24 -> 0.28032208 | CD33: =CD28/CC24 -> 0.26510738 | CE33: =CE28/CD24 -> 0.27268629 | CF33: =CF28/CE24 -> 0.27743258 | CG33: =CG28/CF24 -> 0.28321477 | CH33: =CH28/CG24 -> 0.27546458 | CI33: =CI28/CH24 -> 0.25046018 | CJ33: =CJ28/CI24 -> 0.2458641 | ... CL33: =CL28/CK24 -> 0.31616609 | CM33: =AVERAGE(CD33:CL33)*0.98 -> 0.26949883 | CN33: =AVERAGE(CE33:CM33)*0.98 -> 0.26997701 | CO33: =AVERAGE(CF33:CN33)*0.98 -> 0.269682 | CP33: =AVERAGE(CG33:CO33)*0.98 -> 0.26883805 | CQ33: =AVERAGE(CM33:CP33)*0.98 -> 0.26410899 | CR33: =AVERAGE(CN33:CQ33)*0.98 -> 0.26278848 | CS33: =AVERAGE(CO33:CR33)*0.98 -> 0.26102729 | CT33: =AVERAGE(CP33:CS33)*0.94 -> 0.24833926 | CU33: =AVERAGE(CQ33:CT33)*0.94 -> 0.24352205 | CV33: =AVERAGE(CR33:CU33)*0.94 -> 0.23868411 | CW33: =AVERAGE(CS33:CV33)*0.94 -> 0.23301959 | CX33: =AVERAGE(CT33:CW33) -> 0.24089125 | CY33: =AVERAGE(CU33:CX33) -> 0.23902925 | CZ33: =AVERAGE(CV33:CY33) -> 0.23790605 | DA33: =AVERAGE(CW33:CZ33) -> 0.23771153 | DB33: =AVERAGE(CX33:DA33) -> 0.23888452 | DF33: 0.29
T35: =T51/T39 -> 0.18735677 | U35: =U51/U39 -> 0.15421549 | V35: =V51/V39 -> 0.13845275 | W35: =W51/W39 -> 0.1531817 | X35: =X51/X39 -> 0.14057848 | Y35: =Y51/Y39 -> 0.123042 | Z35: =Z51/Z39 -> 0.14336481
A37: Presentation Data (End)
A38: Profit & Loss- Annual (Start)
A39: Gross Revenue | B39: ='Annual Raw'!C6 -> 35.032452 | C39: ='Annual Raw'!D6 -> 51.527453 | D39: ='Annual Raw'!E6 -> 48.232658 | E39: ='Annual Raw'!F6 -> 51.989955 | F39: ='Annual Raw'!G6 -> 54.900097 | G39: ='Annual Raw'!H6 -> 87.1955 | H39: ='Annual Raw'!I6 -> 137.65676 | I39: ='Annual Raw'!J6 -> 205.30286 | ... AA39: ='Annual Raw'!AB6 -> 1587.0629 | AB39: =+SUM(CM39:CP39) -> 1832.3331 | AC39: =+SUM(CQ39:CT39) -> 2316.5656 | AD39: =+SUM(CU39:CX39) -> 2756.9697 | AE39: =+SUM(CY39:DB39) -> 3366.0586 | AF39: =2100/AA39-1 -> 0.32319897 | AI39: ='QTR Raw'!C6+'QTR Raw'!C8 -> 0 | AJ39: ='QTR Raw'!D6+'QTR Raw'!D8 -> 0 | AK39: ='QTR Raw'!E6+'QTR Raw'!E8 -> 0 | AL39: ='QTR Raw'!F6+'QTR Raw'!F8 -> 0 | AM39: ='QTR Raw'!G6+'QTR Raw'!G8 -> 0 | AN39: ='QTR Raw'!H6+'QTR Raw'!H8 -> 0 | AO39: ='QTR Raw'!I6+'QTR Raw'!I8 -> 0 | AP39: ='QTR Raw'!J6+'QTR Raw'!J8 -> 0 | ... CL39: ='QTR Raw'!BF6+'QTR Raw'!BF8 -> 460.654 | CM39: =+CM28 -> 408.02123 | CN39: =+CN28 -> 458.78547 | CO39: =+CO28 -> 474.82308 | CP39: =+CP28 -> 490.70328 | CQ39: =+CQ28 -> 532.31843 | CR39: =+CR28 -> 590.46415 | CS39: =+CS28 -> 603.60943 | CT39: =+CT28 -> 590.17359 | ... DB39: =+DB28 -> 873.97802 | DF39: 422.53
A40: Less: Exise Duty | B40: ='Annual Raw'!C7+'Annual Raw'!C8+'Annual Raw'!C9 -> 3.2351323 | C40: ='Annual Raw'!D7+'Annual Raw'!D8+'Annual Raw'!D9 -> 2.5807622 | D40: ='Annual Raw'!E7+'Annual Raw'!E8+'Annual Raw'!E9 -> 1.7177281 | E40: ='Annual Raw'!F7+'Annual Raw'!F8+'Annual Raw'!F9 -> 2.7170725 | F40: ='Annual Raw'!G7+'Annual Raw'!G8+'Annual Raw'!G9 -> 3.4063634 | G40: ='Annual Raw'!H7+'Annual Raw'!H8+'Annual Raw'!H9 -> 5.3058515 | H40: ='Annual Raw'!I7+'Annual Raw'!I8+'Annual Raw'!I9 -> 7.3428139 | I40: ='Annual Raw'!J7+'Annual Raw'!J8+'Annual Raw'!J9 -> 11.593145 | ... AA40: ='Annual Raw'!AB7+'Annual Raw'!AB8+'Annual Raw'!AB9 -> 0 | AB40: =+SUM(CM40:CP40) -> 0 | AC40: =+SUM(CQ40:CT40) -> 0 | AD40: =+SUM(CU40:CX40) -> 0 | AE40: =+SUM(CY40:DB40) -> 0 | AI40: =+'QTR Raw'!C20+'QTR Raw'!C19+'QTR Raw'!C13+'QTR Raw'!C7 -> 0 | AJ40: =+'QTR Raw'!D20+'QTR Raw'!D19+'QTR Raw'!D13+'QTR Raw'!D7 -> 0 | AK40: =+'QTR Raw'!E20+'QTR Raw'!E19+'QTR Raw'!E13+'QTR Raw'!E7 -> 0 | AL40: =+'QTR Raw'!F20+'QTR Raw'!F19+'QTR Raw'!F13+'QTR Raw'!F7 -> 0 | AM40: =+'QTR Raw'!G20+'QTR Raw'!G19+'QTR Raw'!G13+'QTR Raw'!G7 -> 0 | AN40: =+'QTR Raw'!H20+'QTR Raw'!H19+'QTR Raw'!H13+'QTR Raw'!H7 -> 0 | AO40: =+'QTR Raw'!I20+'QTR Raw'!I19+'QTR Raw'!I13+'QTR Raw'!I7 -> 0 | AP40: =+'QTR Raw'!J20+'QTR Raw'!J19+'QTR Raw'!J13+'QTR Raw'!J7 -> 0 | ... CL40: =+'QTR Raw'!BF20+'QTR Raw'!BF19+'QTR Raw'!BF13+'QTR Raw'!BF7 -> 0 | DF40: 0
A41: Net Revenue | B41: =+B39-B40 -> 31.797319 | C41: =+C39-C40 -> 48.946691 | D41: =+D39-D40 -> 46.51493 | E41: =+E39-E40 -> 49.272882 | F41: =+F39-F40 -> 51.493734 | G41: =+G39-G40 -> 81.889648 | H41: =+H39-H40 -> 130.31394 | I41: =+I39-I40 -> 193.70972 | ... AE41: =+AE39-AE40 -> 3366.0586 | AI41: =+AI39-AI40 -> 0 | AJ41: =+AJ39-AJ40 -> 0 | AK41: =+AK39-AK40 -> 0 | AL41: =+AL39-AL40 -> 0 | AM41: =+AM39-AM40 -> 0 | AN41: =+AN39-AN40 -> 0 | AO41: =+AO39-AO40 -> 0 | AP41: =+AP39-AP40 -> 0 | ... DB41: =+DB39-DB40 -> 873.97802 | DF41: 422.53
A42: Net Revenue YOY% | C42: =C41/B41-1 -> 0.53933387 | D42: =D41/C41-1 -> -0.049681814 | E42: =E41/D41-1 -> 0.059291758 | F42: =F41/E41-1 -> 0.045072486 | G42: =G41/F41-1 -> 0.59028377 | H42: =H41/G41-1 -> 0.59133598 | I42: =I41/H41-1 -> 0.48648496 | J42: =J41/I41-1 -> 0.24112377 | ... AE42: =AE41/AD41-1 -> 0.22092695 | AM42: =+IF(AI41<0,1-AM41/AI41,AM41/AI41-1) -> #DIV/0! | AN42: =+IF(AJ41<0,1-AN41/AJ41,AN41/AJ41-1) -> #DIV/0! | AO42: =+IF(AK41<0,1-AO41/AK41,AO41/AK41-1) -> #DIV/0! | AP42: =+IF(AL41<0,1-AP41/AL41,AP41/AL41-1) -> #DIV/0! | AQ42: =+IF(AM41<0,1-AQ41/AM41,AQ41/AM41-1) -> #DIV/0! | AR42: =+IF(AN41<0,1-AR41/AN41,AR41/AN41-1) -> #DIV/0! | AS42: =+IF(AO41<0,1-AS41/AO41,AS41/AO41-1) -> #DIV/0! | AT42: =+IF(AP41<0,1-AT41/AP41,AT41/AP41-1) -> #DIV/0! | ... DB42: =+IF(CX41<0,1-DB41/CX41,DB41/CX41-1) -> 0.18628095 | DF42: 0.14383402
A43: Net Revenue QOQ% | AJ43: =+IF(AI41<0,1-AJ41/AI41,AJ41/AI41-1) -> #DIV/0! | AK43: =+IF(AJ41<0,1-AK41/AJ41,AK41/AJ41-1) -> #DIV/0! | AL43: =+IF(AK41<0,1-AL41/AK41,AL41/AK41-1) -> #DIV/0! | AM43: =+IF(AL41<0,1-AM41/AL41,AM41/AL41-1) -> #DIV/0! | AN43: =+IF(AM41<0,1-AN41/AM41,AN41/AM41-1) -> #DIV/0! | AO43: =+IF(AN41<0,1-AO41/AN41,AO41/AN41-1) -> #DIV/0! | AP43: =+IF(AO41<0,1-AP41/AO41,AP41/AO41-1) -> #DIV/0! | AQ43: =+IF(AP41<0,1-AQ41/AP41,AQ41/AP41-1) -> #DIV/0! | ... CL43: =+IF(CK41<0,1-CL41/CK41,CL41/CK41-1) -> 0.074885489 | CM43: =+CM41/CL41-1 -> -0.11425663 | CN43: =+CN41/CM41-1 -> 0.1244157 | CO43: =+CO41/CN41-1 -> 0.034956652 | CP43: =+CP41/CO41-1 -> 0.033444471 | CQ43: =+CQ41/CP41-1 -> 0.084807143 | CR43: =+CR41/CQ41-1 -> 0.10923108 | CS43: =+CS41/CR41-1 -> 0.022262632 | CT43: =+CT41/CS41-1 -> -0.022259159 | ... DB43: =+DB41/DA41-1 -> 0.017111274 | DF43: -0.014072676
A44: Increase/Decrease in Stock | B44: ='Annual Raw'!C11 -> 0.254252 | C44: ='Annual Raw'!D11 -> 0.3561504 | D44: ='Annual Raw'!E11 -> -0.4957742 | E44: ='Annual Raw'!F11 -> -0.4386168 | F44: ='Annual Raw'!G11 -> -3.880121 | G44: ='Annual Raw'!H11 -> -5.5437663 | H44: ='Annual Raw'!I11 -> -12.068485 | I44: ='Annual Raw'!J11 -> -12.77424 | ... AA44: ='Annual Raw'!AB11 -> 20.1944 | AB44: =+SUM(CM44:CP44) -> 0 | AC44: =+SUM(CQ44:CT44) -> 0 | AD44: =+SUM(CU44:CX44) -> 0 | AE44: =+SUM(CY44:DB44) -> 0 | AI44: ='QTR Raw'!C10 -> 0 | AJ44: ='QTR Raw'!D10 -> 0 | AK44: ='QTR Raw'!E10 -> 0 | AL44: ='QTR Raw'!F10 -> 0 | AM44: ='QTR Raw'!G10 -> 0 | AN44: ='QTR Raw'!H10 -> 0 | AO44: ='QTR Raw'!I10 -> 0 | AP44: ='QTR Raw'!J10 -> 0 | ... CL44: ='QTR Raw'!BF10 -> -9.999 | DF44: 16.335
A45: Purchase of Finished Goods | B45: 0 | C45: 0 | D45: 0 | E45: 0 | F45: 0 | G45: 0 | H45: 0 | I45: 0 | J45: 0 | K45: 0 | L45: 0 | M45: 0 | N45: 0 | O45: 0 | P45: 0 | Q45: 0 | R45: 0 | S45: 0 | T45: 0 | U45: 0 | V45: 0 | W45: 0 | X45: 0 | Y45: 0 | Z45: 0 | AA45: 0 | AB45: =+SUM(CM45:CP45) -> 0 | AC45: =+SUM(CQ45:CT45) -> 0 | AD45: =+SUM(CU45:CX45) -> 0 | AE45: =+SUM(CY45:DB45) -> 0 | AI45: ='QTR Raw'!C12 -> 0 | AJ45: ='QTR Raw'!D12 -> 0 | AK45: ='QTR Raw'!E12 -> 0 | AL45: ='QTR Raw'!F12 -> 0 | AM45: ='QTR Raw'!G12 -> 0 | AN45: ='QTR Raw'!H12 -> 0 | AO45: ='QTR Raw'!I12 -> 0 | AP45: ='QTR Raw'!J12 -> 0 | ... CL45: ='QTR Raw'!BF12 -> 14.477 | DF45: 14.477
A46: Raw Material Consumed | B46: ='Annual Raw'!C12 -> 13.138791 | C46: ='Annual Raw'!D12 -> 28.892685 | D46: ='Annual Raw'!E12 -> 29.077509 | E46: ='Annual Raw'!F12 -> 27.412232 | F46: ='Annual Raw'!G12 -> 30.416405 | G46: ='Annual Raw'!H12 -> 46.127885 | H46: ='Annual Raw'!I12 -> 71.685462 | I46: ='Annual Raw'!J12 -> 106.80836 | ... AA46: ='Annual Raw'!AB12 -> 687.0164 | AB46: =+SUM(CM46:CP46) -> 817.46343 | AC46: =+SUM(CQ46:CT46) -> 1036.6981 | AD46: =+SUM(CU46:CX46) -> 1234.3284 | AE46: =+SUM(CY46:DB46) -> 1507.0965 | AI46: ='QTR Raw'!C11 -> 0 | AJ46: ='QTR Raw'!D11 -> 0 | AK46: ='QTR Raw'!E11 -> 0 | AL46: ='QTR Raw'!F11 -> 0 | AM46: ='QTR Raw'!G11 -> 0 | AN46: ='QTR Raw'!H11 -> 0 | AO46: ='QTR Raw'!I11 -> 0 | AP46: ='QTR Raw'!J11 -> 0 | ... CL46: ='QTR Raw'!BF11 -> 204.133 | CM46: =+CM41-CM47 -> 178.08538 | CN46: =+CN41-CN47 -> 204.79158 | CO46: =+CO41-CO47 -> 215.14392 | CP46: =+CP41-CP47 -> 219.44255 | CQ46: =+CQ41-CQ47 -> 237.29986 | CR46: =+CR41-CR47 -> 264.59682 | CS46: =+CS41-CS47 -> 270.74986 | CT46: =+CT41-CT47 -> 264.05159 | ... DB46: =+DB41-DB47 -> 391.29412 | DF46: 181.42563
A47: Gross Profit | B47: =B41-B44-B46-B45 -> 18.404277 | C47: =C41-C44-C46-C45 -> 19.697855 | D47: =D41-D44-D46-D45 -> 17.933196 | E47: =E41-E44-E46-E45 -> 22.299267 | F47: =F41-F44-F46-F45 -> 24.95745 | G47: =G41-G44-G46-G45 -> 41.30553 | H47: =H41-H44-H46-H45 -> 70.696967 | I47: =I41-I44-I46-I45 -> 99.675595 | ... AE47: =AE41-AE44-AE46-AE45 -> 1858.9621 | AI47: =AI41-AI44-AI46-AI45 -> 0 | AJ47: =AJ41-AJ44-AJ46-AJ45 -> 0 | AK47: =AK41-AK44-AK46-AK45 -> 0 | AL47: =AL41-AL44-AL46-AL45 -> 0 | AM47: =AM41-AM44-AM46-AM45 -> 0 | AN47: =AN41-AN44-AN46-AN45 -> 0 | AO47: =AO41-AO44-AO46-AO45 -> 0 | AP47: =AP41-AP44-AP46-AP45 -> 0 | ... CL47: =CL41-CL44-CL46-CL45 -> 252.043 | CM47: =+CM48*CM41 -> 229.93585 | CN47: =+CN48*CN41 -> 253.99389 | CO47: =+CO48*CO41 -> 259.67916 | CP47: =+CP48*CP41 -> 271.26073 | CQ47: =+CQ48*CQ41 -> 295.01857 | CR47: =+CR48*CR41 -> 325.86733 | CS47: =+CS48*CS41 -> 332.85957 | CT47: =+CT48*CT41 -> 326.12201 | ... DB47: =+DB48*DB41 -> 482.6839 | DF47: 241.10437
...

Sheet Sheet1
A46: Exports Countrywise break up
A47: North America | B47: 0.32
A48: Export to others | B48: 0.31
A49: Europe | B49: 0.23
A50: South America | B50: 0.14
C56: 2022 | D56: 2023 | E56: 2024 | F56: 2025 | G56: 2026
C57: 20 | D57: 244 | E57: 349 | F57: 607 | G57: 71 | H57: =SUM(C57:G57) -> 1291
C58: 10 | G58: 55

Sheet QTR Raw
A1: ='Annual Raw'!A1 -> 208433 | B1: X | C1: 201206 | D1: 201209 | E1: 201212 | F1: 201303 | G1: 201306 | H1: 201309 | I1: 201312 | J1: 201403 | K1: 201406 | L1: 201409 | M1: 201412 | N1: 201503 | O1: 201506 | P1: 201509 | Q1: 201512 | R1: 201603 | S1: 201606 | T1: 201609 | U1: 201612 | V1: 201703 | W1: 201706 | X1: 201709 | Y1: 201712 | Z1: 201803 | AA1: 201806 | AB1: 201809 | AC1: 201812 | AD1: 201903 | AE1: 201906 | AF1: 201909 | AG1: 201912 | AH1: 202003 | AI1: 202006 | AJ1: 202009 | AK1: 202012 | AL1: 202103 | AM1: 202106 | AN1: 202109 | AO1: 202112 | AP1: 202203 | AQ1: 202206 | AR1: 202209 | AS1: 202212 | AT1: 202303 | AU1: 202306 | AV1: 202309 | AW1: 202312 | AX1: 202403 | AY1: 202406 | AZ1: 202409 | BA1: 202412 | BB1: 202503 | BC1: 202506 | BD1: 202509 | BE1: 202512 | BF1: 202603 | BG1: 202606 | BH1: 202609 | BI1: 202612 | BJ1: 202703 | BK1: 202706 | BL1: 202709 | BM1: 202712 | BN1: 202803 | BO1: 202806 | BP1: 202809 | BQ1: 202812 | BR1: 202903 | BS1: 202906 | BT1: 202909 | BU1: 202912 | BV1: 203003
A3: Field Description | B3: Field Name
A4: Company Name | B4: CD_COMPNAME | C4: =_xll.EQNXTDZ(A1,B4,C1) -> Inox India Ltd.
A5: Date End | B5: QTR_DATE_END | C5: =_xll.EQNXTDZ($A$1,$B5,C$1,$B$1) -> 0 | D5: =_xll.EQNXTDZ($A$1,$B5,D$1,$B$1) -> 0 | E5: =_xll.EQNXTDZ($A$1,$B5,E$1,$B$1) -> 0 | F5: =_xll.EQNXTDZ($A$1,$B5,F$1,$B$1) -> 0 | G5: =_xll.EQNXTDZ($A$1,$B5,G$1,$B$1) -> 0 | H5: =_xll.EQNXTDZ($A$1,$B5,H$1,$B$1) -> 0 | I5: =_xll.EQNXTDZ($A$1,$B5,I$1,$B$1) -> 0 | J5: =_xll.EQNXTDZ($A$1,$B5,J$1,$B$1) -> 0 | ... BV5: =_xll.EQNXTDZ($A$1,$B5,BV$1,$B$1) -> 0
A6: Gross Sales | B6: QTR_GROSS_SALE | C6: =_xll.EQNXTDZ($A$1,$B6,C$1,$B$1) -> 0 | D6: =_xll.EQNXTDZ($A$1,$B6,D$1,$B$1) -> 0 | E6: =_xll.EQNXTDZ($A$1,$B6,E$1,$B$1) -> 0 | F6: =_xll.EQNXTDZ($A$1,$B6,F$1,$B$1) -> 0 | G6: =_xll.EQNXTDZ($A$1,$B6,G$1,$B$1) -> 0 | H6: =_xll.EQNXTDZ($A$1,$B6,H$1,$B$1) -> 0 | I6: =_xll.EQNXTDZ($A$1,$B6,I$1,$B$1) -> 0 | J6: =_xll.EQNXTDZ($A$1,$B6,J$1,$B$1) -> 0 | ... BV6: =_xll.EQNXTDZ($A$1,$B6,BV$1,$B$1) -> 0
A7: Less: Excise Duty | B7: QTR_EXCISE_DUTY | C7: =_xll.EQNXTDZ($A$1,$B7,C$1,$B$1) -> 0 | D7: =_xll.EQNXTDZ($A$1,$B7,D$1,$B$1) -> 0 | E7: =_xll.EQNXTDZ($A$1,$B7,E$1,$B$1) -> 0 | F7: =_xll.EQNXTDZ($A$1,$B7,F$1,$B$1) -> 0 | G7: =_xll.EQNXTDZ($A$1,$B7,G$1,$B$1) -> 0 | H7: =_xll.EQNXTDZ($A$1,$B7,H$1,$B$1) -> 0 | I7: =_xll.EQNXTDZ($A$1,$B7,I$1,$B$1) -> 0 | J7: =_xll.EQNXTDZ($A$1,$B7,J$1,$B$1) -> 0 | ... BV7: =_xll.EQNXTDZ($A$1,$B7,BV$1,$B$1) -> 0
A8: Other operating income | B8: QTR_JOB_WORKS | C8: =_xll.EQNXTDZ($A$1,$B8,C$1,$B$1) -> 0 | D8: =_xll.EQNXTDZ($A$1,$B8,D$1,$B$1) -> 0 | E8: =_xll.EQNXTDZ($A$1,$B8,E$1,$B$1) -> 0 | F8: =_xll.EQNXTDZ($A$1,$B8,F$1,$B$1) -> 0 | G8: =_xll.EQNXTDZ($A$1,$B8,G$1,$B$1) -> 0 | H8: =_xll.EQNXTDZ($A$1,$B8,H$1,$B$1) -> 0 | I8: =_xll.EQNXTDZ($A$1,$B8,I$1,$B$1) -> 0 | J8: =_xll.EQNXTDZ($A$1,$B8,J$1,$B$1) -> 0 | ... BV8: =_xll.EQNXTDZ($A$1,$B8,BV$1,$B$1) -> 0
A9: Net Sales & Other Operating Income | B9: QTR_NET_SALES | C9: =_xll.EQNXTDZ($A$1,$B9,C$1,$B$1) -> 0 | D9: =_xll.EQNXTDZ($A$1,$B9,D$1,$B$1) -> 0 | E9: =_xll.EQNXTDZ($A$1,$B9,E$1,$B$1) -> 0 | F9: =_xll.EQNXTDZ($A$1,$B9,F$1,$B$1) -> 0 | G9: =_xll.EQNXTDZ($A$1,$B9,G$1,$B$1) -> 0 | H9: =_xll.EQNXTDZ($A$1,$B9,H$1,$B$1) -> 0 | I9: =_xll.EQNXTDZ($A$1,$B9,I$1,$B$1) -> 0 | J9: =_xll.EQNXTDZ($A$1,$B9,J$1,$B$1) -> 0 | ... BV9: =_xll.EQNXTDZ($A$1,$B9,BV$1,$B$1) -> 0
A10: (Increase) / Decrease In Stocks | B10: QTR_INC_DEC_INVENTORY | C10: =_xll.EQNXTDZ($A$1,$B10,C$1,$B$1) -> 0 | D10: =_xll.EQNXTDZ($A$1,$B10,D$1,$B$1) -> 0 | E10: =_xll.EQNXTDZ($A$1,$B10,E$1,$B$1) -> 0 | F10: =_xll.EQNXTDZ($A$1,$B10,F$1,$B$1) -> 0 | G10: =_xll.EQNXTDZ($A$1,$B10,G$1,$B$1) -> 0 | H10: =_xll.EQNXTDZ($A$1,$B10,H$1,$B$1) -> 0 | I10: =_xll.EQNXTDZ($A$1,$B10,I$1,$B$1) -> 0 | J10: =_xll.EQNXTDZ($A$1,$B10,J$1,$B$1) -> 0 | ... BV10: =_xll.EQNXTDZ($A$1,$B10,BV$1,$B$1) -> 0
A11: Cost of Services & Raw Materials | B11: QTR_RAW_MATERIAL_COST | C11: =_xll.EQNXTDZ($A$1,$B11,C$1,$B$1) -> 0 | D11: =_xll.EQNXTDZ($A$1,$B11,D$1,$B$1) -> 0 | E11: =_xll.EQNXTDZ($A$1,$B11,E$1,$B$1) -> 0 | F11: =_xll.EQNXTDZ($A$1,$B11,F$1,$B$1) -> 0 | G11: =_xll.EQNXTDZ($A$1,$B11,G$1,$B$1) -> 0 | H11: =_xll.EQNXTDZ($A$1,$B11,H$1,$B$1) -> 0 | I11: =_xll.EQNXTDZ($A$1,$B11,I$1,$B$1) -> 0 | J11: =_xll.EQNXTDZ($A$1,$B11,J$1,$B$1) -> 0 | ... BV11: =_xll.EQNXTDZ($A$1,$B11,BV$1,$B$1) -> 0
A12: Purchase of Finished Goods | B12: QTR_PURCHASE_FIN_GOOD | C12: =_xll.EQNXTDZ($A$1,$B12,C$1,$B$1) -> 0 | D12: =_xll.EQNXTDZ($A$1,$B12,D$1,$B$1) -> 0 | E12: =_xll.EQNXTDZ($A$1,$B12,E$1,$B$1) -> 0 | F12: =_xll.EQNXTDZ($A$1,$B12,F$1,$B$1) -> 0 | G12: =_xll.EQNXTDZ($A$1,$B12,G$1,$B$1) -> 0 | H12: =_xll.EQNXTDZ($A$1,$B12,H$1,$B$1) -> 0 | I12: =_xll.EQNXTDZ($A$1,$B12,I$1,$B$1) -> 0 | J12: =_xll.EQNXTDZ($A$1,$B12,J$1,$B$1) -> 0 | ... BV12: =_xll.EQNXTDZ($A$1,$B12,BV$1,$B$1) -> 0
A13: Excise Duty | B13: QTR_EXCISE | C13: =_xll.EQNXTDZ($A$1,$B13,C$1,$B$1) -> 0 | D13: =_xll.EQNXTDZ($A$1,$B13,D$1,$B$1) -> 0 | E13: =_xll.EQNXTDZ($A$1,$B13,E$1,$B$1) -> 0 | F13: =_xll.EQNXTDZ($A$1,$B13,F$1,$B$1) -> 0 | G13: =_xll.EQNXTDZ($A$1,$B13,G$1,$B$1) -> 0 | H13: =_xll.EQNXTDZ($A$1,$B13,H$1,$B$1) -> 0 | I13: =_xll.EQNXTDZ($A$1,$B13,I$1,$B$1) -> 0 | J13: =_xll.EQNXTDZ($A$1,$B13,J$1,$B$1) -> 0 | ... BV13: =_xll.EQNXTDZ($A$1,$B13,BV$1,$B$1) -> 0
A14: Operating & Manufacturing Expenses | B14: QTR_MFG_EXPS | C14: =_xll.EQNXTDZ($A$1,$B14,C$1,$B$1) -> 0 | D14: =_xll.EQNXTDZ($A$1,$B14,D$1,$B$1) -> 0 | E14: =_xll.EQNXTDZ($A$1,$B14,E$1,$B$1) -> 0 | F14: =_xll.EQNXTDZ($A$1,$B14,F$1,$B$1) -> 0 | G14: =_xll.EQNXTDZ($A$1,$B14,G$1,$B$1) -> 0 | H14: =_xll.EQNXTDZ($A$1,$B14,H$1,$B$1) -> 0 | I14: =_xll.EQNXTDZ($A$1,$B14,I$1,$B$1) -> 0 | J14: =_xll.EQNXTDZ($A$1,$B14,J$1,$B$1) -> 0 | ... BV14: =_xll.EQNXTDZ($A$1,$B14,BV$1,$B$1) -> 0
A15: Electricity Power & Fuel Cost | B15: QTR_ELECTRICITY_POWER_FUEL | C15: =_xll.EQNXTDZ($A$1,$B15,C$1,$B$1) -> 0 | D15: =_xll.EQNXTDZ($A$1,$B15,D$1,$B$1) -> 0 | E15: =_xll.EQNXTDZ($A$1,$B15,E$1,$B$1) -> 0 | F15: =_xll.EQNXTDZ($A$1,$B15,F$1,$B$1) -> 0 | G15: =_xll.EQNXTDZ($A$1,$B15,G$1,$B$1) -> 0 | H15: =_xll.EQNXTDZ($A$1,$B15,H$1,$B$1) -> 0 | I15: =_xll.EQNXTDZ($A$1,$B15,I$1,$B$1) -> 0 | J15: =_xll.EQNXTDZ($A$1,$B15,J$1,$B$1) -> 0 | ... BV15: =_xll.EQNXTDZ($A$1,$B15,BV$1,$B$1) -> 0
A16: Employee Cost | B16: QTR_EXPLOYEE_COST | C16: =_xll.EQNXTDZ($A$1,$B16,C$1,$B$1) -> 0 | D16: =_xll.EQNXTDZ($A$1,$B16,D$1,$B$1) -> 0 | E16: =_xll.EQNXTDZ($A$1,$B16,E$1,$B$1) -> 0 | F16: =_xll.EQNXTDZ($A$1,$B16,F$1,$B$1) -> 0 | G16: =_xll.EQNXTDZ($A$1,$B16,G$1,$B$1) -> 0 | H16: =_xll.EQNXTDZ($A$1,$B16,H$1,$B$1) -> 0 | I16: =_xll.EQNXTDZ($A$1,$B16,I$1,$B$1) -> 0 | J16: =_xll.EQNXTDZ($A$1,$B16,J$1,$B$1) -> 0 | ... BV16: =_xll.EQNXTDZ($A$1,$B16,BV$1,$B$1) -> 0
... A42: Consolidated PAT(after extra items) | B42: QTR_CONS_PAT_EXITM | C42: =_xll.EQNXTDZ($A$1,$B42,C$1,$B$1) -> 0 | D42: =_xll.EQNXTDZ($A$1,$B42,D$1,$B$1) -> 0 | E42: =_xll.EQNXTDZ($A$1,$B42,E$1,$B$1) -> 0 | F42: =_xll.EQNXTDZ($A$1,$B42,F$1,$B$1) -> 0 | G42: =_xll.EQNXTDZ($A$1,$B42,G$1,$B$1) -> 0 | H42: =_xll.EQNXTDZ($A$1,$B42,H$1,$B$1) -> 0 | I42: =_xll.EQNXTDZ($A$1,$B42,I$1,$B$1) -> 0 | J42: =_xll.EQNXTDZ($A$1,$B42,J$1,$B$1) -> 0 | ... BV42: =_xll.EQNXTDZ($A$1,$B42,BV$1,$B$1) -> 0
A44: Field Description | B44: Field Name
A45: Equity Capital | B45: QTR_EQUITY_CAP | C45: =_xll.EQNXTDZ($A$1,$B45,C$1,$B$1) -> 0 | D45: =_xll.EQNXTDZ($A$1,$B45,D$1,$B$1) -> 0 | E45: =_xll.EQNXTDZ($A$1,$B45,E$1,$B$1) -> 0 | F45: =_xll.EQNXTDZ($A$1,$B45,F$1,$B$1) -> 0 | G45: =_xll.EQNXTDZ($A$1,$B45,G$1,$B$1) -> 0 | H45: =_xll.EQNXTDZ($A$1,$B45,H$1,$B$1) -> 0 | I45: =_xll.EQNXTDZ($A$1,$B45,I$1,$B$1) -> 0 | J45: =_xll.EQNXTDZ($A$1,$B45,J$1,$B$1) -> 0 | ... BV45: =_xll.EQNXTDZ($A$1,$B45,BV$1,$B$1) -> 0
A46: Face Value | B46: QTR_FV | C46: =_xll.EQNXTDZ($A$1,$B46,C$1,$B$1) -> 0 | D46: =_xll.EQNXTDZ($A$1,$B46,D$1,$B$1) -> 0 | E46: =_xll.EQNXTDZ($A$1,$B46,E$1,$B$1) -> 0 | F46: =_xll.EQNXTDZ($A$1,$B46,F$1,$B$1) -> 0 | G46: =_xll.EQNXTDZ($A$1,$B46,G$1,$B$1) -> 0 | H46: =_xll.EQNXTDZ($A$1,$B46,H$1,$B$1) -> 0 | I46: =_xll.EQNXTDZ($A$1,$B46,I$1,$B$1) -> 0 | J46: =_xll.EQNXTDZ($A$1,$B46,J$1,$B$1) -> 0 | ... BV46: =_xll.EQNXTDZ($A$1,$B46,BV$1,$B$1) -> 0
A47: Month End | B47: BMONTH_MONTHEND | C47: =_xll.EQNXTDZ($A$1,$B47,C$5) -> 0 | D47: =_xll.EQNXTDZ($A$1,$B47,D$5) -> 0 | E47: =_xll.EQNXTDZ($A$1,$B47,E$5) -> 0 | F47: =_xll.EQNXTDZ($A$1,$B47,F$5) -> 0 | G47: =_xll.EQNXTDZ($A$1,$B47,G$5) -> 0 | H47: =_xll.EQNXTDZ($A$1,$B47,H$5) -> 0 | I47: =_xll.EQNXTDZ($A$1,$B47,I$5) -> 0 | J47: =_xll.EQNXTDZ($A$1,$B47,J$5) -> 0 | ... BV47: =_xll.EQNXTDZ($A$1,$B47,BV$5) -> 0
A48: Close | B48: BMONTH_CLOSE | C48: =_xll.EQNXTDZ($A$1,$B48,C$5) -> 0 | D48: =_xll.EQNXTDZ($A$1,$B48,D$5) -> 0 | E48: =_xll.EQNXTDZ($A$1,$B48,E$5) -> 0 | F48: =_xll.EQNXTDZ($A$1,$B48,F$5) -> 0 | G48: =_xll.EQNXTDZ($A$1,$B48,G$5) -> 0 | H48: =_xll.EQNXTDZ($A$1,$B48,H$5) -> 0 | I48: =_xll.EQNXTDZ($A$1,$B48,I$5) -> 0 | J48: =_xll.EQNXTDZ($A$1,$B48,J$5) -> 0 | ... BV48: =_xll.EQNXTDZ($A$1,$B48,BV$5) -> 0
A49: Total of Promoter and Promoter Group | B49: SHP_TPFTOTALPROMOTER | C49: =_xll.EQNXTDZ($A$1,$B49,C$5) -> 0 | D49: =_xll.EQNXTDZ($A$1,$B49,D$5) -> 0 | E49: =_xll.EQNXTDZ($A$1,$B49,E$5) -> 0 | F49: =_xll.EQNXTDZ($A$1,$B49,F$5) -> 0 | G49: =_xll.EQNXTDZ($A$1,$B49,G$5) -> 0 | H49: =_xll.EQNXTDZ($A$1,$B49,H$5) -> 0 | I49: =_xll.EQNXTDZ($A$1,$B49,I$5) -> 0 | J49: =_xll.EQNXTDZ($A$1,$B49,J$5) -> 0 | ... BV49: =_xll.EQNXTDZ($A$1,$B49,BV$5) -> 0
A50: Total of Promoter and Promoter Group Pledged | B50: SHP_PSHFTOTALPROMOTER | C50: =_xll.EQNXTDZ($A$1,$B50,C$5) -> 0 | D50: =_xll.EQNXTDZ($A$1,$B50,D$5) -> 0 | E50: =_xll.EQNXTDZ($A$1,$B50,E$5) -> 0 | F50: =_xll.EQNXTDZ($A$1,$B50,F$5) -> 0 | G50: =_xll.EQNXTDZ($A$1,$B50,G$5) -> 0 | H50: =_xll.EQNXTDZ($A$1,$B50,H$5) -> 0 | I50: =_xll.EQNXTDZ($A$1,$B50,I$5) -> 0 | J50: =_xll.EQNXTDZ($A$1,$B50,J$5) -> 0 | ... BV50: =_xll.EQNXTDZ($A$1,$B50,BV$5) -> 0
A54: Field Description | B54: Field Name | C54: =_xll.EQNXTDZ($A$1,$B54,C$5) -> 0 | D54: =_xll.EQNXTDZ($A$1,$B54,D$5) -> 0 | E54: =_xll.EQNXTDZ($A$1,$B54,E$5) -> 0 | F54: =_xll.EQNXTDZ($A$1,$B54,F$5) -> 0 | G54: =_xll.EQNXTDZ($A$1,$B54,G$5) -> 0 | H54: =_xll.EQNXTDZ($A$1,$B54,H$5) -> 0 | I54: =_xll.EQNXTDZ($A$1,$B54,I$5) -> 0 | J54: =_xll.EQNXTDZ($A$1,$B54,J$5) -> 0 | ... BV54: =_xll.EQNXTDZ($A$1,$B54,BV$5) -> 0
A55: Year End | B55: QTRB_DATE_END | C55: =_xll.EQNXTDZ($A$1,$B55,C$5,$B$1) -> 0 | D55: =_xll.EQNXTDZ($A$1,$B55,D$5,$B$1) -> 0 | E55: =_xll.EQNXTDZ($A$1,$B55,E$5,$B$1) -> 0 | F55: =_xll.EQNXTDZ($A$1,$B55,F$5,$B$1) -> 0 | G55: =_xll.EQNXTDZ($A$1,$B55,G$5,$B$1) -> 0 | H55: =_xll.EQNXTDZ($A$1,$B55,H$5,$B$1) -> 0 | I55: =_xll.EQNXTDZ($A$1,$B55,I$5,$B$1) -> 0 | J55: =_xll.EQNXTDZ($A$1,$B55,J$5,$B$1) -> 0 | ... BV55: =_xll.EQNXTDZ($A$1,$B55,BV$5,$B$1) -> 0
A56: Share Capital | B56: QTRB_SHARE_CAPITAL | C56: =_xll.EQNXTDZ($A$1,$B56,C$5,$B$1) -> 0 | D56: =_xll.EQNXTDZ($A$1,$B56,D$5,$B$1) -> 0 | E56: =_xll.EQNXTDZ($A$1,$B56,E$5,$B$1) -> 0 | F56: =_xll.EQNXTDZ($A$1,$B56,F$5,$B$1) -> 0 | G56: =_xll.EQNXTDZ($A$1,$B56,G$5,$B$1) -> 0 | H56: =_xll.EQNXTDZ($A$1,$B56,H$5,$B$1) -> 0 | I56: =_xll.EQNXTDZ($A$1,$B56,I$5,$B$1) -> 0 | J56: =_xll.EQNXTDZ($A$1,$B56,J$5,$B$1) -> 0 | ... BV56: =_xll.EQNXTDZ($A$1,$B56,BV$5,$B$1) -> 0
A57: Share Warrants & outstandings | B57: QTRB_SHAREWARNDOUT | C57: =_xll.EQNXTDZ($A$1,$B57,C$5,$B$1) -> 0 | D57: =_xll.EQNXTDZ($A$1,$B57,D$5,$B$1) -> 0 | E57: =_xll.EQNXTDZ($A$1,$B57,E$5,$B$1) -> 0 | F57: =_xll.EQNXTDZ($A$1,$B57,F$5,$B$1) -> 0 | G57: =_xll.EQNXTDZ($A$1,$B57,G$5,$B$1) -> 0 | H57: =_xll.EQNXTDZ($A$1,$B57,H$5,$B$1) -> 0 | I57: =_xll.EQNXTDZ($A$1,$B57,I$5,$B$1) -> 0 | J57: =_xll.EQNXTDZ($A$1,$B57,J$5,$B$1) -> 0 | ... BV57: =_xll.EQNXTDZ($A$1,$B57,BV$5,$B$1) -> 0
A58: Reserves & Surplus | B58: QTRB_RESERVE | C58: =_xll.EQNXTDZ($A$1,$B58,C$5,$B$1) -> 0 | D58: =_xll.EQNXTDZ($A$1,$B58,D$5,$B$1) -> 0 | E58: =_xll.EQNXTDZ($A$1,$B58,E$5,$B$1) -> 0 | F58: =_xll.EQNXTDZ($A$1,$B58,F$5,$B$1) -> 0 | G58: =_xll.EQNXTDZ($A$1,$B58,G$5,$B$1) -> 0 | H58: =_xll.EQNXTDZ($A$1,$B58,H$5,$B$1) -> 0 | I58: =_xll.EQNXTDZ($A$1,$B58,I$5,$B$1) -> 0 | J58: =_xll.EQNXTDZ($A$1,$B58,J$5,$B$1) -> 0 | ... BV58: =_xll.EQNXTDZ($A$1,$B58,BV$5,$B$1) -> 0
A59: Shareholder's Funds | B59: QTRB_SHAREHODERS_FUNDS | C59: =_xll.EQNXTDZ($A$1,$B59,C$5,$B$1) -> 0 | D59: =_xll.EQNXTDZ($A$1,$B59,D$5,$B$1) -> 0 | E59: =_xll.EQNXTDZ($A$1,$B59,E$5,$B$1) -> 0 | F59: =_xll.EQNXTDZ($A$1,$B59,F$5,$B$1) -> 0 | G59: =_xll.EQNXTDZ($A$1,$B59,G$5,$B$1) -> 0 | H59: =_xll.EQNXTDZ($A$1,$B59,H$5,$B$1) -> 0 | I59: =_xll.EQNXTDZ($A$1,$B59,I$5,$B$1) -> 0 | J59: =_xll.EQNXTDZ($A$1,$B59,J$5,$B$1) -> 0 | ... BV59: =_xll.EQNXTDZ($A$1,$B59,BV$5,$B$1) -> 0
A60: Minority Interest | B60: QTRB_MINORITY_INTEREST_BS | C60: =_xll.EQNXTDZ($A$1,$B60,C$5,$B$1) -> 0 | D60: =_xll.EQNXTDZ($A$1,$B60,D$5,$B$1) -> 0 | E60: =_xll.EQNXTDZ($A$1,$B60,E$5,$B$1) -> 0 | F60: =_xll.EQNXTDZ($A$1,$B60,F$5,$B$1) -> 0 | G60: =_xll.EQNXTDZ($A$1,$B60,G$5,$B$1) -> 0 | H60: =_xll.EQNXTDZ($A$1,$B60,H$5,$B$1) -> 0 | I60: =_xll.EQNXTDZ($A$1,$B60,I$5,$B$1) -> 0 | J60: =_xll.EQNXTDZ($A$1,$B60,J$5,$B$1) -> 0 | ... BV60: =_xll.EQNXTDZ($A$1,$B60,BV$5,$B$1) -> 0
A61: Long Term Borrowings | B61: QTRB_TOTAL_DEBTS | C61: =_xll.EQNXTDZ($A$1,$B61,C$5,$B$1) -> 0 | D61: =_xll.EQNXTDZ($A$1,$B61,D$5,$B$1) -> 0 | E61: =_xll.EQNXTDZ($A$1,$B61,E$5,$B$1) -> 0 | F61: =_xll.EQNXTDZ($A$1,$B61,F$5,$B$1) -> 0 | G61: =_xll.EQNXTDZ($A$1,$B61,G$5,$B$1) -> 0 | H61: =_xll.EQNXTDZ($A$1,$B61,H$5,$B$1) -> 0 | I61: =_xll.EQNXTDZ($A$1,$B61,I$5,$B$1) -> 0 | J61: =_xll.EQNXTDZ($A$1,$B61,J$5,$B$1) -> 0 | ... BV61: =_xll.EQNXTDZ($A$1,$B61,BV$5,$B$1) -> 0
A62: Secured Loans | B62: QTRB_SECURED_LOANS | C62: =_xll.EQNXTDZ($A$1,$B62,C$5,$B$1) -> 0 | D62: =_xll.EQNXTDZ($A$1,$B62,D$5,$B$1) -> 0 | E62: =_xll.EQNXTDZ($A$1,$B62,E$5,$B$1) -> 0 | F62: =_xll.EQNXTDZ($A$1,$B62,F$5,$B$1) -> 0 | G62: =_xll.EQNXTDZ($A$1,$B62,G$5,$B$1) -> 0 | H62: =_xll.EQNXTDZ($A$1,$B62,H$5,$B$1) -> 0 | I62: =_xll.EQNXTDZ($A$1,$B62,I$5,$B$1) -> 0 | J62: =_xll.EQNXTDZ($A$1,$B62,J$5,$B$1) -> 0 | ... BV62: =_xll.EQNXTDZ($A$1,$B62,BV$5,$B$1) -> 0
A63: Unsecured Loans | B63: QTRB_UNSECURED_LOANS_NF | C63: =_xll.EQNXTDZ($A$1,$B63,C$5,$B$1) -> 0 | D63: =_xll.EQNXTDZ($A$1,$B63,D$5,$B$1) -> 0 | E63: =_xll.EQNXTDZ($A$1,$B63,E$5,$B$1) -> 0 | F63: =_xll.EQNXTDZ($A$1,$B63,F$5,$B$1) -> 0 | G63: =_xll.EQNXTDZ($A$1,$B63,G$5,$B$1) -> 0 | H63: =_xll.EQNXTDZ($A$1,$B63,H$5,$B$1) -> 0 | I63: =_xll.EQNXTDZ($A$1,$B63,I$5,$B$1) -> 0 | J63: =_xll.EQNXTDZ($A$1,$B63,J$5,$B$1) -> 0 | ... BV63: =_xll.EQNXTDZ($A$1,$B63,BV$5,$B$1) -> 0
A64: Other Long Term Liabilities | B64: QTRB_OTHER_LT_LIABILITIES | C64: =_xll.EQNXTDZ($A$1,$B64,C$5,$B$1) -> 0 | D64: =_xll.EQNXTDZ($A$1,$B64,D$5,$B$1) -> 0 | E64: =_xll.EQNXTDZ($A$1,$B64,E$5,$B$1) -> 0 | F64: =_xll.EQNXTDZ($A$1,$B64,F$5,$B$1) -> 0 | G64: =_xll.EQNXTDZ($A$1,$B64,G$5,$B$1) -> 0 | H64: =_xll.EQNXTDZ($A$1,$B64,H$5,$B$1) -> 0 | I64: =_xll.EQNXTDZ($A$1,$B64,I$5,$B$1) -> 0 | J64: =_xll.EQNXTDZ($A$1,$B64,J$5,$B$1) -> 0 | ... BV64: =_xll.EQNXTDZ($A$1,$B64,BV$5,$B$1) -> 0
A65: Long Term Trade Payables | B65: QTRB_LT_TRADE_PAYABLE | C65: =_xll.EQNXTDZ($A$1,$B65,C$5,$B$1) -> 0 | D65: =_xll.EQNXTDZ($A$1,$B65,D$5,$B$1) -> 0 | E65: =_xll.EQNXTDZ($A$1,$B65,E$5,$B$1) -> 0 | F65: =_xll.EQNXTDZ($A$1,$B65,F$5,$B$1) -> 0 | G65: =_xll.EQNXTDZ($A$1,$B65,G$5,$B$1) -> 0 | H65: =_xll.EQNXTDZ($A$1,$B65,H$5,$B$1) -> 0 | I65: =_xll.EQNXTDZ($A$1,$B65,I$5,$B$1) -> 0 | J65: =_xll.EQNXTDZ($A$1,$B65,J$5,$B$1) -> 0 | ... BV65: =_xll.EQNXTDZ($A$1,$B65,BV$5,$B$1) -> 0
A66: Lont Term Provisions | B66: QTRB_LT_PROVISIONS | C66: =_xll.EQNXTDZ($A$1,$B66,C$5,$B$1) -> 0 | D66: =_xll.EQNXTDZ($A$1,$B66,D$5,$B$1) -> 0 | E66: =_xll.EQNXTDZ($A$1,$B66,E$5,$B$1) -> 0 | F66: =_xll.EQNXTDZ($A$1,$B66,F$5,$B$1) -> 0 | G66: =_xll.EQNXTDZ($A$1,$B66,G$5,$B$1) -> 0 | H66: =_xll.EQNXTDZ($A$1,$B66,H$5,$B$1) -> 0 | I66: =_xll.EQNXTDZ($A$1,$B66,I$5,$B$1) -> 0 | J66: =_xll.EQNXTDZ($A$1,$B66,J$5,$B$1) -> 0 | ... BV66: =_xll.EQNXTDZ($A$1,$B66,BV$5,$B$1) -> 0
... A97: Total Assets | B97: QTRB_TOTAL_APPLICATIONS | C97: =_xll.EQNXTDZ($A$1,$B97,C$5,$B$1) -> 0 | D97: =_xll.EQNXTDZ($A$1,$B97,D$5,$B$1) -> 0 | E97: =_xll.EQNXTDZ($A$1,$B97,E$5,$B$1) -> 0 | F97: =_xll.EQNXTDZ($A$1,$B97,F$5,$B$1) -> 0 | G97: =_xll.EQNXTDZ($A$1,$B97,G$5,$B$1) -> 0 | H97: =_xll.EQNXTDZ($A$1,$B97,H$5,$B$1) -> 0 | I97: =_xll.EQNXTDZ($A$1,$B97,I$5,$B$1) -> 0 | J97: =_xll.EQNXTDZ($A$1,$B97,J$5,$B$1) -> 0 | ... BV97: =_xll.EQNXTDZ($A$1,$B97,BV$5,$B$1) -> 0

Sheet Annual Raw
A1: 208433 | B1: X | C1: 200103 | D1: 200203 | E1: 200303 | F1: 200403 | G1: 200503 | H1: 200603 | I1: 200703 | J1: 200803 | K1: 200903 | L1: 201003 | M1: 201103 | N1: 201203 | O1: 201303 | P1: 201403 | Q1: 201503 | R1: 201603 | S1: 201703 | T1: 201803 | U1: 201903 | V1: 202003 | W1: 202103 | X1: 202203 | Y1: 202303 | Z1: 202403 | AA1: 202503 | AB1: 202603 | AC1: 202703 | AD1: 202803 | AE1: 202903 | AF1: 203003
A3: Field Description | B3: Field Name
A4: Company Name | B4: CD_COMPNAME | C4: =_xll.EQNXTDZ(A1,B4,"L") -> Inox India Ltd.
A5: Year End | B5: PL_YEAR_END | C5: =_xll.EQNXTDZ($A$1,$B5,C$1,$B$1) -> 200103 | D5: =_xll.EQNXTDZ($A$1,$B5,D$1,$B$1) -> 200203 | E5: =_xll.EQNXTDZ($A$1,$B5,E$1,$B$1) -> 200303 | F5: =_xll.EQNXTDZ($A$1,$B5,F$1,$B$1) -> 200403 | G5: =_xll.EQNXTDZ($A$1,$B5,G$1,$B$1) -> 200503 | H5: =_xll.EQNXTDZ($A$1,$B5,H$1,$B$1) -> 200603 | I5: =_xll.EQNXTDZ($A$1,$B5,I$1,$B$1) -> 200703 | J5: =_xll.EQNXTDZ($A$1,$B5,J$1,$B$1) -> 200803 | ... AF5: =_xll.EQNXTDZ($A$1,$B5,AF$1,$B$1) -> 0
A6: Sales Turnover | B6: PL_TOTAL_GROSS_SALES | C6: =_xll.EQNXTDZ($A$1,$B6,C$1,$B$1) -> 35.032452 | D6: =_xll.EQNXTDZ($A$1,$B6,D$1,$B$1) -> 51.527453 | E6: =_xll.EQNXTDZ($A$1,$B6,E$1,$B$1) -> 48.232658 | F6: =_xll.EQNXTDZ($A$1,$B6,F$1,$B$1) -> 51.989955 | G6: =_xll.EQNXTDZ($A$1,$B6,G$1,$B$1) -> 54.900097 | H6: =_xll.EQNXTDZ($A$1,$B6,H$1,$B$1) -> 87.1955 | I6: =_xll.EQNXTDZ($A$1,$B6,I$1,$B$1) -> 137.65676 | J6: =_xll.EQNXTDZ($A$1,$B6,J$1,$B$1) -> 205.30286 | ... AF6: =_xll.EQNXTDZ($A$1,$B6,AF$1,$B$1) -> 0
A7: Less: Inter divisional transfers | B7: PL_INTER_DIV_TRF | C7: =_xll.EQNXTDZ($A$1,$B7,C$1,$B$1) -> 0 | D7: =_xll.EQNXTDZ($A$1,$B7,D$1,$B$1) -> 0 | E7: =_xll.EQNXTDZ($A$1,$B7,E$1,$B$1) -> 0 | F7: =_xll.EQNXTDZ($A$1,$B7,F$1,$B$1) -> 0 | G7: =_xll.EQNXTDZ($A$1,$B7,G$1,$B$1) -> 0 | H7: =_xll.EQNXTDZ($A$1,$B7,H$1,$B$1) -> 0 | I7: =_xll.EQNXTDZ($A$1,$B7,I$1,$B$1) -> 0 | J7: =_xll.EQNXTDZ($A$1,$B7,J$1,$B$1) -> 0 | ... AF7: =_xll.EQNXTDZ($A$1,$B7,AF$1,$B$1) -> 0
A8: Less: Sales Returns | B8: PL_SALES_RETURN | C8: =_xll.EQNXTDZ($A$1,$B8,C$1,$B$1) -> 0 | D8: =_xll.EQNXTDZ($A$1,$B8,D$1,$B$1) -> 0 | E8: =_xll.EQNXTDZ($A$1,$B8,E$1,$B$1) -> 0 | F8: =_xll.EQNXTDZ($A$1,$B8,F$1,$B$1) -> 0 | G8: =_xll.EQNXTDZ($A$1,$B8,G$1,$B$1) -> 0 | H8: =_xll.EQNXTDZ($A$1,$B8,H$1,$B$1) -> 0 | I8: =_xll.EQNXTDZ($A$1,$B8,I$1,$B$1) -> 0 | J8: =_xll.EQNXTDZ($A$1,$B8,J$1,$B$1) -> 0 | ... AF8: =_xll.EQNXTDZ($A$1,$B8,AF$1,$B$1) -> 0
A9: Less: Excise | B9: PL_EXCISE | C9: =_xll.EQNXTDZ($A$1,$B9,C$1,$B$1) -> 3.2351323 | D9: =_xll.EQNXTDZ($A$1,$B9,D$1,$B$1) -> 2.5807622 | E9: =_xll.EQNXTDZ($A$1,$B9,E$1,$B$1) -> 1.7177281 | F9: =_xll.EQNXTDZ($A$1,$B9,F$1,$B$1) -> 2.7170725 | G9: =_xll.EQNXTDZ($A$1,$B9,G$1,$B$1) -> 3.4063634 | H9: =_xll.EQNXTDZ($A$1,$B9,H$1,$B$1) -> 5.3058515 | I9: =_xll.EQNXTDZ($A$1,$B9,I$1,$B$1) -> 7.3428139 | J9: =_xll.EQNXTDZ($A$1,$B9,J$1,$B$1) -> 11.593145 | ... AF9: =_xll.EQNXTDZ($A$1,$B9,AF$1,$B$1) -> 0
A10: Net Sales | B10: PL_NET_SALES | C10: =_xll.EQNXTDZ($A$1,$B10,C$1,$B$1) -> 31.797319 | D10: =_xll.EQNXTDZ($A$1,$B10,D$1,$B$1) -> 48.946691 | E10: =_xll.EQNXTDZ($A$1,$B10,E$1,$B$1) -> 46.51493 | F10: =_xll.EQNXTDZ($A$1,$B10,F$1,$B$1) -> 49.272882 | G10: =_xll.EQNXTDZ($A$1,$B10,G$1,$B$1) -> 51.493733 | H10: =_xll.EQNXTDZ($A$1,$B10,H$1,$B$1) -> 81.889649 | I10: =_xll.EQNXTDZ($A$1,$B10,I$1,$B$1) -> 130.31394 | J10: =_xll.EQNXTDZ($A$1,$B10,J$1,$B$1) -> 193.70972 | ... AF10: =_xll.EQNXTDZ($A$1,$B10,AF$1,$B$1) -> 0
A11: Increase/Decrease in Stock | B11: PL_INC_DEC_INVENTORY | C11: =_xll.EQNXTDZ($A$1,$B11,C$1,$B$1) -> 0.254252 | D11: =_xll.EQNXTDZ($A$1,$B11,D$1,$B$1) -> 0.3561504 | E11: =_xll.EQNXTDZ($A$1,$B11,E$1,$B$1) -> -0.4957742 | F11: =_xll.EQNXTDZ($A$1,$B11,F$1,$B$1) -> -0.4386168 | G11: =_xll.EQNXTDZ($A$1,$B11,G$1,$B$1) -> -3.880121 | H11: =_xll.EQNXTDZ($A$1,$B11,H$1,$B$1) -> -5.5437663 | I11: =_xll.EQNXTDZ($A$1,$B11,I$1,$B$1) -> -12.068485 | J11: =_xll.EQNXTDZ($A$1,$B11,J$1,$B$1) -> -12.77424 | ... AF11: =_xll.EQNXTDZ($A$1,$B11,AF$1,$B$1) -> 0
A12: Raw Material Consumed | B12: PL_RAW_MATRS_CONSUMED | C12: =_xll.EQNXTDZ($A$1,$B12,C$1,$B$1) -> 13.138791 | D12: =_xll.EQNXTDZ($A$1,$B12,D$1,$B$1) -> 28.892685 | E12: =_xll.EQNXTDZ($A$1,$B12,E$1,$B$1) -> 29.077509 | F12: =_xll.EQNXTDZ($A$1,$B12,F$1,$B$1) -> 27.412232 | G12: =_xll.EQNXTDZ($A$1,$B12,G$1,$B$1) -> 30.416405 | H12: =_xll.EQNXTDZ($A$1,$B12,H$1,$B$1) -> 46.127885 | I12: =_xll.EQNXTDZ($A$1,$B12,I$1,$B$1) -> 71.685462 | J12: =_xll.EQNXTDZ($A$1,$B12,J$1,$B$1) -> 106.80836 | ... AF12: =_xll.EQNXTDZ($A$1,$B12,AF$1,$B$1) -> 0
A13: Power & Fuel Cost | B13: PL_POWER_FUEL | C13: =_xll.EQNXTDZ($A$1,$B13,C$1,$B$1) -> 0.6412955 | D13: =_xll.EQNXTDZ($A$1,$B13,D$1,$B$1) -> 0.6726684 | E13: =_xll.EQNXTDZ($A$1,$B13,E$1,$B$1) -> 0.7121749 | F13: =_xll.EQNXTDZ($A$1,$B13,F$1,$B$1) -> 0.8292202 | G13: =_xll.EQNXTDZ($A$1,$B13,G$1,$B$1) -> 0.8905262 | H13: =_xll.EQNXTDZ($A$1,$B13,H$1,$B$1) -> 0.9735511 | I13: =_xll.EQNXTDZ($A$1,$B13,I$1,$B$1) -> 1.6014805 | J13: =_xll.EQNXTDZ($A$1,$B13,J$1,$B$1) -> 2.232156 | ... AF13: =_xll.EQNXTDZ($A$1,$B13,AF$1,$B$1) -> 0
A14: Employee Cost | B14: PL_EMPLOYEES | C14: =_xll.EQNXTDZ($A$1,$B14,C$1,$B$1) -> 2.1856685 | D14: =_xll.EQNXTDZ($A$1,$B14,D$1,$B$1) -> 2.3922158 | E14: =_xll.EQNXTDZ($A$1,$B14,E$1,$B$1) -> 2.7783973 | F14: =_xll.EQNXTDZ($A$1,$B14,F$1,$B$1) -> 3.1842187 | G14: =_xll.EQNXTDZ($A$1,$B14,G$1,$B$1) -> 3.5654644 | H14: =_xll.EQNXTDZ($A$1,$B14,H$1,$B$1) -> 4.3553126 | I14: =_xll.EQNXTDZ($A$1,$B14,I$1,$B$1) -> 5.9573332 | J14: =_xll.EQNXTDZ($A$1,$B14,J$1,$B$1) -> 9.0858556 | ... AF14: =_xll.EQNXTDZ($A$1,$B14,AF$1,$B$1) -> 0
A15: Operating & Manufacturing Expenses | B15: PL_GEN_OTHER_MFG_EXPS | C15: =_xll.EQNXTDZ($A$1,$B15,C$1,$B$1) -> 4.0648788 | D15: =_xll.EQNXTDZ($A$1,$B15,D$1,$B$1) -> 4.1775609 | E15: =_xll.EQNXTDZ($A$1,$B15,E$1,$B$1) -> 5.2862596 | F15: =_xll.EQNXTDZ($A$1,$B15,F$1,$B$1) -> 7.8473365 | G15: =_xll.EQNXTDZ($A$1,$B15,G$1,$B$1) -> 7.6527092 | H15: =_xll.EQNXTDZ($A$1,$B15,H$1,$B$1) -> 13.158724 | I15: =_xll.EQNXTDZ($A$1,$B15,I$1,$B$1) -> 21.597667 | J15: =_xll.EQNXTDZ($A$1,$B15,J$1,$B$1) -> 32.498882 | ... AF15: =_xll.EQNXTDZ($A$1,$B15,AF$1,$B$1) -> 0
A16: Cost of Software development | B16: PL_COST_SW | C16: =_xll.EQNXTDZ($A$1,$B16,C$1,$B$1) -> 0 | D16: =_xll.EQNXTDZ($A$1,$B16,D$1,$B$1) -> 0 | E16: =_xll.EQNXTDZ($A$1,$B16,E$1,$B$1) -> 0 | F16: =_xll.EQNXTDZ($A$1,$B16,F$1,$B$1) -> 0 | G16: =_xll.EQNXTDZ($A$1,$B16,G$1,$B$1) -> 0 | H16: =_xll.EQNXTDZ($A$1,$B16,H$1,$B$1) -> 0 | I16: =_xll.EQNXTDZ($A$1,$B16,I$1,$B$1) -> 0 | J16: =_xll.EQNXTDZ($A$1,$B16,J$1,$B$1) -> 0 | ... AF16: =_xll.EQNXTDZ($A$1,$B16,AF$1,$B$1) -> 0
... A36: Profit After Tax from Discontinued Operations | B36: PL_PAT_DIS_OP | C36: =_xll.EQNXTDZ($A$1,$B36,C$1,$B$1) -> 0 | D36: =_xll.EQNXTDZ($A$1,$B36,D$1,$B$1) -> 0 | E36: =_xll.EQNXTDZ($A$1,$B36,E$1,$B$1) -> 0 | F36: =_xll.EQNXTDZ($A$1,$B36,F$1,$B$1) -> 0 | G36: =_xll.EQNXTDZ($A$1,$B36,G$1,$B$1) -> 0 | H36: =_xll.EQNXTDZ($A$1,$B36,H$1,$B$1) -> 0 | I36: =_xll.EQNXTDZ($A$1,$B36,I$1,$B$1) -> 0 | J36: =_xll.EQNXTDZ($A$1,$B36,J$1,$B$1) -> 0 | ... AF36: =_xll.EQNXTDZ($A$1,$B36,AF$1,$B$1) -> 0
A39: Field Description | B39: Field Name
A40: Year End | B40: BS_YEAR_END | C40: =_xll.EQNXTDZ($A$1,$B40,C$1,$B$1) -> 200103 | D40: =_xll.EQNXTDZ($A$1,$B40,D$1,$B$1) -> 200203 | E40: =_xll.EQNXTDZ($A$1,$B40,E$1,$B$1) -> 200303 | F40: =_xll.EQNXTDZ($A$1,$B40,F$1,$B$1) -> 200403 | G40: =_xll.EQNXTDZ($A$1,$B40,G$1,$B$1) -> 200503 | H40: =_xll.EQNXTDZ($A$1,$B40,H$1,$B$1) -> 200603 | I40: =_xll.EQNXTDZ($A$1,$B40,I$1,$B$1) -> 200703 | J40: =_xll.EQNXTDZ($A$1,$B40,J$1,$B$1) -> 200803 | ... AF40: =_xll.EQNXTDZ($A$1,$B40,AF$1,$B$1) -> 0
A41: Share Capital | B41: BS_SHARE_CAPITAL | C41: =_xll.EQNXTDZ($A$1,$B41,C$1,$B$1) -> 4.338175 | D41: =_xll.EQNXTDZ($A$1,$B41,D$1,$B$1) -> 4.338175 | E41: =_xll.EQNXTDZ($A$1,$B41,E$1,$B$1) -> 4.338175 | F41: =_xll.EQNXTDZ($A$1,$B41,F$1,$B$1) -> 4.338175 | G41: =_xll.EQNXTDZ($A$1,$B41,G$1,$B$1) -> 4.338175 | H41: =_xll.EQNXTDZ($A$1,$B41,H$1,$B$1) -> 4.338175 | I41: =_xll.EQNXTDZ($A$1,$B41,I$1,$B$1) -> 9.07635 | J41: =_xll.EQNXTDZ($A$1,$B41,J$1,$B$1) -> 9.07635 | ... AF41: =_xll.EQNXTDZ($A$1,$B41,AF$1,$B$1) -> 0
A42: Share Warrants & Outstandings | B42: BS_SHAREWROUTST | C42: =_xll.EQNXTDZ($A$1,$B42,C$1,$B$1) -> 0 | D42: =_xll.EQNXTDZ($A$1,$B42,D$1,$B$1) -> 0 | E42: =_xll.EQNXTDZ($A$1,$B42,E$1,$B$1) -> 0 | F42: =_xll.EQNXTDZ($A$1,$B42,F$1,$B$1) -> 0 | G42: =_xll.EQNXTDZ($A$1,$B42,G$1,$B$1) -> 0 | H42: =_xll.EQNXTDZ($A$1,$B42,H$1,$B$1) -> 0 | I42: =_xll.EQNXTDZ($A$1,$B42,I$1,$B$1) -> 0 | J42: =_xll.EQNXTDZ($A$1,$B42,J$1,$B$1) -> 0 | ... AF42: =_xll.EQNXTDZ($A$1,$B42,AF$1,$B$1) -> 0
A43: Total Reserves | B43: BS_RESERVE | C43: =_xll.EQNXTDZ($A$1,$B43,C$1,$B$1) -> 12.79249 | D43: =_xll.EQNXTDZ($A$1,$B43,D$1,$B$1) -> 15.515159 | E43: =_xll.EQNXTDZ($A$1,$B43,E$1,$B$1) -> 16.326594 | F43: =_xll.EQNXTDZ($A$1,$B43,F$1,$B$1) -> 18.896301 | G43: =_xll.EQNXTDZ($A$1,$B43,G$1,$B$1) -> 21.693607 | H43: =_xll.EQNXTDZ($A$1,$B43,H$1,$B$1) -> 30.038525 | I43: =_xll.EQNXTDZ($A$1,$B43,I$1,$B$1) -> 41.22561 | J43: =_xll.EQNXTDZ($A$1,$B43,J$1,$B$1) -> 60.698651 | ... AF43: =_xll.EQNXTDZ($A$1,$B43,AF$1,$B$1) -> 0
A44: Shareholder's Funds | B44: BS_SHAREHODERS_FUNDS | C44: =_xll.EQNXTDZ($A$1,$B44,C$1,$B$1) -> 17.130665 | D44: =_xll.EQNXTDZ($A$1,$B44,D$1,$B$1) -> 19.853334 | E44: =_xll.EQNXTDZ($A$1,$B44,E$1,$B$1) -> 20.664769 | F44: =_xll.EQNXTDZ($A$1,$B44,F$1,$B$1) -> 23.234476 | G44: =_xll.EQNXTDZ($A$1,$B44,G$1,$B$1) -> 26.031782 | H44: =_xll.EQNXTDZ($A$1,$B44,H$1,$B$1) -> 34.3767 | I44: =_xll.EQNXTDZ($A$1,$B44,I$1,$B$1) -> 50.30196 | J44: =_xll.EQNXTDZ($A$1,$B44,J$1,$B$1) -> 69.775001 | ... AF44: =_xll.EQNXTDZ($A$1,$B44,AF$1,$B$1) -> 0
A45: Minority Interest | B45: BS_MINORITY_INTEREST | C45: =_xll.EQNXTDZ($A$1,$B45,C$1,$B$1) -> 0 | D45: =_xll.EQNXTDZ($A$1,$B45,D$1,$B$1) -> 0 | E45: =_xll.EQNXTDZ($A$1,$B45,E$1,$B$1) -> 0 | F45: =_xll.EQNXTDZ($A$1,$B45,F$1,$B$1) -> 0 | G45: =_xll.EQNXTDZ($A$1,$B45,G$1,$B$1) -> 0 | H45: =_xll.EQNXTDZ($A$1,$B45,H$1,$B$1) -> 0 | I45: =_xll.EQNXTDZ($A$1,$B45,I$1,$B$1) -> 0 | J45: =_xll.EQNXTDZ($A$1,$B45,J$1,$B$1) -> 0 | ... AF45: =_xll.EQNXTDZ($A$1,$B45,AF$1,$B$1) -> 0
A46: Long-Term Borrowings | B46: BS_LTRM_BORROWING | C46: =_xll.EQNXTDZ($A$1,$B46,C$1,$B$1) -> 0 | D46: =_xll.EQNXTDZ($A$1,$B46,D$1,$B$1) -> 0 | E46: =_xll.EQNXTDZ($A$1,$B46,E$1,$B$1) -> 0 | F46: =_xll.EQNXTDZ($A$1,$B46,F$1,$B$1) -> 0 | G46: =_xll.EQNXTDZ($A$1,$B46,G$1,$B$1) -> 0 | H46: =_xll.EQNXTDZ($A$1,$B46,H$1,$B$1) -> 0 | I46: =_xll.EQNXTDZ($A$1,$B46,I$1,$B$1) -> 0 | J46: =_xll.EQNXTDZ($A$1,$B46,J$1,$B$1) -> 0 | ... AF46: =_xll.EQNXTDZ($A$1,$B46,AF$1,$B$1) -> 0
A47: Secured Loans | B47: BS_SECURED_LOANS | C47: =_xll.EQNXTDZ($A$1,$B47,C$1,$B$1) -> 6.9256003 | D47: =_xll.EQNXTDZ($A$1,$B47,D$1,$B$1) -> 1.7983299 | E47: =_xll.EQNXTDZ($A$1,$B47,E$1,$B$1) -> 5.3148854 | F47: =_xll.EQNXTDZ($A$1,$B47,F$1,$B$1) -> 0 | G47: =_xll.EQNXTDZ($A$1,$B47,G$1,$B$1) -> 0.9197791 | H47: =_xll.EQNXTDZ($A$1,$B47,H$1,$B$1) -> 1.2939266 | I47: =_xll.EQNXTDZ($A$1,$B47,I$1,$B$1) -> 8.0543794 | J47: =_xll.EQNXTDZ($A$1,$B47,J$1,$B$1) -> 11.896456 | ... AF47: =_xll.EQNXTDZ($A$1,$B47,AF$1,$B$1) -> 0
A48: Unsecured Loans | B48: BS_UNSECURED_LOANS_NF | C48: =_xll.EQNXTDZ($A$1,$B48,C$1,$B$1) -> 1.475 | D48: =_xll.EQNXTDZ($A$1,$B48,D$1,$B$1) -> 0.95 | E48: =_xll.EQNXTDZ($A$1,$B48,E$1,$B$1) -> 0.775 | F48: =_xll.EQNXTDZ($A$1,$B48,F$1,$B$1) -> 0.6 | G48: =_xll.EQNXTDZ($A$1,$B48,G$1,$B$1) -> 0.075 | H48: =_xll.EQNXTDZ($A$1,$B48,H$1,$B$1) -> 0 | I48: =_xll.EQNXTDZ($A$1,$B48,I$1,$B$1) -> 0 | J48: =_xll.EQNXTDZ($A$1,$B48,J$1,$B$1) -> 10 | ... AF48: =_xll.EQNXTDZ($A$1,$B48,AF$1,$B$1) -> 0
A49: Deferred Tax Assets / Liabilities | B49: BS_NET_DEF_TAX_NF | C49: =_xll.EQNXTDZ($A$1,$B49,C$1,$B$1) -> 0 | D49: =_xll.EQNXTDZ($A$1,$B49,D$1,$B$1) -> 0 | E49: =_xll.EQNXTDZ($A$1,$B49,E$1,$B$1) -> 1.8425793 | F49: =_xll.EQNXTDZ($A$1,$B49,F$1,$B$1) -> 1.8222732 | G49: =_xll.EQNXTDZ($A$1,$B49,G$1,$B$1) -> 1.7154844 | H49: =_xll.EQNXTDZ($A$1,$B49,H$1,$B$1) -> 1.7564706 | I49: =_xll.EQNXTDZ($A$1,$B49,I$1,$B$1) -> 3.9844117 | J49: =_xll.EQNXTDZ($A$1,$B49,J$1,$B$1) -> 6.2079525 | ... AF49: =_xll.EQNXTDZ($A$1,$B49,AF$1,$B$1) -> 0
A50: Other Long Term Liabilities | B50: BS_OTH_LT_LIAB | C50: =_xll.EQNXTDZ($A$1,$B50,C$1,$B$1) -> 0 | D50: =_xll.EQNXTDZ($A$1,$B50,D$1,$B$1) -> 0 | E50: =_xll.EQNXTDZ($A$1,$B50,E$1,$B$1) -> 0 | F50: =_xll.EQNXTDZ($A$1,$B50,F$1,$B$1) -> 0 | G50: =_xll.EQNXTDZ($A$1,$B50,G$1,$B$1) -> 0 | H50: =_xll.EQNXTDZ($A$1,$B50,H$1,$B$1) -> 0 | I50: =_xll.EQNXTDZ($A$1,$B50,I$1,$B$1) -> 0 | J50: =_xll.EQNXTDZ($A$1,$B50,J$1,$B$1) -> 0 | ... AF50: =_xll.EQNXTDZ($A$1,$B50,AF$1,$B$1) -> 0
A51: Long Term Trade Payables | B51: BS_LT_TRADE_PAYABLES | C51: =_xll.EQNXTDZ($A$1,$B51,C$1,$B$1) -> 0 | D51: =_xll.EQNXTDZ($A$1,$B51,D$1,$B$1) -> 0 | E51: =_xll.EQNXTDZ($A$1,$B51,E$1,$B$1) -> 0 | F51: =_xll.EQNXTDZ($A$1,$B51,F$1,$B$1) -> 0 | G51: =_xll.EQNXTDZ($A$1,$B51,G$1,$B$1) -> 0 | H51: =_xll.EQNXTDZ($A$1,$B51,H$1,$B$1) -> 0 | I51: =_xll.EQNXTDZ($A$1,$B51,I$1,$B$1) -> 0 | J51: =_xll.EQNXTDZ($A$1,$B51,J$1,$B$1) -> 0 | ... AF51: =_xll.EQNXTDZ($A$1,$B51,AF$1,$B$1) -> 0
... A99: Estimated Capital Contracts Remaining | B99: BS_ESTIMATED_CAPITAL_CONTRACT | C99: =_xll.EQNXTDZ($A$1,$B99,C$1,$B$1) -> 0 | D99: =_xll.EQNXTDZ($A$1,$B99,D$1,$B$1) -> 0 | E99: =_xll.EQNXTDZ($A$1,$B99,E$1,$B$1) -> 0 | F99: =_xll.EQNXTDZ($A$1,$B99,F$1,$B$1) -> 0 | G99: =_xll.EQNXTDZ($A$1,$B99,G$1,$B$1) -> 0 | H99: =_xll.EQNXTDZ($A$1,$B99,H$1,$B$1) -> 0 | I99: =_xll.EQNXTDZ($A$1,$B99,I$1,$B$1) -> 0 | J99: =_xll.EQNXTDZ($A$1,$B99,J$1,$B$1) -> 0 | ... AF99: =_xll.EQNXTDZ($A$1,$B99,AF$1,$B$1) -> 0
A103: Field Description | B103: Field Name
A104: Equity Paid Up | B104: BS_EQUITY_PAIDUP | C104: =_xll.EQNXTDZ($A$1,$B104,C$1,$B$1) -> 4.338175 | D104: =_xll.EQNXTDZ($A$1,$B104,D$1,$B$1) -> 4.338175 | E104: =_xll.EQNXTDZ($A$1,$B104,E$1,$B$1) -> 4.338175 | F104: =_xll.EQNXTDZ($A$1,$B104,F$1,$B$1) -> 4.338175 | G104: =_xll.EQNXTDZ($A$1,$B104,G$1,$B$1) -> 4.338175 | H104: =_xll.EQNXTDZ($A$1,$B104,H$1,$B$1) -> 4.338175 | I104: =_xll.EQNXTDZ($A$1,$B104,I$1,$B$1) -> 9.07635 | J104: =_xll.EQNXTDZ($A$1,$B104,J$1,$B$1) -> 9.07635 | ... AF104: =_xll.EQNXTDZ($A$1,$B104,AF$1,$B$1) -> 0
A105: Face Value | B105: BS_FACE_VALUE | C105: =_xll.EQNXTDZ($A$1,$B105,C$1,$B$1) -> 10 | D105: =_xll.EQNXTDZ($A$1,$B105,D$1,$B$1) -> 10 | E105: =_xll.EQNXTDZ($A$1,$B105,E$1,$B$1) -> 10 | F105: =_xll.EQNXTDZ($A$1,$B105,F$1,$B$1) -> 10 | G105: =_xll.EQNXTDZ($A$1,$B105,G$1,$B$1) -> 10 | H105: =_xll.EQNXTDZ($A$1,$B105,H$1,$B$1) -> 10 | I105: =_xll.EQNXTDZ($A$1,$B105,I$1,$B$1) -> 10 | J105: =_xll.EQNXTDZ($A$1,$B105,J$1,$B$1) -> 10 | ... AF105: =_xll.EQNXTDZ($A$1,$B105,AF$1,$B$1) -> 0
A106: Close Price (Unit Curr.) | B106: FH_YEAR_PRICE | C106: =_xll.EQNXTDZ($A$1,$B106,C$1,$B$1) -> 0 | D106: =_xll.EQNXTDZ($A$1,$B106,D$1,$B$1) -> 0 | E106: =_xll.EQNXTDZ($A$1,$B106,E$1,$B$1) -> 0 | F106: =_xll.EQNXTDZ($A$1,$B106,F$1,$B$1) -> 0 | G106: =_xll.EQNXTDZ($A$1,$B106,G$1,$B$1) -> 0 | H106: =_xll.EQNXTDZ($A$1,$B106,H$1,$B$1) -> 0 | I106: =_xll.EQNXTDZ($A$1,$B106,I$1,$B$1) -> 0 | J106: =_xll.EQNXTDZ($A$1,$B106,J$1,$B$1) -> 0 | ... AF106: =_xll.EQNXTDZ($A$1,$B106,AF$1,$B$1) -> 0
A107: High Price (Unit Curr.) | B107: FH_HIGH | C107: =_xll.EQNXTDZ($A$1,$B107,C$1,$B$1) -> 0 | D107: =_xll.EQNXTDZ($A$1,$B107,D$1,$B$1) -> 0 | E107: =_xll.EQNXTDZ($A$1,$B107,E$1,$B$1) -> 0 | F107: =_xll.EQNXTDZ($A$1,$B107,F$1,$B$1) -> 0 | G107: =_xll.EQNXTDZ($A$1,$B107,G$1,$B$1) -> 0 | H107: =_xll.EQNXTDZ($A$1,$B107,H$1,$B$1) -> 0 | I107: =_xll.EQNXTDZ($A$1,$B107,I$1,$B$1) -> 0 | J107: =_xll.EQNXTDZ($A$1,$B107,J$1,$B$1) -> 0 | ... AF107: =_xll.EQNXTDZ($A$1,$B107,AF$1,$B$1) -> 0
A108: Low Price (Unit Curr.) | B108: FH_LOW | C108: =_xll.EQNXTDZ($A$1,$B108,C$1,$B$1) -> 0 | D108: =_xll.EQNXTDZ($A$1,$B108,D$1,$B$1) -> 0 | E108: =_xll.EQNXTDZ($A$1,$B108,E$1,$B$1) -> 0 | F108: =_xll.EQNXTDZ($A$1,$B108,F$1,$B$1) -> 0 | G108: =_xll.EQNXTDZ($A$1,$B108,G$1,$B$1) -> 0 | H108: =_xll.EQNXTDZ($A$1,$B108,H$1,$B$1) -> 0 | I108: =_xll.EQNXTDZ($A$1,$B108,I$1,$B$1) -> 0 | J108: =_xll.EQNXTDZ($A$1,$B108,J$1,$B$1) -> 0 | ... AF108: =_xll.EQNXTDZ($A$1,$B108,AF$1,$B$1) -> 0
A109: Market Capitalization | B109: FH_MCAP | C109: =_xll.EQNXTDZ($A$1,$B109,C$1,$B$1) -> 0 | D109: =_xll.EQNXTDZ($A$1,$B109,D$1,$B$1) -> 0 | E109: =_xll.EQNXTDZ($A$1,$B109,E$1,$B$1) -> 0 | F109: =_xll.EQNXTDZ($A$1,$B109,F$1,$B$1) -> 0 | G109: =_xll.EQNXTDZ($A$1,$B109,G$1,$B$1) -> 0 | H109: =_xll.EQNXTDZ($A$1,$B109,H$1,$B$1) -> 0 | I109: =_xll.EQNXTDZ($A$1,$B109,I$1,$B$1) -> 0 | J109: =_xll.EQNXTDZ($A$1,$B109,J$1,$B$1) -> 0 | ... AF109: =_xll.EQNXTDZ($A$1,$B109,AF$1,$B$1) -> 0
A110: Adj DPS(Rs) | B110: FR_ADJ_DPS | C110: =_xll.EQNXTDZ($A$1,$B110,C$1,$B$1) -> 0.125 | D110: =_xll.EQNXTDZ($A$1,$B110,D$1,$B$1) -> 0.25 | E110: =_xll.EQNXTDZ($A$1,$B110,E$1,$B$1) -> 0.1 | F110: =_xll.EQNXTDZ($A$1,$B110,F$1,$B$1) -> 0.125 | G110: =_xll.EQNXTDZ($A$1,$B110,G$1,$B$1) -> 0.25 | H110: =_xll.EQNXTDZ($A$1,$B110,H$1,$B$1) -> 0.25 | I110: =_xll.EQNXTDZ($A$1,$B110,I$1,$B$1) -> 0.25 | J110: =_xll.EQNXTDZ($A$1,$B110,J$1,$B$1) -> 0.5 | ... AF110: =_xll.EQNXTDZ($A$1,$B110,AF$1,$B$1) -> 0
A111: Date End | B111: SHP_DATE_END | C111: =_xll.EQNXTDZ($A$1,$B111,C$5) -> 0 | D111: =_xll.EQNXTDZ($A$1,$B111,D$5) -> 0 | E111: =_xll.EQNXTDZ($A$1,$B111,E$5) -> 0 | F111: =_xll.EQNXTDZ($A$1,$B111,F$5) -> 0 | G111: =_xll.EQNXTDZ($A$1,$B111,G$5) -> 0 | H111: =_xll.EQNXTDZ($A$1,$B111,H$5) -> 0 | I111: =_xll.EQNXTDZ($A$1,$B111,I$5) -> 0 | J111: =_xll.EQNXTDZ($A$1,$B111,J$5) -> 0 | ... AF111: =_xll.EQNXTDZ($A$1,$B111,AF$5) -> 0
A112: Total of Promoter and Promoter Group | B112: SHP_TPFTOTALPROMOTER | C112: =_xll.EQNXTDZ($A$1,$B112,C$5) -> 0 | D112: =_xll.EQNXTDZ($A$1,$B112,D$5) -> 0 | E112: =_xll.EQNXTDZ($A$1,$B112,E$5) -> 0 | F112: =_xll.EQNXTDZ($A$1,$B112,F$5) -> 0 | G112: =_xll.EQNXTDZ($A$1,$B112,G$5) -> 0 | H112: =_xll.EQNXTDZ($A$1,$B112,H$5) -> 0 | I112: =_xll.EQNXTDZ($A$1,$B112,I$5) -> 0 | J112: =_xll.EQNXTDZ($A$1,$B112,J$5) -> 0 | ... AF112: =_xll.EQNXTDZ($A$1,$B112,AF$5) -> 0
...

Sheet QTR Share Price
A1: ='QTR Raw'!A1 -> 208433 | C1: 201206 | D1: 201207 | E1: 201208 | F1: 201209 | G1: 201210 | H1: 201211 | I1: 201212 | J1: 201301 | K1: 201302 | L1: 201303 | M1: 201304 | N1: 201305 | O1: 201306 | P1: 201307 | Q1: 201308 | R1: 201309 | S1: 201310 | T1: 201311 | U1: 201312 | V1: 201401 | W1: 201402 | X1: 201403 | Y1: 201404 | Z1: 201405 | AA1: 201406 | AB1: 201407 | AC1: 201408 | AD1: 201409 | AE1: 201410 | AF1: 201411 | AG1: 201412 | AH1: 201501 | AI1: 201502 | AJ1: 201503 | AK1: 201504 | AL1: 201505 | AM1: 201506 | AN1: 201507 | AO1: 201508 | AP1: 201509 | AQ1: 201510 | AR1: 201511 | AS1: 201512 | AT1: 201601 | AU1: 201602 | AV1: 201603 | AW1: 201604 | AX1: 201605 | AY1: 201606 | AZ1: 201607 | BA1: 201608 | BB1: 201609 | BC1: 201610 | BD1: 201611 | BE1: 201612 | BF1: 201701 | BG1: 201702 | BH1: 201703 | BI1: 201704 | BJ1: 201705 | BK1: 201706 | BL1: 201707 | BM1: 201708 | BN1: 201709 | BO1: 201710 | BP1: 201711 | BQ1: 201712 | BR1: 201801 | BS1: 201802 | BT1: 201803 | BU1: 201804 | BV1: 201805 | BW1: 201806 | BX1: 201807 | BY1: 201808 | BZ1: 201809 | CA1: 201810 | CB1: 201811 | CC1: 201812 | CD1: 201901 | CE1: 201902 | CF1: 201903 | CG1: 201904 | CH1: 201905 | CI1: 201906 | CJ1: 201907 | CK1: 201908 | CL1: 201909 | CM1: 201910 | CN1: 201911 | CO1: 201912 | CP1: 202001 | CQ1: 202002 | CR1: 202003 | CS1: 202004 | CT1: 202005 | CU1: 202006 | CV1: 202007 | CW1: 202008 | CX1: 202009 | CY1: 202010 | CZ1: 202011 | DA1: 202012 | DB1: 202101 | DC1: 202102 | DD1: 202103 | DE1: 202104 | DF1: 202105 | DG1: 202106 | DH1: 202107 | DI1: 202108 | DJ1: 202109 | DK1: 202110 | DL1: 202111 | DM1: 202112 | DN1: 202201 | DO1: 202202 | DP1: 202203 | DQ1: 202204 | DR1: 202205 | DS1: 202206 | DT1: 202207 | DU1: 202208 | DV1: 202209 | DW1: 202210 | DX1: 202211 | DY1: 202212 | DZ1: 202301 | EA1: 202302 | EB1: 202303 | EC1: 202304 | ED1: 202305 | EE1: 202306 | EF1: 202307 | EG1: 202308 | EH1: 202309 | EI1: 202310 | EJ1: 202311 | EK1: 202312 | EL1: 202401 | EM1: 202402 | EN1: 202403 | EO1: 202404 | EP1: 202405 | EQ1: 202406 | ER1: 202407 | ES1: 202408 | ET1: 202409 | EU1: 202410 | EV1: 202411 | EW1: 202412 | EX1: 202501 | EY1: 202502 | EZ1: 202503 | FA1: 202504 | FB1: 202505 | FC1: 202506 | FD1: 202507 | FE1: 202508 | FF1: 202509 | FG1: 202510 | FH1: 202511 | FI1: 202512 | FJ1: 202601 | FK1: 202602 | FL1: 202603 | FM1: 202604 | FN1: 202605 | FO1: 202606 | FP1: 202607 | FQ1: 202608 | FR1: 202609 | FS1: 202610 | FT1: 202611 | FU1: 202612 | FV1: 202701 | FW1: 202702 | FX1: 202703 | FY1: 202704 | FZ1: 202705 | GA1: 202706 | GB1: 202707 | GC1: 202708 | GD1: 202709 | GE1: 202710 | GF1: 202711 | GG1: 202712 | GH1: 202801 | GI1: 202802 | GJ1: 202803 | GK1: 202804 | GL1: 202805 | GM1: 202806 | GN1: 202807 | GO1: 202808 | GP1: 202809 | GQ1: 202810 | GR1: 202811 | GS1: 202812 | GT1: 202901 | GU1: 202902 | GV1: 202903 | GW1: 202904 | GX1: 202905 | GY1: 202906 | GZ1: 202907 | HA1: 202908 | HB1: 202909 | HC1: 202910 | HD1: 202911 | HE1: 202912 | HF1: 203001 | HG1: 203002 | HH1: 203003 | HM1: 201206 | HN1: 201207 | HO1: 201208 | HP1: 201209 | HQ1: 201212 | HR1: 201303 | HS1: 201306 | HT1: 201309 | HU1: 201312 | HV1: 201403 | HW1: 201406 | HX1: 201409 | HY1: 201412 | HZ1: 201503 | IA1: 201506 | IB1: 201509 | IC1: 201512 | ID1: 201603 | IE1: 201606 | IF1: 201609 | IG1: 201612 | IH1: 201703 | II1: 201706 | IJ1: 201709 | IK1: 201712 | IL1: 201803 | IM1: 201806 | IN1: 201809 | IO1: 201812 | IP1: 201903 | IQ1: 201906 | IR1: 201909 | IS1: 201912 | IT1: 202003 | IU1: 202006 | IV1: 202009 | IW1: 202012 | IX1: 202103 | IY1: 202106 | IZ1: 202109 | JA1: 202112 | JB1: 202203 | JC1: 202206 | JD1: 202209 | JE1: 202212 | JF1: 202303 | JG1: 202306 | JH1: 202309 | JI1: 202312 | JJ1: 202403 | JK1: 202406 | JL1: 202409 | JM1: 202412 | JN1: 202503 | JO1: 202506 | JP1: 202509 | JQ1: 202512 | JR1: 202603 | JS1: 202606 | JT1: 202609 | JU1: 202612 | JV1: 202703 | JW1: 202706 | JX1: 202709 | JY1: 202712 | JZ1: 202803 | KA1: 202806 | KB1: 202809 | KC1: 202812 | KD1: 202903 | KE1: 202906 | KF1: 202909 | KG1: 202912 | KH1: 203003
FF2: 45901 | FG2: =+EOMONTH(FF2,1) -> 45961 | FH2: =+EOMONTH(FG2,1) -> 45991 | FI2: =+EOMONTH(FH2,1) -> 46022 | FJ2: =+EOMONTH(FI2,1) -> 46053 | FK2: =+EOMONTH(FJ2,1) -> 46081 | FL2: =+EOMONTH(FK2,1) -> 46112 | FM2: =+EOMONTH(FL2,1) -> 46142 | FN2: =+EOMONTH(FM2,1) -> 46173 | ... HH2: =+EOMONTH(HG2,1) -> 47573
