Workbook

Sheet Template
A1: =+'Annual Raw'!C4 -> Jindal Saw Ltd. | B1: 36951 | C1: =EOMONTH(B1,12) -> 37346 | D1: =EOMONTH(C1,12) -> 37711 | E1: =EOMONTH(D1,12) -> 38077 | F1: =EOMONTH(E1,12) -> 38442 | G1: =EOMONTH(F1,12) -> 38807 | H1: =EOMONTH(G1,12) -> 39172 | I1: =EOMONTH(H1,12) -> 39538 | J1: =EOMONTH(I1,12) -> 39903 | ... AE1: =EOMONTH(AD1,12) -> 47573 | AH1: QTR | AI1: 41061 | AJ1: 41153 | AK1: 41244 | AL1: 41334 | AM1: 41426 | AN1: 41518 | AO1: 41609 | AP1: 41699 | AQ1: 41791 | AR1: 41883 | AS1: 41974 | AT1: 42064 | AU1: 42156 | AV1: 42248 | AW1: 42339 | AX1: 42430 | AY1: 42522 | AZ1: 42614 | BA1: 42705 | BB1: 42795 | BC1: 42887 | BD1: 42979 | BE1: 43070 | BF1: 43160 | BG1: 43252 | BH1: 43344 | BI1: 43435 | BJ1: 43525 | BK1: 43617 | BL1: 43709 | BM1: 43800 | BN1: 43891 | BO1: 43983 | BP1: 44075 | BQ1: =EOMONTH(BP1,3) -> 44196 | BR1: =EOMONTH(BQ1,3) -> 44286 | BS1: =EOMONTH(BR1,3) -> 44377 | BT1: =EOMONTH(BS1,3) -> 44469 | BU1: =EOMONTH(BT1,3) -> 44561 | BV1: =EOMONTH(BU1,3) -> 44651 | BW1: =EOMONTH(BV1,3) -> 44742 | BX1: =EOMONTH(BW1,3) -> 44834 | ... DB1: =EOMONTH(DA1,3) -> 47573 | DE1: HISTORICAL ESTIMATES | DF1: 46112
A2: Presentation Data (Start)
A4: Current Capacity - MT pipes | W4: 1800000 | X4: =W4 -> 1800000 | Y4: 2350000 | Z4: =Y4 -> 2350000 | AA4: 2700000 | CE4: =CF4 -> 587500 | CF4: =CG4 -> 587500 | CG4: =CH4 -> 587500 | CH4: =Z4/4 -> 587500 | CI4: =AA4/4 -> 675000 | CJ4: =CI4 -> 675000 | CK4: =CJ4 -> 675000 | CL4: =CK4 -> 675000 | CM4: =+CL4 -> 675000 | CN4: =+CM4 -> 675000 | CO4: =+CN4 -> 675000 | CP4: =+CO4 -> 675000 | CQ4: =+CP4 -> 675000 | CR4: =+CQ4 -> 675000 | DF4: 675000
A6: Total Vol with Abu Dhabi | Q6: =+Q7+Q10 -> 2158700 | R6: =+R7+R10 -> 2240000 | S6: =+S7+S10 -> 2471860 | T6: =+T7+T10 -> 2666194 | U6: =+U7+U10 -> 2569827 | V6: =+V7+V10 -> 2355422 | W6: =+W7+W10 -> 2540977 | X6: =+X7+X10 -> 2823000 | ... Z6: =+Z7+Z10 -> 3546300
A7: Sales Vol - MT | Q7: =Q8+Q9 -> 2158700 | R7: =R8+R9 -> 2240000 | S7: =S8+S9 -> 2471860 | T7: =T8+T9 -> 2666194 | U7: =U8+U9 -> 2569827 | V7: =V8+V9 -> 2355422 | W7: =W8+W9 -> 2540977 | X7: =SUM(BW7:BZ7) -> 2823000 | Y7: =SUM(CA7:CD7) -> 3460600 | Z7: =SUM(CE7:CH7) -> 3347000 | AA7: =SUM(CI7:CL7) -> 2830000 | AB7: =+SUM(CM7:CP7) -> 0 | AC7: =+SUM(CQ7:CT7) -> 0 | AD7: =+SUM(CU7:CX7) -> 0 | AE7: =+SUM(CY7:DB7) -> 0 | BK7: 641405 | BL7: 625800 | BM7: 720900 | BN7: 596200 | BO7: 394906 | BP7: 620800 | BQ7: 615800 | BR7: 744894 | BS7: =257800+366200 -> 624000 | BT7: 616000 | BU7: 659500 | BV7: 686700 | BW7: =233200+295200 -> 528400 | BX7: 657800 | BY7: 820362 | BZ7: 816438 | CA7: 805000 | CB7: 885000 | CC7: 893600 | CD7: =478000+399000 -> 877000 | CE7: =400000+413000 -> 813000 | CF7: =432000+396000 -> 828000 | CG7: =432000+443000 -> 875000 | CH7: =434000+397000 -> 831000 | CI7: =326000+222000 -> 548000 | CJ7: =293000+356000 -> 649000 | CK7: =370000+491000 -> 861000 | CL7: =CL8+CL9 -> 772000
A8: Pipes- MT Standalone | Q8: 958700 | R8: 1040000 | S8: 1171860 | T8: 1266194 | U8: 1237931 | V8: 1090656 | W8: 1023567 | X8: 1285619 | Y8: 1716000 | Z8: 1698000 | AA8: =SUM(CI8:CL8) -> 1387000 | AB8: =+SUM(CM8:CP8) -> 1525700 | AC8: =+SUM(CQ8:CT8) -> 1678270 | AD8: =+SUM(CU8:CX8) -> 1846097 | AE8: =+SUM(CY8:DB8) -> 2030706.7 | BK8: =+BK7-BK9 -> 321405 | BL8: =+BL7-BL9 -> 305800 | BM8: =+BM7-BM9 -> 400900 | BN8: =+BN7-BN9 -> 276200 | BO8: =+BO7-BO9 -> 214906 | BP8: =+BP7-BP9 -> 254600 | BQ8: =+BQ7-BQ9 -> 249600 | BR8: =+BR7-BR9 -> 378694 | BS8: 257800 | BT8: 295000 | BU8: 310000 | BV8: 350000 | BW8: 233200 | BX8: 280000 | BY8: 330000 | BZ8: 410000 | CA8: 340000 | CB8: 375000 | CC8: 390000 | CD8: 478000 | CE8: 400000 | CF8: =+Z8-CE8-CG8-CH8 -> 432000 | CG8: 432000 | CH8: 434000 | CI8: 326000 | CJ8: 293000 | CK8: 370000 | CL8: 398000 | CM8: =+CI8*1.1 -> 358600 | CN8: =+CJ8*1.1 -> 322300 | CO8: =+CK8*1.1 -> 407000 | CP8: =+CL8*1.1 -> 437800 | CQ8: =+CM8*1.1 -> 394460 | CR8: =+CN8*1.1 -> 354530 | CS8: =+CO8*1.1 -> 447700 | CT8: =+CP8*1.1 -> 481580 | ... DB8: =+CX8*1.1 -> 582711.8 | DF8: 347200
A9: Pellets | Q9: 1200000 | R9: 1200000 | S9: 1300000 | T9: 1400000 | U9: 1331896 | V9: 1264766 | W9: 1517410 | X9: =+X7-X8 -> 1537381 | Y9: =+Y7-Y8 -> 1744600 | Z9: =+Z7-Z8 -> 1649000 | AA9: =SUM(CI9:CL9) -> 1443000 | AB9: =+SUM(CM9:CP9) -> 0 | AC9: =+SUM(CQ9:CT9) -> 0 | AD9: =+SUM(CU9:CX9) -> 0 | AE9: =+SUM(CY9:DB9) -> 0 | BK9: 320000 | BL9: 320000 | BM9: 320000 | BN9: 320000 | BO9: 180000 | BP9: =+BQ9 -> 366200 | BQ9: =+BR9 -> 366200 | BR9: =+BS9 -> 366200 | BS9: =+BS7-BS8 -> 366200 | BT9: =+BT7-BT8 -> 321000 | BU9: =+BU7-BU8 -> 349500 | BV9: =+BV7-BV8 -> 336700 | BW9: =+BW7-BW8 -> 295200 | BX9: =+BX7-BX8 -> 377800 | BY9: =+BY7-BY8 -> 490362 | BZ9: =+BZ7-BZ8 -> 406438 | ... CK9: =+CK7-CK8 -> 491000 | CL9: 374000
A10: Pipes Abu Dhabi | Y10: 191000 | Z10: 199300 | AA10: =SUM(CI10:CL10) -> 209000 | AB10: =+SUM(CM10:CP10) -> 208000 | AC10: =+SUM(CQ10:CT10) -> 208000 | AD10: =+SUM(CU10:CX10) -> 208000 | AE10: =+SUM(CY10:DB10) -> 208000 | BY10: 37362 | BZ10: 39638 | CA10: 43000 | CB10: 59000 | CC10: 63000 | CD10: 26000 | CE10: 36800 | CF10: 61000 | CG10: 57000 | CH10: =+Z10-CE10-CF10-CG10 -> 44500 | CI10: 51000 | CJ10: 58000 | CK10: 52000 | CL10: 48000 | CM10: 52000 | CN10: =+CM10 -> 52000 | CO10: =+CN10 -> 52000 | CP10: =+CO10 -> 52000 | CQ10: =+CP10 -> 52000 | CR10: =+CQ10 -> 52000 | CS10: =+CR10 -> 52000 | CT10: =+CS10 -> 52000 | CU10: =+CT10 -> 52000 | ... DB10: =+DA10 -> 52000 | DF10: 41600
A11: Vol Growth pipes only | R11: =(R10+R8)/(Q8+Q10)-1 -> 0.084802336 | S11: =(S10+S8)/(R8+R10)-1 -> 0.12678846 | T11: =(T10+T8)/(S8+S10)-1 -> 0.080499377 | U11: =(U10+U8)/(T8+T10)-1 -> -0.022321224 | V11: =(V10+V8)/(U8+U10)-1 -> -0.11896867 | W11: =(W10+W8)/(V8+V10)-1 -> -0.061512521 | X11: =(X10+X8)/(W8+W10)-1 -> 0.25601841 | Y11: =(Y10+Y8)/(X8+X10)-1 -> 0.48333215 | ... AE11: =(AE10+AE8)/(AD8+AD10)-1 -> 0.089873896 | BQ11: =(BQ10+BQ8)/(BM8+BM10)-1 -> -0.37740085 | BR11: =(BR10+BR8)/(BN8+BN10)-1 -> 0.37108617 | BS11: =(BS10+BS8)/(BO8+BO10)-1 -> 0.19959424 | BT11: =(BT10+BT8)/(BP8+BP10)-1 -> 0.15868028 | BU11: =(BU10+BU8)/(BQ8+BQ10)-1 -> 0.24198718 | BV11: =(BV10+BV8)/(BR8+BR10)-1 -> -0.075770939 | BW11: =(BW10+BW8)/(BS8+BS10)-1 -> -0.095422808 | BX11: =(BX10+BX8)/(BT8+BT10)-1 -> -0.050847458 | ... DB11: =(DB10+DB8)/(CX8+CX10)-1 -> 0.091061268 | DF11: -0.18746082
A13: Orderbook Crs | Y13: =CD13 -> 12657.5 | Z13: =CH13 -> 11271 | CB13: =1.44*83*100 -> 11952 | CC13: =1.49*83*100 -> 12367 | CD13: =+((1509+16)/10)*83 -> 12657.5 | CE13: =165*83 -> 13695 | CF13: =162*83 -> 13446 | CG13: =148*83 -> 12284 | CH13: =132.6*85 -> 11271 | CI13: =130.5*85 -> 11092.5 | CJ13: =145.2*88 -> 12777.6 | CK13: =148.1*90 -> 13329
A14: OB MT - Pipes | Y14: =CD14 -> 1376000 | Z14: =CH14 -> 1301000 | CD14: 1376000 | CE14: 1524000 | CF14: 1469000 | CG14: 1394000 | CH14: 1301000 | CI14: 1560000 | CJ14: 1925000 | CK14: 1964000 | CL14: 1900000
A15: DI Pipes | Z15: =CH15 -> 625000 | CG15: 680000 | CH15: 625000 | CK15: 700000
A17: Unit Matrix
A18: Sales | Q18: =+Q27*10^7/(Q$8+Q$10)/1000 -> 82.824723 | R18: =+R27*10^7/(R$8+R$10)/1000 -> 70.606387 | S18: =+S27*10^7/(S$8+S$10)/1000 -> 73.083214 | T18: =+T27*10^7/(T$8+T$10)/1000 -> 95.696249 | U18: =+U27*10^7/(U$8+U$10)/1000 -> 93.923141 | V18: =+V27*10^7/(V$8+V$10)/1000 -> 97.772678 | W18: =+W27*10^7/(W$8+W$10)/1000 -> 129.92233 | X18: =+X27*10^7/(X$8+X$10)/1000 -> 138.98417 | ... AE18: =+AE27*10^7/(AE$8+AE$10)/1000 -> 107.88969 | BO18: =+BO27*10^7/(BO$8+BO$10)/1000 -> 76.349195 | BP18: =+BP27*10^7/(BP$8+BP$10)/1000 -> 93.256874 | BQ18: =+BQ27*10^7/(BQ$8+BQ$10)/1000 -> 114.77083 | BR18: =+BR27*10^7/(BR$8+BR$10)/1000 -> 99.918404 | BS18: =+BS27*10^7/(BS$8+BS$10)/1000 -> 111.89294 | BT18: =+BT27*10^7/(BT$8+BT$10)/1000 -> 100.77559 | BU18: =+BU27*10^7/(BU$8+BU$10)/1000 -> 111.96903 | BV18: =+BV27*10^7/(BV$8+BV$10)/1000 -> 113.42571 | ... CL18: =+CL27*10^7/(CL$8+CL$10)/1000 -> 103.88969 | CM18: =+CL18+2 -> 105.88969 | CN18: =+CM18+2 -> 107.88969 | CO18: =+CN18 -> 107.88969 | CP18: =+CO18 -> 107.88969 | CQ18: =+CP18 -> 107.88969 | CR18: =+CQ18 -> 107.88969 | CS18: =+CR18 -> 107.88969 | CT18: =+CS18 -> 107.88969 | CU18: =+CT18 -> 107.88969 | CV18: =+CU18 -> 107.88969 | ... DB18: =+DA18 -> 107.88969 | DF18: 117.14242
A19: Raw Mat | Q19: =+Q18-Q20 -> 47.259395 | R19: =+R18-R20 -> 39.269639 | S19: =+S18-S20 -> 42.308059 | T19: =+T18-T20 -> 58.963831 | U19: =+U18-U20 -> 56.018023 | V19: =+V18-V20 -> 55.265002 | W19: =+W18-W20 -> 77.203042 | X19: =+X18-X20 -> 87.058821 | ... AE19: =+AE18-AE20 -> 59.174664 | BO19: =+BO18-BO20 -> 41.875518 | BP19: =+BP18-BP20 -> 50.765515 | BQ19: =+BQ18-BQ20 -> 63.191907 | BR19: =+BR18-BR20 -> 59.621489 | BS19: =+BS18-BS20 -> 59.408456 | BT19: =+BT18-BT20 -> 56.470169 | BU19: =+BU18-BU20 -> 71.886774 | BV19: =+BV18-BV20 -> 70.781143 | ... CL19: =+CL18-CL20 -> 59.174664 | CM19: =+CL19 -> 59.174664 | CN19: =+CM19 -> 59.174664 | CO19: =+CN19 -> 59.174664 | CP19: =+CO19 -> 59.174664 | CQ19: =+CP19 -> 59.174664 | CR19: =+CQ19 -> 59.174664 | CS19: =+CR19 -> 59.174664 | CT19: =+CS19 -> 59.174664 | ... DB19: =+DA19 -> 59.174664 | DF19: 69.001185
A20: GP | Q20: =+Q35*10^7/(Q$8+Q$10)/1000 -> 35.565328 | R20: =+R35*10^7/(R$8+R$10)/1000 -> 31.336747 | S20: =+S35*10^7/(S$8+S$10)/1000 -> 30.775155 | T20: =+T35*10^7/(T$8+T$10)/1000 -> 36.732418 | U20: =+U35*10^7/(U$8+U$10)/1000 -> 37.905118 | V20: =+V35*10^7/(V$8+V$10)/1000 -> 42.507676 | W20: =+W35*10^7/(W$8+W$10)/1000 -> 52.71929 | X20: =+X35*10^7/(X$8+X$10)/1000 -> 51.925348 | ... AE20: =+AE35*10^7/(AE$8+AE$10)/1000 -> 48.715022 | BO20: =+BO35*10^7/(BO$8+BO$10)/1000 -> 34.473677 | BP20: =+BP35*10^7/(BP$8+BP$10)/1000 -> 42.491359 | BQ20: =+BQ35*10^7/(BQ$8+BQ$10)/1000 -> 51.578926 | BR20: =+BR35*10^7/(BR$8+BR$10)/1000 -> 40.296915 | BS20: =+BS35*10^7/(BS$8+BS$10)/1000 -> 52.484484 | BT20: =+BT35*10^7/(BT$8+BT$10)/1000 -> 44.305424 | BU20: =+BU35*10^7/(BU$8+BU$10)/1000 -> 40.082258 | BV20: =+BV35*10^7/(BV$8+BV$10)/1000 -> 42.644571 | ... CL20: =+CL35*10^7/(CL$8+CL$10)/1000 -> 44.715022 | CM20: =+CM18-CM19 -> 46.715022 | CN20: =+CN18-CN19 -> 48.715022 | CO20: =+CO18-CO19 -> 48.715022 | CP20: =+CP18-CP19 -> 48.715022 | CQ20: =+CQ18-CQ19 -> 48.715022 | CR20: =+CR18-CR19 -> 48.715022 | CS20: =+CS18-CS19 -> 48.715022 | CT20: =+CT18-CT19 -> 48.715022 | ... DB20: =+DB18-DB19 -> 48.715022 | DF20: 48.141232
A21: Other Cost | Q21: =+Q20-Q22 -> 28.572117 | R21: =+R20-R22 -> 24.387977 | S21: =+S20-S22 -> 22.276204 | T21: =+T20-T22 -> 25.423293 | U21: =+U20-U22 -> 26.079158 | V21: =+V20-V22 -> 31.643294 | W21: =+W20-W22 -> 39.477432 | X21: =+X20-X22 -> 39.447232 | ... AE21: =+AE20-AE22 -> 33.93296 | BO21: =+BO20-BO22 -> 25.937852 | BP21: =+BP20-BP22 -> 31.638256 | BQ21: =+BQ20-BQ22 -> 39.225962 | BR21: =+BR20-BR22 -> 27.754335 | BS21: =+BS20-BS22 -> 36.244375 | BT21: =+BT20-BT22 -> 31.487119 | BU21: =+BU20-BU22 -> 33.481935 | BV21: =+BV20-BV22 -> 31.198571 | ... CL21: =+CL20-CL22 -> 33.93296 | CM21: =+CL21 -> 33.93296 | CN21: =+CM21 -> 33.93296 | CO21: =+CN21 -> 33.93296 | CP21: =+CO21 -> 33.93296 | CQ21: =+CP21 -> 33.93296 | CR21: =+CQ21 -> 33.93296 | CS21: =+CR21 -> 33.93296 | CT21: =+CS21 -> 33.93296 | ... DB21: =+DA21 -> 33.93296 | DF21: 33.623934
A22: EBIDTA | Q22: =+Q47*10^7/(Q$8+Q$10)/1000 -> 6.9932106 | R22: =+R47*10^7/(R$8+R$10)/1000 -> 6.9487702 | S22: =+S47*10^7/(S$8+S$10)/1000 -> 8.4989504 | T22: =+T47*10^7/(T$8+T$10)/1000 -> 11.309125 | U22: =+U47*10^7/(U$8+U$10)/1000 -> 11.82596 | V22: =+V47*10^7/(V$8+V$10)/1000 -> 10.864383 | W22: =+W47*10^7/(W$8+W$10)/1000 -> 13.241857 | X22: =+X47*10^7/(X$8+X$10)/1000 -> 12.478116 | ... AE22: =+AE47*10^7/(AE$8+AE$10)/1000 -> 14.782063 | BO22: =+BO47*10^7/(BO$8+BO$10)/1000 -> 8.535825 | BP22: =+BP47*10^7/(BP$8+BP$10)/1000 -> 10.853103 | BQ22: =+BQ47*10^7/(BQ$8+BQ$10)/1000 -> 12.352965 | BR22: =+BR47*10^7/(BR$8+BR$10)/1000 -> 12.542581 | BS22: =+BS47*10^7/(BS$8+BS$10)/1000 -> 16.240109 | BT22: =+BT47*10^7/(BT$8+BT$10)/1000 -> 12.818305 | BU22: =+BU47*10^7/(BU$8+BU$10)/1000 -> 6.6003226 | BV22: =+BV47*10^7/(BV$8+BV$10)/1000 -> 11.446 | ... CL22: =+CL47*10^7/(CL$8+CL$10)/1000 -> 10.782063 | CM22: =+CM20-CM21 -> 12.782063 | CN22: =+CN20-CN21 -> 14.782063 | CO22: =+CO20-CO21 -> 14.782063 | CP22: =+CP20-CP21 -> 14.782063 | CQ22: =+CQ20-CQ21 -> 14.782063 | CR22: =+CR20-CR21 -> 14.782063 | CS22: =+CS20-CS21 -> 14.782063 | CT22: =+CT20-CT21 -> 14.782063 | ... DB22: =+DB20-DB21 -> 14.782063 | DF22: 14.517299
A25: Presentation Data (End)
A26: Profit & Loss- Annual (Start)
A27: Gross Revenue | B27: ='Annual Raw'!C6 -> 0 | C27: ='Annual Raw'!D6 -> 0 | D27: ='Annual Raw'!E6 -> 0 | E27: ='Annual Raw'!F6 -> 0 | F27: ='Annual Raw'!G6 -> 0 | G27: ='Annual Raw'!H6 -> 0 | H27: ='Annual Raw'!I6 -> 0 | I27: ='Annual Raw'!J6 -> 0 | ... AA27: ='Annual Raw'!AB6 -> 17895.165 | AB27: =+SUM(CM27:CP27) -> 18622.715 | AC27: =+SUM(CQ27:CT27) -> 20350.908 | AD27: =+SUM(CU27:CX27) -> 22161.588 | AE27: =+SUM(CY27:DB27) -> 24153.336 | AI27: ='QTR Raw'!C6+'QTR Raw'!C8 -> 1290.43 | AJ27: ='QTR Raw'!D6+'QTR Raw'!D8 -> 1636.93 | AK27: ='QTR Raw'!E6+'QTR Raw'!E8 -> 1722.73 | AL27: ='QTR Raw'!F6+'QTR Raw'!F8 -> 980.07 | AM27: ='QTR Raw'!G6+'QTR Raw'!G8 -> 1207.01 | AN27: ='QTR Raw'!H6+'QTR Raw'!H8 -> 1229.39 | AO27: ='QTR Raw'!I6+'QTR Raw'!I8 -> 1709.61 | AP27: ='QTR Raw'!J6+'QTR Raw'!J8 -> 1363.58 | ... CL27: ='QTR Raw'!BF6+'QTR Raw'!BF8 -> 4633.48 | CM27: =+(CM$8+CM$10)*CM18/10^4 -> 4347.8305 | CN27: =+(CN$8+CN$10)*CN18/10^4 -> 4038.311 | CO27: =+(CO$8+CO$10)*CO18/10^4 -> 4952.1366 | CP27: =+(CP$8+CP$10)*CP18/10^4 -> 5284.4368 | CQ27: =+(CQ$8+CQ$10)*CQ18/10^4 -> 4816.8429 | CR27: =+(CR$8+CR$10)*CR18/10^4 -> 4386.0394 | CS27: =+(CS$8+CS$10)*CS18/10^4 -> 5391.2476 | CT27: =+(CT$8+CT$10)*CT18/10^4 -> 5756.7779 | ... DB27: =+(DB$8+DB$10)*DB18/10^4 -> 6847.8857 | DF27: 17895.165
A28: Less: Exise Duty | B28: ='Annual Raw'!C7+'Annual Raw'!C8+'Annual Raw'!C9 -> 0 | C28: ='Annual Raw'!D7+'Annual Raw'!D8+'Annual Raw'!D9 -> 0 | D28: ='Annual Raw'!E7+'Annual Raw'!E8+'Annual Raw'!E9 -> 0 | E28: ='Annual Raw'!F7+'Annual Raw'!F8+'Annual Raw'!F9 -> 0 | F28: ='Annual Raw'!G7+'Annual Raw'!G8+'Annual Raw'!G9 -> 0 | G28: ='Annual Raw'!H7+'Annual Raw'!H8+'Annual Raw'!H9 -> 0 | H28: ='Annual Raw'!I7+'Annual Raw'!I8+'Annual Raw'!I9 -> 0 | I28: ='Annual Raw'!J7+'Annual Raw'!J8+'Annual Raw'!J9 -> 0 | ... AA28: ='Annual Raw'!AB7+'Annual Raw'!AB8+'Annual Raw'!AB9 -> 0 | AB28: =+SUM(CM28:CP28) -> 0 | AC28: =+SUM(CQ28:CT28) -> 0 | AD28: =+SUM(CU28:CX28) -> 0 | AE28: =+SUM(CY28:DB28) -> 0 | AI28: =+'QTR Raw'!C20+'QTR Raw'!C19+'QTR Raw'!C13+'QTR Raw'!C7 -> 0 | AJ28: =+'QTR Raw'!D20+'QTR Raw'!D19+'QTR Raw'!D13+'QTR Raw'!D7 -> 0 | AK28: =+'QTR Raw'!E20+'QTR Raw'!E19+'QTR Raw'!E13+'QTR Raw'!E7 -> 0 | AL28: =+'QTR Raw'!F20+'QTR Raw'!F19+'QTR Raw'!F13+'QTR Raw'!F7 -> 0 | AM28: =+'QTR Raw'!G20+'QTR Raw'!G19+'QTR Raw'!G13+'QTR Raw'!G7 -> 0 | AN28: =+'QTR Raw'!H20+'QTR Raw'!H19+'QTR Raw'!H13+'QTR Raw'!H7 -> 0 | AO28: =+'QTR Raw'!I20+'QTR Raw'!I19+'QTR Raw'!I13+'QTR Raw'!I7 -> 0 | AP28: =+'QTR Raw'!J20+'QTR Raw'!J19+'QTR Raw'!J13+'QTR Raw'!J7 -> 0 | ... CL28: =+'QTR Raw'!BF20+'QTR Raw'!BF19+'QTR Raw'!BF13+'QTR Raw'!BF7 -> 0 | DF28: 0
A29: Net Revenue | B29: =+B27-B28 -> 0 | C29: =+C27-C28 -> 0 | D29: =+D27-D28 -> 0 | E29: =+E27-E28 -> 0 | F29: =+F27-F28 -> 0 | G29: =+G27-G28 -> 0 | H29: =+H27-H28 -> 0 | I29: =+I27-I28 -> 0 | ... AE29: =+AE27-AE28 -> 24153.336 | AI29: =+AI27-AI28 -> 1290.43 | AJ29: =+AJ27-AJ28 -> 1636.93 | AK29: =+AK27-AK28 -> 1722.73 | AL29: =+AL27-AL28 -> 980.07 | AM29: =+AM27-AM28 -> 1207.01 | AN29: =+AN27-AN28 -> 1229.39 | AO29: =+AO27-AO28 -> 1709.61 | AP29: =+AP27-AP28 -> 1363.58 | ... DB29: =+DB27-DB28 -> 6847.8857 | DF29: 17895.165
A30: Net Revenue YOY% | C30: =C29/B29-1 -> #DIV/0! | D30: =D29/C29-1 -> #DIV/0! | E30: =E29/D29-1 -> #DIV/0! | F30: =F29/E29-1 -> #DIV/0! | G30: =G29/F29-1 -> #DIV/0! | H30: =H29/G29-1 -> #DIV/0! | I30: =I29/H29-1 -> #DIV/0! | J30: =J29/I29-1 -> #DIV/0! | ... AE30: =AE29/AD29-1 -> 0.089873896 | AM30: =+IF(AI29<0,1-AM29/AI29,AM29/AI29-1) -> -0.064645118 | AN30: =+IF(AJ29<0,1-AN29/AJ29,AN29/AJ29-1) -> -0.24896605 | AO30: =+IF(AK29<0,1-AO29/AK29,AO29/AK29-1) -> -0.0076158191 | AP30: =+IF(AL29<0,1-AP29/AL29,AP29/AL29-1) -> 0.39130878 | AQ30: =+IF(AM29<0,1-AQ29/AM29,AQ29/AM29-1) -> -0.048002916 | AR30: =+IF(AN29<0,1-AR29/AN29,AR29/AN29-1) -> 0.29443057 | AS30: =+IF(AO29<0,1-AS29/AO29,AS29/AO29-1) -> 0.039669866 | AT30: =+IF(AP29<0,1-AT29/AP29,AT29/AP29-1) -> 0.5283445 | ... DB30: =+IF(CX29<0,1-DB29/CX29,DB29/CX29-1) -> 0.091061268 | DF30: -0.14084903
A31: Net Revenue QOQ% | AJ31: =+IF(AI29<0,1-AJ29/AI29,AJ29/AI29-1) -> 0.26851515 | AK31: =+IF(AJ29<0,1-AK29/AJ29,AK29/AJ29-1) -> 0.052415192 | AL31: =+IF(AK29<0,1-AL29/AK29,AL29/AK29-1) -> -0.43109483 | AM31: =+IF(AL29<0,1-AM29/AL29,AM29/AL29-1) -> 0.23155489 | AN31: =+IF(AM29<0,1-AN29/AM29,AN29/AM29-1) -> 0.018541686 | AO31: =+IF(AN29<0,1-AO29/AN29,AO29/AN29-1) -> 0.39061648 | AP31: =+IF(AO29<0,1-AP29/AO29,AP29/AO29-1) -> -0.20240289 | AQ31: =+IF(AP29<0,1-AQ29/AP29,AQ29/AP29-1) -> -0.15731384 | ... CL31: =+IF(CK29<0,1-CL29/CK29,CL29/CK29-1) -> -0.062695589 | CM31: =+CM29/CL29-1 -> -0.061649017 | CN31: =+CN29/CM29-1 -> -0.071189426 | CO31: =+CO29/CN29-1 -> 0.22628907 | CP31: =+CP29/CO29-1 -> 0.067102397 | CQ31: =+CQ29/CP29-1 -> -0.088485096 | CR31: =+CR29/CQ29-1 -> -0.089436904 | CS31: =+CS29/CR29-1 -> 0.22918358 | CT31: =+CT29/CS29-1 -> 0.06780068 | ... DB31: =+DB29/DA29-1 -> 0.069047711
A32: Increase/Decrease in Stock | B32: ='Annual Raw'!C11 -> 0 | C32: ='Annual Raw'!D11 -> 0 | D32: ='Annual Raw'!E11 -> 0 | E32: ='Annual Raw'!F11 -> 0 | F32: ='Annual Raw'!G11 -> 0 | G32: ='Annual Raw'!H11 -> 0 | H32: ='Annual Raw'!I11 -> 0 | I32: ='Annual Raw'!J11 -> 0 | ... AA32: ='Annual Raw'!AB11 -> -587.217 | AB32: =+SUM(CM32:CP32) -> 0 | AC32: =+SUM(CQ32:CT32) -> 0 | AD32: =+SUM(CU32:CX32) -> 0 | AE32: =+SUM(CY32:DB32) -> 0 | AI32: ='QTR Raw'!C10 -> -191.53 | AJ32: ='QTR Raw'!D10 -> 112.79 | AK32: ='QTR Raw'!E10 -> 366.5 | AL32: ='QTR Raw'!F10 -> -56.95 | AM32: ='QTR Raw'!G10 -> 28.77 | AN32: ='QTR Raw'!H10 -> -70.38 | AO32: ='QTR Raw'!I10 -> 190.88 | AP32: ='QTR Raw'!J10 -> 93.36 | ... CL32: ='QTR Raw'!BF10 -> -23.16 | DF32: -587.217
A33: Purchase of Finished Goods | B33: 0 | C33: 0 | D33: 0 | E33: 0 | F33: 0 | G33: 0 | H33: 0 | I33: 0 | J33: 0 | K33: 0 | L33: 0 | M33: 0 | N33: 0 | O33: 0 | P33: 0 | Q33: 0 | R33: 0 | S33: 0 | T33: 0 | U33: 0 | V33: 0 | W33: 0 | X33: 0 | Y33: 0 | Z33: 0 | AA33: 0 | AB33: =+SUM(CM33:CP33) -> 0 | AC33: =+SUM(CQ33:CT33) -> 0 | AD33: =+SUM(CU33:CX33) -> 0 | AE33: =+SUM(CY33:DB33) -> 0 | AI33: ='QTR Raw'!C12 -> 0 | AJ33: ='QTR Raw'!D12 -> 0 | AK33: ='QTR Raw'!E12 -> 0 | AL33: ='QTR Raw'!F12 -> 21.38 | AM33: ='QTR Raw'!G12 -> 0 | AN33: ='QTR Raw'!H12 -> 0 | AO33: ='QTR Raw'!I12 -> 0 | AP33: ='QTR Raw'!J12 -> 4.48 | ... CL33: ='QTR Raw'!BF12 -> 0.98 | DF33: 0
A34: Raw Material Consumed | B34: ='Annual Raw'!C12 -> 0 | C34: ='Annual Raw'!D12 -> 0 | D34: ='Annual Raw'!E12 -> 0 | E34: ='Annual Raw'!F12 -> 0 | F34: ='Annual Raw'!G12 -> 0 | G34: ='Annual Raw'!H12 -> 0 | H34: ='Annual Raw'!I12 -> 0 | I34: ='Annual Raw'!J12 -> 0 | ... AA34: ='Annual Raw'!AB12 -> 10640.055 | AB34: =+SUM(CM34:CP34) -> 10259.111 | AC34: =+SUM(CQ34:CT34) -> 11161.939 | AD34: =+SUM(CU34:CX34) -> 12155.05 | AE34: =+SUM(CY34:DB34) -> 13247.472 | AI34: ='QTR Raw'!C11 -> 1035.26 | AJ34: ='QTR Raw'!D11 -> 984.68 | AK34: ='QTR Raw'!E11 -> 892.56 | AL34: ='QTR Raw'!F11 -> 660.83 | AM34: ='QTR Raw'!G11 -> 759.39 | AN34: ='QTR Raw'!H11 -> 840.83 | AO34: ='QTR Raw'!I11 -> 916.31 | AP34: ='QTR Raw'!J11 -> 619.51 | ... CL34: ='QTR Raw'!BF11 -> 2661.37 | CM34: =+CM29-CM35 -> 2429.7117 | CN34: =+CN29-CN35 -> 2214.9077 | CO34: =+CO29-CO35 -> 2716.1171 | CP34: =+CP29-CP35 -> 2898.375 | CQ34: =+CQ29-CQ35 -> 2641.912 | CR34: =+CR29-CR35 -> 2405.6276 | CS34: =+CS29-CS35 -> 2956.9579 | CT34: =+CT29-CT35 -> 3157.4417 | ... DB34: =+DB29-DB35 -> 3755.8857 | DF34: 10640.055
A35: Gross Profit | B35: =B29-B32-B34-B33 -> 0 | C35: =C29-C32-C34-C33 -> 0 | D35: =D29-D32-D34-D33 -> 0 | E35: =E29-E32-E34-E33 -> 0 | F35: =F29-F32-F34-F33 -> 0 | G35: =G29-G32-G34-G33 -> 0 | H35: =H29-H32-H34-H33 -> 0 | I35: =I29-I32-I34-I33 -> 0 | ... AE35: =AE29-AE32-AE34-AE33 -> 10905.865 | AI35: =AI29-AI32-AI34-AI33 -> 446.7 | AJ35: =AJ29-AJ32-AJ34-AJ33 -> 539.46 | AK35: =AK29-AK32-AK34-AK33 -> 463.67 | AL35: =AL29-AL32-AL34-AL33 -> 354.81 | AM35: =AM29-AM32-AM34-AM33 -> 418.85 | AN35: =AN29-AN32-AN34-AN33 -> 458.94 | AO35: =AO29-AO32-AO34-AO33 -> 602.42 | AP35: =AP29-AP32-AP34-AP33 -> 646.23 | ... CL35: =CL29-CL32-CL34-CL33 -> 1994.29 | CM35: =+(CM$8+CM$10)*CM20/10^4 -> 1918.1188 | CN35: =+(CN$8+CN$10)*CN20/10^4 -> 1823.4033 | CO35: =+(CO$8+CO$10)*CO20/10^4 -> 2236.0195 | CP35: =+(CP$8+CP$10)*CP20/10^4 -> 2386.0618 | CQ35: =+(CQ$8+CQ$10)*CQ20/10^4 -> 2174.9309 | CR35: =+(CR$8+CR$10)*CR20/10^4 -> 1980.4118 | CS35: =+(CS$8+CS$10)*CS20/10^4 -> 2434.2897 | CT35: =+(CT$8+CT$10)*CT20/10^4 -> 2599.3362 | ... DB35: =+(DB$8+DB$10)*DB20/10^4 -> 3092 | DF35: 7842.3271
A36: GP% | B36: =B35/B29 -> #DIV/0! | C36: =C35/C29 -> #DIV/0! | D36: =D35/D29 -> #DIV/0! | E36: =E35/E29 -> #DIV/0! | F36: =F35/F29 -> #DIV/0! | G36: =G35/G29 -> #DIV/0! | H36: =H35/H29 -> #DIV/0! | I36: =I35/I29 -> #DIV/0! | ... AE36: =AE35/AE29 -> 0.45152622 | AI36: =AI35/AI29 -> 0.34616368 | AJ36: =AJ35/AJ29 -> 0.32955594 | AK36: =AK35/AK29 -> 0.26914839 | AL36: =AL35/AL29 -> 0.36202516 | AM36: =AM35/AM29 -> 0.34701452 | AN36: =AN35/AN29 -> 0.37330709 | AO36: =AO35/AO29 -> 0.35237276 | AP36: =AP35/AP29 -> 0.47392159 | ... DB36: =DB35/DB29 -> 0.45152622 | DF36: 0.4382372
A37: GP YOY% | C37: =+IF(B35<0,1-C35/B35,C35/B35-1) -> #DIV/0! | D37: =+IF(C35<0,1-D35/C35,D35/C35-1) -> #DIV/0! | E37: =+IF(D35<0,1-E35/D35,E35/D35-1) -> #DIV/0! | F37: =+IF(E35<0,1-F35/E35,F35/E35-1) -> #DIV/0! | G37: =+IF(F35<0,1-G35/F35,G35/F35-1) -> #DIV/0! | H37: =+IF(G35<0,1-H35/G35,H35/G35-1) -> #DIV/0! | I37: =+IF(H35<0,1-I35/H35,I35/H35-1) -> #DIV/0! | J37: =+IF(I35<0,1-J35/I35,J35/I35-1) -> #DIV/0! | ... AE37: =+IF(AD35<0,1-AE35/AD35,AE35/AD35-1) -> 0.089873896 | AM37: =+IF(AI35<0,1-AM35/AI35,AM35/AI35-1) -> -0.062346094 | AN37: =+IF(AJ35<0,1-AN35/AJ35,AN35/AJ35-1) -> -0.14926037 | AO37: =+IF(AK35<0,1-AO35/AK35,AO35/AK35-1) -> 0.299243 | AP37: =+IF(AL35<0,1-AP35/AL35,AP35/AL35-1) -> 0.821341 | AQ37: =+IF(AM35<0,1-AQ35/AM35,AQ35/AM35-1) -> 0.28976961 | AR37: =+IF(AN35<0,1-AR35/AN35,AR35/AN35-1) -> 0.59027324 | AS37: =+IF(AO35<0,1-AS35/AO35,AS35/AO35-1) -> 0.35186415 | AT37: =+IF(AP35<0,1-AT35/AP35,AT35/AP35-1) -> 0.38456896 | ... CL37: =+IF(CH35<0,1-CL35/CH35,CL35/CH35-1) -> -0.048861566 | CM37: =+CM35/CI35-1 -> -0.013018894 | CN37: =+CN35/CJ35-1 -> -0.026516206 | CO37: =+CO35/CK35-1 -> 0.10064164 | CP37: =+CP35/CL35-1 -> 0.19644675 | CQ37: =+CQ35/CM35-1 -> 0.13388747 | CR37: =+CR35/CN35-1 -> 0.0861074 | CS37: =+CS35/CO35-1 -> 0.088671024 | CT37: =+CT35/CP35-1 -> 0.089383422 | ... DB37: =+DB35/CX35-1 -> 0.091061268 | DF37: -0.12705973
A38: GP QOQ% | AJ38: =+IF(AI35<0,1-AJ35/AI35,AJ35/AI35-1) -> 0.20765615 | AK38: =+IF(AJ35<0,1-AK35/AJ35,AK35/AJ35-1) -> -0.14049234 | AL38: =+IF(AK35<0,1-AL35/AK35,AL35/AK35-1) -> -0.23477905 | AM38: =+IF(AL35<0,1-AM35/AL35,AM35/AL35-1) -> 0.18049097 | AN38: =+IF(AM35<0,1-AN35/AM35,AN35/AM35-1) -> 0.095714456 | AO38: =+IF(AN35<0,1-AO35/AN35,AO35/AN35-1) -> 0.31263346 | AP38: =+IF(AO35<0,1-AP35/AO35,AP35/AO35-1) -> 0.072723349 | AQ38: =+IF(AP35<0,1-AQ35/AP35,AQ35/AP35-1) -> -0.16404376 | ... CL38: =+IF(CK35<0,1-CL35/CK35,CL35/CK35-1) -> -0.018345508 | CM38: =+CM35/CL35-1 -> -0.038194635 | CN38: =+CN35/CM35-1 -> -0.049379387 | CO38: =+CO35/CN35-1 -> 0.22628907 | CP38: =+CP35/CO35-1 -> 0.067102397 | CQ38: =+CQ35/CP35-1 -> -0.088485096 | CR38: =+CR35/CQ35-1 -> -0.089436904 | CS38: =+CS35/CR35-1 -> 0.22918358 | CT38: =+CT35/CS35-1 -> 0.06780068 | ... DB38: =+DB35/DA35-1 -> 0.069047711
A39: Employee Cost | B39: ='Annual Raw'!C14 -> 0 | C39: ='Annual Raw'!D14 -> 0 | D39: ='Annual Raw'!E14 -> 0 | E39: ='Annual Raw'!F14 -> 0 | F39: ='Annual Raw'!G14 -> 0 | G39: ='Annual Raw'!H14 -> 0 | H39: ='Annual Raw'!I14 -> 0 | I39: ='Annual Raw'!J14 -> 0 | ... AA39: ='Annual Raw'!AB14 -> 1629.7263 | AB39: =+SUM(CM39:CP39) -> 1743.8111 | AC39: =+SUM(CQ39:CT39) -> 1865.8779 | AD39: =+SUM(CU39:CX39) -> 1996.4893 | AE39: =+SUM(CY39:DB39) -> 2136.2436 | AI39: ='QTR Raw'!C16 -> 61.88 | AJ39: ='QTR Raw'!D16 -> 62.85 | AK39: ='QTR Raw'!E16 -> 64.17 | AL39: ='QTR Raw'!F16 -> 63.36 | AM39: ='QTR Raw'!G16 -> 68.02 | AN39: ='QTR Raw'!H16 -> 76.7 | AO39: ='QTR Raw'!I16 -> 78.73 | AP39: ='QTR Raw'!J16 -> 76.75 | ... CL39: ='QTR Raw'!BF16 -> 398.79 | CM39: =CI39*107% -> 436.0571 | CN39: =CJ39*107% -> 445.5266 | CO39: =CK39*107% -> 435.5221 | CP39: =CL39*107% -> 426.7053 | CQ39: =CM39*107% -> 466.5811 | CR39: =CN39*107% -> 476.71346 | CS39: =CO39*107% -> 466.00865 | CT39: =CP39*107% -> 456.57467 | ... DB39: =CX39*107% -> 522.73234 | DF39: 1629.7263
A40: General and Administration Expenses | B40: ='Annual Raw'!C17 -> 0 | C40: ='Annual Raw'!D17 -> 0 | D40: ='Annual Raw'!E17 -> 0 | E40: ='Annual Raw'!F17 -> 0 | F40: ='Annual Raw'!G17 -> 0 | G40: ='Annual Raw'!H17 -> 0 | H40: ='Annual Raw'!I17 -> 0 | I40: ='Annual Raw'!J17 -> 0 | ... AA40: ='Annual Raw'!AB17 -> 246.2315 | AB40: =+SUM(CM40:CP40) -> 0 | AC40: =+SUM(CQ40:CT40) -> 0 | AD40: =+SUM(CU40:CX40) -> 0 | AE40: =+SUM(CY40:DB40) -> 0 | AI40: ='QTR Raw'!C17 -> 0 | AJ40: ='QTR Raw'!D17 -> 0 | AK40: ='QTR Raw'!E17 -> 0 | AL40: ='QTR Raw'!F17 -> 0 | AM40: ='QTR Raw'!G17 -> 0 | AN40: ='QTR Raw'!H17 -> 0 | AO40: ='QTR Raw'!I17 -> 0 | AP40: ='QTR Raw'!J17 -> 0 | ... CL40: ='QTR Raw'!BF17 -> 0 | DF40: 246.2315
A41: Miscellaneous Expenses | B41: ='Annual Raw'!C19-'Annual Raw'!C20 -> 0 | C41: ='Annual Raw'!D19-'Annual Raw'!D20 -> 0 | D41: ='Annual Raw'!E19-'Annual Raw'!E20 -> 0 | E41: ='Annual Raw'!F19-'Annual Raw'!F20 -> 0 | F41: ='Annual Raw'!G19-'Annual Raw'!G20 -> 0 | G41: ='Annual Raw'!H19-'Annual Raw'!H20 -> 0 | H41: ='Annual Raw'!I19-'Annual Raw'!I20 -> 0 | I41: ='Annual Raw'!J19-'Annual Raw'!J20 -> 0 | ... AA41: ='Annual Raw'!AB19-'Annual Raw'!AB20 -> 275.1806 | AB41: =+SUM(CM41:CP41) -> 0 | AC41: =+SUM(CQ41:CT41) -> 0 | AD41: =+SUM(CU41:CX41) -> 0 | AE41: =+SUM(CY41:DB41) -> 0 | AI41: =+'QTR Raw'!C21 -> 0 | AJ41: =+'QTR Raw'!D21 -> 0 | AK41: =+'QTR Raw'!E21 -> 0 | AL41: =+'QTR Raw'!F21 -> 0 | AM41: =+'QTR Raw'!G21 -> 0 | AN41: =+'QTR Raw'!H21 -> 0 | AO41: =+'QTR Raw'!I21 -> 0 | AP41: =+'QTR Raw'!J21 -> 0 | ... CL41: =+'QTR Raw'!BF21 -> 0 | DF41: 275.1806
A42: Other Manufacturing Expenses | B42: ='Annual Raw'!C15+'Annual Raw'!C16 -> 0 | C42: ='Annual Raw'!D15+'Annual Raw'!D16 -> 0 | D42: ='Annual Raw'!E15+'Annual Raw'!E16 -> 0 | E42: ='Annual Raw'!F15+'Annual Raw'!F16 -> 0 | F42: ='Annual Raw'!G15+'Annual Raw'!G16 -> 0 | G42: ='Annual Raw'!H15+'Annual Raw'!H16 -> 0 | H42: ='Annual Raw'!I15+'Annual Raw'!I16 -> 0 | I42: ='Annual Raw'!J15+'Annual Raw'!J16 -> 0 | ... AA42: ='Annual Raw'!AB15+'Annual Raw'!AB16 -> 1395.5755 | AB42: =+SUM(CM42:CP42) -> 4139.1461 | AC42: =+SUM(CQ42:CT42) -> 4534.7945 | AD42: =+SUM(CU42:CX42) -> 4973.6697 | AE42: =+SUM(CY42:DB42) -> 5460.3508 | AI42: ='QTR Raw'!C14 -> 224.58 | AJ42: ='QTR Raw'!D14 -> 278.76 | AK42: ='QTR Raw'!E14 -> 240.94 | AL42: ='QTR Raw'!F14 -> 188.49 | AM42: ='QTR Raw'!G14 -> 208.47 | AN42: ='QTR Raw'!H14 -> 234.04 | AO42: ='QTR Raw'!I14 -> 357.96 | AP42: ='QTR Raw'!J14 -> 406.77 | ... CL42: ='QTR Raw'!BF14 -> 1114.62 | CM42: =CM45-CM39-CM40-CM41-CM43-CM44 -> 957.23022 | CN42: =CN45-CN39-CN40-CN41-CN43-CN44 -> 824.58408 | CO42: =CO45-CO39-CO40-CO41-CO43-CO44 -> 1122.0007 | CP42: =CP45-CP39-CP40-CP41-CP43-CP44 -> 1235.3311 | CQ42: =CQ45-CQ39-CQ40-CQ41-CQ43-CQ44 -> 1048.3898 | CR42: =CR45-CR39-CR40-CR41-CR43-CR44 -> 902.76315 | CS42: =CS45-CS39-CS40-CS41-CS43-CS44 -> 1229.6213 | CT42: =CT45-CT39-CT40-CT41-CT43-CT44 -> 1354.0202 | ... DB42: =DB45-DB39-DB40-DB41-DB43-DB44 -> 1631.0326 | DF42: 1395.5755
A43: Power & Fuel Cost | B43: ='Annual Raw'!C13 -> 0 | C43: ='Annual Raw'!D13 -> 0 | D43: ='Annual Raw'!E13 -> 0 | E43: ='Annual Raw'!F13 -> 0 | F43: ='Annual Raw'!G13 -> 0 | G43: ='Annual Raw'!H13 -> 0 | H43: ='Annual Raw'!I13 -> 0 | I43: ='Annual Raw'!J13 -> 0 | ... AA43: ='Annual Raw'!AB13 -> 724.0416 | AB43: =+SUM(CM43:CP43) -> 0 | AC43: =+SUM(CQ43:CT43) -> 0 | AD43: =+SUM(CU43:CX43) -> 0 | AE43: =+SUM(CY43:DB43) -> 0 | AI43: ='QTR Raw'!C15 -> 0 | AJ43: ='QTR Raw'!D15 -> 0 | AK43: ='QTR Raw'!E15 -> 0 | AL43: ='QTR Raw'!F15 -> 0 | AM43: ='QTR Raw'!G15 -> 0 | AN43: ='QTR Raw'!H15 -> 0 | AO43: ='QTR Raw'!I15 -> 0 | AP43: ='QTR Raw'!J15 -> 0 | ... CL43: ='QTR Raw'!BF15 -> 0 | DF43: 724.0416
A44: Selling and Distribution Expenses | B44: ='Annual Raw'!C18 -> 0 | C44: ='Annual Raw'!D18 -> 0 | D44: ='Annual Raw'!E18 -> 0 | E44: ='Annual Raw'!F18 -> 0 | F44: ='Annual Raw'!G18 -> 0 | G44: ='Annual Raw'!H18 -> 0 | H44: ='Annual Raw'!I18 -> 0 | I44: ='Annual Raw'!J18 -> 0 | ... AA44: ='Annual Raw'!AB18 -> 1409.8388 | AB44: =+SUM(CM44:CP44) -> 0 | AC44: =+SUM(CQ44:CT44) -> 0 | AD44: =+SUM(CU44:CX44) -> 0 | AE44: =+SUM(CY44:DB44) -> 0 | AI44: ='QTR Raw'!C18 -> 0 | AJ44: ='QTR Raw'!D18 -> 0 | AK44: ='QTR Raw'!E18 -> 0 | AL44: ='QTR Raw'!F18 -> 0 | AM44: ='QTR Raw'!G18 -> 0 | AN44: ='QTR Raw'!H18 -> 0 | AO44: ='QTR Raw'!I18 -> 0 | AP44: ='QTR Raw'!J18 -> 0 | ... CL44: ='QTR Raw'!BF18 -> 0 | DF44: 1409.8388
A45: Total Cost | B45: =+SUM(B39:B44) -> 0 | C45: =+SUM(C39:C44) -> 0 | D45: =+SUM(D39:D44) -> 0 | E45: =+SUM(E39:E44) -> 0 | F45: =+SUM(F39:F44) -> 0 | G45: =+SUM(G39:G44) -> 0 | H45: =+SUM(H39:H44) -> 0 | I45: =+SUM(I39:I44) -> 0 | ... AE45: =+SUM(AE39:AE44) -> 7596.5944 | AI45: =+SUM(AI39:AI44) -> 286.46 | AJ45: =+SUM(AJ39:AJ44) -> 341.61 | AK45: =+SUM(AK39:AK44) -> 305.11 | AL45: =+SUM(AL39:AL44) -> 251.85 | AM45: =+SUM(AM39:AM44) -> 276.49 | AN45: =+SUM(AN39:AN44) -> 310.74 | AO45: =+SUM(AO39:AO44) -> 436.69 | AP45: =+SUM(AP39:AP44) -> 483.52 | ... CL45: =+SUM(CL39:CL44) -> 1513.41 | CM45: =+CM35-CM47 -> 1393.2873 | CN45: =+CN35-CN47 -> 1270.1107 | CO45: =+CO35-CO47 -> 1557.5228 | CP45: =+CP35-CP47 -> 1662.0364 | CQ45: =+CQ35-CQ47 -> 1514.9709 | CR45: =+CR35-CR47 -> 1379.4766 | CS45: =+CS35-CS47 -> 1695.63 | CT45: =+CT35-CT47 -> 1810.5949 | ... DB45: =+DB35-DB47 -> 2153.765 | DF45: 5680.5943
A46: Cost % | B46: =B45/B29 -> #DIV/0! | C46: =C45/C29 -> #DIV/0! | D46: =D45/D29 -> #DIV/0! | E46: =E45/E29 -> #DIV/0! | F46: =F45/F29 -> #DIV/0! | G46: =G45/G29 -> #DIV/0! | H46: =H45/H29 -> #DIV/0! | I46: =I45/I29 -> #DIV/0! | ... AE46: =AE45/AE29 -> 0.31451532 | AI46: =AI45/AI29 -> 0.22198802 | AJ46: =AJ45/AJ29 -> 0.20868944 | AK46: =AK45/AK29 -> 0.17710843 | AL46: =AL45/AL29 -> 0.25697144 | AM46: =AM45/AM29 -> 0.22907018 | AN46: =AN45/AN29 -> 0.2527595 | AO46: =AO45/AO29 -> 0.25543253 | AP46: =AP45/AP29 -> 0.35459599 | ... DB46: =DB45/DB29 -> 0.31451532 | DF46: 0.31743738
...

Sheet Notes
J5: Rajeev Goyal - VP Finance Mar 19, 2026
J6: Feed back from ground is good
J7: MP, rajasthan, and UP - by mar end to release 8000 crs
J8: Thrust on jal jeevan mission - some things are seeing
J9: positivity on the EPC sector
J10: 620,000 MT order from Saudi company - jobwork - 18-24 months
J11: stuck money -
J12: 450 crs jal jeevan mission money has not come
J14: 2 expansion - KSA - local demand
J15: 1 in Abu Dhabi - adnoc demand local
J16: all at starting point
J18: 20 lakh MT - can do in full swing in pipe
J20: Pellet - don’t take this vol. compare company of pipe volumes only

Sheet QTR Raw
A1: ='Annual Raw'!A1 -> 100378 | B1: X | C1: 201206 | D1: 201209 | E1: 201212 | F1: 201303 | G1: 201306 | H1: 201309 | I1: 201312 | J1: 201403 | K1: 201406 | L1: 201409 | M1: 201412 | N1: 201503 | O1: 201506 | P1: 201509 | Q1: 201512 | R1: 201603 | S1: 201606 | T1: 201609 | U1: 201612 | V1: 201703 | W1: 201706 | X1: 201709 | Y1: 201712 | Z1: 201803 | AA1: 201806 | AB1: 201809 | AC1: 201812 | AD1: 201903 | AE1: 201906 | AF1: 201909 | AG1: 201912 | AH1: 202003 | AI1: 202006 | AJ1: 202009 | AK1: 202012 | AL1: 202103 | AM1: 202106 | AN1: 202109 | AO1: 202112 | AP1: 202203 | AQ1: 202206 | AR1: 202209 | AS1: 202212 | AT1: 202303 | AU1: 202306 | AV1: 202309 | AW1: 202312 | AX1: 202403 | AY1: 202406 | AZ1: 202409 | BA1: 202412 | BB1: 202503 | BC1: 202506 | BD1: 202509 | BE1: 202512 | BF1: 202603 | BG1: 202606 | BH1: 202609 | BI1: 202612 | BJ1: 202703 | BK1: 202706 | BL1: 202709 | BM1: 202712 | BN1: 202803 | BO1: 202806 | BP1: 202809 | BQ1: 202812 | BR1: 202903 | BS1: 202906 | BT1: 202909 | BU1: 202912 | BV1: 203003
A3: Field Description | B3: Field Name
A4: Company Name | B4: CD_COMPNAME | C4: =_xll.EQNXTDZ(A1,B4,C1) -> Jindal Saw Ltd.
A5: Date End | B5: QTR_DATE_END | C5: =_xll.EQNXTDZ($A$1,$B5,C$1,$B$1) -> 201206 | D5: =_xll.EQNXTDZ($A$1,$B5,D$1,$B$1) -> 201209 | E5: =_xll.EQNXTDZ($A$1,$B5,E$1,$B$1) -> 201212 | F5: =_xll.EQNXTDZ($A$1,$B5,F$1,$B$1) -> 201303 | G5: =_xll.EQNXTDZ($A$1,$B5,G$1,$B$1) -> 201306 | H5: =_xll.EQNXTDZ($A$1,$B5,H$1,$B$1) -> 201309 | I5: =_xll.EQNXTDZ($A$1,$B5,I$1,$B$1) -> 201312 | J5: =_xll.EQNXTDZ($A$1,$B5,J$1,$B$1) -> 201403 | ... BV5: =_xll.EQNXTDZ($A$1,$B5,BV$1,$B$1) -> 0
A6: Gross Sales | B6: QTR_GROSS_SALE | C6: =_xll.EQNXTDZ($A$1,$B6,C$1,$B$1) -> 1290.06 | D6: =_xll.EQNXTDZ($A$1,$B6,D$1,$B$1) -> 1635.21 | E6: =_xll.EQNXTDZ($A$1,$B6,E$1,$B$1) -> 1722.01 | F6: =_xll.EQNXTDZ($A$1,$B6,F$1,$B$1) -> 979.04 | G6: =_xll.EQNXTDZ($A$1,$B6,G$1,$B$1) -> 1206.7 | H6: =_xll.EQNXTDZ($A$1,$B6,H$1,$B$1) -> 1223.71 | I6: =_xll.EQNXTDZ($A$1,$B6,I$1,$B$1) -> 1709.45 | J6: =_xll.EQNXTDZ($A$1,$B6,J$1,$B$1) -> 1363.13 | ... BV6: =_xll.EQNXTDZ($A$1,$B6,BV$1,$B$1) -> 0
A7: Less: Excise Duty | B7: QTR_EXCISE_DUTY | C7: =_xll.EQNXTDZ($A$1,$B7,C$1,$B$1) -> 0 | D7: =_xll.EQNXTDZ($A$1,$B7,D$1,$B$1) -> 0 | E7: =_xll.EQNXTDZ($A$1,$B7,E$1,$B$1) -> 0 | F7: =_xll.EQNXTDZ($A$1,$B7,F$1,$B$1) -> 0 | G7: =_xll.EQNXTDZ($A$1,$B7,G$1,$B$1) -> 0 | H7: =_xll.EQNXTDZ($A$1,$B7,H$1,$B$1) -> 0 | I7: =_xll.EQNXTDZ($A$1,$B7,I$1,$B$1) -> 0 | J7: =_xll.EQNXTDZ($A$1,$B7,J$1,$B$1) -> 0 | ... BV7: =_xll.EQNXTDZ($A$1,$B7,BV$1,$B$1) -> 0
A8: Other operating income | B8: QTR_JOB_WORKS | C8: =_xll.EQNXTDZ($A$1,$B8,C$1,$B$1) -> 0.37 | D8: =_xll.EQNXTDZ($A$1,$B8,D$1,$B$1) -> 1.72 | E8: =_xll.EQNXTDZ($A$1,$B8,E$1,$B$1) -> 0.72 | F8: =_xll.EQNXTDZ($A$1,$B8,F$1,$B$1) -> 1.03 | G8: =_xll.EQNXTDZ($A$1,$B8,G$1,$B$1) -> 0.31 | H8: =_xll.EQNXTDZ($A$1,$B8,H$1,$B$1) -> 5.68 | I8: =_xll.EQNXTDZ($A$1,$B8,I$1,$B$1) -> 0.16 | J8: =_xll.EQNXTDZ($A$1,$B8,J$1,$B$1) -> 0.45 | ... BV8: =_xll.EQNXTDZ($A$1,$B8,BV$1,$B$1) -> 0
A9: Net Sales & Other Operating Income | B9: QTR_NET_SALES | C9: =_xll.EQNXTDZ($A$1,$B9,C$1,$B$1) -> 1290.43 | D9: =_xll.EQNXTDZ($A$1,$B9,D$1,$B$1) -> 1636.93 | E9: =_xll.EQNXTDZ($A$1,$B9,E$1,$B$1) -> 1722.73 | F9: =_xll.EQNXTDZ($A$1,$B9,F$1,$B$1) -> 980.07 | G9: =_xll.EQNXTDZ($A$1,$B9,G$1,$B$1) -> 1207.01 | H9: =_xll.EQNXTDZ($A$1,$B9,H$1,$B$1) -> 1229.39 | I9: =_xll.EQNXTDZ($A$1,$B9,I$1,$B$1) -> 1709.61 | J9: =_xll.EQNXTDZ($A$1,$B9,J$1,$B$1) -> 1363.58 | ... BV9: =_xll.EQNXTDZ($A$1,$B9,BV$1,$B$1) -> 0
A10: (Increase) / Decrease In Stocks | B10: QTR_INC_DEC_INVENTORY | C10: =_xll.EQNXTDZ($A$1,$B10,C$1,$B$1) -> -191.53 | D10: =_xll.EQNXTDZ($A$1,$B10,D$1,$B$1) -> 112.79 | E10: =_xll.EQNXTDZ($A$1,$B10,E$1,$B$1) -> 366.5 | F10: =_xll.EQNXTDZ($A$1,$B10,F$1,$B$1) -> -56.95 | G10: =_xll.EQNXTDZ($A$1,$B10,G$1,$B$1) -> 28.77 | H10: =_xll.EQNXTDZ($A$1,$B10,H$1,$B$1) -> -70.38 | I10: =_xll.EQNXTDZ($A$1,$B10,I$1,$B$1) -> 190.88 | J10: =_xll.EQNXTDZ($A$1,$B10,J$1,$B$1) -> 93.36 | ... BV10: =_xll.EQNXTDZ($A$1,$B10,BV$1,$B$1) -> 0
A11: Cost of Services & Raw Materials | B11: QTR_RAW_MATERIAL_COST | C11: =_xll.EQNXTDZ($A$1,$B11,C$1,$B$1) -> 1035.26 | D11: =_xll.EQNXTDZ($A$1,$B11,D$1,$B$1) -> 984.68 | E11: =_xll.EQNXTDZ($A$1,$B11,E$1,$B$1) -> 892.56 | F11: =_xll.EQNXTDZ($A$1,$B11,F$1,$B$1) -> 660.83 | G11: =_xll.EQNXTDZ($A$1,$B11,G$1,$B$1) -> 759.39 | H11: =_xll.EQNXTDZ($A$1,$B11,H$1,$B$1) -> 840.83 | I11: =_xll.EQNXTDZ($A$1,$B11,I$1,$B$1) -> 916.31 | J11: =_xll.EQNXTDZ($A$1,$B11,J$1,$B$1) -> 619.51 | ... BV11: =_xll.EQNXTDZ($A$1,$B11,BV$1,$B$1) -> 0
A12: Purchase of Finished Goods | B12: QTR_PURCHASE_FIN_GOOD | C12: =_xll.EQNXTDZ($A$1,$B12,C$1,$B$1) -> 0 | D12: =_xll.EQNXTDZ($A$1,$B12,D$1,$B$1) -> 0 | E12: =_xll.EQNXTDZ($A$1,$B12,E$1,$B$1) -> 0 | F12: =_xll.EQNXTDZ($A$1,$B12,F$1,$B$1) -> 21.38 | G12: =_xll.EQNXTDZ($A$1,$B12,G$1,$B$1) -> 0 | H12: =_xll.EQNXTDZ($A$1,$B12,H$1,$B$1) -> 0 | I12: =_xll.EQNXTDZ($A$1,$B12,I$1,$B$1) -> 0 | J12: =_xll.EQNXTDZ($A$1,$B12,J$1,$B$1) -> 4.48 | ... BV12: =_xll.EQNXTDZ($A$1,$B12,BV$1,$B$1) -> 0
A13: Excise Duty | B13: QTR_EXCISE | C13: =_xll.EQNXTDZ($A$1,$B13,C$1,$B$1) -> 0 | D13: =_xll.EQNXTDZ($A$1,$B13,D$1,$B$1) -> 0 | E13: =_xll.EQNXTDZ($A$1,$B13,E$1,$B$1) -> 0 | F13: =_xll.EQNXTDZ($A$1,$B13,F$1,$B$1) -> 0 | G13: =_xll.EQNXTDZ($A$1,$B13,G$1,$B$1) -> 0 | H13: =_xll.EQNXTDZ($A$1,$B13,H$1,$B$1) -> 0 | I13: =_xll.EQNXTDZ($A$1,$B13,I$1,$B$1) -> 0 | J13: =_xll.EQNXTDZ($A$1,$B13,J$1,$B$1) -> 0 | ... BV13: =_xll.EQNXTDZ($A$1,$B13,BV$1,$B$1) -> 0
A14: Operating & Manufacturing Expenses | B14: QTR_MFG_EXPS | C14: =_xll.EQNXTDZ($A$1,$B14,C$1,$B$1) -> 224.58 | D14: =_xll.EQNXTDZ($A$1,$B14,D$1,$B$1) -> 278.76 | E14: =_xll.EQNXTDZ($A$1,$B14,E$1,$B$1) -> 240.94 | F14: =_xll.EQNXTDZ($A$1,$B14,F$1,$B$1) -> 188.49 | G14: =_xll.EQNXTDZ($A$1,$B14,G$1,$B$1) -> 208.47 | H14: =_xll.EQNXTDZ($A$1,$B14,H$1,$B$1) -> 234.04 | I14: =_xll.EQNXTDZ($A$1,$B14,I$1,$B$1) -> 357.96 | J14: =_xll.EQNXTDZ($A$1,$B14,J$1,$B$1) -> 406.77 | ... BV14: =_xll.EQNXTDZ($A$1,$B14,BV$1,$B$1) -> 0
A15: Electricity Power & Fuel Cost | B15: QTR_ELECTRICITY_POWER_FUEL | C15: =_xll.EQNXTDZ($A$1,$B15,C$1,$B$1) -> 0 | D15: =_xll.EQNXTDZ($A$1,$B15,D$1,$B$1) -> 0 | E15: =_xll.EQNXTDZ($A$1,$B15,E$1,$B$1) -> 0 | F15: =_xll.EQNXTDZ($A$1,$B15,F$1,$B$1) -> 0 | G15: =_xll.EQNXTDZ($A$1,$B15,G$1,$B$1) -> 0 | H15: =_xll.EQNXTDZ($A$1,$B15,H$1,$B$1) -> 0 | I15: =_xll.EQNXTDZ($A$1,$B15,I$1,$B$1) -> 0 | J15: =_xll.EQNXTDZ($A$1,$B15,J$1,$B$1) -> 0 | ... BV15: =_xll.EQNXTDZ($A$1,$B15,BV$1,$B$1) -> 0
A16: Employee Cost | B16: QTR_EXPLOYEE_COST | C16: =_xll.EQNXTDZ($A$1,$B16,C$1,$B$1) -> 61.88 | D16: =_xll.EQNXTDZ($A$1,$B16,D$1,$B$1) -> 62.85 | E16: =_xll.EQNXTDZ($A$1,$B16,E$1,$B$1) -> 64.17 | F16: =_xll.EQNXTDZ($A$1,$B16,F$1,$B$1) -> 63.36 | G16: =_xll.EQNXTDZ($A$1,$B16,G$1,$B$1) -> 68.02 | H16: =_xll.EQNXTDZ($A$1,$B16,H$1,$B$1) -> 76.7 | I16: =_xll.EQNXTDZ($A$1,$B16,I$1,$B$1) -> 78.73 | J16: =_xll.EQNXTDZ($A$1,$B16,J$1,$B$1) -> 76.75 | ... BV16: =_xll.EQNXTDZ($A$1,$B16,BV$1,$B$1) -> 0
... A42: Consolidated PAT(after extra items) | B42: QTR_CONS_PAT_EXITM | C42: =_xll.EQNXTDZ($A$1,$B42,C$1,$B$1) -> 35.19 | D42: =_xll.EQNXTDZ($A$1,$B42,D$1,$B$1) -> 61.11 | E42: =_xll.EQNXTDZ($A$1,$B42,E$1,$B$1) -> 60.03 | F42: =_xll.EQNXTDZ($A$1,$B42,F$1,$B$1) -> 37.08 | G42: =_xll.EQNXTDZ($A$1,$B42,G$1,$B$1) -> 15.21 | H42: =_xll.EQNXTDZ($A$1,$B42,H$1,$B$1) -> 21.96 | I42: =_xll.EQNXTDZ($A$1,$B42,I$1,$B$1) -> 50.04 | J42: =_xll.EQNXTDZ($A$1,$B42,J$1,$B$1) -> 57.06 | ... BV42: =_xll.EQNXTDZ($A$1,$B42,BV$1,$B$1) -> 0
A44: Field Description | B44: Field Name
A45: Equity Capital | B45: QTR_EQUITY_CAP | C45: =_xll.EQNXTDZ($A$1,$B45,C$1,$B$1) -> 55.25 | D45: =_xll.EQNXTDZ($A$1,$B45,D$1,$B$1) -> 55.25 | E45: =_xll.EQNXTDZ($A$1,$B45,E$1,$B$1) -> 55.25 | F45: =_xll.EQNXTDZ($A$1,$B45,F$1,$B$1) -> 55.25 | G45: =_xll.EQNXTDZ($A$1,$B45,G$1,$B$1) -> 55.25 | H45: =_xll.EQNXTDZ($A$1,$B45,H$1,$B$1) -> 55.25 | I45: =_xll.EQNXTDZ($A$1,$B45,I$1,$B$1) -> 55.25 | J45: =_xll.EQNXTDZ($A$1,$B45,J$1,$B$1) -> 55.25 | ... BV45: =_xll.EQNXTDZ($A$1,$B45,BV$1,$B$1) -> 0
A46: Face Value | B46: QTR_FV | C46: =_xll.EQNXTDZ($A$1,$B46,C$1,$B$1) -> 2 | D46: =_xll.EQNXTDZ($A$1,$B46,D$1,$B$1) -> 2 | E46: =_xll.EQNXTDZ($A$1,$B46,E$1,$B$1) -> 2 | F46: =_xll.EQNXTDZ($A$1,$B46,F$1,$B$1) -> 2 | G46: =_xll.EQNXTDZ($A$1,$B46,G$1,$B$1) -> 2 | H46: =_xll.EQNXTDZ($A$1,$B46,H$1,$B$1) -> 2 | I46: =_xll.EQNXTDZ($A$1,$B46,I$1,$B$1) -> 2 | J46: =_xll.EQNXTDZ($A$1,$B46,J$1,$B$1) -> 2 | ... BV46: =_xll.EQNXTDZ($A$1,$B46,BV$1,$B$1) -> 0
A47: Month End | B47: BMONTH_MONTHEND | C47: =_xll.EQNXTDZ($A$1,$B47,C$5) -> 201206 | D47: =_xll.EQNXTDZ($A$1,$B47,D$5) -> 201209 | E47: =_xll.EQNXTDZ($A$1,$B47,E$5) -> 201212 | F47: =_xll.EQNXTDZ($A$1,$B47,F$5) -> 201303 | G47: =_xll.EQNXTDZ($A$1,$B47,G$5) -> 201306 | H47: =_xll.EQNXTDZ($A$1,$B47,H$5) -> 201309 | I47: =_xll.EQNXTDZ($A$1,$B47,I$5) -> 201312 | J47: =_xll.EQNXTDZ($A$1,$B47,J$5) -> 201403 | ... BV47: =_xll.EQNXTDZ($A$1,$B47,BV$5) -> 0
A48: Close | B48: BMONTH_CLOSE | C48: =_xll.EQNXTDZ($A$1,$B48,C$5) -> 66.175 | D48: =_xll.EQNXTDZ($A$1,$B48,D$5) -> 59.25 | E48: =_xll.EQNXTDZ($A$1,$B48,E$5) -> 64.3 | F48: =_xll.EQNXTDZ($A$1,$B48,F$5) -> 41.05 | G48: =_xll.EQNXTDZ($A$1,$B48,G$5) -> 28.65 | H48: =_xll.EQNXTDZ($A$1,$B48,H$5) -> 22.175 | I48: =_xll.EQNXTDZ($A$1,$B48,I$5) -> 24.525 | J48: =_xll.EQNXTDZ($A$1,$B48,J$5) -> 28.3 | ... BV48: =_xll.EQNXTDZ($A$1,$B48,BV$5) -> 0
A49: Total of Promoter and Promoter Group | B49: SHP_TPFTOTALPROMOTER | C49: =_xll.EQNXTDZ($A$1,$B49,C$5) -> 46 | D49: =_xll.EQNXTDZ($A$1,$B49,D$5) -> 45.99 | E49: =_xll.EQNXTDZ($A$1,$B49,E$5) -> 46 | F49: =_xll.EQNXTDZ($A$1,$B49,F$5) -> 46 | G49: =_xll.EQNXTDZ($A$1,$B49,G$5) -> 46 | H49: =_xll.EQNXTDZ($A$1,$B49,H$5) -> 46.27 | I49: =_xll.EQNXTDZ($A$1,$B49,I$5) -> 46.27 | J49: =_xll.EQNXTDZ($A$1,$B49,J$5) -> 46.27 | ... BV49: =_xll.EQNXTDZ($A$1,$B49,BV$5) -> 0
A50: Total of Promoter and Promoter Group Pledged | B50: SHP_PSHFTOTALPROMOTER | C50: =_xll.EQNXTDZ($A$1,$B50,C$5) -> 0 | D50: =_xll.EQNXTDZ($A$1,$B50,D$5) -> 0 | E50: =_xll.EQNXTDZ($A$1,$B50,E$5) -> 0 | F50: =_xll.EQNXTDZ($A$1,$B50,F$5) -> 0 | G50: =_xll.EQNXTDZ($A$1,$B50,G$5) -> 0 | H50: =_xll.EQNXTDZ($A$1,$B50,H$5) -> 0 | I50: =_xll.EQNXTDZ($A$1,$B50,I$5) -> 0 | J50: =_xll.EQNXTDZ($A$1,$B50,J$5) -> 0 | ... BV50: =_xll.EQNXTDZ($A$1,$B50,BV$5) -> 0
A54: Field Description | B54: Field Name | C54: =_xll.EQNXTDZ($A$1,$B54,C$5) -> 0 | D54: =_xll.EQNXTDZ($A$1,$B54,D$5) -> 0 | E54: =_xll.EQNXTDZ($A$1,$B54,E$5) -> 0 | F54: =_xll.EQNXTDZ($A$1,$B54,F$5) -> 0 | G54: =_xll.EQNXTDZ($A$1,$B54,G$5) -> 0 | H54: =_xll.EQNXTDZ($A$1,$B54,H$5) -> 0 | I54: =_xll.EQNXTDZ($A$1,$B54,I$5) -> 0 | J54: =_xll.EQNXTDZ($A$1,$B54,J$5) -> 0 | ... BV54: =_xll.EQNXTDZ($A$1,$B54,BV$5) -> 0
A55: Year End | B55: QTRB_DATE_END | C55: =_xll.EQNXTDZ($A$1,$B55,C$5,$B$1) -> 0 | D55: =_xll.EQNXTDZ($A$1,$B55,D$5,$B$1) -> 201209 | E55: =_xll.EQNXTDZ($A$1,$B55,E$5,$B$1) -> 0 | F55: =_xll.EQNXTDZ($A$1,$B55,F$5,$B$1) -> 201303 | G55: =_xll.EQNXTDZ($A$1,$B55,G$5,$B$1) -> 0 | H55: =_xll.EQNXTDZ($A$1,$B55,H$5,$B$1) -> 201309 | I55: =_xll.EQNXTDZ($A$1,$B55,I$5,$B$1) -> 0 | J55: =_xll.EQNXTDZ($A$1,$B55,J$5,$B$1) -> 201403 | ... BV55: =_xll.EQNXTDZ($A$1,$B55,BV$5,$B$1) -> 0
A56: Share Capital | B56: QTRB_SHARE_CAPITAL | C56: =_xll.EQNXTDZ($A$1,$B56,C$5,$B$1) -> 0 | D56: =_xll.EQNXTDZ($A$1,$B56,D$5,$B$1) -> 55.25 | E56: =_xll.EQNXTDZ($A$1,$B56,E$5,$B$1) -> 0 | F56: =_xll.EQNXTDZ($A$1,$B56,F$5,$B$1) -> 55.25 | G56: =_xll.EQNXTDZ($A$1,$B56,G$5,$B$1) -> 0 | H56: =_xll.EQNXTDZ($A$1,$B56,H$5,$B$1) -> 55.25 | I56: =_xll.EQNXTDZ($A$1,$B56,I$5,$B$1) -> 0 | J56: =_xll.EQNXTDZ($A$1,$B56,J$5,$B$1) -> 55.25 | ... BV56: =_xll.EQNXTDZ($A$1,$B56,BV$5,$B$1) -> 0
A57: Share Warrants & outstandings | B57: QTRB_SHAREWARNDOUT | C57: =_xll.EQNXTDZ($A$1,$B57,C$5,$B$1) -> 0 | D57: =_xll.EQNXTDZ($A$1,$B57,D$5,$B$1) -> 0 | E57: =_xll.EQNXTDZ($A$1,$B57,E$5,$B$1) -> 0 | F57: =_xll.EQNXTDZ($A$1,$B57,F$5,$B$1) -> 0 | G57: =_xll.EQNXTDZ($A$1,$B57,G$5,$B$1) -> 0 | H57: =_xll.EQNXTDZ($A$1,$B57,H$5,$B$1) -> 0 | I57: =_xll.EQNXTDZ($A$1,$B57,I$5,$B$1) -> 0 | J57: =_xll.EQNXTDZ($A$1,$B57,J$5,$B$1) -> 0 | ... BV57: =_xll.EQNXTDZ($A$1,$B57,BV$5,$B$1) -> 0
A58: Reserves & Surplus | B58: QTRB_RESERVE | C58: =_xll.EQNXTDZ($A$1,$B58,C$5,$B$1) -> 0 | D58: =_xll.EQNXTDZ($A$1,$B58,D$5,$B$1) -> 3602.35 | E58: =_xll.EQNXTDZ($A$1,$B58,E$5,$B$1) -> 0 | F58: =_xll.EQNXTDZ($A$1,$B58,F$5,$B$1) -> 3612.24 | G58: =_xll.EQNXTDZ($A$1,$B58,G$5,$B$1) -> 0 | H58: =_xll.EQNXTDZ($A$1,$B58,H$5,$B$1) -> 3710.27 | I58: =_xll.EQNXTDZ($A$1,$B58,I$5,$B$1) -> 0 | J58: =_xll.EQNXTDZ($A$1,$B58,J$5,$B$1) -> 3513.13 | ... BV58: =_xll.EQNXTDZ($A$1,$B58,BV$5,$B$1) -> 0
A59: Shareholder's Funds | B59: QTRB_SHAREHODERS_FUNDS | C59: =_xll.EQNXTDZ($A$1,$B59,C$5,$B$1) -> 0 | D59: =_xll.EQNXTDZ($A$1,$B59,D$5,$B$1) -> 3657.6 | E59: =_xll.EQNXTDZ($A$1,$B59,E$5,$B$1) -> 0 | F59: =_xll.EQNXTDZ($A$1,$B59,F$5,$B$1) -> 3667.49 | G59: =_xll.EQNXTDZ($A$1,$B59,G$5,$B$1) -> 0 | H59: =_xll.EQNXTDZ($A$1,$B59,H$5,$B$1) -> 3765.52 | I59: =_xll.EQNXTDZ($A$1,$B59,I$5,$B$1) -> 0 | J59: =_xll.EQNXTDZ($A$1,$B59,J$5,$B$1) -> 3568.38 | ... BV59: =_xll.EQNXTDZ($A$1,$B59,BV$5,$B$1) -> 0
A60: Minority Interest | B60: QTRB_MINORITY_INTEREST_BS | C60: =_xll.EQNXTDZ($A$1,$B60,C$5,$B$1) -> 0 | D60: =_xll.EQNXTDZ($A$1,$B60,D$5,$B$1) -> 0 | E60: =_xll.EQNXTDZ($A$1,$B60,E$5,$B$1) -> 0 | F60: =_xll.EQNXTDZ($A$1,$B60,F$5,$B$1) -> 197.98 | G60: =_xll.EQNXTDZ($A$1,$B60,G$5,$B$1) -> 0 | H60: =_xll.EQNXTDZ($A$1,$B60,H$5,$B$1) -> 0 | I60: =_xll.EQNXTDZ($A$1,$B60,I$5,$B$1) -> 0 | J60: =_xll.EQNXTDZ($A$1,$B60,J$5,$B$1) -> 157.83 | ... BV60: =_xll.EQNXTDZ($A$1,$B60,BV$5,$B$1) -> 0
A61: Long Term Borrowings | B61: QTRB_TOTAL_DEBTS | C61: =_xll.EQNXTDZ($A$1,$B61,C$5,$B$1) -> 0 | D61: =_xll.EQNXTDZ($A$1,$B61,D$5,$B$1) -> 1166.93 | E61: =_xll.EQNXTDZ($A$1,$B61,E$5,$B$1) -> 0 | F61: =_xll.EQNXTDZ($A$1,$B61,F$5,$B$1) -> 2843.79 | G61: =_xll.EQNXTDZ($A$1,$B61,G$5,$B$1) -> 0 | H61: =_xll.EQNXTDZ($A$1,$B61,H$5,$B$1) -> 1612.35 | I61: =_xll.EQNXTDZ($A$1,$B61,I$5,$B$1) -> 0 | J61: =_xll.EQNXTDZ($A$1,$B61,J$5,$B$1) -> 3492.7 | ... BV61: =_xll.EQNXTDZ($A$1,$B61,BV$5,$B$1) -> 0
A62: Secured Loans | B62: QTRB_SECURED_LOANS | C62: =_xll.EQNXTDZ($A$1,$B62,C$5,$B$1) -> 0 | D62: =_xll.EQNXTDZ($A$1,$B62,D$5,$B$1) -> 0 | E62: =_xll.EQNXTDZ($A$1,$B62,E$5,$B$1) -> 0 | F62: =_xll.EQNXTDZ($A$1,$B62,F$5,$B$1) -> 0 | G62: =_xll.EQNXTDZ($A$1,$B62,G$5,$B$1) -> 0 | H62: =_xll.EQNXTDZ($A$1,$B62,H$5,$B$1) -> 0 | I62: =_xll.EQNXTDZ($A$1,$B62,I$5,$B$1) -> 0 | J62: =_xll.EQNXTDZ($A$1,$B62,J$5,$B$1) -> 0 | ... BV62: =_xll.EQNXTDZ($A$1,$B62,BV$5,$B$1) -> 0
A63: Unsecured Loans | B63: QTRB_UNSECURED_LOANS_NF | C63: =_xll.EQNXTDZ($A$1,$B63,C$5,$B$1) -> 0 | D63: =_xll.EQNXTDZ($A$1,$B63,D$5,$B$1) -> 1166.93 | E63: =_xll.EQNXTDZ($A$1,$B63,E$5,$B$1) -> 0 | F63: =_xll.EQNXTDZ($A$1,$B63,F$5,$B$1) -> 2843.79 | G63: =_xll.EQNXTDZ($A$1,$B63,G$5,$B$1) -> 0 | H63: =_xll.EQNXTDZ($A$1,$B63,H$5,$B$1) -> 1612.35 | I63: =_xll.EQNXTDZ($A$1,$B63,I$5,$B$1) -> 0 | J63: =_xll.EQNXTDZ($A$1,$B63,J$5,$B$1) -> 3492.7 | ... BV63: =_xll.EQNXTDZ($A$1,$B63,BV$5,$B$1) -> 0
A64: Other Long Term Liabilities | B64: QTRB_OTHER_LT_LIABILITIES | C64: =_xll.EQNXTDZ($A$1,$B64,C$5,$B$1) -> 0 | D64: =_xll.EQNXTDZ($A$1,$B64,D$5,$B$1) -> 0.08 | E64: =_xll.EQNXTDZ($A$1,$B64,E$5,$B$1) -> 0 | F64: =_xll.EQNXTDZ($A$1,$B64,F$5,$B$1) -> 101.96 | G64: =_xll.EQNXTDZ($A$1,$B64,G$5,$B$1) -> 0 | H64: =_xll.EQNXTDZ($A$1,$B64,H$5,$B$1) -> 0 | I64: =_xll.EQNXTDZ($A$1,$B64,I$5,$B$1) -> 0 | J64: =_xll.EQNXTDZ($A$1,$B64,J$5,$B$1) -> 187.99 | ... BV64: =_xll.EQNXTDZ($A$1,$B64,BV$5,$B$1) -> 0
A65: Long Term Trade Payables | B65: QTRB_LT_TRADE_PAYABLE | C65: =_xll.EQNXTDZ($A$1,$B65,C$5,$B$1) -> 0 | D65: =_xll.EQNXTDZ($A$1,$B65,D$5,$B$1) -> 0 | E65: =_xll.EQNXTDZ($A$1,$B65,E$5,$B$1) -> 0 | F65: =_xll.EQNXTDZ($A$1,$B65,F$5,$B$1) -> 0 | G65: =_xll.EQNXTDZ($A$1,$B65,G$5,$B$1) -> 0 | H65: =_xll.EQNXTDZ($A$1,$B65,H$5,$B$1) -> 0 | I65: =_xll.EQNXTDZ($A$1,$B65,I$5,$B$1) -> 0 | J65: =_xll.EQNXTDZ($A$1,$B65,J$5,$B$1) -> 0 | ... BV65: =_xll.EQNXTDZ($A$1,$B65,BV$5,$B$1) -> 0
A66: Lont Term Provisions | B66: QTRB_LT_PROVISIONS | C66: =_xll.EQNXTDZ($A$1,$B66,C$5,$B$1) -> 0 | D66: =_xll.EQNXTDZ($A$1,$B66,D$5,$B$1) -> 28.88 | E66: =_xll.EQNXTDZ($A$1,$B66,E$5,$B$1) -> 0 | F66: =_xll.EQNXTDZ($A$1,$B66,F$5,$B$1) -> 34.48 | G66: =_xll.EQNXTDZ($A$1,$B66,G$5,$B$1) -> 0 | H66: =_xll.EQNXTDZ($A$1,$B66,H$5,$B$1) -> 29.87 | I66: =_xll.EQNXTDZ($A$1,$B66,I$5,$B$1) -> 0 | J66: =_xll.EQNXTDZ($A$1,$B66,J$5,$B$1) -> 36.63 | ... BV66: =_xll.EQNXTDZ($A$1,$B66,BV$5,$B$1) -> 0
... A97: Total Assets | B97: QTRB_TOTAL_APPLICATIONS | C97: =_xll.EQNXTDZ($A$1,$B97,C$5,$B$1) -> 0 | D97: =_xll.EQNXTDZ($A$1,$B97,D$5,$B$1) -> 4853.49 | E97: =_xll.EQNXTDZ($A$1,$B97,E$5,$B$1) -> 0 | F97: =_xll.EQNXTDZ($A$1,$B97,F$5,$B$1) -> 6845.7 | G97: =_xll.EQNXTDZ($A$1,$B97,G$5,$B$1) -> 0 | H97: =_xll.EQNXTDZ($A$1,$B97,H$5,$B$1) -> 5407.74 | I97: =_xll.EQNXTDZ($A$1,$B97,I$5,$B$1) -> 0 | J97: =_xll.EQNXTDZ($A$1,$B97,J$5,$B$1) -> 7443.53 | ... BV97: =_xll.EQNXTDZ($A$1,$B97,BV$5,$B$1) -> 0

Sheet Annual Raw
A1: 100378 | B1: X | C1: 200103 | D1: 200203 | E1: 200303 | F1: 200403 | G1: 200503 | H1: 200603 | I1: 200703 | J1: 200803 | K1: 200903 | L1: 201003 | M1: 201103 | N1: 201203 | O1: 201303 | P1: 201403 | Q1: 201503 | R1: 201603 | S1: 201703 | T1: 201803 | U1: 201903 | V1: 202003 | W1: 202103 | X1: 202203 | Y1: 202303 | Z1: 202403 | AA1: 202503 | AB1: 202603 | AC1: 202703 | AD1: 202803 | AE1: 202903 | AF1: 203003
A3: Field Description | B3: Field Name
A4: Company Name | B4: CD_COMPNAME | C4: =_xll.EQNXTDZ(A1,B4,"L") -> Jindal Saw Ltd.
A5: Year End | B5: PL_YEAR_END | C5: =_xll.EQNXTDZ($A$1,$B5,C$1,$B$1) -> 0 | D5: =_xll.EQNXTDZ($A$1,$B5,D$1,$B$1) -> 0 | E5: =_xll.EQNXTDZ($A$1,$B5,E$1,$B$1) -> 0 | F5: =_xll.EQNXTDZ($A$1,$B5,F$1,$B$1) -> 0 | G5: =_xll.EQNXTDZ($A$1,$B5,G$1,$B$1) -> 0 | H5: =_xll.EQNXTDZ($A$1,$B5,H$1,$B$1) -> 0 | I5: =_xll.EQNXTDZ($A$1,$B5,I$1,$B$1) -> 0 | J5: =_xll.EQNXTDZ($A$1,$B5,J$1,$B$1) -> 0 | ... AF5: =_xll.EQNXTDZ($A$1,$B5,AF$1,$B$1) -> 0
A6: Sales Turnover | B6: PL_TOTAL_GROSS_SALES | C6: =_xll.EQNXTDZ($A$1,$B6,C$1,$B$1) -> 0 | D6: =_xll.EQNXTDZ($A$1,$B6,D$1,$B$1) -> 0 | E6: =_xll.EQNXTDZ($A$1,$B6,E$1,$B$1) -> 0 | F6: =_xll.EQNXTDZ($A$1,$B6,F$1,$B$1) -> 0 | G6: =_xll.EQNXTDZ($A$1,$B6,G$1,$B$1) -> 0 | H6: =_xll.EQNXTDZ($A$1,$B6,H$1,$B$1) -> 0 | I6: =_xll.EQNXTDZ($A$1,$B6,I$1,$B$1) -> 0 | J6: =_xll.EQNXTDZ($A$1,$B6,J$1,$B$1) -> 0 | ... AF6: =_xll.EQNXTDZ($A$1,$B6,AF$1,$B$1) -> 0
A7: Less: Inter divisional transfers | B7: PL_INTER_DIV_TRF | C7: =_xll.EQNXTDZ($A$1,$B7,C$1,$B$1) -> 0 | D7: =_xll.EQNXTDZ($A$1,$B7,D$1,$B$1) -> 0 | E7: =_xll.EQNXTDZ($A$1,$B7,E$1,$B$1) -> 0 | F7: =_xll.EQNXTDZ($A$1,$B7,F$1,$B$1) -> 0 | G7: =_xll.EQNXTDZ($A$1,$B7,G$1,$B$1) -> 0 | H7: =_xll.EQNXTDZ($A$1,$B7,H$1,$B$1) -> 0 | I7: =_xll.EQNXTDZ($A$1,$B7,I$1,$B$1) -> 0 | J7: =_xll.EQNXTDZ($A$1,$B7,J$1,$B$1) -> 0 | ... AF7: =_xll.EQNXTDZ($A$1,$B7,AF$1,$B$1) -> 0
A8: Less: Sales Returns | B8: PL_SALES_RETURN | C8: =_xll.EQNXTDZ($A$1,$B8,C$1,$B$1) -> 0 | D8: =_xll.EQNXTDZ($A$1,$B8,D$1,$B$1) -> 0 | E8: =_xll.EQNXTDZ($A$1,$B8,E$1,$B$1) -> 0 | F8: =_xll.EQNXTDZ($A$1,$B8,F$1,$B$1) -> 0 | G8: =_xll.EQNXTDZ($A$1,$B8,G$1,$B$1) -> 0 | H8: =_xll.EQNXTDZ($A$1,$B8,H$1,$B$1) -> 0 | I8: =_xll.EQNXTDZ($A$1,$B8,I$1,$B$1) -> 0 | J8: =_xll.EQNXTDZ($A$1,$B8,J$1,$B$1) -> 0 | ... AF8: =_xll.EQNXTDZ($A$1,$B8,AF$1,$B$1) -> 0
A9: Less: Excise | B9: PL_EXCISE | C9: =_xll.EQNXTDZ($A$1,$B9,C$1,$B$1) -> 0 | D9: =_xll.EQNXTDZ($A$1,$B9,D$1,$B$1) -> 0 | E9: =_xll.EQNXTDZ($A$1,$B9,E$1,$B$1) -> 0 | F9: =_xll.EQNXTDZ($A$1,$B9,F$1,$B$1) -> 0 | G9: =_xll.EQNXTDZ($A$1,$B9,G$1,$B$1) -> 0 | H9: =_xll.EQNXTDZ($A$1,$B9,H$1,$B$1) -> 0 | I9: =_xll.EQNXTDZ($A$1,$B9,I$1,$B$1) -> 0 | J9: =_xll.EQNXTDZ($A$1,$B9,J$1,$B$1) -> 0 | ... AF9: =_xll.EQNXTDZ($A$1,$B9,AF$1,$B$1) -> 0
A10: Net Sales | B10: PL_NET_SALES | C10: =_xll.EQNXTDZ($A$1,$B10,C$1,$B$1) -> 0 | D10: =_xll.EQNXTDZ($A$1,$B10,D$1,$B$1) -> 0 | E10: =_xll.EQNXTDZ($A$1,$B10,E$1,$B$1) -> 0 | F10: =_xll.EQNXTDZ($A$1,$B10,F$1,$B$1) -> 0 | G10: =_xll.EQNXTDZ($A$1,$B10,G$1,$B$1) -> 0 | H10: =_xll.EQNXTDZ($A$1,$B10,H$1,$B$1) -> 0 | I10: =_xll.EQNXTDZ($A$1,$B10,I$1,$B$1) -> 0 | J10: =_xll.EQNXTDZ($A$1,$B10,J$1,$B$1) -> 0 | ... AF10: =_xll.EQNXTDZ($A$1,$B10,AF$1,$B$1) -> 0
A11: Increase/Decrease in Stock | B11: PL_INC_DEC_INVENTORY | C11: =_xll.EQNXTDZ($A$1,$B11,C$1,$B$1) -> 0 | D11: =_xll.EQNXTDZ($A$1,$B11,D$1,$B$1) -> 0 | E11: =_xll.EQNXTDZ($A$1,$B11,E$1,$B$1) -> 0 | F11: =_xll.EQNXTDZ($A$1,$B11,F$1,$B$1) -> 0 | G11: =_xll.EQNXTDZ($A$1,$B11,G$1,$B$1) -> 0 | H11: =_xll.EQNXTDZ($A$1,$B11,H$1,$B$1) -> 0 | I11: =_xll.EQNXTDZ($A$1,$B11,I$1,$B$1) -> 0 | J11: =_xll.EQNXTDZ($A$1,$B11,J$1,$B$1) -> 0 | ... AF11: =_xll.EQNXTDZ($A$1,$B11,AF$1,$B$1) -> 0
A12: Raw Material Consumed | B12: PL_RAW_MATRS_CONSUMED | C12: =_xll.EQNXTDZ($A$1,$B12,C$1,$B$1) -> 0 | D12: =_xll.EQNXTDZ($A$1,$B12,D$1,$B$1) -> 0 | E12: =_xll.EQNXTDZ($A$1,$B12,E$1,$B$1) -> 0 | F12: =_xll.EQNXTDZ($A$1,$B12,F$1,$B$1) -> 0 | G12: =_xll.EQNXTDZ($A$1,$B12,G$1,$B$1) -> 0 | H12: =_xll.EQNXTDZ($A$1,$B12,H$1,$B$1) -> 0 | I12: =_xll.EQNXTDZ($A$1,$B12,I$1,$B$1) -> 0 | J12: =_xll.EQNXTDZ($A$1,$B12,J$1,$B$1) -> 0 | ... AF12: =_xll.EQNXTDZ($A$1,$B12,AF$1,$B$1) -> 0
A13: Power & Fuel Cost | B13: PL_POWER_FUEL | C13: =_xll.EQNXTDZ($A$1,$B13,C$1,$B$1) -> 0 | D13: =_xll.EQNXTDZ($A$1,$B13,D$1,$B$1) -> 0 | E13: =_xll.EQNXTDZ($A$1,$B13,E$1,$B$1) -> 0 | F13: =_xll.EQNXTDZ($A$1,$B13,F$1,$B$1) -> 0 | G13: =_xll.EQNXTDZ($A$1,$B13,G$1,$B$1) -> 0 | H13: =_xll.EQNXTDZ($A$1,$B13,H$1,$B$1) -> 0 | I13: =_xll.EQNXTDZ($A$1,$B13,I$1,$B$1) -> 0 | J13: =_xll.EQNXTDZ($A$1,$B13,J$1,$B$1) -> 0 | ... AF13: =_xll.EQNXTDZ($A$1,$B13,AF$1,$B$1) -> 0
A14: Employee Cost | B14: PL_EMPLOYEES | C14: =_xll.EQNXTDZ($A$1,$B14,C$1,$B$1) -> 0 | D14: =_xll.EQNXTDZ($A$1,$B14,D$1,$B$1) -> 0 | E14: =_xll.EQNXTDZ($A$1,$B14,E$1,$B$1) -> 0 | F14: =_xll.EQNXTDZ($A$1,$B14,F$1,$B$1) -> 0 | G14: =_xll.EQNXTDZ($A$1,$B14,G$1,$B$1) -> 0 | H14: =_xll.EQNXTDZ($A$1,$B14,H$1,$B$1) -> 0 | I14: =_xll.EQNXTDZ($A$1,$B14,I$1,$B$1) -> 0 | J14: =_xll.EQNXTDZ($A$1,$B14,J$1,$B$1) -> 0 | ... AF14: =_xll.EQNXTDZ($A$1,$B14,AF$1,$B$1) -> 0
A15: Operating & Manufacturing Expenses | B15: PL_GEN_OTHER_MFG_EXPS | C15: =_xll.EQNXTDZ($A$1,$B15,C$1,$B$1) -> 0 | D15: =_xll.EQNXTDZ($A$1,$B15,D$1,$B$1) -> 0 | E15: =_xll.EQNXTDZ($A$1,$B15,E$1,$B$1) -> 0 | F15: =_xll.EQNXTDZ($A$1,$B15,F$1,$B$1) -> 0 | G15: =_xll.EQNXTDZ($A$1,$B15,G$1,$B$1) -> 0 | H15: =_xll.EQNXTDZ($A$1,$B15,H$1,$B$1) -> 0 | I15: =_xll.EQNXTDZ($A$1,$B15,I$1,$B$1) -> 0 | J15: =_xll.EQNXTDZ($A$1,$B15,J$1,$B$1) -> 0 | ... AF15: =_xll.EQNXTDZ($A$1,$B15,AF$1,$B$1) -> 0
A16: Cost of Software development | B16: PL_COST_SW | C16: =_xll.EQNXTDZ($A$1,$B16,C$1,$B$1) -> 0 | D16: =_xll.EQNXTDZ($A$1,$B16,D$1,$B$1) -> 0 | E16: =_xll.EQNXTDZ($A$1,$B16,E$1,$B$1) -> 0 | F16: =_xll.EQNXTDZ($A$1,$B16,F$1,$B$1) -> 0 | G16: =_xll.EQNXTDZ($A$1,$B16,G$1,$B$1) -> 0 | H16: =_xll.EQNXTDZ($A$1,$B16,H$1,$B$1) -> 0 | I16: =_xll.EQNXTDZ($A$1,$B16,I$1,$B$1) -> 0 | J16: =_xll.EQNXTDZ($A$1,$B16,J$1,$B$1) -> 0 | ... AF16: =_xll.EQNXTDZ($A$1,$B16,AF$1,$B$1) -> 0
... A36: Profit After Tax from Discontinued Operations | B36: PL_PAT_DIS_OP | C36: =_xll.EQNXTDZ($A$1,$B36,C$1,$B$1) -> 0 | D36: =_xll.EQNXTDZ($A$1,$B36,D$1,$B$1) -> 0 | E36: =_xll.EQNXTDZ($A$1,$B36,E$1,$B$1) -> 0 | F36: =_xll.EQNXTDZ($A$1,$B36,F$1,$B$1) -> 0 | G36: =_xll.EQNXTDZ($A$1,$B36,G$1,$B$1) -> 0 | H36: =_xll.EQNXTDZ($A$1,$B36,H$1,$B$1) -> 0 | I36: =_xll.EQNXTDZ($A$1,$B36,I$1,$B$1) -> 0 | J36: =_xll.EQNXTDZ($A$1,$B36,J$1,$B$1) -> 0 | ... AF36: =_xll.EQNXTDZ($A$1,$B36,AF$1,$B$1) -> 0
A39: Field Description | B39: Field Name
A40: Year End | B40: BS_YEAR_END | C40: =_xll.EQNXTDZ($A$1,$B40,C$1,$B$1) -> 0 | D40: =_xll.EQNXTDZ($A$1,$B40,D$1,$B$1) -> 0 | E40: =_xll.EQNXTDZ($A$1,$B40,E$1,$B$1) -> 0 | F40: =_xll.EQNXTDZ($A$1,$B40,F$1,$B$1) -> 0 | G40: =_xll.EQNXTDZ($A$1,$B40,G$1,$B$1) -> 0 | H40: =_xll.EQNXTDZ($A$1,$B40,H$1,$B$1) -> 0 | I40: =_xll.EQNXTDZ($A$1,$B40,I$1,$B$1) -> 0 | J40: =_xll.EQNXTDZ($A$1,$B40,J$1,$B$1) -> 0 | ... AF40: =_xll.EQNXTDZ($A$1,$B40,AF$1,$B$1) -> 0
A41: Share Capital | B41: BS_SHARE_CAPITAL | C41: =_xll.EQNXTDZ($A$1,$B41,C$1,$B$1) -> 0 | D41: =_xll.EQNXTDZ($A$1,$B41,D$1,$B$1) -> 0 | E41: =_xll.EQNXTDZ($A$1,$B41,E$1,$B$1) -> 0 | F41: =_xll.EQNXTDZ($A$1,$B41,F$1,$B$1) -> 0 | G41: =_xll.EQNXTDZ($A$1,$B41,G$1,$B$1) -> 0 | H41: =_xll.EQNXTDZ($A$1,$B41,H$1,$B$1) -> 0 | I41: =_xll.EQNXTDZ($A$1,$B41,I$1,$B$1) -> 0 | J41: =_xll.EQNXTDZ($A$1,$B41,J$1,$B$1) -> 0 | ... AF41: =_xll.EQNXTDZ($A$1,$B41,AF$1,$B$1) -> 0
A42: Share Warrants & Outstandings | B42: BS_SHAREWROUTST | C42: =_xll.EQNXTDZ($A$1,$B42,C$1,$B$1) -> 0 | D42: =_xll.EQNXTDZ($A$1,$B42,D$1,$B$1) -> 0 | E42: =_xll.EQNXTDZ($A$1,$B42,E$1,$B$1) -> 0 | F42: =_xll.EQNXTDZ($A$1,$B42,F$1,$B$1) -> 0 | G42: =_xll.EQNXTDZ($A$1,$B42,G$1,$B$1) -> 0 | H42: =_xll.EQNXTDZ($A$1,$B42,H$1,$B$1) -> 0 | I42: =_xll.EQNXTDZ($A$1,$B42,I$1,$B$1) -> 0 | J42: =_xll.EQNXTDZ($A$1,$B42,J$1,$B$1) -> 0 | ... AF42: =_xll.EQNXTDZ($A$1,$B42,AF$1,$B$1) -> 0
A43: Total Reserves | B43: BS_RESERVE | C43: =_xll.EQNXTDZ($A$1,$B43,C$1,$B$1) -> 0 | D43: =_xll.EQNXTDZ($A$1,$B43,D$1,$B$1) -> 0 | E43: =_xll.EQNXTDZ($A$1,$B43,E$1,$B$1) -> 0 | F43: =_xll.EQNXTDZ($A$1,$B43,F$1,$B$1) -> 0 | G43: =_xll.EQNXTDZ($A$1,$B43,G$1,$B$1) -> 0 | H43: =_xll.EQNXTDZ($A$1,$B43,H$1,$B$1) -> 0 | I43: =_xll.EQNXTDZ($A$1,$B43,I$1,$B$1) -> 0 | J43: =_xll.EQNXTDZ($A$1,$B43,J$1,$B$1) -> 0 | ... AF43: =_xll.EQNXTDZ($A$1,$B43,AF$1,$B$1) -> 0
A44: Shareholder's Funds | B44: BS_SHAREHODERS_FUNDS | C44: =_xll.EQNXTDZ($A$1,$B44,C$1,$B$1) -> 0 | D44: =_xll.EQNXTDZ($A$1,$B44,D$1,$B$1) -> 0 | E44: =_xll.EQNXTDZ($A$1,$B44,E$1,$B$1) -> 0 | F44: =_xll.EQNXTDZ($A$1,$B44,F$1,$B$1) -> 0 | G44: =_xll.EQNXTDZ($A$1,$B44,G$1,$B$1) -> 0 | H44: =_xll.EQNXTDZ($A$1,$B44,H$1,$B$1) -> 0 | I44: =_xll.EQNXTDZ($A$1,$B44,I$1,$B$1) -> 0 | J44: =_xll.EQNXTDZ($A$1,$B44,J$1,$B$1) -> 0 | ... AF44: =_xll.EQNXTDZ($A$1,$B44,AF$1,$B$1) -> 0
A45: Minority Interest | B45: BS_MINORITY_INTEREST | C45: =_xll.EQNXTDZ($A$1,$B45,C$1,$B$1) -> 0 | D45: =_xll.EQNXTDZ($A$1,$B45,D$1,$B$1) -> 0 | E45: =_xll.EQNXTDZ($A$1,$B45,E$1,$B$1) -> 0 | F45: =_xll.EQNXTDZ($A$1,$B45,F$1,$B$1) -> 0 | G45: =_xll.EQNXTDZ($A$1,$B45,G$1,$B$1) -> 0 | H45: =_xll.EQNXTDZ($A$1,$B45,H$1,$B$1) -> 0 | I45: =_xll.EQNXTDZ($A$1,$B45,I$1,$B$1) -> 0 | J45: =_xll.EQNXTDZ($A$1,$B45,J$1,$B$1) -> 0 | ... AF45: =_xll.EQNXTDZ($A$1,$B45,AF$1,$B$1) -> 0
A46: Long-Term Borrowings | B46: BS_LTRM_BORROWING | C46: =_xll.EQNXTDZ($A$1,$B46,C$1,$B$1) -> 0 | D46: =_xll.EQNXTDZ($A$1,$B46,D$1,$B$1) -> 0 | E46: =_xll.EQNXTDZ($A$1,$B46,E$1,$B$1) -> 0 | F46: =_xll.EQNXTDZ($A$1,$B46,F$1,$B$1) -> 0 | G46: =_xll.EQNXTDZ($A$1,$B46,G$1,$B$1) -> 0 | H46: =_xll.EQNXTDZ($A$1,$B46,H$1,$B$1) -> 0 | I46: =_xll.EQNXTDZ($A$1,$B46,I$1,$B$1) -> 0 | J46: =_xll.EQNXTDZ($A$1,$B46,J$1,$B$1) -> 0 | ... AF46: =_xll.EQNXTDZ($A$1,$B46,AF$1,$B$1) -> 0
A47: Secured Loans | B47: BS_SECURED_LOANS | C47: =_xll.EQNXTDZ($A$1,$B47,C$1,$B$1) -> 0 | D47: =_xll.EQNXTDZ($A$1,$B47,D$1,$B$1) -> 0 | E47: =_xll.EQNXTDZ($A$1,$B47,E$1,$B$1) -> 0 | F47: =_xll.EQNXTDZ($A$1,$B47,F$1,$B$1) -> 0 | G47: =_xll.EQNXTDZ($A$1,$B47,G$1,$B$1) -> 0 | H47: =_xll.EQNXTDZ($A$1,$B47,H$1,$B$1) -> 0 | I47: =_xll.EQNXTDZ($A$1,$B47,I$1,$B$1) -> 0 | J47: =_xll.EQNXTDZ($A$1,$B47,J$1,$B$1) -> 0 | ... AF47: =_xll.EQNXTDZ($A$1,$B47,AF$1,$B$1) -> 0
A48: Unsecured Loans | B48: BS_UNSECURED_LOANS_NF | C48: =_xll.EQNXTDZ($A$1,$B48,C$1,$B$1) -> 0 | D48: =_xll.EQNXTDZ($A$1,$B48,D$1,$B$1) -> 0 | E48: =_xll.EQNXTDZ($A$1,$B48,E$1,$B$1) -> 0 | F48: =_xll.EQNXTDZ($A$1,$B48,F$1,$B$1) -> 0 | G48: =_xll.EQNXTDZ($A$1,$B48,G$1,$B$1) -> 0 | H48: =_xll.EQNXTDZ($A$1,$B48,H$1,$B$1) -> 0 | I48: =_xll.EQNXTDZ($A$1,$B48,I$1,$B$1) -> 0 | J48: =_xll.EQNXTDZ($A$1,$B48,J$1,$B$1) -> 0 | ... AF48: =_xll.EQNXTDZ($A$1,$B48,AF$1,$B$1) -> 0
A49: Deferred Tax Assets / Liabilities | B49: BS_NET_DEF_TAX_NF | C49: =_xll.EQNXTDZ($A$1,$B49,C$1,$B$1) -> 0 | D49: =_xll.EQNXTDZ($A$1,$B49,D$1,$B$1) -> 0 | E49: =_xll.EQNXTDZ($A$1,$B49,E$1,$B$1) -> 0 | F49: =_xll.EQNXTDZ($A$1,$B49,F$1,$B$1) -> 0 | G49: =_xll.EQNXTDZ($A$1,$B49,G$1,$B$1) -> 0 | H49: =_xll.EQNXTDZ($A$1,$B49,H$1,$B$1) -> 0 | I49: =_xll.EQNXTDZ($A$1,$B49,I$1,$B$1) -> 0 | J49: =_xll.EQNXTDZ($A$1,$B49,J$1,$B$1) -> 0 | ... AF49: =_xll.EQNXTDZ($A$1,$B49,AF$1,$B$1) -> 0
