Workbook

Sheet Template
A1: =+'Annual Raw'!C4 -> John Cockerill India Ltd | B1: 36951 | C1: =EOMONTH(B1,12) -> 37346 | D1: 37591 | E1: =EOMONTH(D1,12) -> 37986 | F1: =EOMONTH(E1,12) -> 38352 | G1: =EOMONTH(F1,12) -> 38717 | H1: =EOMONTH(G1,12) -> 39082 | I1: =EOMONTH(H1,12) -> 39447 | J1: =EOMONTH(I1,12) -> 39813 | K1: =EOMONTH(J1,12) -> 40178 | L1: =EOMONTH(K1,12) -> 40543 | ... AE1: =EOMONTH(AD1,12) -> 47483 | AH1: QTR | AI1: 41061 | AJ1: 41153 | AK1: 41244 | AL1: 41334 | AM1: 41426 | AN1: 41518 | AO1: 41609 | AP1: 41699 | AQ1: 41791 | AR1: 41883 | AS1: 41974 | AT1: 42064 | AU1: 42156 | AV1: 42248 | AW1: 42339 | AX1: 42430 | AY1: 42522 | AZ1: 42614 | BA1: 42705 | BB1: 42795 | BC1: 42887 | BD1: 42979 | BE1: 43070 | BF1: 43160 | BG1: 43252 | BH1: 43344 | BI1: 43435 | BJ1: 43525 | BK1: 43617 | BL1: 43709 | BM1: 43800 | BN1: 43891 | BO1: 43983 | BP1: 44075 | BQ1: =EOMONTH(BP1,3) -> 44196 | BR1: =EOMONTH(BQ1,3) -> 44286 | BS1: =EOMONTH(BR1,3) -> 44377 | BT1: =EOMONTH(BS1,3) -> 44469 | BU1: =EOMONTH(BT1,3) -> 44561 | BV1: =EOMONTH(BU1,3) -> 44651 | BW1: =EOMONTH(BV1,3) -> 44742 | BX1: =EOMONTH(BW1,3) -> 44834 | ... DA1: =EOMONTH(CZ1,3) -> 47483 | DC1: historical estimates | DD1: 46022
A2: Presentation Data (Start)
A4: Order Book
A5: Opening | T5: =S8 -> 0 | U5: =T8 -> 0 | V5: =U8 -> 0 | W5: =V8 -> 0 | X5: =W8 -> 0 | Y5: =X8 -> 0 | Z5: =Y8 -> 1000 | AA5: =Z8 -> 680.8 | ... AE5: =AD8 -> 9133.5717 | CH5: =CG8 -> 680.8 | CI5: =CH8 -> 683 | CJ5: =CI8 -> 680 | CK5: =CJ8 -> 1129.1 | CL5: =CK8 -> 1186.9 | CM5: =CL8 -> 3300 | CN5: =CM8 -> 5073 | CO5: =CN8 -> 5271.7308 | ... DA5: =CZ8 -> 11866.42
A6: Addition | T6: =T8+T7-T5 -> 0 | U6: =U8+U7-U5 -> 0 | V6: =V8+V7-V5 -> 0 | W6: =W8+W7-W5 -> 0 | X6: =X8+X7-X5 -> 0 | Y6: =Y8+Y7-Y5 -> 1666.6143 | Z6: =Z8+Z7-Z5 -> 69.526 | AA6: =AA8+AA7-AA5 -> 863.6948 | ... AE6: =AE8+AE7-AE5 -> 6022.8067 | CH6: =CH8+CH7-CH5 -> 223.1 | CI6: =CI8+CI7-CI5 -> 79.118 | CJ6: =CJ8+CJ7-CJ5 -> 546.084 | CK6: =CK8+CK7-CK5 -> 286.2109 | CL6: =CL8+CL7-CL5 -> 2457.617 | CM6: =300+470+1300 -> 2070 | CN6: =CJ6*(1+CN12) -> 655.3008 | CO6: =CK6*(1+CO12) -> 343.45308 | CP6: 500 | CQ6: =CM6*(1+CQ12) -> 2484 | CR6: =CN6*(1+CR12) -> 786.36096 | CS6: =CO6*(1+CS12) -> 412.1437 | CT6: =CP6*(1+CT12) -> 600 | CU6: =CQ6*(1+CU12) -> 2980.8 | CV6: =CR6*(1+CV12) -> 943.63315 | CW6: =CS6*(1+CW12) -> 494.57244 | CX6: =CT6*(1+CX12) -> 720 | ... DA6: =CW6*(1+DA12) -> 593.48692
A7: Executed | T7: =T27 -> 0 | U7: =U27 -> 0 | V7: =V27 -> 0 | W7: =W27 -> 0 | X7: =X27 -> 0 | Y7: =Y27 -> 666.6143 | Z7: =Z27 -> 388.726 | AA7: =AA27 -> 357.5948 | ... AE7: =AE27 -> 3764.4492 | CG7: =CG27 -> 72.339 | CH7: =CH27 -> 220.9 | CI7: =CI27 -> 82.118 | CJ7: =CJ27 -> 96.984 | CK7: =CK27 -> 228.4109 | CL7: =CL27 -> 344.517 | CM7: =CM5*CM13 -> 297 | CN7: =CN5*CN13 -> 456.57 | CO7: =CO5*CO13 -> 474.45577 | CP7: =CP5*CP13 -> 462.66553 | CQ7: =CQ5*CQ13 -> 466.02563 | CR7: =CR5*CR13 -> 647.64333 | CS7: =CS5*CS13 -> 660.12791 | CT7: =CT5*CT13 -> 637.80933 | ... DA7: =DA5*DA13 -> 1067.9778
A8: Closing | Y8: 1000 | Z8: =CG8 -> 680.8 | AA8: =CK8 -> 1186.9 | AB8: =CO8 -> 5140.7281 | AC8: =CS8 -> 7086.7704 | AD8: =CW8 -> 9133.5717 | AE8: =DA8 -> 11391.929 | CG8: 680.8 | CH8: 683 | CI8: 680 | CJ8: 1129.1 | CK8: 1186.9 | CL8: 3300 | CM8: =CM5+CM6-CM7 -> 5073 | CN8: =CN5+CN6-CN7 -> 5271.7308 | CO8: =CO5+CO6-CO7 -> 5140.7281 | CP8: =CP5+CP6-CP7 -> 5178.0626 | CQ8: =CQ5+CQ6-CQ7 -> 7196.0369 | CR8: =CR5+CR6-CR7 -> 7334.7546 | CS8: =CS5+CS6-CS7 -> 7086.7704 | CT8: =CT5+CT6-CT7 -> 7048.961 | ... DA8: =DA5+DA6-DA7 -> 11391.929
A9: OB to Mkt cap | Y9: =+(Y96*Y84)/Y8 -> #DIV/0! | Z9: =+(Z96*Z84)/Z8 -> #DIV/0! | AA9: =+(AA96*AA84)/AA8 -> #DIV/0! | CG9: =+(CG96*CG84)/CG8 -> 3.0351147 | CH9: =+(CH96*CH84)/CH8 -> 2.0793101 | CI9: =+(CI96*CI84)/CI8 -> 2.4923103 | CJ9: =+(CJ96*CJ84)/CJ8 -> 2.5922641 | CK9: =+(CK96*CK84)/CK8 -> 2.1921034 | CL9: =+(CL96*CL84)/CL8 -> 0.61084556 | CM9: =+(CM96*CM84)/CM8 -> 0.79237004 | CN9: =+(CN96*CN84)/CN8 -> 0.76249971
CM10: =+CM8*2.5 -> 12682.5
A11: OB YoY growth % | Z11: =Z8/Y8-1 -> -0.3192 | AA11: =AA8/Z8-1 -> 0.74339013 | AB11: =AB8/AA8-1 -> 3.3312226 | AC11: =AC8/AB8-1 -> 0.37855382 | AD11: =AD8/AC8-1 -> 0.28882004 | AE11: =AE8/AD8-1 -> 0.24725897 | CK11: =CK8/CG8-1 -> 0.74339013
A12: Addition YoY Growth % | Z12: =Z6/Y6-1 -> -0.95828309 | AA12: =AA6/Z6-1 -> 11.422616 | AB12: =AB6/AA6-1 -> 5.3985228 | AC12: =AC6/AB6-1 -> -0.24317337 | AD12: =AD6/AC6-1 -> 0.2 | AE12: =AE6/AD6-1 -> 0.2 | CL12: =CL6/CH6-1 -> 10.015764 | CM12: =CM6/CI6-1 -> 25.163452 | CN12: 0.2 | CO12: =CN12 -> 0.2 | CP12: =+CP6/CL6-1 -> -0.79655089 | CQ12: 0.2 | CR12: 0.2 | CS12: 0.2 | CT12: 0.2 | CU12: 0.2 | CV12: 0.2 | CW12: 0.2 | CX12: 0.2 | CY12: 0.2 | CZ12: 0.2 | DA12: 0.2
A13: Execution % | Z13: =Z7/Z5 -> 0.388726 | AA13: =AA7/AA5 -> 0.52525676 | AB13: =AB7/AB5 -> 1.324916 | AC13: =AC7/AC5 -> 0.43504779 | AD13: =AD7/AD5 -> 0.4194018 | AE13: =AE7/AE5 -> 0.41215521 | CH13: =CH7/CH5 -> 0.32447121 | CI13: =CI7/CI5 -> 0.12023133 | CJ13: =CJ7/CJ5 -> 0.14262353 | CK13: =CK7/CK5 -> 0.20229466 | CL13: =CL7/CL5 -> 0.29026624 | CM13: 0.09 | CN13: 0.09 | CO13: 0.09 | CP13: 0.09 | CQ13: 0.09 | CR13: 0.09 | CS13: 0.09 | CT13: 0.09 | CU13: 0.09 | CV13: 0.09 | CW13: 0.09 | CX13: 0.09 | CY13: 0.09 | CZ13: 0.09 | DA13: 0.09
A15: Standalone sales | AA15: 357.5948 | CH15: 76.4243 | CK15: 102.0693 | CL15: 200.0443
A16: Standalone EBIDTA | AA16: =22.763+3.0328+6.1507-9.0317 -> 22.9148 | CH16: =-1.02+1.5086+0.4225-1.3543 -> -0.4432 | CK16: =9.5493+1.5585+1.6721-2.6706 -> 10.1093 | CL16: =7.5045+5.1412+1.5615-2.8007 -> 11.4065
A17: Standalone PAT | AA17: 10.3139 | CH17: 0.7461 | CK17: 0.4211 | CL17: =7.0068 -> 7.0068
A19: Subsidiary sales | AA19: =AA27-AA15 -> 0 | CH19: =CH27-CH15 -> 144.4757 | CK19: =CK27-CK15 -> 126.3416 | CL19: =CL27-CL15 -> 144.4727
A20: Subsidiary EBIDTA | AA20: =AA47-AA16 -> -0.4746 | CH20: =CH47-CH16 -> -1.0478 | CK20: =CK47-CK16 -> -29.7676 | CL20: =CL47-CL16 -> -6.4945
A21: Subsidiary PAT | AA21: =AA67-AA17 -> 0 | CH21: =CH67-CH17 -> -3.6601 | CK21: =CK67-CK17 -> -9.3434 | CL21: =CL67-CL17 -> 0.3542
A23: Other Exp | AA23: =+AA41/AA29 -> 0.11922265 | CI23: =+CI41/CI29 -> 0.74894664 | CJ23: =+CJ41/CJ29 -> 0.76354863 | CK23: =+CK41/CK29 -> 0.33480495 | CL23: =+CL41/CL29 -> 0.33005628 | CM23: =+CL23 -> 0.33005628 | CN23: =+CM23-0.5% -> 0.32505628 | CO23: =+CN23-0.5% -> 0.32005628 | CP23: =+CO23-0.5% -> 0.31505628 | CQ23: =+CP23-0.5% -> 0.31005628 | CR23: =+CQ23-0.5% -> 0.30505628 | CS23: =+CR23-0.5% -> 0.30005628 | CT23: =+CS23-0.5% -> 0.29505628 | CU23: =+CT23-0.5% -> 0.29005628 | ... DA23: =+CZ23-0.5% -> 0.26005628
A25: Presentation Data (End)
A26: Profit & Loss- Annual (Start)
A27: Gross Revenue | B27: ='Annual Raw'!C6 -> 94.467588 | C27: ='Annual Raw'!D6 -> 127.52504 | D27: ='Annual Raw'!E6 -> 0 | E27: ='Annual Raw'!F6 -> 0 | F27: ='Annual Raw'!G6 -> 0 | G27: ='Annual Raw'!H6 -> 0 | H27: ='Annual Raw'!I6 -> 0 | I27: ='Annual Raw'!J6 -> 0 | ... AA27: ='Annual Raw'!AB6 -> 357.5948 | AB27: =+SUM(CL27:CO27) -> 1572.5428 | AC27: =+SUM(CP27:CS27) -> 2236.4624 | AD27: =+SUM(CT27:CW27) -> 2972.2043 | AE27: =+SUM(CX27:DA27) -> 3764.4492 | AI27: ='QTR Raw'!C6+'QTR Raw'!C8 -> 92.71 | AJ27: ='QTR Raw'!D6+'QTR Raw'!D8 -> 110.46 | AK27: ='QTR Raw'!E6+'QTR Raw'!E8 -> 194.452 | AL27: ='QTR Raw'!F6+'QTR Raw'!F8 -> 135.274 | AM27: ='QTR Raw'!G6+'QTR Raw'!G8 -> 101.785 | AN27: ='QTR Raw'!H6+'QTR Raw'!H8 -> 122.009 | AO27: ='QTR Raw'!I6+'QTR Raw'!I8 -> 126.378 | AP27: ='QTR Raw'!J6+'QTR Raw'!J8 -> 92.661 | ... CJ27: ='QTR Raw'!BD6+'QTR Raw'!BD8 -> 96.984 | CK27: 228.4109 | CL27: ='QTR Raw'!BF6+'QTR Raw'!BF8 -> 344.517 | CM27: =CM7 -> 297 | CN27: =CN7 -> 456.57 | CO27: =CO7 -> 474.45577 | CP27: =CP7 -> 462.66553 | CQ27: =CQ7 -> 466.02563 | CR27: =CR7 -> 647.64333 | CS27: =CS7 -> 660.12791 | CT27: =CT7 -> 637.80933 | ... DA27: =DA7 -> 1067.9778 | DD27: 53.536827 | DE27: 279.9248
A28: Less: Exise Duty | B28: ='Annual Raw'!C7+'Annual Raw'!C8+'Annual Raw'!C9 -> 9.8270536 | C28: ='Annual Raw'!D7+'Annual Raw'!D8+'Annual Raw'!D9 -> 4.5848681 | D28: ='Annual Raw'!E7+'Annual Raw'!E8+'Annual Raw'!E9 -> 0 | E28: ='Annual Raw'!F7+'Annual Raw'!F8+'Annual Raw'!F9 -> 0 | F28: ='Annual Raw'!G7+'Annual Raw'!G8+'Annual Raw'!G9 -> 0 | G28: ='Annual Raw'!H7+'Annual Raw'!H8+'Annual Raw'!H9 -> 0 | H28: ='Annual Raw'!I7+'Annual Raw'!I8+'Annual Raw'!I9 -> 0 | I28: ='Annual Raw'!J7+'Annual Raw'!J8+'Annual Raw'!J9 -> 0 | ... AA28: ='Annual Raw'!AB7+'Annual Raw'!AB8+'Annual Raw'!AB9 -> 0 | AB28: =+SUM(CL28:CO28) -> 0 | AC28: =+SUM(CP28:CS28) -> 0 | AD28: =+SUM(CT28:CW28) -> 0 | AE28: =+SUM(CX28:DA28) -> 0 | AI28: ='QTR Raw'!C21+'QTR Raw'!C20+'QTR Raw'!C19+'QTR Raw'!C13+'QTR Raw'!C7 -> 0 | AJ28: ='QTR Raw'!D21+'QTR Raw'!D20+'QTR Raw'!D19+'QTR Raw'!D13+'QTR Raw'!D7 -> 0 | AK28: ='QTR Raw'!E21+'QTR Raw'!E20+'QTR Raw'!E19+'QTR Raw'!E13+'QTR Raw'!E7 -> 0 | AL28: ='QTR Raw'!F21+'QTR Raw'!F20+'QTR Raw'!F19+'QTR Raw'!F13+'QTR Raw'!F7 -> 2.818 | AM28: ='QTR Raw'!G21+'QTR Raw'!G20+'QTR Raw'!G19+'QTR Raw'!G13+'QTR Raw'!G7 -> 0 | AN28: ='QTR Raw'!H21+'QTR Raw'!H20+'QTR Raw'!H19+'QTR Raw'!H13+'QTR Raw'!H7 -> 0 | AO28: ='QTR Raw'!I21+'QTR Raw'!I20+'QTR Raw'!I19+'QTR Raw'!I13+'QTR Raw'!I7 -> 0 | AP28: ='QTR Raw'!J21+'QTR Raw'!J20+'QTR Raw'!J19+'QTR Raw'!J13+'QTR Raw'!J7 -> 12.888 | ... CL28: ='QTR Raw'!BF21+'QTR Raw'!BF20+'QTR Raw'!BF19+'QTR Raw'!BF13+'QTR Raw'!BF7 -> 0 | DD28: 0
A29: Net Revenue | B29: =+B27-B28 -> 84.640534 | C29: =+C27-C28 -> 122.94017 | D29: =+D27-D28 -> 0 | E29: =+E27-E28 -> 0 | F29: =+F27-F28 -> 0 | G29: =+G27-G28 -> 0 | H29: =+H27-H28 -> 0 | I29: =+I27-I28 -> 0 | ... AE29: =+AE27-AE28 -> 3764.4492 | AI29: =+AI27-AI28 -> 92.71 | AJ29: =+AJ27-AJ28 -> 110.46 | AK29: =+AK27-AK28 -> 194.452 | AL29: =+AL27-AL28 -> 132.456 | AM29: =+AM27-AM28 -> 101.785 | AN29: =+AN27-AN28 -> 122.009 | AO29: =+AO27-AO28 -> 126.378 | AP29: =+AP27-AP28 -> 79.773 | ... DA29: =+DA27-DA28 -> 1067.9778 | DD29: 53.536827 | DE29: 279.9248
A30: Net Revenue YOY% | C30: =C29/B29-1 -> 0.45249761 | D30: =D29/C29-1 -> -1 | E30: =E29/D29-1 -> #DIV/0! | F30: =F29/E29-1 -> #DIV/0! | G30: =G29/F29-1 -> #DIV/0! | H30: =H29/G29-1 -> #DIV/0! | I30: =I29/H29-1 -> #DIV/0! | J30: =J29/I29-1 -> #DIV/0! | ... AE30: =AE29/AD29-1 -> 0.2665513 | AM30: =+IF(AI29<0,1-AM29/AI29,AM29/AI29-1) -> 0.097885881 | AN30: =+IF(AJ29<0,1-AN29/AJ29,AN29/AJ29-1) -> 0.10455368 | AO30: =+IF(AK29<0,1-AO29/AK29,AO29/AK29-1) -> -0.35008125 | AP30: =+IF(AL29<0,1-AP29/AL29,AP29/AL29-1) -> -0.39773963 | AQ30: =+IF(AM29<0,1-AQ29/AM29,AQ29/AM29-1) -> -0.48803851 | AR30: =+IF(AN29<0,1-AR29/AN29,AR29/AN29-1) -> -0.56157333 | AS30: =+IF(AO29<0,1-AS29/AO29,AS29/AO29-1) -> -0.56761462 | AT30: =+IF(AP29<0,1-AT29/AP29,AT29/AP29-1) -> -0.25929826 | ... DA30: =+IF(CW29<0,1-DA29/CW29,DA29/CW29-1) -> 0.24996449 | DD30: -0.25991752 | DE30: 0.26720144
A31: Net Revenue QOQ% | AJ31: =+IF(AI29<0,1-AJ29/AI29,AJ29/AI29-1) -> 0.19145723 | AK31: =+IF(AJ29<0,1-AK29/AJ29,AK29/AJ29-1) -> 0.76038385 | AL31: =+IF(AK29<0,1-AL29/AK29,AL29/AK29-1) -> -0.31882418 | AM31: =+IF(AL29<0,1-AM29/AL29,AM29/AL29-1) -> -0.23155614 | AN31: =+IF(AM29<0,1-AN29/AM29,AN29/AM29-1) -> 0.19869332 | AO31: =+IF(AN29<0,1-AO29/AN29,AO29/AN29-1) -> 0.035808834 | AP31: =+IF(AO29<0,1-AP29/AO29,AP29/AO29-1) -> -0.36877463 | AQ31: =+IF(AP29<0,1-AQ29/AP29,AQ29/AP29-1) -> -0.34677146 | ... CL31: =+IF(CK29<0,1-CL29/CK29,CL29/CK29-1) -> 0.50832119 | CM31: =+CM29/CL29-1 -> -0.13792353 | CN31: =+CN29/CM29-1 -> 0.53727273 | CO31: =+CO29/CN29-1 -> 0.039174216 | CP31: =+CP29/CO29-1 -> -0.024850034 | CQ31: =+CQ29/CP29-1 -> 0.0072624868 | CR31: =+CR29/CQ29-1 -> 0.3897161 | CS31: =+CS29/CR29-1 -> 0.019276949 | CT31: =+CT29/CS29-1 -> -0.033809477 | ... DA31: =+DA29/CZ29-1 -> 0.0059979139 | DD31: -0.4479829 | DE31: 1.7425055
A32: Increase/Decrease in Stock | B32: ='Annual Raw'!C11 -> -2.4551 | C32: ='Annual Raw'!D11 -> 10.9082 | D32: ='Annual Raw'!E11 -> 0 | E32: ='Annual Raw'!F11 -> 0 | F32: ='Annual Raw'!G11 -> 0 | G32: ='Annual Raw'!H11 -> 0 | H32: ='Annual Raw'!I11 -> 0 | I32: ='Annual Raw'!J11 -> 0 | ... AA32: ='Annual Raw'!AB11 -> 1.8645 | AB32: =+SUM(CL32:CO32) -> -0.659 | AC32: =+SUM(CP32:CS32) -> 0 | AD32: =+SUM(CT32:CW32) -> 0 | AE32: =+SUM(CX32:DA32) -> 0 | AI32: ='QTR Raw'!C10 -> -0.416 | AJ32: ='QTR Raw'!D10 -> 1.175 | AK32: ='QTR Raw'!E10 -> -0.81 | AL32: ='QTR Raw'!F10 -> -1.338 | AM32: ='QTR Raw'!G10 -> 1.701 | AN32: ='QTR Raw'!H10 -> -0.053 | AO32: ='QTR Raw'!I10 -> 0.205 | AP32: ='QTR Raw'!J10 -> -1.586 | ... CJ32: ='QTR Raw'!BD10 -> -0.678 | CK32: 16.5718 | CL32: ='QTR Raw'!BF10 -> -0.659 | DD32: 37.3584
A33: Purchase of Finished Goods | B33: 0 | C33: 0 | D33: 0 | E33: 0 | F33: 0 | G33: 0 | H33: 0 | I33: 0 | J33: 0 | K33: 0 | L33: 0 | M33: 0 | N33: 0 | O33: 0 | P33: 0 | Q33: 0 | R33: 0 | S33: 0 | T33: 0 | U33: 0 | V33: 0 | W33: 0 | X33: 0 | Y33: 0 | Z33: 0 | AA33: 0 | AB33: =+SUM(CL33:CO33) -> 0 | AC33: =+SUM(CP33:CS33) -> 0 | AD33: =+SUM(CT33:CW33) -> 0 | AE33: =+SUM(CX33:DA33) -> 0 | AI33: ='QTR Raw'!C12 -> 15.591 | AJ33: ='QTR Raw'!D12 -> 32.846 | AK33: ='QTR Raw'!E12 -> 68.75 | AL33: ='QTR Raw'!F12 -> 24.29 | AM33: ='QTR Raw'!G12 -> 32.826 | AN33: ='QTR Raw'!H12 -> 55.692 | AO33: ='QTR Raw'!I12 -> 50.49 | AP33: ='QTR Raw'!J12 -> 26.933 | ... CL33: ='QTR Raw'!BF12 -> 0 | DD33: 0
A34: Raw Material Consumed | B34: ='Annual Raw'!C12 -> 64.55574 | C34: ='Annual Raw'!D12 -> 64.487941 | D34: ='Annual Raw'!E12 -> 0 | E34: ='Annual Raw'!F12 -> 0 | F34: ='Annual Raw'!G12 -> 0 | G34: ='Annual Raw'!H12 -> 0 | H34: ='Annual Raw'!I12 -> 0 | I34: ='Annual Raw'!J12 -> 0 | ... AA34: ='Annual Raw'!AB12 -> 159.9097 | AB34: =+SUM(CL34:CO34) -> 705.00472 | AC34: =+SUM(CP34:CS34) -> 1001.7169 | AD34: =+SUM(CT34:CW34) -> 1331.2575 | AE34: =+SUM(CX34:DA34) -> 1686.1059 | AI34: ='QTR Raw'!C11 -> 35.855 | AJ34: ='QTR Raw'!D11 -> 47.087 | AK34: ='QTR Raw'!E11 -> 78.065 | AL34: ='QTR Raw'!F11 -> 78.283 | AM34: ='QTR Raw'!G11 -> 44.369 | AN34: ='QTR Raw'!H11 -> 35.775 | AO34: ='QTR Raw'!I11 -> 36.873 | AP34: ='QTR Raw'!J11 -> 33.207 | ... CJ34: ='QTR Raw'!BD11 -> 0 | CK34: 104.3428 | CL34: ='QTR Raw'!BF11 -> 154.969 | CM34: =+CM29-CM35 -> 133.02702 | CN34: =+CN29-CN35 -> 204.49881 | CO34: =+CO29-CO35 -> 212.50989 | CP34: =+CP29-CP35 -> 207.22901 | CQ34: =+CQ29-CQ35 -> 208.73401 | CR34: =+CR29-CR35 -> 290.08102 | CS34: =+CS29-CS35 -> 295.67289 | CT34: =+CT29-CT35 -> 285.67635 | ... DA34: =+DA29-DA35 -> 478.34985 | DD34: -0.12722574 | DE34: 31.90592
A35: Gross Profit | B35: =B29-B32-B34-B33 -> 22.539894 | C35: =C29-C32-C34-C33 -> 47.544033 | D35: =D29-D32-D34-D33 -> 0 | E35: =E29-E32-E34-E33 -> 0 | F35: =F29-F32-F34-F33 -> 0 | G35: =G29-G32-G34-G33 -> 0 | H35: =H29-H32-H34-H33 -> 0 | I35: =I29-I32-I34-I33 -> 0 | ... AE35: =AE29-AE32-AE34-AE33 -> 2078.3432 | AI35: =AI29-AI32-AI34-AI33 -> 41.68 | AJ35: =AJ29-AJ32-AJ34-AJ33 -> 29.352 | AK35: =AK29-AK32-AK34-AK33 -> 48.447 | AL35: =AL29-AL32-AL34-AL33 -> 31.221 | AM35: =AM29-AM32-AM34-AM33 -> 22.889 | AN35: =AN29-AN32-AN34-AN33 -> 30.595 | AO35: =AO29-AO32-AO34-AO33 -> 38.81 | AP35: =AP29-AP32-AP34-AP33 -> 21.219 | ... CL35: =CL29-CL32-CL34-CL33 -> 190.207 | CM35: =+CM36*CM29 -> 163.97298 | CN35: =+CN36*CN29 -> 252.07119 | CO35: =+CO36*CO29 -> 261.94588 | CP35: =+CP36*CP29 -> 255.43652 | CQ35: =+CQ36*CQ29 -> 257.29162 | CR35: =+CR36*CR29 -> 357.56231 | CS35: =+CS36*CS29 -> 364.45502 | CT35: =+CT36*CT29 -> 352.13299 | ... DA35: =+DA36*DA29 -> 589.62796 | DD35: 53.664053 | DE35: 248.01888
A36: GP% | B36: =B35/B29 -> 0.26630142 | C36: =C35/C29 -> 0.38672495 | D36: =D35/D29 -> #DIV/0! | E36: =E35/E29 -> #DIV/0! | F36: =F35/F29 -> #DIV/0! | G36: =G35/G29 -> #DIV/0! | H36: =H35/H29 -> #DIV/0! | I36: =I35/I29 -> #DIV/0! | ... AE36: =AE35/AE29 -> 0.55209757 | AI36: =AI35/AI29 -> 0.44957394 | AJ36: =AJ35/AJ29 -> 0.26572515 | AK36: =AK35/AK29 -> 0.24914632 | AL36: =AL35/AL29 -> 0.23570846 | AM36: =AM35/AM29 -> 0.22487596 | AN36: =AN35/AN29 -> 0.25076019 | AO36: =AO35/AO29 -> 0.30709459 | AP36: =AP35/AP29 -> 0.26599225 | ... CL36: =CL35/CL29 -> 0.55209757 | CM36: =+CL36 -> 0.55209757 | CN36: =+CM36 -> 0.55209757 | CO36: =+CN36 -> 0.55209757 | CP36: =+CO36 -> 0.55209757 | CQ36: =+CP36 -> 0.55209757 | CR36: =+CQ36 -> 0.55209757 | CS36: =+CR36 -> 0.55209757 | CT36: =+CS36 -> 0.55209757 | ... DA36: =+CZ36 -> 0.55209757 | DD36: 1.0023764 | DE36: 0.88601967
A37: GP YOY% | C37: =+IF(B35<0,1-C35/B35,C35/B35-1) -> 1.1093281 | D37: =+IF(C35<0,1-D35/C35,D35/C35-1) -> -1 | E37: =+IF(D35<0,1-E35/D35,E35/D35-1) -> #DIV/0! | F37: =+IF(E35<0,1-F35/E35,F35/E35-1) -> #DIV/0! | G37: =+IF(F35<0,1-G35/F35,G35/F35-1) -> #DIV/0! | H37: =+IF(G35<0,1-H35/G35,H35/G35-1) -> #DIV/0! | I37: =+IF(H35<0,1-I35/H35,I35/H35-1) -> #DIV/0! | J37: =+IF(I35<0,1-J35/I35,J35/I35-1) -> #DIV/0! | ... AE37: =+IF(AD35<0,1-AE35/AD35,AE35/AD35-1) -> 0.2665513 | AM37: =+IF(AI35<0,1-AM35/AI35,AM35/AI35-1) -> -0.45083973 | AN37: =+IF(AJ35<0,1-AN35/AJ35,AN35/AJ35-1) -> 0.042348051 | AO37: =+IF(AK35<0,1-AO35/AK35,AO35/AK35-1) -> -0.19891841 | AP37: =+IF(AL35<0,1-AP35/AL35,AP35/AL35-1) -> -0.3203613 | AQ37: =+IF(AM35<0,1-AQ35/AM35,AQ35/AM35-1) -> -0.2848093 | AR37: =+IF(AN35<0,1-AR35/AN35,AR35/AN35-1) -> -0.46635071 | AS37: =+IF(AO35<0,1-AS35/AO35,AS35/AO35-1) -> -0.58098428 | AT37: =+IF(AP35<0,1-AT35/AP35,AT35/AP35-1) -> 0.14661388 | ... CL37: =+IF(CH35<0,1-CL35/CH35,CL35/CH35-1) -> 0.57137428 | CM37: =+CM35/CI35-1 -> 1.0011103 | CN37: =+CN35/CJ35-1 -> 1.581057 | CO37: =+CO35/CK35-1 -> 1.4367897 | CP37: =+CP35/CL35-1 -> 0.34293962 | CQ37: =+CQ35/CM35-1 -> 0.56910987 | CR37: =+CR35/CN35-1 -> 0.41849733 | CS37: =+CS35/CO35-1 -> 0.39133709 | CT37: =+CT35/CP35-1 -> 0.37855382 | ... DA37: =+DA35/CW35-1 -> 0.24996449 | DD37: -0.27552479 | DE37: 1.0489808
A38: GP QOQ% | AJ38: =+IF(AI35<0,1-AJ35/AI35,AJ35/AI35-1) -> -0.29577735 | AK38: =+IF(AJ35<0,1-AK35/AJ35,AK35/AJ35-1) -> 0.65055192 | AL38: =+IF(AK35<0,1-AL35/AK35,AL35/AK35-1) -> -0.35556381 | AM38: =+IF(AL35<0,1-AM35/AL35,AM35/AL35-1) -> -0.26687166 | AN38: =+IF(AM35<0,1-AN35/AM35,AN35/AM35-1) -> 0.33666827 | AO38: =+IF(AN35<0,1-AO35/AN35,AO35/AN35-1) -> 0.26850793 | AP38: =+IF(AO35<0,1-AP35/AO35,AP35/AO35-1) -> -0.45325947 | AQ38: =+IF(AP35<0,1-AQ35/AP35,AQ35/AP35-1) -> -0.22852161 | ... CL38: =+IF(CK35<0,1-CL35/CK35,CL35/CK35-1) -> 0.76942834 | CM38: =+CM35/CL35-1 -> -0.13792353 | CN38: =+CN35/CM35-1 -> 0.53727273 | CO38: =+CO35/CN35-1 -> 0.039174216 | CP38: =+CP35/CO35-1 -> -0.024850034 | CQ38: =+CQ35/CP35-1 -> 0.0072624868 | CR38: =+CR35/CQ35-1 -> 0.3897161 | CS38: =+CS35/CR35-1 -> 0.019276949 | CT38: =+CT35/CS35-1 -> -0.033809477 | ... DA38: =+DA35/CZ35-1 -> 0.0059979139 | DD38: -0.45051246 | DE38: 1.4512881
A39: Power & Fuel Cost | B39: ='Annual Raw'!C13 -> 0.3935483 | C39: ='Annual Raw'!D13 -> 0.49143431 | D39: ='Annual Raw'!E13 -> 0 | E39: ='Annual Raw'!F13 -> 0 | F39: ='Annual Raw'!G13 -> 0 | G39: ='Annual Raw'!H13 -> 0 | H39: ='Annual Raw'!I13 -> 0 | I39: ='Annual Raw'!J13 -> 0 | ... AA39: ='Annual Raw'!AB13 -> 1.7533 | AB39: =+SUM(CL39:CO39) -> 0 | AC39: =+SUM(CP39:CS39) -> 0 | AD39: =+SUM(CT39:CW39) -> 0 | AE39: =+SUM(CX39:DA39) -> 0 | AI39: ='QTR Raw'!C15 -> 0 | AJ39: ='QTR Raw'!D15 -> 0 | AK39: ='QTR Raw'!E15 -> 0 | AL39: ='QTR Raw'!F15 -> 0 | AM39: ='QTR Raw'!G15 -> 0 | AN39: ='QTR Raw'!H15 -> 0 | AO39: ='QTR Raw'!I15 -> 0 | AP39: ='QTR Raw'!J15 -> 0 | ... CL39: ='QTR Raw'!BF15 -> 0 | DD39: 0
A40: Selling and Distribution Expenses | B40: =('Annual Raw'!C18) -> 0.49196158 | C40: =('Annual Raw'!D18) -> 5.5031474 | D40: =('Annual Raw'!E18) -> 0 | E40: =('Annual Raw'!F18) -> 0 | F40: =('Annual Raw'!G18) -> 0 | G40: =('Annual Raw'!H18) -> 0 | H40: =('Annual Raw'!I18) -> 0 | I40: =('Annual Raw'!J18) -> 0 | ... AA40: =('Annual Raw'!AB18) -> 4.8797 | AB40: =+SUM(CL40:CO40) -> 0 | AC40: =+SUM(CP40:CS40) -> 0 | AD40: =+SUM(CT40:CW40) -> 0 | AE40: =+SUM(CX40:DA40) -> 0 | AI40: ='QTR Raw'!C18 -> 0 | AJ40: ='QTR Raw'!D18 -> 0 | AK40: ='QTR Raw'!E18 -> 0 | AL40: ='QTR Raw'!F18 -> 0 | AM40: ='QTR Raw'!G18 -> 0 | AN40: ='QTR Raw'!H18 -> 0 | AO40: ='QTR Raw'!I18 -> 0 | AP40: ='QTR Raw'!J18 -> 0 | ... CL40: ='QTR Raw'!BF18 -> 0 | DD40: 0
A41: Other Manufacturing Expenses | B41: ='Annual Raw'!C15+'Annual Raw'!C16 -> 13.841807 | C41: ='Annual Raw'!D15+'Annual Raw'!D16 -> 12.645187 | D41: ='Annual Raw'!E15+'Annual Raw'!E16 -> 0 | E41: ='Annual Raw'!F15+'Annual Raw'!F16 -> 0 | F41: ='Annual Raw'!G15+'Annual Raw'!G16 -> 0 | G41: ='Annual Raw'!H15+'Annual Raw'!H16 -> 0 | H41: ='Annual Raw'!I15+'Annual Raw'!I16 -> 0 | I41: ='Annual Raw'!J15+'Annual Raw'!J16 -> 0 | ... AA41: ='Annual Raw'!AB15+'Annual Raw'!AB16 -> 42.6334 | AB41: =+SUM(CL41:CO41) -> 512.00021 | AC41: =+SUM(CP41:CS41) -> 685.90305 | AD41: =+SUM(CT41:CW41) -> 852.52359 | AE41: =+SUM(CX41:DA41) -> 1004.7354 | AI41: ='QTR Raw'!C14 -> 24.914 | AJ41: ='QTR Raw'!D14 -> 22.731 | AK41: ='QTR Raw'!E14 -> 33.6 | AL41: ='QTR Raw'!F14 -> 27.844 | AM41: ='QTR Raw'!G14 -> 29.033 | AN41: ='QTR Raw'!H14 -> 31.506 | AO41: ='QTR Raw'!I14 -> 15.745 | AP41: ='QTR Raw'!J14 -> 20.862 | ... CJ41: ='QTR Raw'!BD14 -> 74.052 | CK41: 76.4731 | CL41: ='QTR Raw'!BF14 -> 113.71 | CM41: =+CM23*CM29 -> 98.026716 | CN41: =+CN23*CN29 -> 148.41095 | CO41: =+CO23*CO29 -> 151.85255 | CP41: =+CP23*CP29 -> 145.76568 | CQ41: =+CQ23*CQ29 -> 144.49417 | CR41: =+CR23*CR29 -> 197.56766 | CS41: =+CS23*CS29 -> 198.07553 | CT41: =+CT23*CT29 -> 188.18965 | ... DA41: =+DA23*DA29 -> 277.73434 | DD41: 39.683199 | DE41: 166.64904
A42: Employee Cost | B42: ='Annual Raw'!C14 -> 4.8360056 | C42: ='Annual Raw'!D14 -> 4.8083723 | D42: ='Annual Raw'!E14 -> 0 | E42: ='Annual Raw'!F14 -> 0 | F42: ='Annual Raw'!G14 -> 0 | G42: ='Annual Raw'!H14 -> 0 | H42: ='Annual Raw'!I14 -> 0 | I42: ='Annual Raw'!J14 -> 0 | ... AA42: ='Annual Raw'!AB14 -> 63.3485 | AB42: =+SUM(CL42:CO42) -> 286.34 | AC42: =+SUM(CP42:CS42) -> 314.974 | AD42: =+SUM(CT42:CW42) -> 346.4714 | AE42: =+SUM(CX42:DA42) -> 381.11854 | AI42: ='QTR Raw'!C16 -> 9.925 | AJ42: ='QTR Raw'!D16 -> 12.134 | AK42: ='QTR Raw'!E16 -> 12.361 | AL42: ='QTR Raw'!F16 -> 8.983 | AM42: ='QTR Raw'!G16 -> 11.883 | AN42: ='QTR Raw'!H16 -> 11.589 | AO42: ='QTR Raw'!I16 -> 10.835 | AP42: ='QTR Raw'!J16 -> 8.541 | ... CJ42: ='QTR Raw'!BD16 -> 12.292 | CK42: 50.6815 | CL42: ='QTR Raw'!BF16 -> 71.585 | CM42: =+CL42 -> 71.585 | CN42: =+CM42 -> 71.585 | CO42: =+CN42 -> 71.585 | CP42: =CL42*110% -> 78.7435 | CQ42: =CM42*110% -> 78.7435 | CR42: =CN42*110% -> 78.7435 | CS42: =CO42*110% -> 78.7435 | CT42: =CP42*110% -> 86.61785 | CU42: =CQ42*110% -> 86.61785 | CV42: =CR42*110% -> 86.61785 | CW42: =CS42*110% -> 86.61785 | ... DA42: =CW42*110% -> 95.279635 | DD42: 12.27076 | DE42: 65.0988
A43: General and Administration Expenses | B43: ='Annual Raw'!C17 -> 6.2128015 | C43: ='Annual Raw'!D17 -> 7.9917853 | D43: ='Annual Raw'!E17 -> 0 | E43: ='Annual Raw'!F17 -> 0 | F43: ='Annual Raw'!G17 -> 0 | G43: ='Annual Raw'!H17 -> 0 | H43: ='Annual Raw'!I17 -> 0 | I43: ='Annual Raw'!J17 -> 0 | ... AA43: ='Annual Raw'!AB17 -> 31.7816 | AB43: =+SUM(CL43:CO43) -> 0 | AC43: =+SUM(CP43:CS43) -> 0 | AD43: =+SUM(CT43:CW43) -> 0 | AE43: =+SUM(CX43:DA43) -> 0 | AI43: ='QTR Raw'!C17 -> 0 | AJ43: ='QTR Raw'!D17 -> 0 | AK43: ='QTR Raw'!E17 -> 0 | AL43: ='QTR Raw'!F17 -> 0 | AM43: ='QTR Raw'!G17 -> 0 | AN43: ='QTR Raw'!H17 -> 0 | AO43: ='QTR Raw'!I17 -> 0 | AP43: ='QTR Raw'!J17 -> 0 | ... CL43: ='QTR Raw'!BF17 -> 0 | DD43: 0
A44: Miscellaneous Expenses | B44: ='Annual Raw'!C19-'Annual Raw'!C20 -> 0.15594419 | C44: ='Annual Raw'!D19-'Annual Raw'!D20 -> 1.0731105 | D44: ='Annual Raw'!E19-'Annual Raw'!E20 -> 0 | E44: ='Annual Raw'!F19-'Annual Raw'!F20 -> 0 | F44: ='Annual Raw'!G19-'Annual Raw'!G20 -> 0 | G44: ='Annual Raw'!H19-'Annual Raw'!H20 -> 0 | H44: ='Annual Raw'!I19-'Annual Raw'!I20 -> 0 | I44: ='Annual Raw'!J19-'Annual Raw'!J20 -> 0 | ... AA44: ='Annual Raw'!AB19-'Annual Raw'!AB20 -> 28.9839 | AB44: =+SUM(CL44:CO44) -> 0 | AC44: =+SUM(CP44:CS44) -> 0 | AD44: =+SUM(CT44:CW44) -> 0 | AE44: =+SUM(CX44:DA44) -> 0 | DD44: 0
A45: Total Cost | B45: =+SUM(B39:B44) -> 25.932068 | C45: =+SUM(C39:C44) -> 32.513037 | D45: =+SUM(D39:D44) -> 0 | E45: =+SUM(E39:E44) -> 0 | F45: =+SUM(F39:F44) -> 0 | G45: =+SUM(G39:G44) -> 0 | H45: =+SUM(H39:H44) -> 0 | I45: =+SUM(I39:I44) -> 0 | ... AE45: =+SUM(AE39:AE44) -> 1385.854 | AI45: =+SUM(AI39:AI44) -> 34.839 | AJ45: =+SUM(AJ39:AJ44) -> 34.865 | AK45: =+SUM(AK39:AK44) -> 45.961 | AL45: =+SUM(AL39:AL44) -> 36.827 | AM45: =+SUM(AM39:AM44) -> 40.916 | AN45: =+SUM(AN39:AN44) -> 43.095 | AO45: =+SUM(AO39:AO44) -> 26.58 | AP45: =+SUM(AP39:AP44) -> 29.403 | ... DA45: =+SUM(DA39:DA44) -> 373.01397 | DD45: 51.953959 | DE45: 231.74784
...

Sheet Acquisition
C2: crs
A3: Transactions | B3: 30 Mln Euros | C3: =3*105 -> 315 | D3: Germany (Europe) and China
I7: 58028 | J7: price
I8: 35185 | J8: no of shares | K8: metals shares 1.9746 crs share swap | O8: =+I8*10 -> 351850
I9: =+I7*I8/10^7 -> 204.17152 | O9: =+O8/10^7 -> 0.035185
O10: =+O9*10 -> 0.35185
H13: =+J13/K13 -> 0.49367269 | I13: Pre share | J13: 0.3472 | K13: 0.7033 | M13: 0.3824 | N13: 0.723 | P13: =+M13/N13 -> 0.52890733
M14: =+M13-J13 -> 0.0352 | O14: =+M14*10^7 -> 352000
B15: in crs | M15: =200/M14 -> 5681.8182
A16: JCMI Belgium | B16: 2025
A17: Sales | B17: =3.44*106 -> 364.64 | M17: =7.3*100 -> 730
A18: PAT | B18: =-0.47*105 -> -49.35
A19: Networth | B19: =2.1*105 -> 220.5
A22: JCMI USA | B22: 2025
A23: Sales | B23: =2.4*90 -> 216
A24: PAT | B24: =0.09*90 -> 8.1
A25: Networth | B25: =-0.46*90 -> -41.4 | J25: =J27*500 -> 3750000
J26: 30000 | K26: =J26*20% -> 6000
J27: 7500 | K27: 7500
J28: =J26*J27 -> 225000000 | K28: =K26*K27 -> 45000000
J29: =J28/10^7 -> 22.5 | K29: =K28/10^7 -> 4.5

Sheet OB Data
A2: Date | B2: Order size | C2: Order details
A3: 46127 | B3: 300 | C3: JSW Steel Coated Products Limited Design, Engineering, Supply of Continuous Galvanizing Line (CGL#3) and associated equipment Technical Scope for Continuous Galvanizing Line (CGL) as per list agreed in Technical Scope of supply. Time period: May 2028
A4: 46157 | B4: 470 | C4: Order from JSW Steel Coated Products Limited to Design, Manufacturing, Supply, Supervision of Erection & Commissioning of Pickling Line, 2 Stand cold Rolling Mill, Galvanising line (Cold Rolling Complex) as per list agreed in Technical Scope of supply. Time period: June 2028
A5: 46175 | B5: 1300 | C5: Order from JSW Vijayanagar Metallics Limited to Design, Engineering, Supply, Supervision of Erection & Commissioning of Two Annealing & Coating Line (ACL 1 & ACL 2) and one Annealing & Pickling Line (APL) for CRNO Project. Time period: 36 month

Sheet QTR Raw
A1: ='Annual Raw'!A1 -> 100147 | B1: X | C1: 201206 | D1: 201209 | E1: 201212 | F1: 201303 | G1: 201306 | H1: 201309 | I1: 201312 | J1: 201403 | K1: 201406 | L1: 201409 | M1: 201412 | N1: 201503 | O1: 201506 | P1: 201509 | Q1: 201512 | R1: 201603 | S1: 201606 | T1: 201609 | U1: 201612 | V1: 201703 | W1: 201706 | X1: 201709 | Y1: 201712 | Z1: 201803 | AA1: 201806 | AB1: 201809 | AC1: 201812 | AD1: 201903 | AE1: 201906 | AF1: 201909 | AG1: 201912 | AH1: 202003 | AI1: 202006 | AJ1: 202009 | AK1: 202012 | AL1: 202103 | AM1: 202106 | AN1: 202109 | AO1: 202112 | AP1: 202203 | AQ1: 202206 | AR1: 202209 | AS1: 202212 | AT1: 202303 | AU1: 202306 | AV1: 202309 | AW1: 202312 | AX1: 202403 | AY1: 202406 | AZ1: 202409 | BA1: 202412 | BB1: 202503 | BC1: 202506 | BD1: 202509 | BE1: 202512 | BF1: 202603 | BG1: 202606 | BH1: 202609 | BI1: 202612 | BJ1: 202703 | BK1: 202706 | BL1: 202709 | BM1: 202712 | BN1: 202803 | BO1: 202806 | BP1: 202809 | BQ1: 202812 | BR1: 202903 | BS1: 202906 | BT1: 202909 | BU1: 202912
A3: Field Description | B3: Field Name
A4: Company Name | B4: CD_COMPNAME | C4: =_xll.EQNXTDZ(A1,B4,C1) -> John Cockerill India Ltd
A5: Date End | B5: QTR_DATE_END | C5: =_xll.EQNXTDZ($A$1,$B5,C$1,$B$1) -> 201206 | D5: =_xll.EQNXTDZ($A$1,$B5,D$1,$B$1) -> 201209 | E5: =_xll.EQNXTDZ($A$1,$B5,E$1,$B$1) -> 201212 | F5: =_xll.EQNXTDZ($A$1,$B5,F$1,$B$1) -> 201303 | G5: =_xll.EQNXTDZ($A$1,$B5,G$1,$B$1) -> 201306 | H5: =_xll.EQNXTDZ($A$1,$B5,H$1,$B$1) -> 201309 | I5: =_xll.EQNXTDZ($A$1,$B5,I$1,$B$1) -> 201312 | J5: =_xll.EQNXTDZ($A$1,$B5,J$1,$B$1) -> 201403 | ... BU5: =_xll.EQNXTDZ($A$1,$B5,BU$1,$B$1) -> 0
A6: Gross Sales | B6: QTR_GROSS_SALE | C6: =_xll.EQNXTDZ($A$1,$B6,C$1,$B$1) -> 92.428 | D6: =_xll.EQNXTDZ($A$1,$B6,D$1,$B$1) -> 110.081 | E6: =_xll.EQNXTDZ($A$1,$B6,E$1,$B$1) -> 194.165 | F6: =_xll.EQNXTDZ($A$1,$B6,F$1,$B$1) -> 133.297 | G6: =_xll.EQNXTDZ($A$1,$B6,G$1,$B$1) -> 101.481 | H6: =_xll.EQNXTDZ($A$1,$B6,H$1,$B$1) -> 121.6 | I6: =_xll.EQNXTDZ($A$1,$B6,I$1,$B$1) -> 125.846 | J6: =_xll.EQNXTDZ($A$1,$B6,J$1,$B$1) -> 92.323 | ... BU6: =_xll.EQNXTDZ($A$1,$B6,BU$1,$B$1) -> 0
A7: Less: Excise Duty | B7: QTR_EXCISE_DUTY | C7: =_xll.EQNXTDZ($A$1,$B7,C$1,$B$1) -> 0 | D7: =_xll.EQNXTDZ($A$1,$B7,D$1,$B$1) -> 0 | E7: =_xll.EQNXTDZ($A$1,$B7,E$1,$B$1) -> 0 | F7: =_xll.EQNXTDZ($A$1,$B7,F$1,$B$1) -> 0 | G7: =_xll.EQNXTDZ($A$1,$B7,G$1,$B$1) -> 0 | H7: =_xll.EQNXTDZ($A$1,$B7,H$1,$B$1) -> 0 | I7: =_xll.EQNXTDZ($A$1,$B7,I$1,$B$1) -> 0 | J7: =_xll.EQNXTDZ($A$1,$B7,J$1,$B$1) -> 0 | ... BU7: =_xll.EQNXTDZ($A$1,$B7,BU$1,$B$1) -> 0
A8: Other operating income | B8: QTR_JOB_WORKS | C8: =_xll.EQNXTDZ($A$1,$B8,C$1,$B$1) -> 0.282 | D8: =_xll.EQNXTDZ($A$1,$B8,D$1,$B$1) -> 0.379 | E8: =_xll.EQNXTDZ($A$1,$B8,E$1,$B$1) -> 0.287 | F8: =_xll.EQNXTDZ($A$1,$B8,F$1,$B$1) -> 1.977 | G8: =_xll.EQNXTDZ($A$1,$B8,G$1,$B$1) -> 0.304 | H8: =_xll.EQNXTDZ($A$1,$B8,H$1,$B$1) -> 0.409 | I8: =_xll.EQNXTDZ($A$1,$B8,I$1,$B$1) -> 0.532 | J8: =_xll.EQNXTDZ($A$1,$B8,J$1,$B$1) -> 0.338 | ... BU8: =_xll.EQNXTDZ($A$1,$B8,BU$1,$B$1) -> 0
A9: Net Sales & Other Operating Income | B9: QTR_NET_SALES | C9: =_xll.EQNXTDZ($A$1,$B9,C$1,$B$1) -> 92.709 | D9: =_xll.EQNXTDZ($A$1,$B9,D$1,$B$1) -> 110.46 | E9: =_xll.EQNXTDZ($A$1,$B9,E$1,$B$1) -> 194.452 | F9: =_xll.EQNXTDZ($A$1,$B9,F$1,$B$1) -> 135.274 | G9: =_xll.EQNXTDZ($A$1,$B9,G$1,$B$1) -> 101.785 | H9: =_xll.EQNXTDZ($A$1,$B9,H$1,$B$1) -> 122.009 | I9: =_xll.EQNXTDZ($A$1,$B9,I$1,$B$1) -> 126.378 | J9: =_xll.EQNXTDZ($A$1,$B9,J$1,$B$1) -> 92.661 | ... BU9: =_xll.EQNXTDZ($A$1,$B9,BU$1,$B$1) -> 0
A10: (Increase) / Decrease In Stocks | B10: QTR_INC_DEC_INVENTORY | C10: =_xll.EQNXTDZ($A$1,$B10,C$1,$B$1) -> -0.416 | D10: =_xll.EQNXTDZ($A$1,$B10,D$1,$B$1) -> 1.175 | E10: =_xll.EQNXTDZ($A$1,$B10,E$1,$B$1) -> -0.81 | F10: =_xll.EQNXTDZ($A$1,$B10,F$1,$B$1) -> -1.338 | G10: =_xll.EQNXTDZ($A$1,$B10,G$1,$B$1) -> 1.701 | H10: =_xll.EQNXTDZ($A$1,$B10,H$1,$B$1) -> -0.053 | I10: =_xll.EQNXTDZ($A$1,$B10,I$1,$B$1) -> 0.205 | J10: =_xll.EQNXTDZ($A$1,$B10,J$1,$B$1) -> -1.586 | ... BU10: =_xll.EQNXTDZ($A$1,$B10,BU$1,$B$1) -> 0
A11: Cost of Services & Raw Materials | B11: QTR_RAW_MATERIAL_COST | C11: =_xll.EQNXTDZ($A$1,$B11,C$1,$B$1) -> 35.855 | D11: =_xll.EQNXTDZ($A$1,$B11,D$1,$B$1) -> 47.087 | E11: =_xll.EQNXTDZ($A$1,$B11,E$1,$B$1) -> 78.065 | F11: =_xll.EQNXTDZ($A$1,$B11,F$1,$B$1) -> 78.283 | G11: =_xll.EQNXTDZ($A$1,$B11,G$1,$B$1) -> 44.369 | H11: =_xll.EQNXTDZ($A$1,$B11,H$1,$B$1) -> 35.775 | I11: =_xll.EQNXTDZ($A$1,$B11,I$1,$B$1) -> 36.873 | J11: =_xll.EQNXTDZ($A$1,$B11,J$1,$B$1) -> 33.207 | ... BU11: =_xll.EQNXTDZ($A$1,$B11,BU$1,$B$1) -> 0
A12: Purchase of Finished Goods | B12: QTR_PURCHASE_FIN_GOOD | C12: =_xll.EQNXTDZ($A$1,$B12,C$1,$B$1) -> 15.591 | D12: =_xll.EQNXTDZ($A$1,$B12,D$1,$B$1) -> 32.846 | E12: =_xll.EQNXTDZ($A$1,$B12,E$1,$B$1) -> 68.75 | F12: =_xll.EQNXTDZ($A$1,$B12,F$1,$B$1) -> 24.29 | G12: =_xll.EQNXTDZ($A$1,$B12,G$1,$B$1) -> 32.826 | H12: =_xll.EQNXTDZ($A$1,$B12,H$1,$B$1) -> 55.692 | I12: =_xll.EQNXTDZ($A$1,$B12,I$1,$B$1) -> 50.49 | J12: =_xll.EQNXTDZ($A$1,$B12,J$1,$B$1) -> 26.933 | ... BU12: =_xll.EQNXTDZ($A$1,$B12,BU$1,$B$1) -> 0
A13: Excise Duty | B13: QTR_EXCISE | C13: =_xll.EQNXTDZ($A$1,$B13,C$1,$B$1) -> 0 | D13: =_xll.EQNXTDZ($A$1,$B13,D$1,$B$1) -> 0 | E13: =_xll.EQNXTDZ($A$1,$B13,E$1,$B$1) -> 0 | F13: =_xll.EQNXTDZ($A$1,$B13,F$1,$B$1) -> 0 | G13: =_xll.EQNXTDZ($A$1,$B13,G$1,$B$1) -> 0 | H13: =_xll.EQNXTDZ($A$1,$B13,H$1,$B$1) -> 0 | I13: =_xll.EQNXTDZ($A$1,$B13,I$1,$B$1) -> 0 | J13: =_xll.EQNXTDZ($A$1,$B13,J$1,$B$1) -> 0 | ... BU13: =_xll.EQNXTDZ($A$1,$B13,BU$1,$B$1) -> 0
A14: Operating & Manufacturing Expenses | B14: QTR_MFG_EXPS | C14: =_xll.EQNXTDZ($A$1,$B14,C$1,$B$1) -> 24.914 | D14: =_xll.EQNXTDZ($A$1,$B14,D$1,$B$1) -> 22.731 | E14: =_xll.EQNXTDZ($A$1,$B14,E$1,$B$1) -> 33.6 | F14: =_xll.EQNXTDZ($A$1,$B14,F$1,$B$1) -> 27.844 | G14: =_xll.EQNXTDZ($A$1,$B14,G$1,$B$1) -> 29.033 | H14: =_xll.EQNXTDZ($A$1,$B14,H$1,$B$1) -> 31.506 | I14: =_xll.EQNXTDZ($A$1,$B14,I$1,$B$1) -> 15.745 | J14: =_xll.EQNXTDZ($A$1,$B14,J$1,$B$1) -> 20.862 | ... BU14: =_xll.EQNXTDZ($A$1,$B14,BU$1,$B$1) -> 0
A15: Electricity Power & Fuel Cost | B15: QTR_ELECTRICITY_POWER_FUEL | C15: =_xll.EQNXTDZ($A$1,$B15,C$1,$B$1) -> 0 | D15: =_xll.EQNXTDZ($A$1,$B15,D$1,$B$1) -> 0 | E15: =_xll.EQNXTDZ($A$1,$B15,E$1,$B$1) -> 0 | F15: =_xll.EQNXTDZ($A$1,$B15,F$1,$B$1) -> 0 | G15: =_xll.EQNXTDZ($A$1,$B15,G$1,$B$1) -> 0 | H15: =_xll.EQNXTDZ($A$1,$B15,H$1,$B$1) -> 0 | I15: =_xll.EQNXTDZ($A$1,$B15,I$1,$B$1) -> 0 | J15: =_xll.EQNXTDZ($A$1,$B15,J$1,$B$1) -> 0 | ... BU15: =_xll.EQNXTDZ($A$1,$B15,BU$1,$B$1) -> 0
A16: Employee Cost | B16: QTR_EXPLOYEE_COST | C16: =_xll.EQNXTDZ($A$1,$B16,C$1,$B$1) -> 9.925 | D16: =_xll.EQNXTDZ($A$1,$B16,D$1,$B$1) -> 12.134 | E16: =_xll.EQNXTDZ($A$1,$B16,E$1,$B$1) -> 12.361 | F16: =_xll.EQNXTDZ($A$1,$B16,F$1,$B$1) -> 8.983 | G16: =_xll.EQNXTDZ($A$1,$B16,G$1,$B$1) -> 11.883 | H16: =_xll.EQNXTDZ($A$1,$B16,H$1,$B$1) -> 11.589 | I16: =_xll.EQNXTDZ($A$1,$B16,I$1,$B$1) -> 10.835 | J16: =_xll.EQNXTDZ($A$1,$B16,J$1,$B$1) -> 8.541 | ... BU16: =_xll.EQNXTDZ($A$1,$B16,BU$1,$B$1) -> 0
... A42: Consolidated PAT(after extra items) | B42: QTR_CONS_PAT_EXITM | C42: =_xll.EQNXTDZ($A$1,$B42,C$1,$B$1) -> 4.466 | D42: =_xll.EQNXTDZ($A$1,$B42,D$1,$B$1) -> -3.717 | E42: =_xll.EQNXTDZ($A$1,$B42,E$1,$B$1) -> 1.695 | F42: =_xll.EQNXTDZ($A$1,$B42,F$1,$B$1) -> -3.437 | G42: =_xll.EQNXTDZ($A$1,$B42,G$1,$B$1) -> -13.758 | H42: =_xll.EQNXTDZ($A$1,$B42,H$1,$B$1) -> -18.51 | I42: =_xll.EQNXTDZ($A$1,$B42,I$1,$B$1) -> 11.531 | J42: =_xll.EQNXTDZ($A$1,$B42,J$1,$B$1) -> -1.576 | ... BU42: =_xll.EQNXTDZ($A$1,$B42,BU$1,$B$1) -> 0
A44: Field Description | B44: Field Name
A45: Equity Capital | B45: QTR_EQUITY_CAP | C45: =_xll.EQNXTDZ($A$1,$B45,C$1,$B$1) -> 4.938 | D45: =_xll.EQNXTDZ($A$1,$B45,D$1,$B$1) -> 4.938 | E45: =_xll.EQNXTDZ($A$1,$B45,E$1,$B$1) -> 4.938 | F45: =_xll.EQNXTDZ($A$1,$B45,F$1,$B$1) -> 4.938 | G45: =_xll.EQNXTDZ($A$1,$B45,G$1,$B$1) -> 4.938 | H45: =_xll.EQNXTDZ($A$1,$B45,H$1,$B$1) -> 4.938 | I45: =_xll.EQNXTDZ($A$1,$B45,I$1,$B$1) -> 4.938 | J45: =_xll.EQNXTDZ($A$1,$B45,J$1,$B$1) -> 4.938 | ... BU45: =_xll.EQNXTDZ($A$1,$B45,BU$1,$B$1) -> 0
A46: Face Value | B46: QTR_FV | C46: =_xll.EQNXTDZ($A$1,$B46,C$1,$B$1) -> 10 | D46: =_xll.EQNXTDZ($A$1,$B46,D$1,$B$1) -> 10 | E46: =_xll.EQNXTDZ($A$1,$B46,E$1,$B$1) -> 10 | F46: =_xll.EQNXTDZ($A$1,$B46,F$1,$B$1) -> 10 | G46: =_xll.EQNXTDZ($A$1,$B46,G$1,$B$1) -> 10 | H46: =_xll.EQNXTDZ($A$1,$B46,H$1,$B$1) -> 10 | I46: =_xll.EQNXTDZ($A$1,$B46,I$1,$B$1) -> 10 | J46: =_xll.EQNXTDZ($A$1,$B46,J$1,$B$1) -> 10 | ... BU46: =_xll.EQNXTDZ($A$1,$B46,BU$1,$B$1) -> 0
A47: Month End | B47: BMONTH_MONTHEND | C47: =_xll.EQNXTDZ($A$1,$B47,C$5) -> 201206 | D47: =_xll.EQNXTDZ($A$1,$B47,D$5) -> 201209 | E47: =_xll.EQNXTDZ($A$1,$B47,E$5) -> 201212 | F47: =_xll.EQNXTDZ($A$1,$B47,F$5) -> 201303 | G47: =_xll.EQNXTDZ($A$1,$B47,G$5) -> 201306 | H47: =_xll.EQNXTDZ($A$1,$B47,H$5) -> 201309 | I47: =_xll.EQNXTDZ($A$1,$B47,I$5) -> 201312 | J47: =_xll.EQNXTDZ($A$1,$B47,J$5) -> 201403 | ... BU47: =_xll.EQNXTDZ($A$1,$B47,BU$5) -> 0
A48: Close | B48: BMONTH_CLOSE | C48: =_xll.EQNXTDZ($A$1,$B48,C$5) -> 763.65 | D48: =_xll.EQNXTDZ($A$1,$B48,D$5) -> 705.5 | E48: =_xll.EQNXTDZ($A$1,$B48,E$5) -> 660 | F48: =_xll.EQNXTDZ($A$1,$B48,F$5) -> 372.95 | G48: =_xll.EQNXTDZ($A$1,$B48,G$5) -> 330 | H48: =_xll.EQNXTDZ($A$1,$B48,H$5) -> 263 | I48: =_xll.EQNXTDZ($A$1,$B48,I$5) -> 314.4 | J48: =_xll.EQNXTDZ($A$1,$B48,J$5) -> 445 | ... BU48: =_xll.EQNXTDZ($A$1,$B48,BU$5) -> 0
A49: Total of Promoter and Promoter Group | B49: SHP_TPFTOTALPROMOTER | C49: =_xll.EQNXTDZ($A$1,$B49,C$5) -> 75 | D49: =_xll.EQNXTDZ($A$1,$B49,D$5) -> 75 | E49: =_xll.EQNXTDZ($A$1,$B49,E$5) -> 75 | F49: =_xll.EQNXTDZ($A$1,$B49,F$5) -> 75 | G49: =_xll.EQNXTDZ($A$1,$B49,G$5) -> 75 | H49: =_xll.EQNXTDZ($A$1,$B49,H$5) -> 75 | I49: =_xll.EQNXTDZ($A$1,$B49,I$5) -> 75 | J49: =_xll.EQNXTDZ($A$1,$B49,J$5) -> 75 | ... BU49: =_xll.EQNXTDZ($A$1,$B49,BU$5) -> 0
A50: Total of Promoter and Promoter Group Pledged | B50: SHP_PSHFTOTALPROMOTER | C50: =_xll.EQNXTDZ($A$1,$B50,C$5) -> 0 | D50: =_xll.EQNXTDZ($A$1,$B50,D$5) -> 0 | E50: =_xll.EQNXTDZ($A$1,$B50,E$5) -> 0 | F50: =_xll.EQNXTDZ($A$1,$B50,F$5) -> 0 | G50: =_xll.EQNXTDZ($A$1,$B50,G$5) -> 0 | H50: =_xll.EQNXTDZ($A$1,$B50,H$5) -> 0 | I50: =_xll.EQNXTDZ($A$1,$B50,I$5) -> 0 | J50: =_xll.EQNXTDZ($A$1,$B50,J$5) -> 0 | ... BU50: =_xll.EQNXTDZ($A$1,$B50,BU$5) -> 0
A54: Field Description | B54: Field Name | C54: =_xll.EQNXTDZ($A$1,$B54,C$5) -> 0 | D54: =_xll.EQNXTDZ($A$1,$B54,D$5) -> 0 | E54: =_xll.EQNXTDZ($A$1,$B54,E$5) -> 0 | F54: =_xll.EQNXTDZ($A$1,$B54,F$5) -> 0 | G54: =_xll.EQNXTDZ($A$1,$B54,G$5) -> 0 | H54: =_xll.EQNXTDZ($A$1,$B54,H$5) -> 0 | I54: =_xll.EQNXTDZ($A$1,$B54,I$5) -> 0 | J54: =_xll.EQNXTDZ($A$1,$B54,J$5) -> 0 | ... BU54: =_xll.EQNXTDZ($A$1,$B54,BU$5) -> 0
A55: Year End | B55: QTRB_DATE_END | C55: =_xll.EQNXTDZ($A$1,$B55,C$5,$B$1) -> 0 | D55: =_xll.EQNXTDZ($A$1,$B55,D$5,$B$1) -> 201209 | E55: =_xll.EQNXTDZ($A$1,$B55,E$5,$B$1) -> 0 | F55: =_xll.EQNXTDZ($A$1,$B55,F$5,$B$1) -> 201303 | G55: =_xll.EQNXTDZ($A$1,$B55,G$5,$B$1) -> 0 | H55: =_xll.EQNXTDZ($A$1,$B55,H$5,$B$1) -> 201309 | I55: =_xll.EQNXTDZ($A$1,$B55,I$5,$B$1) -> 0 | J55: =_xll.EQNXTDZ($A$1,$B55,J$5,$B$1) -> 201403 | ... BU55: =_xll.EQNXTDZ($A$1,$B55,BU$5,$B$1) -> 0
A56: Share Capital | B56: QTRB_SHARE_CAPITAL | C56: =_xll.EQNXTDZ($A$1,$B56,C$5,$B$1) -> 0 | D56: =_xll.EQNXTDZ($A$1,$B56,D$5,$B$1) -> 4.938 | E56: =_xll.EQNXTDZ($A$1,$B56,E$5,$B$1) -> 0 | F56: =_xll.EQNXTDZ($A$1,$B56,F$5,$B$1) -> 4.938 | G56: =_xll.EQNXTDZ($A$1,$B56,G$5,$B$1) -> 0 | H56: =_xll.EQNXTDZ($A$1,$B56,H$5,$B$1) -> 4.938 | I56: =_xll.EQNXTDZ($A$1,$B56,I$5,$B$1) -> 0 | J56: =_xll.EQNXTDZ($A$1,$B56,J$5,$B$1) -> 4.938 | ... BU56: =_xll.EQNXTDZ($A$1,$B56,BU$5,$B$1) -> 0
A57: Share Warrants & outstandings | B57: QTRB_SHAREWARNDOUT | C57: =_xll.EQNXTDZ($A$1,$B57,C$5,$B$1) -> 0 | D57: =_xll.EQNXTDZ($A$1,$B57,D$5,$B$1) -> 0 | E57: =_xll.EQNXTDZ($A$1,$B57,E$5,$B$1) -> 0 | F57: =_xll.EQNXTDZ($A$1,$B57,F$5,$B$1) -> 0 | G57: =_xll.EQNXTDZ($A$1,$B57,G$5,$B$1) -> 0 | H57: =_xll.EQNXTDZ($A$1,$B57,H$5,$B$1) -> 0 | I57: =_xll.EQNXTDZ($A$1,$B57,I$5,$B$1) -> 0 | J57: =_xll.EQNXTDZ($A$1,$B57,J$5,$B$1) -> 0 | ... BU57: =_xll.EQNXTDZ($A$1,$B57,BU$5,$B$1) -> 0
A58: Reserves & Surplus | B58: QTRB_RESERVE | C58: =_xll.EQNXTDZ($A$1,$B58,C$5,$B$1) -> 0 | D58: =_xll.EQNXTDZ($A$1,$B58,D$5,$B$1) -> 147.412 | E58: =_xll.EQNXTDZ($A$1,$B58,E$5,$B$1) -> 0 | F58: =_xll.EQNXTDZ($A$1,$B58,F$5,$B$1) -> 145.669 | G58: =_xll.EQNXTDZ($A$1,$B58,G$5,$B$1) -> 0 | H58: =_xll.EQNXTDZ($A$1,$B58,H$5,$B$1) -> 113.402 | I58: =_xll.EQNXTDZ($A$1,$B58,I$5,$B$1) -> 0 | J58: =_xll.EQNXTDZ($A$1,$B58,J$5,$B$1) -> 123.357 | ... BU58: =_xll.EQNXTDZ($A$1,$B58,BU$5,$B$1) -> 0
A59: Shareholder's Funds | B59: QTRB_SHAREHODERS_FUNDS | C59: =_xll.EQNXTDZ($A$1,$B59,C$5,$B$1) -> 0 | D59: =_xll.EQNXTDZ($A$1,$B59,D$5,$B$1) -> 152.35 | E59: =_xll.EQNXTDZ($A$1,$B59,E$5,$B$1) -> 0 | F59: =_xll.EQNXTDZ($A$1,$B59,F$5,$B$1) -> 150.607 | G59: =_xll.EQNXTDZ($A$1,$B59,G$5,$B$1) -> 0 | H59: =_xll.EQNXTDZ($A$1,$B59,H$5,$B$1) -> 118.34 | I59: =_xll.EQNXTDZ($A$1,$B59,I$5,$B$1) -> 0 | J59: =_xll.EQNXTDZ($A$1,$B59,J$5,$B$1) -> 128.295 | ... BU59: =_xll.EQNXTDZ($A$1,$B59,BU$5,$B$1) -> 0
A60: Minority Interest | B60: QTRB_MINORITY_INTEREST_BS | C60: =_xll.EQNXTDZ($A$1,$B60,C$5,$B$1) -> 0 | D60: =_xll.EQNXTDZ($A$1,$B60,D$5,$B$1) -> 0 | E60: =_xll.EQNXTDZ($A$1,$B60,E$5,$B$1) -> 0 | F60: =_xll.EQNXTDZ($A$1,$B60,F$5,$B$1) -> 0 | G60: =_xll.EQNXTDZ($A$1,$B60,G$5,$B$1) -> 0 | H60: =_xll.EQNXTDZ($A$1,$B60,H$5,$B$1) -> 0 | I60: =_xll.EQNXTDZ($A$1,$B60,I$5,$B$1) -> 0 | J60: =_xll.EQNXTDZ($A$1,$B60,J$5,$B$1) -> 0 | ... BU60: =_xll.EQNXTDZ($A$1,$B60,BU$5,$B$1) -> 0
A61: Long Term Borrowings | B61: QTRB_TOTAL_DEBTS | C61: =_xll.EQNXTDZ($A$1,$B61,C$5,$B$1) -> 0 | D61: =_xll.EQNXTDZ($A$1,$B61,D$5,$B$1) -> 15.686 | E61: =_xll.EQNXTDZ($A$1,$B61,E$5,$B$1) -> 0 | F61: =_xll.EQNXTDZ($A$1,$B61,F$5,$B$1) -> 23.086 | G61: =_xll.EQNXTDZ($A$1,$B61,G$5,$B$1) -> 0 | H61: =_xll.EQNXTDZ($A$1,$B61,H$5,$B$1) -> 20.2 | I61: =_xll.EQNXTDZ($A$1,$B61,I$5,$B$1) -> 0 | J61: =_xll.EQNXTDZ($A$1,$B61,J$5,$B$1) -> 17.314 | ... BU61: =_xll.EQNXTDZ($A$1,$B61,BU$5,$B$1) -> 0
A62: Secured Loans | B62: QTRB_SECURED_LOANS | C62: =_xll.EQNXTDZ($A$1,$B62,C$5,$B$1) -> 0 | D62: =_xll.EQNXTDZ($A$1,$B62,D$5,$B$1) -> 0 | E62: =_xll.EQNXTDZ($A$1,$B62,E$5,$B$1) -> 0 | F62: =_xll.EQNXTDZ($A$1,$B62,F$5,$B$1) -> 0 | G62: =_xll.EQNXTDZ($A$1,$B62,G$5,$B$1) -> 0 | H62: =_xll.EQNXTDZ($A$1,$B62,H$5,$B$1) -> 0 | I62: =_xll.EQNXTDZ($A$1,$B62,I$5,$B$1) -> 0 | J62: =_xll.EQNXTDZ($A$1,$B62,J$5,$B$1) -> 0 | ... BU62: =_xll.EQNXTDZ($A$1,$B62,BU$5,$B$1) -> 0
A63: Unsecured Loans | B63: QTRB_UNSECURED_LOANS_NF | C63: =_xll.EQNXTDZ($A$1,$B63,C$5,$B$1) -> 0 | D63: =_xll.EQNXTDZ($A$1,$B63,D$5,$B$1) -> 15.686 | E63: =_xll.EQNXTDZ($A$1,$B63,E$5,$B$1) -> 0 | F63: =_xll.EQNXTDZ($A$1,$B63,F$5,$B$1) -> 23.086 | G63: =_xll.EQNXTDZ($A$1,$B63,G$5,$B$1) -> 0 | H63: =_xll.EQNXTDZ($A$1,$B63,H$5,$B$1) -> 20.2 | I63: =_xll.EQNXTDZ($A$1,$B63,I$5,$B$1) -> 0 | J63: =_xll.EQNXTDZ($A$1,$B63,J$5,$B$1) -> 17.314 | ... BU63: =_xll.EQNXTDZ($A$1,$B63,BU$5,$B$1) -> 0
A64: Other Long Term Liabilities | B64: QTRB_OTHER_LT_LIABILITIES | C64: =_xll.EQNXTDZ($A$1,$B64,C$5,$B$1) -> 0 | D64: =_xll.EQNXTDZ($A$1,$B64,D$5,$B$1) -> 22.798 | E64: =_xll.EQNXTDZ($A$1,$B64,E$5,$B$1) -> 0 | F64: =_xll.EQNXTDZ($A$1,$B64,F$5,$B$1) -> 8.99 | G64: =_xll.EQNXTDZ($A$1,$B64,G$5,$B$1) -> 0 | H64: =_xll.EQNXTDZ($A$1,$B64,H$5,$B$1) -> 13.422 | I64: =_xll.EQNXTDZ($A$1,$B64,I$5,$B$1) -> 0 | J64: =_xll.EQNXTDZ($A$1,$B64,J$5,$B$1) -> 10.543 | ... BU64: =_xll.EQNXTDZ($A$1,$B64,BU$5,$B$1) -> 0
A65: Long Term Trade Payables | B65: QTRB_LT_TRADE_PAYABLE | C65: =_xll.EQNXTDZ($A$1,$B65,C$5,$B$1) -> 0 | D65: =_xll.EQNXTDZ($A$1,$B65,D$5,$B$1) -> 0 | E65: =_xll.EQNXTDZ($A$1,$B65,E$5,$B$1) -> 0 | F65: =_xll.EQNXTDZ($A$1,$B65,F$5,$B$1) -> 0 | G65: =_xll.EQNXTDZ($A$1,$B65,G$5,$B$1) -> 0 | H65: =_xll.EQNXTDZ($A$1,$B65,H$5,$B$1) -> 0 | I65: =_xll.EQNXTDZ($A$1,$B65,I$5,$B$1) -> 0 | J65: =_xll.EQNXTDZ($A$1,$B65,J$5,$B$1) -> 0 | ... BU65: =_xll.EQNXTDZ($A$1,$B65,BU$5,$B$1) -> 0
A66: Lont Term Provisions | B66: QTRB_LT_PROVISIONS | C66: =_xll.EQNXTDZ($A$1,$B66,C$5,$B$1) -> 0 | D66: =_xll.EQNXTDZ($A$1,$B66,D$5,$B$1) -> 8.953 | E66: =_xll.EQNXTDZ($A$1,$B66,E$5,$B$1) -> 0 | F66: =_xll.EQNXTDZ($A$1,$B66,F$5,$B$1) -> 11.671 | G66: =_xll.EQNXTDZ($A$1,$B66,G$5,$B$1) -> 0 | H66: =_xll.EQNXTDZ($A$1,$B66,H$5,$B$1) -> 11.381 | I66: =_xll.EQNXTDZ($A$1,$B66,I$5,$B$1) -> 0 | J66: =_xll.EQNXTDZ($A$1,$B66,J$5,$B$1) -> 6.806 | ... BU66: =_xll.EQNXTDZ($A$1,$B66,BU$5,$B$1) -> 0
... A97: Total Assets | B97: QTRB_TOTAL_APPLICATIONS | C97: =_xll.EQNXTDZ($A$1,$B97,C$5,$B$1) -> 0 | D97: =_xll.EQNXTDZ($A$1,$B97,D$5,$B$1) -> 199.787 | E97: =_xll.EQNXTDZ($A$1,$B97,E$5,$B$1) -> 0 | F97: =_xll.EQNXTDZ($A$1,$B97,F$5,$B$1) -> 194.354 | G97: =_xll.EQNXTDZ($A$1,$B97,G$5,$B$1) -> 0 | H97: =_xll.EQNXTDZ($A$1,$B97,H$5,$B$1) -> 163.343 | I97: =_xll.EQNXTDZ($A$1,$B97,I$5,$B$1) -> 0 | J97: =_xll.EQNXTDZ($A$1,$B97,J$5,$B$1) -> 162.958 | ... BU97: =_xll.EQNXTDZ($A$1,$B97,BU$5,$B$1) -> 0

Sheet Annual Raw
A1: 100147 | B1: X | C1: 200003 | D1: 200103 | E1: 200212 | F1: 200312 | G1: 200412 | H1: 200512 | I1: 200612 | J1: 200712 | K1: 200812 | L1: 200912 | M1: 201012 | N1: 201112 | O1: 201212 | P1: 201312 | Q1: 201412 | R1: 201512 | S1: 201612 | T1: 201712 | U1: 201812 | V1: 201912 | W1: 202012 | X1: 202112 | Y1: 202212 | Z1: 202312 | AA1: 202412 | AB1: 202512 | AC1: 202612 | AD1: 202712 | AE1: 202812 | AF1: 202912 | AG1: 203012
A3: Field Description | B3: Field Name
A4: Company Name | B4: CD_COMPNAME | C4: =_xll.EQNXTDZ(A1,B4,"L") -> John Cockerill India Ltd
A5: Year End | B5: PL_YEAR_END | C5: =_xll.EQNXTDZ($A$1,$B5,C$1,$B$1) -> 200003 | D5: =_xll.EQNXTDZ($A$1,$B5,D$1,$B$1) -> 200103 | E5: =_xll.EQNXTDZ($A$1,$B5,E$1,$B$1) -> 0 | F5: =_xll.EQNXTDZ($A$1,$B5,F$1,$B$1) -> 0 | G5: =_xll.EQNXTDZ($A$1,$B5,G$1,$B$1) -> 0 | H5: =_xll.EQNXTDZ($A$1,$B5,H$1,$B$1) -> 0 | I5: =_xll.EQNXTDZ($A$1,$B5,I$1,$B$1) -> 0 | J5: =_xll.EQNXTDZ($A$1,$B5,J$1,$B$1) -> 0 | ... AG5: =_xll.EQNXTDZ($A$1,$B5,AG$1,$B$1) -> 0
A6: Sales Turnover | B6: PL_TOTAL_GROSS_SALES | C6: =_xll.EQNXTDZ($A$1,$B6,C$1,$B$1) -> 94.467588 | D6: =_xll.EQNXTDZ($A$1,$B6,D$1,$B$1) -> 127.52504 | E6: =_xll.EQNXTDZ($A$1,$B6,E$1,$B$1) -> 0 | F6: =_xll.EQNXTDZ($A$1,$B6,F$1,$B$1) -> 0 | G6: =_xll.EQNXTDZ($A$1,$B6,G$1,$B$1) -> 0 | H6: =_xll.EQNXTDZ($A$1,$B6,H$1,$B$1) -> 0 | I6: =_xll.EQNXTDZ($A$1,$B6,I$1,$B$1) -> 0 | J6: =_xll.EQNXTDZ($A$1,$B6,J$1,$B$1) -> 0 | ... AG6: =_xll.EQNXTDZ($A$1,$B6,AG$1,$B$1) -> 0
A7: Less: Inter divisional transfers | B7: PL_INTER_DIV_TRF | C7: =_xll.EQNXTDZ($A$1,$B7,C$1,$B$1) -> 0 | D7: =_xll.EQNXTDZ($A$1,$B7,D$1,$B$1) -> 0 | E7: =_xll.EQNXTDZ($A$1,$B7,E$1,$B$1) -> 0 | F7: =_xll.EQNXTDZ($A$1,$B7,F$1,$B$1) -> 0 | G7: =_xll.EQNXTDZ($A$1,$B7,G$1,$B$1) -> 0 | H7: =_xll.EQNXTDZ($A$1,$B7,H$1,$B$1) -> 0 | I7: =_xll.EQNXTDZ($A$1,$B7,I$1,$B$1) -> 0 | J7: =_xll.EQNXTDZ($A$1,$B7,J$1,$B$1) -> 0 | ... AG7: =_xll.EQNXTDZ($A$1,$B7,AG$1,$B$1) -> 0
A8: Less: Sales Returns | B8: PL_SALES_RETURN | C8: =_xll.EQNXTDZ($A$1,$B8,C$1,$B$1) -> 0 | D8: =_xll.EQNXTDZ($A$1,$B8,D$1,$B$1) -> 0 | E8: =_xll.EQNXTDZ($A$1,$B8,E$1,$B$1) -> 0 | F8: =_xll.EQNXTDZ($A$1,$B8,F$1,$B$1) -> 0 | G8: =_xll.EQNXTDZ($A$1,$B8,G$1,$B$1) -> 0 | H8: =_xll.EQNXTDZ($A$1,$B8,H$1,$B$1) -> 0 | I8: =_xll.EQNXTDZ($A$1,$B8,I$1,$B$1) -> 0 | J8: =_xll.EQNXTDZ($A$1,$B8,J$1,$B$1) -> 0 | ... AG8: =_xll.EQNXTDZ($A$1,$B8,AG$1,$B$1) -> 0
A9: Less: Excise | B9: PL_EXCISE | C9: =_xll.EQNXTDZ($A$1,$B9,C$1,$B$1) -> 9.8270536 | D9: =_xll.EQNXTDZ($A$1,$B9,D$1,$B$1) -> 4.5848681 | E9: =_xll.EQNXTDZ($A$1,$B9,E$1,$B$1) -> 0 | F9: =_xll.EQNXTDZ($A$1,$B9,F$1,$B$1) -> 0 | G9: =_xll.EQNXTDZ($A$1,$B9,G$1,$B$1) -> 0 | H9: =_xll.EQNXTDZ($A$1,$B9,H$1,$B$1) -> 0 | I9: =_xll.EQNXTDZ($A$1,$B9,I$1,$B$1) -> 0 | J9: =_xll.EQNXTDZ($A$1,$B9,J$1,$B$1) -> 0 | ... AG9: =_xll.EQNXTDZ($A$1,$B9,AG$1,$B$1) -> 0
A10: Net Sales | B10: PL_NET_SALES | C10: =_xll.EQNXTDZ($A$1,$B10,C$1,$B$1) -> 84.640534 | D10: =_xll.EQNXTDZ($A$1,$B10,D$1,$B$1) -> 122.94017 | E10: =_xll.EQNXTDZ($A$1,$B10,E$1,$B$1) -> 0 | F10: =_xll.EQNXTDZ($A$1,$B10,F$1,$B$1) -> 0 | G10: =_xll.EQNXTDZ($A$1,$B10,G$1,$B$1) -> 0 | H10: =_xll.EQNXTDZ($A$1,$B10,H$1,$B$1) -> 0 | I10: =_xll.EQNXTDZ($A$1,$B10,I$1,$B$1) -> 0 | J10: =_xll.EQNXTDZ($A$1,$B10,J$1,$B$1) -> 0 | ... AG10: =_xll.EQNXTDZ($A$1,$B10,AG$1,$B$1) -> 0
A11: Increase/Decrease in Stock | B11: PL_INC_DEC_INVENTORY | C11: =_xll.EQNXTDZ($A$1,$B11,C$1,$B$1) -> -2.4551 | D11: =_xll.EQNXTDZ($A$1,$B11,D$1,$B$1) -> 10.9082 | E11: =_xll.EQNXTDZ($A$1,$B11,E$1,$B$1) -> 0 | F11: =_xll.EQNXTDZ($A$1,$B11,F$1,$B$1) -> 0 | G11: =_xll.EQNXTDZ($A$1,$B11,G$1,$B$1) -> 0 | H11: =_xll.EQNXTDZ($A$1,$B11,H$1,$B$1) -> 0 | I11: =_xll.EQNXTDZ($A$1,$B11,I$1,$B$1) -> 0 | J11: =_xll.EQNXTDZ($A$1,$B11,J$1,$B$1) -> 0 | ... AG11: =_xll.EQNXTDZ($A$1,$B11,AG$1,$B$1) -> 0
A12: Raw Material Consumed | B12: PL_RAW_MATRS_CONSUMED | C12: =_xll.EQNXTDZ($A$1,$B12,C$1,$B$1) -> 64.55574 | D12: =_xll.EQNXTDZ($A$1,$B12,D$1,$B$1) -> 64.487941 | E12: =_xll.EQNXTDZ($A$1,$B12,E$1,$B$1) -> 0 | F12: =_xll.EQNXTDZ($A$1,$B12,F$1,$B$1) -> 0 | G12: =_xll.EQNXTDZ($A$1,$B12,G$1,$B$1) -> 0 | H12: =_xll.EQNXTDZ($A$1,$B12,H$1,$B$1) -> 0 | I12: =_xll.EQNXTDZ($A$1,$B12,I$1,$B$1) -> 0 | J12: =_xll.EQNXTDZ($A$1,$B12,J$1,$B$1) -> 0 | ... AG12: =_xll.EQNXTDZ($A$1,$B12,AG$1,$B$1) -> 0
A13: Power & Fuel Cost | B13: PL_POWER_FUEL | C13: =_xll.EQNXTDZ($A$1,$B13,C$1,$B$1) -> 0.3935483 | D13: =_xll.EQNXTDZ($A$1,$B13,D$1,$B$1) -> 0.49143431 | E13: =_xll.EQNXTDZ($A$1,$B13,E$1,$B$1) -> 0 | F13: =_xll.EQNXTDZ($A$1,$B13,F$1,$B$1) -> 0 | G13: =_xll.EQNXTDZ($A$1,$B13,G$1,$B$1) -> 0 | H13: =_xll.EQNXTDZ($A$1,$B13,H$1,$B$1) -> 0 | I13: =_xll.EQNXTDZ($A$1,$B13,I$1,$B$1) -> 0 | J13: =_xll.EQNXTDZ($A$1,$B13,J$1,$B$1) -> 0 | ... AG13: =_xll.EQNXTDZ($A$1,$B13,AG$1,$B$1) -> 0
A14: Employee Cost | B14: PL_EMPLOYEES | C14: =_xll.EQNXTDZ($A$1,$B14,C$1,$B$1) -> 4.8360056 | D14: =_xll.EQNXTDZ($A$1,$B14,D$1,$B$1) -> 4.8083723 | E14: =_xll.EQNXTDZ($A$1,$B14,E$1,$B$1) -> 0 | F14: =_xll.EQNXTDZ($A$1,$B14,F$1,$B$1) -> 0 | G14: =_xll.EQNXTDZ($A$1,$B14,G$1,$B$1) -> 0 | H14: =_xll.EQNXTDZ($A$1,$B14,H$1,$B$1) -> 0 | I14: =_xll.EQNXTDZ($A$1,$B14,I$1,$B$1) -> 0 | J14: =_xll.EQNXTDZ($A$1,$B14,J$1,$B$1) -> 0 | ... AG14: =_xll.EQNXTDZ($A$1,$B14,AG$1,$B$1) -> 0
A15: Operating & Manufacturing Expenses | B15: PL_GEN_OTHER_MFG_EXPS | C15: =_xll.EQNXTDZ($A$1,$B15,C$1,$B$1) -> 13.841807 | D15: =_xll.EQNXTDZ($A$1,$B15,D$1,$B$1) -> 12.645187 | E15: =_xll.EQNXTDZ($A$1,$B15,E$1,$B$1) -> 0 | F15: =_xll.EQNXTDZ($A$1,$B15,F$1,$B$1) -> 0 | G15: =_xll.EQNXTDZ($A$1,$B15,G$1,$B$1) -> 0 | H15: =_xll.EQNXTDZ($A$1,$B15,H$1,$B$1) -> 0 | I15: =_xll.EQNXTDZ($A$1,$B15,I$1,$B$1) -> 0 | J15: =_xll.EQNXTDZ($A$1,$B15,J$1,$B$1) -> 0 | ... AG15: =_xll.EQNXTDZ($A$1,$B15,AG$1,$B$1) -> 0
A16: Cost of Software development | B16: PL_COST_SW | C16: =_xll.EQNXTDZ($A$1,$B16,C$1,$B$1) -> 0 | D16: =_xll.EQNXTDZ($A$1,$B16,D$1,$B$1) -> 0 | E16: =_xll.EQNXTDZ($A$1,$B16,E$1,$B$1) -> 0 | F16: =_xll.EQNXTDZ($A$1,$B16,F$1,$B$1) -> 0 | G16: =_xll.EQNXTDZ($A$1,$B16,G$1,$B$1) -> 0 | H16: =_xll.EQNXTDZ($A$1,$B16,H$1,$B$1) -> 0 | I16: =_xll.EQNXTDZ($A$1,$B16,I$1,$B$1) -> 0 | J16: =_xll.EQNXTDZ($A$1,$B16,J$1,$B$1) -> 0 | ... AG16: =_xll.EQNXTDZ($A$1,$B16,AG$1,$B$1) -> 0
... A36: Profit After Tax from Discontinued Operations | B36: PL_PAT_DIS_OP | C36: =_xll.EQNXTDZ($A$1,$B36,C$1,$B$1) -> 0 | D36: =_xll.EQNXTDZ($A$1,$B36,D$1,$B$1) -> 0 | E36: =_xll.EQNXTDZ($A$1,$B36,E$1,$B$1) -> 0 | F36: =_xll.EQNXTDZ($A$1,$B36,F$1,$B$1) -> 0 | G36: =_xll.EQNXTDZ($A$1,$B36,G$1,$B$1) -> 0 | H36: =_xll.EQNXTDZ($A$1,$B36,H$1,$B$1) -> 0 | I36: =_xll.EQNXTDZ($A$1,$B36,I$1,$B$1) -> 0 | J36: =_xll.EQNXTDZ($A$1,$B36,J$1,$B$1) -> 0 | ... AG36: =_xll.EQNXTDZ($A$1,$B36,AG$1,$B$1) -> 0
A39: Field Description | B39: Field Name
A40: Year End | B40: BS_YEAR_END | C40: =_xll.EQNXTDZ($A$1,$B40,C$1,$B$1) -> 200003 | D40: =_xll.EQNXTDZ($A$1,$B40,D$1,$B$1) -> 200103 | E40: =_xll.EQNXTDZ($A$1,$B40,E$1,$B$1) -> 0 | F40: =_xll.EQNXTDZ($A$1,$B40,F$1,$B$1) -> 0 | G40: =_xll.EQNXTDZ($A$1,$B40,G$1,$B$1) -> 0 | H40: =_xll.EQNXTDZ($A$1,$B40,H$1,$B$1) -> 0 | I40: =_xll.EQNXTDZ($A$1,$B40,I$1,$B$1) -> 0 | J40: =_xll.EQNXTDZ($A$1,$B40,J$1,$B$1) -> 0 | ... AG40: =_xll.EQNXTDZ($A$1,$B40,AG$1,$B$1) -> 0
A41: Share Capital | B41: BS_SHARE_CAPITAL | C41: =_xll.EQNXTDZ($A$1,$B41,C$1,$B$1) -> 4.937813 | D41: =_xll.EQNXTDZ($A$1,$B41,D$1,$B$1) -> 4.937813 | E41: =_xll.EQNXTDZ($A$1,$B41,E$1,$B$1) -> 0 | F41: =_xll.EQNXTDZ($A$1,$B41,F$1,$B$1) -> 0 | G41: =_xll.EQNXTDZ($A$1,$B41,G$1,$B$1) -> 0 | H41: =_xll.EQNXTDZ($A$1,$B41,H$1,$B$1) -> 0 | I41: =_xll.EQNXTDZ($A$1,$B41,I$1,$B$1) -> 0 | J41: =_xll.EQNXTDZ($A$1,$B41,J$1,$B$1) -> 0 | ... AG41: =_xll.EQNXTDZ($A$1,$B41,AG$1,$B$1) -> 0
A42: Share Warrants & Outstandings | B42: BS_SHAREWROUTST | C42: =_xll.EQNXTDZ($A$1,$B42,C$1,$B$1) -> 0 | D42: =_xll.EQNXTDZ($A$1,$B42,D$1,$B$1) -> 0 | E42: =_xll.EQNXTDZ($A$1,$B42,E$1,$B$1) -> 0 | F42: =_xll.EQNXTDZ($A$1,$B42,F$1,$B$1) -> 0 | G42: =_xll.EQNXTDZ($A$1,$B42,G$1,$B$1) -> 0 | H42: =_xll.EQNXTDZ($A$1,$B42,H$1,$B$1) -> 0 | I42: =_xll.EQNXTDZ($A$1,$B42,I$1,$B$1) -> 0 | J42: =_xll.EQNXTDZ($A$1,$B42,J$1,$B$1) -> 0 | ... AG42: =_xll.EQNXTDZ($A$1,$B42,AG$1,$B$1) -> 0
A43: Total Reserves | B43: BS_RESERVE | C43: =_xll.EQNXTDZ($A$1,$B43,C$1,$B$1) -> 40.619013 | D43: =_xll.EQNXTDZ($A$1,$B43,D$1,$B$1) -> 45.273175 | E43: =_xll.EQNXTDZ($A$1,$B43,E$1,$B$1) -> 0 | F43: =_xll.EQNXTDZ($A$1,$B43,F$1,$B$1) -> 0 | G43: =_xll.EQNXTDZ($A$1,$B43,G$1,$B$1) -> 0 | H43: =_xll.EQNXTDZ($A$1,$B43,H$1,$B$1) -> 0 | I43: =_xll.EQNXTDZ($A$1,$B43,I$1,$B$1) -> 0 | J43: =_xll.EQNXTDZ($A$1,$B43,J$1,$B$1) -> 0 | ... AG43: =_xll.EQNXTDZ($A$1,$B43,AG$1,$B$1) -> 0
A44: Shareholder's Funds | B44: BS_SHAREHODERS_FUNDS | C44: =_xll.EQNXTDZ($A$1,$B44,C$1,$B$1) -> 45.556826 | D44: =_xll.EQNXTDZ($A$1,$B44,D$1,$B$1) -> 50.210988 | E44: =_xll.EQNXTDZ($A$1,$B44,E$1,$B$1) -> 0 | F44: =_xll.EQNXTDZ($A$1,$B44,F$1,$B$1) -> 0 | G44: =_xll.EQNXTDZ($A$1,$B44,G$1,$B$1) -> 0 | H44: =_xll.EQNXTDZ($A$1,$B44,H$1,$B$1) -> 0 | I44: =_xll.EQNXTDZ($A$1,$B44,I$1,$B$1) -> 0 | J44: =_xll.EQNXTDZ($A$1,$B44,J$1,$B$1) -> 0 | ... AG44: =_xll.EQNXTDZ($A$1,$B44,AG$1,$B$1) -> 0
A45: Minority Interest | B45: BS_MINORITY_INTEREST | C45: =_xll.EQNXTDZ($A$1,$B45,C$1,$B$1) -> 0 | D45: =_xll.EQNXTDZ($A$1,$B45,D$1,$B$1) -> 0 | E45: =_xll.EQNXTDZ($A$1,$B45,E$1,$B$1) -> 0 | F45: =_xll.EQNXTDZ($A$1,$B45,F$1,$B$1) -> 0 | G45: =_xll.EQNXTDZ($A$1,$B45,G$1,$B$1) -> 0 | H45: =_xll.EQNXTDZ($A$1,$B45,H$1,$B$1) -> 0 | I45: =_xll.EQNXTDZ($A$1,$B45,I$1,$B$1) -> 0 | J45: =_xll.EQNXTDZ($A$1,$B45,J$1,$B$1) -> 0 | ... AG45: =_xll.EQNXTDZ($A$1,$B45,AG$1,$B$1) -> 0
A46: Long-Term Borrowings | B46: BS_LTRM_BORROWING | C46: =_xll.EQNXTDZ($A$1,$B46,C$1,$B$1) -> 0 | D46: =_xll.EQNXTDZ($A$1,$B46,D$1,$B$1) -> 0 | E46: =_xll.EQNXTDZ($A$1,$B46,E$1,$B$1) -> 0 | F46: =_xll.EQNXTDZ($A$1,$B46,F$1,$B$1) -> 0 | G46: =_xll.EQNXTDZ($A$1,$B46,G$1,$B$1) -> 0 | H46: =_xll.EQNXTDZ($A$1,$B46,H$1,$B$1) -> 0 | I46: =_xll.EQNXTDZ($A$1,$B46,I$1,$B$1) -> 0 | J46: =_xll.EQNXTDZ($A$1,$B46,J$1,$B$1) -> 0 | ... AG46: =_xll.EQNXTDZ($A$1,$B46,AG$1,$B$1) -> 0
A47: Secured Loans | B47: BS_SECURED_LOANS | C47: =_xll.EQNXTDZ($A$1,$B47,C$1,$B$1) -> 26.601813 | D47: =_xll.EQNXTDZ($A$1,$B47,D$1,$B$1) -> 29.762912 | E47: =_xll.EQNXTDZ($A$1,$B47,E$1,$B$1) -> 0 | F47: =_xll.EQNXTDZ($A$1,$B47,F$1,$B$1) -> 0 | G47: =_xll.EQNXTDZ($A$1,$B47,G$1,$B$1) -> 0 | H47: =_xll.EQNXTDZ($A$1,$B47,H$1,$B$1) -> 0 | I47: =_xll.EQNXTDZ($A$1,$B47,I$1,$B$1) -> 0 | J47: =_xll.EQNXTDZ($A$1,$B47,J$1,$B$1) -> 0 | ... AG47: =_xll.EQNXTDZ($A$1,$B47,AG$1,$B$1) -> 0
A48: Unsecured Loans | B48: BS_UNSECURED_LOANS_NF | C48: =_xll.EQNXTDZ($A$1,$B48,C$1,$B$1) -> 4.660122 | D48: =_xll.EQNXTDZ($A$1,$B48,D$1,$B$1) -> 3.8020562 | E48: =_xll.EQNXTDZ($A$1,$B48,E$1,$B$1) -> 0 | F48: =_xll.EQNXTDZ($A$1,$B48,F$1,$B$1) -> 0 | G48: =_xll.EQNXTDZ($A$1,$B48,G$1,$B$1) -> 0 | H48: =_xll.EQNXTDZ($A$1,$B48,H$1,$B$1) -> 0 | I48: =_xll.EQNXTDZ($A$1,$B48,I$1,$B$1) -> 0 | J48: =_xll.EQNXTDZ($A$1,$B48,J$1,$B$1) -> 0 | ... AG48: =_xll.EQNXTDZ($A$1,$B48,AG$1,$B$1) -> 0
A49: Deferred Tax Assets / Liabilities | B49: BS_NET_DEF_TAX_NF | C49: =_xll.EQNXTDZ($A$1,$B49,C$1,$B$1) -> 0 | D49: =_xll.EQNXTDZ($A$1,$B49,D$1,$B$1) -> 0 | E49: =_xll.EQNXTDZ($A$1,$B49,E$1,$B$1) -> 0 | F49: =_xll.EQNXTDZ($A$1,$B49,F$1,$B$1) -> 0 | G49: =_xll.EQNXTDZ($A$1,$B49,G$1,$B$1) -> 0 | H49: =_xll.EQNXTDZ($A$1,$B49,H$1,$B$1) -> 0 | I49: =_xll.EQNXTDZ($A$1,$B49,I$1,$B$1) -> 0 | J49: =_xll.EQNXTDZ($A$1,$B49,J$1,$B$1) -> 0 | ... AG49: =_xll.EQNXTDZ($A$1,$B49,AG$1,$B$1) -> 0
A50: Other Long Term Liabilities | B50: BS_OTH_LT_LIAB | C50: =_xll.EQNXTDZ($A$1,$B50,C$1,$B$1) -> 0 | D50: =_xll.EQNXTDZ($A$1,$B50,D$1,$B$1) -> 0 | E50: =_xll.EQNXTDZ($A$1,$B50,E$1,$B$1) -> 0 | F50: =_xll.EQNXTDZ($A$1,$B50,F$1,$B$1) -> 0 | G50: =_xll.EQNXTDZ($A$1,$B50,G$1,$B$1) -> 0 | H50: =_xll.EQNXTDZ($A$1,$B50,H$1,$B$1) -> 0 | I50: =_xll.EQNXTDZ($A$1,$B50,I$1,$B$1) -> 0 | J50: =_xll.EQNXTDZ($A$1,$B50,J$1,$B$1) -> 0 | ... AG50: =_xll.EQNXTDZ($A$1,$B50,AG$1,$B$1) -> 0
A51: Long Term Trade Payables | B51: BS_LT_TRADE_PAYABLES | C51: =_xll.EQNXTDZ($A$1,$B51,C$1,$B$1) -> 0 | D51: =_xll.EQNXTDZ($A$1,$B51,D$1,$B$1) -> 0 | E51: =_xll.EQNXTDZ($A$1,$B51,E$1,$B$1) -> 0 | F51: =_xll.EQNXTDZ($A$1,$B51,F$1,$B$1) -> 0 | G51: =_xll.EQNXTDZ($A$1,$B51,G$1,$B$1) -> 0 | H51: =_xll.EQNXTDZ($A$1,$B51,H$1,$B$1) -> 0 | I51: =_xll.EQNXTDZ($A$1,$B51,I$1,$B$1) -> 0 | J51: =_xll.EQNXTDZ($A$1,$B51,J$1,$B$1) -> 0 | ... AG51: =_xll.EQNXTDZ($A$1,$B51,AG$1,$B$1) -> 0
... A99: Estimated Capital Contracts Remaining | B99: BS_ESTIMATED_CAPITAL_CONTRACT | C99: =_xll.EQNXTDZ($A$1,$B99,C$1,$B$1) -> 0 | D99: =_xll.EQNXTDZ($A$1,$B99,D$1,$B$1) -> 0 | E99: =_xll.EQNXTDZ($A$1,$B99,E$1,$B$1) -> 0 | F99: =_xll.EQNXTDZ($A$1,$B99,F$1,$B$1) -> 0 | G99: =_xll.EQNXTDZ($A$1,$B99,G$1,$B$1) -> 0 | H99: =_xll.EQNXTDZ($A$1,$B99,H$1,$B$1) -> 0 | I99: =_xll.EQNXTDZ($A$1,$B99,I$1,$B$1) -> 0 | J99: =_xll.EQNXTDZ($A$1,$B99,J$1,$B$1) -> 0 | ... AG99: =_xll.EQNXTDZ($A$1,$B99,AG$1,$B$1) -> 0
A103: Field Description | B103: Field Name
A104: Equity Paid Up | B104: BS_EQUITY_PAIDUP | C104: =_xll.EQNXTDZ($A$1,$B104,C$1,$B$1) -> 4.937813 | D104: =_xll.EQNXTDZ($A$1,$B104,D$1,$B$1) -> 4.937813 | E104: =_xll.EQNXTDZ($A$1,$B104,E$1,$B$1) -> 0 | F104: =_xll.EQNXTDZ($A$1,$B104,F$1,$B$1) -> 0 | G104: =_xll.EQNXTDZ($A$1,$B104,G$1,$B$1) -> 0 | H104: =_xll.EQNXTDZ($A$1,$B104,H$1,$B$1) -> 0 | I104: =_xll.EQNXTDZ($A$1,$B104,I$1,$B$1) -> 0 | J104: =_xll.EQNXTDZ($A$1,$B104,J$1,$B$1) -> 0 | ... AG104: =_xll.EQNXTDZ($A$1,$B104,AG$1,$B$1) -> 0
A105: Face Value | B105: BS_FACE_VALUE | C105: =_xll.EQNXTDZ($A$1,$B105,C$1,$B$1) -> 10 | D105: =_xll.EQNXTDZ($A$1,$B105,D$1,$B$1) -> 10 | E105: =_xll.EQNXTDZ($A$1,$B105,E$1,$B$1) -> 0 | F105: =_xll.EQNXTDZ($A$1,$B105,F$1,$B$1) -> 0 | G105: =_xll.EQNXTDZ($A$1,$B105,G$1,$B$1) -> 0 | H105: =_xll.EQNXTDZ($A$1,$B105,H$1,$B$1) -> 0 | I105: =_xll.EQNXTDZ($A$1,$B105,I$1,$B$1) -> 0 | J105: =_xll.EQNXTDZ($A$1,$B105,J$1,$B$1) -> 0 | ... AG105: =_xll.EQNXTDZ($A$1,$B105,AG$1,$B$1) -> 0
A106: Close Price (Unit Curr.) | B106: FH_YEAR_PRICE | C106: =_xll.EQNXTDZ($A$1,$B106,C$1,$B$1) -> 16.5 | D106: =_xll.EQNXTDZ($A$1,$B106,D$1,$B$1) -> 15.85 | E106: =_xll.EQNXTDZ($A$1,$B106,E$1,$B$1) -> 0 | F106: =_xll.EQNXTDZ($A$1,$B106,F$1,$B$1) -> 0 | G106: =_xll.EQNXTDZ($A$1,$B106,G$1,$B$1) -> 0 | H106: =_xll.EQNXTDZ($A$1,$B106,H$1,$B$1) -> 0 | I106: =_xll.EQNXTDZ($A$1,$B106,I$1,$B$1) -> 0 | J106: =_xll.EQNXTDZ($A$1,$B106,J$1,$B$1) -> 0 | ... AG106: =_xll.EQNXTDZ($A$1,$B106,AG$1,$B$1) -> 0
A107: High Price (Unit Curr.) | B107: FH_HIGH | C107: =_xll.EQNXTDZ($A$1,$B107,C$1,$B$1) -> 46 | D107: =_xll.EQNXTDZ($A$1,$B107,D$1,$B$1) -> 28.95 | E107: =_xll.EQNXTDZ($A$1,$B107,E$1,$B$1) -> 0 | F107: =_xll.EQNXTDZ($A$1,$B107,F$1,$B$1) -> 0 | G107: =_xll.EQNXTDZ($A$1,$B107,G$1,$B$1) -> 0 | H107: =_xll.EQNXTDZ($A$1,$B107,H$1,$B$1) -> 0 | I107: =_xll.EQNXTDZ($A$1,$B107,I$1,$B$1) -> 0 | J107: =_xll.EQNXTDZ($A$1,$B107,J$1,$B$1) -> 0 | ... AG107: =_xll.EQNXTDZ($A$1,$B107,AG$1,$B$1) -> 0
A108: Low Price (Unit Curr.) | B108: FH_LOW | C108: =_xll.EQNXTDZ($A$1,$B108,C$1,$B$1) -> 13.85 | D108: =_xll.EQNXTDZ($A$1,$B108,D$1,$B$1) -> 10.75 | E108: =_xll.EQNXTDZ($A$1,$B108,E$1,$B$1) -> 0 | F108: =_xll.EQNXTDZ($A$1,$B108,F$1,$B$1) -> 0 | G108: =_xll.EQNXTDZ($A$1,$B108,G$1,$B$1) -> 0 | H108: =_xll.EQNXTDZ($A$1,$B108,H$1,$B$1) -> 0 | I108: =_xll.EQNXTDZ($A$1,$B108,I$1,$B$1) -> 0 | J108: =_xll.EQNXTDZ($A$1,$B108,J$1,$B$1) -> 0 | ... AG108: =_xll.EQNXTDZ($A$1,$B108,AG$1,$B$1) -> 0
A109: Market Capitalization | B109: FH_MCAP | C109: =_xll.EQNXTDZ($A$1,$B109,C$1,$B$1) -> 8.1473915 | D109: =_xll.EQNXTDZ($A$1,$B109,D$1,$B$1) -> 7.8264336 | E109: =_xll.EQNXTDZ($A$1,$B109,E$1,$B$1) -> 0 | F109: =_xll.EQNXTDZ($A$1,$B109,F$1,$B$1) -> 0 | G109: =_xll.EQNXTDZ($A$1,$B109,G$1,$B$1) -> 0 | H109: =_xll.EQNXTDZ($A$1,$B109,H$1,$B$1) -> 0 | I109: =_xll.EQNXTDZ($A$1,$B109,I$1,$B$1) -> 0 | J109: =_xll.EQNXTDZ($A$1,$B109,J$1,$B$1) -> 0 | ... AG109: =_xll.EQNXTDZ($A$1,$B109,AG$1,$B$1) -> 0
