Workbook

Sheet Template
A1: =+'Annual Raw'!C4 -> KSB Ltd. | B1: 36951 | C1: =EOMONTH(B1,12) -> 37346 | D1: 37591 | E1: =EOMONTH(D1,12) -> 37986 | F1: =EOMONTH(E1,12) -> 38352 | G1: =EOMONTH(F1,12) -> 38717 | H1: =EOMONTH(G1,12) -> 39082 | I1: =EOMONTH(H1,12) -> 39447 | J1: =EOMONTH(I1,12) -> 39813 | K1: =EOMONTH(J1,12) -> 40178 | L1: =EOMONTH(K1,12) -> 40543 | ... AE1: =EOMONTH(AD1,12) -> 47483 | AH1: QTR | AI1: 41061 | AJ1: 41153 | AK1: 41244 | AL1: 41334 | AM1: 41426 | AN1: 41518 | AO1: 41609 | AP1: 41699 | AQ1: 41791 | AR1: 41883 | AS1: 41974 | AT1: 42064 | AU1: 42156 | AV1: 42248 | AW1: 42339 | AX1: 42430 | AY1: 42522 | AZ1: 42614 | BA1: 42705 | BB1: 42795 | BC1: 42887 | BD1: 42979 | BE1: 43070 | BF1: 43160 | BG1: 43252 | BH1: 43344 | BI1: 43435 | BJ1: 43525 | BK1: 43617 | BL1: 43709 | BM1: 43800 | BN1: 43891 | BO1: 43983 | BP1: 44075 | BQ1: =EOMONTH(BP1,3) -> 44196 | BR1: =EOMONTH(BQ1,3) -> 44286 | BS1: =EOMONTH(BR1,3) -> 44377 | BT1: =EOMONTH(BS1,3) -> 44469 | BU1: =EOMONTH(BT1,3) -> 44561 | BV1: =EOMONTH(BU1,3) -> 44651 | BW1: =EOMONTH(BV1,3) -> 44742 | BX1: =EOMONTH(BW1,3) -> 44834 | ... DA1: =EOMONTH(CZ1,3) -> 47483 | DD1: HISTORICAL ESTIMATES | DE1: 46022
A2: Presentation Data (Start)
A4: REVENUE FROM OPERATIONS
A5: Pumps | U5: 1087.8 | V5: 1008 | W5: 1262 | X5: 1521.9 | Y5: 1896.8 | Z5: 2108.1 | AA5: =SUM(CH5:CK5) -> 2215 | BK5: 247.6 | BL5: 315.5 | BM5: 281.5 | BN5: 216.7 | BO5: 189.2 | BP5: 301.6 | BQ5: 300.5 | BR5: 317.7 | BS5: 262.3 | BT5: 305.4 | BU5: 376.6 | BV5: 349.6 | BW5: 381.4 | BX5: 351.4 | BY5: 439.5 | BZ5: 412.9 | CA5: 501.8 | CB5: 473.8 | CC5: 508.3 | CD5: 450 | CE5: 540.6 | CF5: 515.3 | CG5: 602.2 | CH5: 473.8 | CI5: 551.2 | CJ5: 533.1 | CK5: 656.9 | CL5: 499.5
A6: Valves | U6: 208.1 | V6: 201 | W6: 237 | X6: 302.3 | Y6: 353.6 | Z6: 428.8 | AA6: =SUM(CH6:CK6) -> 485.1 | BK6: 55.5 | BL6: 50.5 | BM6: 55.8 | BN6: 40.7 | BO6: 29.9 | BP6: 60.8 | BQ6: 69.6 | BR6: 64.1 | BS6: 41.3 | BT6: 63.1 | BU6: 68.5 | BV6: 68.5 | BW6: 67.4 | BX6: 80.5 | BY6: 85.9 | BZ6: 77.3 | CA6: 90.3 | CB6: 90.9 | CC6: 95.1 | CD6: 95 | CE6: 106.4 | CF6: 102.2 | CG6: 125.2 | CH6: 122.4 | CI6: 116.3 | CJ6: 117.9 | CK6: 128.5 | CL6: 102.5
A7: Less Inter Segment Revenue | U7: 1.992 | V7: 0.885 | W7: 1.709 | X7: 2.24 | Y7: 3.162 | Z7: 3.814 | AA7: =SUM(CH7:CK7) -> 4.4 | BK7: 1.3 | BL7: 0.2 | BM7: 0.3 | BN7: 0.4 | BO7: 0.2 | BP7: 0.1 | BQ7: 0.2 | BR7: 0.2 | BS7: 0.6 | BT7: 0.4 | BU7: 0.5 | BV7: 0.4 | BW7: 0.4 | BX7: 0.6 | BY7: 0.8 | BZ7: 0.6 | CA7: 0.8 | CB7: 1 | CC7: 0.8 | CD7: 0.8 | CE7: 1 | CF7: 1 | CG7: 1 | CH7: 0.8 | CI7: 0.8 | CJ7: 1.4 | CK7: 1.4 | CL7: 0.7
A8: Net Revenue/Inc. From Ops. | U8: =+U5+U6-U7 -> 1293.908 | V8: =+V5+V6-V7 -> 1208.115 | W8: =+W5+W6-W7 -> 1497.291 | X8: =+X5+X6-X7 -> 1821.96 | Y8: =+Y5+Y6-Y7 -> 2247.238 | Z8: =+Z5+Z6-Z7 -> 2533.086 | AA8: =+AA5+AA6-AA7 -> 2695.7 | BK8: =SUM(BK5:BK6)-BK7 -> 301.8 | BL8: =SUM(BL5:BL6)-BL7 -> 365.8 | BM8: =SUM(BM5:BM6)-BM7 -> 337 | BN8: =SUM(BN5:BN6)-BN7 -> 257 | BO8: =SUM(BO5:BO6)-BO7 -> 218.9 | BP8: =SUM(BP5:BP6)-BP7 -> 362.3 | BQ8: =SUM(BQ5:BQ6)-BQ7 -> 369.9 | BR8: =SUM(BR5:BR6)-BR7 -> 381.6 | ... CL8: =SUM(CL5:CL6)-CL7 -> 601.3
A9: Checskum | U9: =+U46-U8 -> 0 | V9: =+V46-V8 -> 0 | W9: =+W46-W8 -> 0 | X9: =+X46-X8 -> 0 | Y9: =+Y46-Y8 -> 0 | Z9: =+Z46-Z8 -> 0 | AA9: =+AA46-AA8 -> 0.028 | BK9: =+BK46-BK8 -> 0 | BL9: =+BL46-BL8 -> 0 | BM9: =+BM46-BM8 -> 0 | BN9: =+BN46-BN8 -> 0 | BO9: =+BO46-BO8 -> 0 | BP9: =+BP46-BP8 -> 0 | BQ9: =+BQ46-BQ8 -> 0 | BR9: =+BR46-BR8 -> 0 | ... CL9: =+CL46-CL8 -> 0
A11: Growth (%)
A12: Pumps | V12: =+V5/U5-1 -> -0.073359073 | W12: =+W5/V5-1 -> 0.25198413 | X12: =+X5/W5-1 -> 0.20594295 | Y12: =+Y5/X5-1 -> 0.24633682 | Z12: =+Z5/Y5-1 -> 0.11139814 | AA12: =+AA5/Z5-1 -> 0.050709169 | BO12: =+BO5/BK5-1 -> -0.2358643 | BP12: =+BP5/BL5-1 -> -0.044057052 | BQ12: =+BQ5/BM5-1 -> 0.06749556 | BR12: =+BR5/BN5-1 -> 0.46608214 | BS12: =+BS5/BO5-1 -> 0.38636364 | BT12: =+BT5/BP5-1 -> 0.012599469 | BU12: =+BU5/BQ5-1 -> 0.25324459 | BV12: =+BV5/BR5-1 -> 0.10040919 | ... CL12: =+CL5/CH5-1 -> 0.054242296
A13: Valves | V13: =+V6/U6-1 -> -0.034118212 | W13: =+W6/V6-1 -> 0.17910448 | X13: =+X6/W6-1 -> 0.27552743 | Y13: =+Y6/X6-1 -> 0.16969897 | Z13: =+Z6/Y6-1 -> 0.21266968 | AA13: =+AA6/Z6-1 -> 0.13129664 | BO13: =+BO6/BK6-1 -> -0.46126126 | BP13: =+BP6/BL6-1 -> 0.2039604 | BQ13: =+BQ6/BM6-1 -> 0.24731183 | BR13: =+BR6/BN6-1 -> 0.57493857 | BS13: =+BS6/BO6-1 -> 0.3812709 | BT13: =+BT6/BP6-1 -> 0.037828947 | BU13: =+BU6/BQ6-1 -> -0.015804598 | BV13: =+BV6/BR6-1 -> 0.068642746 | ... CL13: =+CL6/CH6-1 -> -0.1625817
A15: PROFIT / LOSS BEFORE INTEREST & TAX
A16: Pumps | U16: 124.6 | V16: 127.8 | W16: 162.8 | X16: 197.2 | Y16: 214.8 | Z16: 231.3 | AA16: =SUM(CH16:CK16) -> 284.7 | BK16: 22.1 | BL16: 30 | BM16: 50 | BN16: 16.9 | BO16: 9.3 | BP16: 46.6 | BQ16: 55 | BR16: 46.8 | BS16: 31.3 | BT16: 40.3 | BU16: 44.4 | BV16: 43.1 | BW16: 54 | BX16: 40.8 | BY16: 59.3 | BZ16: 41.3 | CA16: 64.4 | CB16: 52.4 | CC16: 56.7 | CD16: 36.2 | CE16: 66.3 | CF16: 63.2 | CG16: 65.6 | CH16: 41.5 | CI16: 64 | CJ16: 70.7 | CK16: 108.5 | CL16: 39.3
A17: Valves | U17: 14.1 | V17: 16 | W17: 17.2 | X17: 27 | Y17: 45.1 | Z17: 64.8 | AA17: =SUM(CH17:CK17) -> 69.7 | BK17: 3.4 | BL17: 2.9 | BM17: 5.5 | BN17: 2.3 | BO17: -0.5 | BP17: 7.5 | BQ17: 6.7 | BR17: 7.1 | BS17: 0.6 | BT17: 4.5 | BU17: 5 | BV17: 5.9 | BW17: 3.7 | BX17: 7.8 | BY17: 9.6 | BZ17: 9.5 | CA17: 11.7 | CB17: 10.5 | CC17: 13.4 | CD17: 15.5 | CE17: 15.3 | CF17: 11.7 | CG17: 22.3 | CH17: 19.4 | CI17: 17.8 | CJ17: 14.8 | CK17: 17.7 | CL17: 8.4
A18: Less :Finance Cost | U18: 5.3 | V18: 3.4 | W18: 5 | X18: 6.1 | Y18: 5.3 | Z18: 2.7 | AA18: =SUM(CH18:CK18) -> 3 | BK18: 1 | BL18: 1.2 | BM18: 2.2 | BN18: 0.8 | BO18: 0.9 | BP18: 1 | BQ18: 0.7 | BR18: 0.9 | BS18: 1 | BT18: 1.2 | BU18: 1.9 | BV18: 0.9 | BW18: 1.4 | BX18: 1.3 | BY18: 2.5 | BZ18: 0.8 | CA18: 0.9 | CB18: 2 | CC18: 1.6 | CD18: 0.9 | CE18: 0.8 | CF18: 0.6 | CG18: 0.4 | CH18: 0.8 | CI18: 0.7 | CJ18: 0.7 | CK18: 0.8 | CL18: 0.6
A19: Other Un-Allocable Expenditure Net Off + share of asscicate | U19: -7.6 | V19: -16.6 | W19: -26 | X19: -27.2 | Y19: -25.7 | Z19: -37.3 | AA19: =SUM(CH19:CK19) -> -9.1 | BK19: -15.3 | BL19: -2 | BM19: 11 | BN19: -2.3 | BO19: -2.5 | BP19: -4.7 | BQ19: -7.1 | BR19: -6.4 | BS19: -6.2 | BT19: -7.2 | BU19: -6.2 | BV19: -6.6 | BW19: -7.7 | BX19: -6.1 | BY19: -6.8 | BZ19: -5.2 | CA19: -7.9 | CB19: =-3.6-2.7 -> -6.3 | CC19: -6.3 | CD19: -8.9 | CE19: -9.1 | CF19: =-5.6-3.2 -> -8.8 | CG19: -10.5 | CH19: -8.9 | CI19: -11.1 | CJ19: -6.3 | CK19: 17.2 | CL19: -6.2
A20: Total Profit Before Tax | U20: =SUM(U16:U17)-U18-U19 -> 141 | V20: =SUM(V16:V17)-V18-V19 -> 157 | W20: =SUM(W16:W17)-W18-W19 -> 201 | X20: =SUM(X16:X17)-X18-X19 -> 245.3 | Y20: =SUM(Y16:Y17)-Y18-Y19 -> 280.3 | Z20: =SUM(Z16:Z17)-Z18-Z19 -> 330.7 | AA20: =SUM(AA16:AA17)-AA18-AA19 -> 360.5 | BK20: =SUM(BK16:BK17)-BK18-BK19 -> 39.8 | BL20: =SUM(BL16:BL17)-BL18-BL19 -> 33.7 | BM20: =SUM(BM16:BM17)-BM18-BM19 -> 42.3 | BN20: =SUM(BN16:BN17)-BN18-BN19 -> 20.7 | BO20: =SUM(BO16:BO17)-BO18-BO19 -> 10.4 | BP20: =SUM(BP16:BP17)-BP18-BP19 -> 57.8 | BQ20: =SUM(BQ16:BQ17)-BQ18-BQ19 -> 68.1 | BR20: =SUM(BR16:BR17)-BR18-BR19 -> 59.4 | ... CL20: =SUM(CL16:CL17)-CL18-CL19 -> 53.3
A21: Checksum | U21: =+U20-(U74+U83+U82) -> 0.511 | V21: =+V20-(V74+V83+V82) -> 0.043 | W21: =+W20-(W74+W83+W82) -> -0.007 | X21: =+X20-(X74+X83+X82) -> 0.031 | Y21: =+Y20-(Y74+Y83+Y82) -> -0.049 | Z21: =+Z20-(Z74+Z83+Z82) -> 0.05 | AA21: =+AA20-(AA74+AA83+AA82) -> 0.038 | BK21: =+BK20-(BK74+BK83+BK82) -> 0.1 | BL21: =+BL20-(BL74+BL83+BL82) -> -0.4 | BM21: =+BM20-(BM74+BM83+BM82) -> 0.8 | BN21: =+BN20-(BN74+BN83+BN82) -> 0 | BO21: =+BO20-(BO74+BO83+BO82) -> 0.1 | BP21: =+BP20-(BP74+BP83+BP82) -> -0.1 | BQ21: =+BQ20-(BQ74+BQ83+BQ82) -> 0 | BR21: =+BR20-(BR74+BR83+BR82) -> 0 | ... CL21: =+CL20-(CL74+CL83+CL82) -> 0
A23: PBIT Margins (%)
A24: Pumps | U24: =+U16/U5 -> 0.11454311 | V24: =+V16/V5 -> 0.12678571 | W24: =+W16/W5 -> 0.12900158 | X24: =+X16/X5 -> 0.12957487 | Y24: =+Y16/Y5 -> 0.11324336 | Z24: =+Z16/Z5 -> 0.10971965 | AA24: =+AA16/AA5 -> 0.12853273 | BK24: =+BK16/BK5 -> 0.089256866 | BL24: =+BL16/BL5 -> 0.095087163 | BM24: =+BM16/BM5 -> 0.17761989 | BN24: =+BN16/BN5 -> 0.077988002 | BO24: =+BO16/BO5 -> 0.049154334 | BP24: =+BP16/BP5 -> 0.15450928 | BQ24: =+BQ16/BQ5 -> 0.18302829 | BR24: =+BR16/BR5 -> 0.14730878 | ... CL24: =+CL16/CL5 -> 0.078678679
A25: Valves | U25: =+U17/U6 -> 0.067755887 | V25: =+V17/V6 -> 0.07960199 | W25: =+W17/W6 -> 0.07257384 | X25: =+X17/X6 -> 0.08931525 | Y25: =+Y17/Y6 -> 0.12754525 | Z25: =+Z17/Z6 -> 0.1511194 | AA25: =+AA17/AA6 -> 0.14368172 | BK25: =+BK17/BK6 -> 0.061261261 | BL25: =+BL17/BL6 -> 0.057425743 | BM25: =+BM17/BM6 -> 0.098566308 | BN25: =+BN17/BN6 -> 0.056511057 | BO25: =+BO17/BO6 -> -0.016722408 | BP25: =+BP17/BP6 -> 0.12335526 | BQ25: =+BQ17/BQ6 -> 0.096264368 | BR25: =+BR17/BR6 -> 0.11076443 | ... CL25: =+CL17/CL6 -> 0.08195122
A28: Orderbook
A29: Nuclear | X29: =+BY29 -> 700 | Y29: 968.7 | Z29: 1282.8 | AA29: 1282.8 | BW29: 600 | BX29: 650 | BY29: 700 | BZ29: 750 | CA29: 750 | CB29: 1020 | CC29: 920 | CD29: 915 | CE29: 915 | CF29: 920 | CG29: 920 | CH29: 1310 | CI29: 1313 | CJ29: 1314 | CK29: 1315
A30: Legacy Business | X30: =+BY30 -> 1050 | Y30: 1175.5 | Z30: 967.5 | AA30: 967.5 | BW30: 850 | BX30: 950 | BY30: 1050 | BZ30: 1050 | CA30: 1200 | CB30: 1180 | CC30: 1180 | CD30: 1235 | CE30: 1265 | CF30: 1330 | CG30: 1380 | CH30: 1140 | CI30: 1384 | CJ30: 1325 | CK30: 1385
A31: Total OB | X31: =+BY31 -> 1750 | Y31: =SUM(Y29:Y30) -> 2144.2 | Z31: =SUM(Z29:Z30) -> 2250.3 | AA31: =+CK31 -> 2700 | BW31: =SUM(BW29:BW30) -> 1450 | BX31: =SUM(BX29:BX30) -> 1600 | BY31: =SUM(BY29:BY30) -> 1750 | BZ31: =SUM(BZ29:BZ30) -> 1800 | CA31: =SUM(CA29:CA30) -> 1950 | CB31: =SUM(CB29:CB30) -> 2200 | CC31: =SUM(CC29:CC30) -> 2100 | CD31: =SUM(CD29:CD30) -> 2150 | ... CK31: =SUM(CK29:CK30) -> 2700
A33: Opening | Y33: =+X31 -> 1750 | Z33: =+Y31 -> 2144.2 | AA33: =+Z31 -> 2250.3 | AB33: =+AA36 -> 2700 | AC33: =+AB36 -> 2951.7281 | AD33: =+AC36 -> 3241.8579 | AE33: =+AD36 -> 3564.6517 | BX33: =+BW36 -> 1450 | BY33: =+BX36 -> 1600 | BZ33: =+BY36 -> 1750 | CA33: =+BZ36 -> 1800 | CB33: =+CA36 -> 1950 | CC33: =+CB36 -> 2200 | CD33: =+CC36 -> 2100 | CE33: =+CD36 -> 2150 | ... DA33: =+CZ36 -> 3817.7555
A34: Additions | Y34: =+Y36+Y35-Y33 -> 2641.438 | Z34: =+Z36+Z35-Z33 -> 2639.186 | AA34: =+AA36+AA35-AA33 -> 3145.428 | AB34: =+AB36+AB35-AB33 -> 3307.6222 | AC34: =+AC36+AC35-AC33 -> 3745.797 | AD34: =+AD36+AD35-AD33 -> 4120.3767 | AE34: =+AE36+AE35-AE33 -> 4532.4144 | BX34: =+BX36+BX35-BX33 -> 581.3 | BY34: =+BY36+BY35-BY33 -> 674.6 | BZ34: =+BZ36+BZ35-BZ33 -> 539.6 | CA34: =+CA36+CA35-CA33 -> 741.3 | CB34: =+CB36+CB35-CB33 -> 813.7 | CC34: =+CC36+CC35-CC33 -> 502.6 | CD34: =+CD36+CD35-CD33 -> 594.2 | CE34: =+CE36+CE35-CE33 -> 676 | ... CK34: =+CK36+CK35-CK33 -> 845 | CL34: =+CH34*(1+CL38) -> 819.94 | CM34: =+CI34*(1+CM38) -> 1005.07 | CN34: =+CJ34*(1+CN38) -> 650.76 | CO34: =+CK34*(1+CO38) -> 929.5 | CP34: =+CL34*(1+CP38) -> 901.934 | CQ34: =+CM34*(1+CQ38) -> 1105.577 | CR34: =+CN34*(1+CR38) -> 715.836 | CS34: =+CO34*(1+CS38) -> 1022.45 | ... DA34: =+CW34*(1+DA38) -> 1237.1645
A35: Execution | Y35: =+Y46 -> 2247.238 | Z35: =+Z46 -> 2533.086 | AA35: =+AA46 -> 2695.728 | AB35: =+AB44 -> 3055.894 | AC35: =+AC44 -> 3455.6673 | AD35: =+AD44 -> 3797.5828 | AE35: =+AE44 -> 4176.3334 | BX35: =+BX46 -> 431.3 | BY35: =+BY46 -> 524.6 | BZ35: =+BZ46 -> 489.6 | CA35: =+CA46 -> 591.3 | CB35: =+CB46 -> 563.7 | CC35: =+CC46 -> 602.6 | CD35: =+CD46 -> 544.2 | CE35: =+CE46 -> 646 | ... CK35: =+CK46 -> 784 | CL35: =+CL33*CL39 -> 698.94783 | CM35: =+CM33*CM39 -> 767.6553 | CN35: =+CN33*CN39 -> 832.26117 | CO35: =+CO33*CO39 -> 854.67756 | CP35: =+CP33*CP39 -> 764.11258 | CQ35: =+CQ33*CQ39 -> 840.73579 | CR35: =+CR33*CR39 -> 912.80503 | CS35: =+CS33*CS39 -> 938.01389 | ... DA35: =+DA33*DA39 -> 1134.1873
A36: Closing | X36: =+X31 -> 1750 | Y36: =+Y31 -> 2144.2 | Z36: =+Z31 -> 2250.3 | AA36: =+AA31 -> 2700 | AB36: =+CO36 -> 2951.7281 | AC36: =+CS36 -> 3241.8579 | AD36: =+CW36 -> 3564.6517 | AE36: =+DA36 -> 3920.7327 | BW36: =+BW31 -> 1450 | BX36: =+BX31 -> 1600 | BY36: =+BY31 -> 1750 | BZ36: =+BZ31 -> 1800 | CA36: =+CA31 -> 1950 | CB36: =+CB31 -> 2200 | CC36: =+CC31 -> 2100 | CD36: =+CD31 -> 2150 | ... CK36: =+CK31 -> 2700 | CL36: =+CL33+CL34-CL35 -> 2820.9922 | CM36: =+CM33+CM34-CM35 -> 3058.4069 | CN36: =+CN33+CN34-CN35 -> 2876.9057 | CO36: =+CO33+CO34-CO35 -> 2951.7281 | CP36: =+CP33+CP34-CP35 -> 3089.5496 | CQ36: =+CQ33+CQ34-CQ35 -> 3354.3908 | CR36: =+CR33+CR34-CR35 -> 3157.4217 | CS36: =+CS33+CS34-CS35 -> 3241.8579 | ... DA36: =+DA33+DA34-DA35 -> 3920.7327
A37: OB Growth | Y37: =+Y36/X36-1 -> 0.22525714 | Z37: =+Z36/Y36-1 -> 0.049482324 | AA37: =+AA36/Z36-1 -> 0.19984002 | AB37: =+AB36/AA36-1 -> 0.093232648 | AC37: =+AC36/AB36-1 -> 0.098291472 | AD37: =+AD36/AC36-1 -> 0.099570641 | AE37: =+AE36/AD36-1 -> 0.099892226 | CA37: =+CA36/BW36-1 -> 0.34482759 | CB37: =+CB36/BX36-1 -> 0.375 | CC37: =+CC36/BY36-1 -> 0.2 | CD37: =+CD36/BZ36-1 -> 0.19444444 | CE37: =+CE36/CA36-1 -> 0.11794872 | CF37: =+CF36/CB36-1 -> 0.022727273 | CG37: =+CG36/CC36-1 -> 0.095238095 | CH37: =+CH36/CD36-1 -> 0.13953488 | ... DA37: =+DA36/CW36-1 -> 0.099892226
A38: Additions Growth | Z38: =+Z34/Y34-1 -> -0.00085256591 | AA38: =+AA34/Z34-1 -> 0.19181748 | AB38: =+AB34/AA34-1 -> 0.051565057 | AC38: =+AC34/AB34-1 -> 0.13247427 | AD38: =+AD34/AC34-1 -> 0.1 | AE38: =+AE34/AD34-1 -> 0.1 | CB38: =+CB34/BX34-1 -> 0.39979357 | CC38: =+CC34/BY34-1 -> -0.25496591 | CD38: =+CD34/BZ34-1 -> 0.10118606 | CE38: =+CE34/CA34-1 -> -0.088088493 | CF38: =+CF34/CB34-1 -> -0.15632297 | CG38: =+CG34/CC34-1 -> 0.54476721 | CH38: =+CH34/CD34-1 -> 0.25445978 | CI38: =+CI34/CE34-1 -> 0.35162722 | ... CK38: =+CK34/CG34-1 -> 0.088356517 | CL38: 0.1 | CM38: 0.1 | CN38: 0.1 | CO38: 0.1 | CP38: 0.1 | CQ38: 0.1 | CR38: 0.1 | CS38: 0.1 | CT38: 0.1 | CU38: 0.1 | CV38: 0.1 | CW38: 0.1 | CX38: 0.1 | CY38: 0.1 | CZ38: 0.1 | DA38: 0.1
A39: Execution % | Y39: =+Y35/Y33 -> 1.284136 | Z39: =+Z35/Z33 -> 1.1813665 | AA39: =+AA35/AA33 -> 1.1979416 | AB39: =+AB35/AB33 -> 1.1318126 | AC39: =+AC35/AC33 -> 1.1707268 | AD39: =+AD35/AD33 -> 1.1714218 | AE39: =+AE35/AE33 -> 1.1715965 | BX39: =+BX35/BX33 -> 0.29744828 | BY39: =+BY35/BY33 -> 0.327875 | BZ39: =+BZ35/BZ33 -> 0.27977143 | CA39: =+CA35/CA33 -> 0.3285 | CB39: =+CB35/CB33 -> 0.28907692 | CC39: =+CC35/CC33 -> 0.27390909 | CD39: =+CD35/CD33 -> 0.25914286 | CE39: =+CE35/CE33 -> 0.30046512 | ... CK39: =+CK35/CK33 -> 0.29708223 | CL39: =+CH39 -> 0.25886957 | CM39: =+CI39 -> 0.27212245 | CN39: =+CM39 -> 0.27212245 | CO39: =+CK39 -> 0.29708223 | CP39: =+CL39 -> 0.25886957 | CQ39: =+CM39 -> 0.27212245 | CR39: =+CN39 -> 0.27212245 | CS39: =+CO39 -> 0.29708223 | CT39: =+CP39 -> 0.25886957 | CU39: =+CQ39 -> 0.27212245 | CV39: =+CR39 -> 0.27212245 | ... DA39: =+CW39 -> 0.29708223
A42: Presentation Data (End)
A43: Profit & Loss- Annual (Start)
A44: Gross Revenue | B44: ='Annual Raw'!C6 -> 183.5706 | C44: ='Annual Raw'!D6 -> 208.06 | D44: ='Annual Raw'!E6 -> 246.6743 | E44: ='Annual Raw'!F6 -> 262.837 | F44: ='Annual Raw'!G6 -> 332.4444 | G44: ='Annual Raw'!H6 -> 397.7657 | H44: ='Annual Raw'!I6 -> 453.1451 | I44: ='Annual Raw'!J6 -> 513.1169 | ... AA44: ='Annual Raw'!AB6 -> 2753.025 | AB44: =+SUM(CL44:CO44) -> 3055.894 | AC44: =+SUM(CP44:CS44) -> 3455.6673 | AD44: =+SUM(CT44:CW44) -> 3797.5828 | AE44: =+SUM(CX44:DA44) -> 4176.3334 | AI44: ='QTR Raw'!C6+'QTR Raw'!C8 -> 187.38 | AJ44: ='QTR Raw'!D6+'QTR Raw'!D8 -> 169.74 | AK44: ='QTR Raw'!E6+'QTR Raw'!E8 -> 194.58 | AL44: ='QTR Raw'!F6+'QTR Raw'!F8 -> 163.79 | AM44: ='QTR Raw'!G6+'QTR Raw'!G8 -> 195.22 | AN44: ='QTR Raw'!H6+'QTR Raw'!H8 -> 190.24 | AO44: ='QTR Raw'!I6+'QTR Raw'!I8 -> 182.09 | AP44: ='QTR Raw'!J6+'QTR Raw'!J8 -> 173.37 | ... CL44: ='QTR Raw'!BF6+'QTR Raw'!BF8 -> 601.3 | CM44: =+CM35 -> 767.6553 | CN44: =+CN35 -> 832.26117 | CO44: =+CO35 -> 854.67756 | CP44: =+CP35 -> 764.11258 | CQ44: =+CQ35 -> 840.73579 | CR44: =+CR35 -> 912.80503 | CS44: =+CS35 -> 938.01389 | CT44: =+CT35 -> 839.21833 | ... DA44: =+DA35 -> 1134.1873 | DE44: 2695.7
A45: Less: Exise Duty | B45: ='Annual Raw'!C7+'Annual Raw'!C8+'Annual Raw'!C9 -> 0 | C45: ='Annual Raw'!D7+'Annual Raw'!D8+'Annual Raw'!D9 -> 0 | D45: ='Annual Raw'!E7+'Annual Raw'!E8+'Annual Raw'!E9 -> 16.1455 | E45: ='Annual Raw'!F7+'Annual Raw'!F8+'Annual Raw'!F9 -> 19.9915 | F45: ='Annual Raw'!G7+'Annual Raw'!G8+'Annual Raw'!G9 -> 27.8799 | G45: ='Annual Raw'!H7+'Annual Raw'!H8+'Annual Raw'!H9 -> 37.8643 | H45: ='Annual Raw'!I7+'Annual Raw'!I8+'Annual Raw'!I9 -> 45.6415 | I45: ='Annual Raw'!J7+'Annual Raw'!J8+'Annual Raw'!J9 -> 46.6397 | ... AA45: ='Annual Raw'!AB7+'Annual Raw'!AB8+'Annual Raw'!AB9 -> 57.297 | AB45: =+SUM(CL45:CO45) -> 0 | AC45: =+SUM(CP45:CS45) -> 0 | AD45: =+SUM(CT45:CW45) -> 0 | AE45: =+SUM(CX45:DA45) -> 0 | AI45: ='QTR Raw'!C21+'QTR Raw'!C20+'QTR Raw'!C19+'QTR Raw'!C13+'QTR Raw'!C7 -> 0 | AJ45: ='QTR Raw'!D21+'QTR Raw'!D20+'QTR Raw'!D19+'QTR Raw'!D13+'QTR Raw'!D7 -> 0 | AK45: ='QTR Raw'!E21+'QTR Raw'!E20+'QTR Raw'!E19+'QTR Raw'!E13+'QTR Raw'!E7 -> 0 | AL45: ='QTR Raw'!F21+'QTR Raw'!F20+'QTR Raw'!F19+'QTR Raw'!F13+'QTR Raw'!F7 -> 0 | AM45: ='QTR Raw'!G21+'QTR Raw'!G20+'QTR Raw'!G19+'QTR Raw'!G13+'QTR Raw'!G7 -> 0 | AN45: ='QTR Raw'!H21+'QTR Raw'!H20+'QTR Raw'!H19+'QTR Raw'!H13+'QTR Raw'!H7 -> 0 | AO45: ='QTR Raw'!I21+'QTR Raw'!I20+'QTR Raw'!I19+'QTR Raw'!I13+'QTR Raw'!I7 -> 0 | AP45: ='QTR Raw'!J21+'QTR Raw'!J20+'QTR Raw'!J19+'QTR Raw'!J13+'QTR Raw'!J7 -> 0 | ... CL45: ='QTR Raw'!BF21+'QTR Raw'!BF20+'QTR Raw'!BF19+'QTR Raw'!BF13+'QTR Raw'!BF7 -> 0 | DE45: 0
A46: Net Revenue | B46: =+B44-B45 -> 183.5706 | C46: =+C44-C45 -> 208.06 | D46: =+D44-D45 -> 230.5288 | E46: =+E44-E45 -> 242.8455 | F46: =+F44-F45 -> 304.5645 | G46: =+G44-G45 -> 359.9014 | H46: =+H44-H45 -> 407.5036 | I46: =+I44-I45 -> 466.4772 | ... AE46: =+AE44-AE45 -> 4176.3334 | AI46: =+AI44-AI45 -> 187.38 | AJ46: =+AJ44-AJ45 -> 169.74 | AK46: =+AK44-AK45 -> 194.58 | AL46: =+AL44-AL45 -> 163.79 | AM46: =+AM44-AM45 -> 195.22 | AN46: =+AN44-AN45 -> 190.24 | AO46: =+AO44-AO45 -> 182.09 | AP46: =+AP44-AP45 -> 173.37 | ... DA46: =+DA44-DA45 -> 1134.1873 | DE46: 2695.7
A47: Net Revenue YOY% | C47: =C46/B46-1 -> 0.13340589 | D47: =D46/C46-1 -> 0.10799193 | E47: =E46/D46-1 -> 0.053428032 | F47: =F46/E46-1 -> 0.25414924 | G47: =G46/F46-1 -> 0.18169189 | H47: =H46/G46-1 -> 0.13226456 | I47: =I46/H46-1 -> 0.14471921 | J47: =J46/I46-1 -> 0.28216213 | ... AE47: =AE46/AD46-1 -> 0.099734635 | AM47: =+IF(AI46<0,1-AM46/AI46,AM46/AI46-1) -> 0.041840111 | AN47: =+IF(AJ46<0,1-AN46/AJ46,AN46/AJ46-1) -> 0.12077295 | AO47: =+IF(AK46<0,1-AO46/AK46,AO46/AK46-1) -> -0.064189536 | AP47: =+IF(AL46<0,1-AP46/AL46,AP46/AL46-1) -> 0.058489529 | AQ47: =+IF(AM46<0,1-AQ46/AM46,AQ46/AM46-1) -> 0.021155619 | AR47: =+IF(AN46<0,1-AR46/AN46,AR46/AN46-1) -> 0.045468881 | AS47: =+IF(AO46<0,1-AS46/AO46,AS46/AO46-1) -> 0.26360591 | AT47: =+IF(AP46<0,1-AT46/AP46,AT46/AP46-1) -> 0.091711369 | ... DA47: =+IF(CW46<0,1-DA46/CW46,DA46/CW46-1) -> 0.099842548 | DE47: 0.064196004
A48: Net Revenue QOQ% | AJ48: =+IF(AI46<0,1-AJ46/AI46,AJ46/AI46-1) -> -0.09414025 | AK48: =+IF(AJ46<0,1-AK46/AJ46,AK46/AJ46-1) -> 0.14634146 | AL48: =+IF(AK46<0,1-AL46/AK46,AL46/AK46-1) -> -0.15823826 | AM48: =+IF(AL46<0,1-AM46/AL46,AM46/AL46-1) -> 0.19189206 | AN48: =+IF(AM46<0,1-AN46/AM46,AN46/AM46-1) -> -0.025509681 | AO48: =+IF(AN46<0,1-AO46/AN46,AO46/AN46-1) -> -0.042840622 | AP48: =+IF(AO46<0,1-AP46/AO46,AP46/AO46-1) -> -0.047888407 | AQ48: =+IF(AP46<0,1-AQ46/AP46,AQ46/AP46-1) -> 0.14985292 | ... CL48: =+IF(CK46<0,1-CL46/CK46,CL46/CK46-1) -> -0.23303571 | CM48: =+CM46/CL46-1 -> 0.2766594 | CN48: =+CN46/CM46-1 -> 0.08416 | CO48: =+CO46/CN46-1 -> 0.02693432 | CP48: =+CP46/CO46-1 -> -0.10596391 | CQ48: =+CQ46/CP46-1 -> 0.10027739 | CR48: =+CR46/CQ46-1 -> 0.085721624 | CS48: =+CS46/CR46-1 -> 0.02761691 | CT48: =+CT46/CS46-1 -> -0.10532419 | ... DA48: =+DA46/CZ46-1 -> 0.027831982
A49: Increase/Decrease in Stock | B49: ='Annual Raw'!C11 -> -4.9865 | C49: ='Annual Raw'!D11 -> -2.3004 | D49: ='Annual Raw'!E11 -> -0.2105 | E49: ='Annual Raw'!F11 -> -5.7236 | F49: ='Annual Raw'!G11 -> -2.9785 | G49: ='Annual Raw'!H11 -> -5.5271 | H49: ='Annual Raw'!I11 -> -1.3516 | I49: ='Annual Raw'!J11 -> -24.511 | ... AA49: ='Annual Raw'!AB11 -> -93.224 | AB49: =+SUM(CL49:CO49) -> -100.1 | AC49: =+SUM(CP49:CS49) -> 0 | AD49: =+SUM(CT49:CW49) -> 0 | AE49: =+SUM(CX49:DA49) -> 0 | AI49: ='QTR Raw'!C10 -> 8.28 | AJ49: ='QTR Raw'!D10 -> -7.8 | AK49: ='QTR Raw'!E10 -> 8.8 | AL49: ='QTR Raw'!F10 -> -21.35 | AM49: ='QTR Raw'!G10 -> 11.93 | AN49: ='QTR Raw'!H10 -> 6 | AO49: ='QTR Raw'!I10 -> 7.68 | AP49: ='QTR Raw'!J10 -> -17.34 | ... CL49: ='QTR Raw'!BF10 -> -100.1 | DE49: -93.2
...

Sheet Sheet1
A2: Calendar Year | B2: Quarter | C2: Nuclear (NPCIL) | D2: Non-Nuclear | E2: Total Order Book
A3: 2022 | B3: Q2 (Jun) | C3: ~600 | D3: ~850 | E3: 1450
B4: Q3 (Sep) | C4: ~650 | D4: ~950 | E4: 1600
B5: Q4 (Dec) | C5: ~700 | D5: 1050 | E5: 1750
A6: 2023 | B6: Q1 (Mar) | C6: ~750 | D6: ~1,050 | E6: 1800
B7: Q2 (Jun) | C7: ~750 | D7: 1200 | E7: 1950
B8: Q3 (Sep) | C8: 1020 | D8: 1180 | E8: 2200
B9: Q4 (Dec) | C9: 920 | D9: 1180 | E9: 2100
A10: 2024 | B10: Q1 (Mar) | C10: ~915 | D10: 1235 | E10: 2150
B11: Q2 (Jun) | C11: ~915 | D11: ~1,265 | E11: 2180
B12: Q3 (Sep) | C12: ~920 | D12: ~1,330 | E12: 2250
B13: Q4 (Dec) | C13: ~920 | D13: ~1,380 | E13: 2300
A14: 2025 | B14: Q1 (Mar) | C14: ~1,310 | D14: ~1,140 | E14: 2450
B15: Q2 (Jun) | C15: ~1,313 | D15: ~1,384 | E15: 2697
B16: Q3 (Sep) | C16: 1314 | D16: 1325 | E16: 2639
B17: Q4 (Dec) | C17: ~1,315 | D17: ~1,385 | E17: 2700
B19: 2022 | E19: 2023 | I19: 2024 | M19: 2025
B20: Q2 (Jun) | C20: Q3 (Sep) | D20: Q4 (Dec) | E20: Q1 (Mar) | F20: Q2 (Jun) | G20: Q3 (Sep) | H20: Q4 (Dec) | I20: Q1 (Mar) | J20: Q2 (Jun) | K20: Q3 (Sep) | L20: Q4 (Dec) | M20: Q1 (Mar) | N20: Q2 (Jun) | O20: Q3 (Sep) | P20: Q4 (Dec)
A21: Nuclear (NPCIL) | B21: ~600 | C21: ~650 | D21: ~700 | E21: ~750 | F21: ~750 | G21: 1020 | H21: 920 | I21: ~915 | J21: ~915 | K21: ~920 | L21: ~920 | M21: ~1,310 | N21: ~1,313 | O21: 1314 | P21: ~1,315
A22: Non-Nuclear | B22: ~850 | C22: ~950 | D22: 1050 | E22: ~1,050 | F22: 1200 | G22: 1180 | H22: 1180 | I22: 1235 | J22: ~1,265 | K22: ~1,330 | L22: ~1,380 | M22: ~1,140 | N22: ~1,384 | O22: 1325 | P22: ~1,385
B23: 1450 | C23: 1600 | D23: 1750 | E23: 1800 | F23: 1950 | G23: 2200 | H23: 2100 | I23: 2150 | J23: 2180 | K23: 2250 | L23: 2300 | M23: 2450 | N23: 2697 | O23: 2639 | P23: 2700
B25: 600 | C25: 650 | D25: 700 | E25: 750 | F25: 750 | G25: 1020 | H25: 920 | I25: 915 | J25: 915 | K25: 920 | L25: 920 | M25: 1310 | N25: 1313 | O25: 1314 | P25: 1315
B26: 850 | C26: 950 | D26: 1050 | E26: 1050 | F26: 1200 | G26: 1180 | H26: 1180 | I26: 1235 | J26: 1265 | K26: 1330 | L26: 1380 | M26: 1140 | N26: 1384 | O26: 1325 | P26: 1385

Sheet QTR Raw
A1: ='Annual Raw'!A1 -> 100249 | B1: X | C1: 201206 | D1: 201209 | E1: 201212 | F1: 201303 | G1: 201306 | H1: 201309 | I1: 201312 | J1: 201403 | K1: 201406 | L1: 201409 | M1: 201412 | N1: 201503 | O1: 201506 | P1: 201509 | Q1: 201512 | R1: 201603 | S1: 201606 | T1: 201609 | U1: 201612 | V1: 201703 | W1: 201706 | X1: 201709 | Y1: 201712 | Z1: 201803 | AA1: 201806 | AB1: 201809 | AC1: 201812 | AD1: 201903 | AE1: 201906 | AF1: 201909 | AG1: 201912 | AH1: 202003 | AI1: 202006 | AJ1: 202009 | AK1: 202012 | AL1: 202103 | AM1: 202106 | AN1: 202109 | AO1: 202112 | AP1: 202203 | AQ1: 202206 | AR1: 202209 | AS1: 202212 | AT1: 202303 | AU1: 202306 | AV1: 202309 | AW1: 202312 | AX1: 202403 | AY1: 202406 | AZ1: 202409 | BA1: 202412 | BB1: 202503 | BC1: 202506 | BD1: 202509 | BE1: 202512 | BF1: 202603 | BG1: 202606 | BH1: 202609 | BI1: 202612 | BJ1: 202703 | BK1: 202706 | BL1: 202709 | BM1: 202712 | BN1: 202803 | BO1: 202806 | BP1: 202809 | BQ1: 202812 | BR1: 202903 | BS1: 202906 | BT1: 202909 | BU1: 202912
A3: Field Description | B3: Field Name
A4: Company Name | B4: CD_COMPNAME | C4: =_xll.EQNXTDZ(A1,B4,C1) -> KSB Ltd.
A5: Date End | B5: QTR_DATE_END | C5: =_xll.EQNXTDZ($A$1,$B5,C$1,$B$1) -> 201206 | D5: =_xll.EQNXTDZ($A$1,$B5,D$1,$B$1) -> 201209 | E5: =_xll.EQNXTDZ($A$1,$B5,E$1,$B$1) -> 201212 | F5: =_xll.EQNXTDZ($A$1,$B5,F$1,$B$1) -> 201303 | G5: =_xll.EQNXTDZ($A$1,$B5,G$1,$B$1) -> 201306 | H5: =_xll.EQNXTDZ($A$1,$B5,H$1,$B$1) -> 201309 | I5: =_xll.EQNXTDZ($A$1,$B5,I$1,$B$1) -> 201312 | J5: =_xll.EQNXTDZ($A$1,$B5,J$1,$B$1) -> 201403 | ... BU5: =_xll.EQNXTDZ($A$1,$B5,BU$1,$B$1) -> 0
A6: Gross Sales | B6: QTR_GROSS_SALE | C6: =_xll.EQNXTDZ($A$1,$B6,C$1,$B$1) -> 186.66 | D6: =_xll.EQNXTDZ($A$1,$B6,D$1,$B$1) -> 168.72 | E6: =_xll.EQNXTDZ($A$1,$B6,E$1,$B$1) -> 193.77 | F6: =_xll.EQNXTDZ($A$1,$B6,F$1,$B$1) -> 162.87 | G6: =_xll.EQNXTDZ($A$1,$B6,G$1,$B$1) -> 194.1 | H6: =_xll.EQNXTDZ($A$1,$B6,H$1,$B$1) -> 188.16 | I6: =_xll.EQNXTDZ($A$1,$B6,I$1,$B$1) -> 179.49 | J6: =_xll.EQNXTDZ($A$1,$B6,J$1,$B$1) -> 171.63 | ... BU6: =_xll.EQNXTDZ($A$1,$B6,BU$1,$B$1) -> 0
A7: Less: Excise Duty | B7: QTR_EXCISE_DUTY | C7: =_xll.EQNXTDZ($A$1,$B7,C$1,$B$1) -> 0 | D7: =_xll.EQNXTDZ($A$1,$B7,D$1,$B$1) -> 0 | E7: =_xll.EQNXTDZ($A$1,$B7,E$1,$B$1) -> 0 | F7: =_xll.EQNXTDZ($A$1,$B7,F$1,$B$1) -> 0 | G7: =_xll.EQNXTDZ($A$1,$B7,G$1,$B$1) -> 0 | H7: =_xll.EQNXTDZ($A$1,$B7,H$1,$B$1) -> 0 | I7: =_xll.EQNXTDZ($A$1,$B7,I$1,$B$1) -> 0 | J7: =_xll.EQNXTDZ($A$1,$B7,J$1,$B$1) -> 0 | ... BU7: =_xll.EQNXTDZ($A$1,$B7,BU$1,$B$1) -> 0
A8: Other operating income | B8: QTR_JOB_WORKS | C8: =_xll.EQNXTDZ($A$1,$B8,C$1,$B$1) -> 0.72 | D8: =_xll.EQNXTDZ($A$1,$B8,D$1,$B$1) -> 1.02 | E8: =_xll.EQNXTDZ($A$1,$B8,E$1,$B$1) -> 0.81 | F8: =_xll.EQNXTDZ($A$1,$B8,F$1,$B$1) -> 0.92 | G8: =_xll.EQNXTDZ($A$1,$B8,G$1,$B$1) -> 1.12 | H8: =_xll.EQNXTDZ($A$1,$B8,H$1,$B$1) -> 2.08 | I8: =_xll.EQNXTDZ($A$1,$B8,I$1,$B$1) -> 2.6 | J8: =_xll.EQNXTDZ($A$1,$B8,J$1,$B$1) -> 1.74 | ... BU8: =_xll.EQNXTDZ($A$1,$B8,BU$1,$B$1) -> 0
A9: Net Sales & Other Operating Income | B9: QTR_NET_SALES | C9: =_xll.EQNXTDZ($A$1,$B9,C$1,$B$1) -> 187.38 | D9: =_xll.EQNXTDZ($A$1,$B9,D$1,$B$1) -> 169.74 | E9: =_xll.EQNXTDZ($A$1,$B9,E$1,$B$1) -> 194.58 | F9: =_xll.EQNXTDZ($A$1,$B9,F$1,$B$1) -> 163.79 | G9: =_xll.EQNXTDZ($A$1,$B9,G$1,$B$1) -> 195.22 | H9: =_xll.EQNXTDZ($A$1,$B9,H$1,$B$1) -> 190.24 | I9: =_xll.EQNXTDZ($A$1,$B9,I$1,$B$1) -> 182.09 | J9: =_xll.EQNXTDZ($A$1,$B9,J$1,$B$1) -> 173.37 | ... BU9: =_xll.EQNXTDZ($A$1,$B9,BU$1,$B$1) -> 0
A10: (Increase) / Decrease In Stocks | B10: QTR_INC_DEC_INVENTORY | C10: =_xll.EQNXTDZ($A$1,$B10,C$1,$B$1) -> 8.28 | D10: =_xll.EQNXTDZ($A$1,$B10,D$1,$B$1) -> -7.8 | E10: =_xll.EQNXTDZ($A$1,$B10,E$1,$B$1) -> 8.8 | F10: =_xll.EQNXTDZ($A$1,$B10,F$1,$B$1) -> -21.35 | G10: =_xll.EQNXTDZ($A$1,$B10,G$1,$B$1) -> 11.93 | H10: =_xll.EQNXTDZ($A$1,$B10,H$1,$B$1) -> 6 | I10: =_xll.EQNXTDZ($A$1,$B10,I$1,$B$1) -> 7.68 | J10: =_xll.EQNXTDZ($A$1,$B10,J$1,$B$1) -> -17.34 | ... BU10: =_xll.EQNXTDZ($A$1,$B10,BU$1,$B$1) -> 0
A11: Cost of Services & Raw Materials | B11: QTR_RAW_MATERIAL_COST | C11: =_xll.EQNXTDZ($A$1,$B11,C$1,$B$1) -> 91.95 | D11: =_xll.EQNXTDZ($A$1,$B11,D$1,$B$1) -> 87.13 | E11: =_xll.EQNXTDZ($A$1,$B11,E$1,$B$1) -> 82.97 | F11: =_xll.EQNXTDZ($A$1,$B11,F$1,$B$1) -> 91.88 | G11: =_xll.EQNXTDZ($A$1,$B11,G$1,$B$1) -> 85.09 | H11: =_xll.EQNXTDZ($A$1,$B11,H$1,$B$1) -> 77.48 | I11: =_xll.EQNXTDZ($A$1,$B11,I$1,$B$1) -> 73.57 | J11: =_xll.EQNXTDZ($A$1,$B11,J$1,$B$1) -> 86.74 | ... BU11: =_xll.EQNXTDZ($A$1,$B11,BU$1,$B$1) -> 0
A12: Purchase of Finished Goods | B12: QTR_PURCHASE_FIN_GOOD | C12: =_xll.EQNXTDZ($A$1,$B12,C$1,$B$1) -> 1.88 | D12: =_xll.EQNXTDZ($A$1,$B12,D$1,$B$1) -> 2.26 | E12: =_xll.EQNXTDZ($A$1,$B12,E$1,$B$1) -> 4.23 | F12: =_xll.EQNXTDZ($A$1,$B12,F$1,$B$1) -> 1.71 | G12: =_xll.EQNXTDZ($A$1,$B12,G$1,$B$1) -> 0.31 | H12: =_xll.EQNXTDZ($A$1,$B12,H$1,$B$1) -> 2.52 | I12: =_xll.EQNXTDZ($A$1,$B12,I$1,$B$1) -> 7.51 | J12: =_xll.EQNXTDZ($A$1,$B12,J$1,$B$1) -> 8.42 | ... BU12: =_xll.EQNXTDZ($A$1,$B12,BU$1,$B$1) -> 0
A13: Excise Duty | B13: QTR_EXCISE | C13: =_xll.EQNXTDZ($A$1,$B13,C$1,$B$1) -> 0 | D13: =_xll.EQNXTDZ($A$1,$B13,D$1,$B$1) -> 0 | E13: =_xll.EQNXTDZ($A$1,$B13,E$1,$B$1) -> 0 | F13: =_xll.EQNXTDZ($A$1,$B13,F$1,$B$1) -> 0 | G13: =_xll.EQNXTDZ($A$1,$B13,G$1,$B$1) -> 0 | H13: =_xll.EQNXTDZ($A$1,$B13,H$1,$B$1) -> 0 | I13: =_xll.EQNXTDZ($A$1,$B13,I$1,$B$1) -> 0 | J13: =_xll.EQNXTDZ($A$1,$B13,J$1,$B$1) -> 0 | ... BU13: =_xll.EQNXTDZ($A$1,$B13,BU$1,$B$1) -> 0
A14: Operating & Manufacturing Expenses | B14: QTR_MFG_EXPS | C14: =_xll.EQNXTDZ($A$1,$B14,C$1,$B$1) -> 34.83 | D14: =_xll.EQNXTDZ($A$1,$B14,D$1,$B$1) -> 40.74 | E14: =_xll.EQNXTDZ($A$1,$B14,E$1,$B$1) -> 44.25 | F14: =_xll.EQNXTDZ($A$1,$B14,F$1,$B$1) -> 41.57 | G14: =_xll.EQNXTDZ($A$1,$B14,G$1,$B$1) -> 42.57 | H14: =_xll.EQNXTDZ($A$1,$B14,H$1,$B$1) -> 46.26 | I14: =_xll.EQNXTDZ($A$1,$B14,I$1,$B$1) -> 45.98 | J14: =_xll.EQNXTDZ($A$1,$B14,J$1,$B$1) -> 39.34 | ... BU14: =_xll.EQNXTDZ($A$1,$B14,BU$1,$B$1) -> 0
A15: Electricity Power & Fuel Cost | B15: QTR_ELECTRICITY_POWER_FUEL | C15: =_xll.EQNXTDZ($A$1,$B15,C$1,$B$1) -> 0 | D15: =_xll.EQNXTDZ($A$1,$B15,D$1,$B$1) -> 0 | E15: =_xll.EQNXTDZ($A$1,$B15,E$1,$B$1) -> 0 | F15: =_xll.EQNXTDZ($A$1,$B15,F$1,$B$1) -> 0 | G15: =_xll.EQNXTDZ($A$1,$B15,G$1,$B$1) -> 0 | H15: =_xll.EQNXTDZ($A$1,$B15,H$1,$B$1) -> 0 | I15: =_xll.EQNXTDZ($A$1,$B15,I$1,$B$1) -> 0 | J15: =_xll.EQNXTDZ($A$1,$B15,J$1,$B$1) -> 0 | ... BU15: =_xll.EQNXTDZ($A$1,$B15,BU$1,$B$1) -> 0
A16: Employee Cost | B16: QTR_EXPLOYEE_COST | C16: =_xll.EQNXTDZ($A$1,$B16,C$1,$B$1) -> 25.72 | D16: =_xll.EQNXTDZ($A$1,$B16,D$1,$B$1) -> 24.68 | E16: =_xll.EQNXTDZ($A$1,$B16,E$1,$B$1) -> 24.42 | F16: =_xll.EQNXTDZ($A$1,$B16,F$1,$B$1) -> 28.26 | G16: =_xll.EQNXTDZ($A$1,$B16,G$1,$B$1) -> 28.39 | H16: =_xll.EQNXTDZ($A$1,$B16,H$1,$B$1) -> 27.78 | I16: =_xll.EQNXTDZ($A$1,$B16,I$1,$B$1) -> 25.63 | J16: =_xll.EQNXTDZ($A$1,$B16,J$1,$B$1) -> 31.08 | ... BU16: =_xll.EQNXTDZ($A$1,$B16,BU$1,$B$1) -> 0
... A42: Consolidated PAT(after extra items) | B42: QTR_CONS_PAT_EXITM | C42: =_xll.EQNXTDZ($A$1,$B42,C$1,$B$1) -> 17.46 | D42: =_xll.EQNXTDZ($A$1,$B42,D$1,$B$1) -> 12.92 | E42: =_xll.EQNXTDZ($A$1,$B42,E$1,$B$1) -> 19.54 | F42: =_xll.EQNXTDZ($A$1,$B42,F$1,$B$1) -> 15.61 | G42: =_xll.EQNXTDZ($A$1,$B42,G$1,$B$1) -> 15.46 | H42: =_xll.EQNXTDZ($A$1,$B42,H$1,$B$1) -> 17.9 | I42: =_xll.EQNXTDZ($A$1,$B42,I$1,$B$1) -> 10.79 | J42: =_xll.EQNXTDZ($A$1,$B42,J$1,$B$1) -> 15.13 | ... BU42: =_xll.EQNXTDZ($A$1,$B42,BU$1,$B$1) -> 0
A44: Field Description | B44: Field Name
A45: Equity Capital | B45: QTR_EQUITY_CAP | C45: =_xll.EQNXTDZ($A$1,$B45,C$1,$B$1) -> 34.81 | D45: =_xll.EQNXTDZ($A$1,$B45,D$1,$B$1) -> 34.81 | E45: =_xll.EQNXTDZ($A$1,$B45,E$1,$B$1) -> 34.81 | F45: =_xll.EQNXTDZ($A$1,$B45,F$1,$B$1) -> 34.81 | G45: =_xll.EQNXTDZ($A$1,$B45,G$1,$B$1) -> 34.81 | H45: =_xll.EQNXTDZ($A$1,$B45,H$1,$B$1) -> 34.81 | I45: =_xll.EQNXTDZ($A$1,$B45,I$1,$B$1) -> 34.81 | J45: =_xll.EQNXTDZ($A$1,$B45,J$1,$B$1) -> 34.81 | ... BU45: =_xll.EQNXTDZ($A$1,$B45,BU$1,$B$1) -> 0
A46: Face Value | B46: QTR_FV | C46: =_xll.EQNXTDZ($A$1,$B46,C$1,$B$1) -> 10 | D46: =_xll.EQNXTDZ($A$1,$B46,D$1,$B$1) -> 10 | E46: =_xll.EQNXTDZ($A$1,$B46,E$1,$B$1) -> 10 | F46: =_xll.EQNXTDZ($A$1,$B46,F$1,$B$1) -> 10 | G46: =_xll.EQNXTDZ($A$1,$B46,G$1,$B$1) -> 10 | H46: =_xll.EQNXTDZ($A$1,$B46,H$1,$B$1) -> 10 | I46: =_xll.EQNXTDZ($A$1,$B46,I$1,$B$1) -> 10 | J46: =_xll.EQNXTDZ($A$1,$B46,J$1,$B$1) -> 10 | ... BU46: =_xll.EQNXTDZ($A$1,$B46,BU$1,$B$1) -> 0
A47: Month End | B47: BMONTH_MONTHEND | C47: =_xll.EQNXTDZ($A$1,$B47,C$5) -> 201206 | D47: =_xll.EQNXTDZ($A$1,$B47,D$5) -> 201209 | E47: =_xll.EQNXTDZ($A$1,$B47,E$5) -> 201212 | F47: =_xll.EQNXTDZ($A$1,$B47,F$5) -> 201303 | G47: =_xll.EQNXTDZ($A$1,$B47,G$5) -> 201306 | H47: =_xll.EQNXTDZ($A$1,$B47,H$5) -> 201309 | I47: =_xll.EQNXTDZ($A$1,$B47,I$5) -> 201312 | J47: =_xll.EQNXTDZ($A$1,$B47,J$5) -> 201403 | ... BU47: =_xll.EQNXTDZ($A$1,$B47,BU$5) -> 0
A48: Close | B48: BMONTH_CLOSE | C48: =_xll.EQNXTDZ($A$1,$B48,C$5) -> 36.88 | D48: =_xll.EQNXTDZ($A$1,$B48,D$5) -> 41.19 | E48: =_xll.EQNXTDZ($A$1,$B48,E$5) -> 44.32 | F48: =_xll.EQNXTDZ($A$1,$B48,F$5) -> 40.66 | G48: =_xll.EQNXTDZ($A$1,$B48,G$5) -> 41.64 | H48: =_xll.EQNXTDZ($A$1,$B48,H$5) -> 42.91 | I48: =_xll.EQNXTDZ($A$1,$B48,I$5) -> 53.6 | J48: =_xll.EQNXTDZ($A$1,$B48,J$5) -> 64.96 | ... BU48: =_xll.EQNXTDZ($A$1,$B48,BU$5) -> 0
A49: Total of Promoter and Promoter Group | B49: SHP_TPFTOTALPROMOTER | C49: =_xll.EQNXTDZ($A$1,$B49,C$5) -> 66.8 | D49: =_xll.EQNXTDZ($A$1,$B49,D$5) -> 66.8 | E49: =_xll.EQNXTDZ($A$1,$B49,E$5) -> 66.8 | F49: =_xll.EQNXTDZ($A$1,$B49,F$5) -> 66.8 | G49: =_xll.EQNXTDZ($A$1,$B49,G$5) -> 66.8 | H49: =_xll.EQNXTDZ($A$1,$B49,H$5) -> 66.8 | I49: =_xll.EQNXTDZ($A$1,$B49,I$5) -> 66.42 | J49: =_xll.EQNXTDZ($A$1,$B49,J$5) -> 66.42 | ... BU49: =_xll.EQNXTDZ($A$1,$B49,BU$5) -> 0
A50: Total of Promoter and Promoter Group Pledged | B50: SHP_PSHFTOTALPROMOTER | C50: =_xll.EQNXTDZ($A$1,$B50,C$5) -> 0 | D50: =_xll.EQNXTDZ($A$1,$B50,D$5) -> 0 | E50: =_xll.EQNXTDZ($A$1,$B50,E$5) -> 0 | F50: =_xll.EQNXTDZ($A$1,$B50,F$5) -> 0 | G50: =_xll.EQNXTDZ($A$1,$B50,G$5) -> 0 | H50: =_xll.EQNXTDZ($A$1,$B50,H$5) -> 0 | I50: =_xll.EQNXTDZ($A$1,$B50,I$5) -> 0 | J50: =_xll.EQNXTDZ($A$1,$B50,J$5) -> 0 | ... BU50: =_xll.EQNXTDZ($A$1,$B50,BU$5) -> 0
A54: Field Description | B54: Field Name | C54: =_xll.EQNXTDZ($A$1,$B54,C$5) -> 0 | D54: =_xll.EQNXTDZ($A$1,$B54,D$5) -> 0 | E54: =_xll.EQNXTDZ($A$1,$B54,E$5) -> 0 | F54: =_xll.EQNXTDZ($A$1,$B54,F$5) -> 0 | G54: =_xll.EQNXTDZ($A$1,$B54,G$5) -> 0 | H54: =_xll.EQNXTDZ($A$1,$B54,H$5) -> 0 | I54: =_xll.EQNXTDZ($A$1,$B54,I$5) -> 0 | J54: =_xll.EQNXTDZ($A$1,$B54,J$5) -> 0 | ... BU54: =_xll.EQNXTDZ($A$1,$B54,BU$5) -> 0
A55: Year End | B55: QTRB_DATE_END | C55: =_xll.EQNXTDZ($A$1,$B55,C$5,$B$1) -> 201206 | D55: =_xll.EQNXTDZ($A$1,$B55,D$5,$B$1) -> 0 | E55: =_xll.EQNXTDZ($A$1,$B55,E$5,$B$1) -> 0 | F55: =_xll.EQNXTDZ($A$1,$B55,F$5,$B$1) -> 0 | G55: =_xll.EQNXTDZ($A$1,$B55,G$5,$B$1) -> 201306 | H55: =_xll.EQNXTDZ($A$1,$B55,H$5,$B$1) -> 0 | I55: =_xll.EQNXTDZ($A$1,$B55,I$5,$B$1) -> 201312 | J55: =_xll.EQNXTDZ($A$1,$B55,J$5,$B$1) -> 0 | ... BU55: =_xll.EQNXTDZ($A$1,$B55,BU$5,$B$1) -> 0
A56: Share Capital | B56: QTRB_SHARE_CAPITAL | C56: =_xll.EQNXTDZ($A$1,$B56,C$5,$B$1) -> 34.81 | D56: =_xll.EQNXTDZ($A$1,$B56,D$5,$B$1) -> 0 | E56: =_xll.EQNXTDZ($A$1,$B56,E$5,$B$1) -> 0 | F56: =_xll.EQNXTDZ($A$1,$B56,F$5,$B$1) -> 0 | G56: =_xll.EQNXTDZ($A$1,$B56,G$5,$B$1) -> 34.81 | H56: =_xll.EQNXTDZ($A$1,$B56,H$5,$B$1) -> 0 | I56: =_xll.EQNXTDZ($A$1,$B56,I$5,$B$1) -> 34.81 | J56: =_xll.EQNXTDZ($A$1,$B56,J$5,$B$1) -> 0 | ... BU56: =_xll.EQNXTDZ($A$1,$B56,BU$5,$B$1) -> 0
A57: Share Warrants & outstandings | B57: QTRB_SHAREWARNDOUT | C57: =_xll.EQNXTDZ($A$1,$B57,C$5,$B$1) -> 0 | D57: =_xll.EQNXTDZ($A$1,$B57,D$5,$B$1) -> 0 | E57: =_xll.EQNXTDZ($A$1,$B57,E$5,$B$1) -> 0 | F57: =_xll.EQNXTDZ($A$1,$B57,F$5,$B$1) -> 0 | G57: =_xll.EQNXTDZ($A$1,$B57,G$5,$B$1) -> 0 | H57: =_xll.EQNXTDZ($A$1,$B57,H$5,$B$1) -> 0 | I57: =_xll.EQNXTDZ($A$1,$B57,I$5,$B$1) -> 0 | J57: =_xll.EQNXTDZ($A$1,$B57,J$5,$B$1) -> 0 | ... BU57: =_xll.EQNXTDZ($A$1,$B57,BU$5,$B$1) -> 0
A58: Reserves & Surplus | B58: QTRB_RESERVE | C58: =_xll.EQNXTDZ($A$1,$B58,C$5,$B$1) -> 380.87 | D58: =_xll.EQNXTDZ($A$1,$B58,D$5,$B$1) -> 0 | E58: =_xll.EQNXTDZ($A$1,$B58,E$5,$B$1) -> 0 | F58: =_xll.EQNXTDZ($A$1,$B58,F$5,$B$1) -> 0 | G58: =_xll.EQNXTDZ($A$1,$B58,G$5,$B$1) -> 422.15 | H58: =_xll.EQNXTDZ($A$1,$B58,H$5,$B$1) -> 0 | I58: =_xll.EQNXTDZ($A$1,$B58,I$5,$B$1) -> 476.96 | J58: =_xll.EQNXTDZ($A$1,$B58,J$5,$B$1) -> 0 | ... BU58: =_xll.EQNXTDZ($A$1,$B58,BU$5,$B$1) -> 0
A59: Shareholder's Funds | B59: QTRB_SHAREHODERS_FUNDS | C59: =_xll.EQNXTDZ($A$1,$B59,C$5,$B$1) -> 415.68 | D59: =_xll.EQNXTDZ($A$1,$B59,D$5,$B$1) -> 0 | E59: =_xll.EQNXTDZ($A$1,$B59,E$5,$B$1) -> 0 | F59: =_xll.EQNXTDZ($A$1,$B59,F$5,$B$1) -> 0 | G59: =_xll.EQNXTDZ($A$1,$B59,G$5,$B$1) -> 456.96 | H59: =_xll.EQNXTDZ($A$1,$B59,H$5,$B$1) -> 0 | I59: =_xll.EQNXTDZ($A$1,$B59,I$5,$B$1) -> 511.77 | J59: =_xll.EQNXTDZ($A$1,$B59,J$5,$B$1) -> 0 | ... BU59: =_xll.EQNXTDZ($A$1,$B59,BU$5,$B$1) -> 0
A60: Minority Interest | B60: QTRB_MINORITY_INTEREST_BS | C60: =_xll.EQNXTDZ($A$1,$B60,C$5,$B$1) -> 0 | D60: =_xll.EQNXTDZ($A$1,$B60,D$5,$B$1) -> 0 | E60: =_xll.EQNXTDZ($A$1,$B60,E$5,$B$1) -> 0 | F60: =_xll.EQNXTDZ($A$1,$B60,F$5,$B$1) -> 0 | G60: =_xll.EQNXTDZ($A$1,$B60,G$5,$B$1) -> 0 | H60: =_xll.EQNXTDZ($A$1,$B60,H$5,$B$1) -> 0 | I60: =_xll.EQNXTDZ($A$1,$B60,I$5,$B$1) -> 0 | J60: =_xll.EQNXTDZ($A$1,$B60,J$5,$B$1) -> 0 | ... BU60: =_xll.EQNXTDZ($A$1,$B60,BU$5,$B$1) -> 0
A61: Long Term Borrowings | B61: QTRB_TOTAL_DEBTS | C61: =_xll.EQNXTDZ($A$1,$B61,C$5,$B$1) -> 0.01 | D61: =_xll.EQNXTDZ($A$1,$B61,D$5,$B$1) -> 0 | E61: =_xll.EQNXTDZ($A$1,$B61,E$5,$B$1) -> 0 | F61: =_xll.EQNXTDZ($A$1,$B61,F$5,$B$1) -> 0 | G61: =_xll.EQNXTDZ($A$1,$B61,G$5,$B$1) -> 0 | H61: =_xll.EQNXTDZ($A$1,$B61,H$5,$B$1) -> 0 | I61: =_xll.EQNXTDZ($A$1,$B61,I$5,$B$1) -> 0 | J61: =_xll.EQNXTDZ($A$1,$B61,J$5,$B$1) -> 0 | ... BU61: =_xll.EQNXTDZ($A$1,$B61,BU$5,$B$1) -> 0
A62: Secured Loans | B62: QTRB_SECURED_LOANS | C62: =_xll.EQNXTDZ($A$1,$B62,C$5,$B$1) -> 0 | D62: =_xll.EQNXTDZ($A$1,$B62,D$5,$B$1) -> 0 | E62: =_xll.EQNXTDZ($A$1,$B62,E$5,$B$1) -> 0 | F62: =_xll.EQNXTDZ($A$1,$B62,F$5,$B$1) -> 0 | G62: =_xll.EQNXTDZ($A$1,$B62,G$5,$B$1) -> 0 | H62: =_xll.EQNXTDZ($A$1,$B62,H$5,$B$1) -> 0 | I62: =_xll.EQNXTDZ($A$1,$B62,I$5,$B$1) -> 0 | J62: =_xll.EQNXTDZ($A$1,$B62,J$5,$B$1) -> 0 | ... BU62: =_xll.EQNXTDZ($A$1,$B62,BU$5,$B$1) -> 0
A63: Unsecured Loans | B63: QTRB_UNSECURED_LOANS_NF | C63: =_xll.EQNXTDZ($A$1,$B63,C$5,$B$1) -> 0.01 | D63: =_xll.EQNXTDZ($A$1,$B63,D$5,$B$1) -> 0 | E63: =_xll.EQNXTDZ($A$1,$B63,E$5,$B$1) -> 0 | F63: =_xll.EQNXTDZ($A$1,$B63,F$5,$B$1) -> 0 | G63: =_xll.EQNXTDZ($A$1,$B63,G$5,$B$1) -> 0 | H63: =_xll.EQNXTDZ($A$1,$B63,H$5,$B$1) -> 0 | I63: =_xll.EQNXTDZ($A$1,$B63,I$5,$B$1) -> 0 | J63: =_xll.EQNXTDZ($A$1,$B63,J$5,$B$1) -> 0 | ... BU63: =_xll.EQNXTDZ($A$1,$B63,BU$5,$B$1) -> 0
A64: Other Long Term Liabilities | B64: QTRB_OTHER_LT_LIABILITIES | C64: =_xll.EQNXTDZ($A$1,$B64,C$5,$B$1) -> 5.4 | D64: =_xll.EQNXTDZ($A$1,$B64,D$5,$B$1) -> 0 | E64: =_xll.EQNXTDZ($A$1,$B64,E$5,$B$1) -> 0 | F64: =_xll.EQNXTDZ($A$1,$B64,F$5,$B$1) -> 0 | G64: =_xll.EQNXTDZ($A$1,$B64,G$5,$B$1) -> 5.79 | H64: =_xll.EQNXTDZ($A$1,$B64,H$5,$B$1) -> 0 | I64: =_xll.EQNXTDZ($A$1,$B64,I$5,$B$1) -> 6.04 | J64: =_xll.EQNXTDZ($A$1,$B64,J$5,$B$1) -> 0 | ... BU64: =_xll.EQNXTDZ($A$1,$B64,BU$5,$B$1) -> 0
A65: Long Term Trade Payables | B65: QTRB_LT_TRADE_PAYABLE | C65: =_xll.EQNXTDZ($A$1,$B65,C$5,$B$1) -> 0 | D65: =_xll.EQNXTDZ($A$1,$B65,D$5,$B$1) -> 0 | E65: =_xll.EQNXTDZ($A$1,$B65,E$5,$B$1) -> 0 | F65: =_xll.EQNXTDZ($A$1,$B65,F$5,$B$1) -> 0 | G65: =_xll.EQNXTDZ($A$1,$B65,G$5,$B$1) -> 0 | H65: =_xll.EQNXTDZ($A$1,$B65,H$5,$B$1) -> 0 | I65: =_xll.EQNXTDZ($A$1,$B65,I$5,$B$1) -> 0 | J65: =_xll.EQNXTDZ($A$1,$B65,J$5,$B$1) -> 0 | ... BU65: =_xll.EQNXTDZ($A$1,$B65,BU$5,$B$1) -> 0
A66: Lont Term Provisions | B66: QTRB_LT_PROVISIONS | C66: =_xll.EQNXTDZ($A$1,$B66,C$5,$B$1) -> 22.05 | D66: =_xll.EQNXTDZ($A$1,$B66,D$5,$B$1) -> 0 | E66: =_xll.EQNXTDZ($A$1,$B66,E$5,$B$1) -> 0 | F66: =_xll.EQNXTDZ($A$1,$B66,F$5,$B$1) -> 0 | G66: =_xll.EQNXTDZ($A$1,$B66,G$5,$B$1) -> 22.96 | H66: =_xll.EQNXTDZ($A$1,$B66,H$5,$B$1) -> 0 | I66: =_xll.EQNXTDZ($A$1,$B66,I$5,$B$1) -> 23.27 | J66: =_xll.EQNXTDZ($A$1,$B66,J$5,$B$1) -> 0 | ... BU66: =_xll.EQNXTDZ($A$1,$B66,BU$5,$B$1) -> 0
... A97: Total Assets | B97: QTRB_TOTAL_APPLICATIONS | C97: =_xll.EQNXTDZ($A$1,$B97,C$5,$B$1) -> 443.14 | D97: =_xll.EQNXTDZ($A$1,$B97,D$5,$B$1) -> 0 | E97: =_xll.EQNXTDZ($A$1,$B97,E$5,$B$1) -> 0 | F97: =_xll.EQNXTDZ($A$1,$B97,F$5,$B$1) -> 0 | G97: =_xll.EQNXTDZ($A$1,$B97,G$5,$B$1) -> 485.71 | H97: =_xll.EQNXTDZ($A$1,$B97,H$5,$B$1) -> 0 | I97: =_xll.EQNXTDZ($A$1,$B97,I$5,$B$1) -> 541.08 | J97: =_xll.EQNXTDZ($A$1,$B97,J$5,$B$1) -> 0 | ... BU97: =_xll.EQNXTDZ($A$1,$B97,BU$5,$B$1) -> 0

Sheet Annual Raw
A1: 100249 | B1: X | C1: 200003 | D1: 200103 | E1: 200212 | F1: 200312 | G1: 200412 | H1: 200512 | I1: 200612 | J1: 200712 | K1: 200812 | L1: 200912 | M1: 201012 | N1: 201112 | O1: 201212 | P1: 201312 | Q1: 201412 | R1: 201512 | S1: 201612 | T1: 201712 | U1: 201812 | V1: 201912 | W1: 202012 | X1: 202112 | Y1: 202212 | Z1: 202312 | AA1: 202412 | AB1: 202512 | AC1: 202612 | AD1: 202712 | AE1: 202812 | AF1: 202912 | AG1: 203012
A3: Field Description | B3: Field Name
A4: Company Name | B4: CD_COMPNAME | C4: =_xll.EQNXTDZ(A1,B4,"L") -> KSB Ltd.
A5: Year End | B5: PL_YEAR_END | C5: =_xll.EQNXTDZ($A$1,$B5,C$1,$B$1) -> 200003 | D5: =_xll.EQNXTDZ($A$1,$B5,D$1,$B$1) -> 200103 | E5: =_xll.EQNXTDZ($A$1,$B5,E$1,$B$1) -> 200212 | F5: =_xll.EQNXTDZ($A$1,$B5,F$1,$B$1) -> 200312 | G5: =_xll.EQNXTDZ($A$1,$B5,G$1,$B$1) -> 200412 | H5: =_xll.EQNXTDZ($A$1,$B5,H$1,$B$1) -> 200512 | I5: =_xll.EQNXTDZ($A$1,$B5,I$1,$B$1) -> 200612 | J5: =_xll.EQNXTDZ($A$1,$B5,J$1,$B$1) -> 200712 | ... AG5: =_xll.EQNXTDZ($A$1,$B5,AG$1,$B$1) -> 0
A6: Sales Turnover | B6: PL_TOTAL_GROSS_SALES | C6: =_xll.EQNXTDZ($A$1,$B6,C$1,$B$1) -> 183.5706 | D6: =_xll.EQNXTDZ($A$1,$B6,D$1,$B$1) -> 208.06 | E6: =_xll.EQNXTDZ($A$1,$B6,E$1,$B$1) -> 246.6743 | F6: =_xll.EQNXTDZ($A$1,$B6,F$1,$B$1) -> 262.837 | G6: =_xll.EQNXTDZ($A$1,$B6,G$1,$B$1) -> 332.4444 | H6: =_xll.EQNXTDZ($A$1,$B6,H$1,$B$1) -> 397.7657 | I6: =_xll.EQNXTDZ($A$1,$B6,I$1,$B$1) -> 453.1451 | J6: =_xll.EQNXTDZ($A$1,$B6,J$1,$B$1) -> 513.1169 | ... AG6: =_xll.EQNXTDZ($A$1,$B6,AG$1,$B$1) -> 0
A7: Less: Inter divisional transfers | B7: PL_INTER_DIV_TRF | C7: =_xll.EQNXTDZ($A$1,$B7,C$1,$B$1) -> 0 | D7: =_xll.EQNXTDZ($A$1,$B7,D$1,$B$1) -> 0 | E7: =_xll.EQNXTDZ($A$1,$B7,E$1,$B$1) -> 0 | F7: =_xll.EQNXTDZ($A$1,$B7,F$1,$B$1) -> 0 | G7: =_xll.EQNXTDZ($A$1,$B7,G$1,$B$1) -> 0 | H7: =_xll.EQNXTDZ($A$1,$B7,H$1,$B$1) -> 0 | I7: =_xll.EQNXTDZ($A$1,$B7,I$1,$B$1) -> 0 | J7: =_xll.EQNXTDZ($A$1,$B7,J$1,$B$1) -> 0 | ... AG7: =_xll.EQNXTDZ($A$1,$B7,AG$1,$B$1) -> 0
A8: Less: Sales Returns | B8: PL_SALES_RETURN | C8: =_xll.EQNXTDZ($A$1,$B8,C$1,$B$1) -> 0 | D8: =_xll.EQNXTDZ($A$1,$B8,D$1,$B$1) -> 0 | E8: =_xll.EQNXTDZ($A$1,$B8,E$1,$B$1) -> 0 | F8: =_xll.EQNXTDZ($A$1,$B8,F$1,$B$1) -> 0 | G8: =_xll.EQNXTDZ($A$1,$B8,G$1,$B$1) -> 0 | H8: =_xll.EQNXTDZ($A$1,$B8,H$1,$B$1) -> 0 | I8: =_xll.EQNXTDZ($A$1,$B8,I$1,$B$1) -> 0 | J8: =_xll.EQNXTDZ($A$1,$B8,J$1,$B$1) -> 0 | ... AG8: =_xll.EQNXTDZ($A$1,$B8,AG$1,$B$1) -> 0
A9: Less: Excise | B9: PL_EXCISE | C9: =_xll.EQNXTDZ($A$1,$B9,C$1,$B$1) -> 0 | D9: =_xll.EQNXTDZ($A$1,$B9,D$1,$B$1) -> 0 | E9: =_xll.EQNXTDZ($A$1,$B9,E$1,$B$1) -> 16.1455 | F9: =_xll.EQNXTDZ($A$1,$B9,F$1,$B$1) -> 19.9915 | G9: =_xll.EQNXTDZ($A$1,$B9,G$1,$B$1) -> 27.8799 | H9: =_xll.EQNXTDZ($A$1,$B9,H$1,$B$1) -> 37.8643 | I9: =_xll.EQNXTDZ($A$1,$B9,I$1,$B$1) -> 45.6415 | J9: =_xll.EQNXTDZ($A$1,$B9,J$1,$B$1) -> 46.6397 | ... AG9: =_xll.EQNXTDZ($A$1,$B9,AG$1,$B$1) -> 0
A10: Net Sales | B10: PL_NET_SALES | C10: =_xll.EQNXTDZ($A$1,$B10,C$1,$B$1) -> 183.5706 | D10: =_xll.EQNXTDZ($A$1,$B10,D$1,$B$1) -> 208.06 | E10: =_xll.EQNXTDZ($A$1,$B10,E$1,$B$1) -> 230.5288 | F10: =_xll.EQNXTDZ($A$1,$B10,F$1,$B$1) -> 242.8455 | G10: =_xll.EQNXTDZ($A$1,$B10,G$1,$B$1) -> 304.5645 | H10: =_xll.EQNXTDZ($A$1,$B10,H$1,$B$1) -> 359.9014 | I10: =_xll.EQNXTDZ($A$1,$B10,I$1,$B$1) -> 407.5036 | J10: =_xll.EQNXTDZ($A$1,$B10,J$1,$B$1) -> 466.4772 | ... AG10: =_xll.EQNXTDZ($A$1,$B10,AG$1,$B$1) -> 0
A11: Increase/Decrease in Stock | B11: PL_INC_DEC_INVENTORY | C11: =_xll.EQNXTDZ($A$1,$B11,C$1,$B$1) -> -4.9865 | D11: =_xll.EQNXTDZ($A$1,$B11,D$1,$B$1) -> -2.3004 | E11: =_xll.EQNXTDZ($A$1,$B11,E$1,$B$1) -> -0.2105 | F11: =_xll.EQNXTDZ($A$1,$B11,F$1,$B$1) -> -5.7236 | G11: =_xll.EQNXTDZ($A$1,$B11,G$1,$B$1) -> -2.9785 | H11: =_xll.EQNXTDZ($A$1,$B11,H$1,$B$1) -> -5.5271 | I11: =_xll.EQNXTDZ($A$1,$B11,I$1,$B$1) -> -1.3516 | J11: =_xll.EQNXTDZ($A$1,$B11,J$1,$B$1) -> -24.511 | ... AG11: =_xll.EQNXTDZ($A$1,$B11,AG$1,$B$1) -> 0
A12: Raw Material Consumed | B12: PL_RAW_MATRS_CONSUMED | C12: =_xll.EQNXTDZ($A$1,$B12,C$1,$B$1) -> 89.8881 | D12: =_xll.EQNXTDZ($A$1,$B12,D$1,$B$1) -> 99.2511 | E12: =_xll.EQNXTDZ($A$1,$B12,E$1,$B$1) -> 101.805 | F12: =_xll.EQNXTDZ($A$1,$B12,F$1,$B$1) -> 106.0585 | G12: =_xll.EQNXTDZ($A$1,$B12,G$1,$B$1) -> 137.6404 | H12: =_xll.EQNXTDZ($A$1,$B12,H$1,$B$1) -> 165.4362 | I12: =_xll.EQNXTDZ($A$1,$B12,I$1,$B$1) -> 175.7443 | J12: =_xll.EQNXTDZ($A$1,$B12,J$1,$B$1) -> 250.9755 | ... AG12: =_xll.EQNXTDZ($A$1,$B12,AG$1,$B$1) -> 0
A13: Power & Fuel Cost | B13: PL_POWER_FUEL | C13: =_xll.EQNXTDZ($A$1,$B13,C$1,$B$1) -> 4.914 | D13: =_xll.EQNXTDZ($A$1,$B13,D$1,$B$1) -> 5.2112 | E13: =_xll.EQNXTDZ($A$1,$B13,E$1,$B$1) -> 7.6916 | F13: =_xll.EQNXTDZ($A$1,$B13,F$1,$B$1) -> 7.4721 | G13: =_xll.EQNXTDZ($A$1,$B13,G$1,$B$1) -> 8.3325 | H13: =_xll.EQNXTDZ($A$1,$B13,H$1,$B$1) -> 8.5092 | I13: =_xll.EQNXTDZ($A$1,$B13,I$1,$B$1) -> 8.9057 | J13: =_xll.EQNXTDZ($A$1,$B13,J$1,$B$1) -> 9.8512 | ... AG13: =_xll.EQNXTDZ($A$1,$B13,AG$1,$B$1) -> 0
A14: Employee Cost | B14: PL_EMPLOYEES | C14: =_xll.EQNXTDZ($A$1,$B14,C$1,$B$1) -> 37.5406 | D14: =_xll.EQNXTDZ($A$1,$B14,D$1,$B$1) -> 31.7845 | E14: =_xll.EQNXTDZ($A$1,$B14,E$1,$B$1) -> 38.63 | F14: =_xll.EQNXTDZ($A$1,$B14,F$1,$B$1) -> 45.9854 | G14: =_xll.EQNXTDZ($A$1,$B14,G$1,$B$1) -> 45.3776 | H14: =_xll.EQNXTDZ($A$1,$B14,H$1,$B$1) -> 48.9709 | I14: =_xll.EQNXTDZ($A$1,$B14,I$1,$B$1) -> 53.2348 | J14: =_xll.EQNXTDZ($A$1,$B14,J$1,$B$1) -> 62.1157 | ... AG14: =_xll.EQNXTDZ($A$1,$B14,AG$1,$B$1) -> 0
A15: Operating & Manufacturing Expenses | B15: PL_GEN_OTHER_MFG_EXPS | C15: =_xll.EQNXTDZ($A$1,$B15,C$1,$B$1) -> 14.9782 | D15: =_xll.EQNXTDZ($A$1,$B15,D$1,$B$1) -> 15.8263 | E15: =_xll.EQNXTDZ($A$1,$B15,E$1,$B$1) -> 19.4585 | F15: =_xll.EQNXTDZ($A$1,$B15,F$1,$B$1) -> 20.8578 | G15: =_xll.EQNXTDZ($A$1,$B15,G$1,$B$1) -> 26.2982 | H15: =_xll.EQNXTDZ($A$1,$B15,H$1,$B$1) -> 31.3784 | I15: =_xll.EQNXTDZ($A$1,$B15,I$1,$B$1) -> 36.23 | J15: =_xll.EQNXTDZ($A$1,$B15,J$1,$B$1) -> 40.3246 | ... AG15: =_xll.EQNXTDZ($A$1,$B15,AG$1,$B$1) -> 0
A16: Cost of Software development | B16: PL_COST_SW | C16: =_xll.EQNXTDZ($A$1,$B16,C$1,$B$1) -> 0 | D16: =_xll.EQNXTDZ($A$1,$B16,D$1,$B$1) -> 0 | E16: =_xll.EQNXTDZ($A$1,$B16,E$1,$B$1) -> 0 | F16: =_xll.EQNXTDZ($A$1,$B16,F$1,$B$1) -> 0 | G16: =_xll.EQNXTDZ($A$1,$B16,G$1,$B$1) -> 0 | H16: =_xll.EQNXTDZ($A$1,$B16,H$1,$B$1) -> 0 | I16: =_xll.EQNXTDZ($A$1,$B16,I$1,$B$1) -> 0 | J16: =_xll.EQNXTDZ($A$1,$B16,J$1,$B$1) -> 0 | ... AG16: =_xll.EQNXTDZ($A$1,$B16,AG$1,$B$1) -> 0
... A36: Profit After Tax from Discontinued Operations | B36: PL_PAT_DIS_OP | C36: =_xll.EQNXTDZ($A$1,$B36,C$1,$B$1) -> 0 | D36: =_xll.EQNXTDZ($A$1,$B36,D$1,$B$1) -> 0 | E36: =_xll.EQNXTDZ($A$1,$B36,E$1,$B$1) -> 0 | F36: =_xll.EQNXTDZ($A$1,$B36,F$1,$B$1) -> 0 | G36: =_xll.EQNXTDZ($A$1,$B36,G$1,$B$1) -> 0 | H36: =_xll.EQNXTDZ($A$1,$B36,H$1,$B$1) -> 0 | I36: =_xll.EQNXTDZ($A$1,$B36,I$1,$B$1) -> 0 | J36: =_xll.EQNXTDZ($A$1,$B36,J$1,$B$1) -> 0 | ... AG36: =_xll.EQNXTDZ($A$1,$B36,AG$1,$B$1) -> 0
A39: Field Description | B39: Field Name
A40: Year End | B40: BS_YEAR_END | C40: =_xll.EQNXTDZ($A$1,$B40,C$1,$B$1) -> 200003 | D40: =_xll.EQNXTDZ($A$1,$B40,D$1,$B$1) -> 200103 | E40: =_xll.EQNXTDZ($A$1,$B40,E$1,$B$1) -> 200212 | F40: =_xll.EQNXTDZ($A$1,$B40,F$1,$B$1) -> 200312 | G40: =_xll.EQNXTDZ($A$1,$B40,G$1,$B$1) -> 200412 | H40: =_xll.EQNXTDZ($A$1,$B40,H$1,$B$1) -> 200512 | I40: =_xll.EQNXTDZ($A$1,$B40,I$1,$B$1) -> 200612 | J40: =_xll.EQNXTDZ($A$1,$B40,J$1,$B$1) -> 200712 | ... AG40: =_xll.EQNXTDZ($A$1,$B40,AG$1,$B$1) -> 0
A41: Share Capital | B41: BS_SHARE_CAPITAL | C41: =_xll.EQNXTDZ($A$1,$B41,C$1,$B$1) -> 17.403 | D41: =_xll.EQNXTDZ($A$1,$B41,D$1,$B$1) -> 17.403 | E41: =_xll.EQNXTDZ($A$1,$B41,E$1,$B$1) -> 17.4039 | F41: =_xll.EQNXTDZ($A$1,$B41,F$1,$B$1) -> 17.4039 | G41: =_xll.EQNXTDZ($A$1,$B41,G$1,$B$1) -> 17.4039 | H41: =_xll.EQNXTDZ($A$1,$B41,H$1,$B$1) -> 17.4039 | I41: =_xll.EQNXTDZ($A$1,$B41,I$1,$B$1) -> 17.4039 | J41: =_xll.EQNXTDZ($A$1,$B41,J$1,$B$1) -> 17.4039 | ... AG41: =_xll.EQNXTDZ($A$1,$B41,AG$1,$B$1) -> 0
A42: Share Warrants & Outstandings | B42: BS_SHAREWROUTST | C42: =_xll.EQNXTDZ($A$1,$B42,C$1,$B$1) -> 0 | D42: =_xll.EQNXTDZ($A$1,$B42,D$1,$B$1) -> 0 | E42: =_xll.EQNXTDZ($A$1,$B42,E$1,$B$1) -> 0 | F42: =_xll.EQNXTDZ($A$1,$B42,F$1,$B$1) -> 0 | G42: =_xll.EQNXTDZ($A$1,$B42,G$1,$B$1) -> 0 | H42: =_xll.EQNXTDZ($A$1,$B42,H$1,$B$1) -> 0 | I42: =_xll.EQNXTDZ($A$1,$B42,I$1,$B$1) -> 0 | J42: =_xll.EQNXTDZ($A$1,$B42,J$1,$B$1) -> 0 | ... AG42: =_xll.EQNXTDZ($A$1,$B42,AG$1,$B$1) -> 0
A43: Total Reserves | B43: BS_RESERVE | C43: =_xll.EQNXTDZ($A$1,$B43,C$1,$B$1) -> 74.4565 | D43: =_xll.EQNXTDZ($A$1,$B43,D$1,$B$1) -> 76.6793 | E43: =_xll.EQNXTDZ($A$1,$B43,E$1,$B$1) -> 82.1553 | F43: =_xll.EQNXTDZ($A$1,$B43,F$1,$B$1) -> 95.5454 | G43: =_xll.EQNXTDZ($A$1,$B43,G$1,$B$1) -> 116.1537 | H43: =_xll.EQNXTDZ($A$1,$B43,H$1,$B$1) -> 149.168 | I43: =_xll.EQNXTDZ($A$1,$B43,I$1,$B$1) -> 192.6471 | J43: =_xll.EQNXTDZ($A$1,$B43,J$1,$B$1) -> 232.3169 | ... AG43: =_xll.EQNXTDZ($A$1,$B43,AG$1,$B$1) -> 0
A44: Shareholder's Funds | B44: BS_SHAREHODERS_FUNDS | C44: =_xll.EQNXTDZ($A$1,$B44,C$1,$B$1) -> 91.8595 | D44: =_xll.EQNXTDZ($A$1,$B44,D$1,$B$1) -> 94.0823 | E44: =_xll.EQNXTDZ($A$1,$B44,E$1,$B$1) -> 99.5592 | F44: =_xll.EQNXTDZ($A$1,$B44,F$1,$B$1) -> 112.9493 | G44: =_xll.EQNXTDZ($A$1,$B44,G$1,$B$1) -> 133.5576 | H44: =_xll.EQNXTDZ($A$1,$B44,H$1,$B$1) -> 166.5719 | I44: =_xll.EQNXTDZ($A$1,$B44,I$1,$B$1) -> 210.051 | J44: =_xll.EQNXTDZ($A$1,$B44,J$1,$B$1) -> 249.7208 | ... AG44: =_xll.EQNXTDZ($A$1,$B44,AG$1,$B$1) -> 0
A45: Minority Interest | B45: BS_MINORITY_INTEREST | C45: =_xll.EQNXTDZ($A$1,$B45,C$1,$B$1) -> 0 | D45: =_xll.EQNXTDZ($A$1,$B45,D$1,$B$1) -> 0 | E45: =_xll.EQNXTDZ($A$1,$B45,E$1,$B$1) -> 0.3759 | F45: =_xll.EQNXTDZ($A$1,$B45,F$1,$B$1) -> 0 | G45: =_xll.EQNXTDZ($A$1,$B45,G$1,$B$1) -> 0 | H45: =_xll.EQNXTDZ($A$1,$B45,H$1,$B$1) -> 0 | I45: =_xll.EQNXTDZ($A$1,$B45,I$1,$B$1) -> 0 | J45: =_xll.EQNXTDZ($A$1,$B45,J$1,$B$1) -> 0 | ... AG45: =_xll.EQNXTDZ($A$1,$B45,AG$1,$B$1) -> 0
A46: Long-Term Borrowings | B46: BS_LTRM_BORROWING | C46: =_xll.EQNXTDZ($A$1,$B46,C$1,$B$1) -> 0 | D46: =_xll.EQNXTDZ($A$1,$B46,D$1,$B$1) -> 0 | E46: =_xll.EQNXTDZ($A$1,$B46,E$1,$B$1) -> 0 | F46: =_xll.EQNXTDZ($A$1,$B46,F$1,$B$1) -> 0 | G46: =_xll.EQNXTDZ($A$1,$B46,G$1,$B$1) -> 0 | H46: =_xll.EQNXTDZ($A$1,$B46,H$1,$B$1) -> 0 | I46: =_xll.EQNXTDZ($A$1,$B46,I$1,$B$1) -> 0 | J46: =_xll.EQNXTDZ($A$1,$B46,J$1,$B$1) -> 0 | ... AG46: =_xll.EQNXTDZ($A$1,$B46,AG$1,$B$1) -> 0
A47: Secured Loans | B47: BS_SECURED_LOANS | C47: =_xll.EQNXTDZ($A$1,$B47,C$1,$B$1) -> 20.6329 | D47: =_xll.EQNXTDZ($A$1,$B47,D$1,$B$1) -> 19.8949 | E47: =_xll.EQNXTDZ($A$1,$B47,E$1,$B$1) -> 10.8991 | F47: =_xll.EQNXTDZ($A$1,$B47,F$1,$B$1) -> 6.545 | G47: =_xll.EQNXTDZ($A$1,$B47,G$1,$B$1) -> 4.5416 | H47: =_xll.EQNXTDZ($A$1,$B47,H$1,$B$1) -> 9.8549 | I47: =_xll.EQNXTDZ($A$1,$B47,I$1,$B$1) -> 10.0336 | J47: =_xll.EQNXTDZ($A$1,$B47,J$1,$B$1) -> 24.215 | ... AG47: =_xll.EQNXTDZ($A$1,$B47,AG$1,$B$1) -> 0
A48: Unsecured Loans | B48: BS_UNSECURED_LOANS_NF | C48: =_xll.EQNXTDZ($A$1,$B48,C$1,$B$1) -> 20.9201 | D48: =_xll.EQNXTDZ($A$1,$B48,D$1,$B$1) -> 26.5731 | E48: =_xll.EQNXTDZ($A$1,$B48,E$1,$B$1) -> 17.5067 | F48: =_xll.EQNXTDZ($A$1,$B48,F$1,$B$1) -> 6.2016 | G48: =_xll.EQNXTDZ($A$1,$B48,G$1,$B$1) -> 3.1373 | H48: =_xll.EQNXTDZ($A$1,$B48,H$1,$B$1) -> 1.4473 | I48: =_xll.EQNXTDZ($A$1,$B48,I$1,$B$1) -> 0.9172 | J48: =_xll.EQNXTDZ($A$1,$B48,J$1,$B$1) -> 0.8973 | ... AG48: =_xll.EQNXTDZ($A$1,$B48,AG$1,$B$1) -> 0
A49: Deferred Tax Assets / Liabilities | B49: BS_NET_DEF_TAX_NF | C49: =_xll.EQNXTDZ($A$1,$B49,C$1,$B$1) -> 0 | D49: =_xll.EQNXTDZ($A$1,$B49,D$1,$B$1) -> 0 | E49: =_xll.EQNXTDZ($A$1,$B49,E$1,$B$1) -> 5.1152 | F49: =_xll.EQNXTDZ($A$1,$B49,F$1,$B$1) -> 2.4358 | G49: =_xll.EQNXTDZ($A$1,$B49,G$1,$B$1) -> 1.0205 | H49: =_xll.EQNXTDZ($A$1,$B49,H$1,$B$1) -> 0 | I49: =_xll.EQNXTDZ($A$1,$B49,I$1,$B$1) -> -0.0003 | J49: =_xll.EQNXTDZ($A$1,$B49,J$1,$B$1) -> -1.0473 | ... AG49: =_xll.EQNXTDZ($A$1,$B49,AG$1,$B$1) -> 0
A50: Other Long Term Liabilities | B50: BS_OTH_LT_LIAB | C50: =_xll.EQNXTDZ($A$1,$B50,C$1,$B$1) -> 0 | D50: =_xll.EQNXTDZ($A$1,$B50,D$1,$B$1) -> 0 | E50: =_xll.EQNXTDZ($A$1,$B50,E$1,$B$1) -> 0 | F50: =_xll.EQNXTDZ($A$1,$B50,F$1,$B$1) -> 0 | G50: =_xll.EQNXTDZ($A$1,$B50,G$1,$B$1) -> 0 | H50: =_xll.EQNXTDZ($A$1,$B50,H$1,$B$1) -> 0 | I50: =_xll.EQNXTDZ($A$1,$B50,I$1,$B$1) -> 0 | J50: =_xll.EQNXTDZ($A$1,$B50,J$1,$B$1) -> 0 | ... AG50: =_xll.EQNXTDZ($A$1,$B50,AG$1,$B$1) -> 0
A51: Long Term Trade Payables | B51: BS_LT_TRADE_PAYABLES | C51: =_xll.EQNXTDZ($A$1,$B51,C$1,$B$1) -> 0 | D51: =_xll.EQNXTDZ($A$1,$B51,D$1,$B$1) -> 0 | E51: =_xll.EQNXTDZ($A$1,$B51,E$1,$B$1) -> 0 | F51: =_xll.EQNXTDZ($A$1,$B51,F$1,$B$1) -> 0 | G51: =_xll.EQNXTDZ($A$1,$B51,G$1,$B$1) -> 0 | H51: =_xll.EQNXTDZ($A$1,$B51,H$1,$B$1) -> 0 | I51: =_xll.EQNXTDZ($A$1,$B51,I$1,$B$1) -> 0 | J51: =_xll.EQNXTDZ($A$1,$B51,J$1,$B$1) -> 0 | ... AG51: =_xll.EQNXTDZ($A$1,$B51,AG$1,$B$1) -> 0
... A99: Estimated Capital Contracts Remaining | B99: BS_ESTIMATED_CAPITAL_CONTRACT | C99: =_xll.EQNXTDZ($A$1,$B99,C$1,$B$1) -> 0 | D99: =_xll.EQNXTDZ($A$1,$B99,D$1,$B$1) -> 0 | E99: =_xll.EQNXTDZ($A$1,$B99,E$1,$B$1) -> 0 | F99: =_xll.EQNXTDZ($A$1,$B99,F$1,$B$1) -> 0 | G99: =_xll.EQNXTDZ($A$1,$B99,G$1,$B$1) -> 0 | H99: =_xll.EQNXTDZ($A$1,$B99,H$1,$B$1) -> 0 | I99: =_xll.EQNXTDZ($A$1,$B99,I$1,$B$1) -> 0 | J99: =_xll.EQNXTDZ($A$1,$B99,J$1,$B$1) -> 0 | ... AG99: =_xll.EQNXTDZ($A$1,$B99,AG$1,$B$1) -> 0
A103: Field Description | B103: Field Name
A104: Equity Paid Up | B104: BS_EQUITY_PAIDUP | C104: =_xll.EQNXTDZ($A$1,$B104,C$1,$B$1) -> 17.403 | D104: =_xll.EQNXTDZ($A$1,$B104,D$1,$B$1) -> 17.403 | E104: =_xll.EQNXTDZ($A$1,$B104,E$1,$B$1) -> 17.4039 | F104: =_xll.EQNXTDZ($A$1,$B104,F$1,$B$1) -> 17.4039 | G104: =_xll.EQNXTDZ($A$1,$B104,G$1,$B$1) -> 17.4039 | H104: =_xll.EQNXTDZ($A$1,$B104,H$1,$B$1) -> 17.4039 | I104: =_xll.EQNXTDZ($A$1,$B104,I$1,$B$1) -> 17.4039 | J104: =_xll.EQNXTDZ($A$1,$B104,J$1,$B$1) -> 17.4039 | ... AG104: =_xll.EQNXTDZ($A$1,$B104,AG$1,$B$1) -> 0
A105: Face Value | B105: BS_FACE_VALUE | C105: =_xll.EQNXTDZ($A$1,$B105,C$1,$B$1) -> 10 | D105: =_xll.EQNXTDZ($A$1,$B105,D$1,$B$1) -> 10 | E105: =_xll.EQNXTDZ($A$1,$B105,E$1,$B$1) -> 10 | F105: =_xll.EQNXTDZ($A$1,$B105,F$1,$B$1) -> 10 | G105: =_xll.EQNXTDZ($A$1,$B105,G$1,$B$1) -> 10 | H105: =_xll.EQNXTDZ($A$1,$B105,H$1,$B$1) -> 10 | I105: =_xll.EQNXTDZ($A$1,$B105,I$1,$B$1) -> 10 | J105: =_xll.EQNXTDZ($A$1,$B105,J$1,$B$1) -> 10 | ... AG105: =_xll.EQNXTDZ($A$1,$B105,AG$1,$B$1) -> 0
A106: Close Price (Unit Curr.) | B106: FH_YEAR_PRICE | C106: =_xll.EQNXTDZ($A$1,$B106,C$1,$B$1) -> 9.6 | D106: =_xll.EQNXTDZ($A$1,$B106,D$1,$B$1) -> 5.375 | E106: =_xll.EQNXTDZ($A$1,$B106,E$1,$B$1) -> 5.995 | F106: =_xll.EQNXTDZ($A$1,$B106,F$1,$B$1) -> 12.575 | G106: =_xll.EQNXTDZ($A$1,$B106,G$1,$B$1) -> 24.33 | H106: =_xll.EQNXTDZ($A$1,$B106,H$1,$B$1) -> 41.88 | I106: =_xll.EQNXTDZ($A$1,$B106,I$1,$B$1) -> 67.635 | J106: =_xll.EQNXTDZ($A$1,$B106,J$1,$B$1) -> 46.53 | ... AG106: =_xll.EQNXTDZ($A$1,$B106,AG$1,$B$1) -> 0
A107: High Price (Unit Curr.) | B107: FH_HIGH | C107: =_xll.EQNXTDZ($A$1,$B107,C$1,$B$1) -> 25.4 | D107: =_xll.EQNXTDZ($A$1,$B107,D$1,$B$1) -> 10.365 | E107: =_xll.EQNXTDZ($A$1,$B107,E$1,$B$1) -> 9.5 | F107: =_xll.EQNXTDZ($A$1,$B107,F$1,$B$1) -> 16.2 | G107: =_xll.EQNXTDZ($A$1,$B107,G$1,$B$1) -> 24.485 | H107: =_xll.EQNXTDZ($A$1,$B107,H$1,$B$1) -> 45.5 | I107: =_xll.EQNXTDZ($A$1,$B107,I$1,$B$1) -> 68.04 | J107: =_xll.EQNXTDZ($A$1,$B107,J$1,$B$1) -> 67.9 | ... AG107: =_xll.EQNXTDZ($A$1,$B107,AG$1,$B$1) -> 0
A108: Low Price (Unit Curr.) | B108: FH_LOW | C108: =_xll.EQNXTDZ($A$1,$B108,C$1,$B$1) -> 9.5 | D108: =_xll.EQNXTDZ($A$1,$B108,D$1,$B$1) -> 4.9 | E108: =_xll.EQNXTDZ($A$1,$B108,E$1,$B$1) -> 4.44 | F108: =_xll.EQNXTDZ($A$1,$B108,F$1,$B$1) -> 5.75 | G108: =_xll.EQNXTDZ($A$1,$B108,G$1,$B$1) -> 7.7 | H108: =_xll.EQNXTDZ($A$1,$B108,H$1,$B$1) -> 20.125 | I108: =_xll.EQNXTDZ($A$1,$B108,I$1,$B$1) -> 36 | J108: =_xll.EQNXTDZ($A$1,$B108,J$1,$B$1) -> 41.525 | ... AG108: =_xll.EQNXTDZ($A$1,$B108,AG$1,$B$1) -> 0
A109: Market Capitalization | B109: FH_MCAP | C109: =_xll.EQNXTDZ($A$1,$B109,C$1,$B$1) -> 167.0688 | D109: =_xll.EQNXTDZ($A$1,$B109,D$1,$B$1) -> 93.541125 | E109: =_xll.EQNXTDZ($A$1,$B109,E$1,$B$1) -> 104.33638 | F109: =_xll.EQNXTDZ($A$1,$B109,F$1,$B$1) -> 218.85404 | G109: =_xll.EQNXTDZ($A$1,$B109,G$1,$B$1) -> 423.43689 | H109: =_xll.EQNXTDZ($A$1,$B109,H$1,$B$1) -> 728.87533 | I109: =_xll.EQNXTDZ($A$1,$B109,I$1,$B$1) -> 1177.1128 | J109: =_xll.EQNXTDZ($A$1,$B109,J$1,$B$1) -> 809.80347 | ... AG109: =_xll.EQNXTDZ($A$1,$B109,AG$1,$B$1) -> 0
A110: Adj DPS(Rs) | B110: FR_ADJ_DPS | C110: =_xll.EQNXTDZ($A$1,$B110,C$1,$B$1) -> 0.3 | D110: =_xll.EQNXTDZ($A$1,$B110,D$1,$B$1) -> 0.3 | E110: =_xll.EQNXTDZ($A$1,$B110,E$1,$B$1) -> 0.3 | F110: =_xll.EQNXTDZ($A$1,$B110,F$1,$B$1) -> 0.35 | G110: =_xll.EQNXTDZ($A$1,$B110,G$1,$B$1) -> 0.4 | H110: =_xll.EQNXTDZ($A$1,$B110,H$1,$B$1) -> 0.45 | I110: =_xll.EQNXTDZ($A$1,$B110,I$1,$B$1) -> 0.55 | J110: =_xll.EQNXTDZ($A$1,$B110,J$1,$B$1) -> 0.55 | ... AG110: =_xll.EQNXTDZ($A$1,$B110,AG$1,$B$1) -> 0
A111: Date End | B111: SHP_DATE_END | C111: =_xll.EQNXTDZ($A$1,$B111,C$5) -> 0 | D111: =_xll.EQNXTDZ($A$1,$B111,D$5) -> 200103 | E111: =_xll.EQNXTDZ($A$1,$B111,E$5) -> 200212 | F111: =_xll.EQNXTDZ($A$1,$B111,F$5) -> 200312 | G111: =_xll.EQNXTDZ($A$1,$B111,G$5) -> 200412 | H111: =_xll.EQNXTDZ($A$1,$B111,H$5) -> 200512 | I111: =_xll.EQNXTDZ($A$1,$B111,I$5) -> 200612 | J111: =_xll.EQNXTDZ($A$1,$B111,J$5) -> 200712 | ... AG111: =_xll.EQNXTDZ($A$1,$B111,AG$5) -> 0
A112: Total of Promoter and Promoter Group | B112: SHP_TPFTOTALPROMOTER | C112: =_xll.EQNXTDZ($A$1,$B112,C$5) -> 0 | D112: =_xll.EQNXTDZ($A$1,$B112,D$5) -> 65.38 | E112: =_xll.EQNXTDZ($A$1,$B112,E$5) -> 66.55 | F112: =_xll.EQNXTDZ($A$1,$B112,F$5) -> 66.49 | G112: =_xll.EQNXTDZ($A$1,$B112,G$5) -> 66.49 | H112: =_xll.EQNXTDZ($A$1,$B112,H$5) -> 66.49 | I112: =_xll.EQNXTDZ($A$1,$B112,I$5) -> 66.49 | J112: =_xll.EQNXTDZ($A$1,$B112,J$5) -> 66.49 | ... AG112: =_xll.EQNXTDZ($A$1,$B112,AG$5) -> 0
...

Sheet QTR Share Price
