Workbook

Sheet Template
A1: =+'Annual Raw'!C4 -> Larsen & Toubro Ltd. | B1: 36951 | C1: =EOMONTH(B1,12) -> 37346 | D1: =EOMONTH(C1,12) -> 37711 | E1: =EOMONTH(D1,12) -> 38077 | F1: =EOMONTH(E1,12) -> 38442 | G1: =EOMONTH(F1,12) -> 38807 | H1: =EOMONTH(G1,12) -> 39172 | I1: =EOMONTH(H1,12) -> 39538 | J1: =EOMONTH(I1,12) -> 39903 | ... AE1: =EOMONTH(AD1,12) -> 47573 | AH1: QTR | AI1: 41061 | AJ1: 41153 | AK1: 41244 | AL1: 41334 | AM1: 41426 | AN1: 41518 | AO1: 41609 | AP1: 41699 | AQ1: 41791 | AR1: 41883 | AS1: 41974 | AT1: 42064 | AU1: 42156 | AV1: 42248 | AW1: 42339 | AX1: 42430 | AY1: 42522 | AZ1: 42614 | BA1: 42705 | BB1: 42795 | BC1: 42887 | BD1: 42979 | BE1: 43070 | BF1: 43160 | BG1: 43252 | BH1: 43344 | BI1: 43435 | BJ1: 43525 | BK1: 43617 | BL1: 43709 | BM1: 43800 | BN1: 43891 | BO1: 43983 | BP1: 44075 | BQ1: =EOMONTH(BP1,3) -> 44196 | BR1: =EOMONTH(BQ1,3) -> 44286 | BS1: =EOMONTH(BR1,3) -> 44377 | BT1: =EOMONTH(BS1,3) -> 44469 | BU1: =EOMONTH(BT1,3) -> 44561 | BV1: =EOMONTH(BU1,3) -> 44651 | BW1: =EOMONTH(BV1,3) -> 44742 | BX1: =EOMONTH(BW1,3) -> 44834 | ... DB1: =EOMONTH(DA1,3) -> 47573 | DE1: HISTORICAL ESTIMATES | DF1: 46112
A2: Presentation Data (Start)
A4: Order Book-Segment Wise
A5: Infrastructure Projects Segment (orderbook) | CG5: =+CG7+CG14+CG21 -> 98787
A6: Infrastructure Projects Segment- Opening | T6: 0 | U6: 221810.4 | V6: 224886 | W6: 245550 | X6: 261048 | Y6: 283645 | Z6: =+Y9 -> 311665 | AA6: =+Z9 -> 357073 | AB6: =+AA9 -> 422562 | AC6: =+AB9 -> 481360.92 | AD6: =+AC9 -> 536492.48 | AE6: =+AD9 -> 590139 | BK6: =+BJ9 -> 221810.4 | BL6: =+BK9 -> 218736 | BM6: =+BL9 -> 215272 | BN6: =+BM9 -> 223599 | BO6: =+BN9 -> 224886 | BP6: =+BO9 -> 219672 | BQ6: =+BP9 -> 221186 | BR6: =+BQ9 -> 245014 | ... DB6: =+DA9 -> 655126.42 | DF6: 424937
A7: Infrastructure Projects Segment- Addition | T7: 0 | U7: 64498 | V7: 82094 | W7: 87902 | X7: 109314 | Y7: 140571 | Z7: =+SUM(CE7:CH7) -> 175305 | AA7: =SUM(CI7:CL7) -> 199399 | AB7: =+SUM(CM7:CP7) -> 214498.19 | AC7: =+SUM(CQ7:CT7) -> 230740.75 | AD7: =+SUM(CU7:CX7) -> 248213.25 | AE7: =+SUM(CY7:DB7) -> 267008.83 | BK7: =+BK9+BK8-BK6 -> 10519.6 | BL7: =+BL9+BL8-BL6 -> 12766 | BM7: =+BM9+BM8-BM6 -> 25353 | BN7: =+BN9+BN8-BN6 -> 26379 | BO7: =+BO9+BO8-BO6 -> 1179 | BP7: =+BP9+BP8-BP6 -> 14483 | BQ7: =+BQ9+BQ8-BQ6 -> 39656 | BR7: =+BR9+BR8-BR6 -> 26776 | ... CL7: =+CL9+CL8-CL6 -> 37319 | CM7: =+CI7+(CI7*CM10) -> 45259.991 | CN7: =+CJ7+(CJ7*CN10) -> 60321.196 | CO7: =+CK7+(CK7*CO10) -> 68772.08 | CP7: =+CL7+(CL7*CP10) -> 40144.926 | CQ7: =+CM7+(CM7*CQ10) -> 48687.236 | CR7: =+CN7+(CN7*CR10) -> 64888.928 | CS7: =+CO7+(CO7*CS10) -> 73979.743 | CT7: =+CP7+(CP7*CT10) -> 43184.84 | ... DB7: =+CX7+(CX7*DB10) -> 49972.68 | DF7: 41630.4
A8: Infrastructure Projects Segment- Execution % | T8: 0 | U8: 58348 | V8: 61430 | W8: 72404 | X8: 86717 | Y8: 112551 | Z8: =+SUM(CE8:CH8) -> 129897 | AA8: =SUM(CI8:CL8) -> 133910 | AB8: =+SUM(CM8:CP8) -> 155699.27 | AC8: =+SUM(CQ8:CT8) -> 175609.19 | AD8: =+SUM(CU8:CX8) -> 194566.73 | AE8: =+SUM(CY8:DB8) -> 213245.06 | AF8: =24*80 -> 1920 | AG8: tr | BK8: =+BK37 -> 13594 | BL8: =+BL37 -> 16230 | BM8: =+BM37 -> 17026 | BN8: =+BN37 -> 25092 | BO8: =+BO37 -> 6393 | BP8: =+BP37 -> 12969 | BQ8: =+BQ37 -> 15828 | BR8: =+BR37 -> 26240 | ... CL8: =+CL37 -> 39694 | CM8: =+CM6*CM11 -> 34031.18 | CN8: =+CN6*CN11 -> 37195.287 | CO8: =+CO6*CO11 -> 39011.552 | CP8: =+CP6*CP11 -> 45461.249 | CQ8: =+CQ6*CQ11 -> 38766.572 | CR8: =+CR6*CR11 -> 42124.82 | CS8: =+CS6*CS11 -> 43889.224 | CT8: =+CT6*CT11 -> 50828.577 | ... DB8: =+DB6*DB11 -> 61196.338 | DF8: 36281.12
A9: Infrastructure Projects Segment- Closing | T9: 221810.4 | U9: 224886 | V9: 245550 | W9: 261048 | X9: 283645 | Y9: 311665 | Z9: =+Z6+Z7-Z8 -> 357073 | AA9: =+AA6+AA7-AA8 -> 422562 | AB9: =+AB6+AB7-AB8 -> 481360.92 | AC9: =+AC6+AC7-AC8 -> 536492.48 | AD9: =+AD6+AD7-AD8 -> 590139 | AE9: =+AE6+AE7-AE8 -> 643902.76 | AF9: 1.1 | AG9: tr | AY9: 190476 | AZ9: 186332 | BA9: 193950 | BB9: 193362 | BC9: 197175 | BD9: 190550 | BE9: 200318 | BF9: 195483.3 | BG9: 210567.5 | BH9: 218211.2 | BI9: 219248 | BJ9: 221810.4 | BK9: 218736 | BL9: 215272 | BM9: 223599 | BN9: 224886 | BO9: 219672 | BP9: 221186 | BQ9: 245014 | BR9: 245550 | BS9: 246012 | BT9: 244570 | BU9: 248492 | BV9: 261048 | BW9: 265282 | BX9: 268128 | BY9: 278352 | BZ9: 283645 | CA9: 301198 | CB9: 301969 | CC9: 317693 | CD9: 311665 | CE9: 323994 | CF9: 342954 | CG9: 361282 | CH9: 357073 | CI9: 370390 | CJ9: 394706 | CK9: 424937 | CL9: 422562 | CM9: =+CM6+CM7-CM8 -> 433790.81 | CN9: =+CN6+CN7-CN8 -> 456916.72 | CO9: =+CO6+CO7-CO8 -> 486677.25 | CP9: =+CP6+CP7-CP8 -> 481360.92 | CQ9: =+CQ6+CQ7-CQ8 -> 491281.59 | CR9: =+CR6+CR7-CR8 -> 514045.7 | CS9: =+CS6+CS7-CS8 -> 544136.22 | CT9: =+CT6+CT7-CT8 -> 536492.48 | ... DB9: =+DB6+DB7-DB8 -> 643902.76 | DF9: 430286.28
A10: Infrastructure Projects Segment- Inflow growth YoY% | U10: =+U7/T7-1 -> #DIV/0! | V10: =+V7/U7-1 -> 0.27281466 | W10: =+W7/V7-1 -> 0.070748167 | X10: =+X7/W7-1 -> 0.24358945 | Y10: =+Y7/X7-1 -> 0.28593776 | Z10: =+Z7/Y7-1 -> 0.24709222 | AA10: =+AA7/Z7-1 -> 0.13744046 | AB10: =+AB7/AA7-1 -> 0.07572351 | ... AE10: =+AE7/AD7-1 -> 0.07572351 | AF10: =+AF9*20% -> 0.22 | AG10: bn | BP10: =+BP7/BL7-1 -> 0.13449789 | BQ10: =+BQ7/BM7-1 -> 0.56415414 | BR10: =+BR7/BN7-1 -> 0.01504985 | BS10: =+BS7/BO7-1 -> 8.2205259 | BT10: =+BT7/BP7-1 -> -0.13823103 | BU10: =+BU7/BQ7-1 -> -0.43849607 | BV10: =+BV7/BR7-1 -> 0.57913803 | BW10: =+BW7/BS7-1 -> 0.6939564 | ... CL10: =+CL7/CH7-1 -> 0.07572351 | CM10: =+CL10 -> 0.07572351 | CN10: =+CM10 -> 0.07572351 | CO10: =+CN10 -> 0.07572351 | CP10: =+CO10 -> 0.07572351 | CQ10: =+CP10 -> 0.07572351 | CR10: =+CQ10 -> 0.07572351 | CS10: =+CR10 -> 0.07572351 | CT10: =+CS10 -> 0.07572351 | ... DB10: =+DA10 -> 0.07572351 | DF10: 0.2
A11: Infrastructure Projects Segment- Execution % | U11: =+U8/U6 -> 0.26305349 | V11: =+V8/V6 -> 0.27316062 | W11: =+W8/W6 -> 0.29486459 | X11: =+X8/X6 -> 0.33218795 | Y11: =+Y8/Y6 -> 0.39680234 | Z11: =+Z8/Z6 -> 0.41678405 | AA11: =+AA8/AA6 -> 0.37502135 | AB11: =+AB8/AB6 -> 0.3684649 | ... AE11: =+AE8/AE6 -> 0.36134718 | BP11: =+BP8/BP6 -> 0.05903802 | BQ11: =+BQ8/BQ6 -> 0.071559683 | BR11: =+BR8/BR6 -> 0.10709592 | BS11: =+BS8/BS6 -> 0.042390552 | BT11: =+BT8/BT6 -> 0.0565948 | BU11: =+BU8/BU6 -> 0.0750092 | BV11: =+BV8/BV6 -> 0.11962961 | BW11: =+BW8/BW6 -> 0.054323343 | ... CL11: =+CL8/CL6 -> 0.093411494 | CM11: =+CI11 -> 0.080535353 | CN11: =+CJ11 -> 0.085744756 | CO11: =+CK11 -> 0.085380004 | CP11: =+CL11 -> 0.093411494 | CQ11: =+CM11 -> 0.080535353 | CR11: =+CN11 -> 0.085744756 | CS11: =+CO11 -> 0.085380004 | CT11: =+CP11 -> 0.093411494 | ... DB11: =+CX11 -> 0.093411494 | DF11: 0.09
A12: Energy Projects Segment (orderbook)
A13: Energy Projects Segment- Opening | T13: 0 | U13: 46944 | V13: 60780 | W13: 58932 | X13: 64368 | Y13: 71910 | Z13: =+Y16 -> 118189 | AA13: =+Z16 -> 165754 | AB13: =+AA16 -> 258472 | AC13: =+AB16 -> 308318.27 | AD13: =+AC16 -> 328729.74 | AE13: =+AD16 -> 329515.3 | BL13: =+BK16 -> 53214 | BM13: =+BL16 -> 66704 | BN13: =+BM16 -> 64323 | BO13: =+BN16 -> 60780 | BP13: =+BO16 -> 57969 | BQ13: =+BP16 -> 53802 | BR13: =+BQ16 -> 59598 | BS13: =+BR16 -> 58932 | ... DB13: =+DA16 -> 325589.32 | DF13: 247861
A14: Energy Projects Segment- Addition | T14: 0 | U14: 22956 | V14: 18251 | W14: 29029 | X14: 32450 | Y14: 75818 | Z14: =+SUM(CE14:CH14) -> 88229 | AA14: =SUM(CI14:CL14) -> 147590 | AB14: =+SUM(CM14:CP14) -> 124788.23 | AC14: =+SUM(CQ14:CT14) -> 105509.19 | AD14: =+SUM(CU14:CX14) -> 89208.649 | AE14: =+SUM(CY14:DB14) -> 75426.445 | BL14: =+BL16+BL15-BL13 -> 18276 | BM14: =+BM16+BM15-BM13 -> 2700 | BN14: =+BN16+BN15-BN13 -> 1980 | BO14: =+BO16+BO15-BO13 -> 625 | BP14: =+BP16+BP15-BP13 -> 564 | BQ14: =+BQ16+BQ15-BQ13 -> 11100 | BR14: =+BR16+BR15-BR13 -> 5962 | BS14: =+BS16+BS15-BS13 -> 1046 | ... CL14: =+CL16+CL15-CL13 -> 27205 | CM14: =+CI14+(CI14*CM17) -> 28000.621 | CN14: =+CJ14+(CJ14*CN17) -> 34815.399 | CO14: =+CK14+(CK14*CO17) -> 38970.216 | CP14: =+CL14+(CL14*CP17) -> 23001.99 | CQ14: =+CM14+(CM14*CQ17) -> 23674.692 | CR14: =+CN14+(CN14*CR17) -> 29436.628 | CS14: =+CO14+(CO14*CS17) -> 32949.55 | CT14: =+CP14+(CP14*CT17) -> 19448.32 | ... DB14: =+CX14+(CX14*DB17) -> 13903.221 | DF14: 37323.8
A15: Energy Projects Segment- Execution % | T15: 0 | U15: 15390 | V15: 20099 | W15: 23593 | X15: 24908 | Y15: 29539 | Z15: =+SUM(CE15:CH15) -> 40664 | AA15: =SUM(CI15:CL15) -> 54872 | AB15: =+SUM(CM15:CP15) -> 74941.955 | AC15: =+SUM(CQ15:CT15) -> 85097.72 | AD15: =+SUM(CU15:CX15) -> 88423.093 | AE15: =+SUM(CY15:DB15) -> 87247.019 | BL15: =+BL38 -> 4786 | BM15: =+BM38 -> 5081 | BN15: =+BN38 -> 5523 | BO15: =+BO38 -> 3436 | BP15: =+BP38 -> 4731 | BQ15: =+BQ38 -> 5304 | BR15: =+BR38 -> 6628 | BS15: =+BS38 -> 4949 | ... CL15: =+CL38 -> 16594 | CM15: =+CM13*CM18 -> 17304.394 | CN15: =+CN13*CN18 -> 18020.494 | CO15: =+CO13*CO18 -> 19144.893 | CP15: =+CP13*CP18 -> 20472.174 | CQ15: =+CQ13*CQ18 -> 20641.543 | CR15: =+CR13*CR18 -> 20844.608 | CS15: =+CS13*CS18 -> 21419.834 | CT15: =+CT13*CT18 -> 22191.735 | ... DB15: =+DB13*DB18 -> 21797.819 | DF15: 14705.54
A16: Energy Projects Segment- Closing | T16: 46944 | U16: 60780 | V16: 58932 | W16: 64368 | X16: 71910 | Y16: 118189 | Z16: =+Z13+Z14-Z15 -> 165754 | AA16: =+AA13+AA14-AA15 -> 258472 | AB16: =+AB13+AB14-AB15 -> 308318.27 | AC16: =+AC13+AC14-AC15 -> 328729.74 | AD16: =+AD13+AD14-AD15 -> 329515.3 | AE16: =+AE13+AE14-AE15 -> 317694.72 | AY16: 38610 | AZ16: 37770 | BA16: 36204 | BB16: 39195 | BC16: 36806 | BD16: 36050 | BE16: 40605 | BF16: 36044.7 | BG16: 36407.8 | BH16: 36837.2 | BI16: 40044 | BJ16: 46944 | BK16: 53214 | BL16: 66704 | BM16: 64323 | BN16: 60780 | BO16: 57969 | BP16: 53802 | BQ16: 59598 | BR16: 58932 | BS16: 55029 | BT16: 62795 | BU16: 64676 | BV16: 64368 | BW16: 65412 | BX16: 70756 | BY16: 73454 | BZ16: 71910 | CA16: 74268 | CB16: 108168 | CC16: 112777 | CD16: 118189 | CE16: 117816 | CF16: 117144 | CG16: 145827 | CH16: 165754 | CI16: 186401 | CJ16: 214496 | CK16: 247861 | CL16: 258472 | CM16: =+CM13+CM14-CM15 -> 269168.23 | CN16: =+CN13+CN14-CN15 -> 285963.13 | CO16: =+CO13+CO14-CO15 -> 305788.46 | CP16: =+CP13+CP14-CP15 -> 308318.27 | CQ16: =+CQ13+CQ14-CQ15 -> 311351.42 | CR16: =+CR13+CR14-CR15 -> 319943.44 | CS16: =+CS13+CS14-CS15 -> 331473.16 | CT16: =+CT13+CT14-CT15 -> 328729.74 | ... DB16: =+DB13+DB14-DB15 -> 317694.72 | DF16: 270479.27
A17: Energy Projects Segment- Inflow growth YoY% | U17: =+U14/T14-1 -> #DIV/0! | V17: =+V14/U14-1 -> -0.20495731 | W17: =+W14/V14-1 -> 0.59054298 | X17: =+X14/W14-1 -> 0.11784767 | Y17: =+Y14/X14-1 -> 1.3364561 | Z17: =+Z14/Y14-1 -> 0.16369464 | AA17: =+AA14/Z14-1 -> 0.67280599 | AB17: =+AB14/AA14-1 -> -0.15449403 | ... AE17: =+AE14/AD14-1 -> -0.15449403 | BP17: =+BP14/BL14-1 -> -0.96913986 | BQ17: =+BQ14/BM14-1 -> 3.1111111 | BR17: =+BR14/BN14-1 -> 2.0111111 | BS17: =+BS14/BO14-1 -> 0.6736 | BT17: =+BT14/BP14-1 -> 23.374113 | BU17: =+BU14/BQ14-1 -> -0.29486486 | BV17: =+BV14/BR14-1 -> 0.074974841 | BW17: =+BW14/BS14-1 -> 4.8479924 | ... CL17: =+CL14/CH14-1 -> -0.15449403 | CM17: =+CL17 -> -0.15449403 | CN17: =+CM17 -> -0.15449403 | CO17: =+CN17 -> -0.15449403 | CP17: =+CO17 -> -0.15449403 | CQ17: =+CP17 -> -0.15449403 | CR17: =+CQ17 -> -0.15449403 | CS17: =+CR17 -> -0.15449403 | CT17: =+CS17 -> -0.15449403 | ... DB17: =+DA17 -> -0.15449403 | DF17: 0.16
A18: Energy Projects Segment- Execution % | U18: =+U15/U13 -> 0.32783742 | V18: =+V15/V13 -> 0.33068444 | W18: =+W15/W13 -> 0.40034277 | X18: =+X15/X13 -> 0.38696247 | Y18: =+Y15/Y13 -> 0.41077736 | Z18: =+Z15/Z13 -> 0.34405909 | AA18: =+AA15/AA13 -> 0.3310448 | AB18: =+AB15/AB13 -> 0.28994226 | ... AE18: =+AE15/AE13 -> 0.2647738 | BP18: =+BP15/BP13 -> 0.081612586 | BQ18: =+BQ15/BQ13 -> 0.098583696 | BR18: =+BR15/BR13 -> 0.11121179 | BS18: =+BS15/BS13 -> 0.083978144 | BT18: =+BT15/BT13 -> 0.10868815 | BU18: =+BU15/BU13 -> 0.094689068 | BV18: =+BV15/BV13 -> 0.10385614 | BW18: =+BW15/BW13 -> 0.078812453 | ... CL18: =+CL15/CL13 -> 0.066948814 | CM18: =+CL18 -> 0.066948814 | CN18: =+CM18 -> 0.066948814 | CO18: =+CN18 -> 0.066948814 | CP18: =+CO18 -> 0.066948814 | CQ18: =+CP18 -> 0.066948814 | CR18: =+CQ18 -> 0.066948814 | CS18: =+CR18 -> 0.066948814 | CT18: =+CS18 -> 0.066948814 | ... DB18: =+DA18 -> 0.066948814 | DF18: 0.06
A19: Hi-Tech Manufacturing Segment (orderbook)
A20: Hi-Tech Manufacturing Segment- Opening | T20: 0 | U20: 18777.6 | V20: 12156 | W20: 9822 | X20: 21456 | Y20: 27965 | Z20: =+Y23 -> 31975 | AA20: =+Z23 -> 40388 | AB20: =+AA23 -> 35312 | AC20: =+AB23 -> 29557.791 | AD20: =+AC23 -> 24128.405 | AE20: =+AD23 -> 19586.428 | BL20: =+BK23 -> 15288 | BM20: =+BL23 -> 15160 | BN20: =+BM23 -> 12252 | BO20: =+BN23 -> 12156 | BP20: =+BO23 -> 12204 | BQ20: =+BP23 -> 11956 | BR20: =+BQ23 -> 13244 | BS20: =+BR23 -> 9822 | ... DB20: =+DA23 -> 17404.697 | DF20: 37865
A21: Hi-Tech Manufacturing Segment- Addition | T21: 0 | U21: 1602 | V21: 3773 | W21: 17575 | X21: 13044 | Y21: 12205 | Z21: =+SUM(CE21:CH21) -> 18108 | AA21: =SUM(CI21:CL21) -> 9033 | AB21: =+SUM(CM21:CP21) -> 9033 | AC21: =+SUM(CQ21:CT21) -> 9033 | AD21: =+SUM(CU21:CX21) -> 9033 | AE21: =+SUM(CY21:DB21) -> 9033 | BL21: =+BL23+BL22-BL20 -> 1447 | BM21: =+BM23+BM22-BM20 -> -1182 | BN21: =+BN23+BN22-BN20 -> 1337 | BO21: =+BO23+BO22-BO20 -> 899 | BP21: =+BP23+BP22-BP20 -> 1118 | BQ21: =+BQ23+BQ22-BQ20 -> 3043 | BR21: =+BR23+BR22-BR20 -> -1287 | BS21: =+BS23+BS22-BS20 -> 1126 | ... CL21: =+CL23+CL22-CL20 -> 2308 | CM21: =+CI21+(CI21*CM24) -> 2001 | CN21: =+CJ21+(CJ21*CN24) -> 2656 | CO21: =+CK21+(CK21*CO24) -> 2068 | CP21: =+CL21+(CL21*CP24) -> 2308 | CQ21: =+CM21+(CM21*CQ24) -> 2001 | CR21: =+CN21+(CN21*CR24) -> 2656 | CS21: =+CO21+(CO21*CS24) -> 2068 | CT21: =+CP21+(CP21*CT24) -> 2308 | ... DB21: =+CX21+(CX21*DB24) -> 2308 | DF21: 474.93
A22: Hi-Tech Manufacturing Segment- Executiom | T22: 0 | U22: 4734 | V22: 6107 | W22: 5941 | X22: 6535 | Y22: 8195 | Z22: =+SUM(CE22:CH22) -> 9695 | AA22: =SUM(CI22:CL22) -> 14109 | AB22: =+SUM(CM22:CP22) -> 14787.209 | AC22: =+SUM(CQ22:CT22) -> 14462.387 | AD22: =+SUM(CU22:CX22) -> 13574.976 | AE22: =+SUM(CY22:DB22) -> 12533.472 | BL22: =+BL39 -> 1575 | BM22: =+BM39 -> 1726 | BN22: =+BN39 -> 1433 | BO22: =+BO39 -> 851 | BP22: =+BP39 -> 1366 | BQ22: =+BQ39 -> 1755 | BR22: =+BR39 -> 2135 | BS22: =+BS39 -> 1237 | ... CL22: =+CL39 -> 4861 | CM22: =+CM20*CM25 -> 3527.6678 | CN22: =+CN20*CN25 -> 3051.6018 | CO22: =+CO20*CO25 -> 3460.2442 | CP22: =+CP20*CP25 -> 4747.6952 | CQ22: =+CQ20*CQ25 -> 3543.9783 | CR22: =+CR20*CR25 -> 3090.6858 | CS22: =+CS20*CS25 -> 3409.7859 | CT22: =+CT20*CT25 -> 4417.9365 | ... DB22: =+DB20*DB25 -> 3626.7408 | DF22: 3797.81
A23: Hi-Tech Manufacturing Segment- Closing | T23: 18777.6 | U23: 12156 | V23: 9822 | W23: 21456 | X23: 27965 | Y23: 31975 | Z23: =+Z20+Z21-Z22 -> 40388 | AA23: =+AA20+AA21-AA22 -> 35312 | AB23: =+AB20+AB21-AB22 -> 29557.791 | AC23: =+AC20+AC21-AC22 -> 24128.405 | AD23: =+AD20+AD21-AD22 -> 19586.428 | AE23: =+AE20+AE21-AE22 -> 16085.956 | AY23: 10296 | AZ23: 10072 | BA23: 10344 | BB23: 15678 | BC23: 13145 | BD23: 15450 | BE23: 16242 | BF23: 16575.3 | BG23: 18747.3 | BH23: 20246.4 | BI23: 19028 | BJ23: 18777.6 | BK23: 15288 | BL23: 15160 | BM23: 12252 | BN23: 12156 | BO23: 12204 | BP23: 11956 | BQ23: 13244 | BR23: 9822 | BS23: 9711 | BT23: 9915 | BU23: 13616 | BV23: 21456 | BW23: 18170 | BX23: 18620 | BY23: 19330 | BZ23: 27965 | CA23: 24756 | CB23: 27042 | CC23: 25758 | CD23: 31975 | CE23: 34363 | CF23: 35611 | CG23: 41769 | CH23: 40388 | CI23: 39162 | CJ23: 39064 | CK23: 37865 | CL23: 35312 | CM23: =+CM20+CM21-CM22 -> 33785.332 | CN23: =+CN20+CN21-CN22 -> 33389.73 | CO23: =+CO20+CO21-CO22 -> 31997.486 | CP23: =+CP20+CP21-CP22 -> 29557.791 | CQ23: =+CQ20+CQ21-CQ22 -> 28014.813 | CR23: =+CR20+CR21-CR22 -> 27580.127 | CS23: =+CS20+CS21-CS22 -> 26238.341 | CT23: =+CT20+CT21-CT22 -> 24128.405 | ... DB23: =+DB20+DB21-DB22 -> 16085.956 | DF23: 34542.12
A24: Hi-Tech Manufacturing Segment- Inflow growth YoY% | U24: =+U21/T21-1 -> #DIV/0! | V24: =+V21/U21-1 -> 1.355181 | W24: =+W21/V21-1 -> 3.658097 | X24: =+X21/W21-1 -> -0.25780939 | Y24: =+Y21/X21-1 -> -0.064320761 | Z24: =+Z21/Y21-1 -> 0.48365424 | AA24: =+AA21/Z21-1 -> -0.50115971 | AB24: =+AB21/AA21-1 -> 0 | ... AE24: =+AE21/AD21-1 -> 0 | BP24: =+BP21/BL21-1 -> -0.22736697 | BQ24: =+BQ21/BM21-1 -> -3.5744501 | BR24: =+BR21/BN21-1 -> -1.9626028 | BS24: =+BS21/BO21-1 -> 0.25250278 | BT24: =+BT21/BP21-1 -> 0.49642218 | BU24: =+BU21/BQ21-1 -> 0.70029576 | BV24: =+BV21/BR21-1 -> -8.4607615 | BW24: =+BW21/BS21-1 -> -2.7886323 | ... CL24: =+CL21/CH21-1 -> 0.16979219 | CM24: 0 | CN24: 0 | CO24: 0 | CP24: 0 | CQ24: 0 | CR24: 0 | CS24: 0 | CT24: 0 | CU24: 0 | CV24: 0 | CW24: 0 | CX24: 0 | CY24: 0 | CZ24: 0 | DA24: 0 | DB24: 0 | DF24: -0.76
A25: Hi-Tech Manufacturing Segment- Execution % | U25: =+U22/U20 -> 0.2521089 | V25: =+V22/V20 -> 0.50238565 | W25: =+W22/W20 -> 0.60486663 | X25: =+X22/X20 -> 0.30457681 | Y25: =+Y22/Y20 -> 0.29304488 | Z25: =+Z22/Z20 -> 0.30320563 | AA25: =+AA22/AA20 -> 0.34933644 | AB25: =+AB22/AB20 -> 0.41875875 | ... AE25: =+AE22/AE20 -> 0.63990596 | BP25: =+BP22/BP20 -> 0.11193051 | BQ25: =+BQ22/BQ20 -> 0.14678822 | BR25: =+BR22/BR20 -> 0.16120507 | BS25: =+BS22/BS20 -> 0.12594176 | BT25: =+BT22/BT20 -> 0.15127175 | BU25: =+BU22/BU20 -> 0.14856278 | BV25: =+BV22/BV20 -> 0.12940658 | BW25: =+BW22/BW20 -> 0.059284116 | ... CL25: =+CL22/CL20 -> 0.12837713 | CM25: =+CI25+2% -> 0.09989997 | CN25: =+CJ25+2% -> 0.090323273 | CO25: =+CK25+2% -> 0.10363199 | CP25: =+CL25+2% -> 0.14837713 | CQ25: =+CM25+2% -> 0.11989997 | CR25: =+CN25+2% -> 0.11032327 | CS25: =+CO25+2% -> 0.12363199 | CT25: =+CP25+2% -> 0.16837713 | ... DB25: =+CX25+2% -> 0.20837713 | DF25: 0.1
A26: Other Segments- (Orderbook) | T26: 5868 | U26: 6078 | V26: 13096 | W26: 10728 | X26: 15980 | Y26: 13981 | Z26: =+CH26 -> 15921 | AA26: =+CL26 -> 23981 | AB26: =+CP26 -> 23981 | AC26: =+CT26 -> 23981 | AD26: =+CX26 -> 23981 | AE26: =+DB26 -> 23981 | AY26: 18018 | AZ26: 17626 | BA26: 18102 | BB26: 13065 | BC26: 15774 | BD26: 15450 | BE26: 13535 | BF26: 14996.7 | BG26: 5977.4 | BH26: 5624 | BI26: 5680 | BJ26: 5868 | BK26: 6762 | BL26: 6064 | BM26: 6126 | BN26: 6078 | BO26: 15255 | BP26: 11956 | BQ26: 13244 | BR26: 13096 | BS26: 12948 | BT26: 13220 | BU26: 13616 | BV26: 10728 | BW26: 14536 | BX26: 14896 | BY26: 15464 | BZ26: 15980 | CA26: 12378 | CB26: 13521 | CC26: 13580 | CD26: 13981 | CE26: 14727 | CF26: 14684 | CG26: 15345 | CH26: 15921 | CI26: 16808 | CJ26: 18774 | CK26: 22498 | CL26: 23981 | CM26: =+CL26 -> 23981 | CN26: =+CM26 -> 23981 | CO26: =+CN26 -> 23981 | CP26: =+CO26 -> 23981 | CQ26: =+CP26 -> 23981 | CR26: =+CQ26 -> 23981 | CS26: =+CR26 -> 23981 | CT26: =+CS26 -> 23981 | ... DB26: =+DA26 -> 23981 | DF26: 22498
A28: Total Order Book -Opening | BZ28: =+BY31 -> 386600 | CA28: =+BZ31 -> 399500 | CB28: =+CA31 -> 412600 | CC28: =+CB31 -> 450700 | CD28: =+CC31 -> 469808 | CE28: =+CD31 -> 475810 | CF28: =+CE31 -> 490900 | CG28: =+CF31 -> 510393 | ... DB28: =+DA31 -> 1022101.4
A29: Total Order Book -Addition | BZ29: =+BZ31+BZ30-BZ28 -> 71235 | CA29: =+CA31+CA30-CA28 -> 60982 | CB29: =+CB31+CB30-CB28 -> 89124 | CC29: =+CC31+CC30-CC28 -> 74236 | CD29: =+CD31+CD30-CD28 -> 73081 | CE29: =+CE31+CE30-CE28 -> 70209 | CF29: =+CF31+CF30-CF28 -> 81044 | CG29: =+CG31+CG30-CG28 -> 118498 | ... DB29: =+DB31+DB30-DB28 -> 127139.69
A30: Total Order Book -Execution | BZ30: =+BZ45 -> 58335 | CA30: =+CA45 -> 47882 | CB30: =+CB45 -> 51024 | CC30: =+CC45 -> 55128 | CD30: =+CD45 -> 67079 | CE30: =+CE45 -> 55119 | CF30: =+CF45 -> 61551 | CG30: =+CG45 -> 64668 | ... DB30: =+DB45 -> 147576.69
A31: Total Order Book-Closing | T31: =+T9+T16+T23+T26 -> 293400 | U31: =+U9+U16+U23+U26 -> 303900 | V31: =+V9+V16+V23+V26 -> 327400 | W31: =+W9+W16+W23+W26 -> 357600 | X31: =+X9+X16+X23+X26 -> 399500 | Y31: =+Y9+Y16+Y23+Y26 -> 475810 | Z31: =+Z9+Z16+Z23+Z26 -> 579136 | AA31: =+AA9+AA16+AA23+AA26 -> 740327 | ... AE31: =+AE9+AE16+AE23+AE26 -> 1001664.4 | AY31: =+AY9+AY16+AY23+AY26 -> 257400 | AZ31: =+AZ9+AZ16+AZ23+AZ26 -> 251800 | BA31: =+BA9+BA16+BA23+BA26 -> 258600 | BB31: =+BB9+BB16+BB23+BB26 -> 261300 | BC31: =+BC9+BC16+BC23+BC26 -> 262900 | BD31: =+BD9+BD16+BD23+BD26 -> 257500 | BE31: =+BE9+BE16+BE23+BE26 -> 270700 | BF31: =+BF9+BF16+BF23+BF26 -> 263100 | ... DB31: =+DB9+DB16+DB23+DB26 -> 1001664.4 | DF31: 757806
A32: Total Inflow Growth YoY% | CA32: =+CA29/BW29-1 -> #DIV/0! | CB32: =+CB29/BX29-1 -> #DIV/0! | CC32: =+CC29/BY29-1 -> #DIV/0! | CD32: =+CD29/BZ29-1 -> 0.025914228 | CE32: =+CE29/CA29-1 -> 0.15130694 | CF32: =+CF29/CB29-1 -> -0.090660204 | CG32: =+CG29/CC29-1 -> 0.59623363 | CH32: =+CH29/CD29-1 -> 0.22201393 | ... DB32: =+DB29/CX29-1 -> 0.1483027
A33: Total Order Book Growth YoY % | U33: =+U31/T31-1 -> 0.035787321 | V33: =+V31/U31-1 -> 0.077328068 | W33: =+W31/V31-1 -> 0.092241906 | X33: =+X31/W31-1 -> 0.11717002 | Y33: =+Y31/X31-1 -> 0.19101377 | Z33: =+Z31/Y31-1 -> 0.21715811 | AA33: =+AA31/Z31-1 -> 0.27833013 | AB33: =+AB31/AA31-1 -> 0.13898046 | ... AE33: =+AE31/AD31-1 -> 0.039910557 | BC33: =+BC31/AY31-1 -> 0.021367521 | BD33: =+BD31/AZ31-1 -> 0.022637014 | BE33: =+BE31/BA31-1 -> 0.04679041 | BF33: =+BF31/BB31-1 -> 0.0068886338 | BG33: =+BG31/BC31-1 -> 0.033472803 | BH33: =+BH31/BD31-1 -> 0.090946796 | BI33: =+BI31/BE31-1 -> 0.04913188 | BJ33: =+BJ31/BF31-1 -> 0.11516534 | ... DB33: =+DB31/CX31-1 -> 0.039910557 | DF33: 0.31
A35: Segment Revenue
A36: Projects & Manufacturing- Revenue | T36: =+SUM(T37:T40) -> 0 | U36: =+SUM(U37:U40) -> 104644 | V36: =+SUM(V37:V40) -> 93490 | W36: =+SUM(W37:W40) -> 107916 | X36: =+SUM(X37:X40) -> 124204 | Y36: =+SUM(Y37:Y40) -> 157910 | Z36: =+SUM(Z37:Z40) -> 187322 | AA36: =+SUM(AA37:AA40) -> 209984 | ... AE36: =+SUM(AE37:AE40) -> 319785.56 | BK36: =+SUM(BK37:BK40) -> 21176 | BL36: =+SUM(BL37:BL40) -> 24555 | BM36: =+SUM(BM37:BM40) -> 25365 | BN36: =+SUM(BN37:BN40) -> 33548 | BO36: =+SUM(BO37:BO40) -> 11394 | BP36: =+SUM(BP37:BP40) -> 20387 | BQ36: =+SUM(BQ37:BQ40) -> 24876 | BR36: =+SUM(BR37:BR40) -> 36833 | ... DB36: =+SUM(DB37:DB40) -> 88310.897 | DF36: 57378
A37: Infrastructure Projects Segment- Revenue | U37: 71942 | V37: 61430 | W37: 72404 | X37: 86717 | Y37: 112551 | Z37: =+SUM(CE37:CH37) -> 129897 | AA37: =SUM(CI37:CL37) -> 133910 | AB37: =+SUM(CM37:CP37) -> 155699.27 | AC37: =+SUM(CQ37:CT37) -> 175609.19 | AD37: =+SUM(CU37:CX37) -> 194566.73 | AE37: =+SUM(CY37:DB37) -> 213245.06 | BK37: 13594 | BL37: 16230 | BM37: 17026 | BN37: 25092 | BO37: 6393 | BP37: 12969 | BQ37: 15828 | BR37: 26240 | BS37: 10409 | BT37: 13923 | BU37: 18345 | BV37: 29727 | BW37: 14181 | BX37: 19370 | BY37: 21944 | BZ37: 31222 | CA37: 22058 | CB37: 24613 | CC37: 27845 | CD37: 38035 | CE37: 26908 | CF37: 31954 | CG37: 32134 | CH37: 38901 | CI37: 28757 | CJ37: 31759 | CK37: 33700 | CL37: 39694 | CM37: =+CM8 -> 34031.18 | CN37: =+CN8 -> 37195.287 | CO37: =+CO8 -> 39011.552 | CP37: =+CP8 -> 45461.249 | CQ37: =+CQ8 -> 38766.572 | CR37: =+CR8 -> 42124.82 | CS37: =+CS8 -> 43889.224 | CT37: =+CT8 -> 50828.577 | ... DB37: =+DB8 -> 61196.338 | DF37: 36281
A38: Energy Projects Segment- Revenue | U38: 19714 | V38: 20099 | W38: 23593 | X38: 24908 | Y38: 29539 | Z38: =+SUM(CE38:CH38) -> 40664 | AA38: =SUM(CI38:CL38) -> 54872 | AB38: =+SUM(CM38:CP38) -> 74941.955 | AC38: =+SUM(CQ38:CT38) -> 85097.72 | AD38: =+SUM(CU38:CX38) -> 88423.093 | AE38: =+SUM(CY38:DB38) -> 87247.019 | BK38: 4324 | BL38: 4786 | BM38: 5081 | BN38: 5523 | BO38: 3436 | BP38: 4731 | BQ38: 5304 | BR38: 6628 | BS38: 4949 | BT38: 5981 | BU38: 5946 | BV38: 6717 | BW38: 5073 | BX38: 5586 | BY38: 6333 | BZ38: 7916 | CA38: 6682 | CB38: 6788 | CC38: 7864 | CD38: 8205 | CE38: 8495 | CF38: 8869 | CG38: 11051 | CH38: 12249 | CI38: 12470 | CJ38: 13082 | CK38: 12726 | CL38: 16594 | CM38: =+CM15 -> 17304.394 | CN38: =+CN15 -> 18020.494 | CO38: =+CO15 -> 19144.893 | CP38: =+CP15 -> 20472.174 | CQ38: =+CQ15 -> 20641.543 | CR38: =+CR15 -> 20844.608 | CS38: =+CS15 -> 21419.834 | CT38: =+CT15 -> 22191.735 | ... DB38: =+DB15 -> 21797.819 | DF38: 14706
A39: Hi-Tech Manufacturing Segment- Revenue | U39: 6543 | V39: 6107 | W39: 5941 | X39: 6535 | Y39: 8195 | Z39: =+SUM(CE39:CH39) -> 9695 | AA39: =SUM(CI39:CL39) -> 14109 | AB39: =+SUM(CM39:CP39) -> 14787.209 | AC39: =+SUM(CQ39:CT39) -> 14462.387 | AD39: =+SUM(CU39:CX39) -> 13574.976 | AE39: =+SUM(CY39:DB39) -> 12533.472 | BK39: 1809 | BL39: 1575 | BM39: 1726 | BN39: 1433 | BO39: 851 | BP39: 1366 | BQ39: 1755 | BR39: 2135 | BS39: 1237 | BT39: 1469 | BU39: 1473 | BV39: 1762 | BW39: 1272 | BX39: 1456 | BY39: 1673 | BZ39: 2134 | CA39: 1781 | CB39: 1886 | CC39: 2066 | CD39: 2462 | CE39: 1845 | CF39: 2063 | CG39: 2433 | CH39: 3354 | CI39: 3227 | CJ39: 2754 | CK39: 3267 | CL39: 4861 | CM39: =+CM22 -> 3527.6678 | CN39: =+CN22 -> 3051.6018 | CO39: =+CO22 -> 3460.2442 | CP39: =+CP22 -> 4747.6952 | CQ39: =+CQ22 -> 3543.9783 | CR39: =+CR22 -> 3090.6858 | CS39: =+CS22 -> 3409.7859 | CT39: =+CT22 -> 4417.9365 | ... DB39: =+DB22 -> 3626.7408 | DF39: 3798
A40: Other Segment- Revenue | U40: 6445 | V40: 5854 | W40: 5978 | X40: 6044 | Y40: 7625 | Z40: =+SUM(CE40:CH40) -> 7066 | AA40: =SUM(CI40:CL40) -> 7093 | AB40: =+SUM(CM40:CP40) -> 6760 | AC40: =+SUM(CQ40:CT40) -> 6760 | AD40: =+SUM(CU40:CX40) -> 6760 | AE40: =+SUM(CY40:DB40) -> 6760 | BK40: 1449 | BL40: 1964 | BM40: 1532 | BN40: 1500 | BO40: 714 | BP40: 1321 | BQ40: 1989 | BR40: 1830 | BS40: 1320 | BT40: 1379 | BU40: 1455 | BV40: 1824 | BW40: 1467 | BX40: 1418 | BY40: 1361 | BZ40: 1798 | CA40: 2196 | CB40: 1622 | CC40: 1530 | CD40: 2277 | CE40: 1375 | CF40: 1648 | CG40: 1674 | CH40: 2369 | CI40: 1393 | CJ40: 1416 | CK40: 2594 | CL40: 1690 | CM40: =+CL40 -> 1690 | CN40: =+CM40 -> 1690 | CO40: =+CN40 -> 1690 | CP40: =+CO40 -> 1690 | CQ40: =+CP40 -> 1690 | CR40: =+CQ40 -> 1690 | CS40: =+CR40 -> 1690 | CT40: =+CS40 -> 1690 | ... DB40: =+DA40 -> 1690 | DF40: 2594
A41: Services & Concessions- Revenue | V41: =+SUM(V42:V44) -> 42489 | W41: =+SUM(W42:W44) -> 48604 | X41: =+SUM(X42:X44) -> 59136 | Y41: =+SUM(Y42:Y44) -> 63203 | Z41: =+SUM(Z42:Z44) -> 68409 | AA41: =+SUM(AA42:AA44) -> 75890 | AB41: =+SUM(AB42:AB44) -> 0 | AC41: =+SUM(AC42:AC44) -> 0 | ... AE41: =+SUM(AE42:AE44) -> 0 | BK41: =+SUM(BK42:BK44) -> 8460 | BL41: =+SUM(BL42:BL44) -> 10774 | BM41: =+SUM(BM42:BM44) -> 10878 | BN41: =+SUM(BN42:BN44) -> 10690 | BO41: =+SUM(BO42:BO44) -> 9866 | BP41: =+SUM(BP42:BP44) -> 10649 | BQ41: =+SUM(BQ42:BQ44) -> 10720 | BR41: =+SUM(BR42:BR44) -> 11254 | ... CL41: =+SUM(CL42:CL44) -> 19922 | CM41: =+CM45-CM36 -> 16313.084 | CN41: =+CN45-CN36 -> 17647.575 | CO41: =+CO45-CO36 -> 18917.38 | CP41: =+CP45-CP36 -> 23821.467 | CQ41: =+CQ45-CQ36 -> 19133.72 | CR41: =+CR45-CR36 -> 21579.38 | CS41: =+CS45-CS36 -> 24434.005 | CT41: =+CT45-CT36 -> 31891.091 | ... DB41: =+DB45-DB36 -> 59265.793 | DF41: 33262
A42: IT & Technology Services Segment- Revenue | U42: 22135 | V42: 25463 | W42: 32267 | X42: 41538 | Y42: 44473 | Z42: =+SUM(CE42:CH42) -> 47845 | AA42: =SUM(CI42:CL42) -> 53497 | AB42: =+SUM(CM42:CP42) -> 0 | AC42: =+SUM(CQ42:CT42) -> 0 | AD42: =+SUM(CU42:CX42) -> 0 | AE42: =+SUM(CY42:DB42) -> 0 | BK42: 3820 | BL42: 5876 | BM42: 6090 | BN42: 6349 | BO42: 6028 | BP42: 6167 | BQ42: 6505 | BR42: 6763 | BS42: 7232 | BT42: 7876 | BU42: 8398 | BV42: 8761 | BW42: 9556 | BX42: 10437 | BY42: 10625 | BZ42: 10920 | CA42: 10851 | CB42: 11182 | CC42: 11196 | CD42: 11244 | CE42: 11505 | CF42: 11798 | CG42: 12061 | CH42: 12481 | CI42: 12619 | CJ42: 13274 | CK42: 13526 | CL42: 14078
A43: Financial Services Segment- Revenue | U43: 13822 | V43: 13404 | W43: 11969 | X43: 12574 | Y43: 13109 | Z43: =+SUM(CE43:CH43) -> 15194 | AA43: =SUM(CI43:CL43) -> 17283 | AB43: =+SUM(CM43:CP43) -> 0 | AC43: =+SUM(CQ43:CT43) -> 0 | AD43: =+SUM(CU43:CX43) -> 0 | AE43: =+SUM(CY43:DB43) -> 0 | BK43: 3462 | BL43: 3445 | BM43: 3550 | BN43: 3365 | BO43: 3284 | BP43: 3342 | BQ43: 3401 | BR43: 3377 | BS43: 3061 | BT43: 2975 | BU43: 2970 | BV43: 2963 | BW43: 2958 | BX43: 3152 | BY43: 3348 | BZ43: 3116 | CA43: 3020 | CB43: 3084 | CC43: 3407 | CD43: 3598 | CE43: 3664 | CF43: 3837 | CG43: 3881 | CH43: 3812 | CI43: 3971 | CJ43: 4166 | CK43: 4477 | CL43: 4669
...

Sheet QTR Raw
A1: ='Annual Raw'!A1 -> 100510 | B1: X | C1: 201206 | D1: 201209 | E1: 201212 | F1: 201303 | G1: 201306 | H1: 201309 | I1: 201312 | J1: 201403 | K1: 201406 | L1: 201409 | M1: 201412 | N1: 201503 | O1: 201506 | P1: 201509 | Q1: 201512 | R1: 201603 | S1: 201606 | T1: 201609 | U1: 201612 | V1: 201703 | W1: 201706 | X1: 201709 | Y1: 201712 | Z1: 201803 | AA1: 201806 | AB1: 201809 | AC1: 201812 | AD1: 201903 | AE1: 201906 | AF1: 201909 | AG1: 201912 | AH1: 202003 | AI1: 202006 | AJ1: 202009 | AK1: 202012 | AL1: 202103 | AM1: 202106 | AN1: 202109 | AO1: 202112 | AP1: 202203 | AQ1: 202206 | AR1: 202209 | AS1: 202212 | AT1: 202303 | AU1: 202306 | AV1: 202309 | AW1: 202312 | AX1: 202403 | AY1: 202406 | AZ1: 202409 | BA1: 202412 | BB1: 202503 | BC1: 202506 | BD1: 202509 | BE1: 202512 | BF1: 202603 | BG1: 202606 | BH1: 202609 | BI1: 202612 | BJ1: 202703 | BK1: 202706 | BL1: 202709 | BM1: 202712 | BN1: 202803 | BO1: 202806 | BP1: 202809 | BQ1: 202812 | BR1: 202903 | BS1: 202906 | BT1: 202909 | BU1: 202912 | BV1: 203003
A3: Field Description | B3: Field Name
A4: Company Name | B4: CD_COMPNAME | C4: =_xll.EQNXTDZ(A1,B4,C1) -> Larsen & Toubro Ltd.
A5: Date End | B5: QTR_DATE_END | C5: =_xll.EQNXTDZ($A$1,$B5,C$1,$B$1) -> 201206 | D5: =_xll.EQNXTDZ($A$1,$B5,D$1,$B$1) -> 201209 | E5: =_xll.EQNXTDZ($A$1,$B5,E$1,$B$1) -> 201212 | F5: =_xll.EQNXTDZ($A$1,$B5,F$1,$B$1) -> 201303 | G5: =_xll.EQNXTDZ($A$1,$B5,G$1,$B$1) -> 201306 | H5: =_xll.EQNXTDZ($A$1,$B5,H$1,$B$1) -> 201309 | I5: =_xll.EQNXTDZ($A$1,$B5,I$1,$B$1) -> 201312 | J5: =_xll.EQNXTDZ($A$1,$B5,J$1,$B$1) -> 201403 | ... BV5: =_xll.EQNXTDZ($A$1,$B5,BV$1,$B$1) -> 0
A6: Gross Sales | B6: QTR_GROSS_SALE | C6: =_xll.EQNXTDZ($A$1,$B6,C$1,$B$1) -> 12078.33 | D6: =_xll.EQNXTDZ($A$1,$B6,D$1,$B$1) -> 13327.53 | E6: =_xll.EQNXTDZ($A$1,$B6,E$1,$B$1) -> 13016.04 | F6: =_xll.EQNXTDZ($A$1,$B6,F$1,$B$1) -> 18266.05 | G6: =_xll.EQNXTDZ($A$1,$B6,G$1,$B$1) -> 17419.56 | H6: =_xll.EQNXTDZ($A$1,$B6,H$1,$B$1) -> 19313.62 | I6: =_xll.EQNXTDZ($A$1,$B6,I$1,$B$1) -> 21928.54 | J6: =_xll.EQNXTDZ($A$1,$B6,J$1,$B$1) -> 27227.32 | ... BV6: =_xll.EQNXTDZ($A$1,$B6,BV$1,$B$1) -> 0
A7: Less: Excise Duty | B7: QTR_EXCISE_DUTY | C7: =_xll.EQNXTDZ($A$1,$B7,C$1,$B$1) -> 122.98 | D7: =_xll.EQNXTDZ($A$1,$B7,D$1,$B$1) -> 132.3 | E7: =_xll.EQNXTDZ($A$1,$B7,E$1,$B$1) -> 146.7 | F7: =_xll.EQNXTDZ($A$1,$B7,F$1,$B$1) -> 190.45 | G7: =_xll.EQNXTDZ($A$1,$B7,G$1,$B$1) -> 178.42 | H7: =_xll.EQNXTDZ($A$1,$B7,H$1,$B$1) -> 182.85 | I7: =_xll.EQNXTDZ($A$1,$B7,I$1,$B$1) -> 196.19 | J7: =_xll.EQNXTDZ($A$1,$B7,J$1,$B$1) -> 203.18 | ... BV7: =_xll.EQNXTDZ($A$1,$B7,BV$1,$B$1) -> 0
A8: Other operating income | B8: QTR_JOB_WORKS | C8: =_xll.EQNXTDZ($A$1,$B8,C$1,$B$1) -> 0 | D8: =_xll.EQNXTDZ($A$1,$B8,D$1,$B$1) -> 0 | E8: =_xll.EQNXTDZ($A$1,$B8,E$1,$B$1) -> 0 | F8: =_xll.EQNXTDZ($A$1,$B8,F$1,$B$1) -> 0 | G8: =_xll.EQNXTDZ($A$1,$B8,G$1,$B$1) -> 0 | H8: =_xll.EQNXTDZ($A$1,$B8,H$1,$B$1) -> 0 | I8: =_xll.EQNXTDZ($A$1,$B8,I$1,$B$1) -> 0 | J8: =_xll.EQNXTDZ($A$1,$B8,J$1,$B$1) -> 0 | ... BV8: =_xll.EQNXTDZ($A$1,$B8,BV$1,$B$1) -> 0
A9: Net Sales & Other Operating Income | B9: QTR_NET_SALES | C9: =_xll.EQNXTDZ($A$1,$B9,C$1,$B$1) -> 11955.35 | D9: =_xll.EQNXTDZ($A$1,$B9,D$1,$B$1) -> 13195.23 | E9: =_xll.EQNXTDZ($A$1,$B9,E$1,$B$1) -> 12869.34 | F9: =_xll.EQNXTDZ($A$1,$B9,F$1,$B$1) -> 18075.6 | G9: =_xll.EQNXTDZ($A$1,$B9,G$1,$B$1) -> 17241.14 | H9: =_xll.EQNXTDZ($A$1,$B9,H$1,$B$1) -> 19130.77 | I9: =_xll.EQNXTDZ($A$1,$B9,I$1,$B$1) -> 21732.35 | J9: =_xll.EQNXTDZ($A$1,$B9,J$1,$B$1) -> 27024.14 | ... BV9: =_xll.EQNXTDZ($A$1,$B9,BV$1,$B$1) -> 0
A10: (Increase) / Decrease In Stocks | B10: QTR_INC_DEC_INVENTORY | C10: =_xll.EQNXTDZ($A$1,$B10,C$1,$B$1) -> -511.51 | D10: =_xll.EQNXTDZ($A$1,$B10,D$1,$B$1) -> -881.21 | E10: =_xll.EQNXTDZ($A$1,$B10,E$1,$B$1) -> -542.87 | F10: =_xll.EQNXTDZ($A$1,$B10,F$1,$B$1) -> 831.73 | G10: =_xll.EQNXTDZ($A$1,$B10,G$1,$B$1) -> -1875.53 | H10: =_xll.EQNXTDZ($A$1,$B10,H$1,$B$1) -> -339.64 | I10: =_xll.EQNXTDZ($A$1,$B10,I$1,$B$1) -> -69.38 | J10: =_xll.EQNXTDZ($A$1,$B10,J$1,$B$1) -> 1735.38 | ... BV10: =_xll.EQNXTDZ($A$1,$B10,BV$1,$B$1) -> 0
A11: Cost of Services & Raw Materials | B11: QTR_RAW_MATERIAL_COST | C11: =_xll.EQNXTDZ($A$1,$B11,C$1,$B$1) -> 3720.05 | D11: =_xll.EQNXTDZ($A$1,$B11,D$1,$B$1) -> 3191.01 | E11: =_xll.EQNXTDZ($A$1,$B11,E$1,$B$1) -> 2031.46 | F11: =_xll.EQNXTDZ($A$1,$B11,F$1,$B$1) -> 2643.42 | G11: =_xll.EQNXTDZ($A$1,$B11,G$1,$B$1) -> 3148.88 | H11: =_xll.EQNXTDZ($A$1,$B11,H$1,$B$1) -> 3223.99 | I11: =_xll.EQNXTDZ($A$1,$B11,I$1,$B$1) -> 2851.44 | J11: =_xll.EQNXTDZ($A$1,$B11,J$1,$B$1) -> 2936.93 | ... BV11: =_xll.EQNXTDZ($A$1,$B11,BV$1,$B$1) -> 0
A12: Purchase of Finished Goods | B12: QTR_PURCHASE_FIN_GOOD | C12: =_xll.EQNXTDZ($A$1,$B12,C$1,$B$1) -> 501.66 | D12: =_xll.EQNXTDZ($A$1,$B12,D$1,$B$1) -> 437.12 | E12: =_xll.EQNXTDZ($A$1,$B12,E$1,$B$1) -> 516.58 | F12: =_xll.EQNXTDZ($A$1,$B12,F$1,$B$1) -> 607.86 | G12: =_xll.EQNXTDZ($A$1,$B12,G$1,$B$1) -> 407.75 | H12: =_xll.EQNXTDZ($A$1,$B12,H$1,$B$1) -> 471.08 | I12: =_xll.EQNXTDZ($A$1,$B12,I$1,$B$1) -> 405.67 | J12: =_xll.EQNXTDZ($A$1,$B12,J$1,$B$1) -> 509.02 | ... BV12: =_xll.EQNXTDZ($A$1,$B12,BV$1,$B$1) -> 0
A13: Excise Duty | B13: QTR_EXCISE | C13: =_xll.EQNXTDZ($A$1,$B13,C$1,$B$1) -> 0 | D13: =_xll.EQNXTDZ($A$1,$B13,D$1,$B$1) -> 0 | E13: =_xll.EQNXTDZ($A$1,$B13,E$1,$B$1) -> 0 | F13: =_xll.EQNXTDZ($A$1,$B13,F$1,$B$1) -> 0 | G13: =_xll.EQNXTDZ($A$1,$B13,G$1,$B$1) -> 0 | H13: =_xll.EQNXTDZ($A$1,$B13,H$1,$B$1) -> 0 | I13: =_xll.EQNXTDZ($A$1,$B13,I$1,$B$1) -> 0 | J13: =_xll.EQNXTDZ($A$1,$B13,J$1,$B$1) -> 0 | ... BV13: =_xll.EQNXTDZ($A$1,$B13,BV$1,$B$1) -> 0
A14: Operating & Manufacturing Expenses | B14: QTR_MFG_EXPS | C14: =_xll.EQNXTDZ($A$1,$B14,C$1,$B$1) -> 5642.42 | D14: =_xll.EQNXTDZ($A$1,$B14,D$1,$B$1) -> 7217.02 | E14: =_xll.EQNXTDZ($A$1,$B14,E$1,$B$1) -> 8272.34 | F14: =_xll.EQNXTDZ($A$1,$B14,F$1,$B$1) -> 10180.35 | G14: =_xll.EQNXTDZ($A$1,$B14,G$1,$B$1) -> 10973.39 | H14: =_xll.EQNXTDZ($A$1,$B14,H$1,$B$1) -> 9970 | I14: =_xll.EQNXTDZ($A$1,$B14,I$1,$B$1) -> 12876.68 | J14: =_xll.EQNXTDZ($A$1,$B14,J$1,$B$1) -> 15365 | ... BV14: =_xll.EQNXTDZ($A$1,$B14,BV$1,$B$1) -> 0
A15: Electricity Power & Fuel Cost | B15: QTR_ELECTRICITY_POWER_FUEL | C15: =_xll.EQNXTDZ($A$1,$B15,C$1,$B$1) -> 0 | D15: =_xll.EQNXTDZ($A$1,$B15,D$1,$B$1) -> 0 | E15: =_xll.EQNXTDZ($A$1,$B15,E$1,$B$1) -> 0 | F15: =_xll.EQNXTDZ($A$1,$B15,F$1,$B$1) -> 0 | G15: =_xll.EQNXTDZ($A$1,$B15,G$1,$B$1) -> 0 | H15: =_xll.EQNXTDZ($A$1,$B15,H$1,$B$1) -> 0 | I15: =_xll.EQNXTDZ($A$1,$B15,I$1,$B$1) -> 0 | J15: =_xll.EQNXTDZ($A$1,$B15,J$1,$B$1) -> 0 | ... BV15: =_xll.EQNXTDZ($A$1,$B15,BV$1,$B$1) -> 0
A16: Employee Cost | B16: QTR_EXPLOYEE_COST | C16: =_xll.EQNXTDZ($A$1,$B16,C$1,$B$1) -> 947.19 | D16: =_xll.EQNXTDZ($A$1,$B16,D$1,$B$1) -> 1298.51 | E16: =_xll.EQNXTDZ($A$1,$B16,E$1,$B$1) -> 926.75 | F16: =_xll.EQNXTDZ($A$1,$B16,F$1,$B$1) -> 979.16 | G16: =_xll.EQNXTDZ($A$1,$B16,G$1,$B$1) -> 1565.14 | H16: =_xll.EQNXTDZ($A$1,$B16,H$1,$B$1) -> 2003.52 | I16: =_xll.EQNXTDZ($A$1,$B16,I$1,$B$1) -> 1708.34 | J16: =_xll.EQNXTDZ($A$1,$B16,J$1,$B$1) -> 1858.07 | ... BV16: =_xll.EQNXTDZ($A$1,$B16,BV$1,$B$1) -> 0
... A42: Consolidated PAT(after extra items) | B42: QTR_CONS_PAT_EXITM | C42: =_xll.EQNXTDZ($A$1,$B42,C$1,$B$1) -> 863.65 | D42: =_xll.EQNXTDZ($A$1,$B42,D$1,$B$1) -> 1137.31 | E42: =_xll.EQNXTDZ($A$1,$B42,E$1,$B$1) -> 1013.23 | F42: =_xll.EQNXTDZ($A$1,$B42,F$1,$B$1) -> 1787.94 | G42: =_xll.EQNXTDZ($A$1,$B42,G$1,$B$1) -> 458.59 | H42: =_xll.EQNXTDZ($A$1,$B42,H$1,$B$1) -> 806.35 | I42: =_xll.EQNXTDZ($A$1,$B42,I$1,$B$1) -> 796.66 | J42: =_xll.EQNXTDZ($A$1,$B42,J$1,$B$1) -> 2840.4 | ... BV42: =_xll.EQNXTDZ($A$1,$B42,BV$1,$B$1) -> 0
A44: Field Description | B44: Field Name
A45: Equity Capital | B45: QTR_EQUITY_CAP | C45: =_xll.EQNXTDZ($A$1,$B45,C$1,$B$1) -> 122.56 | D45: =_xll.EQNXTDZ($A$1,$B45,D$1,$B$1) -> 122.76 | E45: =_xll.EQNXTDZ($A$1,$B45,E$1,$B$1) -> 122.98 | F45: =_xll.EQNXTDZ($A$1,$B45,F$1,$B$1) -> 123.08 | G45: =_xll.EQNXTDZ($A$1,$B45,G$1,$B$1) -> 123.25 | H45: =_xll.EQNXTDZ($A$1,$B45,H$1,$B$1) -> 185.05 | I45: =_xll.EQNXTDZ($A$1,$B45,I$1,$B$1) -> 185.21 | J45: =_xll.EQNXTDZ($A$1,$B45,J$1,$B$1) -> 185.38 | ... BV45: =_xll.EQNXTDZ($A$1,$B45,BV$1,$B$1) -> 0
A46: Face Value | B46: QTR_FV | C46: =_xll.EQNXTDZ($A$1,$B46,C$1,$B$1) -> 2 | D46: =_xll.EQNXTDZ($A$1,$B46,D$1,$B$1) -> 2 | E46: =_xll.EQNXTDZ($A$1,$B46,E$1,$B$1) -> 2 | F46: =_xll.EQNXTDZ($A$1,$B46,F$1,$B$1) -> 2 | G46: =_xll.EQNXTDZ($A$1,$B46,G$1,$B$1) -> 2 | H46: =_xll.EQNXTDZ($A$1,$B46,H$1,$B$1) -> 2 | I46: =_xll.EQNXTDZ($A$1,$B46,I$1,$B$1) -> 2 | J46: =_xll.EQNXTDZ($A$1,$B46,J$1,$B$1) -> 2 | ... BV46: =_xll.EQNXTDZ($A$1,$B46,BV$1,$B$1) -> 0
A47: Month End | B47: BMONTH_MONTHEND | C47: =_xll.EQNXTDZ($A$1,$B47,C$5) -> 201206 | D47: =_xll.EQNXTDZ($A$1,$B47,D$5) -> 201209 | E47: =_xll.EQNXTDZ($A$1,$B47,E$5) -> 201212 | F47: =_xll.EQNXTDZ($A$1,$B47,F$5) -> 201303 | G47: =_xll.EQNXTDZ($A$1,$B47,G$5) -> 201306 | H47: =_xll.EQNXTDZ($A$1,$B47,H$5) -> 201309 | I47: =_xll.EQNXTDZ($A$1,$B47,I$5) -> 201312 | J47: =_xll.EQNXTDZ($A$1,$B47,J$5) -> 201403 | ... BV47: =_xll.EQNXTDZ($A$1,$B47,BV$5) -> 0
A48: Close | B48: BMONTH_CLOSE | C48: =_xll.EQNXTDZ($A$1,$B48,C$5) -> 621.04444 | D48: =_xll.EQNXTDZ($A$1,$B48,D$5) -> 709.66667 | E48: =_xll.EQNXTDZ($A$1,$B48,E$5) -> 713.71111 | F48: =_xll.EQNXTDZ($A$1,$B48,F$5) -> 606.62222 | G48: =_xll.EQNXTDZ($A$1,$B48,G$5) -> 624.06667 | H48: =_xll.EQNXTDZ($A$1,$B48,H$5) -> 525.73333 | I48: =_xll.EQNXTDZ($A$1,$B48,I$5) -> 713.26667 | J48: =_xll.EQNXTDZ($A$1,$B48,J$5) -> 848.43333 | ... BV48: =_xll.EQNXTDZ($A$1,$B48,BV$5) -> 0
A49: Total of Promoter and Promoter Group | B49: SHP_TPFTOTALPROMOTER | C49: =_xll.EQNXTDZ($A$1,$B49,C$5) -> 0 | D49: =_xll.EQNXTDZ($A$1,$B49,D$5) -> 0 | E49: =_xll.EQNXTDZ($A$1,$B49,E$5) -> 0 | F49: =_xll.EQNXTDZ($A$1,$B49,F$5) -> 0 | G49: =_xll.EQNXTDZ($A$1,$B49,G$5) -> 0 | H49: =_xll.EQNXTDZ($A$1,$B49,H$5) -> 0 | I49: =_xll.EQNXTDZ($A$1,$B49,I$5) -> 0 | J49: =_xll.EQNXTDZ($A$1,$B49,J$5) -> 0 | ... BV49: =_xll.EQNXTDZ($A$1,$B49,BV$5) -> 0
A50: Total of Promoter and Promoter Group Pledged | B50: SHP_PSHFTOTALPROMOTER | C50: =_xll.EQNXTDZ($A$1,$B50,C$5) -> 0 | D50: =_xll.EQNXTDZ($A$1,$B50,D$5) -> 0 | E50: =_xll.EQNXTDZ($A$1,$B50,E$5) -> 0 | F50: =_xll.EQNXTDZ($A$1,$B50,F$5) -> 0 | G50: =_xll.EQNXTDZ($A$1,$B50,G$5) -> 0 | H50: =_xll.EQNXTDZ($A$1,$B50,H$5) -> 0 | I50: =_xll.EQNXTDZ($A$1,$B50,I$5) -> 0 | J50: =_xll.EQNXTDZ($A$1,$B50,J$5) -> 0 | ... BV50: =_xll.EQNXTDZ($A$1,$B50,BV$5) -> 0
A54: Field Description | B54: Field Name | C54: =_xll.EQNXTDZ($A$1,$B54,C$5) -> 0 | D54: =_xll.EQNXTDZ($A$1,$B54,D$5) -> 0 | E54: =_xll.EQNXTDZ($A$1,$B54,E$5) -> 0 | F54: =_xll.EQNXTDZ($A$1,$B54,F$5) -> 0 | G54: =_xll.EQNXTDZ($A$1,$B54,G$5) -> 0 | H54: =_xll.EQNXTDZ($A$1,$B54,H$5) -> 0 | I54: =_xll.EQNXTDZ($A$1,$B54,I$5) -> 0 | J54: =_xll.EQNXTDZ($A$1,$B54,J$5) -> 0 | ... BV54: =_xll.EQNXTDZ($A$1,$B54,BV$5) -> 0
A55: Year End | B55: QTRB_DATE_END | C55: =_xll.EQNXTDZ($A$1,$B55,C$5,$B$1) -> 0 | D55: =_xll.EQNXTDZ($A$1,$B55,D$5,$B$1) -> 201209 | E55: =_xll.EQNXTDZ($A$1,$B55,E$5,$B$1) -> 0 | F55: =_xll.EQNXTDZ($A$1,$B55,F$5,$B$1) -> 201303 | G55: =_xll.EQNXTDZ($A$1,$B55,G$5,$B$1) -> 0 | H55: =_xll.EQNXTDZ($A$1,$B55,H$5,$B$1) -> 201309 | I55: =_xll.EQNXTDZ($A$1,$B55,I$5,$B$1) -> 0 | J55: =_xll.EQNXTDZ($A$1,$B55,J$5,$B$1) -> 201403 | ... BV55: =_xll.EQNXTDZ($A$1,$B55,BV$5,$B$1) -> 0
A56: Share Capital | B56: QTRB_SHARE_CAPITAL | C56: =_xll.EQNXTDZ($A$1,$B56,C$5,$B$1) -> 0 | D56: =_xll.EQNXTDZ($A$1,$B56,D$5,$B$1) -> 122.76 | E56: =_xll.EQNXTDZ($A$1,$B56,E$5,$B$1) -> 0 | F56: =_xll.EQNXTDZ($A$1,$B56,F$5,$B$1) -> 123.08 | G56: =_xll.EQNXTDZ($A$1,$B56,G$5,$B$1) -> 0 | H56: =_xll.EQNXTDZ($A$1,$B56,H$5,$B$1) -> 185.05 | I56: =_xll.EQNXTDZ($A$1,$B56,I$5,$B$1) -> 0 | J56: =_xll.EQNXTDZ($A$1,$B56,J$5,$B$1) -> 185.38 | ... BV56: =_xll.EQNXTDZ($A$1,$B56,BV$5,$B$1) -> 0
A57: Share Warrants & outstandings | B57: QTRB_SHAREWARNDOUT | C57: =_xll.EQNXTDZ($A$1,$B57,C$5,$B$1) -> 0 | D57: =_xll.EQNXTDZ($A$1,$B57,D$5,$B$1) -> 0 | E57: =_xll.EQNXTDZ($A$1,$B57,E$5,$B$1) -> 0 | F57: =_xll.EQNXTDZ($A$1,$B57,F$5,$B$1) -> 0 | G57: =_xll.EQNXTDZ($A$1,$B57,G$5,$B$1) -> 0 | H57: =_xll.EQNXTDZ($A$1,$B57,H$5,$B$1) -> 0 | I57: =_xll.EQNXTDZ($A$1,$B57,I$5,$B$1) -> 0 | J57: =_xll.EQNXTDZ($A$1,$B57,J$5,$B$1) -> 0 | ... BV57: =_xll.EQNXTDZ($A$1,$B57,BV$5,$B$1) -> 0
A58: Reserves & Surplus | B58: QTRB_RESERVE | C58: =_xll.EQNXTDZ($A$1,$B58,C$5,$B$1) -> 0 | D58: =_xll.EQNXTDZ($A$1,$B58,D$5,$B$1) -> 27269.48 | E58: =_xll.EQNXTDZ($A$1,$B58,E$5,$B$1) -> 0 | F58: =_xll.EQNXTDZ($A$1,$B58,F$5,$B$1) -> 33736.61 | G58: =_xll.EQNXTDZ($A$1,$B58,G$5,$B$1) -> 0 | H58: =_xll.EQNXTDZ($A$1,$B58,H$5,$B$1) -> 34783.8 | I58: =_xll.EQNXTDZ($A$1,$B58,I$5,$B$1) -> 0 | J58: =_xll.EQNXTDZ($A$1,$B58,J$5,$B$1) -> 37526.23 | ... BV58: =_xll.EQNXTDZ($A$1,$B58,BV$5,$B$1) -> 0
A59: Shareholder's Funds | B59: QTRB_SHAREHODERS_FUNDS | C59: =_xll.EQNXTDZ($A$1,$B59,C$5,$B$1) -> 0 | D59: =_xll.EQNXTDZ($A$1,$B59,D$5,$B$1) -> 27392.24 | E59: =_xll.EQNXTDZ($A$1,$B59,E$5,$B$1) -> 0 | F59: =_xll.EQNXTDZ($A$1,$B59,F$5,$B$1) -> 33859.69 | G59: =_xll.EQNXTDZ($A$1,$B59,G$5,$B$1) -> 0 | H59: =_xll.EQNXTDZ($A$1,$B59,H$5,$B$1) -> 34968.85 | I59: =_xll.EQNXTDZ($A$1,$B59,I$5,$B$1) -> 0 | J59: =_xll.EQNXTDZ($A$1,$B59,J$5,$B$1) -> 37711.61 | ... BV59: =_xll.EQNXTDZ($A$1,$B59,BV$5,$B$1) -> 0
A60: Minority Interest | B60: QTRB_MINORITY_INTEREST_BS | C60: =_xll.EQNXTDZ($A$1,$B60,C$5,$B$1) -> 0 | D60: =_xll.EQNXTDZ($A$1,$B60,D$5,$B$1) -> 0 | E60: =_xll.EQNXTDZ($A$1,$B60,E$5,$B$1) -> 0 | F60: =_xll.EQNXTDZ($A$1,$B60,F$5,$B$1) -> 2652.87 | G60: =_xll.EQNXTDZ($A$1,$B60,G$5,$B$1) -> 0 | H60: =_xll.EQNXTDZ($A$1,$B60,H$5,$B$1) -> 2645.02 | I60: =_xll.EQNXTDZ($A$1,$B60,I$5,$B$1) -> 0 | J60: =_xll.EQNXTDZ($A$1,$B60,J$5,$B$1) -> 3179.18 | ... BV60: =_xll.EQNXTDZ($A$1,$B60,BV$5,$B$1) -> 0
A61: Long Term Borrowings | B61: QTRB_TOTAL_DEBTS | C61: =_xll.EQNXTDZ($A$1,$B61,C$5,$B$1) -> 0 | D61: =_xll.EQNXTDZ($A$1,$B61,D$5,$B$1) -> 5749.96 | E61: =_xll.EQNXTDZ($A$1,$B61,E$5,$B$1) -> 0 | F61: =_xll.EQNXTDZ($A$1,$B61,F$5,$B$1) -> 47392.14 | G61: =_xll.EQNXTDZ($A$1,$B61,G$5,$B$1) -> 0 | H61: =_xll.EQNXTDZ($A$1,$B61,H$5,$B$1) -> 53702.39 | I61: =_xll.EQNXTDZ($A$1,$B61,I$5,$B$1) -> 0 | J61: =_xll.EQNXTDZ($A$1,$B61,J$5,$B$1) -> 55444.89 | ... BV61: =_xll.EQNXTDZ($A$1,$B61,BV$5,$B$1) -> 0
A62: Secured Loans | B62: QTRB_SECURED_LOANS | C62: =_xll.EQNXTDZ($A$1,$B62,C$5,$B$1) -> 0 | D62: =_xll.EQNXTDZ($A$1,$B62,D$5,$B$1) -> 0 | E62: =_xll.EQNXTDZ($A$1,$B62,E$5,$B$1) -> 0 | F62: =_xll.EQNXTDZ($A$1,$B62,F$5,$B$1) -> 0 | G62: =_xll.EQNXTDZ($A$1,$B62,G$5,$B$1) -> 0 | H62: =_xll.EQNXTDZ($A$1,$B62,H$5,$B$1) -> 0 | I62: =_xll.EQNXTDZ($A$1,$B62,I$5,$B$1) -> 0 | J62: =_xll.EQNXTDZ($A$1,$B62,J$5,$B$1) -> 0 | ... BV62: =_xll.EQNXTDZ($A$1,$B62,BV$5,$B$1) -> 0
A63: Unsecured Loans | B63: QTRB_UNSECURED_LOANS_NF | C63: =_xll.EQNXTDZ($A$1,$B63,C$5,$B$1) -> 0 | D63: =_xll.EQNXTDZ($A$1,$B63,D$5,$B$1) -> 5749.96 | E63: =_xll.EQNXTDZ($A$1,$B63,E$5,$B$1) -> 0 | F63: =_xll.EQNXTDZ($A$1,$B63,F$5,$B$1) -> 47392.14 | G63: =_xll.EQNXTDZ($A$1,$B63,G$5,$B$1) -> 0 | H63: =_xll.EQNXTDZ($A$1,$B63,H$5,$B$1) -> 53702.39 | I63: =_xll.EQNXTDZ($A$1,$B63,I$5,$B$1) -> 0 | J63: =_xll.EQNXTDZ($A$1,$B63,J$5,$B$1) -> 55444.89 | ... BV63: =_xll.EQNXTDZ($A$1,$B63,BV$5,$B$1) -> 0
A64: Other Long Term Liabilities | B64: QTRB_OTHER_LT_LIABILITIES | C64: =_xll.EQNXTDZ($A$1,$B64,C$5,$B$1) -> 0 | D64: =_xll.EQNXTDZ($A$1,$B64,D$5,$B$1) -> 632.87 | E64: =_xll.EQNXTDZ($A$1,$B64,E$5,$B$1) -> 0 | F64: =_xll.EQNXTDZ($A$1,$B64,F$5,$B$1) -> 4642.3 | G64: =_xll.EQNXTDZ($A$1,$B64,G$5,$B$1) -> 0 | H64: =_xll.EQNXTDZ($A$1,$B64,H$5,$B$1) -> 4416.61 | I64: =_xll.EQNXTDZ($A$1,$B64,I$5,$B$1) -> 0 | J64: =_xll.EQNXTDZ($A$1,$B64,J$5,$B$1) -> 3990.86 | ... BV64: =_xll.EQNXTDZ($A$1,$B64,BV$5,$B$1) -> 0
A65: Long Term Trade Payables | B65: QTRB_LT_TRADE_PAYABLE | C65: =_xll.EQNXTDZ($A$1,$B65,C$5,$B$1) -> 0 | D65: =_xll.EQNXTDZ($A$1,$B65,D$5,$B$1) -> 0 | E65: =_xll.EQNXTDZ($A$1,$B65,E$5,$B$1) -> 0 | F65: =_xll.EQNXTDZ($A$1,$B65,F$5,$B$1) -> 0 | G65: =_xll.EQNXTDZ($A$1,$B65,G$5,$B$1) -> 0 | H65: =_xll.EQNXTDZ($A$1,$B65,H$5,$B$1) -> 0 | I65: =_xll.EQNXTDZ($A$1,$B65,I$5,$B$1) -> 0 | J65: =_xll.EQNXTDZ($A$1,$B65,J$5,$B$1) -> 0 | ... BV65: =_xll.EQNXTDZ($A$1,$B65,BV$5,$B$1) -> 0
A66: Lont Term Provisions | B66: QTRB_LT_PROVISIONS | C66: =_xll.EQNXTDZ($A$1,$B66,C$5,$B$1) -> 0 | D66: =_xll.EQNXTDZ($A$1,$B66,D$5,$B$1) -> 286.73 | E66: =_xll.EQNXTDZ($A$1,$B66,E$5,$B$1) -> 0 | F66: =_xll.EQNXTDZ($A$1,$B66,F$5,$B$1) -> 346.67 | G66: =_xll.EQNXTDZ($A$1,$B66,G$5,$B$1) -> 0 | H66: =_xll.EQNXTDZ($A$1,$B66,H$5,$B$1) -> 312 | I66: =_xll.EQNXTDZ($A$1,$B66,I$5,$B$1) -> 0 | J66: =_xll.EQNXTDZ($A$1,$B66,J$5,$B$1) -> 374.24 | ... BV66: =_xll.EQNXTDZ($A$1,$B66,BV$5,$B$1) -> 0
... A97: Total Assets | B97: QTRB_TOTAL_APPLICATIONS | C97: =_xll.EQNXTDZ($A$1,$B97,C$5,$B$1) -> 0 | D97: =_xll.EQNXTDZ($A$1,$B97,D$5,$B$1) -> 34061.8 | E97: =_xll.EQNXTDZ($A$1,$B97,E$5,$B$1) -> 0 | F97: =_xll.EQNXTDZ($A$1,$B97,F$5,$B$1) -> 88893.67 | G97: =_xll.EQNXTDZ($A$1,$B97,G$5,$B$1) -> 0 | H97: =_xll.EQNXTDZ($A$1,$B97,H$5,$B$1) -> 96044.87 | I97: =_xll.EQNXTDZ($A$1,$B97,I$5,$B$1) -> 0 | J97: =_xll.EQNXTDZ($A$1,$B97,J$5,$B$1) -> 100700.78 | ... BV97: =_xll.EQNXTDZ($A$1,$B97,BV$5,$B$1) -> 0

Sheet Annual Raw
A1: 100510 | B1: X | C1: 200103 | D1: 200203 | E1: 200303 | F1: 200403 | G1: 200503 | H1: 200603 | I1: 200703 | J1: 200803 | K1: 200903 | L1: 201003 | M1: 201103 | N1: 201203 | O1: 201303 | P1: 201403 | Q1: 201503 | R1: 201603 | S1: 201703 | T1: 201803 | U1: 201903 | V1: 202003 | W1: 202103 | X1: 202203 | Y1: 202303 | Z1: 202403 | AA1: 202503 | AB1: 202603 | AC1: 202703 | AD1: 202803 | AE1: 202903 | AF1: 203003
A3: Field Description | B3: Field Name
A4: Company Name | B4: CD_COMPNAME | C4: =_xll.EQNXTDZ(A1,B4,"L") -> Larsen & Toubro Ltd.
A5: Year End | B5: PL_YEAR_END | C5: =_xll.EQNXTDZ($A$1,$B5,C$1,$B$1) -> 200103 | D5: =_xll.EQNXTDZ($A$1,$B5,D$1,$B$1) -> 200203 | E5: =_xll.EQNXTDZ($A$1,$B5,E$1,$B$1) -> 200303 | F5: =_xll.EQNXTDZ($A$1,$B5,F$1,$B$1) -> 200403 | G5: =_xll.EQNXTDZ($A$1,$B5,G$1,$B$1) -> 200503 | H5: =_xll.EQNXTDZ($A$1,$B5,H$1,$B$1) -> 200603 | I5: =_xll.EQNXTDZ($A$1,$B5,I$1,$B$1) -> 200703 | J5: =_xll.EQNXTDZ($A$1,$B5,J$1,$B$1) -> 200803 | ... AF5: =_xll.EQNXTDZ($A$1,$B5,AF$1,$B$1) -> 0
A6: Sales Turnover | B6: PL_TOTAL_GROSS_SALES | C6: =_xll.EQNXTDZ($A$1,$B6,C$1,$B$1) -> 7825.43 | D6: =_xll.EQNXTDZ($A$1,$B6,D$1,$B$1) -> 9170.02 | E6: =_xll.EQNXTDZ($A$1,$B6,E$1,$B$1) -> 10813.13 | F6: =_xll.EQNXTDZ($A$1,$B6,F$1,$B$1) -> 11232.34 | G6: =_xll.EQNXTDZ($A$1,$B6,G$1,$B$1) -> 14716.9 | H6: =_xll.EQNXTDZ($A$1,$B6,H$1,$B$1) -> 16808.51 | I6: =_xll.EQNXTDZ($A$1,$B6,I$1,$B$1) -> 20877.32 | J6: =_xll.EQNXTDZ($A$1,$B6,J$1,$B$1) -> 29819.46 | ... AF6: =_xll.EQNXTDZ($A$1,$B6,AF$1,$B$1) -> 0
A7: Less: Inter divisional transfers | B7: PL_INTER_DIV_TRF | C7: =_xll.EQNXTDZ($A$1,$B7,C$1,$B$1) -> 0 | D7: =_xll.EQNXTDZ($A$1,$B7,D$1,$B$1) -> 0 | E7: =_xll.EQNXTDZ($A$1,$B7,E$1,$B$1) -> 0 | F7: =_xll.EQNXTDZ($A$1,$B7,F$1,$B$1) -> 0 | G7: =_xll.EQNXTDZ($A$1,$B7,G$1,$B$1) -> 0 | H7: =_xll.EQNXTDZ($A$1,$B7,H$1,$B$1) -> 0 | I7: =_xll.EQNXTDZ($A$1,$B7,I$1,$B$1) -> 0 | J7: =_xll.EQNXTDZ($A$1,$B7,J$1,$B$1) -> 0 | ... AF7: =_xll.EQNXTDZ($A$1,$B7,AF$1,$B$1) -> 0
A8: Less: Sales Returns | B8: PL_SALES_RETURN | C8: =_xll.EQNXTDZ($A$1,$B8,C$1,$B$1) -> 0 | D8: =_xll.EQNXTDZ($A$1,$B8,D$1,$B$1) -> 0 | E8: =_xll.EQNXTDZ($A$1,$B8,E$1,$B$1) -> 0 | F8: =_xll.EQNXTDZ($A$1,$B8,F$1,$B$1) -> 0 | G8: =_xll.EQNXTDZ($A$1,$B8,G$1,$B$1) -> 0 | H8: =_xll.EQNXTDZ($A$1,$B8,H$1,$B$1) -> 0 | I8: =_xll.EQNXTDZ($A$1,$B8,I$1,$B$1) -> 0 | J8: =_xll.EQNXTDZ($A$1,$B8,J$1,$B$1) -> 0 | ... AF8: =_xll.EQNXTDZ($A$1,$B8,AF$1,$B$1) -> 0
A9: Less: Excise | B9: PL_EXCISE | C9: =_xll.EQNXTDZ($A$1,$B9,C$1,$B$1) -> 446.78 | D9: =_xll.EQNXTDZ($A$1,$B9,D$1,$B$1) -> 480.66 | E9: =_xll.EQNXTDZ($A$1,$B9,E$1,$B$1) -> 530.06 | F9: =_xll.EQNXTDZ($A$1,$B9,F$1,$B$1) -> 258.56 | G9: =_xll.EQNXTDZ($A$1,$B9,G$1,$B$1) -> 220.01 | H9: =_xll.EQNXTDZ($A$1,$B9,H$1,$B$1) -> 247.2 | I9: =_xll.EQNXTDZ($A$1,$B9,I$1,$B$1) -> 364.46 | J9: =_xll.EQNXTDZ($A$1,$B9,J$1,$B$1) -> 362.61 | ... AF9: =_xll.EQNXTDZ($A$1,$B9,AF$1,$B$1) -> 0
A10: Net Sales | B10: PL_NET_SALES | C10: =_xll.EQNXTDZ($A$1,$B10,C$1,$B$1) -> 7378.65 | D10: =_xll.EQNXTDZ($A$1,$B10,D$1,$B$1) -> 8689.36 | E10: =_xll.EQNXTDZ($A$1,$B10,E$1,$B$1) -> 10283.07 | F10: =_xll.EQNXTDZ($A$1,$B10,F$1,$B$1) -> 10973.78 | G10: =_xll.EQNXTDZ($A$1,$B10,G$1,$B$1) -> 14496.89 | H10: =_xll.EQNXTDZ($A$1,$B10,H$1,$B$1) -> 16561.31 | I10: =_xll.EQNXTDZ($A$1,$B10,I$1,$B$1) -> 20512.86 | J10: =_xll.EQNXTDZ($A$1,$B10,J$1,$B$1) -> 29456.85 | ... AF10: =_xll.EQNXTDZ($A$1,$B10,AF$1,$B$1) -> 0
A11: Increase/Decrease in Stock | B11: PL_INC_DEC_INVENTORY | C11: =_xll.EQNXTDZ($A$1,$B11,C$1,$B$1) -> 1.25 | D11: =_xll.EQNXTDZ($A$1,$B11,D$1,$B$1) -> 33.06 | E11: =_xll.EQNXTDZ($A$1,$B11,E$1,$B$1) -> 20.66 | F11: =_xll.EQNXTDZ($A$1,$B11,F$1,$B$1) -> -404.83 | G11: =_xll.EQNXTDZ($A$1,$B11,G$1,$B$1) -> -81.46 | H11: =_xll.EQNXTDZ($A$1,$B11,H$1,$B$1) -> 137.63 | I11: =_xll.EQNXTDZ($A$1,$B11,I$1,$B$1) -> -111.28 | J11: =_xll.EQNXTDZ($A$1,$B11,J$1,$B$1) -> -681.89 | ... AF11: =_xll.EQNXTDZ($A$1,$B11,AF$1,$B$1) -> 0
A12: Raw Material Consumed | B12: PL_RAW_MATRS_CONSUMED | C12: =_xll.EQNXTDZ($A$1,$B12,C$1,$B$1) -> 2198.87 | D12: =_xll.EQNXTDZ($A$1,$B12,D$1,$B$1) -> 2322.62 | E12: =_xll.EQNXTDZ($A$1,$B12,E$1,$B$1) -> 3305.69 | F12: =_xll.EQNXTDZ($A$1,$B12,F$1,$B$1) -> 4499.4 | G12: =_xll.EQNXTDZ($A$1,$B12,G$1,$B$1) -> 6521.43 | H12: =_xll.EQNXTDZ($A$1,$B12,H$1,$B$1) -> 7227.44 | I12: =_xll.EQNXTDZ($A$1,$B12,I$1,$B$1) -> 8765.17 | J12: =_xll.EQNXTDZ($A$1,$B12,J$1,$B$1) -> 13900.13 | ... AF12: =_xll.EQNXTDZ($A$1,$B12,AF$1,$B$1) -> 0
A13: Power & Fuel Cost | B13: PL_POWER_FUEL | C13: =_xll.EQNXTDZ($A$1,$B13,C$1,$B$1) -> 622.03 | D13: =_xll.EQNXTDZ($A$1,$B13,D$1,$B$1) -> 725.55 | E13: =_xll.EQNXTDZ($A$1,$B13,E$1,$B$1) -> 747.86 | F13: =_xll.EQNXTDZ($A$1,$B13,F$1,$B$1) -> 92.89 | G13: =_xll.EQNXTDZ($A$1,$B13,G$1,$B$1) -> 215.49 | H13: =_xll.EQNXTDZ($A$1,$B13,H$1,$B$1) -> 249.86 | I13: =_xll.EQNXTDZ($A$1,$B13,I$1,$B$1) -> 339.3 | J13: =_xll.EQNXTDZ($A$1,$B13,J$1,$B$1) -> 447.6 | ... AF13: =_xll.EQNXTDZ($A$1,$B13,AF$1,$B$1) -> 0
A14: Employee Cost | B14: PL_EMPLOYEES | C14: =_xll.EQNXTDZ($A$1,$B14,C$1,$B$1) -> 585.12 | D14: =_xll.EQNXTDZ($A$1,$B14,D$1,$B$1) -> 634.37 | E14: =_xll.EQNXTDZ($A$1,$B14,E$1,$B$1) -> 727.94 | F14: =_xll.EQNXTDZ($A$1,$B14,F$1,$B$1) -> 741.23 | G14: =_xll.EQNXTDZ($A$1,$B14,G$1,$B$1) -> 855.94 | H14: =_xll.EQNXTDZ($A$1,$B14,H$1,$B$1) -> 1029.76 | I14: =_xll.EQNXTDZ($A$1,$B14,I$1,$B$1) -> 1461 | J14: =_xll.EQNXTDZ($A$1,$B14,J$1,$B$1) -> 2011.41 | ... AF14: =_xll.EQNXTDZ($A$1,$B14,AF$1,$B$1) -> 0
A15: Operating & Manufacturing Expenses | B15: PL_GEN_OTHER_MFG_EXPS | C15: =_xll.EQNXTDZ($A$1,$B15,C$1,$B$1) -> 2351.51 | D15: =_xll.EQNXTDZ($A$1,$B15,D$1,$B$1) -> 2235.39 | E15: =_xll.EQNXTDZ($A$1,$B15,E$1,$B$1) -> 2776.74 | F15: =_xll.EQNXTDZ($A$1,$B15,F$1,$B$1) -> 3719.27 | G15: =_xll.EQNXTDZ($A$1,$B15,G$1,$B$1) -> 4170.22 | H15: =_xll.EQNXTDZ($A$1,$B15,H$1,$B$1) -> 4379.42 | I15: =_xll.EQNXTDZ($A$1,$B15,I$1,$B$1) -> 4731.69 | J15: =_xll.EQNXTDZ($A$1,$B15,J$1,$B$1) -> 6444.69 | ... AF15: =_xll.EQNXTDZ($A$1,$B15,AF$1,$B$1) -> 0
A16: Cost of Software development | B16: PL_COST_SW | C16: =_xll.EQNXTDZ($A$1,$B16,C$1,$B$1) -> 0 | D16: =_xll.EQNXTDZ($A$1,$B16,D$1,$B$1) -> 0 | E16: =_xll.EQNXTDZ($A$1,$B16,E$1,$B$1) -> 0 | F16: =_xll.EQNXTDZ($A$1,$B16,F$1,$B$1) -> 0 | G16: =_xll.EQNXTDZ($A$1,$B16,G$1,$B$1) -> 0 | H16: =_xll.EQNXTDZ($A$1,$B16,H$1,$B$1) -> 0 | I16: =_xll.EQNXTDZ($A$1,$B16,I$1,$B$1) -> 0 | J16: =_xll.EQNXTDZ($A$1,$B16,J$1,$B$1) -> 0 | ... AF16: =_xll.EQNXTDZ($A$1,$B16,AF$1,$B$1) -> 0
... A36: Profit After Tax from Discontinued Operations | B36: PL_PAT_DIS_OP | C36: =_xll.EQNXTDZ($A$1,$B36,C$1,$B$1) -> 0 | D36: =_xll.EQNXTDZ($A$1,$B36,D$1,$B$1) -> 0 | E36: =_xll.EQNXTDZ($A$1,$B36,E$1,$B$1) -> 0 | F36: =_xll.EQNXTDZ($A$1,$B36,F$1,$B$1) -> 0 | G36: =_xll.EQNXTDZ($A$1,$B36,G$1,$B$1) -> 0 | H36: =_xll.EQNXTDZ($A$1,$B36,H$1,$B$1) -> 0 | I36: =_xll.EQNXTDZ($A$1,$B36,I$1,$B$1) -> 0 | J36: =_xll.EQNXTDZ($A$1,$B36,J$1,$B$1) -> 0 | ... AF36: =_xll.EQNXTDZ($A$1,$B36,AF$1,$B$1) -> 0
A39: Field Description | B39: Field Name
A40: Year End | B40: BS_YEAR_END | C40: =_xll.EQNXTDZ($A$1,$B40,C$1,$B$1) -> 200103 | D40: =_xll.EQNXTDZ($A$1,$B40,D$1,$B$1) -> 200203 | E40: =_xll.EQNXTDZ($A$1,$B40,E$1,$B$1) -> 200303 | F40: =_xll.EQNXTDZ($A$1,$B40,F$1,$B$1) -> 200403 | G40: =_xll.EQNXTDZ($A$1,$B40,G$1,$B$1) -> 200503 | H40: =_xll.EQNXTDZ($A$1,$B40,H$1,$B$1) -> 200603 | I40: =_xll.EQNXTDZ($A$1,$B40,I$1,$B$1) -> 200703 | J40: =_xll.EQNXTDZ($A$1,$B40,J$1,$B$1) -> 200803 | ... AF40: =_xll.EQNXTDZ($A$1,$B40,AF$1,$B$1) -> 0
A41: Share Capital | B41: BS_SHARE_CAPITAL | C41: =_xll.EQNXTDZ($A$1,$B41,C$1,$B$1) -> 248.65 | D41: =_xll.EQNXTDZ($A$1,$B41,D$1,$B$1) -> 248.66 | E41: =_xll.EQNXTDZ($A$1,$B41,E$1,$B$1) -> 248.67 | F41: =_xll.EQNXTDZ($A$1,$B41,F$1,$B$1) -> 24.88 | G41: =_xll.EQNXTDZ($A$1,$B41,G$1,$B$1) -> 25.98 | H41: =_xll.EQNXTDZ($A$1,$B41,H$1,$B$1) -> 27.48 | I41: =_xll.EQNXTDZ($A$1,$B41,I$1,$B$1) -> 56.65 | J41: =_xll.EQNXTDZ($A$1,$B41,J$1,$B$1) -> 58.47 | ... AF41: =_xll.EQNXTDZ($A$1,$B41,AF$1,$B$1) -> 0
A42: Share Warrants & Outstandings | B42: BS_SHAREWROUTST | C42: =_xll.EQNXTDZ($A$1,$B42,C$1,$B$1) -> 0 | D42: =_xll.EQNXTDZ($A$1,$B42,D$1,$B$1) -> 0.11 | E42: =_xll.EQNXTDZ($A$1,$B42,E$1,$B$1) -> 0.04 | F42: =_xll.EQNXTDZ($A$1,$B42,F$1,$B$1) -> 0 | G42: =_xll.EQNXTDZ($A$1,$B42,G$1,$B$1) -> 28.19 | H42: =_xll.EQNXTDZ($A$1,$B42,H$1,$B$1) -> 34.99 | I42: =_xll.EQNXTDZ($A$1,$B42,I$1,$B$1) -> 79.41 | J42: =_xll.EQNXTDZ($A$1,$B42,J$1,$B$1) -> 144.31 | ... AF42: =_xll.EQNXTDZ($A$1,$B42,AF$1,$B$1) -> 0
A43: Total Reserves | B43: BS_RESERVE | C43: =_xll.EQNXTDZ($A$1,$B43,C$1,$B$1) -> 3750.76 | D43: =_xll.EQNXTDZ($A$1,$B43,D$1,$B$1) -> 2888.79 | E43: =_xll.EQNXTDZ($A$1,$B43,E$1,$B$1) -> 2967.89 | F43: =_xll.EQNXTDZ($A$1,$B43,F$1,$B$1) -> 2622.44 | G43: =_xll.EQNXTDZ($A$1,$B43,G$1,$B$1) -> 3261.76 | H43: =_xll.EQNXTDZ($A$1,$B43,H$1,$B$1) -> 4902.01 | I43: =_xll.EQNXTDZ($A$1,$B43,I$1,$B$1) -> 6785.49 | J43: =_xll.EQNXTDZ($A$1,$B43,J$1,$B$1) -> 10628.33 | ... AF43: =_xll.EQNXTDZ($A$1,$B43,AF$1,$B$1) -> 0
A44: Shareholder's Funds | B44: BS_SHAREHODERS_FUNDS | C44: =_xll.EQNXTDZ($A$1,$B44,C$1,$B$1) -> 3999.41 | D44: =_xll.EQNXTDZ($A$1,$B44,D$1,$B$1) -> 3137.56 | E44: =_xll.EQNXTDZ($A$1,$B44,E$1,$B$1) -> 3216.6 | F44: =_xll.EQNXTDZ($A$1,$B44,F$1,$B$1) -> 2647.32 | G44: =_xll.EQNXTDZ($A$1,$B44,G$1,$B$1) -> 3315.93 | H44: =_xll.EQNXTDZ($A$1,$B44,H$1,$B$1) -> 4964.48 | I44: =_xll.EQNXTDZ($A$1,$B44,I$1,$B$1) -> 6921.55 | J44: =_xll.EQNXTDZ($A$1,$B44,J$1,$B$1) -> 10831.11 | ... AF44: =_xll.EQNXTDZ($A$1,$B44,AF$1,$B$1) -> 0
A45: Minority Interest | B45: BS_MINORITY_INTEREST | C45: =_xll.EQNXTDZ($A$1,$B45,C$1,$B$1) -> 0 | D45: =_xll.EQNXTDZ($A$1,$B45,D$1,$B$1) -> 44.4 | E45: =_xll.EQNXTDZ($A$1,$B45,E$1,$B$1) -> 50.15 | F45: =_xll.EQNXTDZ($A$1,$B45,F$1,$B$1) -> 54.08 | G45: =_xll.EQNXTDZ($A$1,$B45,G$1,$B$1) -> 104.77 | H45: =_xll.EQNXTDZ($A$1,$B45,H$1,$B$1) -> 106.63 | I45: =_xll.EQNXTDZ($A$1,$B45,I$1,$B$1) -> 645.7 | J45: =_xll.EQNXTDZ($A$1,$B45,J$1,$B$1) -> 922.62 | ... AF45: =_xll.EQNXTDZ($A$1,$B45,AF$1,$B$1) -> 0
A46: Long-Term Borrowings | B46: BS_LTRM_BORROWING | C46: =_xll.EQNXTDZ($A$1,$B46,C$1,$B$1) -> 0 | D46: =_xll.EQNXTDZ($A$1,$B46,D$1,$B$1) -> 0 | E46: =_xll.EQNXTDZ($A$1,$B46,E$1,$B$1) -> 0 | F46: =_xll.EQNXTDZ($A$1,$B46,F$1,$B$1) -> 0 | G46: =_xll.EQNXTDZ($A$1,$B46,G$1,$B$1) -> 0 | H46: =_xll.EQNXTDZ($A$1,$B46,H$1,$B$1) -> 0 | I46: =_xll.EQNXTDZ($A$1,$B46,I$1,$B$1) -> 0 | J46: =_xll.EQNXTDZ($A$1,$B46,J$1,$B$1) -> 0 | ... AF46: =_xll.EQNXTDZ($A$1,$B46,AF$1,$B$1) -> 0
A47: Secured Loans | B47: BS_SECURED_LOANS | C47: =_xll.EQNXTDZ($A$1,$B47,C$1,$B$1) -> 3001.95 | D47: =_xll.EQNXTDZ($A$1,$B47,D$1,$B$1) -> 4081.21 | E47: =_xll.EQNXTDZ($A$1,$B47,E$1,$B$1) -> 3979.65 | F47: =_xll.EQNXTDZ($A$1,$B47,F$1,$B$1) -> 2269.06 | G47: =_xll.EQNXTDZ($A$1,$B47,G$1,$B$1) -> 1848.28 | H47: =_xll.EQNXTDZ($A$1,$B47,H$1,$B$1) -> 1911.43 | I47: =_xll.EQNXTDZ($A$1,$B47,I$1,$B$1) -> 3109.04 | J47: =_xll.EQNXTDZ($A$1,$B47,J$1,$B$1) -> 6756.16 | ... AF47: =_xll.EQNXTDZ($A$1,$B47,AF$1,$B$1) -> 0
A48: Unsecured Loans | B48: BS_UNSECURED_LOANS_NF | C48: =_xll.EQNXTDZ($A$1,$B48,C$1,$B$1) -> 1261.44 | D48: =_xll.EQNXTDZ($A$1,$B48,D$1,$B$1) -> 896.88 | E48: =_xll.EQNXTDZ($A$1,$B48,E$1,$B$1) -> 721.24 | F48: =_xll.EQNXTDZ($A$1,$B48,F$1,$B$1) -> 500.16 | G48: =_xll.EQNXTDZ($A$1,$B48,G$1,$B$1) -> 1605.55 | H48: =_xll.EQNXTDZ($A$1,$B48,H$1,$B$1) -> 1587.26 | I48: =_xll.EQNXTDZ($A$1,$B48,I$1,$B$1) -> 3323.18 | J48: =_xll.EQNXTDZ($A$1,$B48,J$1,$B$1) -> 5559.77 | ... AF48: =_xll.EQNXTDZ($A$1,$B48,AF$1,$B$1) -> 0
A49: Deferred Tax Assets / Liabilities | B49: BS_NET_DEF_TAX_NF | C49: =_xll.EQNXTDZ($A$1,$B49,C$1,$B$1) -> 0 | D49: =_xll.EQNXTDZ($A$1,$B49,D$1,$B$1) -> 927.92 | E49: =_xll.EQNXTDZ($A$1,$B49,E$1,$B$1) -> 913.01 | F49: =_xll.EQNXTDZ($A$1,$B49,F$1,$B$1) -> 213.51 | G49: =_xll.EQNXTDZ($A$1,$B49,G$1,$B$1) -> 137.58 | H49: =_xll.EQNXTDZ($A$1,$B49,H$1,$B$1) -> 126.75 | I49: =_xll.EQNXTDZ($A$1,$B49,I$1,$B$1) -> 107.41 | J49: =_xll.EQNXTDZ($A$1,$B49,J$1,$B$1) -> 121.72 | ... AF49: =_xll.EQNXTDZ($A$1,$B49,AF$1,$B$1) -> 0
A50: Other Long Term Liabilities | B50: BS_OTH_LT_LIAB | C50: =_xll.EQNXTDZ($A$1,$B50,C$1,$B$1) -> 0 | D50: =_xll.EQNXTDZ($A$1,$B50,D$1,$B$1) -> 0 | E50: =_xll.EQNXTDZ($A$1,$B50,E$1,$B$1) -> 0 | F50: =_xll.EQNXTDZ($A$1,$B50,F$1,$B$1) -> 0 | G50: =_xll.EQNXTDZ($A$1,$B50,G$1,$B$1) -> 0 | H50: =_xll.EQNXTDZ($A$1,$B50,H$1,$B$1) -> 0 | I50: =_xll.EQNXTDZ($A$1,$B50,I$1,$B$1) -> 0 | J50: =_xll.EQNXTDZ($A$1,$B50,J$1,$B$1) -> 0 | ... AF50: =_xll.EQNXTDZ($A$1,$B50,AF$1,$B$1) -> 0
A51: Long Term Trade Payables | B51: BS_LT_TRADE_PAYABLES | C51: =_xll.EQNXTDZ($A$1,$B51,C$1,$B$1) -> 0 | D51: =_xll.EQNXTDZ($A$1,$B51,D$1,$B$1) -> 0 | E51: =_xll.EQNXTDZ($A$1,$B51,E$1,$B$1) -> 0 | F51: =_xll.EQNXTDZ($A$1,$B51,F$1,$B$1) -> 0 | G51: =_xll.EQNXTDZ($A$1,$B51,G$1,$B$1) -> 0 | H51: =_xll.EQNXTDZ($A$1,$B51,H$1,$B$1) -> 0 | I51: =_xll.EQNXTDZ($A$1,$B51,I$1,$B$1) -> 0 | J51: =_xll.EQNXTDZ($A$1,$B51,J$1,$B$1) -> 0 | ... AF51: =_xll.EQNXTDZ($A$1,$B51,AF$1,$B$1) -> 0
... A99: Estimated Capital Contracts Remaining | B99: BS_ESTIMATED_CAPITAL_CONTRACT | C99: =_xll.EQNXTDZ($A$1,$B99,C$1,$B$1) -> 0 | D99: =_xll.EQNXTDZ($A$1,$B99,D$1,$B$1) -> 0 | E99: =_xll.EQNXTDZ($A$1,$B99,E$1,$B$1) -> 0 | F99: =_xll.EQNXTDZ($A$1,$B99,F$1,$B$1) -> 0 | G99: =_xll.EQNXTDZ($A$1,$B99,G$1,$B$1) -> 0 | H99: =_xll.EQNXTDZ($A$1,$B99,H$1,$B$1) -> 0 | I99: =_xll.EQNXTDZ($A$1,$B99,I$1,$B$1) -> 0 | J99: =_xll.EQNXTDZ($A$1,$B99,J$1,$B$1) -> 0 | ... AF99: =_xll.EQNXTDZ($A$1,$B99,AF$1,$B$1) -> 0
A103: Field Description | B103: Field Name
A104: Equity Paid Up | B104: BS_EQUITY_PAIDUP | C104: =_xll.EQNXTDZ($A$1,$B104,C$1,$B$1) -> 248.65 | D104: =_xll.EQNXTDZ($A$1,$B104,D$1,$B$1) -> 248.66 | E104: =_xll.EQNXTDZ($A$1,$B104,E$1,$B$1) -> 248.67 | F104: =_xll.EQNXTDZ($A$1,$B104,F$1,$B$1) -> 24.88 | G104: =_xll.EQNXTDZ($A$1,$B104,G$1,$B$1) -> 25.98 | H104: =_xll.EQNXTDZ($A$1,$B104,H$1,$B$1) -> 27.48 | I104: =_xll.EQNXTDZ($A$1,$B104,I$1,$B$1) -> 56.65 | J104: =_xll.EQNXTDZ($A$1,$B104,J$1,$B$1) -> 58.47 | ... AF104: =_xll.EQNXTDZ($A$1,$B104,AF$1,$B$1) -> 0
A105: Face Value | B105: BS_FACE_VALUE | C105: =_xll.EQNXTDZ($A$1,$B105,C$1,$B$1) -> 10 | D105: =_xll.EQNXTDZ($A$1,$B105,D$1,$B$1) -> 10 | E105: =_xll.EQNXTDZ($A$1,$B105,E$1,$B$1) -> 10 | F105: =_xll.EQNXTDZ($A$1,$B105,F$1,$B$1) -> 2 | G105: =_xll.EQNXTDZ($A$1,$B105,G$1,$B$1) -> 2 | H105: =_xll.EQNXTDZ($A$1,$B105,H$1,$B$1) -> 2 | I105: =_xll.EQNXTDZ($A$1,$B105,I$1,$B$1) -> 2 | J105: =_xll.EQNXTDZ($A$1,$B105,J$1,$B$1) -> 2 | ... AF105: =_xll.EQNXTDZ($A$1,$B105,AF$1,$B$1) -> 0
