Workbook

Sheet Template
A1: =+'Annual Raw'!C4 -> Lloyds Metals & Energy Ltd. | B1: 36951 | C1: =EOMONTH(B1,12) -> 37346 | D1: =EOMONTH(C1,12) -> 37711 | E1: =EOMONTH(D1,12) -> 38077 | F1: =EOMONTH(E1,12) -> 38442 | G1: =EOMONTH(F1,12) -> 38807 | H1: =EOMONTH(G1,12) -> 39172 | I1: =EOMONTH(H1,12) -> 39538 | J1: =EOMONTH(I1,12) -> 39903 | ... AE1: =EOMONTH(AD1,12) -> 47573 | AH1: QTR | AI1: 41061 | AJ1: 41153 | AK1: 41244 | AL1: 41334 | AM1: 41426 | AN1: 41518 | AO1: 41609 | AP1: 41699 | AQ1: 41791 | AR1: 41883 | AS1: 41974 | AT1: 42064 | AU1: 42156 | AV1: 42248 | AW1: 42339 | AX1: 42430 | AY1: 42522 | AZ1: 42614 | BA1: 42705 | BB1: 42795 | BC1: 42887 | BD1: 42979 | BE1: 43070 | BF1: 43160 | BG1: 43252 | BH1: 43344 | BI1: 43435 | BJ1: 43525 | BK1: 43617 | BL1: 43709 | BM1: 43800 | BN1: 43891 | BO1: 43983 | BP1: 44075 | BQ1: =EOMONTH(BP1,3) -> 44196 | BR1: =EOMONTH(BQ1,3) -> 44286 | BS1: =EOMONTH(BR1,3) -> 44377 | BT1: =EOMONTH(BS1,3) -> 44469 | BU1: =EOMONTH(BT1,3) -> 44561 | BV1: =EOMONTH(BU1,3) -> 44651 | BW1: =EOMONTH(BV1,3) -> 44742 | BX1: =EOMONTH(BW1,3) -> 44834 | ... DB1: =EOMONTH(DA1,3) -> 47573 | DE1: HISTORICAL ESTIMATES | DF1: 46112
A2: Presentation Data (Start)
A4: Capacity
A5: Iron Ore Mining (mntpa) | Y5: 10 | Z5: 10 | AA5: 26 | AB5: 26 | AC5: 26 | AD5: 26 | AE5: 26 | CA5: =+Y5/4 -> 2.5 | CB5: =+CA5 -> 2.5 | CC5: =+CB5 -> 2.5 | CD5: =+CC5 -> 2.5 | CE5: =+Z5/4 -> 2.5 | CF5: =+CE5 -> 2.5 | CG5: =+CF5 -> 2.5 | CH5: =+CG5 -> 2.5 | CI5: =+AA5/4 -> 6.5 | CJ5: =+CI5 -> 6.5 | CK5: =+CJ5 -> 6.5 | CL5: =+CK5 -> 6.5 | CM5: =+AB5/4 -> 6.5 | CN5: =+CM5 -> 6.5 | CO5: =+CN5 -> 6.5 | CP5: =+CO5 -> 6.5 | CQ5: =+AC5/4 -> 6.5 | CR5: =+CQ5 -> 6.5 | CS5: =+CR5 -> 6.5 | CT5: =+CS5 -> 6.5 | CU5: =+AD5/4 -> 6.5 | CV5: =+CU5 -> 6.5 | CW5: =+CV5 -> 6.5 | CX5: =+CW5 -> 6.5 | CY5: =+AE5/4 -> 6.5 | CZ5: =+CY5 -> 6.5 | DA5: =+CZ5 -> 6.5 | DB5: =+DA5 -> 6.5 | DF5: 26
A6: Pellet(mntpa) Gadchiroli+Ghusghus | AA6: 4 | AB6: =4+4 -> 8 | AC6: =8+4 -> 12 | AD6: =8+4 -> 12 | AE6: =8+4 -> 12 | CI6: =+AA6/4 -> 1 | CJ6: =+CI6 -> 1 | CK6: =+CJ6 -> 1 | CL6: =+CK6 -> 1 | CM6: =+AB6/4 -> 2 | CN6: =+CM6 -> 2 | CO6: =+CN6 -> 2 | CP6: =+CO6 -> 2 | CQ6: =+CP6 -> 2 | CR6: =+CS6 -> 3 | CS6: =+CT6 -> 3 | CT6: =+AC6/4 -> 3 | CU6: =+AD6/4 -> 3 | CV6: =+CU6 -> 3 | CW6: =+CV6 -> 3 | CX6: =+CW6 -> 3 | CY6: =+AE6/4 -> 3 | CZ6: =+CY6 -> 3 | DA6: =+CZ6 -> 3 | DB6: =+DA6 -> 3 | DF6: 4
A7: DRI(Gadchiroli+Ghusghus) | Y7: 0.344 | Z7: 0.344 | AA7: 0.704 | AB7: 0.704 | AC7: 0.704 | AD7: 0.704 | AE7: 0.704 | CA7: =+Y7/4 -> 0.086 | CB7: =+CA7 -> 0.086 | CC7: =+CB7 -> 0.086 | CD7: =+CC7 -> 0.086 | CE7: =+Z7/4 -> 0.086 | CF7: =+CE7 -> 0.086 | CG7: =+CF7 -> 0.086 | CH7: =+CG7 -> 0.086 | CI7: =+AA7/4 -> 0.176 | CJ7: =+CI7 -> 0.176 | CK7: =+CJ7 -> 0.176 | CL7: =+CK7 -> 0.176 | CM7: =+AB7/4 -> 0.176 | CN7: =+CM7 -> 0.176 | CO7: =+CN7 -> 0.176 | CP7: =+CO7 -> 0.176 | CQ7: =+AC7/4 -> 0.176 | CR7: =+CQ7 -> 0.176 | CS7: =+CR7 -> 0.176 | CT7: =+CS7 -> 0.176 | CU7: =+AD7/4 -> 0.176 | CV7: =+CU7 -> 0.176 | CW7: =+CV7 -> 0.176 | CX7: =+CW7 -> 0.176 | CY7: =+AE7/4 -> 0.176 | CZ7: =+CY7 -> 0.176 | DA7: =+CZ7 -> 0.176 | DB7: =+DA7 -> 0.176
A8: Wire Rod in Ghusghus-Steel | AB8: 1.2 | AC8: =+AB8 -> 1.2 | AD8: =+AC8 -> 1.2 | AE8: =+AD8 -> 1.2 | CP8: =+AB8/4 -> 0.3 | CQ8: =+AC8/4 -> 0.3 | CR8: =+CQ8 -> 0.3 | CS8: =+CR8 -> 0.3 | CT8: =+CS8 -> 0.3 | CU8: =+AD8/4 -> 0.3 | CV8: =+CU8 -> 0.3 | CW8: =+CV8 -> 0.3 | CX8: =+CW8 -> 0.3 | CY8: =+AE8/4 -> 0.3 | CZ8: =+CY8 -> 0.3 | DA8: =+CZ8 -> 0.3 | DB8: =+DA8 -> 0.3
A9: HRC in Gadchiroli-Steel | AE9: 3 | CY9: =+AE9/4 -> 0.75 | CZ9: =+CY9 -> 0.75 | DA9: =+CZ9 -> 0.75 | DB9: =+DA9 -> 0.75
A10: Production
A11: Iron Ore Production | W11: =SUM(BS11:BV11) -> 0 | X11: =SUM(BW11:BZ11) -> 3.59 | Y11: =SUM(CA11:CD11) -> 10 | Z11: =SUM(CE11:CH11) -> 10 | AA11: =SUM(CI11:CL11) -> 22 | AB11: =+SUM(CM11:CP11) -> 24 | AC11: =+SUM(CQ11:CT11) -> 16 | AD11: =+SUM(CU11:CX11) -> 11 | AE11: =+SUM(CY11:DB11) -> 11 | BW11: 0.76 | BX11: 0.73 | BY11: 1.52 | BZ11: 0.58 | CA11: 3.8 | CB11: 1.9 | CC11: 2.42 | CD11: 1.88 | CE11: 4 | CF11: 1.9 | CG11: 2.7 | CH11: 1.4 | CI11: 4 | CJ11: 3.4 | CK11: 5.5 | CL11: 9.1 | CM11: 7 | CN11: =+CM11 -> 7 | CO11: 5 | CP11: =+CO11 -> 5 | CQ11: 4 | CR11: =+CQ11 -> 4 | CS11: =+CR11 -> 4 | CT11: =+CS11 -> 4 | CU11: 2.75 | CV11: =+CU11 -> 2.75 | CW11: =+CV11 -> 2.75 | CX11: =+CW11 -> 2.75 | CY11: 2.75 | CZ11: =+CY11 -> 2.75 | DA11: =+CZ11 -> 2.75 | DB11: =+DA11 -> 2.75
A12: BHQ Production | W12: =SUM(BS12:BV12) -> 0 | X12: =SUM(BW12:BZ12) -> 0 | Y12: =SUM(CA12:CD12) -> 0 | Z12: =SUM(CE12:CH12) -> 0 | AA12: =SUM(CI12:CL12) -> 0 | AB12: =+SUM(CM12:CP12) -> 2 | AC12: =+SUM(CQ12:CT12) -> 9 | AD12: =+SUM(CU12:CX12) -> 15 | AE12: =+SUM(CY12:DB12) -> 15 | CO12: 1 | CP12: =+CO12 -> 1 | CQ12: 2.25 | CR12: =+CQ12 -> 2.25 | CS12: =+CR12 -> 2.25 | CT12: =+CS12 -> 2.25 | CU12: 3.75 | CV12: =+CU12 -> 3.75 | CW12: =+CV12 -> 3.75 | CX12: =+CW12 -> 3.75 | CY12: =+CX12 -> 3.75 | CZ12: =+CY12 -> 3.75 | DA12: =+CZ12 -> 3.75 | DB12: =+DA12 -> 3.75
A13: Total Iron Ore Production | W13: =+W11+W12 -> 0 | X13: =+X11+X12 -> 3.59 | Y13: =+Y11+Y12 -> 10 | Z13: =+Z11+Z12 -> 10 | AA13: =+AA11+AA12 -> 22 | AB13: =+AB11+AB12 -> 26 | AC13: =+AC11+AC12 -> 25 | AD13: =+AD11+AD12 -> 26 | AE13: =+AE11+AE12 -> 26 | CE13: =+CE11+CE12 -> 4 | CF13: =+CF11+CF12 -> 1.9 | CG13: =+CG11+CG12 -> 2.7 | CH13: =+CH11+CH12 -> 1.4 | CI13: =+CI11+CI12 -> 4 | CJ13: =+CJ11+CJ12 -> 3.4 | CK13: =+CK11+CK12 -> 5.5 | CL13: =+CL11+CL12 -> 9.1 | ... DB13: =+DB11+DB12 -> 6.5
A14: Pellet Production | W14: =SUM(BS14:BV14) -> 0 | X14: =SUM(BW14:BZ14) -> 0 | Y14: =SUM(CA14:CD14) -> 0 | Z14: =SUM(CE14:CH14) -> 0 | AA14: =SUM(CI14:CL14) -> 3.03 | AB14: =+SUM(CM14:CP14) -> 7.2 | AC14: =+SUM(CQ14:CT14) -> 9.9 | AD14: =+SUM(CU14:CX14) -> 10.92 | AE14: =+SUM(CY14:DB14) -> 10.92 | CI14: 0.02 | CJ14: 0.69 | CK14: =1.95-CJ14-CI14 -> 1.24 | CL14: =3.03-CK14-CJ14-CI14 -> 1.08 | CM14: =+CM6*90% -> 1.8 | CN14: =+CN6*90% -> 1.8 | CO14: =+CO6*90% -> 1.8 | CP14: =+CP6*90% -> 1.8 | CQ14: =+CQ6*90% -> 1.8 | CR14: =+CR6*90% -> 2.7 | CS14: =+CS6*90% -> 2.7 | CT14: =+CT6*90% -> 2.7 | CU14: =+CU6*91% -> 2.73 | CV14: =+CV6*91% -> 2.73 | CW14: =+CW6*91% -> 2.73 | CX14: =+CX6*91% -> 2.73 | CY14: =+CY6*91% -> 2.73 | CZ14: =+CZ6*91% -> 2.73 | DA14: =+DA6*91% -> 2.73 | DB14: =+DB6*91% -> 2.73
A15: DRI production | W15: =SUM(BS15:BV15) -> 0 | X15: =SUM(BW15:BZ15) -> 0.20423 | Y15: =SUM(CA15:CD15) -> 0.261836 | Z15: =SUM(CE15:CH15) -> 0.308243 | AA15: =SUM(CI15:CL15) -> 0.484 | AB15: =+SUM(CM15:CP15) -> 0.704 | AC15: =+SUM(CQ15:CT15) -> 0.704 | AD15: =+SUM(CU15:CX15) -> 0.704 | AE15: =+SUM(CY15:DB15) -> 0.704 | BW15: 0.046 | BX15: 0.04728 | BY15: 0.06048 | BZ15: 0.05047 | CA15: 0.0663 | CB15: 0.04815 | CC15: 0.081581 | CD15: 0.065805 | CE15: 0.076704 | CF15: 0.084968 | CG15: 0.076761 | CH15: 0.06981 | CI15: 0.079033 | CJ15: 0.088767 | CK15: =0.291-CJ15-CI15 -> 0.1232 | CL15: =0.484-CK15-CJ15-CI15 -> 0.193 | CM15: =+CM7 -> 0.176 | CN15: =+CN7 -> 0.176 | CO15: =+CO7 -> 0.176 | CP15: =+CP7 -> 0.176 | CQ15: =+CQ7 -> 0.176 | CR15: =+CR7 -> 0.176 | CS15: =+CS7 -> 0.176 | CT15: =+CT7 -> 0.176 | ... DB15: =+DB7 -> 0.176
A16: Wire Rod Production | W16: =SUM(BS16:BV16) -> 0 | X16: =SUM(BW16:BZ16) -> 0 | Y16: =SUM(CA16:CD16) -> 0 | Z16: =SUM(CE16:CH16) -> 0 | AA16: =SUM(CI16:CL16) -> 0 | AB16: =+SUM(CM16:CP16) -> 0.21 | AC16: =+SUM(CQ16:CT16) -> 0.96 | AD16: =+SUM(CU16:CX16) -> 1.02 | AE16: =+SUM(CY16:DB16) -> 1.08 | CP16: =+CP8*70% -> 0.21 | CQ16: =+CQ8*80% -> 0.24 | CR16: =+CR8*80% -> 0.24 | CS16: =+CS8*80% -> 0.24 | CT16: =+CT8*80% -> 0.24 | CU16: =+CU8*85% -> 0.255 | CV16: =+CV8*85% -> 0.255 | CW16: =+CW8*85% -> 0.255 | CX16: =+CX8*85% -> 0.255 | CY16: =+CY8*90% -> 0.27 | CZ16: =+CZ8*90% -> 0.27 | DA16: =+DA8*90% -> 0.27 | DB16: =+DB8*90% -> 0.27
A17: HRC Steel Production | W17: =SUM(BS17:BV17) -> 0 | X17: =SUM(BW17:BZ17) -> 0 | Y17: =SUM(CA17:CD17) -> 0 | Z17: =SUM(CE17:CH17) -> 0 | AA17: =SUM(CI17:CL17) -> 0 | AB17: =+SUM(CM17:CP17) -> 0 | AC17: =+SUM(CQ17:CT17) -> 0 | AD17: =+SUM(CU17:CX17) -> 0 | AE17: =+SUM(CY17:DB17) -> 2.4 | CY17: =+CY9*80% -> 0.6 | CZ17: =+CZ9*80% -> 0.6 | DA17: =+DA9*80% -> 0.6 | DB17: =+DB9*80% -> 0.6
A19: Intersegmental Usage
A20: Material Used for Pellet Production
A21: Iron Ore Used For Pellet production (1.2 tonnes of raw Iron Ore (IO) to produce 1 tonne of finished iron ore pellets) | W21: =SUM(BS21:BV21) -> 0 | X21: =SUM(BW21:BZ21) -> 0 | Y21: =SUM(CA21:CD21) -> 0 | Z21: =SUM(CE21:CH21) -> 0 | AA21: =SUM(CI21:CL21) -> 3.636 | AB21: =+SUM(CM21:CP21) -> 8.64 | AC21: =+SUM(CQ21:CT21) -> 11.88 | AD21: =+SUM(CU21:CX21) -> 13.104 | AE21: =+SUM(CY21:DB21) -> 13.104 | CI21: =+CI14*1.2 -> 0.024 | CJ21: =+CJ14*1.2 -> 0.828 | CK21: =+CK14*1.2 -> 1.488 | CL21: =+CL14*1.2 -> 1.296 | CM21: =+CM14*1.2 -> 2.16 | CN21: =+CN14*1.2 -> 2.16 | CO21: =+CO14*1.2 -> 2.16 | CP21: =+CP14*1.2 -> 2.16 | ... DB21: =+DB14*1.2 -> 3.276
A22: Materials used for DRI production
A23: Iron Ore used for making DRI(1.62 tonnes of raw ore = 1 tonne of DRI) | W23: =SUM(BS23:BV23) -> 0 | X23: =SUM(BW23:BZ23) -> 0.3308526 | Y23: =SUM(CA23:CD23) -> 0.42417432 | Z23: =SUM(CE23:CH23) -> 0.49935366 | AA23: =SUM(CI23:CL23) -> 0.10803346 | AB23: =+SUM(CM23:CP23) -> 0 | AC23: =+SUM(CQ23:CT23) -> 0 | AD23: =+SUM(CU23:CX23) -> 0 | AE23: =+SUM(CY23:DB23) -> 0 | BW23: =+BW15*1.62 -> 0.07452 | BX23: =+BX15*1.62 -> 0.0765936 | BY23: =+BY15*1.62 -> 0.0979776 | BZ23: =+BZ15*1.62 -> 0.0817614 | CA23: =+CA15*1.62 -> 0.107406 | CB23: =+CB15*1.62 -> 0.078003 | CC23: =+CC15*1.62 -> 0.13216122 | CD23: =+CD15*1.62 -> 0.1066041 | ... CH23: =+CH15*1.62 -> 0.1130922 | CI23: =+(CI15*1.62)-CI24 -> 0.10803346 | CJ23: 0 | CK23: 0
A24: Pellet Used for making DRI((1.35 tonnes of pellets = 1 tonne of DRI) | W24: =SUM(BS24:BV24) -> 0 | X24: =SUM(BW24:BZ24) -> 0 | Y24: =SUM(CA24:CD24) -> 0 | Z24: =SUM(CE24:CH24) -> 0 | AA24: =SUM(CI24:CL24) -> 0.56670545 | AB24: =+SUM(CM24:CP24) -> 0.9504 | AC24: =+SUM(CQ24:CT24) -> 0.9504 | AD24: =+SUM(CU24:CX24) -> 0.9504 | AE24: =+SUM(CY24:DB24) -> 0.9504 | CI24: =+CI14 -> 0.02 | CJ24: =+CJ15*1.35 -> 0.11983545 | CK24: =+CK15*1.35 -> 0.16632 | CL24: =+CL15*1.35 -> 0.26055 | CM24: =+CM15*1.35 -> 0.2376 | CN24: =+CN15*1.35 -> 0.2376 | CO24: =+CO15*1.35 -> 0.2376 | CP24: =+CP15*1.35 -> 0.2376 | CQ24: =+CQ15*1.35 -> 0.2376 | ... DB24: =+DB15*1.35 -> 0.2376
A25: Materials used for Wire Rod plant
A26: Total RM used to make Wire Rod | W26: =SUM(BS26:BV26) -> 0 | X26: =SUM(BW26:BZ26) -> 0 | Y26: =SUM(CA26:CD26) -> 0 | Z26: =SUM(CE26:CH26) -> 0 | AA26: =SUM(CI26:CL26) -> 0 | AB26: =+SUM(CM26:CP26) -> 0.231 | AC26: =+SUM(CQ26:CT26) -> 1.056 | AD26: =+SUM(CU26:CX26) -> 1.122 | AE26: =+SUM(CY26:DB26) -> 1.188 | CP26: =+CP16*1.1 -> 0.231 | CQ26: =+CQ16*1.1 -> 0.264 | CR26: =+CR16*1.1 -> 0.264 | CS26: =+CS16*1.1 -> 0.264 | CT26: =+CT16*1.1 -> 0.264 | CU26: =+CU16*1.1 -> 0.2805 | CV26: =+CV16*1.1 -> 0.2805 | CW26: =+CW16*1.1 -> 0.2805 | ... DB26: =+DB16*1.1 -> 0.297
A27: DRI Used to make Wire Rod | W27: =SUM(BS27:BV27) -> 0 | X27: =SUM(BW27:BZ27) -> 0 | Y27: =SUM(CA27:CD27) -> 0 | Z27: =SUM(CE27:CH27) -> 0 | AA27: =SUM(CI27:CL27) -> 0 | AB27: =+SUM(CM27:CP27) -> 0.176 | AC27: =+SUM(CQ27:CT27) -> 0.704 | AD27: =+SUM(CU27:CX27) -> 0.704 | AE27: =+SUM(CY27:DB27) -> 0.704 | CP27: =+CP15 -> 0.176 | CQ27: =+CQ15 -> 0.176 | CR27: =+CR15 -> 0.176 | CS27: =+CS15 -> 0.176 | CT27: =+CT15 -> 0.176 | CU27: =+CU15 -> 0.176 | CV27: =+CV15 -> 0.176 | CW27: =+CW15 -> 0.176 | ... DB27: =+DB15 -> 0.176
A28: Pellet Used to make Wire Rod(b/f) | W28: =SUM(BS28:BV28) -> 0 | X28: =SUM(BW28:BZ28) -> 0 | Y28: =SUM(CA28:CD28) -> 0 | Z28: =SUM(CE28:CH28) -> 0 | AA28: =SUM(CI28:CL28) -> 0 | AB28: =+SUM(CM28:CP28) -> 0.055 | AC28: =+SUM(CQ28:CT28) -> 0.352 | AD28: =+SUM(CU28:CX28) -> 0.418 | AE28: =+SUM(CY28:DB28) -> 0.484 | CP28: =+CP26-CP27 -> 0.055 | CQ28: =+CQ26-CQ27 -> 0.088 | CR28: =+CR26-CR27 -> 0.088 | CS28: =+CS26-CS27 -> 0.088 | CT28: =+CT26-CT27 -> 0.088 | CU28: =+CU26-CU27 -> 0.1045 | CV28: =+CV26-CV27 -> 0.1045 | CW28: =+CW26-CW27 -> 0.1045 | ... DB28: =+DB26-DB27 -> 0.121
A29: Material Used For HRC
A30: Pellet used for making HRC(1.1 tonne of pellet to make 1 tonne of HRC) | AA30: =SUM(CI30:CL30) -> 0 | AB30: =+SUM(CM30:CP30) -> 0 | AC30: =+SUM(CQ30:CT30) -> 0 | AD30: =+SUM(CU30:CX30) -> 0 | AE30: =+SUM(CY30:DB30) -> 2.64 | CY30: =+CY17*1.1 -> 0.66 | CZ30: =+CZ17*1.1 -> 0.66 | DA30: =+DA17*1.1 -> 0.66 | DB30: =+DB17*1.1 -> 0.66
CJ31: =CJ50/(CJ21+CJ23+CJ24+CJ26+CJ30) -> 501.77486 | CK31: =CK50/(CK21+CK23+CK24+CK26+CK30) -> 554.16123 | CL31: =CL50/(CL21+CL23+CL24+CL26+CL30) -> 938.91619 | CM31: =+CL31 -> 938.91619 | CN31: =+CM31 -> 938.91619 | CO31: =+CN31 -> 938.91619 | CP31: =+CO31 -> 938.91619 | CQ31: 250 | CR31: =+CQ31 -> 250 | CS31: =+CR31 -> 250 | CT31: =+CS31 -> 250 | CU31: =+CT31 -> 250 | CV31: =+CU31 -> 250 | CW31: =+CV31 -> 250 | CX31: =+CW31 -> 250 | CY31: 230 | CZ31: =+CY31 -> 230 | DA31: =+CZ31 -> 230 | DB31: =+DA31 -> 230
A32: Sales (Mn T)
A33: Iron Ore Mining-Sales | W33: =+W13-W21-W23 -> 0 | X33: =+X13-X21-X23 -> 3.2591474 | Y33: =+Y13-Y21-Y23 -> 9.5758257 | Z33: =+Z13-Z21-Z23 -> 9.5006463 | AA33: =+AA13-AA21-AA23 -> 18.255967 | AB33: =+AB13-AB21-AB23 -> 17.36 | AC33: =+AC13-AC21-AC23 -> 13.12 | AD33: =+AD13-AD21-AD23 -> 12.896 | AE33: =+AE13-AE21-AE23 -> 12.896 | BU33: 0.06 | BV33: 0.3 | BW33: 1.15 | BX33: 1.32 | BY33: 1.73 | BZ33: 1.1 | CA33: 3.2 | CB33: 1.98 | CC33: 2.49 | CD33: 1.98 | CE33: 3.6 | CF33: 1.98 | CG33: 2.48 | CH33: 1.66 | CI33: 3.45 | CJ33: 2.5 | CK33: 4.1 | CL33: 6.16 | CM33: =+CM13-CM21-CM23 -> 4.84 | CN33: =+CN13-CN21-CN23 -> 4.84 | CO33: =+CO13-CO21-CO23 -> 3.84 | CP33: =+CP13-CP21-CP23 -> 3.84 | CQ33: =+CQ13-CQ21-CQ23 -> 4.09 | CR33: =+CR13-CR21-CR23 -> 3.01 | CS33: =+CS13-CS21-CS23 -> 3.01 | CT33: =+CT13-CT21-CT23 -> 3.01 | ... DB33: =+DB13-DB21-DB23 -> 3.224 | DF33: 4.92
A34: Pellet-Sales | W34: =+W14-W24-W28-W30 -> 0 | X34: =+X14-X24-X28-X30 -> 0 | Y34: =+Y14-Y24-Y28-Y30 -> 0 | Z34: =+Z14-Z24-Z28-Z30 -> 0 | AA34: =+AA14-AA24-AA28-AA30 -> 2.4632945 | AB34: =+AB14-AB24-AB28-AB30 -> 6.1946 | AC34: =+AC14-AC24-AC28-AC30 -> 8.5976 | AD34: =+AD14-AD24-AD28-AD30 -> 9.5516 | AE34: =+AE14-AE24-AE28-AE30 -> 6.8456 | CJ34: 0.69 | CK34: 1 | CL34: 0.89 | CM34: =+CM14-CM24-CM28-CM30 -> 1.5624 | CN34: =+CN14-CN24-CN28-CN30 -> 1.5624 | CO34: =+CO14-CO24-CO28-CO30 -> 1.5624 | CP34: =+CP14-CP24-CP28-CP30 -> 1.5074 | CQ34: =+CQ14-CQ24-CQ28-CQ30 -> 1.4744 | CR34: =+CR14-CR24-CR28-CR30 -> 2.3744 | CS34: =+CS14-CS24-CS28-CS30 -> 2.3744 | CT34: =+CT14-CT24-CT28-CT30 -> 2.3744 | ... DB34: =+DB14-DB24-DB28-DB30 -> 1.7114 | DF34: 0.684
A35: DRI-Sales | W35: =+W15-W27 -> 0 | X35: =+X15-X27 -> 0.20423 | Y35: =+Y15-Y27 -> 0.261836 | Z35: =+Z15-Z27 -> 0.308243 | AA35: =+AA15-AA27 -> 0.484 | AB35: =+AB15-AB27 -> 0.528 | AC35: =+AC15-AC27 -> 0 | AD35: =+AD15-AD27 -> 0 | AE35: =+AE15-AE27 -> 0 | BU35: 0.03405 | BV35: 0.03484 | BW35: 0.04475 | BX35: 0.04685 | BY35: 0.06089 | BZ35: 0.05167 | CA35: 0.06701 | CB35: 0.04815 | CC35: 0.08096 | CD35: 0.06724 | CE35: =+CE15 -> 0.076704 | CF35: =+CF15 -> 0.084968 | CG35: =+CG15 -> 0.076761 | CH35: =+CH15 -> 0.06981 | CI35: =+CI15 -> 0.079033 | CJ35: =+CJ15 -> 0.088767 | CK35: =+CK15 -> 0.1232 | CL35: 0.188 | CM35: =+CM15-CM27 -> 0.176 | CN35: =+CN15-CN27 -> 0.176 | CO35: =+CO15-CO27 -> 0.176 | CP35: =+CP15-CP27 -> 0 | CQ35: =+CQ15-CQ27 -> 0 | CR35: =+CR15-CR27 -> 0 | CS35: =+CS15-CS27 -> 0 | CT35: =+CT15-CT27 -> 0 | ... DB35: =+DB15-DB27 -> 0 | DF35: 0.12
A36: Wire Rod-Steel Sales | W36: =+W16 -> 0 | X36: =+X16 -> 0 | Y36: =+Y16 -> 0 | Z36: =+Z16 -> 0 | AA36: =+AA16 -> 0 | AB36: =+AB16 -> 0.21 | AC36: =+AC16 -> 0.96 | AD36: =+AD16 -> 1.02 | AE36: =+AE16 -> 1.08 | CP36: =+CP16*50% -> 0.105 | CQ36: =+CQ16*70% -> 0.168 | CR36: =+CR16*70% -> 0.168 | CS36: =+CS16*70% -> 0.168 | CT36: =+CT16*70% -> 0.168 | CU36: =+CU16*80% -> 0.204 | CV36: =+CV16*80% -> 0.204 | CW36: =+CW16*80% -> 0.204 | CX36: =+CX16*80% -> 0.204 | CY36: =+CY16*90% -> 0.243 | CZ36: =+CZ16*90% -> 0.243 | DA36: =+DA16*90% -> 0.243 | DB36: =+DB16*90% -> 0.243
A37: HRC-Steel Sales | W37: =+W17 -> 0 | X37: =+X17 -> 0 | Y37: =+Y17 -> 0 | Z37: =+Z17 -> 0 | AA37: =+AA17 -> 0 | AB37: =+AB17 -> 0 | AC37: =+AC17 -> 0 | AD37: =+AD17 -> 0 | AE37: =+AE17 -> 2.4 | CY37: =+CY17*70% -> 0.42 | CZ37: =+CZ17*70% -> 0.42 | DA37: =+DA17*70% -> 0.42 | DB37: =+DB17*70% -> 0.42
A38: Power(MW) Sales | W38: =SUM(BS38:BV38) -> 66.19 | X38: =SUM(BW38:BZ38) -> 109.42 | Y38: =SUM(CA38:CD38) -> 187.72 | Z38: =SUM(CE38:CH38) -> 200.64 | AA38: =SUM(CI38:CL38) -> 193.1 | AB38: =+SUM(CM38:CP38) -> 256 | AC38: =+SUM(CQ38:CT38) -> 256 | AD38: =+SUM(CU38:CX38) -> 256 | AE38: =+SUM(CY38:DB38) -> 256 | BU38: 30.32 | BV38: 35.87 | BX38: 16.99 | BY38: 46.67 | BZ38: 45.76 | CA38: 49.46 | CB38: 36.82 | CC38: 53.64 | CD38: 47.8 | CE38: 49.1 | CF38: 50.98 | CG38: 53.64 | CH38: 46.92 | CI38: 50.1 | CJ38: 43 | CK38: 36 | CL38: 64 | CM38: =+CL38 -> 64 | CN38: =+CM38 -> 64 | CO38: =+CN38 -> 64 | CP38: =+CO38 -> 64 | CQ38: =+CP38 -> 64 | CR38: =+CQ38 -> 64 | CS38: =+CR38 -> 64 | CT38: =+CS38 -> 64 | ... DB38: =+DA38 -> 64 | DF38: 43
A39: Realisation Per Tonne
A40: Mining (Iron Ore) | W40: =W44/W33*10 -> #DIV/0! | X40: =X44/X33*10 -> 8134.2746 | Y40: =Y44/Y33*10 -> 5558.5598 | Z40: =Z44/Z33*10 -> 5917.2606 | AA40: =AA44/AA33*10 -> 5184.8583 | AB40: =AB44/AB33*10 -> 5745.8986 | AC40: =AC44/AC33*10 -> 5350.5869 | AD40: =AD44/AD33*10 -> 5308.0081 | AE40: =AE44/AE33*10 -> 5300.746 | BU40: =(BU44-BU50)/BU33*10 -> -258.33333 | BV40: =(BV44-BV50)/BV33*10 -> 6187.6667 | BW40: =(BW44-BW50)/BW33*10 -> 5657.3043 | BX40: =(BX44-BX50)/BX33*10 -> 3798.5606 | BY40: =(BY44-BY50)/BY33*10 -> 4581.1561 | BZ40: =(BZ44-BZ50)/BZ33*10 -> 6347.3636 | CA40: =(CA44-CA50)/CA33*10 -> 5362.6562 | CB40: =(CB44-CB50)/CB33*10 -> 4742.5253 | ... CI40: =(CI44-CI50)/CI33*10 -> 6064.9855 | CJ40: =CJ44/CJ33*10 -> 5503.2 | CK40: =CK44/CK33*10 -> 5672.6829 | CL40: =CL44/CL33*10 -> 5849.8377 | CM40: =+AVERAGE(CI40:CL40) -> 5772.6765 | CN40: =+AVERAGE(CJ40:CM40) -> 5699.5993 | CO40: =+AVERAGE(CK40:CN40) -> 5748.6991 | CP40: =+AVERAGE(CL40:CO40) -> 5767.7031 | CQ40: =+AVERAGE(CM40:CP40)*0.95 -> 5459.811 | CR40: =+AVERAGE(CN40:CQ40)*0.95 -> 5385.5055 | CS40: =+AVERAGE(CO40:CR40)*0.95 -> 5310.9082 | CT40: =+AVERAGE(CP40:CS40)*0.95 -> 5206.9329 | CU40: =+AVERAGE(CQ40:CT40) -> 5340.7894 | CV40: =+AVERAGE(CR40:CU40) -> 5311.034 | CW40: =+AVERAGE(CS40:CV40) -> 5292.4161 | CX40: =+AVERAGE(CT40:CW40) -> 5287.7931 | CY40: =+AVERAGE(CU40:CX40) -> 5308.0081 | CZ40: =+AVERAGE(CV40:CY40) -> 5299.8128 | DA40: =+AVERAGE(CW40:CZ40) -> 5297.0075 | DB40: =+AVERAGE(CX40:DA40) -> 5298.1554 | DF40: 5500
A41: Pellet+ DRI | W41: =W45/SUM(W34:W35)*10 -> #DIV/0! | X41: =X45/SUM(X34:X35)*10 -> 36674.338 | Y41: =Y45/SUM(Y34:Y35)*10 -> 31602.988 | Z41: =Z45/SUM(Z34:Z35)*10 -> 32230.091 | AA41: =AA45/SUM(AA34:AA35)*10 -> 15071.381 | AB41: =AB45/SUM(AB34:AB35)*10 -> 13799.239 | AC41: =AC45/SUM(AC34:AC35)*10 -> 12722.276 | AD41: =AD45/SUM(AD34:AD35)*10 -> 12664.883 | AE41: =AE45/SUM(AE34:AE35)*10 -> 12644.587 | BV41: =BV45/SUM(BV34:BV35)*10 -> 42063.72 | BW41: =BW45/SUM(BW34:BW35)*10 -> 41483.799 | BX41: =BX45/SUM(BX34:BX35)*10 -> 37052.295 | BY41: =BY45/SUM(BY34:BY35)*10 -> 36055.181 | BZ41: =BZ45/SUM(BZ34:BZ35)*10 -> 32945.616 | CA41: =CA45/SUM(CA34:CA35)*10 -> 32739.89 | CB41: =CB45/SUM(CB34:CB35)*10 -> 31744.548 | CC41: =CC45/SUM(CC34:CC35)*10 -> 31500.741 | ... CL41: =CL45/SUM(CL34:CL35)*10 -> 12744.898 | CM41: =+AVERAGE(CJ41:CL41) -> 13980.487 | CN41: =+AVERAGE(CJ41:CM41) -> 13980.487 | CO41: =+AVERAGE(CK41:CN41) -> 13624.585 | CP41: =+AVERAGE(CL41:CO41) -> 13582.614 | CQ41: =+AVERAGE(CM41:CP41)*0.95 -> 13102.441 | CR41: =+AVERAGE(CN41:CQ41)*0.95 -> 12893.905 | CS41: =+AVERAGE(CO41:CR41)*0.95 -> 12635.842 | CT41: =+AVERAGE(CP41:CS41)*0.95 -> 12401.015 | CU41: =+AVERAGE(CQ41:CT41) -> 12758.301 | CV41: =+AVERAGE(CR41:CU41) -> 12672.266 | CW41: =+AVERAGE(CS41:CV41) -> 12616.856 | CX41: =+AVERAGE(CT41:CW41) -> 12612.109 | CY41: =+AVERAGE(CU41:CX41) -> 12664.883 | CZ41: =+AVERAGE(CV41:CY41) -> 12641.529 | DA41: =+AVERAGE(CW41:CZ41) -> 12633.844 | DB41: =+AVERAGE(CX41:DA41) -> 12638.091 | DF41: 15000
A42: Steel | AB42: =+AB47/(AB36+AB37)*10 -> 25500 | AC42: =+AC47/(AC36+AC37)*10 -> 36050 | AD42: =+AD47/(AD36+AD37)*10 -> 42400 | AE42: =+AE47/(AE36+AE37)*10 -> 41151.724 | CP42: 51000 | CQ42: 51500 | CR42: =+CQ42 -> 51500 | CS42: =+CR42 -> 51500 | CT42: =+CS42 -> 51500 | CU42: 53000 | CV42: =+CU42 -> 53000 | CW42: =+CV42 -> 53000 | CX42: =+CW42 -> 53000 | CY42: 54000 | CZ42: =+CY42 -> 54000 | DA42: =+CZ42 -> 54000 | DB42: =+DA42 -> 54000
...

Sheet QTR Raw
A1: ='Annual Raw'!A1 -> 112455 | B1: X | C1: 201206 | D1: 201209 | E1: 201212 | F1: 201303 | G1: 201306 | H1: 201309 | I1: 201312 | J1: 201403 | K1: 201406 | L1: 201409 | M1: 201412 | N1: 201503 | O1: 201506 | P1: 201509 | Q1: 201512 | R1: 201603 | S1: 201606 | T1: 201609 | U1: 201612 | V1: 201703 | W1: 201706 | X1: 201709 | Y1: 201712 | Z1: 201803 | AA1: 201806 | AB1: 201809 | AC1: 201812 | AD1: 201903 | AE1: 201906 | AF1: 201909 | AG1: 201912 | AH1: 202003 | AI1: 202006 | AJ1: 202009 | AK1: 202012 | AL1: 202103 | AM1: 202106 | AN1: 202109 | AO1: 202112 | AP1: 202203 | AQ1: 202206 | AR1: 202209 | AS1: 202212 | AT1: 202303 | AU1: 202306 | AV1: 202309 | AW1: 202312 | AX1: 202403 | AY1: 202406 | AZ1: 202409 | BA1: 202412 | BB1: 202503 | BC1: 202506 | BD1: 202509 | BE1: 202512 | BF1: 202603 | BG1: 202606 | BH1: 202609 | BI1: 202612 | BJ1: 202703 | BK1: 202706 | BL1: 202709 | BM1: 202712 | BN1: 202803 | BO1: 202806 | BP1: 202809 | BQ1: 202812 | BR1: 202903 | BS1: 202906 | BT1: 202909 | BU1: 202912 | BV1: 203003
A3: Field Description | B3: Field Name
A4: Company Name | B4: CD_COMPNAME | C4: =_xll.EQNXTDZ(A1,B4,C1) -> Lloyds Metals & Energy Ltd.
A5: Date End | B5: QTR_DATE_END | C5: =_xll.EQNXTDZ($A$1,$B5,C$1,$B$1) -> 201206 | D5: =_xll.EQNXTDZ($A$1,$B5,D$1,$B$1) -> 201209 | E5: =_xll.EQNXTDZ($A$1,$B5,E$1,$B$1) -> 201212 | F5: =_xll.EQNXTDZ($A$1,$B5,F$1,$B$1) -> 201303 | G5: =_xll.EQNXTDZ($A$1,$B5,G$1,$B$1) -> 201306 | H5: =_xll.EQNXTDZ($A$1,$B5,H$1,$B$1) -> 201309 | I5: =_xll.EQNXTDZ($A$1,$B5,I$1,$B$1) -> 201312 | J5: =_xll.EQNXTDZ($A$1,$B5,J$1,$B$1) -> 201403 | ... BV5: =_xll.EQNXTDZ($A$1,$B5,BV$1,$B$1) -> 0
A6: Gross Sales | B6: QTR_GROSS_SALE | C6: =_xll.EQNXTDZ($A$1,$B6,C$1,$B$1) -> 260.709 | D6: =_xll.EQNXTDZ($A$1,$B6,D$1,$B$1) -> 130.556 | E6: =_xll.EQNXTDZ($A$1,$B6,E$1,$B$1) -> 147.374 | F6: =_xll.EQNXTDZ($A$1,$B6,F$1,$B$1) -> 253.529 | G6: =_xll.EQNXTDZ($A$1,$B6,G$1,$B$1) -> 147.415 | H6: =_xll.EQNXTDZ($A$1,$B6,H$1,$B$1) -> 115.678 | I6: =_xll.EQNXTDZ($A$1,$B6,I$1,$B$1) -> 139.526 | J6: =_xll.EQNXTDZ($A$1,$B6,J$1,$B$1) -> 197.025 | ... BV6: =_xll.EQNXTDZ($A$1,$B6,BV$1,$B$1) -> 0
A7: Less: Excise Duty | B7: QTR_EXCISE_DUTY | C7: =_xll.EQNXTDZ($A$1,$B7,C$1,$B$1) -> 13.487 | D7: =_xll.EQNXTDZ($A$1,$B7,D$1,$B$1) -> 9.078 | E7: =_xll.EQNXTDZ($A$1,$B7,E$1,$B$1) -> 9.094 | F7: =_xll.EQNXTDZ($A$1,$B7,F$1,$B$1) -> 10.699 | G7: =_xll.EQNXTDZ($A$1,$B7,G$1,$B$1) -> 9.803 | H7: =_xll.EQNXTDZ($A$1,$B7,H$1,$B$1) -> 7.53 | I7: =_xll.EQNXTDZ($A$1,$B7,I$1,$B$1) -> 11.234 | J7: =_xll.EQNXTDZ($A$1,$B7,J$1,$B$1) -> 13.495 | ... BV7: =_xll.EQNXTDZ($A$1,$B7,BV$1,$B$1) -> 0
A8: Other operating income | B8: QTR_JOB_WORKS | C8: =_xll.EQNXTDZ($A$1,$B8,C$1,$B$1) -> 0 | D8: =_xll.EQNXTDZ($A$1,$B8,D$1,$B$1) -> 0 | E8: =_xll.EQNXTDZ($A$1,$B8,E$1,$B$1) -> 0 | F8: =_xll.EQNXTDZ($A$1,$B8,F$1,$B$1) -> 0 | G8: =_xll.EQNXTDZ($A$1,$B8,G$1,$B$1) -> 0 | H8: =_xll.EQNXTDZ($A$1,$B8,H$1,$B$1) -> 0 | I8: =_xll.EQNXTDZ($A$1,$B8,I$1,$B$1) -> 0 | J8: =_xll.EQNXTDZ($A$1,$B8,J$1,$B$1) -> 0 | ... BV8: =_xll.EQNXTDZ($A$1,$B8,BV$1,$B$1) -> 0
A9: Net Sales & Other Operating Income | B9: QTR_NET_SALES | C9: =_xll.EQNXTDZ($A$1,$B9,C$1,$B$1) -> 247.222 | D9: =_xll.EQNXTDZ($A$1,$B9,D$1,$B$1) -> 121.477 | E9: =_xll.EQNXTDZ($A$1,$B9,E$1,$B$1) -> 138.28 | F9: =_xll.EQNXTDZ($A$1,$B9,F$1,$B$1) -> 242.83 | G9: =_xll.EQNXTDZ($A$1,$B9,G$1,$B$1) -> 137.612 | H9: =_xll.EQNXTDZ($A$1,$B9,H$1,$B$1) -> 108.149 | I9: =_xll.EQNXTDZ($A$1,$B9,I$1,$B$1) -> 128.292 | J9: =_xll.EQNXTDZ($A$1,$B9,J$1,$B$1) -> 183.53 | ... BV9: =_xll.EQNXTDZ($A$1,$B9,BV$1,$B$1) -> 0
A10: (Increase) / Decrease In Stocks | B10: QTR_INC_DEC_INVENTORY | C10: =_xll.EQNXTDZ($A$1,$B10,C$1,$B$1) -> 1.27 | D10: =_xll.EQNXTDZ($A$1,$B10,D$1,$B$1) -> -0.906 | E10: =_xll.EQNXTDZ($A$1,$B10,E$1,$B$1) -> -3.725 | F10: =_xll.EQNXTDZ($A$1,$B10,F$1,$B$1) -> 3.858 | G10: =_xll.EQNXTDZ($A$1,$B10,G$1,$B$1) -> 2.473 | H10: =_xll.EQNXTDZ($A$1,$B10,H$1,$B$1) -> -1.462 | I10: =_xll.EQNXTDZ($A$1,$B10,I$1,$B$1) -> 0.664 | J10: =_xll.EQNXTDZ($A$1,$B10,J$1,$B$1) -> -8.448 | ... BV10: =_xll.EQNXTDZ($A$1,$B10,BV$1,$B$1) -> 0
A11: Cost of Services & Raw Materials | B11: QTR_RAW_MATERIAL_COST | C11: =_xll.EQNXTDZ($A$1,$B11,C$1,$B$1) -> 100.856 | D11: =_xll.EQNXTDZ($A$1,$B11,D$1,$B$1) -> 76.447 | E11: =_xll.EQNXTDZ($A$1,$B11,E$1,$B$1) -> 83.288 | F11: =_xll.EQNXTDZ($A$1,$B11,F$1,$B$1) -> 93.1 | G11: =_xll.EQNXTDZ($A$1,$B11,G$1,$B$1) -> 87.046 | H11: =_xll.EQNXTDZ($A$1,$B11,H$1,$B$1) -> 62.196 | I11: =_xll.EQNXTDZ($A$1,$B11,I$1,$B$1) -> 86.789 | J11: =_xll.EQNXTDZ($A$1,$B11,J$1,$B$1) -> 108.294 | ... BV11: =_xll.EQNXTDZ($A$1,$B11,BV$1,$B$1) -> 0
A12: Purchase of Finished Goods | B12: QTR_PURCHASE_FIN_GOOD | C12: =_xll.EQNXTDZ($A$1,$B12,C$1,$B$1) -> 126.523 | D12: =_xll.EQNXTDZ($A$1,$B12,D$1,$B$1) -> 36.508 | E12: =_xll.EQNXTDZ($A$1,$B12,E$1,$B$1) -> 46.562 | F12: =_xll.EQNXTDZ($A$1,$B12,F$1,$B$1) -> 111.535 | G12: =_xll.EQNXTDZ($A$1,$B12,G$1,$B$1) -> 45.612 | H12: =_xll.EQNXTDZ($A$1,$B12,H$1,$B$1) -> 41.833 | I12: =_xll.EQNXTDZ($A$1,$B12,I$1,$B$1) -> 30.953 | J12: =_xll.EQNXTDZ($A$1,$B12,J$1,$B$1) -> 78.351 | ... BV12: =_xll.EQNXTDZ($A$1,$B12,BV$1,$B$1) -> 0
A13: Excise Duty | B13: QTR_EXCISE | C13: =_xll.EQNXTDZ($A$1,$B13,C$1,$B$1) -> 0 | D13: =_xll.EQNXTDZ($A$1,$B13,D$1,$B$1) -> 0 | E13: =_xll.EQNXTDZ($A$1,$B13,E$1,$B$1) -> 0 | F13: =_xll.EQNXTDZ($A$1,$B13,F$1,$B$1) -> 0 | G13: =_xll.EQNXTDZ($A$1,$B13,G$1,$B$1) -> 0 | H13: =_xll.EQNXTDZ($A$1,$B13,H$1,$B$1) -> 0 | I13: =_xll.EQNXTDZ($A$1,$B13,I$1,$B$1) -> 0 | J13: =_xll.EQNXTDZ($A$1,$B13,J$1,$B$1) -> 0 | ... BV13: =_xll.EQNXTDZ($A$1,$B13,BV$1,$B$1) -> 0
A14: Operating & Manufacturing Expenses | B14: QTR_MFG_EXPS | C14: =_xll.EQNXTDZ($A$1,$B14,C$1,$B$1) -> 8.671 | D14: =_xll.EQNXTDZ($A$1,$B14,D$1,$B$1) -> 11.904 | E14: =_xll.EQNXTDZ($A$1,$B14,E$1,$B$1) -> 8.394 | F14: =_xll.EQNXTDZ($A$1,$B14,F$1,$B$1) -> 9.704 | G14: =_xll.EQNXTDZ($A$1,$B14,G$1,$B$1) -> 8.294 | H14: =_xll.EQNXTDZ($A$1,$B14,H$1,$B$1) -> 7.814 | I14: =_xll.EQNXTDZ($A$1,$B14,I$1,$B$1) -> 7.919 | J14: =_xll.EQNXTDZ($A$1,$B14,J$1,$B$1) -> 9.317 | ... BV14: =_xll.EQNXTDZ($A$1,$B14,BV$1,$B$1) -> 0
A15: Electricity Power & Fuel Cost | B15: QTR_ELECTRICITY_POWER_FUEL | C15: =_xll.EQNXTDZ($A$1,$B15,C$1,$B$1) -> 0 | D15: =_xll.EQNXTDZ($A$1,$B15,D$1,$B$1) -> 0 | E15: =_xll.EQNXTDZ($A$1,$B15,E$1,$B$1) -> 0 | F15: =_xll.EQNXTDZ($A$1,$B15,F$1,$B$1) -> 0 | G15: =_xll.EQNXTDZ($A$1,$B15,G$1,$B$1) -> 0 | H15: =_xll.EQNXTDZ($A$1,$B15,H$1,$B$1) -> 0 | I15: =_xll.EQNXTDZ($A$1,$B15,I$1,$B$1) -> 0 | J15: =_xll.EQNXTDZ($A$1,$B15,J$1,$B$1) -> 0 | ... BV15: =_xll.EQNXTDZ($A$1,$B15,BV$1,$B$1) -> 0
A16: Employee Cost | B16: QTR_EXPLOYEE_COST | C16: =_xll.EQNXTDZ($A$1,$B16,C$1,$B$1) -> 3.281 | D16: =_xll.EQNXTDZ($A$1,$B16,D$1,$B$1) -> 3.231 | E16: =_xll.EQNXTDZ($A$1,$B16,E$1,$B$1) -> 4.403 | F16: =_xll.EQNXTDZ($A$1,$B16,F$1,$B$1) -> 4.234 | G16: =_xll.EQNXTDZ($A$1,$B16,G$1,$B$1) -> 3.719 | H16: =_xll.EQNXTDZ($A$1,$B16,H$1,$B$1) -> 3.837 | I16: =_xll.EQNXTDZ($A$1,$B16,I$1,$B$1) -> 3.664 | J16: =_xll.EQNXTDZ($A$1,$B16,J$1,$B$1) -> 3.954 | ... BV16: =_xll.EQNXTDZ($A$1,$B16,BV$1,$B$1) -> 0
... A42: Consolidated PAT(after extra items) | B42: QTR_CONS_PAT_EXITM | C42: =_xll.EQNXTDZ($A$1,$B42,C$1,$B$1) -> 1.535 | D42: =_xll.EQNXTDZ($A$1,$B42,D$1,$B$1) -> -1.348 | E42: =_xll.EQNXTDZ($A$1,$B42,E$1,$B$1) -> -6.259 | F42: =_xll.EQNXTDZ($A$1,$B42,F$1,$B$1) -> 7.987 | G42: =_xll.EQNXTDZ($A$1,$B42,G$1,$B$1) -> -12.709 | H42: =_xll.EQNXTDZ($A$1,$B42,H$1,$B$1) -> -10.804 | I42: =_xll.EQNXTDZ($A$1,$B42,I$1,$B$1) -> -5.913 | J42: =_xll.EQNXTDZ($A$1,$B42,J$1,$B$1) -> -13.02 | ... BV42: =_xll.EQNXTDZ($A$1,$B42,BV$1,$B$1) -> 0
A44: Field Description | B44: Field Name
A45: Equity Capital | B45: QTR_EQUITY_CAP | C45: =_xll.EQNXTDZ($A$1,$B45,C$1,$B$1) -> 22.431 | D45: =_xll.EQNXTDZ($A$1,$B45,D$1,$B$1) -> 22.431 | E45: =_xll.EQNXTDZ($A$1,$B45,E$1,$B$1) -> 22.431 | F45: =_xll.EQNXTDZ($A$1,$B45,F$1,$B$1) -> 22.431 | G45: =_xll.EQNXTDZ($A$1,$B45,G$1,$B$1) -> 22.431 | H45: =_xll.EQNXTDZ($A$1,$B45,H$1,$B$1) -> 22.431 | I45: =_xll.EQNXTDZ($A$1,$B45,I$1,$B$1) -> 22.431 | J45: =_xll.EQNXTDZ($A$1,$B45,J$1,$B$1) -> 22.431 | ... BV45: =_xll.EQNXTDZ($A$1,$B45,BV$1,$B$1) -> 0
A46: Face Value | B46: QTR_FV | C46: =_xll.EQNXTDZ($A$1,$B46,C$1,$B$1) -> 2 | D46: =_xll.EQNXTDZ($A$1,$B46,D$1,$B$1) -> 2 | E46: =_xll.EQNXTDZ($A$1,$B46,E$1,$B$1) -> 2 | F46: =_xll.EQNXTDZ($A$1,$B46,F$1,$B$1) -> 2 | G46: =_xll.EQNXTDZ($A$1,$B46,G$1,$B$1) -> 2 | H46: =_xll.EQNXTDZ($A$1,$B46,H$1,$B$1) -> 2 | I46: =_xll.EQNXTDZ($A$1,$B46,I$1,$B$1) -> 2 | J46: =_xll.EQNXTDZ($A$1,$B46,J$1,$B$1) -> 2 | ... BV46: =_xll.EQNXTDZ($A$1,$B46,BV$1,$B$1) -> 0
A47: Month End | B47: BMONTH_MONTHEND | C47: =_xll.EQNXTDZ($A$1,$B47,C$5) -> 201206 | D47: =_xll.EQNXTDZ($A$1,$B47,D$5) -> 201209 | E47: =_xll.EQNXTDZ($A$1,$B47,E$5) -> 201212 | F47: =_xll.EQNXTDZ($A$1,$B47,F$5) -> 201303 | G47: =_xll.EQNXTDZ($A$1,$B47,G$5) -> 201306 | H47: =_xll.EQNXTDZ($A$1,$B47,H$5) -> 201309 | I47: =_xll.EQNXTDZ($A$1,$B47,I$5) -> 201312 | J47: =_xll.EQNXTDZ($A$1,$B47,J$5) -> 201403 | ... BV47: =_xll.EQNXTDZ($A$1,$B47,BV$5) -> 0
A48: Close | B48: BMONTH_CLOSE | C48: =_xll.EQNXTDZ($A$1,$B48,C$5) -> 9.975 | D48: =_xll.EQNXTDZ($A$1,$B48,D$5) -> 8.2 | E48: =_xll.EQNXTDZ($A$1,$B48,E$5) -> 8.65 | F48: =_xll.EQNXTDZ($A$1,$B48,F$5) -> 5.99 | G48: =_xll.EQNXTDZ($A$1,$B48,G$5) -> 4.455 | H48: =_xll.EQNXTDZ($A$1,$B48,H$5) -> 8.65 | I48: =_xll.EQNXTDZ($A$1,$B48,I$5) -> 4.96 | J48: =_xll.EQNXTDZ($A$1,$B48,J$5) -> 3.955 | ... BV48: =_xll.EQNXTDZ($A$1,$B48,BV$5) -> 0
A49: Total of Promoter and Promoter Group | B49: SHP_TPFTOTALPROMOTER | C49: =_xll.EQNXTDZ($A$1,$B49,C$5) -> 47.78 | D49: =_xll.EQNXTDZ($A$1,$B49,D$5) -> 51.15 | E49: =_xll.EQNXTDZ($A$1,$B49,E$5) -> 51.15 | F49: =_xll.EQNXTDZ($A$1,$B49,F$5) -> 51.15 | G49: =_xll.EQNXTDZ($A$1,$B49,G$5) -> 52.15 | H49: =_xll.EQNXTDZ($A$1,$B49,H$5) -> 52.38 | I49: =_xll.EQNXTDZ($A$1,$B49,I$5) -> 52.38 | J49: =_xll.EQNXTDZ($A$1,$B49,J$5) -> 53.09 | ... BV49: =_xll.EQNXTDZ($A$1,$B49,BV$5) -> 0
A50: Total of Promoter and Promoter Group Pledged | B50: SHP_PSHFTOTALPROMOTER | C50: =_xll.EQNXTDZ($A$1,$B50,C$5) -> 38.5 | D50: =_xll.EQNXTDZ($A$1,$B50,D$5) -> 35.97 | E50: =_xll.EQNXTDZ($A$1,$B50,E$5) -> 35.97 | F50: =_xll.EQNXTDZ($A$1,$B50,F$5) -> 35.97 | G50: =_xll.EQNXTDZ($A$1,$B50,G$5) -> 35.27 | H50: =_xll.EQNXTDZ($A$1,$B50,H$5) -> 35.12 | I50: =_xll.EQNXTDZ($A$1,$B50,I$5) -> 35.12 | J50: =_xll.EQNXTDZ($A$1,$B50,J$5) -> 34.65 | ... BV50: =_xll.EQNXTDZ($A$1,$B50,BV$5) -> 0
A54: Field Description | B54: Field Name | C54: =_xll.EQNXTDZ($A$1,$B54,C$5) -> 0 | D54: =_xll.EQNXTDZ($A$1,$B54,D$5) -> 0 | E54: =_xll.EQNXTDZ($A$1,$B54,E$5) -> 0 | F54: =_xll.EQNXTDZ($A$1,$B54,F$5) -> 0 | G54: =_xll.EQNXTDZ($A$1,$B54,G$5) -> 0 | H54: =_xll.EQNXTDZ($A$1,$B54,H$5) -> 0 | I54: =_xll.EQNXTDZ($A$1,$B54,I$5) -> 0 | J54: =_xll.EQNXTDZ($A$1,$B54,J$5) -> 0 | ... BV54: =_xll.EQNXTDZ($A$1,$B54,BV$5) -> 0
A55: Year End | B55: QTRB_DATE_END | C55: =_xll.EQNXTDZ($A$1,$B55,C$5,$B$1) -> 0 | D55: =_xll.EQNXTDZ($A$1,$B55,D$5,$B$1) -> 201209 | E55: =_xll.EQNXTDZ($A$1,$B55,E$5,$B$1) -> 0 | F55: =_xll.EQNXTDZ($A$1,$B55,F$5,$B$1) -> 201303 | G55: =_xll.EQNXTDZ($A$1,$B55,G$5,$B$1) -> 0 | H55: =_xll.EQNXTDZ($A$1,$B55,H$5,$B$1) -> 201309 | I55: =_xll.EQNXTDZ($A$1,$B55,I$5,$B$1) -> 0 | J55: =_xll.EQNXTDZ($A$1,$B55,J$5,$B$1) -> 201403 | ... BV55: =_xll.EQNXTDZ($A$1,$B55,BV$5,$B$1) -> 0
A56: Share Capital | B56: QTRB_SHARE_CAPITAL | C56: =_xll.EQNXTDZ($A$1,$B56,C$5,$B$1) -> 0 | D56: =_xll.EQNXTDZ($A$1,$B56,D$5,$B$1) -> 22.431 | E56: =_xll.EQNXTDZ($A$1,$B56,E$5,$B$1) -> 0 | F56: =_xll.EQNXTDZ($A$1,$B56,F$5,$B$1) -> 22.431 | G56: =_xll.EQNXTDZ($A$1,$B56,G$5,$B$1) -> 0 | H56: =_xll.EQNXTDZ($A$1,$B56,H$5,$B$1) -> 22.431 | I56: =_xll.EQNXTDZ($A$1,$B56,I$5,$B$1) -> 0 | J56: =_xll.EQNXTDZ($A$1,$B56,J$5,$B$1) -> 22.431 | ... BV56: =_xll.EQNXTDZ($A$1,$B56,BV$5,$B$1) -> 0
A57: Share Warrants & outstandings | B57: QTRB_SHAREWARNDOUT | C57: =_xll.EQNXTDZ($A$1,$B57,C$5,$B$1) -> 0 | D57: =_xll.EQNXTDZ($A$1,$B57,D$5,$B$1) -> 0 | E57: =_xll.EQNXTDZ($A$1,$B57,E$5,$B$1) -> 0 | F57: =_xll.EQNXTDZ($A$1,$B57,F$5,$B$1) -> 0 | G57: =_xll.EQNXTDZ($A$1,$B57,G$5,$B$1) -> 0 | H57: =_xll.EQNXTDZ($A$1,$B57,H$5,$B$1) -> 0 | I57: =_xll.EQNXTDZ($A$1,$B57,I$5,$B$1) -> 0 | J57: =_xll.EQNXTDZ($A$1,$B57,J$5,$B$1) -> 0 | ... BV57: =_xll.EQNXTDZ($A$1,$B57,BV$5,$B$1) -> 0
A58: Reserves & Surplus | B58: QTRB_RESERVE | C58: =_xll.EQNXTDZ($A$1,$B58,C$5,$B$1) -> 0 | D58: =_xll.EQNXTDZ($A$1,$B58,D$5,$B$1) -> 100.69 | E58: =_xll.EQNXTDZ($A$1,$B58,E$5,$B$1) -> 0 | F58: =_xll.EQNXTDZ($A$1,$B58,F$5,$B$1) -> 102.418 | G58: =_xll.EQNXTDZ($A$1,$B58,G$5,$B$1) -> 0 | H58: =_xll.EQNXTDZ($A$1,$B58,H$5,$B$1) -> 78.906 | I58: =_xll.EQNXTDZ($A$1,$B58,I$5,$B$1) -> 0 | J58: =_xll.EQNXTDZ($A$1,$B58,J$5,$B$1) -> 59.973 | ... BV58: =_xll.EQNXTDZ($A$1,$B58,BV$5,$B$1) -> 0
A59: Shareholder's Funds | B59: QTRB_SHAREHODERS_FUNDS | C59: =_xll.EQNXTDZ($A$1,$B59,C$5,$B$1) -> 0 | D59: =_xll.EQNXTDZ($A$1,$B59,D$5,$B$1) -> 123.121 | E59: =_xll.EQNXTDZ($A$1,$B59,E$5,$B$1) -> 0 | F59: =_xll.EQNXTDZ($A$1,$B59,F$5,$B$1) -> 124.849 | G59: =_xll.EQNXTDZ($A$1,$B59,G$5,$B$1) -> 0 | H59: =_xll.EQNXTDZ($A$1,$B59,H$5,$B$1) -> 101.337 | I59: =_xll.EQNXTDZ($A$1,$B59,I$5,$B$1) -> 0 | J59: =_xll.EQNXTDZ($A$1,$B59,J$5,$B$1) -> 82.404 | ... BV59: =_xll.EQNXTDZ($A$1,$B59,BV$5,$B$1) -> 0
A60: Minority Interest | B60: QTRB_MINORITY_INTEREST_BS | C60: =_xll.EQNXTDZ($A$1,$B60,C$5,$B$1) -> 0 | D60: =_xll.EQNXTDZ($A$1,$B60,D$5,$B$1) -> 0 | E60: =_xll.EQNXTDZ($A$1,$B60,E$5,$B$1) -> 0 | F60: =_xll.EQNXTDZ($A$1,$B60,F$5,$B$1) -> 0 | G60: =_xll.EQNXTDZ($A$1,$B60,G$5,$B$1) -> 0 | H60: =_xll.EQNXTDZ($A$1,$B60,H$5,$B$1) -> 0 | I60: =_xll.EQNXTDZ($A$1,$B60,I$5,$B$1) -> 0 | J60: =_xll.EQNXTDZ($A$1,$B60,J$5,$B$1) -> 0 | ... BV60: =_xll.EQNXTDZ($A$1,$B60,BV$5,$B$1) -> 0
A61: Long Term Borrowings | B61: QTRB_TOTAL_DEBTS | C61: =_xll.EQNXTDZ($A$1,$B61,C$5,$B$1) -> 0 | D61: =_xll.EQNXTDZ($A$1,$B61,D$5,$B$1) -> 26.697 | E61: =_xll.EQNXTDZ($A$1,$B61,E$5,$B$1) -> 0 | F61: =_xll.EQNXTDZ($A$1,$B61,F$5,$B$1) -> 20.585 | G61: =_xll.EQNXTDZ($A$1,$B61,G$5,$B$1) -> 0 | H61: =_xll.EQNXTDZ($A$1,$B61,H$5,$B$1) -> 18.124 | I61: =_xll.EQNXTDZ($A$1,$B61,I$5,$B$1) -> 0 | J61: =_xll.EQNXTDZ($A$1,$B61,J$5,$B$1) -> 15.663 | ... BV61: =_xll.EQNXTDZ($A$1,$B61,BV$5,$B$1) -> 0
A62: Secured Loans | B62: QTRB_SECURED_LOANS | C62: =_xll.EQNXTDZ($A$1,$B62,C$5,$B$1) -> 0 | D62: =_xll.EQNXTDZ($A$1,$B62,D$5,$B$1) -> 0 | E62: =_xll.EQNXTDZ($A$1,$B62,E$5,$B$1) -> 0 | F62: =_xll.EQNXTDZ($A$1,$B62,F$5,$B$1) -> 0 | G62: =_xll.EQNXTDZ($A$1,$B62,G$5,$B$1) -> 0 | H62: =_xll.EQNXTDZ($A$1,$B62,H$5,$B$1) -> 0 | I62: =_xll.EQNXTDZ($A$1,$B62,I$5,$B$1) -> 0 | J62: =_xll.EQNXTDZ($A$1,$B62,J$5,$B$1) -> 0 | ... BV62: =_xll.EQNXTDZ($A$1,$B62,BV$5,$B$1) -> 0
A63: Unsecured Loans | B63: QTRB_UNSECURED_LOANS_NF | C63: =_xll.EQNXTDZ($A$1,$B63,C$5,$B$1) -> 0 | D63: =_xll.EQNXTDZ($A$1,$B63,D$5,$B$1) -> 26.697 | E63: =_xll.EQNXTDZ($A$1,$B63,E$5,$B$1) -> 0 | F63: =_xll.EQNXTDZ($A$1,$B63,F$5,$B$1) -> 20.585 | G63: =_xll.EQNXTDZ($A$1,$B63,G$5,$B$1) -> 0 | H63: =_xll.EQNXTDZ($A$1,$B63,H$5,$B$1) -> 18.124 | I63: =_xll.EQNXTDZ($A$1,$B63,I$5,$B$1) -> 0 | J63: =_xll.EQNXTDZ($A$1,$B63,J$5,$B$1) -> 15.663 | ... BV63: =_xll.EQNXTDZ($A$1,$B63,BV$5,$B$1) -> 0
A64: Other Long Term Liabilities | B64: QTRB_OTHER_LT_LIABILITIES | C64: =_xll.EQNXTDZ($A$1,$B64,C$5,$B$1) -> 0 | D64: =_xll.EQNXTDZ($A$1,$B64,D$5,$B$1) -> 0 | E64: =_xll.EQNXTDZ($A$1,$B64,E$5,$B$1) -> 0 | F64: =_xll.EQNXTDZ($A$1,$B64,F$5,$B$1) -> 0 | G64: =_xll.EQNXTDZ($A$1,$B64,G$5,$B$1) -> 0 | H64: =_xll.EQNXTDZ($A$1,$B64,H$5,$B$1) -> 0 | I64: =_xll.EQNXTDZ($A$1,$B64,I$5,$B$1) -> 0 | J64: =_xll.EQNXTDZ($A$1,$B64,J$5,$B$1) -> 158.995 | ... BV64: =_xll.EQNXTDZ($A$1,$B64,BV$5,$B$1) -> 0
A65: Long Term Trade Payables | B65: QTRB_LT_TRADE_PAYABLE | C65: =_xll.EQNXTDZ($A$1,$B65,C$5,$B$1) -> 0 | D65: =_xll.EQNXTDZ($A$1,$B65,D$5,$B$1) -> 0 | E65: =_xll.EQNXTDZ($A$1,$B65,E$5,$B$1) -> 0 | F65: =_xll.EQNXTDZ($A$1,$B65,F$5,$B$1) -> 0 | G65: =_xll.EQNXTDZ($A$1,$B65,G$5,$B$1) -> 0 | H65: =_xll.EQNXTDZ($A$1,$B65,H$5,$B$1) -> 0 | I65: =_xll.EQNXTDZ($A$1,$B65,I$5,$B$1) -> 0 | J65: =_xll.EQNXTDZ($A$1,$B65,J$5,$B$1) -> 0 | ... BV65: =_xll.EQNXTDZ($A$1,$B65,BV$5,$B$1) -> 0
A66: Lont Term Provisions | B66: QTRB_LT_PROVISIONS | C66: =_xll.EQNXTDZ($A$1,$B66,C$5,$B$1) -> 0 | D66: =_xll.EQNXTDZ($A$1,$B66,D$5,$B$1) -> 3.209 | E66: =_xll.EQNXTDZ($A$1,$B66,E$5,$B$1) -> 0 | F66: =_xll.EQNXTDZ($A$1,$B66,F$5,$B$1) -> 3.189 | G66: =_xll.EQNXTDZ($A$1,$B66,G$5,$B$1) -> 0 | H66: =_xll.EQNXTDZ($A$1,$B66,H$5,$B$1) -> 3.325 | I66: =_xll.EQNXTDZ($A$1,$B66,I$5,$B$1) -> 0 | J66: =_xll.EQNXTDZ($A$1,$B66,J$5,$B$1) -> 3.551 | ... BV66: =_xll.EQNXTDZ($A$1,$B66,BV$5,$B$1) -> 0
... A97: Total Assets | B97: QTRB_TOTAL_APPLICATIONS | C97: =_xll.EQNXTDZ($A$1,$B97,C$5,$B$1) -> 0 | D97: =_xll.EQNXTDZ($A$1,$B97,D$5,$B$1) -> 153.027 | E97: =_xll.EQNXTDZ($A$1,$B97,E$5,$B$1) -> 0 | F97: =_xll.EQNXTDZ($A$1,$B97,F$5,$B$1) -> 148.623 | G97: =_xll.EQNXTDZ($A$1,$B97,G$5,$B$1) -> 0 | H97: =_xll.EQNXTDZ($A$1,$B97,H$5,$B$1) -> 122.786 | I97: =_xll.EQNXTDZ($A$1,$B97,I$5,$B$1) -> 0 | J97: =_xll.EQNXTDZ($A$1,$B97,J$5,$B$1) -> 260.613 | ... BV97: =_xll.EQNXTDZ($A$1,$B97,BV$5,$B$1) -> 0

Sheet Annual Raw
A1: 112455 | B1: X | C1: 200103 | D1: 200203 | E1: 200303 | F1: 200403 | G1: 200503 | H1: 200603 | I1: 200703 | J1: 200803 | K1: 200903 | L1: 201003 | M1: 201103 | N1: 201203 | O1: 201303 | P1: 201403 | Q1: 201503 | R1: 201603 | S1: 201703 | T1: 201803 | U1: 201903 | V1: 202003 | W1: 202103 | X1: 202203 | Y1: 202303 | Z1: 202403 | AA1: 202503 | AB1: 202603 | AC1: 202703 | AD1: 202803 | AE1: 202903 | AF1: 203003
A3: Field Description | B3: Field Name
A4: Company Name | B4: CD_COMPNAME | C4: =_xll.EQNXTDZ(A1,B4,"L") -> Lloyds Metals & Energy Ltd.
A5: Year End | B5: PL_YEAR_END | C5: =_xll.EQNXTDZ($A$1,$B5,C$1,$B$1) -> 200103 | D5: =_xll.EQNXTDZ($A$1,$B5,D$1,$B$1) -> 200203 | E5: =_xll.EQNXTDZ($A$1,$B5,E$1,$B$1) -> 200303 | F5: =_xll.EQNXTDZ($A$1,$B5,F$1,$B$1) -> 200403 | G5: =_xll.EQNXTDZ($A$1,$B5,G$1,$B$1) -> 200503 | H5: =_xll.EQNXTDZ($A$1,$B5,H$1,$B$1) -> 200603 | I5: =_xll.EQNXTDZ($A$1,$B5,I$1,$B$1) -> 200703 | J5: =_xll.EQNXTDZ($A$1,$B5,J$1,$B$1) -> 200803 | ... AF5: =_xll.EQNXTDZ($A$1,$B5,AF$1,$B$1) -> 0
A6: Sales Turnover | B6: PL_TOTAL_GROSS_SALES | C6: =_xll.EQNXTDZ($A$1,$B6,C$1,$B$1) -> 114.754 | D6: =_xll.EQNXTDZ($A$1,$B6,D$1,$B$1) -> 117.1898 | E6: =_xll.EQNXTDZ($A$1,$B6,E$1,$B$1) -> 169.7335 | F6: =_xll.EQNXTDZ($A$1,$B6,F$1,$B$1) -> 198.8392 | G6: =_xll.EQNXTDZ($A$1,$B6,G$1,$B$1) -> 281.165 | H6: =_xll.EQNXTDZ($A$1,$B6,H$1,$B$1) -> 295.0468 | I6: =_xll.EQNXTDZ($A$1,$B6,I$1,$B$1) -> 336.6405 | J6: =_xll.EQNXTDZ($A$1,$B6,J$1,$B$1) -> 381.998 | ... AF6: =_xll.EQNXTDZ($A$1,$B6,AF$1,$B$1) -> 0
A7: Less: Inter divisional transfers | B7: PL_INTER_DIV_TRF | C7: =_xll.EQNXTDZ($A$1,$B7,C$1,$B$1) -> 0 | D7: =_xll.EQNXTDZ($A$1,$B7,D$1,$B$1) -> 0 | E7: =_xll.EQNXTDZ($A$1,$B7,E$1,$B$1) -> 0 | F7: =_xll.EQNXTDZ($A$1,$B7,F$1,$B$1) -> 0 | G7: =_xll.EQNXTDZ($A$1,$B7,G$1,$B$1) -> 0 | H7: =_xll.EQNXTDZ($A$1,$B7,H$1,$B$1) -> 0 | I7: =_xll.EQNXTDZ($A$1,$B7,I$1,$B$1) -> 0 | J7: =_xll.EQNXTDZ($A$1,$B7,J$1,$B$1) -> 0 | ... AF7: =_xll.EQNXTDZ($A$1,$B7,AF$1,$B$1) -> 0
A8: Less: Sales Returns | B8: PL_SALES_RETURN | C8: =_xll.EQNXTDZ($A$1,$B8,C$1,$B$1) -> 0 | D8: =_xll.EQNXTDZ($A$1,$B8,D$1,$B$1) -> 0 | E8: =_xll.EQNXTDZ($A$1,$B8,E$1,$B$1) -> 0 | F8: =_xll.EQNXTDZ($A$1,$B8,F$1,$B$1) -> 0 | G8: =_xll.EQNXTDZ($A$1,$B8,G$1,$B$1) -> 0 | H8: =_xll.EQNXTDZ($A$1,$B8,H$1,$B$1) -> 0 | I8: =_xll.EQNXTDZ($A$1,$B8,I$1,$B$1) -> 0 | J8: =_xll.EQNXTDZ($A$1,$B8,J$1,$B$1) -> 0 | ... AF8: =_xll.EQNXTDZ($A$1,$B8,AF$1,$B$1) -> 0
A9: Less: Excise | B9: PL_EXCISE | C9: =_xll.EQNXTDZ($A$1,$B9,C$1,$B$1) -> 12.6164 | D9: =_xll.EQNXTDZ($A$1,$B9,D$1,$B$1) -> 11.2066 | E9: =_xll.EQNXTDZ($A$1,$B9,E$1,$B$1) -> 19.686 | F9: =_xll.EQNXTDZ($A$1,$B9,F$1,$B$1) -> 23.016 | G9: =_xll.EQNXTDZ($A$1,$B9,G$1,$B$1) -> 23.548 | H9: =_xll.EQNXTDZ($A$1,$B9,H$1,$B$1) -> 41.0368 | I9: =_xll.EQNXTDZ($A$1,$B9,I$1,$B$1) -> 0 | J9: =_xll.EQNXTDZ($A$1,$B9,J$1,$B$1) -> 0 | ... AF9: =_xll.EQNXTDZ($A$1,$B9,AF$1,$B$1) -> 0
A10: Net Sales | B10: PL_NET_SALES | C10: =_xll.EQNXTDZ($A$1,$B10,C$1,$B$1) -> 102.1376 | D10: =_xll.EQNXTDZ($A$1,$B10,D$1,$B$1) -> 105.9832 | E10: =_xll.EQNXTDZ($A$1,$B10,E$1,$B$1) -> 150.0475 | F10: =_xll.EQNXTDZ($A$1,$B10,F$1,$B$1) -> 175.8232 | G10: =_xll.EQNXTDZ($A$1,$B10,G$1,$B$1) -> 257.617 | H10: =_xll.EQNXTDZ($A$1,$B10,H$1,$B$1) -> 254.01 | I10: =_xll.EQNXTDZ($A$1,$B10,I$1,$B$1) -> 336.6405 | J10: =_xll.EQNXTDZ($A$1,$B10,J$1,$B$1) -> 381.998 | ... AF10: =_xll.EQNXTDZ($A$1,$B10,AF$1,$B$1) -> 0
A11: Increase/Decrease in Stock | B11: PL_INC_DEC_INVENTORY | C11: =_xll.EQNXTDZ($A$1,$B11,C$1,$B$1) -> -0.876 | D11: =_xll.EQNXTDZ($A$1,$B11,D$1,$B$1) -> 0.8327 | E11: =_xll.EQNXTDZ($A$1,$B11,E$1,$B$1) -> -1.1713 | F11: =_xll.EQNXTDZ($A$1,$B11,F$1,$B$1) -> -4.0017 | G11: =_xll.EQNXTDZ($A$1,$B11,G$1,$B$1) -> 6.6035 | H11: =_xll.EQNXTDZ($A$1,$B11,H$1,$B$1) -> -21.5463 | I11: =_xll.EQNXTDZ($A$1,$B11,I$1,$B$1) -> 62.954 | J11: =_xll.EQNXTDZ($A$1,$B11,J$1,$B$1) -> 35.1021 | ... AF11: =_xll.EQNXTDZ($A$1,$B11,AF$1,$B$1) -> 0
A12: Raw Material Consumed | B12: PL_RAW_MATRS_CONSUMED | C12: =_xll.EQNXTDZ($A$1,$B12,C$1,$B$1) -> 76.1407 | D12: =_xll.EQNXTDZ($A$1,$B12,D$1,$B$1) -> 79.6914 | E12: =_xll.EQNXTDZ($A$1,$B12,E$1,$B$1) -> 110.4087 | F12: =_xll.EQNXTDZ($A$1,$B12,F$1,$B$1) -> 128.3885 | G12: =_xll.EQNXTDZ($A$1,$B12,G$1,$B$1) -> 179.9905 | H12: =_xll.EQNXTDZ($A$1,$B12,H$1,$B$1) -> 224.977 | I12: =_xll.EQNXTDZ($A$1,$B12,I$1,$B$1) -> 222.043 | J12: =_xll.EQNXTDZ($A$1,$B12,J$1,$B$1) -> 267.9909 | ... AF12: =_xll.EQNXTDZ($A$1,$B12,AF$1,$B$1) -> 0
A13: Power & Fuel Cost | B13: PL_POWER_FUEL | C13: =_xll.EQNXTDZ($A$1,$B13,C$1,$B$1) -> 5.8522 | D13: =_xll.EQNXTDZ($A$1,$B13,D$1,$B$1) -> 5.3826 | E13: =_xll.EQNXTDZ($A$1,$B13,E$1,$B$1) -> 5.5084 | F13: =_xll.EQNXTDZ($A$1,$B13,F$1,$B$1) -> 5.4717 | G13: =_xll.EQNXTDZ($A$1,$B13,G$1,$B$1) -> 5.7165 | H13: =_xll.EQNXTDZ($A$1,$B13,H$1,$B$1) -> 6.2518 | I13: =_xll.EQNXTDZ($A$1,$B13,I$1,$B$1) -> 10.4088 | J13: =_xll.EQNXTDZ($A$1,$B13,J$1,$B$1) -> 10.6621 | ... AF13: =_xll.EQNXTDZ($A$1,$B13,AF$1,$B$1) -> 0
A14: Employee Cost | B14: PL_EMPLOYEES | C14: =_xll.EQNXTDZ($A$1,$B14,C$1,$B$1) -> 4.1956 | D14: =_xll.EQNXTDZ($A$1,$B14,D$1,$B$1) -> 3.6184 | E14: =_xll.EQNXTDZ($A$1,$B14,E$1,$B$1) -> 4.1629 | F14: =_xll.EQNXTDZ($A$1,$B14,F$1,$B$1) -> 4.8744 | G14: =_xll.EQNXTDZ($A$1,$B14,G$1,$B$1) -> 5.0217 | H14: =_xll.EQNXTDZ($A$1,$B14,H$1,$B$1) -> 7.4762 | I14: =_xll.EQNXTDZ($A$1,$B14,I$1,$B$1) -> 8.0661 | J14: =_xll.EQNXTDZ($A$1,$B14,J$1,$B$1) -> 8.3048 | ... AF14: =_xll.EQNXTDZ($A$1,$B14,AF$1,$B$1) -> 0
A15: Operating & Manufacturing Expenses | B15: PL_GEN_OTHER_MFG_EXPS | C15: =_xll.EQNXTDZ($A$1,$B15,C$1,$B$1) -> 4.36 | D15: =_xll.EQNXTDZ($A$1,$B15,D$1,$B$1) -> 4.8002 | E15: =_xll.EQNXTDZ($A$1,$B15,E$1,$B$1) -> 6.796 | F15: =_xll.EQNXTDZ($A$1,$B15,F$1,$B$1) -> 6.7952 | G15: =_xll.EQNXTDZ($A$1,$B15,G$1,$B$1) -> 13.9955 | H15: =_xll.EQNXTDZ($A$1,$B15,H$1,$B$1) -> 13.1343 | I15: =_xll.EQNXTDZ($A$1,$B15,I$1,$B$1) -> 12.4647 | J15: =_xll.EQNXTDZ($A$1,$B15,J$1,$B$1) -> 14.8685 | ... AF15: =_xll.EQNXTDZ($A$1,$B15,AF$1,$B$1) -> 0
A16: Cost of Software development | B16: PL_COST_SW | C16: =_xll.EQNXTDZ($A$1,$B16,C$1,$B$1) -> 0 | D16: =_xll.EQNXTDZ($A$1,$B16,D$1,$B$1) -> 0 | E16: =_xll.EQNXTDZ($A$1,$B16,E$1,$B$1) -> 0 | F16: =_xll.EQNXTDZ($A$1,$B16,F$1,$B$1) -> 0 | G16: =_xll.EQNXTDZ($A$1,$B16,G$1,$B$1) -> 0 | H16: =_xll.EQNXTDZ($A$1,$B16,H$1,$B$1) -> 0 | I16: =_xll.EQNXTDZ($A$1,$B16,I$1,$B$1) -> 0 | J16: =_xll.EQNXTDZ($A$1,$B16,J$1,$B$1) -> 0 | ... AF16: =_xll.EQNXTDZ($A$1,$B16,AF$1,$B$1) -> 0
... A36: Profit After Tax from Discontinued Operations | B36: PL_PAT_DIS_OP | C36: =_xll.EQNXTDZ($A$1,$B36,C$1,$B$1) -> 0 | D36: =_xll.EQNXTDZ($A$1,$B36,D$1,$B$1) -> 0 | E36: =_xll.EQNXTDZ($A$1,$B36,E$1,$B$1) -> 0 | F36: =_xll.EQNXTDZ($A$1,$B36,F$1,$B$1) -> 0 | G36: =_xll.EQNXTDZ($A$1,$B36,G$1,$B$1) -> 0 | H36: =_xll.EQNXTDZ($A$1,$B36,H$1,$B$1) -> 0 | I36: =_xll.EQNXTDZ($A$1,$B36,I$1,$B$1) -> 0 | J36: =_xll.EQNXTDZ($A$1,$B36,J$1,$B$1) -> 0 | ... AF36: =_xll.EQNXTDZ($A$1,$B36,AF$1,$B$1) -> 0
A39: Field Description | B39: Field Name
A40: Year End | B40: BS_YEAR_END | C40: =_xll.EQNXTDZ($A$1,$B40,C$1,$B$1) -> 200103 | D40: =_xll.EQNXTDZ($A$1,$B40,D$1,$B$1) -> 200203 | E40: =_xll.EQNXTDZ($A$1,$B40,E$1,$B$1) -> 200303 | F40: =_xll.EQNXTDZ($A$1,$B40,F$1,$B$1) -> 200403 | G40: =_xll.EQNXTDZ($A$1,$B40,G$1,$B$1) -> 200503 | H40: =_xll.EQNXTDZ($A$1,$B40,H$1,$B$1) -> 200603 | I40: =_xll.EQNXTDZ($A$1,$B40,I$1,$B$1) -> 200703 | J40: =_xll.EQNXTDZ($A$1,$B40,J$1,$B$1) -> 200803 | ... AF40: =_xll.EQNXTDZ($A$1,$B40,AF$1,$B$1) -> 0
A41: Share Capital | B41: BS_SHARE_CAPITAL | C41: =_xll.EQNXTDZ($A$1,$B41,C$1,$B$1) -> 39.4305 | D41: =_xll.EQNXTDZ($A$1,$B41,D$1,$B$1) -> 39.4305 | E41: =_xll.EQNXTDZ($A$1,$B41,E$1,$B$1) -> 39.4305 | F41: =_xll.EQNXTDZ($A$1,$B41,F$1,$B$1) -> 39.4305 | G41: =_xll.EQNXTDZ($A$1,$B41,G$1,$B$1) -> 39.4305 | H41: =_xll.EQNXTDZ($A$1,$B41,H$1,$B$1) -> 39.4305 | I41: =_xll.EQNXTDZ($A$1,$B41,I$1,$B$1) -> 21.4305 | J41: =_xll.EQNXTDZ($A$1,$B41,J$1,$B$1) -> 22.4305 | ... AF41: =_xll.EQNXTDZ($A$1,$B41,AF$1,$B$1) -> 0
A42: Share Warrants & Outstandings | B42: BS_SHAREWROUTST | C42: =_xll.EQNXTDZ($A$1,$B42,C$1,$B$1) -> 0 | D42: =_xll.EQNXTDZ($A$1,$B42,D$1,$B$1) -> 0 | E42: =_xll.EQNXTDZ($A$1,$B42,E$1,$B$1) -> 0 | F42: =_xll.EQNXTDZ($A$1,$B42,F$1,$B$1) -> 0 | G42: =_xll.EQNXTDZ($A$1,$B42,G$1,$B$1) -> 0 | H42: =_xll.EQNXTDZ($A$1,$B42,H$1,$B$1) -> 0 | I42: =_xll.EQNXTDZ($A$1,$B42,I$1,$B$1) -> 0 | J42: =_xll.EQNXTDZ($A$1,$B42,J$1,$B$1) -> 0 | ... AF42: =_xll.EQNXTDZ($A$1,$B42,AF$1,$B$1) -> 0
A43: Total Reserves | B43: BS_RESERVE | C43: =_xll.EQNXTDZ($A$1,$B43,C$1,$B$1) -> -28.3366 | D43: =_xll.EQNXTDZ($A$1,$B43,D$1,$B$1) -> -114.6459 | E43: =_xll.EQNXTDZ($A$1,$B43,E$1,$B$1) -> -147.4108 | F43: =_xll.EQNXTDZ($A$1,$B43,F$1,$B$1) -> -148.2136 | G43: =_xll.EQNXTDZ($A$1,$B43,G$1,$B$1) -> -118.6306 | H43: =_xll.EQNXTDZ($A$1,$B43,H$1,$B$1) -> -53.9715 | I43: =_xll.EQNXTDZ($A$1,$B43,I$1,$B$1) -> -65.9696 | J43: =_xll.EQNXTDZ($A$1,$B43,J$1,$B$1) -> -24.0726 | ... AF43: =_xll.EQNXTDZ($A$1,$B43,AF$1,$B$1) -> 0
A44: Shareholder's Funds | B44: BS_SHAREHODERS_FUNDS | C44: =_xll.EQNXTDZ($A$1,$B44,C$1,$B$1) -> 11.0939 | D44: =_xll.EQNXTDZ($A$1,$B44,D$1,$B$1) -> -75.2154 | E44: =_xll.EQNXTDZ($A$1,$B44,E$1,$B$1) -> -107.9803 | F44: =_xll.EQNXTDZ($A$1,$B44,F$1,$B$1) -> -108.7831 | G44: =_xll.EQNXTDZ($A$1,$B44,G$1,$B$1) -> -79.2001 | H44: =_xll.EQNXTDZ($A$1,$B44,H$1,$B$1) -> -14.541 | I44: =_xll.EQNXTDZ($A$1,$B44,I$1,$B$1) -> -44.5391 | J44: =_xll.EQNXTDZ($A$1,$B44,J$1,$B$1) -> -1.6421 | ... AF44: =_xll.EQNXTDZ($A$1,$B44,AF$1,$B$1) -> 0
A45: Minority Interest | B45: BS_MINORITY_INTEREST | C45: =_xll.EQNXTDZ($A$1,$B45,C$1,$B$1) -> 0 | D45: =_xll.EQNXTDZ($A$1,$B45,D$1,$B$1) -> 0 | E45: =_xll.EQNXTDZ($A$1,$B45,E$1,$B$1) -> 0 | F45: =_xll.EQNXTDZ($A$1,$B45,F$1,$B$1) -> 0 | G45: =_xll.EQNXTDZ($A$1,$B45,G$1,$B$1) -> 0 | H45: =_xll.EQNXTDZ($A$1,$B45,H$1,$B$1) -> 0 | I45: =_xll.EQNXTDZ($A$1,$B45,I$1,$B$1) -> 0 | J45: =_xll.EQNXTDZ($A$1,$B45,J$1,$B$1) -> 0 | ... AF45: =_xll.EQNXTDZ($A$1,$B45,AF$1,$B$1) -> 0
A46: Long-Term Borrowings | B46: BS_LTRM_BORROWING | C46: =_xll.EQNXTDZ($A$1,$B46,C$1,$B$1) -> 0 | D46: =_xll.EQNXTDZ($A$1,$B46,D$1,$B$1) -> 0 | E46: =_xll.EQNXTDZ($A$1,$B46,E$1,$B$1) -> 0 | F46: =_xll.EQNXTDZ($A$1,$B46,F$1,$B$1) -> 0 | G46: =_xll.EQNXTDZ($A$1,$B46,G$1,$B$1) -> 0 | H46: =_xll.EQNXTDZ($A$1,$B46,H$1,$B$1) -> 0 | I46: =_xll.EQNXTDZ($A$1,$B46,I$1,$B$1) -> 0 | J46: =_xll.EQNXTDZ($A$1,$B46,J$1,$B$1) -> 0 | ... AF46: =_xll.EQNXTDZ($A$1,$B46,AF$1,$B$1) -> 0
A47: Secured Loans | B47: BS_SECURED_LOANS | C47: =_xll.EQNXTDZ($A$1,$B47,C$1,$B$1) -> 361.2153 | D47: =_xll.EQNXTDZ($A$1,$B47,D$1,$B$1) -> 454.9876 | E47: =_xll.EQNXTDZ($A$1,$B47,E$1,$B$1) -> 478.0315 | F47: =_xll.EQNXTDZ($A$1,$B47,F$1,$B$1) -> 458.1041 | G47: =_xll.EQNXTDZ($A$1,$B47,G$1,$B$1) -> 305.8907 | H47: =_xll.EQNXTDZ($A$1,$B47,H$1,$B$1) -> 205.8685 | I47: =_xll.EQNXTDZ($A$1,$B47,I$1,$B$1) -> 188.5858 | J47: =_xll.EQNXTDZ($A$1,$B47,J$1,$B$1) -> 124.3943 | ... AF47: =_xll.EQNXTDZ($A$1,$B47,AF$1,$B$1) -> 0
A48: Unsecured Loans | B48: BS_UNSECURED_LOANS_NF | C48: =_xll.EQNXTDZ($A$1,$B48,C$1,$B$1) -> 43.743 | D48: =_xll.EQNXTDZ($A$1,$B48,D$1,$B$1) -> 23.8875 | E48: =_xll.EQNXTDZ($A$1,$B48,E$1,$B$1) -> 28.9392 | F48: =_xll.EQNXTDZ($A$1,$B48,F$1,$B$1) -> 27.6357 | G48: =_xll.EQNXTDZ($A$1,$B48,G$1,$B$1) -> 4.5074 | H48: =_xll.EQNXTDZ($A$1,$B48,H$1,$B$1) -> 4.5074 | I48: =_xll.EQNXTDZ($A$1,$B48,I$1,$B$1) -> 4.4951 | J48: =_xll.EQNXTDZ($A$1,$B48,J$1,$B$1) -> 10.7434 | ... AF48: =_xll.EQNXTDZ($A$1,$B48,AF$1,$B$1) -> 0
A49: Deferred Tax Assets / Liabilities | B49: BS_NET_DEF_TAX_NF | C49: =_xll.EQNXTDZ($A$1,$B49,C$1,$B$1) -> 0 | D49: =_xll.EQNXTDZ($A$1,$B49,D$1,$B$1) -> 0 | E49: =_xll.EQNXTDZ($A$1,$B49,E$1,$B$1) -> 0 | F49: =_xll.EQNXTDZ($A$1,$B49,F$1,$B$1) -> 0 | G49: =_xll.EQNXTDZ($A$1,$B49,G$1,$B$1) -> 0 | H49: =_xll.EQNXTDZ($A$1,$B49,H$1,$B$1) -> 0 | I49: =_xll.EQNXTDZ($A$1,$B49,I$1,$B$1) -> 0 | J49: =_xll.EQNXTDZ($A$1,$B49,J$1,$B$1) -> 0 | ... AF49: =_xll.EQNXTDZ($A$1,$B49,AF$1,$B$1) -> 0
A50: Other Long Term Liabilities | B50: BS_OTH_LT_LIAB | C50: =_xll.EQNXTDZ($A$1,$B50,C$1,$B$1) -> 0 | D50: =_xll.EQNXTDZ($A$1,$B50,D$1,$B$1) -> 0 | E50: =_xll.EQNXTDZ($A$1,$B50,E$1,$B$1) -> 0 | F50: =_xll.EQNXTDZ($A$1,$B50,F$1,$B$1) -> 0 | G50: =_xll.EQNXTDZ($A$1,$B50,G$1,$B$1) -> 0 | H50: =_xll.EQNXTDZ($A$1,$B50,H$1,$B$1) -> 0 | I50: =_xll.EQNXTDZ($A$1,$B50,I$1,$B$1) -> 0 | J50: =_xll.EQNXTDZ($A$1,$B50,J$1,$B$1) -> 0 | ... AF50: =_xll.EQNXTDZ($A$1,$B50,AF$1,$B$1) -> 0
A51: Long Term Trade Payables | B51: BS_LT_TRADE_PAYABLES | C51: =_xll.EQNXTDZ($A$1,$B51,C$1,$B$1) -> 0 | D51: =_xll.EQNXTDZ($A$1,$B51,D$1,$B$1) -> 0 | E51: =_xll.EQNXTDZ($A$1,$B51,E$1,$B$1) -> 0 | F51: =_xll.EQNXTDZ($A$1,$B51,F$1,$B$1) -> 0 | G51: =_xll.EQNXTDZ($A$1,$B51,G$1,$B$1) -> 0 | H51: =_xll.EQNXTDZ($A$1,$B51,H$1,$B$1) -> 0 | I51: =_xll.EQNXTDZ($A$1,$B51,I$1,$B$1) -> 0 | J51: =_xll.EQNXTDZ($A$1,$B51,J$1,$B$1) -> 0 | ... AF51: =_xll.EQNXTDZ($A$1,$B51,AF$1,$B$1) -> 0
... A99: Estimated Capital Contracts Remaining | B99: BS_ESTIMATED_CAPITAL_CONTRACT | C99: =_xll.EQNXTDZ($A$1,$B99,C$1,$B$1) -> 25.2835 | D99: =_xll.EQNXTDZ($A$1,$B99,D$1,$B$1) -> 25.2835 | E99: =_xll.EQNXTDZ($A$1,$B99,E$1,$B$1) -> 16.7835 | F99: =_xll.EQNXTDZ($A$1,$B99,F$1,$B$1) -> 16.7835 | G99: =_xll.EQNXTDZ($A$1,$B99,G$1,$B$1) -> 0 | H99: =_xll.EQNXTDZ($A$1,$B99,H$1,$B$1) -> 0 | I99: =_xll.EQNXTDZ($A$1,$B99,I$1,$B$1) -> 0 | J99: =_xll.EQNXTDZ($A$1,$B99,J$1,$B$1) -> 0 | ... AF99: =_xll.EQNXTDZ($A$1,$B99,AF$1,$B$1) -> 0
A103: Field Description | B103: Field Name
A104: Equity Paid Up | B104: BS_EQUITY_PAIDUP | C104: =_xll.EQNXTDZ($A$1,$B104,C$1,$B$1) -> 16.2583 | D104: =_xll.EQNXTDZ($A$1,$B104,D$1,$B$1) -> 16.2583 | E104: =_xll.EQNXTDZ($A$1,$B104,E$1,$B$1) -> 16.2583 | F104: =_xll.EQNXTDZ($A$1,$B104,F$1,$B$1) -> 16.2583 | G104: =_xll.EQNXTDZ($A$1,$B104,G$1,$B$1) -> 16.2583 | H104: =_xll.EQNXTDZ($A$1,$B104,H$1,$B$1) -> 16.2583 | I104: =_xll.EQNXTDZ($A$1,$B104,I$1,$B$1) -> 21.2583 | J104: =_xll.EQNXTDZ($A$1,$B104,J$1,$B$1) -> 22.2583 | ... AF104: =_xll.EQNXTDZ($A$1,$B104,AF$1,$B$1) -> 0
A105: Face Value | B105: BS_FACE_VALUE | C105: =_xll.EQNXTDZ($A$1,$B105,C$1,$B$1) -> 10 | D105: =_xll.EQNXTDZ($A$1,$B105,D$1,$B$1) -> 10 | E105: =_xll.EQNXTDZ($A$1,$B105,E$1,$B$1) -> 10 | F105: =_xll.EQNXTDZ($A$1,$B105,F$1,$B$1) -> 10 | G105: =_xll.EQNXTDZ($A$1,$B105,G$1,$B$1) -> 10 | H105: =_xll.EQNXTDZ($A$1,$B105,H$1,$B$1) -> 10 | I105: =_xll.EQNXTDZ($A$1,$B105,I$1,$B$1) -> 10 | J105: =_xll.EQNXTDZ($A$1,$B105,J$1,$B$1) -> 2 | ... AF105: =_xll.EQNXTDZ($A$1,$B105,AF$1,$B$1) -> 0
A106: Close Price (Unit Curr.) | B106: FH_YEAR_PRICE | C106: =_xll.EQNXTDZ($A$1,$B106,C$1,$B$1) -> 0.41 | D106: =_xll.EQNXTDZ($A$1,$B106,D$1,$B$1) -> 0.1 | E106: =_xll.EQNXTDZ($A$1,$B106,E$1,$B$1) -> 0.155 | F106: =_xll.EQNXTDZ($A$1,$B106,F$1,$B$1) -> 0.839 | G106: =_xll.EQNXTDZ($A$1,$B106,G$1,$B$1) -> 4.535 | H106: =_xll.EQNXTDZ($A$1,$B106,H$1,$B$1) -> 3.95 | I106: =_xll.EQNXTDZ($A$1,$B106,I$1,$B$1) -> 2.535 | J106: =_xll.EQNXTDZ($A$1,$B106,J$1,$B$1) -> 37.7 | ... AF106: =_xll.EQNXTDZ($A$1,$B106,AF$1,$B$1) -> 0
A107: High Price (Unit Curr.) | B107: FH_HIGH | C107: =_xll.EQNXTDZ($A$1,$B107,C$1,$B$1) -> 1.13 | D107: =_xll.EQNXTDZ($A$1,$B107,D$1,$B$1) -> 0.35 | E107: =_xll.EQNXTDZ($A$1,$B107,E$1,$B$1) -> 0.905 | F107: =_xll.EQNXTDZ($A$1,$B107,F$1,$B$1) -> 1.47 | G107: =_xll.EQNXTDZ($A$1,$B107,G$1,$B$1) -> 5.08 | H107: =_xll.EQNXTDZ($A$1,$B107,H$1,$B$1) -> 6.77 | I107: =_xll.EQNXTDZ($A$1,$B107,I$1,$B$1) -> 4.67 | J107: =_xll.EQNXTDZ($A$1,$B107,J$1,$B$1) -> 83 | ... AF107: =_xll.EQNXTDZ($A$1,$B107,AF$1,$B$1) -> 0
A108: Low Price (Unit Curr.) | B108: FH_LOW | C108: =_xll.EQNXTDZ($A$1,$B108,C$1,$B$1) -> 0.345 | D108: =_xll.EQNXTDZ($A$1,$B108,D$1,$B$1) -> 0.065 | E108: =_xll.EQNXTDZ($A$1,$B108,E$1,$B$1) -> 0.08 | F108: =_xll.EQNXTDZ($A$1,$B108,F$1,$B$1) -> 0.145 | G108: =_xll.EQNXTDZ($A$1,$B108,G$1,$B$1) -> 0.417 | H108: =_xll.EQNXTDZ($A$1,$B108,H$1,$B$1) -> 2.205 | I108: =_xll.EQNXTDZ($A$1,$B108,I$1,$B$1) -> 1.81 | J108: =_xll.EQNXTDZ($A$1,$B108,J$1,$B$1) -> 2.365 | ... AF108: =_xll.EQNXTDZ($A$1,$B108,AF$1,$B$1) -> 0
A109: Market Capitalization | B109: FH_MCAP | C109: =_xll.EQNXTDZ($A$1,$B109,C$1,$B$1) -> 6.665903 | D109: =_xll.EQNXTDZ($A$1,$B109,D$1,$B$1) -> 1.62583 | E109: =_xll.EQNXTDZ($A$1,$B109,E$1,$B$1) -> 2.5200365 | F109: =_xll.EQNXTDZ($A$1,$B109,F$1,$B$1) -> 13.640714 | G109: =_xll.EQNXTDZ($A$1,$B109,G$1,$B$1) -> 73.731391 | H109: =_xll.EQNXTDZ($A$1,$B109,H$1,$B$1) -> 64.220285 | I109: =_xll.EQNXTDZ($A$1,$B109,I$1,$B$1) -> 53.88979 | J109: =_xll.EQNXTDZ($A$1,$B109,J$1,$B$1) -> 839.13791 | ... AF109: =_xll.EQNXTDZ($A$1,$B109,AF$1,$B$1) -> 0
A110: Adj DPS(Rs) | B110: FR_ADJ_DPS | C110: =_xll.EQNXTDZ($A$1,$B110,C$1,$B$1) -> 0 | D110: =_xll.EQNXTDZ($A$1,$B110,D$1,$B$1) -> 0 | E110: =_xll.EQNXTDZ($A$1,$B110,E$1,$B$1) -> 0 | F110: =_xll.EQNXTDZ($A$1,$B110,F$1,$B$1) -> 0 | G110: =_xll.EQNXTDZ($A$1,$B110,G$1,$B$1) -> 0 | H110: =_xll.EQNXTDZ($A$1,$B110,H$1,$B$1) -> 0 | I110: =_xll.EQNXTDZ($A$1,$B110,I$1,$B$1) -> 0 | J110: =_xll.EQNXTDZ($A$1,$B110,J$1,$B$1) -> 0 | ... AF110: =_xll.EQNXTDZ($A$1,$B110,AF$1,$B$1) -> 0
A111: Date End | B111: SHP_DATE_END | C111: =_xll.EQNXTDZ($A$1,$B111,C$5) -> 200103 | D111: =_xll.EQNXTDZ($A$1,$B111,D$5) -> 200203 | E111: =_xll.EQNXTDZ($A$1,$B111,E$5) -> 200303 | F111: =_xll.EQNXTDZ($A$1,$B111,F$5) -> 200403 | G111: =_xll.EQNXTDZ($A$1,$B111,G$5) -> 0 | H111: =_xll.EQNXTDZ($A$1,$B111,H$5) -> 200603 | I111: =_xll.EQNXTDZ($A$1,$B111,I$5) -> 200703 | J111: =_xll.EQNXTDZ($A$1,$B111,J$5) -> 200803 | ... AF111: =_xll.EQNXTDZ($A$1,$B111,AF$5) -> 0
A112: Total of Promoter and Promoter Group | B112: SHP_TPFTOTALPROMOTER | C112: =_xll.EQNXTDZ($A$1,$B112,C$5) -> 32.99 | D112: =_xll.EQNXTDZ($A$1,$B112,D$5) -> 32.99 | E112: =_xll.EQNXTDZ($A$1,$B112,E$5) -> 32.99 | F112: =_xll.EQNXTDZ($A$1,$B112,F$5) -> 32.99 | G112: =_xll.EQNXTDZ($A$1,$B112,G$5) -> 0 | H112: =_xll.EQNXTDZ($A$1,$B112,H$5) -> 32.4 | I112: =_xll.EQNXTDZ($A$1,$B112,I$5) -> 47.67 | J112: =_xll.EQNXTDZ($A$1,$B112,J$5) -> 45.53 | ... AF112: =_xll.EQNXTDZ($A$1,$B112,AF$5) -> 0
...

Sheet QTR Share Price
A1: ='QTR Raw'!A1 -> 112455 | C1: 201206 | D1: 201207 | E1: 201208 | F1: 201209 | G1: 201210 | H1: 201211 | I1: 201212 | J1: 201301 | K1: 201302 | L1: 201303 | M1: 201304 | N1: 201305 | O1: 201306 | P1: 201307 | Q1: 201308 | R1: 201309 | S1: 201310 | T1: 201311 | U1: 201312 | V1: 201401 | W1: 201402 | X1: 201403 | Y1: 201404 | Z1: 201405 | AA1: 201406 | AB1: 201407 | AC1: 201408 | AD1: 201409 | AE1: 201410 | AF1: 201411 | AG1: 201412 | AH1: 201501 | AI1: 201502 | AJ1: 201503 | AK1: 201504 | AL1: 201505 | AM1: 201506 | AN1: 201507 | AO1: 201508 | AP1: 201509 | AQ1: 201510 | AR1: 201511 | AS1: 201512 | AT1: 201601 | AU1: 201602 | AV1: 201603 | AW1: 201604 | AX1: 201605 | AY1: 201606 | AZ1: 201607 | BA1: 201608 | BB1: 201609 | BC1: 201610 | BD1: 201611 | BE1: 201612 | BF1: 201701 | BG1: 201702 | BH1: 201703 | BI1: 201704 | BJ1: 201705 | BK1: 201706 | BL1: 201707 | BM1: 201708 | BN1: 201709 | BO1: 201710 | BP1: 201711 | BQ1: 201712 | BR1: 201801 | BS1: 201802 | BT1: 201803 | BU1: 201804 | BV1: 201805 | BW1: 201806 | BX1: 201807 | BY1: 201808 | BZ1: 201809 | CA1: 201810 | CB1: 201811 | CC1: 201812 | CD1: 201901 | CE1: 201902 | CF1: 201903 | CG1: 201904 | CH1: 201905 | CI1: 201906 | CJ1: 201907 | CK1: 201908 | CL1: 201909 | CM1: 201910 | CN1: 201911 | CO1: 201912 | CP1: 202001 | CQ1: 202002 | CR1: 202003 | CS1: 202004 | CT1: 202005 | CU1: 202006 | CV1: 202007 | CW1: 202008 | CX1: 202009 | CY1: 202010 | CZ1: 202011 | DA1: 202012 | DB1: 202101 | DC1: 202102 | DD1: 202103 | DE1: 202104 | DF1: 202105 | DG1: 202106 | DH1: 202107 | DI1: 202108 | DJ1: 202109 | DK1: 202110 | DL1: 202111 | DM1: 202112 | DN1: 202201 | DO1: 202202 | DP1: 202203 | DQ1: 202204 | DR1: 202205 | DS1: 202206 | DT1: 202207 | DU1: 202208 | DV1: 202209 | DW1: 202210 | DX1: 202211 | DY1: 202212 | DZ1: 202301 | EA1: 202302 | EB1: 202303 | EC1: 202304 | ED1: 202305 | EE1: 202306 | EF1: 202307 | EG1: 202308 | EH1: 202309 | EI1: 202310 | EJ1: 202311 | EK1: 202312 | EL1: 202401 | EM1: 202402 | EN1: 202403 | EO1: 202404 | EP1: 202405 | EQ1: 202406 | ER1: 202407 | ES1: 202408 | ET1: 202409 | EU1: 202410 | EV1: 202411 | EW1: 202412 | EX1: 202501 | EY1: 202502 | EZ1: 202503 | FA1: 202504 | FB1: 202505 | FC1: 202506 | FD1: 202507 | FE1: 202508 | FF1: 202509 | FG1: 202510 | FH1: 202511 | FI1: 202512 | FJ1: 202601 | FK1: 202602 | FL1: 202603 | FM1: 202604 | FN1: 202605 | FO1: 202606 | FP1: 202607 | FQ1: 202608 | FR1: 202609 | FS1: 202610 | FT1: 202611 | FU1: 202612 | FV1: 202701 | FW1: 202702 | FX1: 202703 | FY1: 202704 | FZ1: 202705 | GA1: 202706 | GB1: 202707 | GC1: 202708 | GD1: 202709 | GE1: 202710 | GF1: 202711 | GG1: 202712 | GH1: 202801 | GI1: 202802 | GJ1: 202803 | GK1: 202804 | GL1: 202805 | GM1: 202806 | GN1: 202807 | GO1: 202808 | GP1: 202809 | GQ1: 202810 | GR1: 202811 | GS1: 202812 | GT1: 202901 | GU1: 202902 | GV1: 202903 | GW1: 202904 | GX1: 202905 | GY1: 202906 | GZ1: 202907 | HA1: 202908 | HB1: 202909 | HC1: 202910 | HD1: 202911 | HE1: 202912 | HF1: 203001 | HG1: 203002 | HH1: 203003 | HM1: 201206 | HN1: 201207 | HO1: 201208 | HP1: 201209 | HQ1: 201212 | HR1: 201303 | HS1: 201306 | HT1: 201309 | HU1: 201312 | HV1: 201403 | HW1: 201406 | HX1: 201409 | HY1: 201412 | HZ1: 201503 | IA1: 201506 | IB1: 201509 | IC1: 201512 | ID1: 201603 | IE1: 201606 | IF1: 201609 | IG1: 201612 | IH1: 201703 | II1: 201706 | IJ1: 201709 | IK1: 201712 | IL1: 201803 | IM1: 201806 | IN1: 201809 | IO1: 201812 | IP1: 201903 | IQ1: 201906 | IR1: 201909 | IS1: 201912 | IT1: 202003 | IU1: 202006 | IV1: 202009 | IW1: 202012 | IX1: 202103 | IY1: 202106 | IZ1: 202109 | JA1: 202112 | JB1: 202203 | JC1: 202206 | JD1: 202209 | JE1: 202212 | JF1: 202303 | JG1: 202306 | JH1: 202309 | JI1: 202312 | JJ1: 202403 | JK1: 202406 | JL1: 202409 | JM1: 202412 | JN1: 202503 | JO1: 202506 | JP1: 202509 | JQ1: 202512 | JR1: 202603 | JS1: 202606 | JT1: 202609 | JU1: 202612 | JV1: 202703 | JW1: 202706 | JX1: 202709 | JY1: 202712 | JZ1: 202803 | KA1: 202806 | KB1: 202809 | KC1: 202812 | KD1: 202903 | KE1: 202906 | KF1: 202909 | KG1: 202912 | KH1: 203003
