Workbook

Sheet Template
A1: =+'Annual Raw'!C4 -> Sangam (India) Ltd. | B1: 36951 | C1: =EOMONTH(B1,12) -> 37346 | D1: =EOMONTH(C1,12) -> 37711 | E1: =EOMONTH(D1,12) -> 38077 | F1: =EOMONTH(E1,12) -> 38442 | G1: =EOMONTH(F1,12) -> 38807 | H1: =EOMONTH(G1,12) -> 39172 | I1: =EOMONTH(H1,12) -> 39538 | J1: =EOMONTH(I1,12) -> 39903 | ... AE1: =EOMONTH(AD1,12) -> 47573 | AH1: QTR | AI1: 41061 | AJ1: 41153 | AK1: 41244 | AL1: 41334 | AM1: 41426 | AN1: 41518 | AO1: 41609 | AP1: 41699 | AQ1: 41791 | AR1: 41883 | AS1: 41974 | AT1: 42064 | AU1: 42156 | AV1: 42248 | AW1: 42339 | AX1: 42430 | AY1: 42522 | AZ1: 42614 | BA1: 42705 | BB1: 42795 | BC1: 42887 | BD1: 42979 | BE1: 43070 | BF1: 43160 | BG1: 43252 | BH1: 43344 | BI1: 43435 | BJ1: 43525 | BK1: 43617 | BL1: 43709 | BM1: 43800 | BN1: 43891 | BO1: 43983 | BP1: 44075 | BQ1: =EOMONTH(BP1,3) -> 44196 | BR1: =EOMONTH(BQ1,3) -> 44286 | BS1: =EOMONTH(BR1,3) -> 44377 | BT1: =EOMONTH(BS1,3) -> 44469 | BU1: =EOMONTH(BT1,3) -> 44561 | BV1: =EOMONTH(BU1,3) -> 44651 | BW1: =EOMONTH(BV1,3) -> 44742 | BX1: =EOMONTH(BW1,3) -> 44834 | ... DB1: =EOMONTH(DA1,3) -> 47573 | DE1: HISTORICAL ESTIMATES | DF1: 46112
A2: Presentation Data (Start)
A4: Capacity
A5: Yarn (MT) | V5: 85500 | Y5: 103140 | Z5: 114420 | AA5: 114420 | AB5: 114420 | AC5: 114420 | AD5: 114420 | AE5: 114420 | CE5: 28605 | CF5: 28605 | CG5: 28605 | CH5: 28605 | CI5: 28605 | CJ5: 28605 | CK5: 28605 | CL5: 28605 | CM5: =114420/4 -> 28605 | CN5: =114420/4 -> 28605 | CO5: =114420/4 -> 28605 | CP5: =114420/4 -> 28605 | CQ5: =114420/4 -> 28605 | CR5: =114420/4 -> 28605 | CS5: =114420/4 -> 28605 | CT5: =114420/4 -> 28605 | ... DB5: =114420/4 -> 28605
A6: Green Fibre (MT)(polyster) | AA6: =AA13/AA20 -> 15385.567 | AB6: 15385.567 | AC6: 15385.567 | AD6: 15385.567 | AE6: 15385.567 | CK6: =CK13/CK20 -> 3904.1237 | CL6: =CL13/CL20 -> 3788.6598 | CM6: =+CL6 -> 3788.6598 | CN6: =+CM6 -> 3788.6598 | CO6: =+CN6 -> 3788.6598 | CP6: =+CO6 -> 3788.6598 | CQ6: =+CP6 -> 3788.6598 | CR6: =+CQ6 -> 3788.6598 | CS6: =+CR6 -> 3788.6598 | CT6: =+CS6 -> 3788.6598 | ... DB6: =+DA6 -> 3788.6598
A7: PV Fabric MMPA (Weaving) | V7: 30 | W7: 30 | X7: 32.4 | Y7: 48 | Z7: 48 | AA7: 71 | AB7: 71 | AC7: 71 | AD7: 71 | AE7: 71 | CA7: 12 | CB7: 12 | CC7: 12 | CD7: 12 | CE7: 12 | CF7: 12 | CG7: 12 | CH7: 12 | CI7: 17.75 | CJ7: 17.75 | CK7: 17.75 | CL7: 17.75 | CM7: 17.75 | CN7: 17.75 | CO7: 17.75 | CP7: 17.75 | CQ7: 17.75 | CR7: 17.75 | CS7: 17.75 | CT7: 17.75 | CU7: 17.75 | CV7: 17.75 | CW7: 17.75 | CX7: 17.75 | CY7: 17.75 | CZ7: 17.75 | DA7: 17.75 | DB7: 17.75
A8: Denim Fabric MMPA | V8: 48 | W8: 48 | X8: 48 | Y8: 48 | Z8: 60 | AA8: 60 | AB8: 60 | AC8: 60 | AD8: 60 | AE8: 60 | CA8: 12 | CB8: 12 | CC8: 12 | CD8: 12 | CE8: 15 | CF8: 15 | CG8: 15 | CH8: 15 | CI8: 15 | CJ8: 15 | CK8: 15 | CL8: 15 | CM8: 15 | CN8: 15 | CO8: 15 | CP8: 15 | CQ8: 15 | CR8: 15 | CS8: 15 | CT8: 15 | CU8: 15 | CV8: 15 | CW8: 15 | CX8: 15 | CY8: 15 | CZ8: 15 | DA8: 15 | DB8: 15
A9: Garments (mn pieces pa) | Y9: =+Z9 -> 13.5 | Z9: =+AA9 -> 13.5 | AA9: 13.5 | AB9: =+AA9 -> 13.5 | AC9: =+AB9 -> 13.5 | AD9: =+AC9 -> 13.5 | AE9: =+AD9 -> 13.5 | CA9: =+CB9 -> 3.375 | CB9: =+CC9 -> 3.375 | CC9: =+CD9 -> 3.375 | CD9: =+CE9 -> 3.375 | CE9: =+CF9 -> 3.375 | CF9: =+CG9 -> 3.375 | CG9: =+CH9 -> 3.375 | CH9: =+CI9 -> 3.375 | ... CK9: =+CL9 -> 3.375 | CL9: =+AA9/4 -> 3.375 | CM9: =+CL9 -> 3.375 | CN9: =+CM9 -> 3.375 | CO9: =+CN9 -> 3.375 | CP9: =+CO9 -> 3.375 | CQ9: =+CP9 -> 3.375 | CR9: =+CQ9 -> 3.375 | CS9: =+CR9 -> 3.375 | CT9: =+CS9 -> 3.375 | ... DB9: =+DA9 -> 3.375
A11: Production Quantity
A12: Yarn (MT) -Production Quantity | X12: =SUM(BW12:BZ12) -> 77010 | Y12: =SUM(CA12:CD12) -> 85926 | Z12: =SUM(CE12:CH12) -> 84446 | AA12: =SUM(CI12:CL12) -> 93690 | AB12: =SUM(CM12:CP12) -> 108699 | AC12: =SUM(CQ12:CT12) -> 108699 | AD12: =SUM(CU12:CX12) -> 108699 | AE12: =SUM(CY12:DB12) -> 108699 | BW12: 16489 | BX12: 19507 | BY12: 20108 | BZ12: 20906 | CA12: 21135 | CB12: 21205 | CC12: 20867 | CD12: 22719 | CE12: 20862 | CF12: 21177 | CG12: 20531 | CH12: 21876 | CI12: 21226 | CJ12: 24470 | CK12: 23636 | CL12: 24358 | CM12: =CM5*CM19 -> 27174.75 | CN12: =CM12 -> 27174.75 | CO12: =CN12 -> 27174.75 | CP12: =CO12 -> 27174.75 | CQ12: =CP12 -> 27174.75 | CR12: =CQ12 -> 27174.75 | CS12: =CR12 -> 27174.75 | CT12: =CS12 -> 27174.75 | CU12: =CT12 -> 27174.75 | ... DB12: =DA12 -> 27174.75
A13: Green Fibre (MT) - Production Quantity | X13: =SUM(BW13:BZ13) -> 0 | Y13: =SUM(CA13:CD13) -> 0 | Z13: =SUM(CE13:CH13) -> 0 | AA13: =SUM(CI13:CL13) -> 7462 | AB13: =SUM(CM13:CP13) -> 14700 | AC13: =SUM(CQ13:CT13) -> 14700 | AD13: =SUM(CU13:CX13) -> 14700 | AE13: =SUM(CY13:DB13) -> 14700 | BW13: 0 | BX13: 0 | BY13: 0 | BZ13: 0 | CA13: 0 | CB13: 0 | CC13: 0 | CD13: 0 | CE13: 0 | CF13: 0 | CG13: 0 | CH13: 0 | CI13: 0 | CJ13: 0 | CK13: 3787 | CL13: 3675 | CM13: =CM6*CM20 -> 3675 | CN13: =CM13 -> 3675 | CO13: =CN13 -> 3675 | CP13: =CO13 -> 3675 | CQ13: =CP13 -> 3675 | CR13: =CQ13 -> 3675 | CS13: =CR13 -> 3675 | CT13: =CS13 -> 3675 | CU13: =CT13 -> 3675 | ... DB13: =DA13 -> 3675
A14: PV Fabric MMPA - Production Quantity | X14: =SUM(BW14:BZ14) -> 28.8 | Y14: =SUM(CA14:CD14) -> 36.6 | Z14: =SUM(CE14:CH14) -> 42.7 | AA14: =SUM(CI14:CL14) -> 63.4 | AB14: =SUM(CM14:CP14) -> 68.1245 | AC14: =SUM(CQ14:CT14) -> 68.1245 | AD14: =SUM(CU14:CX14) -> 68.1245 | AE14: =SUM(CY14:DB14) -> 68.1245 | BW14: 6.2 | BX14: 7.9 | BY14: 7.6 | BZ14: 7.1 | CA14: 9.7 | CB14: 7.8 | CC14: 9.5 | CD14: 9.6 | CE14: 9.3 | CF14: 10.8 | CG14: 8.2 | CH14: 14.4 | CI14: 12.9 | CJ14: 16.2 | CK14: 16.8 | CL14: 17.5 | CM14: =CM7*CM21 -> 17.031125 | CN14: =CN7*CN21 -> 17.031125 | CO14: =CO7*CO21 -> 17.031125 | CP14: =CP7*CP21 -> 17.031125 | CQ14: =CQ7*CQ21 -> 17.031125 | CR14: =CR7*CR21 -> 17.031125 | CS14: =CS7*CS21 -> 17.031125 | CT14: =CT7*CT21 -> 17.031125 | ... DB14: =DB7*DB21 -> 17.031125
A15: Denim Fabric MMPA - Production Quantity | X15: =SUM(BW15:BZ15) -> 34.4 | Y15: =SUM(CA15:CD15) -> 42.6 | Z15: =SUM(CE15:CH15) -> 48.8 | AA15: =SUM(CI15:CL15) -> 49.8 | AB15: =SUM(CM15:CP15) -> 58.8 | AC15: =SUM(CQ15:CT15) -> 58.8 | AD15: =SUM(CU15:CX15) -> 58.8 | AE15: =SUM(CY15:DB15) -> 58.8 | BW15: 10.6 | BX15: 7.4 | BY15: 7.2 | BZ15: 9.2 | CA15: 10.3 | CB15: 9.5 | CC15: 10.9 | CD15: 11.9 | CE15: 12.2 | CF15: 11.6 | CG15: 12 | CH15: 13 | CI15: 11.8 | CJ15: 11.2 | CK15: 13.2 | CL15: 13.6 | CM15: =CM8*CM22 -> 14.7 | CN15: =CN8*CN22 -> 14.7 | CO15: =CO8*CO22 -> 14.7 | CP15: =CP8*CP22 -> 14.7 | CQ15: =CQ8*CQ22 -> 14.7 | CR15: =CR8*CR22 -> 14.7 | CS15: =CS8*CS22 -> 14.7 | CT15: =CT8*CT22 -> 14.7 | ... DB15: =DB8*DB22 -> 14.7
A16: Garments (lakh pcs) | X16: =SUM(BW16:BZ16) -> 46 | Y16: =SUM(CA16:CD16) -> 41 | Z16: =SUM(CE16:CH16) -> 39 | AA16: =SUM(CI16:CL16) -> 44 | AB16: =SUM(CM16:CP16) -> 81 | AC16: =SUM(CQ16:CT16) -> 121.5 | AD16: =SUM(CU16:CX16) -> 128.25 | AE16: =SUM(CY16:DB16) -> 128.25 | BW16: 12 | BX16: 11 | BY16: 11 | BZ16: 12 | CA16: 8 | CB16: 9 | CC16: 10 | CD16: 14 | CE16: 12 | CF16: 11 | CG16: 9 | CH16: 7 | CI16: 6 | CJ16: 9 | CK16: 14 | CL16: 15 | CM16: =CM9*CM23*10 -> 18.5625 | CN16: =CN9*CN23*10 -> 18.5625 | CO16: =CO9*CO23*10 -> 20.25 | CP16: =CP9*CP23*10 -> 23.625 | CQ16: =CQ9*CQ23*10 -> 27 | CR16: =CR9*CR23*10 -> 30.375 | CS16: =CS9*CS23*10 -> 32.0625 | CT16: =CT9*CT23*10 -> 32.0625 | ... DB16: =DB9*DB23*10 -> 32.0625
A18: Utilization %
A19: Yarn - Utilization % | X19: =AVERAGE(BW19:BZ19) -> 0.87 | Y19: =AVERAGE(CA19:CD19) -> 0.855 | Z19: =AVERAGE(CE19:CH19) -> 0.7975 | AA19: =AVERAGE(CI19:CL19) -> 0.9 | AB19: =AVERAGE(CM19:CP19) -> 0.95 | AC19: =AVERAGE(CQ19:CT19) -> 0.95 | AD19: =AVERAGE(CU19:CX19) -> 0.95 | AE19: =AVERAGE(CY19:DB19) -> 0.95 | BW19: 0.77 | BX19: 0.91 | BY19: 0.94 | BZ19: 0.86 | CA19: 0.87 | CB19: 0.88 | CC19: 0.8 | CD19: 0.87 | CE19: 0.79 | CF19: 0.78 | CG19: 0.75 | CH19: 0.87 | CI19: 0.82 | CJ19: 0.92 | CK19: 0.91 | CL19: 0.95 | CM19: =+CL19 -> 0.95 | CN19: =+CM19 -> 0.95 | CO19: =+CN19 -> 0.95 | CP19: =+CO19 -> 0.95 | CQ19: =+CP19 -> 0.95 | CR19: =+CQ19 -> 0.95 | CS19: =+CR19 -> 0.95 | CT19: =+CS19 -> 0.95 | ... DB19: =+DA19 -> 0.95
A20: Green Fibre - Utilization % | X20: =SUM(BW20:BZ20) -> 0 | Y20: =SUM(CA20:CD20) -> 0 | Z20: =SUM(CE20:CH20) -> 0 | AA20: =AVERAGE(CI20:CL20) -> 0.485 | AB20: =AVERAGE(CM20:CP20) -> 0.97 | AC20: =AVERAGE(CQ20:CT20) -> 0.97 | AD20: =AVERAGE(CU20:CX20) -> 0.97 | AE20: =AVERAGE(CY20:DB20) -> 0.97 | BW20: 0 | BX20: 0 | BY20: 0 | BZ20: 0 | CA20: 0 | CB20: 0 | CC20: 0 | CD20: 0 | CE20: 0 | CF20: 0 | CG20: 0 | CH20: 0 | CI20: 0 | CJ20: 0 | CK20: 0.97 | CL20: 0.97 | CM20: =+CL20 -> 0.97 | CN20: =+CM20 -> 0.97 | CO20: =+CN20 -> 0.97 | CP20: =+CO20 -> 0.97 | CQ20: =+CP20 -> 0.97 | CR20: =+CQ20 -> 0.97 | CS20: =+CR20 -> 0.97 | CT20: =+CS20 -> 0.97 | ... DB20: =+DA20 -> 0.97
A21: PV Fabric - Utilization % | X21: =AVERAGE(BW21:BZ21) -> 0.8925 | Y21: =AVERAGE(CA21:CD21) -> 0.85 | Z21: =AVERAGE(CE21:CH21) -> 0.875 | AA21: =AVERAGE(CI21:CL21) -> 0.885 | AB21: =AVERAGE(CM21:CP21) -> 0.9595 | AC21: =AVERAGE(CQ21:CT21) -> 0.9595 | AD21: =AVERAGE(CU21:CX21) -> 0.9595 | AE21: =AVERAGE(CY21:DB21) -> 0.9595 | BW21: 0.77 | BX21: 0.98 | BY21: 0.94 | BZ21: 0.88 | CA21: 0.93 | CB21: 0.73 | CC21: 0.87 | CD21: 0.87 | CE21: 0.84 | CF21: 0.96 | CG21: 0.82 | CH21: 0.88 | CI21: 0.75 | CJ21: 0.94 | CK21: 0.9 | CL21: 0.95 | CM21: =+CL21*1.01 -> 0.9595 | CN21: =+CM21 -> 0.9595 | CO21: =+CN21 -> 0.9595 | CP21: =+CO21 -> 0.9595 | CQ21: =+CP21 -> 0.9595 | CR21: =+CQ21 -> 0.9595 | CS21: =+CR21 -> 0.9595 | CT21: =+CS21 -> 0.9595 | CU21: =+CT21 -> 0.9595 | ... DB21: =+DA21 -> 0.9595
A22: Denim Fabric - Utilization % | X22: =AVERAGE(BW22:BZ22) -> 0.715 | Y22: =AVERAGE(CA22:CD22) -> 0.8875 | Z22: =AVERAGE(CE22:CH22) -> 0.915 | AA22: =AVERAGE(CI22:CL22) -> 0.9225 | AB22: =AVERAGE(CM22:CP22) -> 0.98 | AC22: =AVERAGE(CQ22:CT22) -> 0.98 | AD22: =AVERAGE(CU22:CX22) -> 0.98 | AE22: =AVERAGE(CY22:DB22) -> 0.98 | BW22: 0.88 | BX22: 0.62 | BY22: 0.6 | BZ22: 0.76 | CA22: 0.86 | CB22: 0.79 | CC22: 0.91 | CD22: 0.99 | CE22: 0.94 | CF22: 0.9 | CG22: 0.89 | CH22: 0.93 | CI22: 0.92 | CJ22: 0.86 | CK22: 0.93 | CL22: 0.98 | CM22: =+CL22 -> 0.98 | CN22: =+CM22 -> 0.98 | CO22: =+CN22 -> 0.98 | CP22: =+CO22 -> 0.98 | CQ22: =+CP22 -> 0.98 | CR22: =+CQ22 -> 0.98 | CS22: =+CR22 -> 0.98 | CT22: =+CS22 -> 0.98 | ... DB22: =+DA22 -> 0.98
A23: Garments - Utilization % | X23: =AVERAGE(BW23:BZ23) -> 0.595 | Y23: =AVERAGE(CA23:CD23) -> 0.425 | Z23: =AVERAGE(CE23:CH23) -> 0.39 | AA23: =AVERAGE(CI23:CL23) -> 0.3025 | AB23: =AVERAGE(CM23:CP23) -> 0.6 | AC23: =AVERAGE(CQ23:CT23) -> 0.9 | AD23: =AVERAGE(CU23:CX23) -> 0.95 | AE23: =AVERAGE(CY23:DB23) -> 0.95 | BW23: 0.86 | BX23: 0.54 | BY23: 0.55 | BZ23: 0.43 | CA23: 0.31 | CB23: 0.39 | CC23: 0.4 | CD23: 0.6 | CE23: 0.5 | CF23: 0.46 | CG23: 0.36 | CH23: 0.24 | CI23: 0.2 | CJ23: 0.18 | CK23: 0.34 | CL23: 0.49 | CM23: 0.55 | CN23: =+CM23 -> 0.55 | CO23: 0.6 | CP23: 0.7 | CQ23: 0.8 | CR23: 0.9 | CS23: 0.95 | CT23: =+CS23 -> 0.95 | CU23: =+CT23 -> 0.95 | CV23: =+CU23 -> 0.95 | CW23: =+CV23 -> 0.95 | CX23: =+CW23 -> 0.95 | CY23: =+CX23 -> 0.95 | CZ23: =+CY23 -> 0.95 | DA23: =+CZ23 -> 0.95 | DB23: =+DA23 -> 0.95
A25: Unit metrics
A26: Spinning - per kg | Y26: =Y34*10^7/Y12/1000 -> 74.491586 | Z26: =Z34*10^7/Z12/1000 -> 169.41841 | AA26: =AA34*10^7/AA12/1000 -> 174.31685 | AB26: =AB34*10^7/AB12/1000 -> 185.53548 | AC26: =AC34*10^7/AC12/1000 -> 190.50577 | AD26: =AD34*10^7/AD12/1000 -> 193.8424 | AE26: =AE34*10^7/AE12/1000 -> 194.61893 | CC26: =CC34*10^7/CC12/1000 -> 148.8235 | CD26: =CD34*10^7/CD12/1000 -> 145.04441 | CE26: =CE34*10^7/CE12/1000 -> 159.4593 | CF26: =CF34*10^7/CF12/1000 -> 153.13444 | CG26: =CG34*10^7/CG12/1000 -> 187.29477 | CH26: =CH34*10^7/CH12/1000 -> 177.90227 | CI26: =CI34*10^7/CI12/1000 -> 163.71375 | CJ26: =CJ34*10^7/CJ12/1000 -> 167.06727 | ... CL26: =CL34*10^7/CL12/1000 -> 185.07234 | CM26: =+CL26*1.001 -> 185.25741 | CN26: =+CM26*1.001 -> 185.44267 | CO26: =+CN26*1.001 -> 185.62811 | CP26: =+CO26*1.001 -> 185.81374 | CQ26: =+CP26*1.01 -> 187.67188 | CR26: =+CQ26*1.01 -> 189.54859 | CS26: =+CR26*1.01 -> 191.44408 | CT26: =+CS26*1.01 -> 193.35852 | CU26: =+CT26*1.001 -> 193.55188 | CV26: =+CU26*1.001 -> 193.74543 | CW26: =+CV26*1.001 -> 193.93918 | CX26: =+CW26*1.001 -> 194.13312 | CY26: =+CX26*1.001 -> 194.32725 | CZ26: =+CY26*1.001 -> 194.52158 | DA26: =+CZ26*1.001 -> 194.7161 | DB26: =+DA26*1.001 -> 194.91081
A27: PV Fabric - per meter | Y27: =Y36*100/Y14 -> 775.62077 | Z27: =Z36*100/Z14 -> 1179.6993 | AA27: =AA36*100/AA14 -> 993.83407 | AB27: =AB36*100/AB14 -> 911.45007 | AC27: =AC36*100/AC14 -> 915.10134 | AD27: =AD36*100/AD14 -> 918.76724 | AE27: =AE36*100/AE14 -> 922.44783 | CC27: =CC36*10/CC14 -> 143.83368 | CD27: =CD36*10/CD14 -> 153.37 | CE27: =CE36*10/CE14 -> 149.04301 | CF27: =CF36*10/CF14 -> 131.36861 | CG27: =CG36*10/CG14 -> 137.925 | CH27: =CH36*10/CH14 -> 76.489583 | CI27: =CI36*10/CI14 -> 171.42295 | CJ27: =CJ36*10/CJ14 -> 82.50037 | ... CL27: =CL36*10/CL14 -> 90.917486 | CM27: =+CL27*1.001 -> 91.008403 | CN27: =+CM27*1.001 -> 91.099412 | CO27: =+CN27*1.001 -> 91.190511 | CP27: =+CO27*1.001 -> 91.281702 | CQ27: =+CP27*1.001 -> 91.372983 | CR27: =+CQ27*1.001 -> 91.464356 | CS27: =+CR27*1.001 -> 91.555821 | CT27: =+CS27*1.001 -> 91.647376 | ... DB27: =+DA27*1.001 -> 92.383127
A28: Denim - per meter | Y28: =Y35*100/Y15 -> 858.24178 | Z28: =Z35*100/Z15 -> 1714.8344 | AA28: =AA35*100/AA15 -> 1771.0347 | AB28: =AB35*100/AB15 -> 1824.3894 | AC28: =AC35*100/AC15 -> 1831.6979 | AD28: =AD35*100/AD15 -> 1839.0357 | AE28: =AE35*100/AE15 -> 1846.4029 | CC28: =CC35*10/CC15 -> 142.45413 | CD28: =CD35*10/CD15 -> 176.75294 | CE28: =CE35*10/CE15 -> 164.74139 | CF28: =CF35*10/CF15 -> 163.07828 | CG28: =CG35*10/CG15 -> 194.78075 | CH28: =CH35*10/CH15 -> 163.80538 | CI28: =CI35*10/CI15 -> 167.32415 | CJ28: =CJ35*10/CJ15 -> 196.545 | ... CL28: =CL35*10/CL15 -> 181.98353 | CM28: =+CL28*1.001 -> 182.16551 | CN28: =+CM28*1.001 -> 182.34768 | CO28: =+CN28*1.001 -> 182.53003 | CP28: =+CO28*1.001 -> 182.71256 | CQ28: =+CP28*1.001 -> 182.89527 | CR28: =+CQ28*1.001 -> 183.07816 | CS28: =+CR28*1.001 -> 183.26124 | CT28: =+CS28*1.001 -> 183.4445 | ... DB28: =+DA28*1.001 -> 184.91721
A29: Garments (per pcs) | Y29: =Y38*100/Y16 -> 79.647317 | Z29: =Z38*100/Z16 -> 219.76538 | AA29: =AA38*100/AA16 -> 202.93023 | AB29: =AB38*100/AB16 -> 177.24486 | AC29: =AC38*100/AC16 -> 177.94872 | AD29: =AD38*100/AD16 -> 178.64919 | AE29: =AE38*100/AE16 -> 179.36486 | CC29: =CC38*100/CC16 -> 186.33 | CD29: =CD38*100/CD16 -> 100.16 | CE29: =CE38*100/CE16 -> 173.2625 | CF29: =CF38*100/CF16 -> 184.25727 | CG29: =CG38*100/CG16 -> 251.33 | CH29: =CH38*100/CH16 -> 314.7 | CI29: =CI38*100/CI16 -> 394.885 | CJ29: =CJ38*100/CJ16 -> 262.06 | ... CL29: =CL38*100/CL16 -> 176.784 | CM29: =+CL29*1.001 -> 176.96078 | CN29: =+CM29*1.001 -> 177.13774 | CO29: =+CN29*1.001 -> 177.31488 | CP29: =+CO29*1.001 -> 177.4922 | CQ29: =+CP29*1.001 -> 177.66969 | CR29: =+CQ29*1.001 -> 177.84736 | CS29: =+CR29*1.001 -> 178.02521 | CT29: =+CS29*1.001 -> 178.20323 | ... DB29: =+DA29*1.001 -> 179.63386
A31: Revenue Breakup - Segment wise
A32: PV Yarn | Y32: =SUM(CA32:CD32) -> 393.4652 | Z32: =SUM(CE32:CH32) -> 730.6655 | AA32: =SUM(CI32:CL32) -> 744.4301 | CC32: =CC57*34% -> 211.174 | CD32: =CD57*26% -> 182.2912 | CE32: =CE57*26% -> 180.193 | CF32: =CF57*22% -> 148.6342 | CG32: =CG57*27% -> 203.5773 | CH32: =CH57*27% -> 198.261 | CI32: =CI57*19% -> 150.0563 | CJ32: =CJ57*23% -> 180.8214 | CK32: =CK57*26% -> 201.4116 | CL32: =CL57*24% -> 212.1408
A33: Cotton Yarn | Y33: =SUM(CA33:CD33) -> 246.6112 | Z33: =SUM(CE33:CH33) -> 700.0052 | AA33: =SUM(CI33:CL33) -> 888.7445 | CC33: =CC57*16% -> 99.376 | CD33: =CD57*21% -> 147.2352 | CE33: =CE57*22% -> 152.471 | CF33: =CF57*26% -> 175.6586 | CG33: =CG57*24% -> 180.9576 | CH33: =CH57*26% -> 190.918 | CI33: =CI57*25% -> 197.4425 | CJ33: =CJ57*29% -> 227.9922 | CK33: =CK57*29% -> 224.6514 | CL33: =CL57*27% -> 238.6584
A34: Spinning (PV + Cotton Yarn) | Y34: =SUM(Y32:Y33) -> 640.0764 | Z34: =SUM(Z32:Z33) -> 1430.6707 | AA34: =SUM(AA32:AA33) -> 1633.1746 | AB34: =SUM(CM34:CP34) -> 2016.7521 | AC34: =SUM(CQ34:CT34) -> 2070.7786 | AD34: =SUM(CU34:CX34) -> 2107.0475 | AE34: =SUM(CY34:DB34) -> 2115.4884 | CC34: =SUM(CC32:CC33) -> 310.55 | CD34: =SUM(CD32:CD33) -> 329.5264 | CE34: =SUM(CE32:CE33) -> 332.664 | CF34: =SUM(CF32:CF33) -> 324.2928 | CG34: =SUM(CG32:CG33) -> 384.5349 | CH34: =SUM(CH32:CH33) -> 389.179 | CI34: =SUM(CI32:CI33) -> 347.4988 | CJ34: =SUM(CJ32:CJ33) -> 408.8136 | ... CL34: =SUM(CL32:CL33) -> 450.7992 | CM34: =CM26*CM12/10000 -> 503.43238 | CN34: =CN26*CN12/10000 -> 503.93581 | CO34: =CO26*CO12/10000 -> 504.43975 | CP34: =CP26*CP12/10000 -> 504.94419 | CQ34: =CQ26*CQ12/10000 -> 509.99363 | CR34: =CR26*CR12/10000 -> 515.09357 | CS34: =CS26*CS12/10000 -> 520.2445 | CT34: =CT26*CT12/10000 -> 525.44695 | ... DB34: =DB26*DB12/10000 -> 529.66526
A35: Denim Fabric | Y35: =SUM(CA35:CD35) -> 365.611 | Z35: =SUM(CE35:CH35) -> 836.8392 | AA35: =SUM(CI35:CL35) -> 881.9753 | AB35: =SUM(CM35:CP35) -> 1072.741 | AC35: =SUM(CQ35:CT35) -> 1077.0384 | AD35: =SUM(CU35:CX35) -> 1081.353 | AE35: =SUM(CY35:DB35) -> 1085.6849 | CC35: =CC57*25% -> 155.275 | CD35: =CD57*30% -> 210.336 | CE35: =CE57*29% -> 200.9845 | CF35: =CF57*28% -> 189.1708 | CG35: =CG57*31% -> 233.7369 | CH35: =CH57*29% -> 212.947 | CI35: =CI57*25% -> 197.4425 | CJ35: =CJ57*28% -> 220.1304 | CK35: =CK57*28% -> 216.9048 | CL35: =CL57*28% -> 247.4976 | CM35: =CM28*CM15/10 -> 267.7833 | CN35: =CN28*CN15/10 -> 268.05109 | CO35: =CO28*CO15/10 -> 268.31914 | CP35: =CP28*CP15/10 -> 268.58746 | CQ35: =CQ28*CQ15/10 -> 268.85605 | CR35: =CR28*CR15/10 -> 269.1249 | CS35: =CS28*CS15/10 -> 269.39403 | CT35: =CT28*CT15/10 -> 269.66342 | ... DB35: =DB28*DB15/10 -> 271.82829
A36: Woven Fabric with processing | Y36: =SUM(CA36:CD36) -> 283.8772 | Z36: =SUM(CE36:CH36) -> 503.7316 | AA36: =SUM(CI36:CL36) -> 630.0908 | AB36: =SUM(CM36:CP36) -> 620.9208 | AC36: =SUM(CQ36:CT36) -> 623.40821 | AD36: =SUM(CU36:CX36) -> 625.90559 | AE36: =SUM(CY36:DB36) -> 628.41297 | CC36: =CC57*22% -> 136.642 | CD36: =CD57*21% -> 147.2352 | CE36: =CE57*20% -> 138.61 | CF36: =CF57*21% -> 141.8781 | CG36: =CG57*15% -> 113.0985 | CH36: =CH57*15% -> 110.145 | CI36: =CI57*28% -> 221.1356 | CJ36: =CJ57*17% -> 133.6506 | CK36: =CK57*15% -> 116.199 | CL36: =CL57*18% -> 159.1056 | CM36: =CM27*CM14/10 -> 154.99755 | CN36: =CN27*CN14/10 -> 155.15255 | CO36: =CO27*CO14/10 -> 155.3077 | CP36: =CP27*CP14/10 -> 155.46301 | CQ36: =CQ27*CQ14/10 -> 155.61847 | CR36: =CR27*CR14/10 -> 155.77409 | CS36: =CS27*CS14/10 -> 155.92986 | CT36: =CT27*CT14/10 -> 156.08579 | ... DB36: =DB27*DB14/10 -> 157.33886
A37: Knitting & Weaving (Denim + Woven Fabric) | Y37: =SUM(Y35:Y36) -> 649.4882 | Z37: =SUM(Z35:Z36) -> 1340.5708 | AA37: =SUM(AA35:AA36) -> 1512.0661 | AB37: =SUM(AB35:AB36) -> 1693.6618 | AC37: =SUM(AC35:AC36) -> 1700.4466 | AD37: =SUM(AD35:AD36) -> 1707.2586 | AE37: =SUM(AE35:AE36) -> 1714.0979 | CC37: =SUM(CC35:CC36) -> 291.917 | CD37: =SUM(CD35:CD36) -> 357.5712 | CE37: =SUM(CE35:CE36) -> 339.5945 | CF37: =SUM(CF35:CF36) -> 331.0489 | CG37: =SUM(CG35:CG36) -> 346.8354 | CH37: =SUM(CH35:CH36) -> 323.092 | CI37: =SUM(CI35:CI36) -> 418.5781 | CJ37: =SUM(CJ35:CJ36) -> 353.781 | ... DB37: =SUM(DB35:DB36) -> 429.16715
A38: Garments | Y38: =SUM(CA38:CD38) -> 32.6554 | Z38: =SUM(CE38:CH38) -> 85.7085 | AA38: =SUM(CI38:CL38) -> 89.2893 | AB38: =SUM(CM38:CP38) -> 143.56833 | AC38: =SUM(CQ38:CT38) -> 216.20769 | AD38: =SUM(CU38:CX38) -> 229.11758 | AE38: =SUM(CY38:DB38) -> 230.03543 | CC38: =CC57*3% -> 18.633 | CD38: =CD57*2% -> 14.0224 | CE38: =CE57*3% -> 20.7915 | CF38: =CF57*3% -> 20.2683 | CG38: =CG57*3% -> 22.6197 | CH38: =CH57*3% -> 22.029 | CI38: =CI57*3% -> 23.6931 | CJ38: =CJ57*3% -> 23.5854 | CK38: =CK57*2% -> 15.4932 | CL38: =CL57*3% -> 26.5176 | CM38: =CM29*CM16/100 -> 32.848346 | CN38: =CN29*CN16/100 -> 32.881194 | CO38: =CO29*CO16/100 -> 35.906264 | CP38: =CP29*CP16/100 -> 41.932532 | CQ38: =CQ29*CQ16/100 -> 47.970816 | CR38: =CR29*CR16/100 -> 54.021135 | CS38: =CS29*CS16/100 -> 57.079332 | CT38: =CT29*CT16/100 -> 57.136411 | ... DB38: =DB29*DB16/100 -> 57.595106
A39: Total | Y39: =Y38+Y37+Y34 -> 1322.22 | Z39: =Z38+Z37+Z34 -> 2856.95 | AA39: =AA38+AA37+AA34 -> 3234.53 | AB39: =AB38+AB37+AB34 -> 3853.9823 | AC39: =AC38+AC37+AC34 -> 3987.4329 | AD39: =AD38+AD37+AD34 -> 4043.4237 | AE39: =AE38+AE37+AE34 -> 4059.6217 | CC39: =CC38+CC37+CC34 -> 621.1 | CD39: =CD38+CD37+CD34 -> 701.12 | CE39: =CE38+CE37+CE34 -> 693.05 | CF39: =CF38+CF37+CF34 -> 675.61 | CG39: =CG38+CG37+CG34 -> 753.99 | CH39: =CH38+CH37+CH34 -> 734.3 | CI39: =CI38+CI37+CI34 -> 789.77 | CJ39: =CJ38+CJ37+CJ34 -> 786.18 | ... DB39: =DB38+DB37+DB34 -> 1016.4275
A40: Checksum | CC40: =CC57-CC39 -> 0 | CD40: =CD57-CD39 -> 0 | CE40: =CE57-CE39 -> 0 | CF40: =CF57-CF39 -> 0 | CG40: =CG57-CG39 -> 0 | CH40: =CH57-CH39 -> 0 | CI40: =CI57-CI39 -> 0 | CJ40: =CJ57-CJ39 -> 0 | ... CL40: =CL57-CL39 -> 0
A42: Revenue Growth % y-o-y
A43: PV Yarn - % | Z43: =Z32/Y32-1 -> 0.85700158 | AA43: =AA32/Z32-1 -> 0.018838442 | CG43: =CG32/CC32-1 -> -0.035973652 | CH43: =CH32/CD32-1 -> 0.087605984 | CI43: =CI32/CE32-1 -> -0.16724679 | CJ43: =CJ32/CF32-1 -> 0.21655312 | CK43: =CK32/CG32-1 -> -0.010638219 | CL43: =CL32/CH32-1 -> 0.070007717
A44: Cotton Yarn - % | Z44: =Z33/Y33-1 -> 1.8384972 | AA44: =AA33/Z33-1 -> 0.26962557 | CG44: =CG33/CC33-1 -> 0.82093866 | CH44: =CH33/CD33-1 -> 0.29668721 | CI44: =CI33/CE33-1 -> 0.29495117 | CJ44: =CJ33/CF33-1 -> 0.29792791 | CK44: =CK33/CG33-1 -> 0.24145877 | CL44: =CL33/CH33-1 -> 0.25005709
A45: Spinning (PV + Cotton Yarn) - % | Z45: =Z34/Y34-1 -> 1.2351561 | AA45: =AA34/Z34-1 -> 0.14154473 | AB45: =AB34/AA34-1 -> 0.23486621 | AC45: =AC34/AB34-1 -> 0.026788873 | AD45: =AD34/AC34-1 -> 0.017514605 | AE45: =AE34/AD34-1 -> 0.004006004 | CG45: =CG34/CC34-1 -> 0.23823829 | CH45: =CH34/CD34-1 -> 0.18102525 | CI45: =CI34/CE34-1 -> 0.044593945 | CJ45: =CJ34/CF34-1 -> 0.26063113 | CK45: =CK34/CG34-1 -> 0.10799566 | CL45: =CL34/CH34-1 -> 0.15833383 | CM45: =CM34/CI34-1 -> 0.44873128 | CN45: =CN34/CJ34-1 -> 0.23267869 | ... DB45: =DB34/CX34-1 -> 0.004006004
A46: Denim Fabric - % | Z46: =Z35/Y35-1 -> 1.2888786 | AA46: =AA35/Z35-1 -> 0.053936407 | AB46: =AB35/AA35-1 -> 0.21629368 | AC46: =AC35/AB35-1 -> 0.004006004 | AD46: =AD35/AC35-1 -> 0.004006004 | AE46: =AE35/AD35-1 -> 0.004006004 | CG46: =CG35/CC35-1 -> 0.50530929 | CH46: =CH35/CD35-1 -> 0.012413472 | CI46: =CI35/CE35-1 -> -0.01762325 | CJ46: =CJ35/CF35-1 -> 0.16365951 | CK46: =CK35/CG35-1 -> -0.07201302 | CL46: =CL35/CH35-1 -> 0.16224976 | CM46: =CM35/CI35-1 -> 0.35625969 | CN46: =CN35/CJ35-1 -> 0.21769227 | ... DB46: =DB35/CX35-1 -> 0.004006004
...

Sheet Sheet1
C3: 18 | D3: 19 | E3: 20 | F3: 21 | G3: 22 | H3: 23 | I3: 24 | J3: 25
A5: Yarn (MTPA) | F5: 85500 | I5: 103140 | J5: 114420
A7: Weaving (MMPA)
B8: PV Fabric (weaving) | F8: 30 | G8: 30 | H8: 32.4 | I8: 48 | J8: 48
B9: Fabric (processing) | F9: 72 | G9: 72 | H9: 72 | I9: 72 | J9: 72
B10: Denim Fabric | F10: 48 | G10: 48 | H10: 48 | I10: 48 | J10: 60
A12: Garments | B12: mn pcs | F12: 4 | G12: 5 | H12: 5.6 | I12: 251.94 | J12: 251.94
B13: Processing | F13: 511 | G13: 511

Sheet QTR Raw
A1: ='Annual Raw'!A1 -> 114234 | B1: X | C1: 201206 | D1: 201209 | E1: 201212 | F1: 201303 | G1: 201306 | H1: 201309 | I1: 201312 | J1: 201403 | K1: 201406 | L1: 201409 | M1: 201412 | N1: 201503 | O1: 201506 | P1: 201509 | Q1: 201512 | R1: 201603 | S1: 201606 | T1: 201609 | U1: 201612 | V1: 201703 | W1: 201706 | X1: 201709 | Y1: 201712 | Z1: 201803 | AA1: 201806 | AB1: 201809 | AC1: 201812 | AD1: 201903 | AE1: 201906 | AF1: 201909 | AG1: 201912 | AH1: 202003 | AI1: 202006 | AJ1: 202009 | AK1: 202012 | AL1: 202103 | AM1: 202106 | AN1: 202109 | AO1: 202112 | AP1: 202203 | AQ1: 202206 | AR1: 202209 | AS1: 202212 | AT1: 202303 | AU1: 202306 | AV1: 202309 | AW1: 202312 | AX1: 202403 | AY1: 202406 | AZ1: 202409 | BA1: 202412 | BB1: 202503 | BC1: 202506 | BD1: 202509 | BE1: 202512 | BF1: 202603 | BG1: 202606 | BH1: 202609 | BI1: 202612 | BJ1: 202703 | BK1: 202706 | BL1: 202709 | BM1: 202712 | BN1: 202803 | BO1: 202806 | BP1: 202809 | BQ1: 202812 | BR1: 202903 | BS1: 202906 | BT1: 202909 | BU1: 202912 | BV1: 203003
A3: Field Description | B3: Field Name
A4: Company Name | B4: CD_COMPNAME | C4: =_xll.EQNXTDZ(A1,B4,C1) -> Sangam (India) Ltd.
A5: Date End | B5: QTR_DATE_END | C5: =_xll.EQNXTDZ($A$1,$B5,C$1,$B$1) -> 201206 | D5: =_xll.EQNXTDZ($A$1,$B5,D$1,$B$1) -> 201209 | E5: =_xll.EQNXTDZ($A$1,$B5,E$1,$B$1) -> 201212 | F5: =_xll.EQNXTDZ($A$1,$B5,F$1,$B$1) -> 201303 | G5: =_xll.EQNXTDZ($A$1,$B5,G$1,$B$1) -> 201306 | H5: =_xll.EQNXTDZ($A$1,$B5,H$1,$B$1) -> 201309 | I5: =_xll.EQNXTDZ($A$1,$B5,I$1,$B$1) -> 201312 | J5: =_xll.EQNXTDZ($A$1,$B5,J$1,$B$1) -> 201403 | ... BV5: =_xll.EQNXTDZ($A$1,$B5,BV$1,$B$1) -> 0
A6: Gross Sales | B6: QTR_GROSS_SALE | C6: =_xll.EQNXTDZ($A$1,$B6,C$1,$B$1) -> 411.09 | D6: =_xll.EQNXTDZ($A$1,$B6,D$1,$B$1) -> 384.06 | E6: =_xll.EQNXTDZ($A$1,$B6,E$1,$B$1) -> 327.96 | F6: =_xll.EQNXTDZ($A$1,$B6,F$1,$B$1) -> 355.73 | G6: =_xll.EQNXTDZ($A$1,$B6,G$1,$B$1) -> 365.8 | H6: =_xll.EQNXTDZ($A$1,$B6,H$1,$B$1) -> 351.4 | I6: =_xll.EQNXTDZ($A$1,$B6,I$1,$B$1) -> 347.89 | J6: =_xll.EQNXTDZ($A$1,$B6,J$1,$B$1) -> 367.52 | ... BV6: =_xll.EQNXTDZ($A$1,$B6,BV$1,$B$1) -> 0
A7: Less: Excise Duty | B7: QTR_EXCISE_DUTY | C7: =_xll.EQNXTDZ($A$1,$B7,C$1,$B$1) -> 0 | D7: =_xll.EQNXTDZ($A$1,$B7,D$1,$B$1) -> 0 | E7: =_xll.EQNXTDZ($A$1,$B7,E$1,$B$1) -> 0 | F7: =_xll.EQNXTDZ($A$1,$B7,F$1,$B$1) -> 0 | G7: =_xll.EQNXTDZ($A$1,$B7,G$1,$B$1) -> 0 | H7: =_xll.EQNXTDZ($A$1,$B7,H$1,$B$1) -> 0 | I7: =_xll.EQNXTDZ($A$1,$B7,I$1,$B$1) -> 0 | J7: =_xll.EQNXTDZ($A$1,$B7,J$1,$B$1) -> 0 | ... BV7: =_xll.EQNXTDZ($A$1,$B7,BV$1,$B$1) -> 0
A8: Other operating income | B8: QTR_JOB_WORKS | C8: =_xll.EQNXTDZ($A$1,$B8,C$1,$B$1) -> 1.45 | D8: =_xll.EQNXTDZ($A$1,$B8,D$1,$B$1) -> 1.6 | E8: =_xll.EQNXTDZ($A$1,$B8,E$1,$B$1) -> 1.5 | F8: =_xll.EQNXTDZ($A$1,$B8,F$1,$B$1) -> 1.53 | G8: =_xll.EQNXTDZ($A$1,$B8,G$1,$B$1) -> 1.82 | H8: =_xll.EQNXTDZ($A$1,$B8,H$1,$B$1) -> 1.64 | I8: =_xll.EQNXTDZ($A$1,$B8,I$1,$B$1) -> 1.69 | J8: =_xll.EQNXTDZ($A$1,$B8,J$1,$B$1) -> 1.86 | ... BV8: =_xll.EQNXTDZ($A$1,$B8,BV$1,$B$1) -> 0
A9: Net Sales & Other Operating Income | B9: QTR_NET_SALES | C9: =_xll.EQNXTDZ($A$1,$B9,C$1,$B$1) -> 412.54 | D9: =_xll.EQNXTDZ($A$1,$B9,D$1,$B$1) -> 385.66 | E9: =_xll.EQNXTDZ($A$1,$B9,E$1,$B$1) -> 329.46 | F9: =_xll.EQNXTDZ($A$1,$B9,F$1,$B$1) -> 357.26 | G9: =_xll.EQNXTDZ($A$1,$B9,G$1,$B$1) -> 367.62 | H9: =_xll.EQNXTDZ($A$1,$B9,H$1,$B$1) -> 353.04 | I9: =_xll.EQNXTDZ($A$1,$B9,I$1,$B$1) -> 349.58 | J9: =_xll.EQNXTDZ($A$1,$B9,J$1,$B$1) -> 369.38 | ... BV9: =_xll.EQNXTDZ($A$1,$B9,BV$1,$B$1) -> 0
A10: (Increase) / Decrease In Stocks | B10: QTR_INC_DEC_INVENTORY | C10: =_xll.EQNXTDZ($A$1,$B10,C$1,$B$1) -> 11.8 | D10: =_xll.EQNXTDZ($A$1,$B10,D$1,$B$1) -> -23.48 | E10: =_xll.EQNXTDZ($A$1,$B10,E$1,$B$1) -> 9.31 | F10: =_xll.EQNXTDZ($A$1,$B10,F$1,$B$1) -> -14.47 | G10: =_xll.EQNXTDZ($A$1,$B10,G$1,$B$1) -> 22.28 | H10: =_xll.EQNXTDZ($A$1,$B10,H$1,$B$1) -> -21.76 | I10: =_xll.EQNXTDZ($A$1,$B10,I$1,$B$1) -> -13.23 | J10: =_xll.EQNXTDZ($A$1,$B10,J$1,$B$1) -> 1.59 | ... BV10: =_xll.EQNXTDZ($A$1,$B10,BV$1,$B$1) -> 0
A11: Cost of Services & Raw Materials | B11: QTR_RAW_MATERIAL_COST | C11: =_xll.EQNXTDZ($A$1,$B11,C$1,$B$1) -> 203.73 | D11: =_xll.EQNXTDZ($A$1,$B11,D$1,$B$1) -> 225.81 | E11: =_xll.EQNXTDZ($A$1,$B11,E$1,$B$1) -> 183.37 | F11: =_xll.EQNXTDZ($A$1,$B11,F$1,$B$1) -> 221.43 | G11: =_xll.EQNXTDZ($A$1,$B11,G$1,$B$1) -> 186.1 | H11: =_xll.EQNXTDZ($A$1,$B11,H$1,$B$1) -> 210.12 | I11: =_xll.EQNXTDZ($A$1,$B11,I$1,$B$1) -> 214.51 | J11: =_xll.EQNXTDZ($A$1,$B11,J$1,$B$1) -> 216.54 | ... BV11: =_xll.EQNXTDZ($A$1,$B11,BV$1,$B$1) -> 0
A12: Purchase of Finished Goods | B12: QTR_PURCHASE_FIN_GOOD | C12: =_xll.EQNXTDZ($A$1,$B12,C$1,$B$1) -> 0 | D12: =_xll.EQNXTDZ($A$1,$B12,D$1,$B$1) -> 0 | E12: =_xll.EQNXTDZ($A$1,$B12,E$1,$B$1) -> 0 | F12: =_xll.EQNXTDZ($A$1,$B12,F$1,$B$1) -> 0 | G12: =_xll.EQNXTDZ($A$1,$B12,G$1,$B$1) -> 0 | H12: =_xll.EQNXTDZ($A$1,$B12,H$1,$B$1) -> 0 | I12: =_xll.EQNXTDZ($A$1,$B12,I$1,$B$1) -> 0 | J12: =_xll.EQNXTDZ($A$1,$B12,J$1,$B$1) -> 0 | ... BV12: =_xll.EQNXTDZ($A$1,$B12,BV$1,$B$1) -> 0
A13: Excise Duty | B13: QTR_EXCISE | C13: =_xll.EQNXTDZ($A$1,$B13,C$1,$B$1) -> 0 | D13: =_xll.EQNXTDZ($A$1,$B13,D$1,$B$1) -> 0 | E13: =_xll.EQNXTDZ($A$1,$B13,E$1,$B$1) -> 0 | F13: =_xll.EQNXTDZ($A$1,$B13,F$1,$B$1) -> 0 | G13: =_xll.EQNXTDZ($A$1,$B13,G$1,$B$1) -> 0 | H13: =_xll.EQNXTDZ($A$1,$B13,H$1,$B$1) -> 0 | I13: =_xll.EQNXTDZ($A$1,$B13,I$1,$B$1) -> 0 | J13: =_xll.EQNXTDZ($A$1,$B13,J$1,$B$1) -> 0 | ... BV13: =_xll.EQNXTDZ($A$1,$B13,BV$1,$B$1) -> 0
A14: Operating & Manufacturing Expenses | B14: QTR_MFG_EXPS | C14: =_xll.EQNXTDZ($A$1,$B14,C$1,$B$1) -> 86.1 | D14: =_xll.EQNXTDZ($A$1,$B14,D$1,$B$1) -> 59.2 | E14: =_xll.EQNXTDZ($A$1,$B14,E$1,$B$1) -> 29.18 | F14: =_xll.EQNXTDZ($A$1,$B14,F$1,$B$1) -> 41.63 | G14: =_xll.EQNXTDZ($A$1,$B14,G$1,$B$1) -> 54.79 | H14: =_xll.EQNXTDZ($A$1,$B14,H$1,$B$1) -> 52.5 | I14: =_xll.EQNXTDZ($A$1,$B14,I$1,$B$1) -> 28.14 | J14: =_xll.EQNXTDZ($A$1,$B14,J$1,$B$1) -> 34.57 | ... BV14: =_xll.EQNXTDZ($A$1,$B14,BV$1,$B$1) -> 0
A15: Electricity Power & Fuel Cost | B15: QTR_ELECTRICITY_POWER_FUEL | C15: =_xll.EQNXTDZ($A$1,$B15,C$1,$B$1) -> 36.21 | D15: =_xll.EQNXTDZ($A$1,$B15,D$1,$B$1) -> 38.58 | E15: =_xll.EQNXTDZ($A$1,$B15,E$1,$B$1) -> 34.23 | F15: =_xll.EQNXTDZ($A$1,$B15,F$1,$B$1) -> 33.62 | G15: =_xll.EQNXTDZ($A$1,$B15,G$1,$B$1) -> 32.77 | H15: =_xll.EQNXTDZ($A$1,$B15,H$1,$B$1) -> 34.32 | I15: =_xll.EQNXTDZ($A$1,$B15,I$1,$B$1) -> 35.28 | J15: =_xll.EQNXTDZ($A$1,$B15,J$1,$B$1) -> 36.21 | ... BV15: =_xll.EQNXTDZ($A$1,$B15,BV$1,$B$1) -> 0
A16: Employee Cost | B16: QTR_EXPLOYEE_COST | C16: =_xll.EQNXTDZ($A$1,$B16,C$1,$B$1) -> 22.78 | D16: =_xll.EQNXTDZ($A$1,$B16,D$1,$B$1) -> 24.72 | E16: =_xll.EQNXTDZ($A$1,$B16,E$1,$B$1) -> 22.07 | F16: =_xll.EQNXTDZ($A$1,$B16,F$1,$B$1) -> 24.65 | G16: =_xll.EQNXTDZ($A$1,$B16,G$1,$B$1) -> 25.51 | H16: =_xll.EQNXTDZ($A$1,$B16,H$1,$B$1) -> 27.64 | I16: =_xll.EQNXTDZ($A$1,$B16,I$1,$B$1) -> 26.14 | J16: =_xll.EQNXTDZ($A$1,$B16,J$1,$B$1) -> 25.96 | ... BV16: =_xll.EQNXTDZ($A$1,$B16,BV$1,$B$1) -> 0
... A42: Consolidated PAT(after extra items) | B42: QTR_CONS_PAT_EXITM | C42: =_xll.EQNXTDZ($A$1,$B42,C$1,$B$1) -> 9.77 | D42: =_xll.EQNXTDZ($A$1,$B42,D$1,$B$1) -> 18.09 | E42: =_xll.EQNXTDZ($A$1,$B42,E$1,$B$1) -> 11.07 | F42: =_xll.EQNXTDZ($A$1,$B42,F$1,$B$1) -> 12.37 | G42: =_xll.EQNXTDZ($A$1,$B42,G$1,$B$1) -> 6.03 | H42: =_xll.EQNXTDZ($A$1,$B42,H$1,$B$1) -> 12.24 | I42: =_xll.EQNXTDZ($A$1,$B42,I$1,$B$1) -> 12.15 | J42: =_xll.EQNXTDZ($A$1,$B42,J$1,$B$1) -> 10.08 | ... BV42: =_xll.EQNXTDZ($A$1,$B42,BV$1,$B$1) -> 0
A44: Field Description | B44: Field Name
A45: Equity Capital | B45: QTR_EQUITY_CAP | C45: =_xll.EQNXTDZ($A$1,$B45,C$1,$B$1) -> 39.42 | D45: =_xll.EQNXTDZ($A$1,$B45,D$1,$B$1) -> 39.42 | E45: =_xll.EQNXTDZ($A$1,$B45,E$1,$B$1) -> 39.42 | F45: =_xll.EQNXTDZ($A$1,$B45,F$1,$B$1) -> 39.42 | G45: =_xll.EQNXTDZ($A$1,$B45,G$1,$B$1) -> 39.42 | H45: =_xll.EQNXTDZ($A$1,$B45,H$1,$B$1) -> 39.42 | I45: =_xll.EQNXTDZ($A$1,$B45,I$1,$B$1) -> 39.42 | J45: =_xll.EQNXTDZ($A$1,$B45,J$1,$B$1) -> 39.42 | ... BV45: =_xll.EQNXTDZ($A$1,$B45,BV$1,$B$1) -> 0
A46: Face Value | B46: QTR_FV | C46: =_xll.EQNXTDZ($A$1,$B46,C$1,$B$1) -> 10 | D46: =_xll.EQNXTDZ($A$1,$B46,D$1,$B$1) -> 10 | E46: =_xll.EQNXTDZ($A$1,$B46,E$1,$B$1) -> 10 | F46: =_xll.EQNXTDZ($A$1,$B46,F$1,$B$1) -> 10 | G46: =_xll.EQNXTDZ($A$1,$B46,G$1,$B$1) -> 10 | H46: =_xll.EQNXTDZ($A$1,$B46,H$1,$B$1) -> 10 | I46: =_xll.EQNXTDZ($A$1,$B46,I$1,$B$1) -> 10 | J46: =_xll.EQNXTDZ($A$1,$B46,J$1,$B$1) -> 10 | ... BV46: =_xll.EQNXTDZ($A$1,$B46,BV$1,$B$1) -> 0
A47: Month End | B47: BMONTH_MONTHEND | C47: =_xll.EQNXTDZ($A$1,$B47,C$5) -> 201206 | D47: =_xll.EQNXTDZ($A$1,$B47,D$5) -> 201209 | E47: =_xll.EQNXTDZ($A$1,$B47,E$5) -> 201212 | F47: =_xll.EQNXTDZ($A$1,$B47,F$5) -> 201303 | G47: =_xll.EQNXTDZ($A$1,$B47,G$5) -> 201306 | H47: =_xll.EQNXTDZ($A$1,$B47,H$5) -> 201309 | I47: =_xll.EQNXTDZ($A$1,$B47,I$5) -> 201312 | J47: =_xll.EQNXTDZ($A$1,$B47,J$5) -> 201403 | ... BV47: =_xll.EQNXTDZ($A$1,$B47,BV$5) -> 0
A48: Close | B48: BMONTH_CLOSE | C48: =_xll.EQNXTDZ($A$1,$B48,C$5) -> 47.85 | D48: =_xll.EQNXTDZ($A$1,$B48,D$5) -> 55.75 | E48: =_xll.EQNXTDZ($A$1,$B48,E$5) -> 51 | F48: =_xll.EQNXTDZ($A$1,$B48,F$5) -> 34 | G48: =_xll.EQNXTDZ($A$1,$B48,G$5) -> 41.25 | H48: =_xll.EQNXTDZ($A$1,$B48,H$5) -> 28.05 | I48: =_xll.EQNXTDZ($A$1,$B48,I$5) -> 35.85 | J48: =_xll.EQNXTDZ($A$1,$B48,J$5) -> 35.1 | ... BV48: =_xll.EQNXTDZ($A$1,$B48,BV$5) -> 0
A49: Total of Promoter and Promoter Group | B49: SHP_TPFTOTALPROMOTER | C49: =_xll.EQNXTDZ($A$1,$B49,C$5) -> 36.99 | D49: =_xll.EQNXTDZ($A$1,$B49,D$5) -> 37.99 | E49: =_xll.EQNXTDZ($A$1,$B49,E$5) -> 37.99 | F49: =_xll.EQNXTDZ($A$1,$B49,F$5) -> 38.65 | G49: =_xll.EQNXTDZ($A$1,$B49,G$5) -> 38.65 | H49: =_xll.EQNXTDZ($A$1,$B49,H$5) -> 38.65 | I49: =_xll.EQNXTDZ($A$1,$B49,I$5) -> 38.65 | J49: =_xll.EQNXTDZ($A$1,$B49,J$5) -> 42.8 | ... BV49: =_xll.EQNXTDZ($A$1,$B49,BV$5) -> 0
A50: Total of Promoter and Promoter Group Pledged | B50: SHP_PSHFTOTALPROMOTER | C50: =_xll.EQNXTDZ($A$1,$B50,C$5) -> 21.26 | D50: =_xll.EQNXTDZ($A$1,$B50,D$5) -> 20.7 | E50: =_xll.EQNXTDZ($A$1,$B50,E$5) -> 20.7 | F50: =_xll.EQNXTDZ($A$1,$B50,F$5) -> 20.35 | G50: =_xll.EQNXTDZ($A$1,$B50,G$5) -> 20.35 | H50: =_xll.EQNXTDZ($A$1,$B50,H$5) -> 20.35 | I50: =_xll.EQNXTDZ($A$1,$B50,I$5) -> 20.35 | J50: =_xll.EQNXTDZ($A$1,$B50,J$5) -> 0 | ... BV50: =_xll.EQNXTDZ($A$1,$B50,BV$5) -> 0
A54: Field Description | B54: Field Name | C54: =_xll.EQNXTDZ($A$1,$B54,C$5) -> 0 | D54: =_xll.EQNXTDZ($A$1,$B54,D$5) -> 0 | E54: =_xll.EQNXTDZ($A$1,$B54,E$5) -> 0 | F54: =_xll.EQNXTDZ($A$1,$B54,F$5) -> 0 | G54: =_xll.EQNXTDZ($A$1,$B54,G$5) -> 0 | H54: =_xll.EQNXTDZ($A$1,$B54,H$5) -> 0 | I54: =_xll.EQNXTDZ($A$1,$B54,I$5) -> 0 | J54: =_xll.EQNXTDZ($A$1,$B54,J$5) -> 0 | ... BV54: =_xll.EQNXTDZ($A$1,$B54,BV$5) -> 0
A55: Year End | B55: QTRB_DATE_END | C55: =_xll.EQNXTDZ($A$1,$B55,C$5,$B$1) -> 0 | D55: =_xll.EQNXTDZ($A$1,$B55,D$5,$B$1) -> 201209 | E55: =_xll.EQNXTDZ($A$1,$B55,E$5,$B$1) -> 0 | F55: =_xll.EQNXTDZ($A$1,$B55,F$5,$B$1) -> 201303 | G55: =_xll.EQNXTDZ($A$1,$B55,G$5,$B$1) -> 0 | H55: =_xll.EQNXTDZ($A$1,$B55,H$5,$B$1) -> 201309 | I55: =_xll.EQNXTDZ($A$1,$B55,I$5,$B$1) -> 0 | J55: =_xll.EQNXTDZ($A$1,$B55,J$5,$B$1) -> 201403 | ... BV55: =_xll.EQNXTDZ($A$1,$B55,BV$5,$B$1) -> 0
A56: Share Capital | B56: QTRB_SHARE_CAPITAL | C56: =_xll.EQNXTDZ($A$1,$B56,C$5,$B$1) -> 0 | D56: =_xll.EQNXTDZ($A$1,$B56,D$5,$B$1) -> 39.42 | E56: =_xll.EQNXTDZ($A$1,$B56,E$5,$B$1) -> 0 | F56: =_xll.EQNXTDZ($A$1,$B56,F$5,$B$1) -> 39.42 | G56: =_xll.EQNXTDZ($A$1,$B56,G$5,$B$1) -> 0 | H56: =_xll.EQNXTDZ($A$1,$B56,H$5,$B$1) -> 39.42 | I56: =_xll.EQNXTDZ($A$1,$B56,I$5,$B$1) -> 0 | J56: =_xll.EQNXTDZ($A$1,$B56,J$5,$B$1) -> 39.42 | ... BV56: =_xll.EQNXTDZ($A$1,$B56,BV$5,$B$1) -> 0
A57: Share Warrants & outstandings | B57: QTRB_SHAREWARNDOUT | C57: =_xll.EQNXTDZ($A$1,$B57,C$5,$B$1) -> 0 | D57: =_xll.EQNXTDZ($A$1,$B57,D$5,$B$1) -> 0 | E57: =_xll.EQNXTDZ($A$1,$B57,E$5,$B$1) -> 0 | F57: =_xll.EQNXTDZ($A$1,$B57,F$5,$B$1) -> 0 | G57: =_xll.EQNXTDZ($A$1,$B57,G$5,$B$1) -> 0 | H57: =_xll.EQNXTDZ($A$1,$B57,H$5,$B$1) -> 0 | I57: =_xll.EQNXTDZ($A$1,$B57,I$5,$B$1) -> 0 | J57: =_xll.EQNXTDZ($A$1,$B57,J$5,$B$1) -> 0 | ... BV57: =_xll.EQNXTDZ($A$1,$B57,BV$5,$B$1) -> 0
A58: Reserves & Surplus | B58: QTRB_RESERVE | C58: =_xll.EQNXTDZ($A$1,$B58,C$5,$B$1) -> 0 | D58: =_xll.EQNXTDZ($A$1,$B58,D$5,$B$1) -> 240.52 | E58: =_xll.EQNXTDZ($A$1,$B58,E$5,$B$1) -> 0 | F58: =_xll.EQNXTDZ($A$1,$B58,F$5,$B$1) -> 258.43 | G58: =_xll.EQNXTDZ($A$1,$B58,G$5,$B$1) -> 0 | H58: =_xll.EQNXTDZ($A$1,$B58,H$5,$B$1) -> 276.7 | I58: =_xll.EQNXTDZ($A$1,$B58,I$5,$B$1) -> 0 | J58: =_xll.EQNXTDZ($A$1,$B58,J$5,$B$1) -> 292.01 | ... BV58: =_xll.EQNXTDZ($A$1,$B58,BV$5,$B$1) -> 0
A59: Shareholder's Funds | B59: QTRB_SHAREHODERS_FUNDS | C59: =_xll.EQNXTDZ($A$1,$B59,C$5,$B$1) -> 0 | D59: =_xll.EQNXTDZ($A$1,$B59,D$5,$B$1) -> 279.94 | E59: =_xll.EQNXTDZ($A$1,$B59,E$5,$B$1) -> 0 | F59: =_xll.EQNXTDZ($A$1,$B59,F$5,$B$1) -> 297.85 | G59: =_xll.EQNXTDZ($A$1,$B59,G$5,$B$1) -> 0 | H59: =_xll.EQNXTDZ($A$1,$B59,H$5,$B$1) -> 316.12 | I59: =_xll.EQNXTDZ($A$1,$B59,I$5,$B$1) -> 0 | J59: =_xll.EQNXTDZ($A$1,$B59,J$5,$B$1) -> 331.43 | ... BV59: =_xll.EQNXTDZ($A$1,$B59,BV$5,$B$1) -> 0
A60: Minority Interest | B60: QTRB_MINORITY_INTEREST_BS | C60: =_xll.EQNXTDZ($A$1,$B60,C$5,$B$1) -> 0 | D60: =_xll.EQNXTDZ($A$1,$B60,D$5,$B$1) -> 0 | E60: =_xll.EQNXTDZ($A$1,$B60,E$5,$B$1) -> 0 | F60: =_xll.EQNXTDZ($A$1,$B60,F$5,$B$1) -> 0 | G60: =_xll.EQNXTDZ($A$1,$B60,G$5,$B$1) -> 0 | H60: =_xll.EQNXTDZ($A$1,$B60,H$5,$B$1) -> 0 | I60: =_xll.EQNXTDZ($A$1,$B60,I$5,$B$1) -> 0 | J60: =_xll.EQNXTDZ($A$1,$B60,J$5,$B$1) -> 0 | ... BV60: =_xll.EQNXTDZ($A$1,$B60,BV$5,$B$1) -> 0
A61: Long Term Borrowings | B61: QTRB_TOTAL_DEBTS | C61: =_xll.EQNXTDZ($A$1,$B61,C$5,$B$1) -> 0 | D61: =_xll.EQNXTDZ($A$1,$B61,D$5,$B$1) -> 387.85 | E61: =_xll.EQNXTDZ($A$1,$B61,E$5,$B$1) -> 0 | F61: =_xll.EQNXTDZ($A$1,$B61,F$5,$B$1) -> 344.86 | G61: =_xll.EQNXTDZ($A$1,$B61,G$5,$B$1) -> 0 | H61: =_xll.EQNXTDZ($A$1,$B61,H$5,$B$1) -> 296.25 | I61: =_xll.EQNXTDZ($A$1,$B61,I$5,$B$1) -> 0 | J61: =_xll.EQNXTDZ($A$1,$B61,J$5,$B$1) -> 275.86 | ... BV61: =_xll.EQNXTDZ($A$1,$B61,BV$5,$B$1) -> 0
A62: Secured Loans | B62: QTRB_SECURED_LOANS | C62: =_xll.EQNXTDZ($A$1,$B62,C$5,$B$1) -> 0 | D62: =_xll.EQNXTDZ($A$1,$B62,D$5,$B$1) -> 0 | E62: =_xll.EQNXTDZ($A$1,$B62,E$5,$B$1) -> 0 | F62: =_xll.EQNXTDZ($A$1,$B62,F$5,$B$1) -> 0 | G62: =_xll.EQNXTDZ($A$1,$B62,G$5,$B$1) -> 0 | H62: =_xll.EQNXTDZ($A$1,$B62,H$5,$B$1) -> 0 | I62: =_xll.EQNXTDZ($A$1,$B62,I$5,$B$1) -> 0 | J62: =_xll.EQNXTDZ($A$1,$B62,J$5,$B$1) -> 0 | ... BV62: =_xll.EQNXTDZ($A$1,$B62,BV$5,$B$1) -> 0
A63: Unsecured Loans | B63: QTRB_UNSECURED_LOANS_NF | C63: =_xll.EQNXTDZ($A$1,$B63,C$5,$B$1) -> 0 | D63: =_xll.EQNXTDZ($A$1,$B63,D$5,$B$1) -> 387.85 | E63: =_xll.EQNXTDZ($A$1,$B63,E$5,$B$1) -> 0 | F63: =_xll.EQNXTDZ($A$1,$B63,F$5,$B$1) -> 344.86 | G63: =_xll.EQNXTDZ($A$1,$B63,G$5,$B$1) -> 0 | H63: =_xll.EQNXTDZ($A$1,$B63,H$5,$B$1) -> 296.25 | I63: =_xll.EQNXTDZ($A$1,$B63,I$5,$B$1) -> 0 | J63: =_xll.EQNXTDZ($A$1,$B63,J$5,$B$1) -> 275.86 | ... BV63: =_xll.EQNXTDZ($A$1,$B63,BV$5,$B$1) -> 0
A64: Other Long Term Liabilities | B64: QTRB_OTHER_LT_LIABILITIES | C64: =_xll.EQNXTDZ($A$1,$B64,C$5,$B$1) -> 0 | D64: =_xll.EQNXTDZ($A$1,$B64,D$5,$B$1) -> 0 | E64: =_xll.EQNXTDZ($A$1,$B64,E$5,$B$1) -> 0 | F64: =_xll.EQNXTDZ($A$1,$B64,F$5,$B$1) -> 0 | G64: =_xll.EQNXTDZ($A$1,$B64,G$5,$B$1) -> 0 | H64: =_xll.EQNXTDZ($A$1,$B64,H$5,$B$1) -> 0 | I64: =_xll.EQNXTDZ($A$1,$B64,I$5,$B$1) -> 0 | J64: =_xll.EQNXTDZ($A$1,$B64,J$5,$B$1) -> 0 | ... BV64: =_xll.EQNXTDZ($A$1,$B64,BV$5,$B$1) -> 0
A65: Long Term Trade Payables | B65: QTRB_LT_TRADE_PAYABLE | C65: =_xll.EQNXTDZ($A$1,$B65,C$5,$B$1) -> 0 | D65: =_xll.EQNXTDZ($A$1,$B65,D$5,$B$1) -> 0 | E65: =_xll.EQNXTDZ($A$1,$B65,E$5,$B$1) -> 0 | F65: =_xll.EQNXTDZ($A$1,$B65,F$5,$B$1) -> 0 | G65: =_xll.EQNXTDZ($A$1,$B65,G$5,$B$1) -> 0 | H65: =_xll.EQNXTDZ($A$1,$B65,H$5,$B$1) -> 0 | I65: =_xll.EQNXTDZ($A$1,$B65,I$5,$B$1) -> 0 | J65: =_xll.EQNXTDZ($A$1,$B65,J$5,$B$1) -> 0 | ... BV65: =_xll.EQNXTDZ($A$1,$B65,BV$5,$B$1) -> 0
A66: Lont Term Provisions | B66: QTRB_LT_PROVISIONS | C66: =_xll.EQNXTDZ($A$1,$B66,C$5,$B$1) -> 0 | D66: =_xll.EQNXTDZ($A$1,$B66,D$5,$B$1) -> 0 | E66: =_xll.EQNXTDZ($A$1,$B66,E$5,$B$1) -> 0 | F66: =_xll.EQNXTDZ($A$1,$B66,F$5,$B$1) -> 0 | G66: =_xll.EQNXTDZ($A$1,$B66,G$5,$B$1) -> 0 | H66: =_xll.EQNXTDZ($A$1,$B66,H$5,$B$1) -> 0 | I66: =_xll.EQNXTDZ($A$1,$B66,I$5,$B$1) -> 0 | J66: =_xll.EQNXTDZ($A$1,$B66,J$5,$B$1) -> 0 | ... BV66: =_xll.EQNXTDZ($A$1,$B66,BV$5,$B$1) -> 0
... A97: Total Assets | B97: QTRB_TOTAL_APPLICATIONS | C97: =_xll.EQNXTDZ($A$1,$B97,C$5,$B$1) -> 0 | D97: =_xll.EQNXTDZ($A$1,$B97,D$5,$B$1) -> 667.79 | E97: =_xll.EQNXTDZ($A$1,$B97,E$5,$B$1) -> 0 | F97: =_xll.EQNXTDZ($A$1,$B97,F$5,$B$1) -> 642.71 | G97: =_xll.EQNXTDZ($A$1,$B97,G$5,$B$1) -> 0 | H97: =_xll.EQNXTDZ($A$1,$B97,H$5,$B$1) -> 612.37 | I97: =_xll.EQNXTDZ($A$1,$B97,I$5,$B$1) -> 0 | J97: =_xll.EQNXTDZ($A$1,$B97,J$5,$B$1) -> 607.27 | ... BV97: =_xll.EQNXTDZ($A$1,$B97,BV$5,$B$1) -> 0

Sheet Sheet3

Sheet Annual Raw
A1: 114234 | B1: X | C1: 200103 | D1: 200203 | E1: 200303 | F1: 200403 | G1: 200503 | H1: 200603 | I1: 200703 | J1: 200803 | K1: 200903 | L1: 201003 | M1: 201103 | N1: 201203 | O1: 201303 | P1: 201403 | Q1: 201503 | R1: 201603 | S1: 201703 | T1: 201803 | U1: 201903 | V1: 202003 | W1: 202103 | X1: 202203 | Y1: 202303 | Z1: 202403 | AA1: 202503 | AB1: 202603 | AC1: 202703 | AD1: 202803 | AE1: 202903 | AF1: 203003
A3: Field Description | B3: Field Name
A4: Company Name | B4: CD_COMPNAME | C4: =_xll.EQNXTDZ(A1,B4,"L") -> Sangam (India) Ltd.
A5: Year End | B5: PL_YEAR_END | C5: =_xll.EQNXTDZ($A$1,$B5,C$1,$B$1) -> 200103 | D5: =_xll.EQNXTDZ($A$1,$B5,D$1,$B$1) -> 200203 | E5: =_xll.EQNXTDZ($A$1,$B5,E$1,$B$1) -> 200303 | F5: =_xll.EQNXTDZ($A$1,$B5,F$1,$B$1) -> 200403 | G5: =_xll.EQNXTDZ($A$1,$B5,G$1,$B$1) -> 200503 | H5: =_xll.EQNXTDZ($A$1,$B5,H$1,$B$1) -> 200603 | I5: =_xll.EQNXTDZ($A$1,$B5,I$1,$B$1) -> 200703 | J5: =_xll.EQNXTDZ($A$1,$B5,J$1,$B$1) -> 200803 | ... AF5: =_xll.EQNXTDZ($A$1,$B5,AF$1,$B$1) -> 0
A6: Sales Turnover | B6: PL_TOTAL_GROSS_SALES | C6: =_xll.EQNXTDZ($A$1,$B6,C$1,$B$1) -> 228.61852 | D6: =_xll.EQNXTDZ($A$1,$B6,D$1,$B$1) -> 217.23503 | E6: =_xll.EQNXTDZ($A$1,$B6,E$1,$B$1) -> 225.45649 | F6: =_xll.EQNXTDZ($A$1,$B6,F$1,$B$1) -> 298.60219 | G6: =_xll.EQNXTDZ($A$1,$B6,G$1,$B$1) -> 311.36159 | H6: =_xll.EQNXTDZ($A$1,$B6,H$1,$B$1) -> 363.44456 | I6: =_xll.EQNXTDZ($A$1,$B6,I$1,$B$1) -> 554.76021 | J6: =_xll.EQNXTDZ($A$1,$B6,J$1,$B$1) -> 695.05185 | ... AF6: =_xll.EQNXTDZ($A$1,$B6,AF$1,$B$1) -> 0
A7: Less: Inter divisional transfers | B7: PL_INTER_DIV_TRF | C7: =_xll.EQNXTDZ($A$1,$B7,C$1,$B$1) -> 20.628236 | D7: =_xll.EQNXTDZ($A$1,$B7,D$1,$B$1) -> 0 | E7: =_xll.EQNXTDZ($A$1,$B7,E$1,$B$1) -> 0 | F7: =_xll.EQNXTDZ($A$1,$B7,F$1,$B$1) -> 0 | G7: =_xll.EQNXTDZ($A$1,$B7,G$1,$B$1) -> 0 | H7: =_xll.EQNXTDZ($A$1,$B7,H$1,$B$1) -> 0 | I7: =_xll.EQNXTDZ($A$1,$B7,I$1,$B$1) -> 0 | J7: =_xll.EQNXTDZ($A$1,$B7,J$1,$B$1) -> 0 | ... AF7: =_xll.EQNXTDZ($A$1,$B7,AF$1,$B$1) -> 0
A8: Less: Sales Returns | B8: PL_SALES_RETURN | C8: =_xll.EQNXTDZ($A$1,$B8,C$1,$B$1) -> 0 | D8: =_xll.EQNXTDZ($A$1,$B8,D$1,$B$1) -> 0 | E8: =_xll.EQNXTDZ($A$1,$B8,E$1,$B$1) -> 0 | F8: =_xll.EQNXTDZ($A$1,$B8,F$1,$B$1) -> 0 | G8: =_xll.EQNXTDZ($A$1,$B8,G$1,$B$1) -> 0 | H8: =_xll.EQNXTDZ($A$1,$B8,H$1,$B$1) -> 0 | I8: =_xll.EQNXTDZ($A$1,$B8,I$1,$B$1) -> 0 | J8: =_xll.EQNXTDZ($A$1,$B8,J$1,$B$1) -> 0 | ... AF8: =_xll.EQNXTDZ($A$1,$B8,AF$1,$B$1) -> 0
A9: Less: Excise | B9: PL_EXCISE | C9: =_xll.EQNXTDZ($A$1,$B9,C$1,$B$1) -> 24.499193 | D9: =_xll.EQNXTDZ($A$1,$B9,D$1,$B$1) -> 27.553137 | E9: =_xll.EQNXTDZ($A$1,$B9,E$1,$B$1) -> 29.747753 | F9: =_xll.EQNXTDZ($A$1,$B9,F$1,$B$1) -> 31.447642 | G9: =_xll.EQNXTDZ($A$1,$B9,G$1,$B$1) -> 21.784497 | H9: =_xll.EQNXTDZ($A$1,$B9,H$1,$B$1) -> 16.657603 | I9: =_xll.EQNXTDZ($A$1,$B9,I$1,$B$1) -> 2.4015717 | J9: =_xll.EQNXTDZ($A$1,$B9,J$1,$B$1) -> 1.6698029 | ... AF9: =_xll.EQNXTDZ($A$1,$B9,AF$1,$B$1) -> 0
A10: Net Sales | B10: PL_NET_SALES | C10: =_xll.EQNXTDZ($A$1,$B10,C$1,$B$1) -> 183.49109 | D10: =_xll.EQNXTDZ($A$1,$B10,D$1,$B$1) -> 189.68189 | E10: =_xll.EQNXTDZ($A$1,$B10,E$1,$B$1) -> 195.70873 | F10: =_xll.EQNXTDZ($A$1,$B10,F$1,$B$1) -> 267.15454 | G10: =_xll.EQNXTDZ($A$1,$B10,G$1,$B$1) -> 289.57709 | H10: =_xll.EQNXTDZ($A$1,$B10,H$1,$B$1) -> 346.78696 | I10: =_xll.EQNXTDZ($A$1,$B10,I$1,$B$1) -> 552.35864 | J10: =_xll.EQNXTDZ($A$1,$B10,J$1,$B$1) -> 693.38204 | ... AF10: =_xll.EQNXTDZ($A$1,$B10,AF$1,$B$1) -> 0
A11: Increase/Decrease in Stock | B11: PL_INC_DEC_INVENTORY | C11: =_xll.EQNXTDZ($A$1,$B11,C$1,$B$1) -> -0.5067473 | D11: =_xll.EQNXTDZ($A$1,$B11,D$1,$B$1) -> 3.5157219 | E11: =_xll.EQNXTDZ($A$1,$B11,E$1,$B$1) -> -7.2267181 | F11: =_xll.EQNXTDZ($A$1,$B11,F$1,$B$1) -> -2.8291686 | G11: =_xll.EQNXTDZ($A$1,$B11,G$1,$B$1) -> -5.3305705 | H11: =_xll.EQNXTDZ($A$1,$B11,H$1,$B$1) -> -6.716897 | I11: =_xll.EQNXTDZ($A$1,$B11,I$1,$B$1) -> -20.445548 | J11: =_xll.EQNXTDZ($A$1,$B11,J$1,$B$1) -> -21.801716 | ... AF11: =_xll.EQNXTDZ($A$1,$B11,AF$1,$B$1) -> 0
A12: Raw Material Consumed | B12: PL_RAW_MATRS_CONSUMED | C12: =_xll.EQNXTDZ($A$1,$B12,C$1,$B$1) -> 108.21479 | D12: =_xll.EQNXTDZ($A$1,$B12,D$1,$B$1) -> 106.92158 | E12: =_xll.EQNXTDZ($A$1,$B12,E$1,$B$1) -> 120.69857 | F12: =_xll.EQNXTDZ($A$1,$B12,F$1,$B$1) -> 163.01752 | G12: =_xll.EQNXTDZ($A$1,$B12,G$1,$B$1) -> 177.16084 | H12: =_xll.EQNXTDZ($A$1,$B12,H$1,$B$1) -> 202.08444 | I12: =_xll.EQNXTDZ($A$1,$B12,I$1,$B$1) -> 331.10324 | J12: =_xll.EQNXTDZ($A$1,$B12,J$1,$B$1) -> 434.69338 | ... AF12: =_xll.EQNXTDZ($A$1,$B12,AF$1,$B$1) -> 0
A13: Power & Fuel Cost | B13: PL_POWER_FUEL | C13: =_xll.EQNXTDZ($A$1,$B13,C$1,$B$1) -> 16.030761 | D13: =_xll.EQNXTDZ($A$1,$B13,D$1,$B$1) -> 14.32233 | E13: =_xll.EQNXTDZ($A$1,$B13,E$1,$B$1) -> 16.242541 | F13: =_xll.EQNXTDZ($A$1,$B13,F$1,$B$1) -> 24.662792 | G13: =_xll.EQNXTDZ($A$1,$B13,G$1,$B$1) -> 26.673482 | H13: =_xll.EQNXTDZ($A$1,$B13,H$1,$B$1) -> 27.422207 | I13: =_xll.EQNXTDZ($A$1,$B13,I$1,$B$1) -> 56.216065 | J13: =_xll.EQNXTDZ($A$1,$B13,J$1,$B$1) -> 75.572922 | ... AF13: =_xll.EQNXTDZ($A$1,$B13,AF$1,$B$1) -> 0
A14: Employee Cost | B14: PL_EMPLOYEES | C14: =_xll.EQNXTDZ($A$1,$B14,C$1,$B$1) -> 9.3838041 | D14: =_xll.EQNXTDZ($A$1,$B14,D$1,$B$1) -> 9.9036198 | E14: =_xll.EQNXTDZ($A$1,$B14,E$1,$B$1) -> 10.181259 | F14: =_xll.EQNXTDZ($A$1,$B14,F$1,$B$1) -> 13.762118 | G14: =_xll.EQNXTDZ($A$1,$B14,G$1,$B$1) -> 16.245073 | H14: =_xll.EQNXTDZ($A$1,$B14,H$1,$B$1) -> 18.710016 | I14: =_xll.EQNXTDZ($A$1,$B14,I$1,$B$1) -> 34.036641 | J14: =_xll.EQNXTDZ($A$1,$B14,J$1,$B$1) -> 44.658973 | ... AF14: =_xll.EQNXTDZ($A$1,$B14,AF$1,$B$1) -> 0
A15: Operating & Manufacturing Expenses | B15: PL_GEN_OTHER_MFG_EXPS | C15: =_xll.EQNXTDZ($A$1,$B15,C$1,$B$1) -> 16.031576 | D15: =_xll.EQNXTDZ($A$1,$B15,D$1,$B$1) -> 22.908752 | E15: =_xll.EQNXTDZ($A$1,$B15,E$1,$B$1) -> 16.674619 | F15: =_xll.EQNXTDZ($A$1,$B15,F$1,$B$1) -> 19.261937 | G15: =_xll.EQNXTDZ($A$1,$B15,G$1,$B$1) -> 19.939484 | H15: =_xll.EQNXTDZ($A$1,$B15,H$1,$B$1) -> 27.49286 | I15: =_xll.EQNXTDZ($A$1,$B15,I$1,$B$1) -> 29.696939 | J15: =_xll.EQNXTDZ($A$1,$B15,J$1,$B$1) -> 40.396378 | ... AF15: =_xll.EQNXTDZ($A$1,$B15,AF$1,$B$1) -> 0
A16: Cost of Software development | B16: PL_COST_SW | C16: =_xll.EQNXTDZ($A$1,$B16,C$1,$B$1) -> 0 | D16: =_xll.EQNXTDZ($A$1,$B16,D$1,$B$1) -> 0 | E16: =_xll.EQNXTDZ($A$1,$B16,E$1,$B$1) -> 0 | F16: =_xll.EQNXTDZ($A$1,$B16,F$1,$B$1) -> 0 | G16: =_xll.EQNXTDZ($A$1,$B16,G$1,$B$1) -> 0 | H16: =_xll.EQNXTDZ($A$1,$B16,H$1,$B$1) -> 0 | I16: =_xll.EQNXTDZ($A$1,$B16,I$1,$B$1) -> 0 | J16: =_xll.EQNXTDZ($A$1,$B16,J$1,$B$1) -> 0 | ... AF16: =_xll.EQNXTDZ($A$1,$B16,AF$1,$B$1) -> 0
... A36: Profit After Tax from Discontinued Operations | B36: PL_PAT_DIS_OP | C36: =_xll.EQNXTDZ($A$1,$B36,C$1,$B$1) -> 0 | D36: =_xll.EQNXTDZ($A$1,$B36,D$1,$B$1) -> 0 | E36: =_xll.EQNXTDZ($A$1,$B36,E$1,$B$1) -> 0 | F36: =_xll.EQNXTDZ($A$1,$B36,F$1,$B$1) -> 0 | G36: =_xll.EQNXTDZ($A$1,$B36,G$1,$B$1) -> 0 | H36: =_xll.EQNXTDZ($A$1,$B36,H$1,$B$1) -> 0 | I36: =_xll.EQNXTDZ($A$1,$B36,I$1,$B$1) -> 0 | J36: =_xll.EQNXTDZ($A$1,$B36,J$1,$B$1) -> 0 | ... AF36: =_xll.EQNXTDZ($A$1,$B36,AF$1,$B$1) -> 0
A39: Field Description | B39: Field Name
A40: Year End | B40: BS_YEAR_END | C40: =_xll.EQNXTDZ($A$1,$B40,C$1,$B$1) -> 200103 | D40: =_xll.EQNXTDZ($A$1,$B40,D$1,$B$1) -> 200203 | E40: =_xll.EQNXTDZ($A$1,$B40,E$1,$B$1) -> 200303 | F40: =_xll.EQNXTDZ($A$1,$B40,F$1,$B$1) -> 200403 | G40: =_xll.EQNXTDZ($A$1,$B40,G$1,$B$1) -> 200503 | H40: =_xll.EQNXTDZ($A$1,$B40,H$1,$B$1) -> 200603 | I40: =_xll.EQNXTDZ($A$1,$B40,I$1,$B$1) -> 200703 | J40: =_xll.EQNXTDZ($A$1,$B40,J$1,$B$1) -> 200803 | ... AF40: =_xll.EQNXTDZ($A$1,$B40,AF$1,$B$1) -> 0
A41: Share Capital | B41: BS_SHARE_CAPITAL | C41: =_xll.EQNXTDZ($A$1,$B41,C$1,$B$1) -> 20.4359 | D41: =_xll.EQNXTDZ($A$1,$B41,D$1,$B$1) -> 21.6359 | E41: =_xll.EQNXTDZ($A$1,$B41,E$1,$B$1) -> 21.6359 | F41: =_xll.EQNXTDZ($A$1,$B41,F$1,$B$1) -> 29.850452 | G41: =_xll.EQNXTDZ($A$1,$B41,G$1,$B$1) -> 29.850452 | H41: =_xll.EQNXTDZ($A$1,$B41,H$1,$B$1) -> 33.32923 | I41: =_xll.EQNXTDZ($A$1,$B41,I$1,$B$1) -> 39.421559 | J41: =_xll.EQNXTDZ($A$1,$B41,J$1,$B$1) -> 39.421559 | ... AF41: =_xll.EQNXTDZ($A$1,$B41,AF$1,$B$1) -> 0
A42: Share Warrants & Outstandings | B42: BS_SHAREWROUTST | C42: =_xll.EQNXTDZ($A$1,$B42,C$1,$B$1) -> 0 | D42: =_xll.EQNXTDZ($A$1,$B42,D$1,$B$1) -> 0 | E42: =_xll.EQNXTDZ($A$1,$B42,E$1,$B$1) -> 0 | F42: =_xll.EQNXTDZ($A$1,$B42,F$1,$B$1) -> 0 | G42: =_xll.EQNXTDZ($A$1,$B42,G$1,$B$1) -> 0 | H42: =_xll.EQNXTDZ($A$1,$B42,H$1,$B$1) -> 2.261339 | I42: =_xll.EQNXTDZ($A$1,$B42,I$1,$B$1) -> 0 | J42: =_xll.EQNXTDZ($A$1,$B42,J$1,$B$1) -> 0 | ... AF42: =_xll.EQNXTDZ($A$1,$B42,AF$1,$B$1) -> 0
A43: Total Reserves | B43: BS_RESERVE | C43: =_xll.EQNXTDZ($A$1,$B43,C$1,$B$1) -> 31.758912 | D43: =_xll.EQNXTDZ($A$1,$B43,D$1,$B$1) -> 24.615586 | E43: =_xll.EQNXTDZ($A$1,$B43,E$1,$B$1) -> 30.119852 | F43: =_xll.EQNXTDZ($A$1,$B43,F$1,$B$1) -> 42.930938 | G43: =_xll.EQNXTDZ($A$1,$B43,G$1,$B$1) -> 53.288591 | H43: =_xll.EQNXTDZ($A$1,$B43,H$1,$B$1) -> 103.99195 | I43: =_xll.EQNXTDZ($A$1,$B43,I$1,$B$1) -> 148.49761 | J43: =_xll.EQNXTDZ($A$1,$B43,J$1,$B$1) -> 153.87218 | ... AF43: =_xll.EQNXTDZ($A$1,$B43,AF$1,$B$1) -> 0
A44: Shareholder's Funds | B44: BS_SHAREHODERS_FUNDS | C44: =_xll.EQNXTDZ($A$1,$B44,C$1,$B$1) -> 52.194812 | D44: =_xll.EQNXTDZ($A$1,$B44,D$1,$B$1) -> 46.251486 | E44: =_xll.EQNXTDZ($A$1,$B44,E$1,$B$1) -> 51.755752 | F44: =_xll.EQNXTDZ($A$1,$B44,F$1,$B$1) -> 72.78139 | G44: =_xll.EQNXTDZ($A$1,$B44,G$1,$B$1) -> 83.139043 | H44: =_xll.EQNXTDZ($A$1,$B44,H$1,$B$1) -> 139.58252 | I44: =_xll.EQNXTDZ($A$1,$B44,I$1,$B$1) -> 187.91917 | J44: =_xll.EQNXTDZ($A$1,$B44,J$1,$B$1) -> 193.29374 | ... AF44: =_xll.EQNXTDZ($A$1,$B44,AF$1,$B$1) -> 0
A45: Minority Interest | B45: BS_MINORITY_INTEREST | C45: =_xll.EQNXTDZ($A$1,$B45,C$1,$B$1) -> 0 | D45: =_xll.EQNXTDZ($A$1,$B45,D$1,$B$1) -> 0 | E45: =_xll.EQNXTDZ($A$1,$B45,E$1,$B$1) -> 0 | F45: =_xll.EQNXTDZ($A$1,$B45,F$1,$B$1) -> 0 | G45: =_xll.EQNXTDZ($A$1,$B45,G$1,$B$1) -> 0 | H45: =_xll.EQNXTDZ($A$1,$B45,H$1,$B$1) -> 0 | I45: =_xll.EQNXTDZ($A$1,$B45,I$1,$B$1) -> 0 | J45: =_xll.EQNXTDZ($A$1,$B45,J$1,$B$1) -> 0 | ... AF45: =_xll.EQNXTDZ($A$1,$B45,AF$1,$B$1) -> 0
A46: Long-Term Borrowings | B46: BS_LTRM_BORROWING | C46: =_xll.EQNXTDZ($A$1,$B46,C$1,$B$1) -> 0 | D46: =_xll.EQNXTDZ($A$1,$B46,D$1,$B$1) -> 0 | E46: =_xll.EQNXTDZ($A$1,$B46,E$1,$B$1) -> 0 | F46: =_xll.EQNXTDZ($A$1,$B46,F$1,$B$1) -> 0 | G46: =_xll.EQNXTDZ($A$1,$B46,G$1,$B$1) -> 0 | H46: =_xll.EQNXTDZ($A$1,$B46,H$1,$B$1) -> 0 | I46: =_xll.EQNXTDZ($A$1,$B46,I$1,$B$1) -> 0 | J46: =_xll.EQNXTDZ($A$1,$B46,J$1,$B$1) -> 0 | ... AF46: =_xll.EQNXTDZ($A$1,$B46,AF$1,$B$1) -> 0
A47: Secured Loans | B47: BS_SECURED_LOANS | C47: =_xll.EQNXTDZ($A$1,$B47,C$1,$B$1) -> 72.910683 | D47: =_xll.EQNXTDZ($A$1,$B47,D$1,$B$1) -> 66.359124 | E47: =_xll.EQNXTDZ($A$1,$B47,E$1,$B$1) -> 99.220855 | F47: =_xll.EQNXTDZ($A$1,$B47,F$1,$B$1) -> 158.01656 | G47: =_xll.EQNXTDZ($A$1,$B47,G$1,$B$1) -> 180.04327 | H47: =_xll.EQNXTDZ($A$1,$B47,H$1,$B$1) -> 291.96326 | I47: =_xll.EQNXTDZ($A$1,$B47,I$1,$B$1) -> 603.93683 | J47: =_xll.EQNXTDZ($A$1,$B47,J$1,$B$1) -> 677.54288 | ... AF47: =_xll.EQNXTDZ($A$1,$B47,AF$1,$B$1) -> 0
A48: Unsecured Loans | B48: BS_UNSECURED_LOANS_NF | C48: =_xll.EQNXTDZ($A$1,$B48,C$1,$B$1) -> 1.73 | D48: =_xll.EQNXTDZ($A$1,$B48,D$1,$B$1) -> 5.21 | E48: =_xll.EQNXTDZ($A$1,$B48,E$1,$B$1) -> 5.21 | F48: =_xll.EQNXTDZ($A$1,$B48,F$1,$B$1) -> 6.2685 | G48: =_xll.EQNXTDZ($A$1,$B48,G$1,$B$1) -> 5 | H48: =_xll.EQNXTDZ($A$1,$B48,H$1,$B$1) -> 20 | I48: =_xll.EQNXTDZ($A$1,$B48,I$1,$B$1) -> 40.81427 | J48: =_xll.EQNXTDZ($A$1,$B48,J$1,$B$1) -> 52.08507 | ... AF48: =_xll.EQNXTDZ($A$1,$B48,AF$1,$B$1) -> 0
A49: Deferred Tax Assets / Liabilities | B49: BS_NET_DEF_TAX_NF | C49: =_xll.EQNXTDZ($A$1,$B49,C$1,$B$1) -> 0 | D49: =_xll.EQNXTDZ($A$1,$B49,D$1,$B$1) -> 12.721459 | E49: =_xll.EQNXTDZ($A$1,$B49,E$1,$B$1) -> 15.423137 | F49: =_xll.EQNXTDZ($A$1,$B49,F$1,$B$1) -> 17.972214 | G49: =_xll.EQNXTDZ($A$1,$B49,G$1,$B$1) -> 20.601136 | H49: =_xll.EQNXTDZ($A$1,$B49,H$1,$B$1) -> 27.008712 | I49: =_xll.EQNXTDZ($A$1,$B49,I$1,$B$1) -> 40.793093 | J49: =_xll.EQNXTDZ($A$1,$B49,J$1,$B$1) -> 41.692893 | ... AF49: =_xll.EQNXTDZ($A$1,$B49,AF$1,$B$1) -> 0
A50: Other Long Term Liabilities | B50: BS_OTH_LT_LIAB | C50: =_xll.EQNXTDZ($A$1,$B50,C$1,$B$1) -> 0 | D50: =_xll.EQNXTDZ($A$1,$B50,D$1,$B$1) -> 0 | E50: =_xll.EQNXTDZ($A$1,$B50,E$1,$B$1) -> 0 | F50: =_xll.EQNXTDZ($A$1,$B50,F$1,$B$1) -> 0 | G50: =_xll.EQNXTDZ($A$1,$B50,G$1,$B$1) -> 0 | H50: =_xll.EQNXTDZ($A$1,$B50,H$1,$B$1) -> 0 | I50: =_xll.EQNXTDZ($A$1,$B50,I$1,$B$1) -> 0 | J50: =_xll.EQNXTDZ($A$1,$B50,J$1,$B$1) -> 0 | ... AF50: =_xll.EQNXTDZ($A$1,$B50,AF$1,$B$1) -> 0
A51: Long Term Trade Payables | B51: BS_LT_TRADE_PAYABLES | C51: =_xll.EQNXTDZ($A$1,$B51,C$1,$B$1) -> 0 | D51: =_xll.EQNXTDZ($A$1,$B51,D$1,$B$1) -> 0 | E51: =_xll.EQNXTDZ($A$1,$B51,E$1,$B$1) -> 0 | F51: =_xll.EQNXTDZ($A$1,$B51,F$1,$B$1) -> 0 | G51: =_xll.EQNXTDZ($A$1,$B51,G$1,$B$1) -> 0 | H51: =_xll.EQNXTDZ($A$1,$B51,H$1,$B$1) -> 0 | I51: =_xll.EQNXTDZ($A$1,$B51,I$1,$B$1) -> 0 | J51: =_xll.EQNXTDZ($A$1,$B51,J$1,$B$1) -> 0 | ... AF51: =_xll.EQNXTDZ($A$1,$B51,AF$1,$B$1) -> 0
... A99: Estimated Capital Contracts Remaining | B99: BS_ESTIMATED_CAPITAL_CONTRACT | C99: =_xll.EQNXTDZ($A$1,$B99,C$1,$B$1) -> 2.923 | D99: =_xll.EQNXTDZ($A$1,$B99,D$1,$B$1) -> 0.045 | E99: =_xll.EQNXTDZ($A$1,$B99,E$1,$B$1) -> 10.0352 | F99: =_xll.EQNXTDZ($A$1,$B99,F$1,$B$1) -> 3.9863 | G99: =_xll.EQNXTDZ($A$1,$B99,G$1,$B$1) -> 18.5439 | H99: =_xll.EQNXTDZ($A$1,$B99,H$1,$B$1) -> 132.7168 | I99: =_xll.EQNXTDZ($A$1,$B99,I$1,$B$1) -> 69.2557 | J99: =_xll.EQNXTDZ($A$1,$B99,J$1,$B$1) -> 18.8218 | ... AF99: =_xll.EQNXTDZ($A$1,$B99,AF$1,$B$1) -> 0
A103: Field Description | B103: Field Name
A104: Equity Paid Up | B104: BS_EQUITY_PAIDUP | C104: =_xll.EQNXTDZ($A$1,$B104,C$1,$B$1) -> 16.4359 | D104: =_xll.EQNXTDZ($A$1,$B104,D$1,$B$1) -> 16.4359 | E104: =_xll.EQNXTDZ($A$1,$B104,E$1,$B$1) -> 16.4359 | F104: =_xll.EQNXTDZ($A$1,$B104,F$1,$B$1) -> 24.650452 | G104: =_xll.EQNXTDZ($A$1,$B104,G$1,$B$1) -> 24.650452 | H104: =_xll.EQNXTDZ($A$1,$B104,H$1,$B$1) -> 33.32923 | I104: =_xll.EQNXTDZ($A$1,$B104,I$1,$B$1) -> 39.421559 | J104: =_xll.EQNXTDZ($A$1,$B104,J$1,$B$1) -> 39.421559 | ... AF104: =_xll.EQNXTDZ($A$1,$B104,AF$1,$B$1) -> 0
A105: Face Value | B105: BS_FACE_VALUE | C105: =_xll.EQNXTDZ($A$1,$B105,C$1,$B$1) -> 10 | D105: =_xll.EQNXTDZ($A$1,$B105,D$1,$B$1) -> 10 | E105: =_xll.EQNXTDZ($A$1,$B105,E$1,$B$1) -> 10 | F105: =_xll.EQNXTDZ($A$1,$B105,F$1,$B$1) -> 10 | G105: =_xll.EQNXTDZ($A$1,$B105,G$1,$B$1) -> 10 | H105: =_xll.EQNXTDZ($A$1,$B105,H$1,$B$1) -> 10 | I105: =_xll.EQNXTDZ($A$1,$B105,I$1,$B$1) -> 10 | J105: =_xll.EQNXTDZ($A$1,$B105,J$1,$B$1) -> 10 | ... AF105: =_xll.EQNXTDZ($A$1,$B105,AF$1,$B$1) -> 0
A106: Close Price (Unit Curr.) | B106: FH_YEAR_PRICE | C106: =_xll.EQNXTDZ($A$1,$B106,C$1,$B$1) -> 9.0231214 | D106: =_xll.EQNXTDZ($A$1,$B106,D$1,$B$1) -> 7.2184971 | E106: =_xll.EQNXTDZ($A$1,$B106,E$1,$B$1) -> 8.5934489 | F106: =_xll.EQNXTDZ($A$1,$B106,F$1,$B$1) -> 16.5 | G106: =_xll.EQNXTDZ($A$1,$B106,G$1,$B$1) -> 34.3 | H106: =_xll.EQNXTDZ($A$1,$B106,H$1,$B$1) -> 75.65 | I106: =_xll.EQNXTDZ($A$1,$B106,I$1,$B$1) -> 79.15 | J106: =_xll.EQNXTDZ($A$1,$B106,J$1,$B$1) -> 28.1 | ... AF106: =_xll.EQNXTDZ($A$1,$B106,AF$1,$B$1) -> 0
A107: High Price (Unit Curr.) | B107: FH_HIGH | C107: =_xll.EQNXTDZ($A$1,$B107,C$1,$B$1) -> 23.589017 | D107: =_xll.EQNXTDZ($A$1,$B107,D$1,$B$1) -> 11.85896 | E107: =_xll.EQNXTDZ($A$1,$B107,E$1,$B$1) -> 18.475915 | F107: =_xll.EQNXTDZ($A$1,$B107,F$1,$B$1) -> 40.5 | G107: =_xll.EQNXTDZ($A$1,$B107,G$1,$B$1) -> 42.25 | H107: =_xll.EQNXTDZ($A$1,$B107,H$1,$B$1) -> 96 | I107: =_xll.EQNXTDZ($A$1,$B107,I$1,$B$1) -> 103 | J107: =_xll.EQNXTDZ($A$1,$B107,J$1,$B$1) -> 90.9 | ... AF107: =_xll.EQNXTDZ($A$1,$B107,AF$1,$B$1) -> 0
A108: Low Price (Unit Curr.) | B108: FH_LOW | C108: =_xll.EQNXTDZ($A$1,$B108,C$1,$B$1) -> 8.8942197 | D108: =_xll.EQNXTDZ($A$1,$B108,D$1,$B$1) -> 6.1872832 | E108: =_xll.EQNXTDZ($A$1,$B108,E$1,$B$1) -> 6.5739884 | F108: =_xll.EQNXTDZ($A$1,$B108,F$1,$B$1) -> 8.5934489 | G108: =_xll.EQNXTDZ($A$1,$B108,G$1,$B$1) -> 14.75 | H108: =_xll.EQNXTDZ($A$1,$B108,H$1,$B$1) -> 33 | I108: =_xll.EQNXTDZ($A$1,$B108,I$1,$B$1) -> 50.1 | J108: =_xll.EQNXTDZ($A$1,$B108,J$1,$B$1) -> 24.05 | ... AF108: =_xll.EQNXTDZ($A$1,$B108,AF$1,$B$1) -> 0
A109: Market Capitalization | B109: FH_MCAP | C109: =_xll.EQNXTDZ($A$1,$B109,C$1,$B$1) -> 17.257695 | D109: =_xll.EQNXTDZ($A$1,$B109,D$1,$B$1) -> 13.806156 | E109: =_xll.EQNXTDZ($A$1,$B109,E$1,$B$1) -> 16.4359 | F109: =_xll.EQNXTDZ($A$1,$B109,F$1,$B$1) -> 40.673246 | G109: =_xll.EQNXTDZ($A$1,$B109,G$1,$B$1) -> 84.55105 | H109: =_xll.EQNXTDZ($A$1,$B109,H$1,$B$1) -> 252.13562 | I109: =_xll.EQNXTDZ($A$1,$B109,I$1,$B$1) -> 312.02164 | J109: =_xll.EQNXTDZ($A$1,$B109,J$1,$B$1) -> 110.77458 | ... AF109: =_xll.EQNXTDZ($A$1,$B109,AF$1,$B$1) -> 0
A110: Adj DPS(Rs) | B110: FR_ADJ_DPS | C110: =_xll.EQNXTDZ($A$1,$B110,C$1,$B$1) -> 0.86206897 | D110: =_xll.EQNXTDZ($A$1,$B110,D$1,$B$1) -> 0 | E110: =_xll.EQNXTDZ($A$1,$B110,E$1,$B$1) -> 0.68965517 | F110: =_xll.EQNXTDZ($A$1,$B110,F$1,$B$1) -> 0.8 | G110: =_xll.EQNXTDZ($A$1,$B110,G$1,$B$1) -> 1.1 | H110: =_xll.EQNXTDZ($A$1,$B110,H$1,$B$1) -> 1.5 | I110: =_xll.EQNXTDZ($A$1,$B110,I$1,$B$1) -> 1 | J110: =_xll.EQNXTDZ($A$1,$B110,J$1,$B$1) -> 0 | ... AF110: =_xll.EQNXTDZ($A$1,$B110,AF$1,$B$1) -> 0
A111: Date End | B111: SHP_DATE_END | C111: =_xll.EQNXTDZ($A$1,$B111,C$5) -> 200103 | D111: =_xll.EQNXTDZ($A$1,$B111,D$5) -> 200203 | E111: =_xll.EQNXTDZ($A$1,$B111,E$5) -> 200303 | F111: =_xll.EQNXTDZ($A$1,$B111,F$5) -> 200403 | G111: =_xll.EQNXTDZ($A$1,$B111,G$5) -> 200503 | H111: =_xll.EQNXTDZ($A$1,$B111,H$5) -> 200603 | I111: =_xll.EQNXTDZ($A$1,$B111,I$5) -> 200703 | J111: =_xll.EQNXTDZ($A$1,$B111,J$5) -> 200803 | ... AF111: =_xll.EQNXTDZ($A$1,$B111,AF$5) -> 0
A112: Total of Promoter and Promoter Group | B112: SHP_TPFTOTALPROMOTER | C112: =_xll.EQNXTDZ($A$1,$B112,C$5) -> 51.26 | D112: =_xll.EQNXTDZ($A$1,$B112,D$5) -> 50.73 | E112: =_xll.EQNXTDZ($A$1,$B112,E$5) -> 48.69 | F112: =_xll.EQNXTDZ($A$1,$B112,F$5) -> 41.83 | G112: =_xll.EQNXTDZ($A$1,$B112,G$5) -> 41.83 | H112: =_xll.EQNXTDZ($A$1,$B112,H$5) -> 35.44 | I112: =_xll.EQNXTDZ($A$1,$B112,I$5) -> 36.03 | J112: =_xll.EQNXTDZ($A$1,$B112,J$5) -> 36.03 | ... AF112: =_xll.EQNXTDZ($A$1,$B112,AF$5) -> 0
...

Sheet QTR Share Price
