Workbook

Sheet Template
A1: =+'Annual Raw'!C4 -> Schaeffler India Ltd. | B1: 36951 | C1: =EOMONTH(B1,12) -> 37346 | D1: 37591 | E1: =EOMONTH(D1,12) -> 37986 | F1: =EOMONTH(E1,12) -> 38352 | G1: =EOMONTH(F1,12) -> 38717 | H1: =EOMONTH(G1,12) -> 39082 | I1: =EOMONTH(H1,12) -> 39447 | J1: =EOMONTH(I1,12) -> 39813 | K1: =EOMONTH(J1,12) -> 40178 | L1: =EOMONTH(K1,12) -> 40543 | ... AE1: =EOMONTH(AD1,12) -> 47483 | AH1: QTR | AI1: 41061 | AJ1: 41153 | AK1: 41244 | AL1: 41334 | AM1: 41426 | AN1: 41518 | AO1: 41609 | AP1: 41699 | AQ1: 41791 | AR1: 41883 | AS1: 41974 | AT1: 42064 | AU1: 42156 | AV1: 42248 | AW1: 42339 | AX1: 42430 | AY1: 42522 | AZ1: 42614 | BA1: 42705 | BB1: 42795 | BC1: 42887 | BD1: 42979 | BE1: 43070 | BF1: 43160 | BG1: 43252 | BH1: 43344 | BI1: 43435 | BJ1: 43525 | BK1: 43617 | BL1: 43709 | BM1: 43800 | BN1: 43891 | BO1: 43983 | BP1: 44075 | BQ1: =EOMONTH(BP1,3) -> 44196 | BR1: =EOMONTH(BQ1,3) -> 44286 | BS1: =EOMONTH(BR1,3) -> 44377 | BT1: =EOMONTH(BS1,3) -> 44469 | BU1: =EOMONTH(BT1,3) -> 44561 | BV1: =EOMONTH(BU1,3) -> 44651 | BW1: =EOMONTH(BV1,3) -> 44742 | BX1: =EOMONTH(BW1,3) -> 44834 | ... DA1: =EOMONTH(CZ1,3) -> 47483 | DD1: HISTORICAL ESTIMATES | DE1: 46022
A2: Presentation Data (Start)
A4: Revenue From Operations
A5: Revenue- Automotive Technologies | W5: =SUM(BR5:BU5) -> 2186.05 | X5: =SUM(BV5:BY5) -> 2706.5 | Y5: =SUM(BZ5:CC5) -> 3025.18 | Z5: =SUM(CD5:CG5) -> 2733.32 | AA5: =SUM(CH5:CK5) -> 3137.27 | AB5: =SUM(CL5:CO5) -> 3945.4039 | AC5: =SUM(CP5:CS5) -> 4916.0353 | AD5: =SUM(CT5:CW5) -> 5950.2807 | AE5: =SUM(CX5:DA5) -> 7190.0936 | BQ5: =BQ$21*47% -> 598.6719 | BR5: 574.3 | BS5: 484.52 | BT5: 560 | BU5: 567.23 | BV5: 609.42 | BW5: 679.49 | BX5: 717.05 | BY5: 700.54 | BZ5: 737.71 | CA5: 749.15 | CB5: 772.66 | CC5: 765.66 | CD5: 652.41 | CE5: 683.72 | CF5: 688.9 | CG5: 708.29 | CH5: 694.17 | CI5: 705.43 | CJ5: 817.71 | CK5: 919.96 | CL5: 907.84 | CM5: =CI5*(1+CM13) -> 850.99283 | CN5: =CJ5*(1+CN13) -> 1022.1331 | CO5: =CK5*(1+CO13) -> 1164.4379 | CP5: =CL5*(1+CP13) -> 1136.9102 | CQ5: =CM5*(1+CQ13) -> 1054.1515 | CR5: =CN5*(1+CR13) -> 1274.2583 | CS5: =CO5*(1+CS13) -> 1450.7152 | CT5: =CP5*(1+CT13) -> 1388.5126 | ... DA5: =CW5*(1+DA13) -> 2101.5303 | DE5: 795.10012
A6: Revenue- Vehicle Lifetime Solutions | W6: =SUM(BR6:BU6) -> 501.87 | X6: =SUM(BV6:BY6) -> 593.58 | Y6: =SUM(BZ6:CC6) -> 708.8 | Z6: =SUM(CD6:CG6) -> 857.76 | AA6: =SUM(CH6:CK6) -> 1430.32 | AB6: =SUM(CL6:CO6) -> 1601.948 | AC6: =SUM(CP6:CS6) -> 1762.1428 | AD6: =SUM(CT6:CW6) -> 1938.3571 | AE6: =SUM(CX6:DA6) -> 2132.1928 | BQ6: 0 | BR6: 107.92 | BS6: 96.68 | BT6: 145.08 | BU6: 152.19 | BV6: 124.67 | BW6: 149.25 | BX6: 150.59 | BY6: 169.07 | BZ6: 146.42 | CA6: 184.8 | CB6: 173.06 | CC6: 204.52 | CD6: 184.5 | CE6: 218.61 | CF6: 222.9 | CG6: 231.75 | CH6: 319.14 | CI6: 374.03 | CJ6: 353.32 | CK6: 383.83 | CL6: 379.65 | CM6: =CI6*(1+CM14) -> 411.433 | CN6: =CJ6*(1+CN14) -> 388.652 | CO6: =CK6*(1+CO14) -> 422.213 | CP6: =CL6*(1+CP14) -> 417.615 | CQ6: =CM6*(1+CQ14) -> 452.5763 | CR6: =CN6*(1+CR14) -> 427.5172 | CS6: =CO6*(1+CS14) -> 464.4343 | CT6: =CP6*(1+CT14) -> 459.3765 | ... DA6: =CW6*(1+DA14) -> 561.9655 | DE6: 351.054
A7: Revenue- Bearings & Industrial Solutions | W7: =SUM(BR7:BU7) -> 2156.62 | X7: =SUM(BV7:BY7) -> 2424.66 | Y7: =SUM(BZ7:CC7) -> 2538.9 | Z7: =SUM(CD7:CG7) -> 3561.71 | AA7: =SUM(CH7:CK7) -> 3686.53 | AB7: =SUM(CL7:CO7) -> 3828.4995 | AC7: =SUM(CP7:CS7) -> 3974.6314 | AD7: =SUM(CT7:CW7) -> 4127.634 | AE7: =SUM(CX7:DA7) -> 4286.9035 | BQ7: =BQ$21*43% -> 547.7211 | BR7: 481.18 | BS7: 479.02 | BT7: 606.76 | BU7: 589.66 | BV7: 585.67 | BW7: 640.62 | BX7: 605.86 | BY7: 592.51 | BZ7: 535.86 | CA7: 625.58 | CB7: 684.53 | CC7: 692.93 | CD7: 783.28 | CE7: 898.79 | CF7: 943.32 | CG7: 936.32 | CH7: 849.36 | CI7: 897.82 | CJ7: 905.35 | CK7: 1034 | CL7: 884.85 | CM7: =CI7*(1+CM15) -> 921.33773 | CN7: =CJ7*(1+CN15) -> 935.23798 | CO7: =CK7*(1+CO15) -> 1087.0738 | CP7: =CL7*(1+CP15) -> 917.87117 | CQ7: =CM7*(1+CQ15) -> 954.71246 | CR7: =CN7*(1+CR15) -> 971.41444 | CS7: =CO7*(1+CS15) -> 1130.6333 | CT7: =CP7*(1+CT15) -> 952.81787 | ... DA7: =CW7*(1+DA15) -> 1219.8611 | DE7: 880.64953
A8: Revenue- Intercompany Exports & Others | W8: =SUM(BR8:BU8) -> 715.97 | X8: =SUM(BV8:BY8) -> 1142.68 | Y8: =SUM(BZ8:CC8) -> 977.83 | Z8: =SUM(CD8:CG8) -> 1079.59 | AA8: =SUM(CH8:CK8) -> 1431.73 | AB8: =SUM(CL8:CO8) -> 1898.1652 | AC8: =SUM(CP8:CS8) -> 2516.5576 | AD8: =SUM(CT8:CW8) -> 2818.5445 | AE8: =SUM(CX8:DA8) -> 3156.7698 | BQ8: =BQ$21*10% -> 127.377 | BR8: 153.42 | BS8: 172.67 | BT8: 175.74 | BU8: 214.14 | BV8: 247.75 | BW8: 279.47 | BX8: 282.93 | BY8: 332.53 | BZ8: 273.63 | CA8: 269.61 | CB8: 223.15 | CC8: 211.44 | CD8: 252.94 | CE8: 305.72 | CF8: 261.23 | CG8: 259.7 | CH8: 311.74 | CI8: 375.31 | CJ8: 358.27 | CK8: 386.41 | CL8: 413.3 | CM8: =CI8*(1+CM16) -> 497.58011 | CN8: =CJ8*(1+CN16) -> 474.98874 | CO8: =CK8*(1+CO16) -> 512.29631 | CP8: =CL8*(1+CP16) -> 547.94665 | CQ8: =CM8*(1+CQ16) -> 659.6839 | CR8: =CN8*(1+CR16) -> 629.73262 | CS8: =CO8*(1+CS16) -> 679.19441 | CT8: =CP8*(1+CT16) -> 613.70025 | ... DA8: =CW8*(1+DA16) -> 851.98147 | DE8: 358.501
A9: Total Revenue | W9: =SUM(W5:W8) -> 5560.51 | X9: =SUM(X5:X8) -> 6867.42 | Y9: =SUM(Y5:Y8) -> 7250.71 | Z9: =SUM(Z5:Z8) -> 8232.38 | AA9: =SUM(AA5:AA8) -> 9685.85 | AB9: =SUM(AB5:AB8) -> 11274.017 | AC9: =SUM(AC5:AC8) -> 13169.367 | AD9: =SUM(AD5:AD8) -> 14834.816 | AE9: =SUM(AE5:AE8) -> 16765.96 | BN9: =SUM(BN5:BN8) -> 0 | BO9: =SUM(BO5:BO8) -> 0 | BP9: =SUM(BP5:BP8) -> 0 | BQ9: =SUM(BQ5:BQ8) -> 1273.77 | BR9: =SUM(BR5:BR8) -> 1316.82 | BS9: =SUM(BS5:BS8) -> 1232.89 | BT9: =SUM(BT5:BT8) -> 1487.58 | BU9: =SUM(BU5:BU8) -> 1523.22 | ... DA9: =SUM(DA5:DA8) -> 4735.3384 | DE9: 2385.3047
A10: Revenue- Checksum | W10: =W23-W9 -> 0 | X10: =X23-X9 -> 0 | Y10: =Y23-Y9 -> 0.2 | Z10: =Z23-Z9 -> 0 | AA10: =AA23-AA9 -> 0 | AB10: =AB23-AB9 -> 0 | AC10: =AC23-AC9 -> 0 | AD10: =AD23-AD9 -> 0 | AE10: =AE23-AE9 -> 0 | BN10: =BN21-BN9 -> 928.54 | BO10: =BO21-BO9 -> 438.88 | BP10: =BP21-BP9 -> 1120.65 | BQ10: =BQ21-BQ9 -> 0 | BR10: =BR21-BR9 -> 0 | BS10: =BS21-BS9 -> 0 | BT10: =BT21-BT9 -> 0 | BU10: =BU21-BU9 -> 0 | ... CL10: =CL21-CL9 -> 0
A12: Revenue Growth %
A13: Automotive Technologies- Growth% | X13: =X5/W5-1 -> 0.23807781 | Y13: =Y5/X5-1 -> 0.11774617 | Z13: =Z5/Y5-1 -> -0.096476904 | AA13: =AA5/Z5-1 -> 0.14778731 | AB13: =AB5/AA5-1 -> 0.25759143 | AC13: =AC5/AB5-1 -> 0.24601572 | AD13: =AD5/AC5-1 -> 0.21038203 | AE13: =AE5/AD5-1 -> 0.20836208 | BU13: =BU5/BQ5-1 -> -0.052519418 | BV13: =BV5/BR5-1 -> 0.061152708 | BW13: =BW5/BS5-1 -> 0.40239825 | BX13: =BX5/BT5-1 -> 0.28044643 | BY13: =BY5/BU5-1 -> 0.2350193 | BZ13: =BZ5/BV5-1 -> 0.21051163 | CA13: =CA5/BW5-1 -> 0.10251807 | CB13: =CB5/BX5-1 -> 0.077553867 | ... CL13: =CL5/CH5-1 -> 0.30780645 | CM13: =AVERAGE(CI13:CL13) -> 0.20634624 | CN13: =AVERAGE(CJ13:CM13) -> 0.24999461 | CO13: =AVERAGE(CK13:CN13) -> 0.26574845 | CP13: =AVERAGE(CL13:CO13)*0.98 -> 0.25232446 | CQ13: =AVERAGE(CM13:CP13)*0.98 -> 0.23873137 | CR13: =AVERAGE(CN13:CQ13)*0.98 -> 0.24666573 | CS13: =AVERAGE(CO13:CR13)*0.98 -> 0.24585015 | CT13: =AVERAGE(CP13:CS13)*0.9 -> 0.22130364 | CU13: =AVERAGE(CQ13:CT13)*0.9 -> 0.21432395 | CV13: =AVERAGE(CR13:CU13)*0.9 -> 0.20883228 | CW13: =AVERAGE(CS13:CV13)*0.9 -> 0.20031976 | CX13: =AVERAGE(CT13:CW13) -> 0.21119491 | CY13: =AVERAGE(CU13:CX13) -> 0.20866772 | CZ13: =AVERAGE(CV13:CY13) -> 0.20725367 | DA13: =AVERAGE(CW13:CZ13) -> 0.20685901 | DE13: 0.14539684
A14: Vehicle Lifetime Solutions- Growth% | X14: =X6/W6-1 -> 0.18273657 | Y14: =Y6/X6-1 -> 0.19411031 | Z14: =Z6/Y6-1 -> 0.21015801 | AA14: =AA6/Z6-1 -> 0.66750606 | AB14: =AB6/AA6-1 -> 0.11999273 | AC14: =AC6/AB6-1 -> 0.1 | AD14: =AD6/AC6-1 -> 0.1 | AE14: =AE6/AD6-1 -> 0.1 | BU14: =BU6/BQ6-1 -> #DIV/0! | BV14: =BV6/BR6-1 -> 0.15520756 | BW14: =BW6/BS6-1 -> 0.54375259 | BX14: =BX6/BT6-1 -> 0.037979046 | BY14: =BY6/BU6-1 -> 0.11091399 | BZ14: =BZ6/BV6-1 -> 0.17446058 | CA14: =CA6/BW6-1 -> 0.23819095 | CB14: =CB6/BX6-1 -> 0.1492131 | ... CL14: =CL6/CH6-1 -> 0.18960331 | CM14: 0.1 | CN14: 0.1 | CO14: 0.1 | CP14: 0.1 | CQ14: 0.1 | CR14: 0.1 | CS14: 0.1 | CT14: 0.1 | CU14: 0.1 | CV14: 0.1 | CW14: 0.1 | CX14: 0.1 | CY14: 0.1 | CZ14: 0.1 | DA14: 0.1 | DE14: 0.1
A15: Bearings & Industrial Solutions- Growth% | X15: =X7/W7-1 -> 0.12428708 | Y15: =Y7/X7-1 -> 0.047115884 | Z15: =Z7/Y7-1 -> 0.40285557 | AA15: =AA7/Z7-1 -> 0.035044964 | AB15: =AB7/AA7-1 -> 0.038510343 | AC15: =AC7/AB7-1 -> 0.038169491 | AD15: =AD7/AC7-1 -> 0.03849478 | AE15: =AE7/AD7-1 -> 0.038586145 | BU15: =BU7/BQ7-1 -> 0.076569809 | BV15: =BV7/BR7-1 -> 0.21715366 | BW15: =BW7/BS7-1 -> 0.33735543 | BX15: =BX7/BT7-1 -> -0.0014832883 | BY15: =BY7/BU7-1 -> 0.0048332938 | BZ15: =BZ7/BV7-1 -> -0.085047894 | CA15: =CA7/BW7-1 -> -0.023477256 | CB15: =CB7/BX7-1 -> 0.12984848 | ... CL15: =CL7/CH7-1 -> 0.041784402 | CM15: =AVERAGE(CI15:CL15) -> 0.026194257 | CN15: =AVERAGE(CJ15:CM15) -> 0.033012629 | CO15: =AVERAGE(CK15:CN15) -> 0.051328649 | CP15: =AVERAGE(CL15:CO15)*0.98 -> 0.037318385 | CQ15: =AVERAGE(CM15:CP15)*0.98 -> 0.03622421 | CR15: =AVERAGE(CN15:CQ15)*0.98 -> 0.038681549 | CS15: =AVERAGE(CO15:CR15)*0.98 -> 0.040070434 | CT15: =AVERAGE(CP15:CS15) -> 0.038073645 | CU15: =AVERAGE(CQ15:CT15) -> 0.03826246 | CV15: =AVERAGE(CR15:CU15) -> 0.038772022 | CW15: =AVERAGE(CS15:CV15) -> 0.03879464 | CX15: =AVERAGE(CT15:CW15) -> 0.038475692 | CY15: =AVERAGE(CU15:CX15) -> 0.038576203 | CZ15: =AVERAGE(CV15:CY15) -> 0.038654639 | DA15: =AVERAGE(CW15:CZ15) -> 0.038625294 | DE15: 0.036838954
A16: Intercompany Exports & Others- Growth% | X16: =X8/W8-1 -> 0.59598866 | Y16: =Y8/X8-1 -> -0.14426611 | Z16: =Z8/Y8-1 -> 0.10406717 | AA16: =AA8/Z8-1 -> 0.32617938 | AB16: =AB8/AA8-1 -> 0.32578431 | AC16: =AC8/AB8-1 -> 0.32578431 | AD16: =AD8/AC8-1 -> 0.12 | AE16: =AE8/AD8-1 -> 0.12 | BU16: =BU8/BQ8-1 -> 0.68115123 | BV16: =BV8/BR8-1 -> 0.61484813 | BW16: =BW8/BS8-1 -> 0.61852088 | BX16: =BX8/BT8-1 -> 0.60993513 | BY16: =BY8/BU8-1 -> 0.55286261 | BZ16: =BZ8/BV8-1 -> 0.10446014 | CA16: =CA8/BW8-1 -> -0.035281068 | CB16: =CB8/BX8-1 -> -0.21128901 | ... CL16: =CL8/CH8-1 -> 0.32578431 | CM16: =+CL16 -> 0.32578431 | CN16: =+CM16 -> 0.32578431 | CO16: =+CN16 -> 0.32578431 | CP16: =+CO16 -> 0.32578431 | CQ16: =+CP16 -> 0.32578431 | CR16: =+CQ16 -> 0.32578431 | CS16: =+CR16 -> 0.32578431 | CT16: 0.12 | CU16: =+CT16 -> 0.12 | CV16: =+CU16 -> 0.12 | CW16: =+CV16 -> 0.12 | CX16: =+CW16 -> 0.12 | CY16: =+CX16 -> 0.12 | CZ16: =+CY16 -> 0.12 | DA16: =+CZ16 -> 0.12 | DE16: 0.15
A19: Presentation Data (End)
A20: Profit & Loss- Annual (Start)
A21: Gross Revenue | B21: ='Annual Raw'!C6 -> 0 | C21: ='Annual Raw'!D6 -> 0 | D21: ='Annual Raw'!E6 -> 278.59 | E21: ='Annual Raw'!F6 -> 305.78 | F21: ='Annual Raw'!G6 -> 368.75 | G21: ='Annual Raw'!H6 -> 462.65 | H21: ='Annual Raw'!I6 -> 612.25 | I21: ='Annual Raw'!J6 -> 715.97 | ... AA21: ='Annual Raw'!AB6 -> 9823.91 | AB21: =+SUM(CL21:CO21) -> 11274.017 | AC21: =+SUM(CP21:CS21) -> 13169.367 | AD21: =+SUM(CT21:CW21) -> 14834.816 | AE21: =+SUM(CX21:DA21) -> 16765.96 | AI21: ='QTR Raw'!C6+'QTR Raw'!C8 -> 380.12 | AJ21: ='QTR Raw'!D6+'QTR Raw'!D8 -> 356.17 | AK21: ='QTR Raw'!E6+'QTR Raw'!E8 -> 347.12 | AL21: ='QTR Raw'!F6+'QTR Raw'!F8 -> 332.61 | AM21: ='QTR Raw'!G6+'QTR Raw'!G8 -> 304.59 | AN21: ='QTR Raw'!H6+'QTR Raw'!H8 -> 371.37 | AO21: ='QTR Raw'!I6+'QTR Raw'!I8 -> 393.85 | AP21: ='QTR Raw'!J6+'QTR Raw'!J8 -> 400.7 | ... CJ21: ='QTR Raw'!BD6+'QTR Raw'!BD8 -> 2434.65 | CK21: 2724.2 | CL21: ='QTR Raw'!BF6+'QTR Raw'!BF8 -> 2585.64 | CM21: =CM9 -> 2681.3437 | CN21: =CN9 -> 2821.0118 | CO21: =CO9 -> 3186.0211 | CP21: =CP9 -> 3020.3431 | CQ21: =CQ9 -> 3121.1242 | CR21: =CR9 -> 3302.9226 | CS21: =CS9 -> 3724.9773 | CT21: =CT9 -> 3414.4072 | ... DA21: =DA9 -> 4735.3384 | DE21: 9685.85
A22: Less: Exise Duty | B22: ='Annual Raw'!C7+'Annual Raw'!C8+'Annual Raw'!C9 -> 0 | C22: ='Annual Raw'!D7+'Annual Raw'!D8+'Annual Raw'!D9 -> 0 | D22: ='Annual Raw'!E7+'Annual Raw'!E8+'Annual Raw'!E9 -> 34.28 | E22: ='Annual Raw'!F7+'Annual Raw'!F8+'Annual Raw'!F9 -> 38.87 | F22: ='Annual Raw'!G7+'Annual Raw'!G8+'Annual Raw'!G9 -> 45.63 | G22: ='Annual Raw'!H7+'Annual Raw'!H8+'Annual Raw'!H9 -> 54.33 | H22: ='Annual Raw'!I7+'Annual Raw'!I8+'Annual Raw'!I9 -> 70.21 | I22: ='Annual Raw'!J7+'Annual Raw'!J8+'Annual Raw'!J9 -> 74.67 | ... AA22: ='Annual Raw'!AB7+'Annual Raw'!AB8+'Annual Raw'!AB9 -> 138.06 | AB22: =+SUM(CL22:CO22) -> 0 | AC22: =+SUM(CP22:CS22) -> 0 | AD22: =+SUM(CT22:CW22) -> 0 | AE22: =+SUM(CX22:DA22) -> 0 | AI22: ='QTR Raw'!C21+'QTR Raw'!C20+'QTR Raw'!C19+'QTR Raw'!C13+'QTR Raw'!C7 -> 0 | AJ22: ='QTR Raw'!D21+'QTR Raw'!D20+'QTR Raw'!D19+'QTR Raw'!D13+'QTR Raw'!D7 -> 0 | AK22: ='QTR Raw'!E21+'QTR Raw'!E20+'QTR Raw'!E19+'QTR Raw'!E13+'QTR Raw'!E7 -> 0 | AL22: ='QTR Raw'!F21+'QTR Raw'!F20+'QTR Raw'!F19+'QTR Raw'!F13+'QTR Raw'!F7 -> 0 | AM22: ='QTR Raw'!G21+'QTR Raw'!G20+'QTR Raw'!G19+'QTR Raw'!G13+'QTR Raw'!G7 -> 0 | AN22: ='QTR Raw'!H21+'QTR Raw'!H20+'QTR Raw'!H19+'QTR Raw'!H13+'QTR Raw'!H7 -> 0 | AO22: ='QTR Raw'!I21+'QTR Raw'!I20+'QTR Raw'!I19+'QTR Raw'!I13+'QTR Raw'!I7 -> 0 | AP22: ='QTR Raw'!J21+'QTR Raw'!J20+'QTR Raw'!J19+'QTR Raw'!J13+'QTR Raw'!J7 -> 0 | ... CJ22: ='QTR Raw'!BD21+'QTR Raw'!BD20+'QTR Raw'!BD19+'QTR Raw'!BD13+'QTR Raw'!BD7 -> 0 | CL22: ='QTR Raw'!BF21+'QTR Raw'!BF20+'QTR Raw'!BF19+'QTR Raw'!BF13+'QTR Raw'!BF7 -> 0 | DE22: 0
A23: Net Revenue | B23: =+B21-B22 -> 0 | C23: =+C21-C22 -> 0 | D23: =+D21-D22 -> 244.31 | E23: =+E21-E22 -> 266.91 | F23: =+F21-F22 -> 323.12 | G23: =+G21-G22 -> 408.32 | H23: =+H21-H22 -> 542.04 | I23: =+I21-I22 -> 641.3 | ... AE23: =+AE21-AE22 -> 16765.96 | AI23: =+AI21-AI22 -> 380.12 | AJ23: =+AJ21-AJ22 -> 356.17 | AK23: =+AK21-AK22 -> 347.12 | AL23: =+AL21-AL22 -> 332.61 | AM23: =+AM21-AM22 -> 304.59 | AN23: =+AN21-AN22 -> 371.37 | AO23: =+AO21-AO22 -> 393.85 | AP23: =+AP21-AP22 -> 400.7 | ... DA23: =+DA21-DA22 -> 4735.3384 | DE23: 9685.85
A24: Net Revenue YOY% | C24: =C23/B23-1 -> #DIV/0! | D24: =D23/C23-1 -> #DIV/0! | E24: =E23/D23-1 -> 0.092505423 | F24: =F23/E23-1 -> 0.21059533 | G24: =G23/F23-1 -> 0.26367913 | H24: =H23/G23-1 -> 0.32748824 | I24: =I23/H23-1 -> 0.18312302 | J24: =J23/I23-1 -> 0.16078278 | ... AE24: =AE23/AD23-1 -> 0.13017643 | AM24: =+IF(AI23<0,1-AM23/AI23,AM23/AI23-1) -> -0.19870041 | AN24: =+IF(AJ23<0,1-AN23/AJ23,AN23/AJ23-1) -> 0.04267625 | AO24: =+IF(AK23<0,1-AO23/AK23,AO23/AK23-1) -> 0.13462203 | AP24: =+IF(AL23<0,1-AP23/AL23,AP23/AL23-1) -> 0.20471423 | AQ24: =+IF(AM23<0,1-AQ23/AM23,AQ23/AM23-1) -> 0.28622082 | AR24: =+IF(AN23<0,1-AR23/AN23,AR23/AN23-1) -> 0.10450494 | AS24: =+IF(AO23<0,1-AS23/AO23,AS23/AO23-1) -> 0.090516694 | AT24: =+IF(AP23<0,1-AT23/AP23,AT23/AP23-1) -> 0.020813576 | ... DA24: =+IF(CW23<0,1-DA23/CW23,DA23/CW23-1) -> 0.13085585 | DE24: 0.17655526
A25: Net Revenue QOQ% | AJ25: =+IF(AI23<0,1-AJ23/AI23,AJ23/AI23-1) -> -0.063006419 | AK25: =+IF(AJ23<0,1-AK23/AJ23,AK23/AJ23-1) -> -0.025409215 | AL25: =+IF(AK23<0,1-AL23/AK23,AL23/AK23-1) -> -0.041801106 | AM25: =+IF(AL23<0,1-AM23/AL23,AM23/AL23-1) -> -0.084242807 | AN25: =+IF(AM23<0,1-AN23/AM23,AN23/AM23-1) -> 0.21924554 | AO25: =+IF(AN23<0,1-AO23/AN23,AO23/AN23-1) -> 0.060532622 | AP25: =+IF(AO23<0,1-AP23/AO23,AP23/AO23-1) -> 0.017392408 | AQ25: =+IF(AP23<0,1-AQ23/AP23,AQ23/AP23-1) -> -0.022286 | ... DA25: =+IF(CZ23<0,1-DA23/CZ23,DA23/CZ23-1) -> 0.12346869
A26: Increase/Decrease in Stock | B26: ='Annual Raw'!C11 -> 0 | C26: ='Annual Raw'!D11 -> 0 | D26: ='Annual Raw'!E11 -> -3.371 | E26: ='Annual Raw'!F11 -> 4.7 | F26: ='Annual Raw'!G11 -> 0.58 | G26: ='Annual Raw'!H11 -> -4.68 | H26: ='Annual Raw'!I11 -> -17.98 | I26: ='Annual Raw'!J11 -> -6.41 | ... AA26: ='Annual Raw'!AB11 -> -94.1 | AB26: =+SUM(CL26:CO26) -> -137.41 | AC26: =+SUM(CP26:CS26) -> 0 | AD26: =+SUM(CT26:CW26) -> 0 | AE26: =+SUM(CX26:DA26) -> 0 | AI26: ='QTR Raw'!C10 -> 10.69 | AJ26: ='QTR Raw'!D10 -> -17.41 | AK26: ='QTR Raw'!E10 -> 22.81 | AL26: ='QTR Raw'!F10 -> 3.36 | AM26: ='QTR Raw'!G10 -> -28.38 | AN26: ='QTR Raw'!H10 -> -9.71 | AO26: ='QTR Raw'!I10 -> 2.53 | AP26: ='QTR Raw'!J10 -> 5.57 | ... CJ26: ='QTR Raw'!BD10 -> -112.03 | CK26: 25.4 | CL26: ='QTR Raw'!BF10 -> -137.41 | DE26: -94.1
A27: Purchase of Finished Goods | B27: 0 | C27: 0 | D27: 0 | E27: 0 | F27: 0 | G27: 0 | H27: 0 | I27: 0 | J27: 0 | K27: 0 | L27: 0 | M27: 0 | N27: 0 | O27: 0 | P27: 0 | Q27: 0 | R27: 0 | S27: 0 | T27: 0 | U27: 0 | V27: 0 | W27: 0 | X27: 0 | Y27: 0 | Z27: 0 | AA27: 0 | AB27: =+SUM(CL27:CO27) -> 574.01 | AC27: =+SUM(CP27:CS27) -> 0 | AD27: =+SUM(CT27:CW27) -> 0 | AE27: =+SUM(CX27:DA27) -> 0 | AI27: ='QTR Raw'!C12 -> 97.75 | AJ27: ='QTR Raw'!D12 -> 110.68 | AK27: ='QTR Raw'!E12 -> 103.85 | AL27: ='QTR Raw'!F12 -> 90.3 | AM27: ='QTR Raw'!G12 -> 90.04 | AN27: ='QTR Raw'!H12 -> 124.51 | AO27: ='QTR Raw'!I12 -> 120.76 | AP27: ='QTR Raw'!J12 -> 99.17 | ... CJ27: ='QTR Raw'!BD12 -> 539.41 | CK27: 534.29 | CL27: ='QTR Raw'!BF12 -> 574.01 | DE27: 1986.37
A28: Raw Material Consumed | B28: ='Annual Raw'!C12 -> 0 | C28: ='Annual Raw'!D12 -> 0 | D28: ='Annual Raw'!E12 -> 96.38 | E28: ='Annual Raw'!F12 -> 109.2 | F28: ='Annual Raw'!G12 -> 146.91 | G28: ='Annual Raw'!H12 -> 195.24 | H28: ='Annual Raw'!I12 -> 278.23 | I28: ='Annual Raw'!J12 -> 321.7 | ... AA28: ='Annual Raw'!AB12 -> 6026.64 | AB28: =+SUM(CL28:CO28) -> 6478.3757 | AC28: =+SUM(CP28:CS28) -> 8073.3197 | AD28: =+SUM(CT28:CW28) -> 9093.7579 | AE28: =+SUM(CX28:DA28) -> 10277.502 | AI28: ='QTR Raw'!C11 -> 130.26 | AJ28: ='QTR Raw'!D11 -> 126.94 | AK28: ='QTR Raw'!E11 -> 100.03 | AL28: ='QTR Raw'!F11 -> 119.5 | AM28: ='QTR Raw'!G11 -> 118.01 | AN28: ='QTR Raw'!H11 -> 125.63 | AO28: ='QTR Raw'!I11 -> 140.54 | AP28: ='QTR Raw'!J11 -> 144.93 | ... CJ28: ='QTR Raw'!BD11 -> 1063.5 | CK28: 1105.56 | CL28: ='QTR Raw'!BF11 -> 1156.3 | CM28: =+CM23-CM29 -> 1640.2414 | CN28: =+CN23-CN29 -> 1728.8708 | CO28: =+CO23-CO29 -> 1952.9635 | CP28: =+CP23-CP29 -> 1852.6888 | CQ28: =+CQ23-CQ29 -> 1912.4383 | CR28: =+CR23-CR29 -> 2024.6728 | CS28: =+CS23-CS29 -> 2283.5198 | CT28: =+CT23-CT29 -> 2093.1743 | ... DA28: =+DA23-DA29 -> 2902.7613 | DE28: 4040.27
A29: Gross Profit | B29: =B23-B26-B28-B27 -> 0 | C29: =C23-C26-C28-C27 -> 0 | D29: =D23-D26-D28-D27 -> 151.301 | E29: =E23-E26-E28-E27 -> 153.01 | F29: =F23-F26-F28-F27 -> 175.63 | G29: =G23-G26-G28-G27 -> 217.76 | H29: =H23-H26-H28-H27 -> 281.79 | I29: =I23-I26-I28-I27 -> 326.01 | ... AE29: =AE23-AE26-AE28-AE27 -> 6488.4572 | AI29: =AI23-AI26-AI28-AI27 -> 141.42 | AJ29: =AJ23-AJ26-AJ28-AJ27 -> 135.96 | AK29: =AK23-AK26-AK28-AK27 -> 120.43 | AL29: =AL23-AL26-AL28-AL27 -> 119.45 | AM29: =AM23-AM26-AM28-AM27 -> 124.92 | AN29: =AN23-AN26-AN28-AN27 -> 130.94 | AO29: =AO23-AO26-AO28-AO27 -> 130.02 | AP29: =AP23-AP26-AP28-AP27 -> 151.03 | ... CL29: =CL23-CL26-CL28-CL27 -> 992.74 | CM29: =+CM30*CM23 -> 1041.1023 | CN29: =+CN30*CN23 -> 1092.141 | CO29: =+CO30*CO23 -> 1233.0576 | CP29: =+CP30*CP23 -> 1167.6543 | CQ29: =+CQ30*CQ23 -> 1208.6859 | CR29: =+CR30*CR23 -> 1278.2497 | CS29: =+CS30*CS23 -> 1441.4574 | CT29: =+CT30*CT23 -> 1321.2329 | ... DA29: =+DA30*DA23 -> 1832.577 | DE29: 3753.31
A30: GP% | B30: =B29/B23 -> #DIV/0! | C30: =C29/C23 -> #DIV/0! | D30: =D29/D23 -> 0.61929925 | E30: =E29/E23 -> 0.5732644 | F30: =F29/F23 -> 0.54354419 | G30: =G29/G23 -> 0.53330721 | H30: =H29/H23 -> 0.51986938 | I30: =I29/I23 -> 0.50835802 | ... AE30: =AE29/AE23 -> 0.38700184 | AI30: =AI29/AI23 -> 0.37204041 | AJ30: =AJ29/AJ23 -> 0.38172783 | AK30: =AK29/AK23 -> 0.34694054 | AL30: =AL29/AL23 -> 0.35912931 | AM30: =AM29/AM23 -> 0.41012509 | AN30: =AN29/AN23 -> 0.35258637 | AO30: =AO29/AO23 -> 0.33012568 | AP30: =AP29/AP23 -> 0.3769154 | ... CL30: =CL29/CL23 -> 0.38394363 | CM30: =AVERAGE(CI30:CL30) -> 0.38827633 | CN30: =AVERAGE(CJ30:CM30) -> 0.38714513 | CO30: =AVERAGE(CK30:CN30) -> 0.38702118 | CP30: =AVERAGE(CL30:CO30) -> 0.38659656 | CQ30: =AVERAGE(CM30:CP30) -> 0.3872598 | CR30: =AVERAGE(CN30:CQ30) -> 0.38700567 | CS30: =AVERAGE(CO30:CR30) -> 0.3869708 | CT30: =AVERAGE(CP30:CS30) -> 0.38695821 | ... DA30: =AVERAGE(CW30:CZ30) -> 0.38700023 | DE30: 0.38750445
A31: GP YOY% | C31: =+IF(B29<0,1-C29/B29,C29/B29-1) -> #DIV/0! | D31: =+IF(C29<0,1-D29/C29,D29/C29-1) -> #DIV/0! | E31: =+IF(D29<0,1-E29/D29,E29/D29-1) -> 0.011295365 | F31: =+IF(E29<0,1-F29/E29,F29/E29-1) -> 0.14783347 | G31: =+IF(F29<0,1-G29/F29,G29/F29-1) -> 0.23987929 | H31: =+IF(G29<0,1-H29/G29,H29/G29-1) -> 0.29403931 | I31: =+IF(H29<0,1-I29/H29,I29/H29-1) -> 0.15692537 | J31: =+IF(I29<0,1-J29/I29,J29/I29-1) -> 0.12616177 | ... AE31: =+IF(AD29<0,1-AE29/AD29,AE29/AD29-1) -> 0.13018485 | AM31: =+IF(AI29<0,1-AM29/AI29,AM29/AI29-1) -> -0.11667374 | AN31: =+IF(AJ29<0,1-AN29/AJ29,AN29/AJ29-1) -> -0.036922624 | AO31: =+IF(AK29<0,1-AO29/AK29,AO29/AK29-1) -> 0.079631321 | AP31: =+IF(AL29<0,1-AP29/AL29,AP29/AL29-1) -> 0.2643784 | AQ31: =+IF(AM29<0,1-AQ29/AM29,AQ29/AM29-1) -> 0.23775216 | AR31: =+IF(AN29<0,1-AR29/AN29,AR29/AN29-1) -> 0.26867267 | AS31: =+IF(AO29<0,1-AS29/AO29,AS29/AO29-1) -> 0.25411475 | AT31: =+IF(AP29<0,1-AT29/AP29,AT29/AP29-1) -> 0.14679203 | ... CL31: =+IF(CH29<0,1-CL29/CH29,CL29/CH29-1) -> 0.20115186 | CM31: =+CM29/CI29-1 -> 0.12661213 | CN31: =+CN29/CJ29-1 -> 0.15721096 | CO31: =+CO29/CK29-1 -> 0.16441535 | CP31: =+CP29/CL29-1 -> 0.17619342 | CQ31: =+CQ29/CM29-1 -> 0.16096752 | CR31: =+CR29/CN29-1 -> 0.17040727 | CS31: =+CS29/CO29-1 -> 0.1690106 | CT31: =+CT29/CP29-1 -> 0.13152751 | ... DA31: =+DA29/CW29-1 -> 0.13087591 | DE31: 0.22041002
A32: GP QOQ% | AJ32: =+IF(AI29<0,1-AJ29/AI29,AJ29/AI29-1) -> -0.038608401 | AK32: =+IF(AJ29<0,1-AK29/AJ29,AK29/AJ29-1) -> -0.11422477 | AL32: =+IF(AK29<0,1-AL29/AK29,AL29/AK29-1) -> -0.0081375073 | AM32: =+IF(AL29<0,1-AM29/AL29,AM29/AL29-1) -> 0.045793219 | AN32: =+IF(AM29<0,1-AN29/AM29,AN29/AM29-1) -> 0.048190842 | AO32: =+IF(AN29<0,1-AO29/AN29,AO29/AN29-1) -> -0.0070261188 | AP32: =+IF(AO29<0,1-AP29/AO29,AP29/AO29-1) -> 0.16159052 | AQ32: =+IF(AP29<0,1-AQ29/AP29,AQ29/AP29-1) -> 0.023770112 | ... CL32: =+IF(CK29<0,1-CL29/CK29,CL29/CK29-1) -> -0.062524198 | CM32: =+CM29/CL29-1 -> 0.04871595 | CN32: =+CN29/CM29-1 -> 0.049023725 | CO32: =+CO29/CN29-1 -> 0.12902789 | CP32: =+CP29/CO29-1 -> -0.053041621 | CQ32: =+CQ29/CP29-1 -> 0.035140255 | CR32: =+CR29/CQ29-1 -> 0.05755327 | CS32: =+CS29/CR29-1 -> 0.12768059 | CT32: =+CT29/CS29-1 -> -0.083404842 | ... DA32: =+DA29/CZ29-1 -> 0.12347124
A33: Power & Fuel Cost | B33: ='Annual Raw'!C13 -> 0 | C33: ='Annual Raw'!D13 -> 0 | D33: ='Annual Raw'!E13 -> 9.8 | E33: ='Annual Raw'!F13 -> 9.72 | F33: ='Annual Raw'!G13 -> 10.4 | G33: ='Annual Raw'!H13 -> 10.95 | H33: ='Annual Raw'!I13 -> 13.32 | I33: ='Annual Raw'!J13 -> 14.94 | ... AA33: ='Annual Raw'!AB13 -> 121.56 | AB33: =+SUM(CL33:CO33) -> 0 | AC33: =+SUM(CP33:CS33) -> 0 | AD33: =+SUM(CT33:CW33) -> 0 | AE33: =+SUM(CX33:DA33) -> 0 | AI33: ='QTR Raw'!C15 -> 0 | AJ33: ='QTR Raw'!D15 -> 0 | AK33: ='QTR Raw'!E15 -> 0 | AL33: ='QTR Raw'!F15 -> 0 | AM33: ='QTR Raw'!G15 -> 0 | AN33: ='QTR Raw'!H15 -> 0 | AO33: ='QTR Raw'!I15 -> 0 | AP33: ='QTR Raw'!J15 -> 0 | ... CJ33: ='QTR Raw'!BD15 -> 0 | CL33: ='QTR Raw'!BF15 -> 0 | DE33: 0
A34: Selling and Distribution Expenses | B34: =('Annual Raw'!C18) -> 0 | C34: =('Annual Raw'!D18) -> 0 | D34: =('Annual Raw'!E18) -> 10.31 | E34: =('Annual Raw'!F18) -> 13.57 | F34: =('Annual Raw'!G18) -> 15.67 | G34: =('Annual Raw'!H18) -> 15.75 | H34: =('Annual Raw'!I18) -> 19.31 | I34: =('Annual Raw'!J18) -> 25.71 | ... AA34: =('Annual Raw'!AB18) -> 136.94 | AB34: =+SUM(CL34:CO34) -> 0 | AC34: =+SUM(CP34:CS34) -> 0 | AD34: =+SUM(CT34:CW34) -> 0 | AE34: =+SUM(CX34:DA34) -> 0 | AI34: ='QTR Raw'!C18 -> 0 | AJ34: ='QTR Raw'!D18 -> 0 | AK34: ='QTR Raw'!E18 -> 0 | AL34: ='QTR Raw'!F18 -> 0 | AM34: ='QTR Raw'!G18 -> 0 | AN34: ='QTR Raw'!H18 -> 0 | AO34: ='QTR Raw'!I18 -> 0 | AP34: ='QTR Raw'!J18 -> 0 | ... CJ34: ='QTR Raw'!BD18 -> 0 | CL34: ='QTR Raw'!BF18 -> 0 | DE34: 0
A35: Other Manufacturing Expenses | B35: ='Annual Raw'!C15+'Annual Raw'!C16 -> 0 | C35: ='Annual Raw'!D15+'Annual Raw'!D16 -> 0 | D35: ='Annual Raw'!E15+'Annual Raw'!E16 -> 34.35 | E35: ='Annual Raw'!F15+'Annual Raw'!F16 -> 36.17 | F35: ='Annual Raw'!G15+'Annual Raw'!G16 -> 47.84 | G35: ='Annual Raw'!H15+'Annual Raw'!H16 -> 55.7 | H35: ='Annual Raw'!I15+'Annual Raw'!I16 -> 65.14 | I35: ='Annual Raw'!J15+'Annual Raw'!J16 -> 68.68 | ... AA35: ='Annual Raw'!AB15+'Annual Raw'!AB16 -> 708.8 | AB35: =+SUM(CL35:CO35) -> 1637.2225 | AC35: =+SUM(CP35:CS35) -> 1984.397 | AD35: =+SUM(CT35:CW35) -> 2320.8337 | AE35: =+SUM(CX35:DA35) -> 2671.7653 | AI35: ='QTR Raw'!C14 -> 49.64 | AJ35: ='QTR Raw'!D14 -> 56.7 | AK35: ='QTR Raw'!E14 -> 48.75 | AL35: ='QTR Raw'!F14 -> 48.06 | AM35: ='QTR Raw'!G14 -> 51.53 | AN35: ='QTR Raw'!H14 -> 49.01 | AO35: ='QTR Raw'!I14 -> 54.01 | AP35: ='QTR Raw'!J14 -> 57.84 | ... CJ35: ='QTR Raw'!BD14 -> 336.76 | CK35: 403.44 | CL35: ='QTR Raw'!BF14 -> 367.12 | CM35: =CM39-CM36 -> 387.81698 | CN35: =CN39-CN36 -> 413.42334 | CO35: =CO39-CO36 -> 468.86223 | CP35: =CP39-CP36 -> 455.97374 | CQ35: =CQ39-CQ36 -> 463.92756 | CR35: =CR39-CR36 -> 500.77415 | CS35: =CS39-CS36 -> 563.72158 | CT35: =CT39-CT36 -> 534.29658 | ... DA35: =DA39-DA36 -> 757.07616 | DE35: 1381.65
A36: Employee Cost | B36: ='Annual Raw'!C14 -> 0 | C36: ='Annual Raw'!D14 -> 0 | D36: ='Annual Raw'!E14 -> 27.84 | E36: ='Annual Raw'!F14 -> 28.02 | F36: ='Annual Raw'!G14 -> 32.32 | G36: ='Annual Raw'!H14 -> 35.32 | H36: ='Annual Raw'!I14 -> 41.34 | I36: ='Annual Raw'!J14 -> 51.56 | ... AA36: ='Annual Raw'!AB14 -> 608.64 | AB36: =+SUM(CL36:CO36) -> 654.3944 | AC36: =+SUM(CP36:CS36) -> 700.20201 | AD36: =+SUM(CT36:CW36) -> 749.21615 | AE36: =+SUM(CX36:DA36) -> 801.66128 | AI36: ='QTR Raw'!C16 -> 27.87 | AJ36: ='QTR Raw'!D16 -> 27.67 | AK36: ='QTR Raw'!E16 -> 30.36 | AL36: ='QTR Raw'!F16 -> 29.94 | AM36: ='QTR Raw'!G16 -> 31.76 | AN36: ='QTR Raw'!H16 -> 31.27 | AO36: ='QTR Raw'!I16 -> 26.16 | AP36: ='QTR Raw'!J16 -> 37.48 | ... CJ36: ='QTR Raw'!BD16 -> 151.07 | CK36: 171.39 | CL36: ='QTR Raw'!BF16 -> 147.3 | CM36: =CI36*107% -> 162.0622 | CN36: =CJ36*107% -> 161.6449 | CO36: =CK36*107% -> 183.3873 | CP36: =CL36*107% -> 157.611 | CQ36: =CM36*107% -> 173.40655 | CR36: =CN36*107% -> 172.96004 | CS36: =CO36*107% -> 196.22441 | CT36: =CP36*107% -> 168.64377 | ... DA36: =CW36*107% -> 224.65733 | DE36: 608.64
A37: General and Administration Expenses | B37: ='Annual Raw'!C17 -> 0 | C37: ='Annual Raw'!D17 -> 0 | D37: ='Annual Raw'!E17 -> 19.26 | E37: ='Annual Raw'!F17 -> 19.14 | F37: ='Annual Raw'!G17 -> 13.69 | G37: ='Annual Raw'!H17 -> 17.67 | H37: ='Annual Raw'!I17 -> 20.63 | I37: ='Annual Raw'!J17 -> 24.51 | ... AA37: ='Annual Raw'!AB17 -> 369.01 | AB37: =+SUM(CL37:CO37) -> 0 | AC37: =+SUM(CP37:CS37) -> 0 | AD37: =+SUM(CT37:CW37) -> 0 | AE37: =+SUM(CX37:DA37) -> 0 | AI37: ='QTR Raw'!C17 -> 0 | AJ37: ='QTR Raw'!D17 -> 0 | AK37: ='QTR Raw'!E17 -> 0 | AL37: ='QTR Raw'!F17 -> 0 | AM37: ='QTR Raw'!G17 -> 0 | AN37: ='QTR Raw'!H17 -> 0 | AO37: ='QTR Raw'!I17 -> 0 | AP37: ='QTR Raw'!J17 -> 0 | ... CJ37: ='QTR Raw'!BD17 -> 0 | CL37: ='QTR Raw'!BF17 -> 0 | DE37: 0
A38: Miscellaneous Expenses | B38: ='Annual Raw'!C19-'Annual Raw'!C20 -> 0 | C38: ='Annual Raw'!D19-'Annual Raw'!D20 -> 0 | D38: ='Annual Raw'!E19-'Annual Raw'!E20 -> 5.611 | E38: ='Annual Raw'!F19-'Annual Raw'!F20 -> 4.1 | F38: ='Annual Raw'!G19-'Annual Raw'!G20 -> 2.92 | G38: ='Annual Raw'!H19-'Annual Raw'!H20 -> 3.79 | H38: ='Annual Raw'!I19-'Annual Raw'!I20 -> 3.91 | I38: ='Annual Raw'!J19-'Annual Raw'!J20 -> 9.68 | ... AA38: ='Annual Raw'!AB19-'Annual Raw'!AB20 -> 45.18 | AB38: =+SUM(CL38:CO38) -> 0 | AC38: =+SUM(CP38:CS38) -> 0 | AD38: =+SUM(CT38:CW38) -> 0 | AE38: =+SUM(CX38:DA38) -> 0 | DE38: 0
A39: Total Cost | B39: =+SUM(B33:B38) -> 0 | C39: =+SUM(C33:C38) -> 0 | D39: =+SUM(D33:D38) -> 107.171 | E39: =+SUM(E33:E38) -> 110.72 | F39: =+SUM(F33:F38) -> 122.84 | G39: =+SUM(G33:G38) -> 139.18 | H39: =+SUM(H33:H38) -> 163.65 | I39: =+SUM(I33:I38) -> 195.08 | ... AE39: =+SUM(AE33:AE38) -> 3473.4266 | AI39: =+SUM(AI33:AI38) -> 77.51 | AJ39: =+SUM(AJ33:AJ38) -> 84.37 | AK39: =+SUM(AK33:AK38) -> 79.11 | AL39: =+SUM(AL33:AL38) -> 78 | AM39: =+SUM(AM33:AM38) -> 83.29 | AN39: =+SUM(AN33:AN38) -> 80.28 | AO39: =+SUM(AO33:AO38) -> 80.17 | AP39: =+SUM(AP33:AP38) -> 95.32 | ... CL39: =+SUM(CL33:CL38) -> 514.42 | CM39: =CM40*CM23 -> 549.87918 | CN39: =CN40*CN23 -> 575.06824 | CO39: =CO40*CO23 -> 652.24953 | CP39: =CP40*CP23 -> 613.58474 | CQ39: =CQ40*CQ23 -> 637.33411 | CR39: =CR40*CR23 -> 673.7342 | CS39: =CS40*CS23 -> 759.94599 | CT39: =CT40*CT23 -> 702.94035 | ... DA39: =DA40*DA23 -> 981.73348 | DE39: 1990.29
A40: Cost % | B40: =B39/B23 -> #DIV/0! | C40: =C39/C23 -> #DIV/0! | D40: =D39/D23 -> 0.43866809 | E40: =E39/E23 -> 0.41482148 | F40: =F39/F23 -> 0.38016836 | G40: =G39/G23 -> 0.34086011 | H40: =H39/H23 -> 0.30191499 | I40: =I39/I23 -> 0.3041946 | ... AE40: =AE39/AE23 -> 0.20717135 | AI40: =AI39/AI23 -> 0.20390929 | AJ40: =AJ39/AJ23 -> 0.23688126 | AK40: =AK39/AK23 -> 0.22790389 | AL40: =AL39/AL23 -> 0.23450888 | AM40: =AM39/AM23 -> 0.27344956 | AN40: =AN39/AN23 -> 0.21617255 | AO40: =AO39/AO23 -> 0.20355465 | AP40: =AP39/AP23 -> 0.2378837 | ... CL40: =CL39/CL23 -> 0.19895268 | CM40: =AVERAGE(CI40:CL40) -> 0.20507598 | CN40: =AVERAGE(CJ40:CM40) -> 0.20385176 | CO40: =AVERAGE(CK40:CN40) -> 0.20472229 | CP40: =AVERAGE(CL40:CO40) -> 0.20315068 | CQ40: =AVERAGE(CM40:CP40) -> 0.20420018 | CR40: =AVERAGE(CN40:CQ40) -> 0.20398123 | CS40: =AVERAGE(CO40:CR40) -> 0.20401359 | CT40: =AVERAGE(CP40:CS40)*1.01 -> 0.20587478 | CU40: =AVERAGE(CQ40:CT40)*1.01 -> 0.20656262 | CV40: =AVERAGE(CR40:CU40)*1.01 -> 0.20715914 | CW40: =AVERAGE(CS40:CV40)*1.01 -> 0.20796156 | CX40: =AVERAGE(CT40:CW40) -> 0.20688952 | CY40: =AVERAGE(CU40:CX40) -> 0.20714321 | CZ40: =AVERAGE(CV40:CY40) -> 0.20728836 | DA40: =AVERAGE(CW40:CZ40) -> 0.20732066 | DE40: 0.20548429
A41: EBITDA | B41: =B29-B39 -> 0 | C41: =C29-C39 -> 0 | D41: =D29-D39 -> 44.13 | E41: =E29-E39 -> 42.29 | F41: =F29-F39 -> 52.79 | G41: =G29-G39 -> 78.58 | H41: =H29-H39 -> 118.14 | I41: =I29-I39 -> 130.93 | ... AE41: =AE29-AE39 -> 3015.0307 | AI41: =AI29-AI39 -> 63.91 | AJ41: =AJ29-AJ39 -> 51.59 | AK41: =AK29-AK39 -> 41.32 | AL41: =AL29-AL39 -> 41.45 | AM41: =AM29-AM39 -> 41.63 | AN41: =AN29-AN39 -> 50.66 | AO41: =AO29-AO39 -> 49.85 | AP41: =AP29-AP39 -> 55.71 | ... DA41: =DA29-DA39 -> 850.84355 | DE41: 1763.02
A42: EBITDA Margins | B42: =B41/B23 -> #DIV/0! | C42: =C41/C23 -> #DIV/0! | D42: =D41/D23 -> 0.18063117 | E42: =E41/E23 -> 0.15844292 | F42: =F41/F23 -> 0.16337584 | G42: =G41/G23 -> 0.1924471 | H42: =H41/H23 -> 0.21795439 | I42: =I41/I23 -> 0.20416342 | ... AE42: =AE41/AE23 -> 0.17983049 | AI42: =AI41/AI23 -> 0.16813112 | AJ42: =AJ41/AJ23 -> 0.14484656 | AK42: =AK41/AK23 -> 0.11903664 | AL42: =AL41/AL23 -> 0.12462043 | AM42: =AM41/AM23 -> 0.13667553 | AN42: =AN41/AN23 -> 0.13641382 | AO42: =AO41/AO23 -> 0.12657103 | AP42: =AP41/AP23 -> 0.13903169 | ... DA42: =DA41/DA23 -> 0.17967957 | DE42: 0.18202016
A43: EBITDA YOY% | C43: =+IF(B41<0,1-C41/B41,C41/B41-1) -> #DIV/0! | D43: =+IF(C41<0,1-D41/C41,D41/C41-1) -> #DIV/0! | E43: =+IF(D41<0,1-E41/D41,E41/D41-1) -> -0.041694992 | F43: =+IF(E41<0,1-F41/E41,F41/E41-1) -> 0.24828565 | G43: =+IF(F41<0,1-G41/F41,G41/F41-1) -> 0.4885395 | H43: =+IF(G41<0,1-H41/G41,H41/G41-1) -> 0.50343599 | I43: =+IF(H41<0,1-I41/H41,I41/H41-1) -> 0.10826138 | J43: =+IF(I41<0,1-J41/I41,J41/I41-1) -> 0.12082792 | ... AE43: =+IF(AD41<0,1-AE41/AD41,AE41/AD41-1) -> 0.1287986 | AM43: =+IF(AI41<0,1-AM41/AI41,AM41/AI41-1) -> -0.34861524 | AN43: =+IF(AJ41<0,1-AN41/AJ41,AN41/AJ41-1) -> -0.018026749 | AO43: =+IF(AK41<0,1-AO41/AK41,AO41/AK41-1) -> 0.20643756 | AP43: =+IF(AL41<0,1-AP41/AL41,AP41/AL41-1) -> 0.34402895 | AQ43: =+IF(AM41<0,1-AQ41/AM41,AQ41/AM41-1) -> 0.52822484 | AR43: =+IF(AN41<0,1-AR41/AN41,AR41/AN41-1) -> 0.18535334 | AS43: =+IF(AO41<0,1-AS41/AO41,AS41/AO41-1) -> 0.25095286 | AT43: =+IF(AP41<0,1-AT41/AP41,AT41/AP41-1) -> 0.13713875 | ... CL43: =+IF(CH41<0,1-CL41/CH41,CL41/CH41-1) -> 0.21759495 | CM43: =+CM41/CI41-1 -> 0.14206058 | CN43: =+CN41/CJ41-1 -> 0.13408069 | CO43: =+CO41/CK41-1 -> 0.19971928 | CP43: =+CP41/CL41-1 -> 0.15836577 | CQ43: =+CQ41/CM41-1 -> 0.16312083 | CR43: =+CR41/CN41-1 -> 0.16911123 | CS43: =+CS41/CO41-1 -> 0.17338488 | CT43: =+CT41/CP41-1 -> 0.11591153 | ... DA43: =+DA41/CW41-1 -> 0.13494744 | DE43: 0.2193489
A44: EBITDA QOQ% | AJ44: =+IF(AI41<0,1-AJ41/AI41,AJ41/AI41-1) -> -0.19277108 | AK44: =+IF(AJ41<0,1-AK41/AJ41,AK41/AJ41-1) -> -0.19906959 | AL44: =+IF(AK41<0,1-AL41/AK41,AL41/AK41-1) -> 0.0031461762 | AM44: =+IF(AL41<0,1-AM41/AL41,AM41/AL41-1) -> 0.0043425814 | AN44: =+IF(AM41<0,1-AN41/AM41,AN41/AM41-1) -> 0.21691088 | AO44: =+IF(AN41<0,1-AO41/AN41,AO41/AN41-1) -> -0.015988946 | AP44: =+IF(AO41<0,1-AP41/AO41,AP41/AO41-1) -> 0.11755266 | AQ44: =+IF(AP41<0,1-AQ41/AP41,AQ41/AP41-1) -> 0.14198528 | ... CI44: =+IF(CH41<0,1-CI41/CH41,CI41/CH41-1) -> 0.094898686 | CJ44: =+IF(CI41>1,CJ41/CI41-1,1-CJ41/CI41) -> 0.060029759 | CK44: =+IF(CJ41<0,1-CK41/CJ41,CK41/CJ41-1) -> 0.061806378 | CL44: =+IF(CK41>1,CL41/CK41-1,1-CL41/CK41) -> -0.011980501 | CM44: =+CM41/CL41-1 -> 0.026975864 | CN44: =+CN41/CM41-1 -> 0.05262304 | CO44: =+CO41/CN41-1 -> 0.12326187 | CP44: =+CP41/CO41-1 -> -0.046036867 | CQ44: =+CQ41/CP41-1 -> 0.031191569 | CR44: =+CR41/CQ41-1 -> 0.058044344 | CS44: =+CS41/CR41-1 -> 0.12736792 | CT44: =+CT41/CS41-1 -> -0.092762764 | ... DA44: =+DA41/CZ41-1 -> 0.12327224
...

Sheet QTR Raw
A1: ='Annual Raw'!A1 -> 105790 | B1: X | C1: 201206 | D1: 201209 | E1: 201212 | F1: 201303 | G1: 201306 | H1: 201309 | I1: 201312 | J1: 201403 | K1: 201406 | L1: 201409 | M1: 201412 | N1: 201503 | O1: 201506 | P1: 201509 | Q1: 201512 | R1: 201603 | S1: 201606 | T1: 201609 | U1: 201612 | V1: 201703 | W1: 201706 | X1: 201709 | Y1: 201712 | Z1: 201803 | AA1: 201806 | AB1: 201809 | AC1: 201812 | AD1: 201903 | AE1: 201906 | AF1: 201909 | AG1: 201912 | AH1: 202003 | AI1: 202006 | AJ1: 202009 | AK1: 202012 | AL1: 202103 | AM1: 202106 | AN1: 202109 | AO1: 202112 | AP1: 202203 | AQ1: 202206 | AR1: 202209 | AS1: 202212 | AT1: 202303 | AU1: 202306 | AV1: 202309 | AW1: 202312 | AX1: 202403 | AY1: 202406 | AZ1: 202409 | BA1: 202412 | BB1: 202503 | BC1: 202506 | BD1: 202509 | BE1: 202512 | BF1: 202603 | BG1: 202606 | BH1: 202609 | BI1: 202612 | BJ1: 202703 | BK1: 202706 | BL1: 202709 | BM1: 202712 | BN1: 202803 | BO1: 202806 | BP1: 202809 | BQ1: 202812 | BR1: 202903 | BS1: 202906 | BT1: 202909 | BU1: 202912
A3: Field Description | B3: Field Name
A4: Company Name | B4: CD_COMPNAME | C4: =_xll.EQNXTDZ(A1,B4,C1) -> Schaeffler India Ltd.
A5: Date End | B5: QTR_DATE_END | C5: =_xll.EQNXTDZ($A$1,$B5,C$1,$B$1) -> 201206 | D5: =_xll.EQNXTDZ($A$1,$B5,D$1,$B$1) -> 201209 | E5: =_xll.EQNXTDZ($A$1,$B5,E$1,$B$1) -> 201212 | F5: =_xll.EQNXTDZ($A$1,$B5,F$1,$B$1) -> 201303 | G5: =_xll.EQNXTDZ($A$1,$B5,G$1,$B$1) -> 201306 | H5: =_xll.EQNXTDZ($A$1,$B5,H$1,$B$1) -> 201309 | I5: =_xll.EQNXTDZ($A$1,$B5,I$1,$B$1) -> 201312 | J5: =_xll.EQNXTDZ($A$1,$B5,J$1,$B$1) -> 201403 | ... BU5: =_xll.EQNXTDZ($A$1,$B5,BU$1,$B$1) -> 0
A6: Gross Sales | B6: QTR_GROSS_SALE | C6: =_xll.EQNXTDZ($A$1,$B6,C$1,$B$1) -> 378.25 | D6: =_xll.EQNXTDZ($A$1,$B6,D$1,$B$1) -> 353.93 | E6: =_xll.EQNXTDZ($A$1,$B6,E$1,$B$1) -> 343.56 | F6: =_xll.EQNXTDZ($A$1,$B6,F$1,$B$1) -> 331.27 | G6: =_xll.EQNXTDZ($A$1,$B6,G$1,$B$1) -> 302.53 | H6: =_xll.EQNXTDZ($A$1,$B6,H$1,$B$1) -> 368.07 | I6: =_xll.EQNXTDZ($A$1,$B6,I$1,$B$1) -> 390.78 | J6: =_xll.EQNXTDZ($A$1,$B6,J$1,$B$1) -> 397.67 | ... BU6: =_xll.EQNXTDZ($A$1,$B6,BU$1,$B$1) -> 0
A7: Less: Excise Duty | B7: QTR_EXCISE_DUTY | C7: =_xll.EQNXTDZ($A$1,$B7,C$1,$B$1) -> 0 | D7: =_xll.EQNXTDZ($A$1,$B7,D$1,$B$1) -> 0 | E7: =_xll.EQNXTDZ($A$1,$B7,E$1,$B$1) -> 0 | F7: =_xll.EQNXTDZ($A$1,$B7,F$1,$B$1) -> 0 | G7: =_xll.EQNXTDZ($A$1,$B7,G$1,$B$1) -> 0 | H7: =_xll.EQNXTDZ($A$1,$B7,H$1,$B$1) -> 0 | I7: =_xll.EQNXTDZ($A$1,$B7,I$1,$B$1) -> 0 | J7: =_xll.EQNXTDZ($A$1,$B7,J$1,$B$1) -> 0 | ... BU7: =_xll.EQNXTDZ($A$1,$B7,BU$1,$B$1) -> 0
A8: Other operating income | B8: QTR_JOB_WORKS | C8: =_xll.EQNXTDZ($A$1,$B8,C$1,$B$1) -> 1.87 | D8: =_xll.EQNXTDZ($A$1,$B8,D$1,$B$1) -> 2.24 | E8: =_xll.EQNXTDZ($A$1,$B8,E$1,$B$1) -> 3.56 | F8: =_xll.EQNXTDZ($A$1,$B8,F$1,$B$1) -> 1.34 | G8: =_xll.EQNXTDZ($A$1,$B8,G$1,$B$1) -> 2.06 | H8: =_xll.EQNXTDZ($A$1,$B8,H$1,$B$1) -> 3.3 | I8: =_xll.EQNXTDZ($A$1,$B8,I$1,$B$1) -> 3.07 | J8: =_xll.EQNXTDZ($A$1,$B8,J$1,$B$1) -> 3.03 | ... BU8: =_xll.EQNXTDZ($A$1,$B8,BU$1,$B$1) -> 0
A9: Net Sales & Other Operating Income | B9: QTR_NET_SALES | C9: =_xll.EQNXTDZ($A$1,$B9,C$1,$B$1) -> 380.12 | D9: =_xll.EQNXTDZ($A$1,$B9,D$1,$B$1) -> 356.17 | E9: =_xll.EQNXTDZ($A$1,$B9,E$1,$B$1) -> 347.12 | F9: =_xll.EQNXTDZ($A$1,$B9,F$1,$B$1) -> 332.61 | G9: =_xll.EQNXTDZ($A$1,$B9,G$1,$B$1) -> 304.59 | H9: =_xll.EQNXTDZ($A$1,$B9,H$1,$B$1) -> 371.37 | I9: =_xll.EQNXTDZ($A$1,$B9,I$1,$B$1) -> 393.85 | J9: =_xll.EQNXTDZ($A$1,$B9,J$1,$B$1) -> 400.7 | ... BU9: =_xll.EQNXTDZ($A$1,$B9,BU$1,$B$1) -> 0
A10: (Increase) / Decrease In Stocks | B10: QTR_INC_DEC_INVENTORY | C10: =_xll.EQNXTDZ($A$1,$B10,C$1,$B$1) -> 10.69 | D10: =_xll.EQNXTDZ($A$1,$B10,D$1,$B$1) -> -17.41 | E10: =_xll.EQNXTDZ($A$1,$B10,E$1,$B$1) -> 22.81 | F10: =_xll.EQNXTDZ($A$1,$B10,F$1,$B$1) -> 3.36 | G10: =_xll.EQNXTDZ($A$1,$B10,G$1,$B$1) -> -28.38 | H10: =_xll.EQNXTDZ($A$1,$B10,H$1,$B$1) -> -9.71 | I10: =_xll.EQNXTDZ($A$1,$B10,I$1,$B$1) -> 2.53 | J10: =_xll.EQNXTDZ($A$1,$B10,J$1,$B$1) -> 5.57 | ... BU10: =_xll.EQNXTDZ($A$1,$B10,BU$1,$B$1) -> 0
A11: Cost of Services & Raw Materials | B11: QTR_RAW_MATERIAL_COST | C11: =_xll.EQNXTDZ($A$1,$B11,C$1,$B$1) -> 130.26 | D11: =_xll.EQNXTDZ($A$1,$B11,D$1,$B$1) -> 126.94 | E11: =_xll.EQNXTDZ($A$1,$B11,E$1,$B$1) -> 100.03 | F11: =_xll.EQNXTDZ($A$1,$B11,F$1,$B$1) -> 119.5 | G11: =_xll.EQNXTDZ($A$1,$B11,G$1,$B$1) -> 118.01 | H11: =_xll.EQNXTDZ($A$1,$B11,H$1,$B$1) -> 125.63 | I11: =_xll.EQNXTDZ($A$1,$B11,I$1,$B$1) -> 140.54 | J11: =_xll.EQNXTDZ($A$1,$B11,J$1,$B$1) -> 144.93 | ... BU11: =_xll.EQNXTDZ($A$1,$B11,BU$1,$B$1) -> 0
A12: Purchase of Finished Goods | B12: QTR_PURCHASE_FIN_GOOD | C12: =_xll.EQNXTDZ($A$1,$B12,C$1,$B$1) -> 97.75 | D12: =_xll.EQNXTDZ($A$1,$B12,D$1,$B$1) -> 110.68 | E12: =_xll.EQNXTDZ($A$1,$B12,E$1,$B$1) -> 103.85 | F12: =_xll.EQNXTDZ($A$1,$B12,F$1,$B$1) -> 90.3 | G12: =_xll.EQNXTDZ($A$1,$B12,G$1,$B$1) -> 90.04 | H12: =_xll.EQNXTDZ($A$1,$B12,H$1,$B$1) -> 124.51 | I12: =_xll.EQNXTDZ($A$1,$B12,I$1,$B$1) -> 120.76 | J12: =_xll.EQNXTDZ($A$1,$B12,J$1,$B$1) -> 99.17 | ... BU12: =_xll.EQNXTDZ($A$1,$B12,BU$1,$B$1) -> 0
A13: Excise Duty | B13: QTR_EXCISE | C13: =_xll.EQNXTDZ($A$1,$B13,C$1,$B$1) -> 0 | D13: =_xll.EQNXTDZ($A$1,$B13,D$1,$B$1) -> 0 | E13: =_xll.EQNXTDZ($A$1,$B13,E$1,$B$1) -> 0 | F13: =_xll.EQNXTDZ($A$1,$B13,F$1,$B$1) -> 0 | G13: =_xll.EQNXTDZ($A$1,$B13,G$1,$B$1) -> 0 | H13: =_xll.EQNXTDZ($A$1,$B13,H$1,$B$1) -> 0 | I13: =_xll.EQNXTDZ($A$1,$B13,I$1,$B$1) -> 0 | J13: =_xll.EQNXTDZ($A$1,$B13,J$1,$B$1) -> 0 | ... BU13: =_xll.EQNXTDZ($A$1,$B13,BU$1,$B$1) -> 0
A14: Operating & Manufacturing Expenses | B14: QTR_MFG_EXPS | C14: =_xll.EQNXTDZ($A$1,$B14,C$1,$B$1) -> 49.64 | D14: =_xll.EQNXTDZ($A$1,$B14,D$1,$B$1) -> 56.7 | E14: =_xll.EQNXTDZ($A$1,$B14,E$1,$B$1) -> 48.75 | F14: =_xll.EQNXTDZ($A$1,$B14,F$1,$B$1) -> 48.06 | G14: =_xll.EQNXTDZ($A$1,$B14,G$1,$B$1) -> 51.53 | H14: =_xll.EQNXTDZ($A$1,$B14,H$1,$B$1) -> 49.01 | I14: =_xll.EQNXTDZ($A$1,$B14,I$1,$B$1) -> 54.01 | J14: =_xll.EQNXTDZ($A$1,$B14,J$1,$B$1) -> 57.84 | ... BU14: =_xll.EQNXTDZ($A$1,$B14,BU$1,$B$1) -> 0
A15: Electricity Power & Fuel Cost | B15: QTR_ELECTRICITY_POWER_FUEL | C15: =_xll.EQNXTDZ($A$1,$B15,C$1,$B$1) -> 0 | D15: =_xll.EQNXTDZ($A$1,$B15,D$1,$B$1) -> 0 | E15: =_xll.EQNXTDZ($A$1,$B15,E$1,$B$1) -> 0 | F15: =_xll.EQNXTDZ($A$1,$B15,F$1,$B$1) -> 0 | G15: =_xll.EQNXTDZ($A$1,$B15,G$1,$B$1) -> 0 | H15: =_xll.EQNXTDZ($A$1,$B15,H$1,$B$1) -> 0 | I15: =_xll.EQNXTDZ($A$1,$B15,I$1,$B$1) -> 0 | J15: =_xll.EQNXTDZ($A$1,$B15,J$1,$B$1) -> 0 | ... BU15: =_xll.EQNXTDZ($A$1,$B15,BU$1,$B$1) -> 0
A16: Employee Cost | B16: QTR_EXPLOYEE_COST | C16: =_xll.EQNXTDZ($A$1,$B16,C$1,$B$1) -> 27.87 | D16: =_xll.EQNXTDZ($A$1,$B16,D$1,$B$1) -> 27.67 | E16: =_xll.EQNXTDZ($A$1,$B16,E$1,$B$1) -> 30.36 | F16: =_xll.EQNXTDZ($A$1,$B16,F$1,$B$1) -> 29.94 | G16: =_xll.EQNXTDZ($A$1,$B16,G$1,$B$1) -> 31.76 | H16: =_xll.EQNXTDZ($A$1,$B16,H$1,$B$1) -> 31.27 | I16: =_xll.EQNXTDZ($A$1,$B16,I$1,$B$1) -> 26.16 | J16: =_xll.EQNXTDZ($A$1,$B16,J$1,$B$1) -> 37.48 | ... BU16: =_xll.EQNXTDZ($A$1,$B16,BU$1,$B$1) -> 0
... A42: Consolidated PAT(after extra items) | B42: QTR_CONS_PAT_EXITM | C42: =_xll.EQNXTDZ($A$1,$B42,C$1,$B$1) -> 46.24 | D42: =_xll.EQNXTDZ($A$1,$B42,D$1,$B$1) -> 36.94 | E42: =_xll.EQNXTDZ($A$1,$B42,E$1,$B$1) -> 29.69 | F42: =_xll.EQNXTDZ($A$1,$B42,F$1,$B$1) -> 25.45 | G42: =_xll.EQNXTDZ($A$1,$B42,G$1,$B$1) -> 25.58 | H42: =_xll.EQNXTDZ($A$1,$B42,H$1,$B$1) -> 35.89 | I42: =_xll.EQNXTDZ($A$1,$B42,I$1,$B$1) -> 34.91 | J42: =_xll.EQNXTDZ($A$1,$B42,J$1,$B$1) -> 34.68 | ... BU42: =_xll.EQNXTDZ($A$1,$B42,BU$1,$B$1) -> 0
A44: Field Description | B44: Field Name
A45: Equity Capital | B45: QTR_EQUITY_CAP | C45: =_xll.EQNXTDZ($A$1,$B45,C$1,$B$1) -> 16.62 | D45: =_xll.EQNXTDZ($A$1,$B45,D$1,$B$1) -> 16.62 | E45: =_xll.EQNXTDZ($A$1,$B45,E$1,$B$1) -> 16.62 | F45: =_xll.EQNXTDZ($A$1,$B45,F$1,$B$1) -> 16.62 | G45: =_xll.EQNXTDZ($A$1,$B45,G$1,$B$1) -> 16.62 | H45: =_xll.EQNXTDZ($A$1,$B45,H$1,$B$1) -> 16.62 | I45: =_xll.EQNXTDZ($A$1,$B45,I$1,$B$1) -> 16.62 | J45: =_xll.EQNXTDZ($A$1,$B45,J$1,$B$1) -> 16.62 | ... BU45: =_xll.EQNXTDZ($A$1,$B45,BU$1,$B$1) -> 0
A46: Face Value | B46: QTR_FV | C46: =_xll.EQNXTDZ($A$1,$B46,C$1,$B$1) -> 10 | D46: =_xll.EQNXTDZ($A$1,$B46,D$1,$B$1) -> 10 | E46: =_xll.EQNXTDZ($A$1,$B46,E$1,$B$1) -> 10 | F46: =_xll.EQNXTDZ($A$1,$B46,F$1,$B$1) -> 10 | G46: =_xll.EQNXTDZ($A$1,$B46,G$1,$B$1) -> 10 | H46: =_xll.EQNXTDZ($A$1,$B46,H$1,$B$1) -> 10 | I46: =_xll.EQNXTDZ($A$1,$B46,I$1,$B$1) -> 10 | J46: =_xll.EQNXTDZ($A$1,$B46,J$1,$B$1) -> 10 | ... BU46: =_xll.EQNXTDZ($A$1,$B46,BU$1,$B$1) -> 0
A47: Month End | B47: BMONTH_MONTHEND | C47: =_xll.EQNXTDZ($A$1,$B47,C$5) -> 201206 | D47: =_xll.EQNXTDZ($A$1,$B47,D$5) -> 201209 | E47: =_xll.EQNXTDZ($A$1,$B47,E$5) -> 201212 | F47: =_xll.EQNXTDZ($A$1,$B47,F$5) -> 201303 | G47: =_xll.EQNXTDZ($A$1,$B47,G$5) -> 201306 | H47: =_xll.EQNXTDZ($A$1,$B47,H$5) -> 201309 | I47: =_xll.EQNXTDZ($A$1,$B47,I$5) -> 201312 | J47: =_xll.EQNXTDZ($A$1,$B47,J$5) -> 201403 | ... BU47: =_xll.EQNXTDZ($A$1,$B47,BU$5) -> 0
A48: Close | B48: BMONTH_CLOSE | C48: =_xll.EQNXTDZ($A$1,$B48,C$5) -> 287.61 | D48: =_xll.EQNXTDZ($A$1,$B48,D$5) -> 352.06 | E48: =_xll.EQNXTDZ($A$1,$B48,E$5) -> 339.94 | F48: =_xll.EQNXTDZ($A$1,$B48,F$5) -> 293.93 | G48: =_xll.EQNXTDZ($A$1,$B48,G$5) -> 284 | H48: =_xll.EQNXTDZ($A$1,$B48,H$5) -> 249.7 | I48: =_xll.EQNXTDZ($A$1,$B48,I$5) -> 322.79 | J48: =_xll.EQNXTDZ($A$1,$B48,J$5) -> 375.5 | ... BU48: =_xll.EQNXTDZ($A$1,$B48,BU$5) -> 0
A49: Total of Promoter and Promoter Group | B49: SHP_TPFTOTALPROMOTER | C49: =_xll.EQNXTDZ($A$1,$B49,C$5) -> 51.33 | D49: =_xll.EQNXTDZ($A$1,$B49,D$5) -> 51.33 | E49: =_xll.EQNXTDZ($A$1,$B49,E$5) -> 51.33 | F49: =_xll.EQNXTDZ($A$1,$B49,F$5) -> 51.33 | G49: =_xll.EQNXTDZ($A$1,$B49,G$5) -> 51.33 | H49: =_xll.EQNXTDZ($A$1,$B49,H$5) -> 51.33 | I49: =_xll.EQNXTDZ($A$1,$B49,I$5) -> 51.33 | J49: =_xll.EQNXTDZ($A$1,$B49,J$5) -> 51.33 | ... BU49: =_xll.EQNXTDZ($A$1,$B49,BU$5) -> 0
A50: Total of Promoter and Promoter Group Pledged | B50: SHP_PSHFTOTALPROMOTER | C50: =_xll.EQNXTDZ($A$1,$B50,C$5) -> 0 | D50: =_xll.EQNXTDZ($A$1,$B50,D$5) -> 0 | E50: =_xll.EQNXTDZ($A$1,$B50,E$5) -> 0 | F50: =_xll.EQNXTDZ($A$1,$B50,F$5) -> 0 | G50: =_xll.EQNXTDZ($A$1,$B50,G$5) -> 0 | H50: =_xll.EQNXTDZ($A$1,$B50,H$5) -> 0 | I50: =_xll.EQNXTDZ($A$1,$B50,I$5) -> 0 | J50: =_xll.EQNXTDZ($A$1,$B50,J$5) -> 0 | ... BU50: =_xll.EQNXTDZ($A$1,$B50,BU$5) -> 0
A54: Field Description | B54: Field Name | C54: =_xll.EQNXTDZ($A$1,$B54,C$5) -> 0 | D54: =_xll.EQNXTDZ($A$1,$B54,D$5) -> 0 | E54: =_xll.EQNXTDZ($A$1,$B54,E$5) -> 0 | F54: =_xll.EQNXTDZ($A$1,$B54,F$5) -> 0 | G54: =_xll.EQNXTDZ($A$1,$B54,G$5) -> 0 | H54: =_xll.EQNXTDZ($A$1,$B54,H$5) -> 0 | I54: =_xll.EQNXTDZ($A$1,$B54,I$5) -> 0 | J54: =_xll.EQNXTDZ($A$1,$B54,J$5) -> 0 | ... BU54: =_xll.EQNXTDZ($A$1,$B54,BU$5) -> 0
A55: Year End | B55: QTRB_DATE_END | C55: =_xll.EQNXTDZ($A$1,$B55,C$5,$B$1) -> 201206 | D55: =_xll.EQNXTDZ($A$1,$B55,D$5,$B$1) -> 0 | E55: =_xll.EQNXTDZ($A$1,$B55,E$5,$B$1) -> 201212 | F55: =_xll.EQNXTDZ($A$1,$B55,F$5,$B$1) -> 0 | G55: =_xll.EQNXTDZ($A$1,$B55,G$5,$B$1) -> 201306 | H55: =_xll.EQNXTDZ($A$1,$B55,H$5,$B$1) -> 0 | I55: =_xll.EQNXTDZ($A$1,$B55,I$5,$B$1) -> 201312 | J55: =_xll.EQNXTDZ($A$1,$B55,J$5,$B$1) -> 0 | ... BU55: =_xll.EQNXTDZ($A$1,$B55,BU$5,$B$1) -> 0
A56: Share Capital | B56: QTRB_SHARE_CAPITAL | C56: =_xll.EQNXTDZ($A$1,$B56,C$5,$B$1) -> 16.62 | D56: =_xll.EQNXTDZ($A$1,$B56,D$5,$B$1) -> 0 | E56: =_xll.EQNXTDZ($A$1,$B56,E$5,$B$1) -> 16.62 | F56: =_xll.EQNXTDZ($A$1,$B56,F$5,$B$1) -> 0 | G56: =_xll.EQNXTDZ($A$1,$B56,G$5,$B$1) -> 16.62 | H56: =_xll.EQNXTDZ($A$1,$B56,H$5,$B$1) -> 0 | I56: =_xll.EQNXTDZ($A$1,$B56,I$5,$B$1) -> 16.62 | J56: =_xll.EQNXTDZ($A$1,$B56,J$5,$B$1) -> 0 | ... BU56: =_xll.EQNXTDZ($A$1,$B56,BU$5,$B$1) -> 0
A57: Share Warrants & outstandings | B57: QTRB_SHAREWARNDOUT | C57: =_xll.EQNXTDZ($A$1,$B57,C$5,$B$1) -> 0 | D57: =_xll.EQNXTDZ($A$1,$B57,D$5,$B$1) -> 0 | E57: =_xll.EQNXTDZ($A$1,$B57,E$5,$B$1) -> 0 | F57: =_xll.EQNXTDZ($A$1,$B57,F$5,$B$1) -> 0 | G57: =_xll.EQNXTDZ($A$1,$B57,G$5,$B$1) -> 0 | H57: =_xll.EQNXTDZ($A$1,$B57,H$5,$B$1) -> 0 | I57: =_xll.EQNXTDZ($A$1,$B57,I$5,$B$1) -> 0 | J57: =_xll.EQNXTDZ($A$1,$B57,J$5,$B$1) -> 0 | ... BU57: =_xll.EQNXTDZ($A$1,$B57,BU$5,$B$1) -> 0
A58: Reserves & Surplus | B58: QTRB_RESERVE | C58: =_xll.EQNXTDZ($A$1,$B58,C$5,$B$1) -> 786.63 | D58: =_xll.EQNXTDZ($A$1,$B58,D$5,$B$1) -> 0 | E58: =_xll.EQNXTDZ($A$1,$B58,E$5,$B$1) -> 862.88 | F58: =_xll.EQNXTDZ($A$1,$B58,F$5,$B$1) -> 0 | G58: =_xll.EQNXTDZ($A$1,$B58,G$5,$B$1) -> 913.82 | H58: =_xll.EQNXTDZ($A$1,$B58,H$5,$B$1) -> 0 | I58: =_xll.EQNXTDZ($A$1,$B58,I$5,$B$1) -> 972.93 | J58: =_xll.EQNXTDZ($A$1,$B58,J$5,$B$1) -> 0 | ... BU58: =_xll.EQNXTDZ($A$1,$B58,BU$5,$B$1) -> 0
A59: Shareholder's Funds | B59: QTRB_SHAREHODERS_FUNDS | C59: =_xll.EQNXTDZ($A$1,$B59,C$5,$B$1) -> 803.25 | D59: =_xll.EQNXTDZ($A$1,$B59,D$5,$B$1) -> 0 | E59: =_xll.EQNXTDZ($A$1,$B59,E$5,$B$1) -> 879.5 | F59: =_xll.EQNXTDZ($A$1,$B59,F$5,$B$1) -> 0 | G59: =_xll.EQNXTDZ($A$1,$B59,G$5,$B$1) -> 930.44 | H59: =_xll.EQNXTDZ($A$1,$B59,H$5,$B$1) -> 0 | I59: =_xll.EQNXTDZ($A$1,$B59,I$5,$B$1) -> 989.55 | J59: =_xll.EQNXTDZ($A$1,$B59,J$5,$B$1) -> 0 | ... BU59: =_xll.EQNXTDZ($A$1,$B59,BU$5,$B$1) -> 0
A60: Minority Interest | B60: QTRB_MINORITY_INTEREST_BS | C60: =_xll.EQNXTDZ($A$1,$B60,C$5,$B$1) -> 0 | D60: =_xll.EQNXTDZ($A$1,$B60,D$5,$B$1) -> 0 | E60: =_xll.EQNXTDZ($A$1,$B60,E$5,$B$1) -> 0 | F60: =_xll.EQNXTDZ($A$1,$B60,F$5,$B$1) -> 0 | G60: =_xll.EQNXTDZ($A$1,$B60,G$5,$B$1) -> 0 | H60: =_xll.EQNXTDZ($A$1,$B60,H$5,$B$1) -> 0 | I60: =_xll.EQNXTDZ($A$1,$B60,I$5,$B$1) -> 0 | J60: =_xll.EQNXTDZ($A$1,$B60,J$5,$B$1) -> 0 | ... BU60: =_xll.EQNXTDZ($A$1,$B60,BU$5,$B$1) -> 0
A61: Long Term Borrowings | B61: QTRB_TOTAL_DEBTS | C61: =_xll.EQNXTDZ($A$1,$B61,C$5,$B$1) -> 0 | D61: =_xll.EQNXTDZ($A$1,$B61,D$5,$B$1) -> 0 | E61: =_xll.EQNXTDZ($A$1,$B61,E$5,$B$1) -> 0 | F61: =_xll.EQNXTDZ($A$1,$B61,F$5,$B$1) -> 0 | G61: =_xll.EQNXTDZ($A$1,$B61,G$5,$B$1) -> 0 | H61: =_xll.EQNXTDZ($A$1,$B61,H$5,$B$1) -> 0 | I61: =_xll.EQNXTDZ($A$1,$B61,I$5,$B$1) -> 0 | J61: =_xll.EQNXTDZ($A$1,$B61,J$5,$B$1) -> 0 | ... BU61: =_xll.EQNXTDZ($A$1,$B61,BU$5,$B$1) -> 0
A62: Secured Loans | B62: QTRB_SECURED_LOANS | C62: =_xll.EQNXTDZ($A$1,$B62,C$5,$B$1) -> 0 | D62: =_xll.EQNXTDZ($A$1,$B62,D$5,$B$1) -> 0 | E62: =_xll.EQNXTDZ($A$1,$B62,E$5,$B$1) -> 0 | F62: =_xll.EQNXTDZ($A$1,$B62,F$5,$B$1) -> 0 | G62: =_xll.EQNXTDZ($A$1,$B62,G$5,$B$1) -> 0 | H62: =_xll.EQNXTDZ($A$1,$B62,H$5,$B$1) -> 0 | I62: =_xll.EQNXTDZ($A$1,$B62,I$5,$B$1) -> 0 | J62: =_xll.EQNXTDZ($A$1,$B62,J$5,$B$1) -> 0 | ... BU62: =_xll.EQNXTDZ($A$1,$B62,BU$5,$B$1) -> 0
A63: Unsecured Loans | B63: QTRB_UNSECURED_LOANS_NF | C63: =_xll.EQNXTDZ($A$1,$B63,C$5,$B$1) -> 0 | D63: =_xll.EQNXTDZ($A$1,$B63,D$5,$B$1) -> 0 | E63: =_xll.EQNXTDZ($A$1,$B63,E$5,$B$1) -> 0 | F63: =_xll.EQNXTDZ($A$1,$B63,F$5,$B$1) -> 0 | G63: =_xll.EQNXTDZ($A$1,$B63,G$5,$B$1) -> 0 | H63: =_xll.EQNXTDZ($A$1,$B63,H$5,$B$1) -> 0 | I63: =_xll.EQNXTDZ($A$1,$B63,I$5,$B$1) -> 0 | J63: =_xll.EQNXTDZ($A$1,$B63,J$5,$B$1) -> 0 | ... BU63: =_xll.EQNXTDZ($A$1,$B63,BU$5,$B$1) -> 0
A64: Other Long Term Liabilities | B64: QTRB_OTHER_LT_LIABILITIES | C64: =_xll.EQNXTDZ($A$1,$B64,C$5,$B$1) -> 1.51 | D64: =_xll.EQNXTDZ($A$1,$B64,D$5,$B$1) -> 0 | E64: =_xll.EQNXTDZ($A$1,$B64,E$5,$B$1) -> 1.52 | F64: =_xll.EQNXTDZ($A$1,$B64,F$5,$B$1) -> 0 | G64: =_xll.EQNXTDZ($A$1,$B64,G$5,$B$1) -> 1.6 | H64: =_xll.EQNXTDZ($A$1,$B64,H$5,$B$1) -> 0 | I64: =_xll.EQNXTDZ($A$1,$B64,I$5,$B$1) -> 1.61 | J64: =_xll.EQNXTDZ($A$1,$B64,J$5,$B$1) -> 0 | ... BU64: =_xll.EQNXTDZ($A$1,$B64,BU$5,$B$1) -> 0
A65: Long Term Trade Payables | B65: QTRB_LT_TRADE_PAYABLE | C65: =_xll.EQNXTDZ($A$1,$B65,C$5,$B$1) -> 196.46 | D65: =_xll.EQNXTDZ($A$1,$B65,D$5,$B$1) -> 0 | E65: =_xll.EQNXTDZ($A$1,$B65,E$5,$B$1) -> 0 | F65: =_xll.EQNXTDZ($A$1,$B65,F$5,$B$1) -> 0 | G65: =_xll.EQNXTDZ($A$1,$B65,G$5,$B$1) -> 0 | H65: =_xll.EQNXTDZ($A$1,$B65,H$5,$B$1) -> 0 | I65: =_xll.EQNXTDZ($A$1,$B65,I$5,$B$1) -> 0 | J65: =_xll.EQNXTDZ($A$1,$B65,J$5,$B$1) -> 0 | ... BU65: =_xll.EQNXTDZ($A$1,$B65,BU$5,$B$1) -> 0
A66: Lont Term Provisions | B66: QTRB_LT_PROVISIONS | C66: =_xll.EQNXTDZ($A$1,$B66,C$5,$B$1) -> 13.18 | D66: =_xll.EQNXTDZ($A$1,$B66,D$5,$B$1) -> 0 | E66: =_xll.EQNXTDZ($A$1,$B66,E$5,$B$1) -> 22.94 | F66: =_xll.EQNXTDZ($A$1,$B66,F$5,$B$1) -> 0 | G66: =_xll.EQNXTDZ($A$1,$B66,G$5,$B$1) -> 22.04 | H66: =_xll.EQNXTDZ($A$1,$B66,H$5,$B$1) -> 0 | I66: =_xll.EQNXTDZ($A$1,$B66,I$5,$B$1) -> 20.5 | J66: =_xll.EQNXTDZ($A$1,$B66,J$5,$B$1) -> 0 | ... BU66: =_xll.EQNXTDZ($A$1,$B66,BU$5,$B$1) -> 0
... A97: Total Assets | B97: QTRB_TOTAL_APPLICATIONS | C97: =_xll.EQNXTDZ($A$1,$B97,C$5,$B$1) -> 1014.4 | D97: =_xll.EQNXTDZ($A$1,$B97,D$5,$B$1) -> 0 | E97: =_xll.EQNXTDZ($A$1,$B97,E$5,$B$1) -> 903.96 | F97: =_xll.EQNXTDZ($A$1,$B97,F$5,$B$1) -> 0 | G97: =_xll.EQNXTDZ($A$1,$B97,G$5,$B$1) -> 954.08 | H97: =_xll.EQNXTDZ($A$1,$B97,H$5,$B$1) -> 0 | I97: =_xll.EQNXTDZ($A$1,$B97,I$5,$B$1) -> 1011.66 | J97: =_xll.EQNXTDZ($A$1,$B97,J$5,$B$1) -> 0 | ... BU97: =_xll.EQNXTDZ($A$1,$B97,BU$5,$B$1) -> 0

Sheet Annual Raw
A1: 105790 | B1: X | C1: 200003 | D1: 200103 | E1: 200212 | F1: 200312 | G1: 200412 | H1: 200512 | I1: 200612 | J1: 200712 | K1: 200812 | L1: 200912 | M1: 201012 | N1: 201112 | O1: 201212 | P1: 201312 | Q1: 201412 | R1: 201512 | S1: 201612 | T1: 201712 | U1: 201812 | V1: 201912 | W1: 202012 | X1: 202112 | Y1: 202212 | Z1: 202312 | AA1: 202412 | AB1: 202512 | AC1: 202612 | AD1: 202712 | AE1: 202812 | AF1: 202912 | AG1: 203012
A3: Field Description | B3: Field Name
A4: Company Name | B4: CD_COMPNAME | C4: =_xll.EQNXTDZ(A1,B4,"L") -> Schaeffler India Ltd.
A5: Year End | B5: PL_YEAR_END | C5: =_xll.EQNXTDZ($A$1,$B5,C$1,$B$1) -> 0 | D5: =_xll.EQNXTDZ($A$1,$B5,D$1,$B$1) -> 0 | E5: =_xll.EQNXTDZ($A$1,$B5,E$1,$B$1) -> 200212 | F5: =_xll.EQNXTDZ($A$1,$B5,F$1,$B$1) -> 200312 | G5: =_xll.EQNXTDZ($A$1,$B5,G$1,$B$1) -> 200412 | H5: =_xll.EQNXTDZ($A$1,$B5,H$1,$B$1) -> 200512 | I5: =_xll.EQNXTDZ($A$1,$B5,I$1,$B$1) -> 200612 | J5: =_xll.EQNXTDZ($A$1,$B5,J$1,$B$1) -> 200712 | ... AG5: =_xll.EQNXTDZ($A$1,$B5,AG$1,$B$1) -> 0
A6: Sales Turnover | B6: PL_TOTAL_GROSS_SALES | C6: =_xll.EQNXTDZ($A$1,$B6,C$1,$B$1) -> 0 | D6: =_xll.EQNXTDZ($A$1,$B6,D$1,$B$1) -> 0 | E6: =_xll.EQNXTDZ($A$1,$B6,E$1,$B$1) -> 278.59 | F6: =_xll.EQNXTDZ($A$1,$B6,F$1,$B$1) -> 305.78 | G6: =_xll.EQNXTDZ($A$1,$B6,G$1,$B$1) -> 368.75 | H6: =_xll.EQNXTDZ($A$1,$B6,H$1,$B$1) -> 462.65 | I6: =_xll.EQNXTDZ($A$1,$B6,I$1,$B$1) -> 612.25 | J6: =_xll.EQNXTDZ($A$1,$B6,J$1,$B$1) -> 715.97 | ... AG6: =_xll.EQNXTDZ($A$1,$B6,AG$1,$B$1) -> 0
A7: Less: Inter divisional transfers | B7: PL_INTER_DIV_TRF | C7: =_xll.EQNXTDZ($A$1,$B7,C$1,$B$1) -> 0 | D7: =_xll.EQNXTDZ($A$1,$B7,D$1,$B$1) -> 0 | E7: =_xll.EQNXTDZ($A$1,$B7,E$1,$B$1) -> 0 | F7: =_xll.EQNXTDZ($A$1,$B7,F$1,$B$1) -> 0 | G7: =_xll.EQNXTDZ($A$1,$B7,G$1,$B$1) -> 0 | H7: =_xll.EQNXTDZ($A$1,$B7,H$1,$B$1) -> 0 | I7: =_xll.EQNXTDZ($A$1,$B7,I$1,$B$1) -> 0 | J7: =_xll.EQNXTDZ($A$1,$B7,J$1,$B$1) -> 0 | ... AG7: =_xll.EQNXTDZ($A$1,$B7,AG$1,$B$1) -> 0
A8: Less: Sales Returns | B8: PL_SALES_RETURN | C8: =_xll.EQNXTDZ($A$1,$B8,C$1,$B$1) -> 0 | D8: =_xll.EQNXTDZ($A$1,$B8,D$1,$B$1) -> 0 | E8: =_xll.EQNXTDZ($A$1,$B8,E$1,$B$1) -> 0 | F8: =_xll.EQNXTDZ($A$1,$B8,F$1,$B$1) -> 0 | G8: =_xll.EQNXTDZ($A$1,$B8,G$1,$B$1) -> 0 | H8: =_xll.EQNXTDZ($A$1,$B8,H$1,$B$1) -> 0 | I8: =_xll.EQNXTDZ($A$1,$B8,I$1,$B$1) -> 0 | J8: =_xll.EQNXTDZ($A$1,$B8,J$1,$B$1) -> 0 | ... AG8: =_xll.EQNXTDZ($A$1,$B8,AG$1,$B$1) -> 0
A9: Less: Excise | B9: PL_EXCISE | C9: =_xll.EQNXTDZ($A$1,$B9,C$1,$B$1) -> 0 | D9: =_xll.EQNXTDZ($A$1,$B9,D$1,$B$1) -> 0 | E9: =_xll.EQNXTDZ($A$1,$B9,E$1,$B$1) -> 34.28 | F9: =_xll.EQNXTDZ($A$1,$B9,F$1,$B$1) -> 38.87 | G9: =_xll.EQNXTDZ($A$1,$B9,G$1,$B$1) -> 45.63 | H9: =_xll.EQNXTDZ($A$1,$B9,H$1,$B$1) -> 54.33 | I9: =_xll.EQNXTDZ($A$1,$B9,I$1,$B$1) -> 70.21 | J9: =_xll.EQNXTDZ($A$1,$B9,J$1,$B$1) -> 74.67 | ... AG9: =_xll.EQNXTDZ($A$1,$B9,AG$1,$B$1) -> 0
A10: Net Sales | B10: PL_NET_SALES | C10: =_xll.EQNXTDZ($A$1,$B10,C$1,$B$1) -> 0 | D10: =_xll.EQNXTDZ($A$1,$B10,D$1,$B$1) -> 0 | E10: =_xll.EQNXTDZ($A$1,$B10,E$1,$B$1) -> 244.31 | F10: =_xll.EQNXTDZ($A$1,$B10,F$1,$B$1) -> 266.91 | G10: =_xll.EQNXTDZ($A$1,$B10,G$1,$B$1) -> 323.12 | H10: =_xll.EQNXTDZ($A$1,$B10,H$1,$B$1) -> 408.32 | I10: =_xll.EQNXTDZ($A$1,$B10,I$1,$B$1) -> 542.04 | J10: =_xll.EQNXTDZ($A$1,$B10,J$1,$B$1) -> 641.3 | ... AG10: =_xll.EQNXTDZ($A$1,$B10,AG$1,$B$1) -> 0
A11: Increase/Decrease in Stock | B11: PL_INC_DEC_INVENTORY | C11: =_xll.EQNXTDZ($A$1,$B11,C$1,$B$1) -> 0 | D11: =_xll.EQNXTDZ($A$1,$B11,D$1,$B$1) -> 0 | E11: =_xll.EQNXTDZ($A$1,$B11,E$1,$B$1) -> -3.371 | F11: =_xll.EQNXTDZ($A$1,$B11,F$1,$B$1) -> 4.7 | G11: =_xll.EQNXTDZ($A$1,$B11,G$1,$B$1) -> 0.58 | H11: =_xll.EQNXTDZ($A$1,$B11,H$1,$B$1) -> -4.68 | I11: =_xll.EQNXTDZ($A$1,$B11,I$1,$B$1) -> -17.98 | J11: =_xll.EQNXTDZ($A$1,$B11,J$1,$B$1) -> -6.41 | ... AG11: =_xll.EQNXTDZ($A$1,$B11,AG$1,$B$1) -> 0
A12: Raw Material Consumed | B12: PL_RAW_MATRS_CONSUMED | C12: =_xll.EQNXTDZ($A$1,$B12,C$1,$B$1) -> 0 | D12: =_xll.EQNXTDZ($A$1,$B12,D$1,$B$1) -> 0 | E12: =_xll.EQNXTDZ($A$1,$B12,E$1,$B$1) -> 96.38 | F12: =_xll.EQNXTDZ($A$1,$B12,F$1,$B$1) -> 109.2 | G12: =_xll.EQNXTDZ($A$1,$B12,G$1,$B$1) -> 146.91 | H12: =_xll.EQNXTDZ($A$1,$B12,H$1,$B$1) -> 195.24 | I12: =_xll.EQNXTDZ($A$1,$B12,I$1,$B$1) -> 278.23 | J12: =_xll.EQNXTDZ($A$1,$B12,J$1,$B$1) -> 321.7 | ... AG12: =_xll.EQNXTDZ($A$1,$B12,AG$1,$B$1) -> 0
A13: Power & Fuel Cost | B13: PL_POWER_FUEL | C13: =_xll.EQNXTDZ($A$1,$B13,C$1,$B$1) -> 0 | D13: =_xll.EQNXTDZ($A$1,$B13,D$1,$B$1) -> 0 | E13: =_xll.EQNXTDZ($A$1,$B13,E$1,$B$1) -> 9.8 | F13: =_xll.EQNXTDZ($A$1,$B13,F$1,$B$1) -> 9.72 | G13: =_xll.EQNXTDZ($A$1,$B13,G$1,$B$1) -> 10.4 | H13: =_xll.EQNXTDZ($A$1,$B13,H$1,$B$1) -> 10.95 | I13: =_xll.EQNXTDZ($A$1,$B13,I$1,$B$1) -> 13.32 | J13: =_xll.EQNXTDZ($A$1,$B13,J$1,$B$1) -> 14.94 | ... AG13: =_xll.EQNXTDZ($A$1,$B13,AG$1,$B$1) -> 0
A14: Employee Cost | B14: PL_EMPLOYEES | C14: =_xll.EQNXTDZ($A$1,$B14,C$1,$B$1) -> 0 | D14: =_xll.EQNXTDZ($A$1,$B14,D$1,$B$1) -> 0 | E14: =_xll.EQNXTDZ($A$1,$B14,E$1,$B$1) -> 27.84 | F14: =_xll.EQNXTDZ($A$1,$B14,F$1,$B$1) -> 28.02 | G14: =_xll.EQNXTDZ($A$1,$B14,G$1,$B$1) -> 32.32 | H14: =_xll.EQNXTDZ($A$1,$B14,H$1,$B$1) -> 35.32 | I14: =_xll.EQNXTDZ($A$1,$B14,I$1,$B$1) -> 41.34 | J14: =_xll.EQNXTDZ($A$1,$B14,J$1,$B$1) -> 51.56 | ... AG14: =_xll.EQNXTDZ($A$1,$B14,AG$1,$B$1) -> 0
A15: Operating & Manufacturing Expenses | B15: PL_GEN_OTHER_MFG_EXPS | C15: =_xll.EQNXTDZ($A$1,$B15,C$1,$B$1) -> 0 | D15: =_xll.EQNXTDZ($A$1,$B15,D$1,$B$1) -> 0 | E15: =_xll.EQNXTDZ($A$1,$B15,E$1,$B$1) -> 34.35 | F15: =_xll.EQNXTDZ($A$1,$B15,F$1,$B$1) -> 36.17 | G15: =_xll.EQNXTDZ($A$1,$B15,G$1,$B$1) -> 47.84 | H15: =_xll.EQNXTDZ($A$1,$B15,H$1,$B$1) -> 55.7 | I15: =_xll.EQNXTDZ($A$1,$B15,I$1,$B$1) -> 65.14 | J15: =_xll.EQNXTDZ($A$1,$B15,J$1,$B$1) -> 68.68 | ... AG15: =_xll.EQNXTDZ($A$1,$B15,AG$1,$B$1) -> 0
A16: Cost of Software development | B16: PL_COST_SW | C16: =_xll.EQNXTDZ($A$1,$B16,C$1,$B$1) -> 0 | D16: =_xll.EQNXTDZ($A$1,$B16,D$1,$B$1) -> 0 | E16: =_xll.EQNXTDZ($A$1,$B16,E$1,$B$1) -> 0 | F16: =_xll.EQNXTDZ($A$1,$B16,F$1,$B$1) -> 0 | G16: =_xll.EQNXTDZ($A$1,$B16,G$1,$B$1) -> 0 | H16: =_xll.EQNXTDZ($A$1,$B16,H$1,$B$1) -> 0 | I16: =_xll.EQNXTDZ($A$1,$B16,I$1,$B$1) -> 0 | J16: =_xll.EQNXTDZ($A$1,$B16,J$1,$B$1) -> 0 | ... AG16: =_xll.EQNXTDZ($A$1,$B16,AG$1,$B$1) -> 0
... A36: Profit After Tax from Discontinued Operations | B36: PL_PAT_DIS_OP | C36: =_xll.EQNXTDZ($A$1,$B36,C$1,$B$1) -> 0 | D36: =_xll.EQNXTDZ($A$1,$B36,D$1,$B$1) -> 0 | E36: =_xll.EQNXTDZ($A$1,$B36,E$1,$B$1) -> 0 | F36: =_xll.EQNXTDZ($A$1,$B36,F$1,$B$1) -> 0 | G36: =_xll.EQNXTDZ($A$1,$B36,G$1,$B$1) -> 0 | H36: =_xll.EQNXTDZ($A$1,$B36,H$1,$B$1) -> 0 | I36: =_xll.EQNXTDZ($A$1,$B36,I$1,$B$1) -> 0 | J36: =_xll.EQNXTDZ($A$1,$B36,J$1,$B$1) -> 0 | ... AG36: =_xll.EQNXTDZ($A$1,$B36,AG$1,$B$1) -> 0
A39: Field Description | B39: Field Name
A40: Year End | B40: BS_YEAR_END | C40: =_xll.EQNXTDZ($A$1,$B40,C$1,$B$1) -> 0 | D40: =_xll.EQNXTDZ($A$1,$B40,D$1,$B$1) -> 0 | E40: =_xll.EQNXTDZ($A$1,$B40,E$1,$B$1) -> 200212 | F40: =_xll.EQNXTDZ($A$1,$B40,F$1,$B$1) -> 200312 | G40: =_xll.EQNXTDZ($A$1,$B40,G$1,$B$1) -> 200412 | H40: =_xll.EQNXTDZ($A$1,$B40,H$1,$B$1) -> 200512 | I40: =_xll.EQNXTDZ($A$1,$B40,I$1,$B$1) -> 200612 | J40: =_xll.EQNXTDZ($A$1,$B40,J$1,$B$1) -> 200712 | ... AG40: =_xll.EQNXTDZ($A$1,$B40,AG$1,$B$1) -> 0
A41: Share Capital | B41: BS_SHARE_CAPITAL | C41: =_xll.EQNXTDZ($A$1,$B41,C$1,$B$1) -> 0 | D41: =_xll.EQNXTDZ($A$1,$B41,D$1,$B$1) -> 0 | E41: =_xll.EQNXTDZ($A$1,$B41,E$1,$B$1) -> 16.62 | F41: =_xll.EQNXTDZ($A$1,$B41,F$1,$B$1) -> 16.62 | G41: =_xll.EQNXTDZ($A$1,$B41,G$1,$B$1) -> 16.62 | H41: =_xll.EQNXTDZ($A$1,$B41,H$1,$B$1) -> 16.62 | I41: =_xll.EQNXTDZ($A$1,$B41,I$1,$B$1) -> 16.62 | J41: =_xll.EQNXTDZ($A$1,$B41,J$1,$B$1) -> 16.62 | ... AG41: =_xll.EQNXTDZ($A$1,$B41,AG$1,$B$1) -> 0
A42: Share Warrants & Outstandings | B42: BS_SHAREWROUTST | C42: =_xll.EQNXTDZ($A$1,$B42,C$1,$B$1) -> 0 | D42: =_xll.EQNXTDZ($A$1,$B42,D$1,$B$1) -> 0 | E42: =_xll.EQNXTDZ($A$1,$B42,E$1,$B$1) -> 0 | F42: =_xll.EQNXTDZ($A$1,$B42,F$1,$B$1) -> 0 | G42: =_xll.EQNXTDZ($A$1,$B42,G$1,$B$1) -> 0 | H42: =_xll.EQNXTDZ($A$1,$B42,H$1,$B$1) -> 0 | I42: =_xll.EQNXTDZ($A$1,$B42,I$1,$B$1) -> 0 | J42: =_xll.EQNXTDZ($A$1,$B42,J$1,$B$1) -> 0 | ... AG42: =_xll.EQNXTDZ($A$1,$B42,AG$1,$B$1) -> 0
A43: Total Reserves | B43: BS_RESERVE | C43: =_xll.EQNXTDZ($A$1,$B43,C$1,$B$1) -> 0 | D43: =_xll.EQNXTDZ($A$1,$B43,D$1,$B$1) -> 0 | E43: =_xll.EQNXTDZ($A$1,$B43,E$1,$B$1) -> 85.76 | F43: =_xll.EQNXTDZ($A$1,$B43,F$1,$B$1) -> 99.57 | G43: =_xll.EQNXTDZ($A$1,$B43,G$1,$B$1) -> 123.81 | H43: =_xll.EQNXTDZ($A$1,$B43,H$1,$B$1) -> 164.95 | I43: =_xll.EQNXTDZ($A$1,$B43,I$1,$B$1) -> 231.01 | J43: =_xll.EQNXTDZ($A$1,$B43,J$1,$B$1) -> 301.48 | ... AG43: =_xll.EQNXTDZ($A$1,$B43,AG$1,$B$1) -> 0
A44: Shareholder's Funds | B44: BS_SHAREHODERS_FUNDS | C44: =_xll.EQNXTDZ($A$1,$B44,C$1,$B$1) -> 0 | D44: =_xll.EQNXTDZ($A$1,$B44,D$1,$B$1) -> 0 | E44: =_xll.EQNXTDZ($A$1,$B44,E$1,$B$1) -> 102.38 | F44: =_xll.EQNXTDZ($A$1,$B44,F$1,$B$1) -> 116.19 | G44: =_xll.EQNXTDZ($A$1,$B44,G$1,$B$1) -> 140.43 | H44: =_xll.EQNXTDZ($A$1,$B44,H$1,$B$1) -> 181.57 | I44: =_xll.EQNXTDZ($A$1,$B44,I$1,$B$1) -> 247.63 | J44: =_xll.EQNXTDZ($A$1,$B44,J$1,$B$1) -> 318.1 | ... AG44: =_xll.EQNXTDZ($A$1,$B44,AG$1,$B$1) -> 0
