Workbook

Sheet Template
A1: =+'Annual Raw'!C4 -> Siemens Energy India Ltd. | B1: 37135 | C1: =EOMONTH(B1,12) -> 37529 | D1: =EOMONTH(C1,12) -> 37894 | E1: =EOMONTH(D1,12) -> 38260 | F1: =EOMONTH(E1,12) -> 38625 | G1: =EOMONTH(F1,12) -> 38990 | H1: =EOMONTH(G1,12) -> 39355 | I1: =EOMONTH(H1,12) -> 39721 | J1: =EOMONTH(I1,12) -> 40086 | ... AE1: =EOMONTH(AD1,12) -> 47756 | AH1: QTR | AI1: 41061 | AJ1: 41153 | AK1: 41244 | AL1: 41334 | AM1: 41426 | AN1: 41518 | AO1: 41609 | AP1: 41699 | AQ1: 41791 | AR1: 41883 | AS1: 41974 | AT1: 42064 | AU1: 42156 | AV1: 42248 | AW1: 42339 | AX1: 42430 | AY1: 42522 | AZ1: 42614 | BA1: 42705 | BB1: 42795 | BC1: 42887 | BD1: 42979 | BE1: 43070 | BF1: 43160 | BG1: 43252 | BH1: 43344 | BI1: 43435 | BJ1: 43525 | BK1: 43617 | BL1: 43709 | BM1: 43800 | BN1: 43891 | BO1: 43983 | BP1: 44075 | BQ1: =EOMONTH(BP1,3) -> 44196 | BR1: =EOMONTH(BQ1,3) -> 44286 | BS1: =EOMONTH(BR1,3) -> 44377 | BT1: =EOMONTH(BS1,3) -> 44469 | BU1: =EOMONTH(BT1,3) -> 44561 | BV1: =EOMONTH(BU1,3) -> 44651 | BW1: =EOMONTH(BV1,3) -> 44742 | BX1: =EOMONTH(BW1,3) -> 44834 | ... DD1: =EOMONTH(DC1,3) -> 47756 | DE1: HISTORICAL ESTIMATES | DF1: 45930
A2: Presentation Data (Start)
A4: Revenue Breakup
A5: Power Transmission | Z5: =+SUM(CG5:CJ5) -> 4189.6 | AA5: =SUM(CK5:CN5) -> 5436.6989 | AB5: =+SUM(CO5:CR5) -> 6481.286 | AC5: =+SUM(CS5:CV5) -> 7742.7769 | AD5: =+SUM(CW5:CZ5) -> 9212.6239 | AE5: =+SUM(DA5:DD5) -> 10953.875 | CD5: 604.9 | CE5: 720.9 | CF5: 919.7 | CG5: 839.4 | CH5: 1013.8 | CI5: 976.4 | CJ5: 1360 | CK5: 1123.7 | CL5: 1279.2 | CM5: =+CI5+(CI5*CM11) -> 1273.8594 | CN5: =+CJ5+(CJ5*CN11) -> 1759.9395 | CO5: =+CK5+(CK5*CO11) -> 1460.5864 | CP5: =+CL5+(CL5*CP11) -> 1650.2673 | CQ5: =+CM5+(CM5*CQ11) -> 1429.0557 | CR5: =+CN5+(CN5*CR11) -> 1941.3766 | CS5: =+CO5+(CO5*CS11) -> 1781.9107 | CT5: =+CP5+(CP5*CT11) -> 1977.7624 | ... DD5: =+CZ5+(CZ5*DD11) -> 3261.1551 | DF5: 1411.8837
A6: Power Generation | Z6: =+SUM(CG6:CJ6) -> 3637.1 | AA6: =SUM(CK6:CN6) -> 4598.7491 | AB6: =+SUM(CO6:CR6) -> 5415.9516 | AC6: =+SUM(CS6:CV6) -> 6228.3444 | AD6: =+SUM(CW6:CZ6) -> 7162.596 | AE6: =+SUM(DA6:DD6) -> 8236.9854 | CD6: 591.7 | CE6: 763.3 | CF6: 1159.1 | CG6: 677.5 | CH6: 865.7 | CI6: 808.2 | CJ6: 1285.7 | CK6: 787.2 | CL6: 1114.9 | CM6: =+CI6+(CI6*CM12) -> 1040.8481 | CN6: =+CJ6+(CJ6*CN12) -> 1655.801 | CO6: =+CK6+(CK6*CO12) -> 1013.803 | CP6: =+CL6+(CL6*CP12) -> 1435.8346 | CQ6: =+CM6+(CM6*CQ12) -> 1144.9329 | CR6: =+CN6+(CN6*CR12) -> 1821.3811 | CS6: =+CO6+(CO6*CS12) -> 1165.8735 | CT6: =+CP6+(CP6*CT12) -> 1651.2098 | ... DD6: =+CZ6+(CZ6*DD12) -> 2770.093 | DF6: 952.27
A7: Total | Z7: =+Z5+Z6 -> 7826.7 | AA7: =+AA5+AA6 -> 10035.448 | AB7: =+AB5+AB6 -> 11897.238 | AC7: =+AC5+AC6 -> 13971.121 | AD7: =+AD5+AD6 -> 16375.22 | AE7: =+AE5+AE6 -> 19190.86 | CD7: =+CD5+CD6 -> 1196.6 | CE7: =+CE5+CE6 -> 1484.2 | CF7: =+CF5+CF6 -> 2078.8 | CG7: =+CG5+CG6 -> 1516.9 | CH7: =+CH5+CH6 -> 1879.5 | CI7: =+CI5+CI6 -> 1784.6 | CJ7: =+CJ5+CJ6 -> 2645.7 | CK7: =+CK5+CK6 -> 1910.9 | ... DD7: =+DD5+DD6 -> 6031.2481 | DF7: 2364.1537
A8: Checksum- Revenue | Z8: =+Z7-Z34 -> 0 | AA8: =+AA7-AA34 -> 0 | AB8: =+AB7-AB34 -> 0 | AC8: =+AC7-AC34 -> 0 | AD8: =+AD7-AD34 -> 0 | AE8: =+AE7-AE34 -> 0 | CD8: =+CD7-CD34 -> 0 | CE8: =+CE7-CE34 -> 0 | CF8: =+CF7-CF34 -> 0 | CG8: =+CG7-CG34 -> 0 | CH8: =+CH7-CH34 -> 0 | CI8: =+CI7-CI34 -> 0 | CJ8: =+CJ7-CJ34 -> 0 | CK8: =+CK7-CK34 -> 0 | ... DD8: =+DD7-DD34 -> 0 | DF8: 0
A10: Revenue Growth %
A11: Power Transmission yoy% | AA11: =+AA5/Z5-1 -> 0.29766539 | AB11: =+AB5/AA5-1 -> 0.19213628 | AC11: =+AC5/AB5-1 -> 0.1946359 | AD11: =+AD5/AC5-1 -> 0.1898346 | AE11: =+AE5/AD5-1 -> 0.18900702 | CH11: =+CH5/CD5-1 -> 0.6759795 | CI11: =+CI5/CE5-1 -> 0.35441809 | CJ11: =+CJ5/CF5-1 -> 0.47874307 | CK11: =+CK5/CG5-1 -> 0.33869431 | CL11: =+CL5/CH5-1 -> 0.26178733 | CM11: =+AVERAGE(CI11:CL11)*0.85 -> 0.30464909 | CN11: =+AVERAGE(CJ11:CM11)*0.85 -> 0.29407318 | CO11: =+AVERAGE(CK11:CN11) -> 0.29980098 | CP11: =+AVERAGE(CL11:CO11) -> 0.29007765 | CQ11: =+AVERAGE(CM11:CP11)*0.41 -> 0.12183159 | CR11: =+AVERAGE(CN11:CQ11)*0.41 -> 0.1030928 | CS11: =+AVERAGE(CO11:CR11)*1.08 -> 0.21999682 | CT11: =+AVERAGE(CP11:CS11)*1.08 -> 0.19844969 | CU11: =+AVERAGE(CQ11:CT11)*1.08 -> 0.17371014 | CV11: =+AVERAGE(CR11:CU11)*1.08 -> 0.18771735 | CW11: =+AVERAGE(CS11:CV11) -> 0.1949685 | CX11: =+AVERAGE(CT11:CW11) -> 0.18871142 | CY11: =+AVERAGE(CU11:CX11) -> 0.18627685 | CZ11: =+AVERAGE(CV11:CY11) -> 0.18941853 | DA11: =+AVERAGE(CW11:CZ11) -> 0.18984383 | DB11: =+AVERAGE(CX11:DA11) -> 0.18856266 | DC11: =+AVERAGE(CY11:DB11) -> 0.18852547 | DD11: =+AVERAGE(CZ11:DC11) -> 0.18908762 | DF11: 0.39266493
A12: Power Generation yoy% | AA12: =+AA6/Z6-1 -> 0.26439996 | AB12: =+AB6/AA6-1 -> 0.17770105 | AC12: =+AC6/AB6-1 -> 0.15 | AD12: =+AD6/AC6-1 -> 0.15 | AE12: =+AE6/AD6-1 -> 0.15 | CH12: =+CH6/CD6-1 -> 0.4630725 | CI12: =+CI6/CE6-1 -> 0.058823529 | CJ12: =+CJ6/CF6-1 -> 0.10922267 | CK12: =+CK6/CG6-1 -> 0.16191882 | CL12: =+CL6/CH6-1 -> 0.28785954 | CM12: =+CL12 -> 0.28785954 | CN12: =+CM12 -> 0.28785954 | CO12: =+CN12 -> 0.28785954 | CP12: =+CO12 -> 0.28785954 | CQ12: 0.1 | CR12: =+CQ12 -> 0.1 | CS12: 0.15 | CT12: =+CS12 -> 0.15 | CU12: =+CT12 -> 0.15 | CV12: =+CU12 -> 0.15 | CW12: =+CV12 -> 0.15 | CX12: =+CW12 -> 0.15 | CY12: =+CX12 -> 0.15 | CZ12: =+CY12 -> 0.15 | DA12: =+CZ12 -> 0.15 | ... DD12: =+DC12 -> 0.15 | DF12: 0.1
A14: EBIT Breakup
A15: Power Transmission-EBIT | Z15: =+SUM(CG15:CJ15) -> 804.6 | AA15: =SUM(CK15:CN15) -> 1021.4741 | AB15: =+SUM(CO15:CR15) -> 1287.7628 | AC15: =+SUM(CS15:CV15) -> 1630.9701 | AD15: =+SUM(CW15:CZ15) -> 1949.767 | AE15: =+SUM(DA15:DD15) -> 2321.0474 | CD15: 127.4 | CE15: 73.1 | CF15: 148 | CG15: 169.9 | CH15: 205.4 | CI15: 182.5 | CJ15: 246.8 | CK15: 273.3 | CL15: 214.3 | CM15: =+CM21*CM5 -> 225.79209 | CN15: =+CN21*CN5 -> 308.08198 | CO15: =+CO21*CO5 -> 295.34027 | CP15: =+CP21*CP5 -> 315.76149 | CQ15: =+CQ21*CQ5 -> 282.45293 | CR15: =+CR21*CR5 -> 394.20809 | CS15: =+CS21*CS5 -> 367.97452 | CT15: =+CT21*CT5 -> 410.62957 | ... DD15: =+DD21*DD5 -> 691.32975 | DF15: 261.52397
A16: Power Generation -EBIT | Z16: =+SUM(CG16:CJ16) -> 605.8 | AA16: =SUM(CK16:CN16) -> 912.38146 | AB16: =+SUM(CO16:CR16) -> 1066.1027 | AC16: =+SUM(CS16:CV16) -> 1222.2307 | AD16: =+SUM(CW16:CZ16) -> 1404.7579 | AE16: =+SUM(DA16:DD16) -> 1615.3337 | CD16: 131.8 | CE16: 124.3 | CF16: 217.8 | CG16: 144.7 | CH16: 128.8 | CI16: 131.2 | CJ16: 201.1 | CK16: 155.2 | CL16: 249.3 | CM16: =+CM22*CM6 -> 192.42962 | CN16: =+CN22*CN6 -> 315.45184 | CO16: =+CO22*CO6 -> 201.78554 | CP16: =+CP22*CP6 -> 286.46212 | CQ16: =+CQ22*CQ6 -> 221.52682 | CR16: =+CR22*CR6 -> 356.32818 | CS16: =+CS22*CS6 -> 229.58035 | CT16: =+CT22*CT6 -> 324.27572 | ... DD16: =+DD22*DD6 -> 543.24977 | DF16: 158.23983
A17: Total EBIT | Z17: =+Z15+Z16 -> 1410.4 | AA17: =+AA15+AA16 -> 1933.8555 | AB17: =+AB15+AB16 -> 2353.8654 | AC17: =+AC15+AC16 -> 2853.2007 | AD17: =+AD15+AD16 -> 3354.5249 | AE17: =+AE15+AE16 -> 3936.3811 | CD17: =+CD15+CD16 -> 259.2 | CE17: =+CE15+CE16 -> 197.4 | CF17: =+CF15+CF16 -> 365.8 | CG17: =+CG15+CG16 -> 314.6 | CH17: =+CH15+CH16 -> 334.2 | CI17: =+CI15+CI16 -> 313.7 | CJ17: =+CJ15+CJ16 -> 447.9 | CK17: =+CK15+CK16 -> 428.5 | ... DD17: =+DD15+DD16 -> 1234.5795 | DF17: 419.7638
A18: Checksum -EBIT | Z18: =+Z17-Z60 -> 23.4 | AA18: =+AA17-AA60 -> 0 | AB18: =+AB17-AB60 -> 0 | AC18: =+AC17-AC60 -> 0 | AD18: =+AD17-AD60 -> 0 | AE18: =+AE17-AE60 -> 0 | CD18: =+CD17-CD60 -> 0 | CE18: =+CE17-CE60 -> 0 | CF18: =+CF17-CF60 -> 0 | CG18: =+CG17-CG60 -> 0 | CH18: =+CH17-CH60 -> 0 | CI18: =+CI17-CI60 -> 0 | CJ18: =+CJ17-CJ60 -> 0 | CK18: =+CK17-CK60 -> 0 | ... DD18: =+DD17-DD60 -> 0 | DF18: 0
A20: EBIT Margins %
A21: Power Transmission-EBIT% | Z21: =+Z15/Z5 -> 0.19204697 | AA21: =+AA15/AA5 -> 0.18788498 | AB21: =+AB15/AB5 -> 0.19868939 | AC21: =+AC15/AC5 -> 0.21064407 | AD21: =+AD15/AD5 -> 0.21164079 | AE21: =+AE15/AE5 -> 0.21189283 | CD21: =+CD15/CD5 -> 0.21061332 | CE21: =+CE15/CE5 -> 0.10140103 | CF21: =+CF15/CF5 -> 0.16092204 | CG21: =+CG15/CG5 -> 0.20240648 | CH21: =+CH15/CH5 -> 0.20260406 | CI21: =+CI15/CI5 -> 0.1869111 | CJ21: =+CJ15/CJ5 -> 0.18147059 | CK21: =+CK15/CK5 -> 0.24321438 | CL21: =+CL15/CL5 -> 0.16752658 | CM21: =+AVERAGE(CI21:CL21)*0.91 -> 0.1772504 | CN21: =+AVERAGE(CJ21:CM21)*0.91 -> 0.17505259 | CO21: =+AVERAGE(CK21:CN21)*1.06 -> 0.20220665 | CP21: =+AVERAGE(CL21:CO21)*1.06 -> 0.1913396 | CQ21: =+AVERAGE(CM21:CP21)*1.06 -> 0.19765005 | CR21: =+AVERAGE(CN21:CQ21)*1.06 -> 0.20305596 | CS21: =+AVERAGE(CO21:CR21)*1.04 -> 0.20650559 | CT21: =+AVERAGE(CP21:CS21)*1.04 -> 0.20762331 | CU21: =+AVERAGE(CQ21:CT21)*1.04 -> 0.21185707 | CV21: =+AVERAGE(CR21:CU21)*1.04 -> 0.2155509 | CW21: =+AVERAGE(CS21:CV21) -> 0.21038422 | CX21: =+AVERAGE(CT21:CW21) -> 0.21135388 | CY21: =+AVERAGE(CU21:CX21) -> 0.21228652 | CZ21: =+AVERAGE(CV21:CY21) -> 0.21239388 | DA21: =+AVERAGE(CW21:CZ21) -> 0.21160462 | DB21: =+AVERAGE(CX21:DA21) -> 0.21190972 | DC21: =+AVERAGE(CY21:DB21) -> 0.21204869 | DD21: =+AVERAGE(CZ21:DC21) -> 0.21198923 | DF21: 0.18523053
A22: Power Generation -EBIT% | Z22: =+Z16/Z6 -> 0.16656127 | AA22: =+AA16/AA6 -> 0.19839775 | AB22: =+AB16/AB6 -> 0.19684494 | AC22: =+AC16/AC6 -> 0.19623685 | AD22: =+AD16/AD6 -> 0.19612413 | AE22: =+AE16/AE6 -> 0.19610738 | CD22: =+CD16/CD6 -> 0.22274801 | CE22: =+CE16/CE6 -> 0.16284554 | CF22: =+CF16/CF6 -> 0.18790441 | CG22: =+CG16/CG6 -> 0.21357934 | CH22: =+CH16/CH6 -> 0.14878133 | CI22: =+CI16/CI6 -> 0.16233606 | CJ22: =+CJ16/CJ6 -> 0.15641285 | CK22: =+CK16/CK6 -> 0.19715447 | CL22: =+CL16/CL6 -> 0.2236075 | CM22: =+AVERAGE(CI22:CL22) -> 0.18487772 | CN22: =+AVERAGE(CJ22:CM22) -> 0.19051313 | CO22: =+AVERAGE(CK22:CN22) -> 0.19903821 | CP22: =+AVERAGE(CL22:CO22) -> 0.19950914 | CQ22: =+AVERAGE(CM22:CP22) -> 0.19348455 | CR22: =+AVERAGE(CN22:CQ22) -> 0.19563626 | CS22: =+AVERAGE(CO22:CR22) -> 0.19691704 | CT22: =+AVERAGE(CP22:CS22) -> 0.19638675 | ... DD22: =+AVERAGE(CZ22:DC22) -> 0.19611247 | DF22: 0.16617118
A25: Order Book
A26: Opening Order Book | Y26: 7720 | Z26: =+Y29 -> 11050 | AA26: =+Z29 -> 16210 | AB26: =+AA29 -> 21474.452 | AC26: =+AB29 -> 26407.104 | AD26: =+AC29 -> 30948.862 | AE26: =+AD29 -> 34937.809 | CJ26: =+CJ29+CJ28-CJ27 -> 15565.7 | CK26: =+CJ29 -> 16210 | CL26: =+CK29 -> 17599 | CM26: =+CL29 -> 19204.9 | CN26: =+CM29 -> 20890.193 | CO26: =+CN29 -> 21474.452 | CP26: =+CO29 -> 22629.953 | CQ26: =+CP29 -> 23943.851 | CR26: =+CQ29 -> 25769.862 | ... DD26: =+DC29 -> 39826.398 | DF26: 17599
A27: Addition | Y27: =+Y29+Y28-Y26 -> 8089.6 | Z27: =+Z29+Z28-Z26 -> 12986.7 | AA27: =SUM(CK27:CN27) -> 15299.9 | AB27: =+SUM(CO27:CR27) -> 16829.89 | AC27: =+SUM(CS27:CV27) -> 18512.879 | AD27: =+SUM(CW27:CZ27) -> 20364.167 | AE27: =+SUM(DA27:DD27) -> 24437 | CJ27: 3290 | CK27: =+CK29+CK28-CK26 -> 3299.9 | CL27: 4000 | CM27: =+CL27 -> 4000 | CN27: =+CM27 -> 4000 | CO27: =+CK27*110% -> 3629.89 | CP27: =+CL27*110% -> 4400 | CQ27: =+CM27*110% -> 4400 | CR27: =+CN27*110% -> 4400 | CS27: =+CO27*110% -> 3992.879 | CT27: =+CP27*110% -> 4840 | CU27: =+CQ27*110% -> 4840 | CV27: =+CR27*110% -> 4840 | ... CZ27: =+CV27*110% -> 5324 | DA27: =+CW27*120% -> 5270.6003 | DB27: =+CX27*120% -> 6388.8 | DC27: =+CY27*120% -> 6388.8 | DD27: =+CZ27*120% -> 6388.8 | DF27: 4000
A28: Execution | Y28: =+Y34 -> 4759.6 | Z28: =+Z34 -> 7826.7 | AA28: =+AA34 -> 10035.448 | AB28: =+AB34 -> 11897.238 | AC28: =+AC34 -> 13971.121 | AD28: =+AD34 -> 16375.22 | AE28: =+AE34 -> 19190.86 | CJ28: =+CJ34 -> 2645.7 | CK28: =+CK34 -> 1910.9 | CL28: =+CL7 -> 2394.1 | CM28: =+CM7 -> 2314.7075 | CN28: =+CN7 -> 3415.7405 | CO28: =+CO7 -> 2474.3894 | CP28: =+CP7 -> 3086.1019 | CQ28: =+CQ7 -> 2573.9886 | CR28: =+CR7 -> 3762.7577 | CS28: =+CS7 -> 2947.7842 | ... DD28: =+DD7 -> 6031.2481 | DF28: 2364.1537
A29: Closing Order Book | Y29: 11050 | Z29: 16210 | AA29: =+AA26+AA27-AA28 -> 21474.452 | AB29: =+AB26+AB27-AB28 -> 26407.104 | AC29: =+AC26+AC27-AC28 -> 30948.862 | AD29: =+AD26+AD27-AD28 -> 34937.809 | AE29: =+AE26+AE27-AE28 -> 40183.949 | CJ29: 16210 | CK29: 17599 | CL29: =+CL26+CL27-CL28 -> 19204.9 | CM29: =+CM26+CM27-CM28 -> 20890.193 | CN29: =+CN26+CN27-CN28 -> 21474.452 | CO29: =+CO26+CO27-CO28 -> 22629.953 | CP29: =+CP26+CP27-CP28 -> 23943.851 | CQ29: =+CQ26+CQ27-CQ28 -> 25769.862 | CR29: =+CR26+CR27-CR28 -> 26407.104 | CS29: =+CS26+CS27-CS28 -> 27452.199 | ... DD29: =+DD26+DD27-DD28 -> 40183.949 | DF29: 19234.846
A32: Presentation Data (End)
A33: Profit & Loss- Annual (Start)
A34: Gross Revenue | B34: ='Annual Raw'!C6 -> 0 | C34: ='Annual Raw'!D6 -> 0 | D34: ='Annual Raw'!E6 -> 0 | E34: ='Annual Raw'!F6 -> 0 | F34: ='Annual Raw'!G6 -> 0 | G34: ='Annual Raw'!H6 -> 0 | H34: ='Annual Raw'!I6 -> 0 | I34: ='Annual Raw'!J6 -> 0 | ... Z34: ='Annual Raw'!AA6 -> 7826.7 | AA34: =SUM(CK34:CN34) -> 10035.448 | AB34: =+SUM(CO34:CR34) -> 11897.238 | AC34: =+SUM(CS34:CV34) -> 13971.121 | AD34: =+SUM(CW34:CZ34) -> 16375.22 | AE34: =+SUM(DA34:DD34) -> 19190.86 | AI34: ='QTR Raw'!C6+'QTR Raw'!C8 -> 0 | AJ34: ='QTR Raw'!D6+'QTR Raw'!D8 -> 0 | AK34: ='QTR Raw'!E6+'QTR Raw'!E8 -> 0 | AL34: ='QTR Raw'!F6+'QTR Raw'!F8 -> 0 | AM34: ='QTR Raw'!G6+'QTR Raw'!G8 -> 0 | AN34: ='QTR Raw'!H6+'QTR Raw'!H8 -> 0 | AO34: ='QTR Raw'!I6+'QTR Raw'!I8 -> 0 | AP34: ='QTR Raw'!J6+'QTR Raw'!J8 -> 0 | ... CL34: ='QTR Raw'!BF6+'QTR Raw'!BF8 -> 2394.1 | CM34: =+CM7 -> 2314.7075 | CN34: =+CN7 -> 3415.7405 | CO34: =+CO7 -> 2474.3894 | CP34: =+CP7 -> 3086.1019 | CQ34: =+CQ7 -> 2573.9886 | CR34: =+CR7 -> 3762.7577 | CS34: =+CS7 -> 2947.7842 | CT34: =+CT7 -> 3628.9722 | ... DD34: =+DD7 -> 6031.2481 | DF34: 7826.7
A35: Less: Exise Duty | B35: ='Annual Raw'!C7+'Annual Raw'!C8+'Annual Raw'!C9 -> 0 | C35: ='Annual Raw'!D7+'Annual Raw'!D8+'Annual Raw'!D9 -> 0 | D35: ='Annual Raw'!E7+'Annual Raw'!E8+'Annual Raw'!E9 -> 0 | E35: ='Annual Raw'!F7+'Annual Raw'!F8+'Annual Raw'!F9 -> 0 | F35: ='Annual Raw'!G7+'Annual Raw'!G8+'Annual Raw'!G9 -> 0 | G35: ='Annual Raw'!H7+'Annual Raw'!H8+'Annual Raw'!H9 -> 0 | H35: ='Annual Raw'!I7+'Annual Raw'!I8+'Annual Raw'!I9 -> 0 | I35: ='Annual Raw'!J7+'Annual Raw'!J8+'Annual Raw'!J9 -> 0 | ... Z35: ='Annual Raw'!AA7+'Annual Raw'!AA8+'Annual Raw'!AA9 -> 0 | AA35: =SUM(CK35:CN35) -> 0 | AB35: =+SUM(CO35:CR35) -> 0 | AC35: =+SUM(CS35:CV35) -> 0 | AD35: =+SUM(CW35:CZ35) -> 0 | AE35: =+SUM(DA35:DD35) -> 0 | AI35: =+'QTR Raw'!C20+'QTR Raw'!C19+'QTR Raw'!C13+'QTR Raw'!C7 -> 0 | AJ35: =+'QTR Raw'!D20+'QTR Raw'!D19+'QTR Raw'!D13+'QTR Raw'!D7 -> 0 | AK35: =+'QTR Raw'!E20+'QTR Raw'!E19+'QTR Raw'!E13+'QTR Raw'!E7 -> 0 | AL35: =+'QTR Raw'!F20+'QTR Raw'!F19+'QTR Raw'!F13+'QTR Raw'!F7 -> 0 | AM35: =+'QTR Raw'!G20+'QTR Raw'!G19+'QTR Raw'!G13+'QTR Raw'!G7 -> 0 | AN35: =+'QTR Raw'!H20+'QTR Raw'!H19+'QTR Raw'!H13+'QTR Raw'!H7 -> 0 | AO35: =+'QTR Raw'!I20+'QTR Raw'!I19+'QTR Raw'!I13+'QTR Raw'!I7 -> 0 | AP35: =+'QTR Raw'!J20+'QTR Raw'!J19+'QTR Raw'!J13+'QTR Raw'!J7 -> 0 | ... CL35: =+'QTR Raw'!BF20+'QTR Raw'!BF19+'QTR Raw'!BF13+'QTR Raw'!BF7 -> 0 | DF35: 0
A36: Net Revenue | B36: =+B34-B35 -> 0 | C36: =+C34-C35 -> 0 | D36: =+D34-D35 -> 0 | E36: =+E34-E35 -> 0 | F36: =+F34-F35 -> 0 | G36: =+G34-G35 -> 0 | H36: =+H34-H35 -> 0 | I36: =+I34-I35 -> 0 | ... AE36: =+AE34-AE35 -> 19190.86 | AI36: =+AI34-AI35 -> 0 | AJ36: =+AJ34-AJ35 -> 0 | AK36: =+AK34-AK35 -> 0 | AL36: =+AL34-AL35 -> 0 | AM36: =+AM34-AM35 -> 0 | AN36: =+AN34-AN35 -> 0 | AO36: =+AO34-AO35 -> 0 | AP36: =+AP34-AP35 -> 0 | ... DD36: =+DD34-DD35 -> 6031.2481 | DF36: 7826.7
A37: Net Revenue YOY% | C37: =C36/B36-1 -> #DIV/0! | D37: =D36/C36-1 -> #DIV/0! | E37: =E36/D36-1 -> #DIV/0! | F37: =F36/E36-1 -> #DIV/0! | G37: =G36/F36-1 -> #DIV/0! | H37: =H36/G36-1 -> #DIV/0! | I37: =I36/H36-1 -> #DIV/0! | J37: =J36/I36-1 -> #DIV/0! | ... AE37: =AE36/AD36-1 -> 0.17194517 | AM37: =+IF(AI36<0,1-AM36/AI36,AM36/AI36-1) -> #DIV/0! | AN37: =+IF(AJ36<0,1-AN36/AJ36,AN36/AJ36-1) -> #DIV/0! | AO37: =+IF(AK36<0,1-AO36/AK36,AO36/AK36-1) -> #DIV/0! | AP37: =+IF(AL36<0,1-AP36/AL36,AP36/AL36-1) -> #DIV/0! | AQ37: =+IF(AM36<0,1-AQ36/AM36,AQ36/AM36-1) -> #DIV/0! | AR37: =+IF(AN36<0,1-AR36/AN36,AR36/AN36-1) -> #DIV/0! | AS37: =+IF(AO36<0,1-AS36/AO36,AS36/AO36-1) -> #DIV/0! | AT37: =+IF(AP36<0,1-AT36/AP36,AT36/AP36-1) -> #DIV/0! | ... DD37: =+IF(CZ36<0,1-DD36/CZ36,DD36/CZ36-1) -> 0.17081019 | DF37: 0.64440289
A38: Net Revenue QOQ% | AJ38: =+IF(AI36<0,1-AJ36/AI36,AJ36/AI36-1) -> #DIV/0! | AK38: =+IF(AJ36<0,1-AK36/AJ36,AK36/AJ36-1) -> #DIV/0! | AL38: =+IF(AK36<0,1-AL36/AK36,AL36/AK36-1) -> #DIV/0! | AM38: =+IF(AL36<0,1-AM36/AL36,AM36/AL36-1) -> #DIV/0! | AN38: =+IF(AM36<0,1-AN36/AM36,AN36/AM36-1) -> #DIV/0! | AO38: =+IF(AN36<0,1-AO36/AN36,AO36/AN36-1) -> #DIV/0! | AP38: =+IF(AO36<0,1-AP36/AO36,AP36/AO36-1) -> #DIV/0! | AQ38: =+IF(AP36<0,1-AQ36/AP36,AQ36/AP36-1) -> #DIV/0! | ... DD38: =+IF(DC36<0,1-DD36/DC36,DD36/DC36-1) -> 0.46883107
A39: Increase/Decrease in Stock | B39: ='Annual Raw'!C11 -> 0 | C39: ='Annual Raw'!D11 -> 0 | D39: ='Annual Raw'!E11 -> 0 | E39: ='Annual Raw'!F11 -> 0 | F39: ='Annual Raw'!G11 -> 0 | G39: ='Annual Raw'!H11 -> 0 | H39: ='Annual Raw'!I11 -> 0 | I39: ='Annual Raw'!J11 -> 0 | ... Z39: ='Annual Raw'!AA11 -> 49 | AA39: =SUM(CK39:CN39) -> -84 | AB39: =+SUM(CO39:CR39) -> 0 | AC39: =+SUM(CS39:CV39) -> 0 | AD39: =+SUM(CW39:CZ39) -> 0 | AE39: =+SUM(DA39:DD39) -> 0 | AI39: ='QTR Raw'!C10 -> 0 | AJ39: ='QTR Raw'!D10 -> 0 | AK39: ='QTR Raw'!E10 -> 0 | AL39: ='QTR Raw'!F10 -> 0 | AM39: ='QTR Raw'!G10 -> 0 | AN39: ='QTR Raw'!H10 -> 0 | AO39: ='QTR Raw'!I10 -> 0 | AP39: ='QTR Raw'!J10 -> 0 | ... CL39: ='QTR Raw'!BF10 -> -55.8 | DF39: 49
A40: Purchase of Finished Goods | B40: 0 | C40: 0 | D40: 0 | E40: 0 | F40: 0 | G40: 0 | H40: 0 | I40: 0 | J40: 0 | K40: 0 | L40: 0 | M40: 0 | N40: 0 | O40: 0 | P40: 0 | Q40: 0 | R40: 0 | S40: 0 | T40: 0 | U40: 0 | V40: 0 | W40: 0 | X40: 0 | Y40: 0 | Z40: 0 | AA40: =SUM(CK40:CN40) -> 198.9 | AB40: =+SUM(CO40:CR40) -> 0 | AC40: =+SUM(CS40:CV40) -> 0 | AD40: =+SUM(CW40:CZ40) -> 0 | AE40: =+SUM(DA40:DD40) -> 0 | AI40: ='QTR Raw'!C12 -> 0 | AJ40: ='QTR Raw'!D12 -> 0 | AK40: ='QTR Raw'!E12 -> 0 | AL40: ='QTR Raw'!F12 -> 0 | AM40: ='QTR Raw'!G12 -> 0 | AN40: ='QTR Raw'!H12 -> 0 | AO40: ='QTR Raw'!I12 -> 0 | AP40: ='QTR Raw'!J12 -> 0 | ... CL40: ='QTR Raw'!BF12 -> 81.2 | DF40: 0
A41: Raw Material Consumed | B41: ='Annual Raw'!C12 -> 0 | C41: ='Annual Raw'!D12 -> 0 | D41: ='Annual Raw'!E12 -> 0 | E41: ='Annual Raw'!F12 -> 0 | F41: ='Annual Raw'!G12 -> 0 | G41: ='Annual Raw'!H12 -> 0 | H41: ='Annual Raw'!I12 -> 0 | I41: ='Annual Raw'!J12 -> 0 | ... Z41: ='Annual Raw'!AA12 -> 2131.8 | AA41: =SUM(CK41:CN41) -> 2052.8669 | AB41: =+SUM(CO41:CR41) -> 2660.9834 | AC41: =+SUM(CS41:CV41) -> 3129.9239 | AD41: =+SUM(CW41:CZ41) -> 3669.8691 | AE41: =+SUM(DA41:DD41) -> 4301.1472 | AI41: ='QTR Raw'!C11 -> 0 | AJ41: ='QTR Raw'!D11 -> 0 | AK41: ='QTR Raw'!E11 -> 0 | AL41: ='QTR Raw'!F11 -> 0 | AM41: ='QTR Raw'!G11 -> 0 | AN41: ='QTR Raw'!H11 -> 0 | AO41: ='QTR Raw'!I11 -> 0 | AP41: ='QTR Raw'!J11 -> 0 | ... CL41: ='QTR Raw'!BF11 -> 352.5 | CM41: =+CM36-CM42 -> 555.47166 | CN41: =+CN36-CN42 -> 766.99525 | CO41: =+CO36-CO42 -> 555.68332 | CP41: =+CP36-CP42 -> 677.76433 | CQ41: =+CQ36-CQ42 -> 584.75508 | CR41: =+CR36-CR42 -> 842.78063 | CS41: =+CS36-CS42 -> 659.82484 | CT41: =+CT36-CT42 -> 811.63225 | ... DD41: =+DD36-DD42 -> 1351.7205 | DF41: 2131.8
A42: Gross Profit | B42: =B36-B39-B41-B40 -> 0 | C42: =C36-C39-C41-C40 -> 0 | D42: =D36-D39-D41-D40 -> 0 | E42: =E36-E39-E41-E40 -> 0 | F42: =F36-F39-F41-F40 -> 0 | G42: =G36-G39-G41-G40 -> 0 | H42: =H36-H39-H41-H40 -> 0 | I42: =I36-I39-I41-I40 -> 0 | ... AE42: =AE36-AE39-AE41-AE40 -> 14889.713 | AI42: =AI36-AI39-AI41-AI40 -> 0 | AJ42: =AJ36-AJ39-AJ41-AJ40 -> 0 | AK42: =AK36-AK39-AK41-AK40 -> 0 | AL42: =AL36-AL39-AL41-AL40 -> 0 | AM42: =AM36-AM39-AM41-AM40 -> 0 | AN42: =AN36-AN39-AN41-AN40 -> 0 | AO42: =AO36-AO39-AO41-AO40 -> 0 | AP42: =AP36-AP39-AP41-AP40 -> 0 | ... CL42: =CL36-CL39-CL41-CL40 -> 2016.2 | CM42: =+CM43*CM36 -> 1759.2358 | CN42: =+CN43*CN36 -> 2648.7453 | CO42: =+CO43*CO36 -> 1918.7061 | CP42: =+CP43*CP36 -> 2408.3376 | CQ42: =+CQ43*CQ36 -> 1989.2335 | CR42: =+CR43*CR36 -> 2919.9771 | CS42: =+CS43*CS36 -> 2287.9593 | CT42: =+CT43*CT36 -> 2817.3399 | ... DD42: =+DD43*DD36 -> 4679.5276 | DF42: 5645.9
A43: GP% | B43: =B42/B36 -> #DIV/0! | C43: =C42/C36 -> #DIV/0! | D43: =D42/D36 -> #DIV/0! | E43: =E42/E36 -> #DIV/0! | F43: =F42/F36 -> #DIV/0! | G43: =G42/G36 -> #DIV/0! | H43: =H42/H36 -> #DIV/0! | I43: =I42/I36 -> #DIV/0! | ... AE43: =AE42/AE36 -> 0.77587522 | AI43: =AI42/AI36 -> #DIV/0! | AJ43: =AJ42/AJ36 -> #DIV/0! | AK43: =AK42/AK36 -> #DIV/0! | AL43: =AL42/AL36 -> #DIV/0! | AM43: =AM42/AM36 -> #DIV/0! | AN43: =AN42/AN36 -> #DIV/0! | AO43: =AO42/AO36 -> #DIV/0! | AP43: =AP42/AP36 -> #DIV/0! | ... CL43: =CL42/CL36 -> 0.84215363 | CM43: =AVERAGE(CI43:CL43)*0.99 -> 0.76002511 | CN43: =AVERAGE(CJ43:CM43)*0.99 -> 0.77545272 | CO43: =AVERAGE(CK43:CN43)*0.99 -> 0.77542608 | CP43: =AVERAGE(CL43:CO43)*0.99 -> 0.78038174 | CQ43: =AVERAGE(CM43:CP43) -> 0.77282141 | CR43: =AVERAGE(CN43:CQ43) -> 0.77602049 | CS43: =AVERAGE(CO43:CR43) -> 0.77616243 | CT43: =AVERAGE(CP43:CS43) -> 0.77634652 | CU43: =AVERAGE(CQ43:CT43) -> 0.77533771 | CV43: =AVERAGE(CR43:CU43) -> 0.77596679 | CW43: =AVERAGE(CS43:CV43) -> 0.77595336 | CX43: =AVERAGE(CT43:CW43) -> 0.7759011 | ... DD43: =AVERAGE(CZ43:DC43) -> 0.77588047 | DF43: 0.72136405
A44: GP YOY% | C44: =+IF(B42<0,1-C42/B42,C42/B42-1) -> #DIV/0! | D44: =+IF(C42<0,1-D42/C42,D42/C42-1) -> #DIV/0! | E44: =+IF(D42<0,1-E42/D42,E42/D42-1) -> #DIV/0! | F44: =+IF(E42<0,1-F42/E42,F42/E42-1) -> #DIV/0! | G44: =+IF(F42<0,1-G42/F42,G42/F42-1) -> #DIV/0! | H44: =+IF(G42<0,1-H42/G42,H42/G42-1) -> #DIV/0! | I44: =+IF(H42<0,1-I42/H42,I42/H42-1) -> #DIV/0! | J44: =+IF(I42<0,1-J42/I42,J42/I42-1) -> #DIV/0! | ... AE44: =+IF(AD42<0,1-AE42/AD42,AE42/AD42-1) -> 0.17192457 | AM44: =+IF(AI42<0,1-AM42/AI42,AM42/AI42-1) -> #DIV/0! | AN44: =+IF(AJ42<0,1-AN42/AJ42,AN42/AJ42-1) -> #DIV/0! | AO44: =+IF(AK42<0,1-AO42/AK42,AO42/AK42-1) -> #DIV/0! | AP44: =+IF(AL42<0,1-AP42/AL42,AP42/AL42-1) -> #DIV/0! | AQ44: =+IF(AM42<0,1-AQ42/AM42,AQ42/AM42-1) -> #DIV/0! | AR44: =+IF(AN42<0,1-AR42/AN42,AR42/AN42-1) -> #DIV/0! | AS44: =+IF(AO42<0,1-AS42/AO42,AS42/AO42-1) -> #DIV/0! | AT44: =+IF(AP42<0,1-AT42/AP42,AT42/AP42-1) -> #DIV/0! | ... CL44: =+IF(CH42<0,1-CL42/CH42,CL42/CH42-1) -> 0.53125237 | CM44: =+CM42/CI42-1 -> 0.41292731 | CN44: =+CN42/CJ42-1 -> 0.29087445 | CO44: =+CO42/CK42-1 -> 0.32920406 | CP44: =+CP42/CL42-1 -> 0.1944934 | CQ44: =+CQ42/CM42-1 -> 0.13073728 | CR44: =+CR42/CN42-1 -> 0.10240011 | CS44: =+CS42/CO42-1 -> 0.19244911 | CT44: =+CT42/CP42-1 -> 0.16982765 | ... DD44: =+DD42/CZ42-1 -> 0.17077658 | DF44: 0.58574879
A45: GP QOQ% | AJ45: =+IF(AI42<0,1-AJ42/AI42,AJ42/AI42-1) -> #DIV/0! | AK45: =+IF(AJ42<0,1-AK42/AJ42,AK42/AJ42-1) -> #DIV/0! | AL45: =+IF(AK42<0,1-AL42/AK42,AL42/AK42-1) -> #DIV/0! | AM45: =+IF(AL42<0,1-AM42/AL42,AM42/AL42-1) -> #DIV/0! | AN45: =+IF(AM42<0,1-AN42/AM42,AN42/AM42-1) -> #DIV/0! | AO45: =+IF(AN42<0,1-AO42/AN42,AO42/AN42-1) -> #DIV/0! | AP45: =+IF(AO42<0,1-AP42/AO42,AP42/AO42-1) -> #DIV/0! | AQ45: =+IF(AP42<0,1-AQ42/AP42,AQ42/AP42-1) -> #DIV/0! | ... CL45: =+IF(CK42<0,1-CL42/CK42,CL42/CK42-1) -> 0.39674402 | CM45: =+CM42/CL42-1 -> -0.12744976 | CN45: =+CN42/CM42-1 -> 0.50562266 | CO45: =+CO42/CN42-1 -> -0.275617 | CP45: =+CP42/CO42-1 -> 0.2551884 | CQ45: =+CQ42/CP42-1 -> -0.17402216 | CR45: =+CR42/CQ42-1 -> 0.46789057 | CS45: =+CS42/CR42-1 -> -0.21644613 | CT45: =+CT42/CS42-1 -> 0.23137673 | ... DD45: =+DD42/DC42-1 -> 0.46886542
A46: Employee Cost | B46: ='Annual Raw'!C14 -> 0 | C46: ='Annual Raw'!D14 -> 0 | D46: ='Annual Raw'!E14 -> 0 | E46: ='Annual Raw'!F14 -> 0 | F46: ='Annual Raw'!G14 -> 0 | G46: ='Annual Raw'!H14 -> 0 | H46: ='Annual Raw'!I14 -> 0 | I46: ='Annual Raw'!J14 -> 0 | ... Z46: ='Annual Raw'!AA14 -> 985.4 | AA46: =SUM(CK46:CN46) -> 1098.937 | AB46: =+SUM(CO46:CR46) -> 1175.8626 | AC46: =+SUM(CS46:CV46) -> 1258.173 | AD46: =+SUM(CW46:CZ46) -> 1346.2451 | AE46: =+SUM(DA46:DD46) -> 1440.4822 | AI46: ='QTR Raw'!C16 -> 0 | AJ46: ='QTR Raw'!D16 -> 0 | AK46: ='QTR Raw'!E16 -> 0 | AL46: ='QTR Raw'!F16 -> 0 | AM46: ='QTR Raw'!G16 -> 0 | AN46: ='QTR Raw'!H16 -> 0 | AO46: ='QTR Raw'!I16 -> 0 | AP46: ='QTR Raw'!J16 -> 0 | ... CL46: ='QTR Raw'!BF16 -> 259.7 | CM46: =CI46*107% -> 258.619 | CN46: =CJ46*107% -> 328.918 | CO46: =CK46*107% -> 269.319 | CP46: =CL46*107% -> 277.879 | CQ46: =CM46*107% -> 276.72233 | CR46: =CN46*107% -> 351.94226 | CS46: =CO46*107% -> 288.17133 | CT46: =CP46*107% -> 297.33053 | ... DD46: =CZ46*107% -> 431.1444 | DF46: 985.4
A47: General and Administration Expenses | B47: ='Annual Raw'!C17 -> 0 | C47: ='Annual Raw'!D17 -> 0 | D47: ='Annual Raw'!E17 -> 0 | E47: ='Annual Raw'!F17 -> 0 | F47: ='Annual Raw'!G17 -> 0 | G47: ='Annual Raw'!H17 -> 0 | H47: ='Annual Raw'!I17 -> 0 | I47: ='Annual Raw'!J17 -> 0 | ... Z47: ='Annual Raw'!AA17 -> 538.1 | AA47: =SUM(CK47:CN47) -> 0 | AB47: =+SUM(CO47:CR47) -> 0 | AC47: =+SUM(CS47:CV47) -> 0 | AD47: =+SUM(CW47:CZ47) -> 0 | AE47: =+SUM(DA47:DD47) -> 0 | AI47: ='QTR Raw'!C17 -> 0 | AJ47: ='QTR Raw'!D17 -> 0 | AK47: ='QTR Raw'!E17 -> 0 | AL47: ='QTR Raw'!F17 -> 0 | AM47: ='QTR Raw'!G17 -> 0 | AN47: ='QTR Raw'!H17 -> 0 | AO47: ='QTR Raw'!I17 -> 0 | AP47: ='QTR Raw'!J17 -> 0 | ... CL47: ='QTR Raw'!BF17 -> 0 | DF47: 538.1
A48: Miscellaneous Expenses | B48: ='Annual Raw'!C19-'Annual Raw'!C20 -> 0 | C48: ='Annual Raw'!D19-'Annual Raw'!D20 -> 0 | D48: ='Annual Raw'!E19-'Annual Raw'!E20 -> 0 | E48: ='Annual Raw'!F19-'Annual Raw'!F20 -> 0 | F48: ='Annual Raw'!G19-'Annual Raw'!G20 -> 0 | G48: ='Annual Raw'!H19-'Annual Raw'!H20 -> 0 | H48: ='Annual Raw'!I19-'Annual Raw'!I20 -> 0 | I48: ='Annual Raw'!J19-'Annual Raw'!J20 -> 0 | ... Z48: ='Annual Raw'!AA19-'Annual Raw'!AA20 -> 82.5 | AA48: =SUM(CK48:CN48) -> 0 | AB48: =+SUM(CO48:CR48) -> 0 | AC48: =+SUM(CS48:CV48) -> 0 | AD48: =+SUM(CW48:CZ48) -> 0 | AE48: =+SUM(DA48:DD48) -> 0 | AI48: =+'QTR Raw'!C21 -> 0 | AJ48: =+'QTR Raw'!D21 -> 0 | AK48: =+'QTR Raw'!E21 -> 0 | AL48: =+'QTR Raw'!F21 -> 0 | AM48: =+'QTR Raw'!G21 -> 0 | AN48: =+'QTR Raw'!H21 -> 0 | AO48: =+'QTR Raw'!I21 -> 0 | AP48: =+'QTR Raw'!J21 -> 0 | ... CL48: =+'QTR Raw'!BF21 -> 0 | DF48: 82.5
...

Sheet QTR Raw
A1: ='Annual Raw'!A1 -> 320028 | B1: X | C1: 201206 | D1: 201209 | E1: 201212 | F1: 201303 | G1: 201306 | H1: 201309 | I1: 201312 | J1: 201403 | K1: 201406 | L1: 201409 | M1: 201412 | N1: 201503 | O1: 201506 | P1: 201509 | Q1: 201512 | R1: 201603 | S1: 201606 | T1: 201609 | U1: 201612 | V1: 201703 | W1: 201706 | X1: 201709 | Y1: 201712 | Z1: 201803 | AA1: 201806 | AB1: 201809 | AC1: 201812 | AD1: 201903 | AE1: 201906 | AF1: 201909 | AG1: 201912 | AH1: 202003 | AI1: 202006 | AJ1: 202009 | AK1: 202012 | AL1: 202103 | AM1: 202106 | AN1: 202109 | AO1: 202112 | AP1: 202203 | AQ1: 202206 | AR1: 202209 | AS1: 202212 | AT1: 202303 | AU1: 202306 | AV1: 202309 | AW1: 202312 | AX1: 202403 | AY1: 202406 | AZ1: 202409 | BA1: 202412 | BB1: 202503 | BC1: 202506 | BD1: 202509 | BE1: 202512 | BF1: 202603 | BG1: 202606 | BH1: 202609 | BI1: 202612 | BJ1: 202703 | BK1: 202706 | BL1: 202709 | BM1: 202712 | BN1: 202803 | BO1: 202806 | BP1: 202809 | BQ1: 202812 | BR1: 202903 | BS1: 202906 | BT1: 202909 | BU1: 202912 | BV1: 203003
A3: Field Description | B3: Field Name
A4: Company Name | B4: CD_COMPNAME | C4: =_xll.EQNXTDZ(A1,B4,C1) -> Siemens Energy India Ltd.
A5: Date End | B5: QTR_DATE_END | C5: =_xll.EQNXTDZ($A$1,$B5,C$1,$B$1) -> 0 | D5: =_xll.EQNXTDZ($A$1,$B5,D$1,$B$1) -> 0 | E5: =_xll.EQNXTDZ($A$1,$B5,E$1,$B$1) -> 0 | F5: =_xll.EQNXTDZ($A$1,$B5,F$1,$B$1) -> 0 | G5: =_xll.EQNXTDZ($A$1,$B5,G$1,$B$1) -> 0 | H5: =_xll.EQNXTDZ($A$1,$B5,H$1,$B$1) -> 0 | I5: =_xll.EQNXTDZ($A$1,$B5,I$1,$B$1) -> 0 | J5: =_xll.EQNXTDZ($A$1,$B5,J$1,$B$1) -> 0 | ... BV5: =_xll.EQNXTDZ($A$1,$B5,BV$1,$B$1) -> 0
A6: Gross Sales | B6: QTR_GROSS_SALE | C6: =_xll.EQNXTDZ($A$1,$B6,C$1,$B$1) -> 0 | D6: =_xll.EQNXTDZ($A$1,$B6,D$1,$B$1) -> 0 | E6: =_xll.EQNXTDZ($A$1,$B6,E$1,$B$1) -> 0 | F6: =_xll.EQNXTDZ($A$1,$B6,F$1,$B$1) -> 0 | G6: =_xll.EQNXTDZ($A$1,$B6,G$1,$B$1) -> 0 | H6: =_xll.EQNXTDZ($A$1,$B6,H$1,$B$1) -> 0 | I6: =_xll.EQNXTDZ($A$1,$B6,I$1,$B$1) -> 0 | J6: =_xll.EQNXTDZ($A$1,$B6,J$1,$B$1) -> 0 | ... BV6: =_xll.EQNXTDZ($A$1,$B6,BV$1,$B$1) -> 0
A7: Less: Excise Duty | B7: QTR_EXCISE_DUTY | C7: =_xll.EQNXTDZ($A$1,$B7,C$1,$B$1) -> 0 | D7: =_xll.EQNXTDZ($A$1,$B7,D$1,$B$1) -> 0 | E7: =_xll.EQNXTDZ($A$1,$B7,E$1,$B$1) -> 0 | F7: =_xll.EQNXTDZ($A$1,$B7,F$1,$B$1) -> 0 | G7: =_xll.EQNXTDZ($A$1,$B7,G$1,$B$1) -> 0 | H7: =_xll.EQNXTDZ($A$1,$B7,H$1,$B$1) -> 0 | I7: =_xll.EQNXTDZ($A$1,$B7,I$1,$B$1) -> 0 | J7: =_xll.EQNXTDZ($A$1,$B7,J$1,$B$1) -> 0 | ... BV7: =_xll.EQNXTDZ($A$1,$B7,BV$1,$B$1) -> 0
A8: Other operating income | B8: QTR_JOB_WORKS | C8: =_xll.EQNXTDZ($A$1,$B8,C$1,$B$1) -> 0 | D8: =_xll.EQNXTDZ($A$1,$B8,D$1,$B$1) -> 0 | E8: =_xll.EQNXTDZ($A$1,$B8,E$1,$B$1) -> 0 | F8: =_xll.EQNXTDZ($A$1,$B8,F$1,$B$1) -> 0 | G8: =_xll.EQNXTDZ($A$1,$B8,G$1,$B$1) -> 0 | H8: =_xll.EQNXTDZ($A$1,$B8,H$1,$B$1) -> 0 | I8: =_xll.EQNXTDZ($A$1,$B8,I$1,$B$1) -> 0 | J8: =_xll.EQNXTDZ($A$1,$B8,J$1,$B$1) -> 0 | ... BV8: =_xll.EQNXTDZ($A$1,$B8,BV$1,$B$1) -> 0
A9: Net Sales & Other Operating Income | B9: QTR_NET_SALES | C9: =_xll.EQNXTDZ($A$1,$B9,C$1,$B$1) -> 0 | D9: =_xll.EQNXTDZ($A$1,$B9,D$1,$B$1) -> 0 | E9: =_xll.EQNXTDZ($A$1,$B9,E$1,$B$1) -> 0 | F9: =_xll.EQNXTDZ($A$1,$B9,F$1,$B$1) -> 0 | G9: =_xll.EQNXTDZ($A$1,$B9,G$1,$B$1) -> 0 | H9: =_xll.EQNXTDZ($A$1,$B9,H$1,$B$1) -> 0 | I9: =_xll.EQNXTDZ($A$1,$B9,I$1,$B$1) -> 0 | J9: =_xll.EQNXTDZ($A$1,$B9,J$1,$B$1) -> 0 | ... BV9: =_xll.EQNXTDZ($A$1,$B9,BV$1,$B$1) -> 0
A10: (Increase) / Decrease In Stocks | B10: QTR_INC_DEC_INVENTORY | C10: =_xll.EQNXTDZ($A$1,$B10,C$1,$B$1) -> 0 | D10: =_xll.EQNXTDZ($A$1,$B10,D$1,$B$1) -> 0 | E10: =_xll.EQNXTDZ($A$1,$B10,E$1,$B$1) -> 0 | F10: =_xll.EQNXTDZ($A$1,$B10,F$1,$B$1) -> 0 | G10: =_xll.EQNXTDZ($A$1,$B10,G$1,$B$1) -> 0 | H10: =_xll.EQNXTDZ($A$1,$B10,H$1,$B$1) -> 0 | I10: =_xll.EQNXTDZ($A$1,$B10,I$1,$B$1) -> 0 | J10: =_xll.EQNXTDZ($A$1,$B10,J$1,$B$1) -> 0 | ... BV10: =_xll.EQNXTDZ($A$1,$B10,BV$1,$B$1) -> 0
A11: Cost of Services & Raw Materials | B11: QTR_RAW_MATERIAL_COST | C11: =_xll.EQNXTDZ($A$1,$B11,C$1,$B$1) -> 0 | D11: =_xll.EQNXTDZ($A$1,$B11,D$1,$B$1) -> 0 | E11: =_xll.EQNXTDZ($A$1,$B11,E$1,$B$1) -> 0 | F11: =_xll.EQNXTDZ($A$1,$B11,F$1,$B$1) -> 0 | G11: =_xll.EQNXTDZ($A$1,$B11,G$1,$B$1) -> 0 | H11: =_xll.EQNXTDZ($A$1,$B11,H$1,$B$1) -> 0 | I11: =_xll.EQNXTDZ($A$1,$B11,I$1,$B$1) -> 0 | J11: =_xll.EQNXTDZ($A$1,$B11,J$1,$B$1) -> 0 | ... BV11: =_xll.EQNXTDZ($A$1,$B11,BV$1,$B$1) -> 0
A12: Purchase of Finished Goods | B12: QTR_PURCHASE_FIN_GOOD | C12: =_xll.EQNXTDZ($A$1,$B12,C$1,$B$1) -> 0 | D12: =_xll.EQNXTDZ($A$1,$B12,D$1,$B$1) -> 0 | E12: =_xll.EQNXTDZ($A$1,$B12,E$1,$B$1) -> 0 | F12: =_xll.EQNXTDZ($A$1,$B12,F$1,$B$1) -> 0 | G12: =_xll.EQNXTDZ($A$1,$B12,G$1,$B$1) -> 0 | H12: =_xll.EQNXTDZ($A$1,$B12,H$1,$B$1) -> 0 | I12: =_xll.EQNXTDZ($A$1,$B12,I$1,$B$1) -> 0 | J12: =_xll.EQNXTDZ($A$1,$B12,J$1,$B$1) -> 0 | ... BV12: =_xll.EQNXTDZ($A$1,$B12,BV$1,$B$1) -> 0
A13: Excise Duty | B13: QTR_EXCISE | C13: =_xll.EQNXTDZ($A$1,$B13,C$1,$B$1) -> 0 | D13: =_xll.EQNXTDZ($A$1,$B13,D$1,$B$1) -> 0 | E13: =_xll.EQNXTDZ($A$1,$B13,E$1,$B$1) -> 0 | F13: =_xll.EQNXTDZ($A$1,$B13,F$1,$B$1) -> 0 | G13: =_xll.EQNXTDZ($A$1,$B13,G$1,$B$1) -> 0 | H13: =_xll.EQNXTDZ($A$1,$B13,H$1,$B$1) -> 0 | I13: =_xll.EQNXTDZ($A$1,$B13,I$1,$B$1) -> 0 | J13: =_xll.EQNXTDZ($A$1,$B13,J$1,$B$1) -> 0 | ... BV13: =_xll.EQNXTDZ($A$1,$B13,BV$1,$B$1) -> 0
A14: Operating & Manufacturing Expenses | B14: QTR_MFG_EXPS | C14: =_xll.EQNXTDZ($A$1,$B14,C$1,$B$1) -> 0 | D14: =_xll.EQNXTDZ($A$1,$B14,D$1,$B$1) -> 0 | E14: =_xll.EQNXTDZ($A$1,$B14,E$1,$B$1) -> 0 | F14: =_xll.EQNXTDZ($A$1,$B14,F$1,$B$1) -> 0 | G14: =_xll.EQNXTDZ($A$1,$B14,G$1,$B$1) -> 0 | H14: =_xll.EQNXTDZ($A$1,$B14,H$1,$B$1) -> 0 | I14: =_xll.EQNXTDZ($A$1,$B14,I$1,$B$1) -> 0 | J14: =_xll.EQNXTDZ($A$1,$B14,J$1,$B$1) -> 0 | ... BV14: =_xll.EQNXTDZ($A$1,$B14,BV$1,$B$1) -> 0
A15: Electricity Power & Fuel Cost | B15: QTR_ELECTRICITY_POWER_FUEL | C15: =_xll.EQNXTDZ($A$1,$B15,C$1,$B$1) -> 0 | D15: =_xll.EQNXTDZ($A$1,$B15,D$1,$B$1) -> 0 | E15: =_xll.EQNXTDZ($A$1,$B15,E$1,$B$1) -> 0 | F15: =_xll.EQNXTDZ($A$1,$B15,F$1,$B$1) -> 0 | G15: =_xll.EQNXTDZ($A$1,$B15,G$1,$B$1) -> 0 | H15: =_xll.EQNXTDZ($A$1,$B15,H$1,$B$1) -> 0 | I15: =_xll.EQNXTDZ($A$1,$B15,I$1,$B$1) -> 0 | J15: =_xll.EQNXTDZ($A$1,$B15,J$1,$B$1) -> 0 | ... BV15: =_xll.EQNXTDZ($A$1,$B15,BV$1,$B$1) -> 0
A16: Employee Cost | B16: QTR_EXPLOYEE_COST | C16: =_xll.EQNXTDZ($A$1,$B16,C$1,$B$1) -> 0 | D16: =_xll.EQNXTDZ($A$1,$B16,D$1,$B$1) -> 0 | E16: =_xll.EQNXTDZ($A$1,$B16,E$1,$B$1) -> 0 | F16: =_xll.EQNXTDZ($A$1,$B16,F$1,$B$1) -> 0 | G16: =_xll.EQNXTDZ($A$1,$B16,G$1,$B$1) -> 0 | H16: =_xll.EQNXTDZ($A$1,$B16,H$1,$B$1) -> 0 | I16: =_xll.EQNXTDZ($A$1,$B16,I$1,$B$1) -> 0 | J16: =_xll.EQNXTDZ($A$1,$B16,J$1,$B$1) -> 0 | ... BV16: =_xll.EQNXTDZ($A$1,$B16,BV$1,$B$1) -> 0
... A42: Consolidated PAT(after extra items) | B42: QTR_CONS_PAT_EXITM | C42: =_xll.EQNXTDZ($A$1,$B42,C$1,$B$1) -> 0 | D42: =_xll.EQNXTDZ($A$1,$B42,D$1,$B$1) -> 0 | E42: =_xll.EQNXTDZ($A$1,$B42,E$1,$B$1) -> 0 | F42: =_xll.EQNXTDZ($A$1,$B42,F$1,$B$1) -> 0 | G42: =_xll.EQNXTDZ($A$1,$B42,G$1,$B$1) -> 0 | H42: =_xll.EQNXTDZ($A$1,$B42,H$1,$B$1) -> 0 | I42: =_xll.EQNXTDZ($A$1,$B42,I$1,$B$1) -> 0 | J42: =_xll.EQNXTDZ($A$1,$B42,J$1,$B$1) -> 0 | ... BV42: =_xll.EQNXTDZ($A$1,$B42,BV$1,$B$1) -> 0
A44: Field Description | B44: Field Name
A45: Equity Capital | B45: QTR_EQUITY_CAP | C45: =_xll.EQNXTDZ($A$1,$B45,C$1,$B$1) -> 0 | D45: =_xll.EQNXTDZ($A$1,$B45,D$1,$B$1) -> 0 | E45: =_xll.EQNXTDZ($A$1,$B45,E$1,$B$1) -> 0 | F45: =_xll.EQNXTDZ($A$1,$B45,F$1,$B$1) -> 0 | G45: =_xll.EQNXTDZ($A$1,$B45,G$1,$B$1) -> 0 | H45: =_xll.EQNXTDZ($A$1,$B45,H$1,$B$1) -> 0 | I45: =_xll.EQNXTDZ($A$1,$B45,I$1,$B$1) -> 0 | J45: =_xll.EQNXTDZ($A$1,$B45,J$1,$B$1) -> 0 | ... BV45: =_xll.EQNXTDZ($A$1,$B45,BV$1,$B$1) -> 0
A46: Face Value | B46: QTR_FV | C46: =_xll.EQNXTDZ($A$1,$B46,C$1,$B$1) -> 0 | D46: =_xll.EQNXTDZ($A$1,$B46,D$1,$B$1) -> 0 | E46: =_xll.EQNXTDZ($A$1,$B46,E$1,$B$1) -> 0 | F46: =_xll.EQNXTDZ($A$1,$B46,F$1,$B$1) -> 0 | G46: =_xll.EQNXTDZ($A$1,$B46,G$1,$B$1) -> 0 | H46: =_xll.EQNXTDZ($A$1,$B46,H$1,$B$1) -> 0 | I46: =_xll.EQNXTDZ($A$1,$B46,I$1,$B$1) -> 0 | J46: =_xll.EQNXTDZ($A$1,$B46,J$1,$B$1) -> 0 | ... BV46: =_xll.EQNXTDZ($A$1,$B46,BV$1,$B$1) -> 0
A47: Month End | B47: BMONTH_MONTHEND | C47: =_xll.EQNXTDZ($A$1,$B47,C$5) -> 0 | D47: =_xll.EQNXTDZ($A$1,$B47,D$5) -> 0 | E47: =_xll.EQNXTDZ($A$1,$B47,E$5) -> 0 | F47: =_xll.EQNXTDZ($A$1,$B47,F$5) -> 0 | G47: =_xll.EQNXTDZ($A$1,$B47,G$5) -> 0 | H47: =_xll.EQNXTDZ($A$1,$B47,H$5) -> 0 | I47: =_xll.EQNXTDZ($A$1,$B47,I$5) -> 0 | J47: =_xll.EQNXTDZ($A$1,$B47,J$5) -> 0 | ... BV47: =_xll.EQNXTDZ($A$1,$B47,BV$5) -> 0
A48: Close | B48: BMONTH_CLOSE | C48: =_xll.EQNXTDZ($A$1,$B48,C$5) -> 0 | D48: =_xll.EQNXTDZ($A$1,$B48,D$5) -> 0 | E48: =_xll.EQNXTDZ($A$1,$B48,E$5) -> 0 | F48: =_xll.EQNXTDZ($A$1,$B48,F$5) -> 0 | G48: =_xll.EQNXTDZ($A$1,$B48,G$5) -> 0 | H48: =_xll.EQNXTDZ($A$1,$B48,H$5) -> 0 | I48: =_xll.EQNXTDZ($A$1,$B48,I$5) -> 0 | J48: =_xll.EQNXTDZ($A$1,$B48,J$5) -> 0 | ... BV48: =_xll.EQNXTDZ($A$1,$B48,BV$5) -> 0
A49: Total of Promoter and Promoter Group | B49: SHP_TPFTOTALPROMOTER | C49: =_xll.EQNXTDZ($A$1,$B49,C$5) -> 0 | D49: =_xll.EQNXTDZ($A$1,$B49,D$5) -> 0 | E49: =_xll.EQNXTDZ($A$1,$B49,E$5) -> 0 | F49: =_xll.EQNXTDZ($A$1,$B49,F$5) -> 0 | G49: =_xll.EQNXTDZ($A$1,$B49,G$5) -> 0 | H49: =_xll.EQNXTDZ($A$1,$B49,H$5) -> 0 | I49: =_xll.EQNXTDZ($A$1,$B49,I$5) -> 0 | J49: =_xll.EQNXTDZ($A$1,$B49,J$5) -> 0 | ... BV49: =_xll.EQNXTDZ($A$1,$B49,BV$5) -> 0
A50: Total of Promoter and Promoter Group Pledged | B50: SHP_PSHFTOTALPROMOTER | C50: =_xll.EQNXTDZ($A$1,$B50,C$5) -> 0 | D50: =_xll.EQNXTDZ($A$1,$B50,D$5) -> 0 | E50: =_xll.EQNXTDZ($A$1,$B50,E$5) -> 0 | F50: =_xll.EQNXTDZ($A$1,$B50,F$5) -> 0 | G50: =_xll.EQNXTDZ($A$1,$B50,G$5) -> 0 | H50: =_xll.EQNXTDZ($A$1,$B50,H$5) -> 0 | I50: =_xll.EQNXTDZ($A$1,$B50,I$5) -> 0 | J50: =_xll.EQNXTDZ($A$1,$B50,J$5) -> 0 | ... BV50: =_xll.EQNXTDZ($A$1,$B50,BV$5) -> 0
A54: Field Description | B54: Field Name | C54: =_xll.EQNXTDZ($A$1,$B54,C$5) -> 0 | D54: =_xll.EQNXTDZ($A$1,$B54,D$5) -> 0 | E54: =_xll.EQNXTDZ($A$1,$B54,E$5) -> 0 | F54: =_xll.EQNXTDZ($A$1,$B54,F$5) -> 0 | G54: =_xll.EQNXTDZ($A$1,$B54,G$5) -> 0 | H54: =_xll.EQNXTDZ($A$1,$B54,H$5) -> 0 | I54: =_xll.EQNXTDZ($A$1,$B54,I$5) -> 0 | J54: =_xll.EQNXTDZ($A$1,$B54,J$5) -> 0 | ... BV54: =_xll.EQNXTDZ($A$1,$B54,BV$5) -> 0
A55: Year End | B55: QTRB_DATE_END | C55: =_xll.EQNXTDZ($A$1,$B55,C$5,$B$1) -> 0 | D55: =_xll.EQNXTDZ($A$1,$B55,D$5,$B$1) -> 0 | E55: =_xll.EQNXTDZ($A$1,$B55,E$5,$B$1) -> 0 | F55: =_xll.EQNXTDZ($A$1,$B55,F$5,$B$1) -> 0 | G55: =_xll.EQNXTDZ($A$1,$B55,G$5,$B$1) -> 0 | H55: =_xll.EQNXTDZ($A$1,$B55,H$5,$B$1) -> 0 | I55: =_xll.EQNXTDZ($A$1,$B55,I$5,$B$1) -> 0 | J55: =_xll.EQNXTDZ($A$1,$B55,J$5,$B$1) -> 0 | ... BV55: =_xll.EQNXTDZ($A$1,$B55,BV$5,$B$1) -> 0
A56: Share Capital | B56: QTRB_SHARE_CAPITAL | C56: =_xll.EQNXTDZ($A$1,$B56,C$5,$B$1) -> 0 | D56: =_xll.EQNXTDZ($A$1,$B56,D$5,$B$1) -> 0 | E56: =_xll.EQNXTDZ($A$1,$B56,E$5,$B$1) -> 0 | F56: =_xll.EQNXTDZ($A$1,$B56,F$5,$B$1) -> 0 | G56: =_xll.EQNXTDZ($A$1,$B56,G$5,$B$1) -> 0 | H56: =_xll.EQNXTDZ($A$1,$B56,H$5,$B$1) -> 0 | I56: =_xll.EQNXTDZ($A$1,$B56,I$5,$B$1) -> 0 | J56: =_xll.EQNXTDZ($A$1,$B56,J$5,$B$1) -> 0 | ... BV56: =_xll.EQNXTDZ($A$1,$B56,BV$5,$B$1) -> 0
A57: Share Warrants & outstandings | B57: QTRB_SHAREWARNDOUT | C57: =_xll.EQNXTDZ($A$1,$B57,C$5,$B$1) -> 0 | D57: =_xll.EQNXTDZ($A$1,$B57,D$5,$B$1) -> 0 | E57: =_xll.EQNXTDZ($A$1,$B57,E$5,$B$1) -> 0 | F57: =_xll.EQNXTDZ($A$1,$B57,F$5,$B$1) -> 0 | G57: =_xll.EQNXTDZ($A$1,$B57,G$5,$B$1) -> 0 | H57: =_xll.EQNXTDZ($A$1,$B57,H$5,$B$1) -> 0 | I57: =_xll.EQNXTDZ($A$1,$B57,I$5,$B$1) -> 0 | J57: =_xll.EQNXTDZ($A$1,$B57,J$5,$B$1) -> 0 | ... BV57: =_xll.EQNXTDZ($A$1,$B57,BV$5,$B$1) -> 0
A58: Reserves & Surplus | B58: QTRB_RESERVE | C58: =_xll.EQNXTDZ($A$1,$B58,C$5,$B$1) -> 0 | D58: =_xll.EQNXTDZ($A$1,$B58,D$5,$B$1) -> 0 | E58: =_xll.EQNXTDZ($A$1,$B58,E$5,$B$1) -> 0 | F58: =_xll.EQNXTDZ($A$1,$B58,F$5,$B$1) -> 0 | G58: =_xll.EQNXTDZ($A$1,$B58,G$5,$B$1) -> 0 | H58: =_xll.EQNXTDZ($A$1,$B58,H$5,$B$1) -> 0 | I58: =_xll.EQNXTDZ($A$1,$B58,I$5,$B$1) -> 0 | J58: =_xll.EQNXTDZ($A$1,$B58,J$5,$B$1) -> 0 | ... BV58: =_xll.EQNXTDZ($A$1,$B58,BV$5,$B$1) -> 0
A59: Shareholder's Funds | B59: QTRB_SHAREHODERS_FUNDS | C59: =_xll.EQNXTDZ($A$1,$B59,C$5,$B$1) -> 0 | D59: =_xll.EQNXTDZ($A$1,$B59,D$5,$B$1) -> 0 | E59: =_xll.EQNXTDZ($A$1,$B59,E$5,$B$1) -> 0 | F59: =_xll.EQNXTDZ($A$1,$B59,F$5,$B$1) -> 0 | G59: =_xll.EQNXTDZ($A$1,$B59,G$5,$B$1) -> 0 | H59: =_xll.EQNXTDZ($A$1,$B59,H$5,$B$1) -> 0 | I59: =_xll.EQNXTDZ($A$1,$B59,I$5,$B$1) -> 0 | J59: =_xll.EQNXTDZ($A$1,$B59,J$5,$B$1) -> 0 | ... BV59: =_xll.EQNXTDZ($A$1,$B59,BV$5,$B$1) -> 0
A60: Minority Interest | B60: QTRB_MINORITY_INTEREST_BS | C60: =_xll.EQNXTDZ($A$1,$B60,C$5,$B$1) -> 0 | D60: =_xll.EQNXTDZ($A$1,$B60,D$5,$B$1) -> 0 | E60: =_xll.EQNXTDZ($A$1,$B60,E$5,$B$1) -> 0 | F60: =_xll.EQNXTDZ($A$1,$B60,F$5,$B$1) -> 0 | G60: =_xll.EQNXTDZ($A$1,$B60,G$5,$B$1) -> 0 | H60: =_xll.EQNXTDZ($A$1,$B60,H$5,$B$1) -> 0 | I60: =_xll.EQNXTDZ($A$1,$B60,I$5,$B$1) -> 0 | J60: =_xll.EQNXTDZ($A$1,$B60,J$5,$B$1) -> 0 | ... BV60: =_xll.EQNXTDZ($A$1,$B60,BV$5,$B$1) -> 0
A61: Long Term Borrowings | B61: QTRB_TOTAL_DEBTS | C61: =_xll.EQNXTDZ($A$1,$B61,C$5,$B$1) -> 0 | D61: =_xll.EQNXTDZ($A$1,$B61,D$5,$B$1) -> 0 | E61: =_xll.EQNXTDZ($A$1,$B61,E$5,$B$1) -> 0 | F61: =_xll.EQNXTDZ($A$1,$B61,F$5,$B$1) -> 0 | G61: =_xll.EQNXTDZ($A$1,$B61,G$5,$B$1) -> 0 | H61: =_xll.EQNXTDZ($A$1,$B61,H$5,$B$1) -> 0 | I61: =_xll.EQNXTDZ($A$1,$B61,I$5,$B$1) -> 0 | J61: =_xll.EQNXTDZ($A$1,$B61,J$5,$B$1) -> 0 | ... BV61: =_xll.EQNXTDZ($A$1,$B61,BV$5,$B$1) -> 0
A62: Secured Loans | B62: QTRB_SECURED_LOANS | C62: =_xll.EQNXTDZ($A$1,$B62,C$5,$B$1) -> 0 | D62: =_xll.EQNXTDZ($A$1,$B62,D$5,$B$1) -> 0 | E62: =_xll.EQNXTDZ($A$1,$B62,E$5,$B$1) -> 0 | F62: =_xll.EQNXTDZ($A$1,$B62,F$5,$B$1) -> 0 | G62: =_xll.EQNXTDZ($A$1,$B62,G$5,$B$1) -> 0 | H62: =_xll.EQNXTDZ($A$1,$B62,H$5,$B$1) -> 0 | I62: =_xll.EQNXTDZ($A$1,$B62,I$5,$B$1) -> 0 | J62: =_xll.EQNXTDZ($A$1,$B62,J$5,$B$1) -> 0 | ... BV62: =_xll.EQNXTDZ($A$1,$B62,BV$5,$B$1) -> 0
A63: Unsecured Loans | B63: QTRB_UNSECURED_LOANS_NF | C63: =_xll.EQNXTDZ($A$1,$B63,C$5,$B$1) -> 0 | D63: =_xll.EQNXTDZ($A$1,$B63,D$5,$B$1) -> 0 | E63: =_xll.EQNXTDZ($A$1,$B63,E$5,$B$1) -> 0 | F63: =_xll.EQNXTDZ($A$1,$B63,F$5,$B$1) -> 0 | G63: =_xll.EQNXTDZ($A$1,$B63,G$5,$B$1) -> 0 | H63: =_xll.EQNXTDZ($A$1,$B63,H$5,$B$1) -> 0 | I63: =_xll.EQNXTDZ($A$1,$B63,I$5,$B$1) -> 0 | J63: =_xll.EQNXTDZ($A$1,$B63,J$5,$B$1) -> 0 | ... BV63: =_xll.EQNXTDZ($A$1,$B63,BV$5,$B$1) -> 0
A64: Other Long Term Liabilities | B64: QTRB_OTHER_LT_LIABILITIES | C64: =_xll.EQNXTDZ($A$1,$B64,C$5,$B$1) -> 0 | D64: =_xll.EQNXTDZ($A$1,$B64,D$5,$B$1) -> 0 | E64: =_xll.EQNXTDZ($A$1,$B64,E$5,$B$1) -> 0 | F64: =_xll.EQNXTDZ($A$1,$B64,F$5,$B$1) -> 0 | G64: =_xll.EQNXTDZ($A$1,$B64,G$5,$B$1) -> 0 | H64: =_xll.EQNXTDZ($A$1,$B64,H$5,$B$1) -> 0 | I64: =_xll.EQNXTDZ($A$1,$B64,I$5,$B$1) -> 0 | J64: =_xll.EQNXTDZ($A$1,$B64,J$5,$B$1) -> 0 | ... BV64: =_xll.EQNXTDZ($A$1,$B64,BV$5,$B$1) -> 0
A65: Long Term Trade Payables | B65: QTRB_LT_TRADE_PAYABLE | C65: =_xll.EQNXTDZ($A$1,$B65,C$5,$B$1) -> 0 | D65: =_xll.EQNXTDZ($A$1,$B65,D$5,$B$1) -> 0 | E65: =_xll.EQNXTDZ($A$1,$B65,E$5,$B$1) -> 0 | F65: =_xll.EQNXTDZ($A$1,$B65,F$5,$B$1) -> 0 | G65: =_xll.EQNXTDZ($A$1,$B65,G$5,$B$1) -> 0 | H65: =_xll.EQNXTDZ($A$1,$B65,H$5,$B$1) -> 0 | I65: =_xll.EQNXTDZ($A$1,$B65,I$5,$B$1) -> 0 | J65: =_xll.EQNXTDZ($A$1,$B65,J$5,$B$1) -> 0 | ... BV65: =_xll.EQNXTDZ($A$1,$B65,BV$5,$B$1) -> 0
A66: Lont Term Provisions | B66: QTRB_LT_PROVISIONS | C66: =_xll.EQNXTDZ($A$1,$B66,C$5,$B$1) -> 0 | D66: =_xll.EQNXTDZ($A$1,$B66,D$5,$B$1) -> 0 | E66: =_xll.EQNXTDZ($A$1,$B66,E$5,$B$1) -> 0 | F66: =_xll.EQNXTDZ($A$1,$B66,F$5,$B$1) -> 0 | G66: =_xll.EQNXTDZ($A$1,$B66,G$5,$B$1) -> 0 | H66: =_xll.EQNXTDZ($A$1,$B66,H$5,$B$1) -> 0 | I66: =_xll.EQNXTDZ($A$1,$B66,I$5,$B$1) -> 0 | J66: =_xll.EQNXTDZ($A$1,$B66,J$5,$B$1) -> 0 | ... BV66: =_xll.EQNXTDZ($A$1,$B66,BV$5,$B$1) -> 0
... A97: Total Assets | B97: QTRB_TOTAL_APPLICATIONS | C97: =_xll.EQNXTDZ($A$1,$B97,C$5,$B$1) -> 0 | D97: =_xll.EQNXTDZ($A$1,$B97,D$5,$B$1) -> 0 | E97: =_xll.EQNXTDZ($A$1,$B97,E$5,$B$1) -> 0 | F97: =_xll.EQNXTDZ($A$1,$B97,F$5,$B$1) -> 0 | G97: =_xll.EQNXTDZ($A$1,$B97,G$5,$B$1) -> 0 | H97: =_xll.EQNXTDZ($A$1,$B97,H$5,$B$1) -> 0 | I97: =_xll.EQNXTDZ($A$1,$B97,I$5,$B$1) -> 0 | J97: =_xll.EQNXTDZ($A$1,$B97,J$5,$B$1) -> 0 | ... BV97: =_xll.EQNXTDZ($A$1,$B97,BV$5,$B$1) -> 0

Sheet Annual Raw
A1: 320028 | B1: X | C1: 200109 | D1: 200209 | E1: 200909 | F1: 200409 | G1: 200509 | H1: 200609 | I1: 200709 | J1: 200809 | K1: 200909 | L1: 201009 | M1: 201109 | N1: 201209 | O1: 201309 | P1: 201409 | Q1: 201509 | R1: 201609 | S1: 201709 | T1: 201809 | U1: 201909 | V1: 202009 | W1: 202109 | X1: 202209 | Y1: 202309 | Z1: 202409 | AA1: 202509 | AB1: 202609 | AC1: 202709 | AD1: 202809 | AE1: 202909 | AF1: 209009
A3: Field Description | B3: Field Name
A4: Company Name | B4: CD_COMPNAME | C4: =_xll.EQNXTDZ(A1,B4,"L") -> Siemens Energy India Ltd.
A5: Year End | B5: PL_YEAR_END | C5: =_xll.EQNXTDZ($A$1,$B5,C$1,$B$1) -> 0 | D5: =_xll.EQNXTDZ($A$1,$B5,D$1,$B$1) -> 0 | E5: =_xll.EQNXTDZ($A$1,$B5,E$1,$B$1) -> 0 | F5: =_xll.EQNXTDZ($A$1,$B5,F$1,$B$1) -> 0 | G5: =_xll.EQNXTDZ($A$1,$B5,G$1,$B$1) -> 0 | H5: =_xll.EQNXTDZ($A$1,$B5,H$1,$B$1) -> 0 | I5: =_xll.EQNXTDZ($A$1,$B5,I$1,$B$1) -> 0 | J5: =_xll.EQNXTDZ($A$1,$B5,J$1,$B$1) -> 0 | ... AF5: =_xll.EQNXTDZ($A$1,$B5,AF$1,$B$1) -> 0
A6: Sales Turnover | B6: PL_TOTAL_GROSS_SALES | C6: =_xll.EQNXTDZ($A$1,$B6,C$1,$B$1) -> 0 | D6: =_xll.EQNXTDZ($A$1,$B6,D$1,$B$1) -> 0 | E6: =_xll.EQNXTDZ($A$1,$B6,E$1,$B$1) -> 0 | F6: =_xll.EQNXTDZ($A$1,$B6,F$1,$B$1) -> 0 | G6: =_xll.EQNXTDZ($A$1,$B6,G$1,$B$1) -> 0 | H6: =_xll.EQNXTDZ($A$1,$B6,H$1,$B$1) -> 0 | I6: =_xll.EQNXTDZ($A$1,$B6,I$1,$B$1) -> 0 | J6: =_xll.EQNXTDZ($A$1,$B6,J$1,$B$1) -> 0 | ... AF6: =_xll.EQNXTDZ($A$1,$B6,AF$1,$B$1) -> 0
A7: Less: Inter divisional transfers | B7: PL_INTER_DIV_TRF | C7: =_xll.EQNXTDZ($A$1,$B7,C$1,$B$1) -> 0 | D7: =_xll.EQNXTDZ($A$1,$B7,D$1,$B$1) -> 0 | E7: =_xll.EQNXTDZ($A$1,$B7,E$1,$B$1) -> 0 | F7: =_xll.EQNXTDZ($A$1,$B7,F$1,$B$1) -> 0 | G7: =_xll.EQNXTDZ($A$1,$B7,G$1,$B$1) -> 0 | H7: =_xll.EQNXTDZ($A$1,$B7,H$1,$B$1) -> 0 | I7: =_xll.EQNXTDZ($A$1,$B7,I$1,$B$1) -> 0 | J7: =_xll.EQNXTDZ($A$1,$B7,J$1,$B$1) -> 0 | ... AF7: =_xll.EQNXTDZ($A$1,$B7,AF$1,$B$1) -> 0
A8: Less: Sales Returns | B8: PL_SALES_RETURN | C8: =_xll.EQNXTDZ($A$1,$B8,C$1,$B$1) -> 0 | D8: =_xll.EQNXTDZ($A$1,$B8,D$1,$B$1) -> 0 | E8: =_xll.EQNXTDZ($A$1,$B8,E$1,$B$1) -> 0 | F8: =_xll.EQNXTDZ($A$1,$B8,F$1,$B$1) -> 0 | G8: =_xll.EQNXTDZ($A$1,$B8,G$1,$B$1) -> 0 | H8: =_xll.EQNXTDZ($A$1,$B8,H$1,$B$1) -> 0 | I8: =_xll.EQNXTDZ($A$1,$B8,I$1,$B$1) -> 0 | J8: =_xll.EQNXTDZ($A$1,$B8,J$1,$B$1) -> 0 | ... AF8: =_xll.EQNXTDZ($A$1,$B8,AF$1,$B$1) -> 0
A9: Less: Excise | B9: PL_EXCISE | C9: =_xll.EQNXTDZ($A$1,$B9,C$1,$B$1) -> 0 | D9: =_xll.EQNXTDZ($A$1,$B9,D$1,$B$1) -> 0 | E9: =_xll.EQNXTDZ($A$1,$B9,E$1,$B$1) -> 0 | F9: =_xll.EQNXTDZ($A$1,$B9,F$1,$B$1) -> 0 | G9: =_xll.EQNXTDZ($A$1,$B9,G$1,$B$1) -> 0 | H9: =_xll.EQNXTDZ($A$1,$B9,H$1,$B$1) -> 0 | I9: =_xll.EQNXTDZ($A$1,$B9,I$1,$B$1) -> 0 | J9: =_xll.EQNXTDZ($A$1,$B9,J$1,$B$1) -> 0 | ... AF9: =_xll.EQNXTDZ($A$1,$B9,AF$1,$B$1) -> 0
A10: Net Sales | B10: PL_NET_SALES | C10: =_xll.EQNXTDZ($A$1,$B10,C$1,$B$1) -> 0 | D10: =_xll.EQNXTDZ($A$1,$B10,D$1,$B$1) -> 0 | E10: =_xll.EQNXTDZ($A$1,$B10,E$1,$B$1) -> 0 | F10: =_xll.EQNXTDZ($A$1,$B10,F$1,$B$1) -> 0 | G10: =_xll.EQNXTDZ($A$1,$B10,G$1,$B$1) -> 0 | H10: =_xll.EQNXTDZ($A$1,$B10,H$1,$B$1) -> 0 | I10: =_xll.EQNXTDZ($A$1,$B10,I$1,$B$1) -> 0 | J10: =_xll.EQNXTDZ($A$1,$B10,J$1,$B$1) -> 0 | ... AF10: =_xll.EQNXTDZ($A$1,$B10,AF$1,$B$1) -> 0
A11: Increase/Decrease in Stock | B11: PL_INC_DEC_INVENTORY | C11: =_xll.EQNXTDZ($A$1,$B11,C$1,$B$1) -> 0 | D11: =_xll.EQNXTDZ($A$1,$B11,D$1,$B$1) -> 0 | E11: =_xll.EQNXTDZ($A$1,$B11,E$1,$B$1) -> 0 | F11: =_xll.EQNXTDZ($A$1,$B11,F$1,$B$1) -> 0 | G11: =_xll.EQNXTDZ($A$1,$B11,G$1,$B$1) -> 0 | H11: =_xll.EQNXTDZ($A$1,$B11,H$1,$B$1) -> 0 | I11: =_xll.EQNXTDZ($A$1,$B11,I$1,$B$1) -> 0 | J11: =_xll.EQNXTDZ($A$1,$B11,J$1,$B$1) -> 0 | ... AF11: =_xll.EQNXTDZ($A$1,$B11,AF$1,$B$1) -> 0
A12: Raw Material Consumed | B12: PL_RAW_MATRS_CONSUMED | C12: =_xll.EQNXTDZ($A$1,$B12,C$1,$B$1) -> 0 | D12: =_xll.EQNXTDZ($A$1,$B12,D$1,$B$1) -> 0 | E12: =_xll.EQNXTDZ($A$1,$B12,E$1,$B$1) -> 0 | F12: =_xll.EQNXTDZ($A$1,$B12,F$1,$B$1) -> 0 | G12: =_xll.EQNXTDZ($A$1,$B12,G$1,$B$1) -> 0 | H12: =_xll.EQNXTDZ($A$1,$B12,H$1,$B$1) -> 0 | I12: =_xll.EQNXTDZ($A$1,$B12,I$1,$B$1) -> 0 | J12: =_xll.EQNXTDZ($A$1,$B12,J$1,$B$1) -> 0 | ... AF12: =_xll.EQNXTDZ($A$1,$B12,AF$1,$B$1) -> 0
A13: Power & Fuel Cost | B13: PL_POWER_FUEL | C13: =_xll.EQNXTDZ($A$1,$B13,C$1,$B$1) -> 0 | D13: =_xll.EQNXTDZ($A$1,$B13,D$1,$B$1) -> 0 | E13: =_xll.EQNXTDZ($A$1,$B13,E$1,$B$1) -> 0 | F13: =_xll.EQNXTDZ($A$1,$B13,F$1,$B$1) -> 0 | G13: =_xll.EQNXTDZ($A$1,$B13,G$1,$B$1) -> 0 | H13: =_xll.EQNXTDZ($A$1,$B13,H$1,$B$1) -> 0 | I13: =_xll.EQNXTDZ($A$1,$B13,I$1,$B$1) -> 0 | J13: =_xll.EQNXTDZ($A$1,$B13,J$1,$B$1) -> 0 | ... AF13: =_xll.EQNXTDZ($A$1,$B13,AF$1,$B$1) -> 0
A14: Employee Cost | B14: PL_EMPLOYEES | C14: =_xll.EQNXTDZ($A$1,$B14,C$1,$B$1) -> 0 | D14: =_xll.EQNXTDZ($A$1,$B14,D$1,$B$1) -> 0 | E14: =_xll.EQNXTDZ($A$1,$B14,E$1,$B$1) -> 0 | F14: =_xll.EQNXTDZ($A$1,$B14,F$1,$B$1) -> 0 | G14: =_xll.EQNXTDZ($A$1,$B14,G$1,$B$1) -> 0 | H14: =_xll.EQNXTDZ($A$1,$B14,H$1,$B$1) -> 0 | I14: =_xll.EQNXTDZ($A$1,$B14,I$1,$B$1) -> 0 | J14: =_xll.EQNXTDZ($A$1,$B14,J$1,$B$1) -> 0 | ... AF14: =_xll.EQNXTDZ($A$1,$B14,AF$1,$B$1) -> 0
A15: Operating & Manufacturing Expenses | B15: PL_GEN_OTHER_MFG_EXPS | C15: =_xll.EQNXTDZ($A$1,$B15,C$1,$B$1) -> 0 | D15: =_xll.EQNXTDZ($A$1,$B15,D$1,$B$1) -> 0 | E15: =_xll.EQNXTDZ($A$1,$B15,E$1,$B$1) -> 0 | F15: =_xll.EQNXTDZ($A$1,$B15,F$1,$B$1) -> 0 | G15: =_xll.EQNXTDZ($A$1,$B15,G$1,$B$1) -> 0 | H15: =_xll.EQNXTDZ($A$1,$B15,H$1,$B$1) -> 0 | I15: =_xll.EQNXTDZ($A$1,$B15,I$1,$B$1) -> 0 | J15: =_xll.EQNXTDZ($A$1,$B15,J$1,$B$1) -> 0 | ... AF15: =_xll.EQNXTDZ($A$1,$B15,AF$1,$B$1) -> 0
A16: Cost of Software development | B16: PL_COST_SW | C16: =_xll.EQNXTDZ($A$1,$B16,C$1,$B$1) -> 0 | D16: =_xll.EQNXTDZ($A$1,$B16,D$1,$B$1) -> 0 | E16: =_xll.EQNXTDZ($A$1,$B16,E$1,$B$1) -> 0 | F16: =_xll.EQNXTDZ($A$1,$B16,F$1,$B$1) -> 0 | G16: =_xll.EQNXTDZ($A$1,$B16,G$1,$B$1) -> 0 | H16: =_xll.EQNXTDZ($A$1,$B16,H$1,$B$1) -> 0 | I16: =_xll.EQNXTDZ($A$1,$B16,I$1,$B$1) -> 0 | J16: =_xll.EQNXTDZ($A$1,$B16,J$1,$B$1) -> 0 | ... AF16: =_xll.EQNXTDZ($A$1,$B16,AF$1,$B$1) -> 0
... A36: Profit After Tax from Discontinued Operations | B36: PL_PAT_DIS_OP | C36: =_xll.EQNXTDZ($A$1,$B36,C$1,$B$1) -> 0 | D36: =_xll.EQNXTDZ($A$1,$B36,D$1,$B$1) -> 0 | E36: =_xll.EQNXTDZ($A$1,$B36,E$1,$B$1) -> 0 | F36: =_xll.EQNXTDZ($A$1,$B36,F$1,$B$1) -> 0 | G36: =_xll.EQNXTDZ($A$1,$B36,G$1,$B$1) -> 0 | H36: =_xll.EQNXTDZ($A$1,$B36,H$1,$B$1) -> 0 | I36: =_xll.EQNXTDZ($A$1,$B36,I$1,$B$1) -> 0 | J36: =_xll.EQNXTDZ($A$1,$B36,J$1,$B$1) -> 0 | ... AF36: =_xll.EQNXTDZ($A$1,$B36,AF$1,$B$1) -> 0
A39: Field Description | B39: Field Name
A40: Year End | B40: BS_YEAR_END | C40: =_xll.EQNXTDZ($A$1,$B40,C$1,$B$1) -> 0 | D40: =_xll.EQNXTDZ($A$1,$B40,D$1,$B$1) -> 0 | E40: =_xll.EQNXTDZ($A$1,$B40,E$1,$B$1) -> 0 | F40: =_xll.EQNXTDZ($A$1,$B40,F$1,$B$1) -> 0 | G40: =_xll.EQNXTDZ($A$1,$B40,G$1,$B$1) -> 0 | H40: =_xll.EQNXTDZ($A$1,$B40,H$1,$B$1) -> 0 | I40: =_xll.EQNXTDZ($A$1,$B40,I$1,$B$1) -> 0 | J40: =_xll.EQNXTDZ($A$1,$B40,J$1,$B$1) -> 0 | ... AF40: =_xll.EQNXTDZ($A$1,$B40,AF$1,$B$1) -> 0
A41: Share Capital | B41: BS_SHARE_CAPITAL | C41: =_xll.EQNXTDZ($A$1,$B41,C$1,$B$1) -> 0 | D41: =_xll.EQNXTDZ($A$1,$B41,D$1,$B$1) -> 0 | E41: =_xll.EQNXTDZ($A$1,$B41,E$1,$B$1) -> 0 | F41: =_xll.EQNXTDZ($A$1,$B41,F$1,$B$1) -> 0 | G41: =_xll.EQNXTDZ($A$1,$B41,G$1,$B$1) -> 0 | H41: =_xll.EQNXTDZ($A$1,$B41,H$1,$B$1) -> 0 | I41: =_xll.EQNXTDZ($A$1,$B41,I$1,$B$1) -> 0 | J41: =_xll.EQNXTDZ($A$1,$B41,J$1,$B$1) -> 0 | ... AF41: =_xll.EQNXTDZ($A$1,$B41,AF$1,$B$1) -> 0
A42: Share Warrants & Outstandings | B42: BS_SHAREWROUTST | C42: =_xll.EQNXTDZ($A$1,$B42,C$1,$B$1) -> 0 | D42: =_xll.EQNXTDZ($A$1,$B42,D$1,$B$1) -> 0 | E42: =_xll.EQNXTDZ($A$1,$B42,E$1,$B$1) -> 0 | F42: =_xll.EQNXTDZ($A$1,$B42,F$1,$B$1) -> 0 | G42: =_xll.EQNXTDZ($A$1,$B42,G$1,$B$1) -> 0 | H42: =_xll.EQNXTDZ($A$1,$B42,H$1,$B$1) -> 0 | I42: =_xll.EQNXTDZ($A$1,$B42,I$1,$B$1) -> 0 | J42: =_xll.EQNXTDZ($A$1,$B42,J$1,$B$1) -> 0 | ... AF42: =_xll.EQNXTDZ($A$1,$B42,AF$1,$B$1) -> 0
A43: Total Reserves | B43: BS_RESERVE | C43: =_xll.EQNXTDZ($A$1,$B43,C$1,$B$1) -> 0 | D43: =_xll.EQNXTDZ($A$1,$B43,D$1,$B$1) -> 0 | E43: =_xll.EQNXTDZ($A$1,$B43,E$1,$B$1) -> 0 | F43: =_xll.EQNXTDZ($A$1,$B43,F$1,$B$1) -> 0 | G43: =_xll.EQNXTDZ($A$1,$B43,G$1,$B$1) -> 0 | H43: =_xll.EQNXTDZ($A$1,$B43,H$1,$B$1) -> 0 | I43: =_xll.EQNXTDZ($A$1,$B43,I$1,$B$1) -> 0 | J43: =_xll.EQNXTDZ($A$1,$B43,J$1,$B$1) -> 0 | ... AF43: =_xll.EQNXTDZ($A$1,$B43,AF$1,$B$1) -> 0
A44: Shareholder's Funds | B44: BS_SHAREHODERS_FUNDS | C44: =_xll.EQNXTDZ($A$1,$B44,C$1,$B$1) -> 0 | D44: =_xll.EQNXTDZ($A$1,$B44,D$1,$B$1) -> 0 | E44: =_xll.EQNXTDZ($A$1,$B44,E$1,$B$1) -> 0 | F44: =_xll.EQNXTDZ($A$1,$B44,F$1,$B$1) -> 0 | G44: =_xll.EQNXTDZ($A$1,$B44,G$1,$B$1) -> 0 | H44: =_xll.EQNXTDZ($A$1,$B44,H$1,$B$1) -> 0 | I44: =_xll.EQNXTDZ($A$1,$B44,I$1,$B$1) -> 0 | J44: =_xll.EQNXTDZ($A$1,$B44,J$1,$B$1) -> 0 | ... AF44: =_xll.EQNXTDZ($A$1,$B44,AF$1,$B$1) -> 0
A45: Minority Interest | B45: BS_MINORITY_INTEREST | C45: =_xll.EQNXTDZ($A$1,$B45,C$1,$B$1) -> 0 | D45: =_xll.EQNXTDZ($A$1,$B45,D$1,$B$1) -> 0 | E45: =_xll.EQNXTDZ($A$1,$B45,E$1,$B$1) -> 0 | F45: =_xll.EQNXTDZ($A$1,$B45,F$1,$B$1) -> 0 | G45: =_xll.EQNXTDZ($A$1,$B45,G$1,$B$1) -> 0 | H45: =_xll.EQNXTDZ($A$1,$B45,H$1,$B$1) -> 0 | I45: =_xll.EQNXTDZ($A$1,$B45,I$1,$B$1) -> 0 | J45: =_xll.EQNXTDZ($A$1,$B45,J$1,$B$1) -> 0 | ... AF45: =_xll.EQNXTDZ($A$1,$B45,AF$1,$B$1) -> 0
A46: Long-Term Borrowings | B46: BS_LTRM_BORROWING | C46: =_xll.EQNXTDZ($A$1,$B46,C$1,$B$1) -> 0 | D46: =_xll.EQNXTDZ($A$1,$B46,D$1,$B$1) -> 0 | E46: =_xll.EQNXTDZ($A$1,$B46,E$1,$B$1) -> 0 | F46: =_xll.EQNXTDZ($A$1,$B46,F$1,$B$1) -> 0 | G46: =_xll.EQNXTDZ($A$1,$B46,G$1,$B$1) -> 0 | H46: =_xll.EQNXTDZ($A$1,$B46,H$1,$B$1) -> 0 | I46: =_xll.EQNXTDZ($A$1,$B46,I$1,$B$1) -> 0 | J46: =_xll.EQNXTDZ($A$1,$B46,J$1,$B$1) -> 0 | ... AF46: =_xll.EQNXTDZ($A$1,$B46,AF$1,$B$1) -> 0
A47: Secured Loans | B47: BS_SECURED_LOANS | C47: =_xll.EQNXTDZ($A$1,$B47,C$1,$B$1) -> 0 | D47: =_xll.EQNXTDZ($A$1,$B47,D$1,$B$1) -> 0 | E47: =_xll.EQNXTDZ($A$1,$B47,E$1,$B$1) -> 0 | F47: =_xll.EQNXTDZ($A$1,$B47,F$1,$B$1) -> 0 | G47: =_xll.EQNXTDZ($A$1,$B47,G$1,$B$1) -> 0 | H47: =_xll.EQNXTDZ($A$1,$B47,H$1,$B$1) -> 0 | I47: =_xll.EQNXTDZ($A$1,$B47,I$1,$B$1) -> 0 | J47: =_xll.EQNXTDZ($A$1,$B47,J$1,$B$1) -> 0 | ... AF47: =_xll.EQNXTDZ($A$1,$B47,AF$1,$B$1) -> 0
A48: Unsecured Loans | B48: BS_UNSECURED_LOANS_NF | C48: =_xll.EQNXTDZ($A$1,$B48,C$1,$B$1) -> 0 | D48: =_xll.EQNXTDZ($A$1,$B48,D$1,$B$1) -> 0 | E48: =_xll.EQNXTDZ($A$1,$B48,E$1,$B$1) -> 0 | F48: =_xll.EQNXTDZ($A$1,$B48,F$1,$B$1) -> 0 | G48: =_xll.EQNXTDZ($A$1,$B48,G$1,$B$1) -> 0 | H48: =_xll.EQNXTDZ($A$1,$B48,H$1,$B$1) -> 0 | I48: =_xll.EQNXTDZ($A$1,$B48,I$1,$B$1) -> 0 | J48: =_xll.EQNXTDZ($A$1,$B48,J$1,$B$1) -> 0 | ... AF48: =_xll.EQNXTDZ($A$1,$B48,AF$1,$B$1) -> 0
A49: Deferred Tax Assets / Liabilities | B49: BS_NET_DEF_TAX_NF | C49: =_xll.EQNXTDZ($A$1,$B49,C$1,$B$1) -> 0 | D49: =_xll.EQNXTDZ($A$1,$B49,D$1,$B$1) -> 0 | E49: =_xll.EQNXTDZ($A$1,$B49,E$1,$B$1) -> 0 | F49: =_xll.EQNXTDZ($A$1,$B49,F$1,$B$1) -> 0 | G49: =_xll.EQNXTDZ($A$1,$B49,G$1,$B$1) -> 0 | H49: =_xll.EQNXTDZ($A$1,$B49,H$1,$B$1) -> 0 | I49: =_xll.EQNXTDZ($A$1,$B49,I$1,$B$1) -> 0 | J49: =_xll.EQNXTDZ($A$1,$B49,J$1,$B$1) -> 0 | ... AF49: =_xll.EQNXTDZ($A$1,$B49,AF$1,$B$1) -> 0
A50: Other Long Term Liabilities | B50: BS_OTH_LT_LIAB | C50: =_xll.EQNXTDZ($A$1,$B50,C$1,$B$1) -> 0 | D50: =_xll.EQNXTDZ($A$1,$B50,D$1,$B$1) -> 0 | E50: =_xll.EQNXTDZ($A$1,$B50,E$1,$B$1) -> 0 | F50: =_xll.EQNXTDZ($A$1,$B50,F$1,$B$1) -> 0 | G50: =_xll.EQNXTDZ($A$1,$B50,G$1,$B$1) -> 0 | H50: =_xll.EQNXTDZ($A$1,$B50,H$1,$B$1) -> 0 | I50: =_xll.EQNXTDZ($A$1,$B50,I$1,$B$1) -> 0 | J50: =_xll.EQNXTDZ($A$1,$B50,J$1,$B$1) -> 0 | ... AF50: =_xll.EQNXTDZ($A$1,$B50,AF$1,$B$1) -> 0
A51: Long Term Trade Payables | B51: BS_LT_TRADE_PAYABLES | C51: =_xll.EQNXTDZ($A$1,$B51,C$1,$B$1) -> 0 | D51: =_xll.EQNXTDZ($A$1,$B51,D$1,$B$1) -> 0 | E51: =_xll.EQNXTDZ($A$1,$B51,E$1,$B$1) -> 0 | F51: =_xll.EQNXTDZ($A$1,$B51,F$1,$B$1) -> 0 | G51: =_xll.EQNXTDZ($A$1,$B51,G$1,$B$1) -> 0 | H51: =_xll.EQNXTDZ($A$1,$B51,H$1,$B$1) -> 0 | I51: =_xll.EQNXTDZ($A$1,$B51,I$1,$B$1) -> 0 | J51: =_xll.EQNXTDZ($A$1,$B51,J$1,$B$1) -> 0 | ... AF51: =_xll.EQNXTDZ($A$1,$B51,AF$1,$B$1) -> 0
... A99: Estimated Capital Contracts Remaining | B99: BS_ESTIMATED_CAPITAL_CONTRACT | C99: =_xll.EQNXTDZ($A$1,$B99,C$1,$B$1) -> 0 | D99: =_xll.EQNXTDZ($A$1,$B99,D$1,$B$1) -> 0 | E99: =_xll.EQNXTDZ($A$1,$B99,E$1,$B$1) -> 0 | F99: =_xll.EQNXTDZ($A$1,$B99,F$1,$B$1) -> 0 | G99: =_xll.EQNXTDZ($A$1,$B99,G$1,$B$1) -> 0 | H99: =_xll.EQNXTDZ($A$1,$B99,H$1,$B$1) -> 0 | I99: =_xll.EQNXTDZ($A$1,$B99,I$1,$B$1) -> 0 | J99: =_xll.EQNXTDZ($A$1,$B99,J$1,$B$1) -> 0 | ... AF99: =_xll.EQNXTDZ($A$1,$B99,AF$1,$B$1) -> 0
A103: Field Description | B103: Field Name
A104: Equity Paid Up | B104: BS_EQUITY_PAIDUP | C104: =_xll.EQNXTDZ($A$1,$B104,C$1,$B$1) -> 0 | D104: =_xll.EQNXTDZ($A$1,$B104,D$1,$B$1) -> 0 | E104: =_xll.EQNXTDZ($A$1,$B104,E$1,$B$1) -> 0 | F104: =_xll.EQNXTDZ($A$1,$B104,F$1,$B$1) -> 0 | G104: =_xll.EQNXTDZ($A$1,$B104,G$1,$B$1) -> 0 | H104: =_xll.EQNXTDZ($A$1,$B104,H$1,$B$1) -> 0 | I104: =_xll.EQNXTDZ($A$1,$B104,I$1,$B$1) -> 0 | J104: =_xll.EQNXTDZ($A$1,$B104,J$1,$B$1) -> 0 | ... AF104: =_xll.EQNXTDZ($A$1,$B104,AF$1,$B$1) -> 0
A105: Face Value | B105: BS_FACE_VALUE | C105: =_xll.EQNXTDZ($A$1,$B105,C$1,$B$1) -> 0 | D105: =_xll.EQNXTDZ($A$1,$B105,D$1,$B$1) -> 0 | E105: =_xll.EQNXTDZ($A$1,$B105,E$1,$B$1) -> 0 | F105: =_xll.EQNXTDZ($A$1,$B105,F$1,$B$1) -> 0 | G105: =_xll.EQNXTDZ($A$1,$B105,G$1,$B$1) -> 0 | H105: =_xll.EQNXTDZ($A$1,$B105,H$1,$B$1) -> 0 | I105: =_xll.EQNXTDZ($A$1,$B105,I$1,$B$1) -> 0 | J105: =_xll.EQNXTDZ($A$1,$B105,J$1,$B$1) -> 0 | ... AF105: =_xll.EQNXTDZ($A$1,$B105,AF$1,$B$1) -> 0
A106: Close Price (Unit Curr.) | B106: FH_YEAR_PRICE | C106: =_xll.EQNXTDZ($A$1,$B106,C$1,$B$1) -> 0 | D106: =_xll.EQNXTDZ($A$1,$B106,D$1,$B$1) -> 0 | E106: =_xll.EQNXTDZ($A$1,$B106,E$1,$B$1) -> 0 | F106: =_xll.EQNXTDZ($A$1,$B106,F$1,$B$1) -> 0 | G106: =_xll.EQNXTDZ($A$1,$B106,G$1,$B$1) -> 0 | H106: =_xll.EQNXTDZ($A$1,$B106,H$1,$B$1) -> 0 | I106: =_xll.EQNXTDZ($A$1,$B106,I$1,$B$1) -> 0 | J106: =_xll.EQNXTDZ($A$1,$B106,J$1,$B$1) -> 0 | ... AF106: =_xll.EQNXTDZ($A$1,$B106,AF$1,$B$1) -> 0
A107: High Price (Unit Curr.) | B107: FH_HIGH | C107: =_xll.EQNXTDZ($A$1,$B107,C$1,$B$1) -> 0 | D107: =_xll.EQNXTDZ($A$1,$B107,D$1,$B$1) -> 0 | E107: =_xll.EQNXTDZ($A$1,$B107,E$1,$B$1) -> 0 | F107: =_xll.EQNXTDZ($A$1,$B107,F$1,$B$1) -> 0 | G107: =_xll.EQNXTDZ($A$1,$B107,G$1,$B$1) -> 0 | H107: =_xll.EQNXTDZ($A$1,$B107,H$1,$B$1) -> 0 | I107: =_xll.EQNXTDZ($A$1,$B107,I$1,$B$1) -> 0 | J107: =_xll.EQNXTDZ($A$1,$B107,J$1,$B$1) -> 0 | ... AF107: =_xll.EQNXTDZ($A$1,$B107,AF$1,$B$1) -> 0
A108: Low Price (Unit Curr.) | B108: FH_LOW | C108: =_xll.EQNXTDZ($A$1,$B108,C$1,$B$1) -> 0 | D108: =_xll.EQNXTDZ($A$1,$B108,D$1,$B$1) -> 0 | E108: =_xll.EQNXTDZ($A$1,$B108,E$1,$B$1) -> 0 | F108: =_xll.EQNXTDZ($A$1,$B108,F$1,$B$1) -> 0 | G108: =_xll.EQNXTDZ($A$1,$B108,G$1,$B$1) -> 0 | H108: =_xll.EQNXTDZ($A$1,$B108,H$1,$B$1) -> 0 | I108: =_xll.EQNXTDZ($A$1,$B108,I$1,$B$1) -> 0 | J108: =_xll.EQNXTDZ($A$1,$B108,J$1,$B$1) -> 0 | ... AF108: =_xll.EQNXTDZ($A$1,$B108,AF$1,$B$1) -> 0
A109: Market Capitalization | B109: FH_MCAP | C109: =_xll.EQNXTDZ($A$1,$B109,C$1,$B$1) -> 0 | D109: =_xll.EQNXTDZ($A$1,$B109,D$1,$B$1) -> 0 | E109: =_xll.EQNXTDZ($A$1,$B109,E$1,$B$1) -> 0 | F109: =_xll.EQNXTDZ($A$1,$B109,F$1,$B$1) -> 0 | G109: =_xll.EQNXTDZ($A$1,$B109,G$1,$B$1) -> 0 | H109: =_xll.EQNXTDZ($A$1,$B109,H$1,$B$1) -> 0 | I109: =_xll.EQNXTDZ($A$1,$B109,I$1,$B$1) -> 0 | J109: =_xll.EQNXTDZ($A$1,$B109,J$1,$B$1) -> 0 | ... AF109: =_xll.EQNXTDZ($A$1,$B109,AF$1,$B$1) -> 0
A110: Adj DPS(Rs) | B110: FR_ADJ_DPS | C110: =_xll.EQNXTDZ($A$1,$B110,C$1,$B$1) -> 0 | D110: =_xll.EQNXTDZ($A$1,$B110,D$1,$B$1) -> 0 | E110: =_xll.EQNXTDZ($A$1,$B110,E$1,$B$1) -> 0 | F110: =_xll.EQNXTDZ($A$1,$B110,F$1,$B$1) -> 0 | G110: =_xll.EQNXTDZ($A$1,$B110,G$1,$B$1) -> 0 | H110: =_xll.EQNXTDZ($A$1,$B110,H$1,$B$1) -> 0 | I110: =_xll.EQNXTDZ($A$1,$B110,I$1,$B$1) -> 0 | J110: =_xll.EQNXTDZ($A$1,$B110,J$1,$B$1) -> 0 | ... AF110: =_xll.EQNXTDZ($A$1,$B110,AF$1,$B$1) -> 0
A111: Date End | B111: SHP_DATE_END | C111: =_xll.EQNXTDZ($A$1,$B111,C$5) -> 0 | D111: =_xll.EQNXTDZ($A$1,$B111,D$5) -> 0 | E111: =_xll.EQNXTDZ($A$1,$B111,E$5) -> 0 | F111: =_xll.EQNXTDZ($A$1,$B111,F$5) -> 0 | G111: =_xll.EQNXTDZ($A$1,$B111,G$5) -> 0 | H111: =_xll.EQNXTDZ($A$1,$B111,H$5) -> 0 | I111: =_xll.EQNXTDZ($A$1,$B111,I$5) -> 0 | J111: =_xll.EQNXTDZ($A$1,$B111,J$5) -> 0 | ... AF111: =_xll.EQNXTDZ($A$1,$B111,AF$5) -> 0
A112: Total of Promoter and Promoter Group | B112: SHP_TPFTOTALPROMOTER | C112: =_xll.EQNXTDZ($A$1,$B112,C$5) -> 0 | D112: =_xll.EQNXTDZ($A$1,$B112,D$5) -> 0 | E112: =_xll.EQNXTDZ($A$1,$B112,E$5) -> 0 | F112: =_xll.EQNXTDZ($A$1,$B112,F$5) -> 0 | G112: =_xll.EQNXTDZ($A$1,$B112,G$5) -> 0 | H112: =_xll.EQNXTDZ($A$1,$B112,H$5) -> 0 | I112: =_xll.EQNXTDZ($A$1,$B112,I$5) -> 0 | J112: =_xll.EQNXTDZ($A$1,$B112,J$5) -> 0 | ... AF112: =_xll.EQNXTDZ($A$1,$B112,AF$5) -> 0
...

Sheet QTR Share Price
