Workbook

Sheet Template
A1: =+'Annual Raw'!C4 -> Tata Motors Ltd. | B1: 36951 | C1: =EOMONTH(B1,12) -> 37346 | D1: =EOMONTH(C1,12) -> 37711 | E1: =EOMONTH(D1,12) -> 38077 | F1: =EOMONTH(E1,12) -> 38442 | G1: =EOMONTH(F1,12) -> 38807 | H1: =EOMONTH(G1,12) -> 39172 | I1: =EOMONTH(H1,12) -> 39538 | J1: =EOMONTH(I1,12) -> 39903 | ... AE1: =EOMONTH(AD1,12) -> 47573 | AH1: QTR | AI1: 41061 | AJ1: 41153 | AK1: 41244 | AL1: 41334 | AM1: 41426 | AN1: 41518 | AO1: 41609 | AP1: 41699 | AQ1: 41791 | AR1: 41883 | AS1: 41974 | AT1: 42064 | AU1: 42156 | AV1: 42248 | AW1: 42339 | AX1: 42430 | AY1: 42522 | AZ1: 42614 | BA1: 42705 | BB1: 42795 | BC1: 42887 | BD1: 42979 | BE1: 43070 | BF1: 43160 | BG1: 43252 | BH1: 43344 | BI1: 43435 | BJ1: 43525 | BK1: 43617 | BL1: 43709 | BM1: 43800 | BN1: 43891 | BO1: 43983 | BP1: 44075 | BQ1: =EOMONTH(BP1,3) -> 44196 | BR1: =EOMONTH(BQ1,3) -> 44286 | BS1: =EOMONTH(BR1,3) -> 44377 | BT1: =EOMONTH(BS1,3) -> 44469 | BU1: =EOMONTH(BT1,3) -> 44561 | BV1: =EOMONTH(BU1,3) -> 44651 | BW1: =EOMONTH(BV1,3) -> 44742 | BX1: =EOMONTH(BW1,3) -> 44834 | ... DB1: =EOMONTH(DA1,3) -> 47573 | DE1: HISTORICAL ESTIMATES | DF1: 46112
A2: Presentation Data (Start)
A4: Vahan Data | X4: =+SUM(BW4:BZ4) -> 382995 | Y4: =+SUM(CA4:CD4) -> 369972 | Z4: =+SUM(CE4:CH4) -> 350232 | BW4: =+'Monthly Nos Vahan'!$E$21 -> 97144 | BX4: =+'Monthly Nos Vahan'!$E$24 -> 90110 | BY4: =+'Monthly Nos Vahan'!$E$27 -> 90519 | BZ4: =+'Monthly Nos Vahan'!$E$30 -> 105222 | CA4: =+'Monthly Nos Vahan'!$E$33 -> 89546 | CB4: =+'Monthly Nos Vahan'!$E$36 -> 88114 | CC4: =+'Monthly Nos Vahan'!$E$39 -> 92136 | CD4: =+'Monthly Nos Vahan'!$E$42 -> 100176 | CE4: =+'Monthly Nos Vahan'!$E$45 -> 91641 | CF4: =+'Monthly Nos Vahan'!$E$48 -> 81058 | CG4: =+'Monthly Nos Vahan'!$E$51 -> 85315 | CH4: =+'Monthly Nos Vahan'!$E$54 -> 92218 | CI4: =+'Monthly Nos Vahan'!$E$57 -> 85244 | CJ4: =+'Monthly Nos Vahan'!$E$60 -> 77120 | CK4: ='Monthly Nos Vahan'!E63 -> 99958 | CL4: ='Monthly Nos Vahan'!E66 -> 112511
A5: Volume YoY% | Y5: =+Y4/X4-1 -> -0.034003055 | Z5: =+Z4/Y4-1 -> -0.053355389 | CA5: =+CA4/BW4-1 -> -0.078213786 | CB5: =+CB4/BX4-1 -> -0.022150705 | CC5: =+CC4/BY4-1 -> 0.017863653 | CD5: =+CD4/BZ4-1 -> -0.047955751 | CE5: =+CE4/CA4-1 -> 0.023395797 | CF5: =+CF4/CB4-1 -> -0.080078081 | CG5: =+CG4/CC4-1 -> -0.074031866 | CH5: =+CH4/CD4-1 -> -0.079440185 | ... CL5: =+CL4/CH4-1 -> 0.22005465
A7: Co. reported Volume TTM | N7: =N12 -> 580711 | O7: =O12 -> 420181 | P7: =P12 -> 364573 | Q7: =Q12 -> 378798 | R7: =R12 -> 385029 | S7: =S12 -> 449281 | T7: =T12 -> 519777 | U7: =U12 -> 339953 | ... Z7: =Z12 -> 376903 | AL7: =SUM(AI12:AL12) -> 580711 | AM7: =SUM(AJ12:AM12) -> 570574 | AN7: =SUM(AK12:AN12) -> 536663 | AO7: =SUM(AL12:AO12) -> 483154 | AP7: =SUM(AM12:AP12) -> 420181 | AQ7: =SUM(AN12:AQ12) -> 388189 | AR7: =SUM(AO12:AR12) -> 366855 | AS7: =SUM(AP12:AS12) -> 361344 | ... CL7: =SUM(CI12:CL12) -> 427306
A8: Vahan Volume TTM | N8: =N4 -> 0 | O8: =O4 -> 0 | P8: =P4 -> 0 | Q8: =Q4 -> 0 | R8: =R4 -> 0 | S8: =S4 -> 0 | T8: =T4 -> 0 | U8: =U4 -> 0 | ... Z8: =Z4 -> 350232 | BZ8: =SUM(BW4:BZ4) -> 382995 | CA8: =SUM(BX4:CA4) -> 375397 | CB8: =SUM(BY4:CB4) -> 373401 | CC8: =SUM(BZ4:CC4) -> 375018 | CD8: =SUM(CA4:CD4) -> 369972 | CE8: =SUM(CB4:CE4) -> 372067 | CF8: =SUM(CC4:CF4) -> 365011 | CG8: =SUM(CD4:CG4) -> 358190 | ... CL8: =SUM(CI4:CL4) -> 374833
A9: Co. reported Volume TTM Growth YoY | O9: =O7/N7-1 -> -0.27643699 | P9: =P7/O7-1 -> -0.13234297 | Q9: =Q7/P7-1 -> 0.039018249 | R9: =R7/Q7-1 -> 0.0164494 | S9: =S7/R7-1 -> 0.16687574 | T9: =T7/S7-1 -> 0.15690848 | U9: =U7/T7-1 -> -0.34596375 | V9: =V7/U7-1 -> -0.20032181 | ... Z9: =Z7/Y7-1 -> -0.047852063 | AP9: =AP7/AL7-1 -> -0.27643699 | AQ9: =AQ7/AM7-1 -> -0.31965179 | AR9: =AR7/AN7-1 -> -0.31641458 | AS9: =AS7/AO7-1 -> -0.25211423 | AT9: =AT7/AP7-1 -> -0.13234297 | AU9: =AU7/AQ7-1 -> -0.063481964 | AV9: =AV7/AR7-1 -> -0.014948685 | AW9: =AW7/AS7-1 -> -0.00095200142 | ... CL9: =CL7/CH7-1 -> 0.13372937
A10: Vahan Volume TTM Growth YoY | Y10: =Y8/X8-1 -> -0.034003055 | Z10: =Z8/Y8-1 -> -0.053355389 | CD10: =CD8/BZ8-1 -> -0.034003055 | CE10: =CE8/CA8-1 -> -0.008870609 | CF10: =CF8/CB8-1 -> -0.022469142 | CG10: =CG8/CC8-1 -> -0.044872513 | CH10: =CH8/CD8-1 -> -0.053355389 | CI10: =CI8/CE8-1 -> -0.075878807 | CJ10: =CJ8/CF8-1 -> -0.068803406 | CK10: =CK8/CG8-1 -> -0.010190123 | CL10: =CL8/CH8-1 -> 0.070242011
A12: Monthly Volume | N12: =+SUM(AI12:AL12) -> 580711 | O12: =+SUM(AM12:AP12) -> 420181 | P12: =+SUM(AQ12:AT12) -> 364573 | Q12: =+SUM(AU12:AX12) -> 378798 | R12: =+SUM(AY12:BB12) -> 385029 | S12: =+SUM(BC12:BF12) -> 449281 | T12: =+SUM(BG12:BJ12) -> 519777 | U12: =+SUM(BK12:BN12) -> 339953 | V12: =+SUM(BO12:BR12) -> 271853 | W12: =+SUM(BS12:BV12) -> 356972 | X12: =+SUM(BW12:BZ12) -> 413539 | Y12: =+SUM(CA12:CD12) -> 395845 | Z12: =+SUM(CE12:CH12) -> 376903 | AA12: =SUM(CI12:CL12) -> 427306 | AB12: =+SUM(CM12:CP12) -> 477140.16 | AC12: =+SUM(CQ12:CT12) -> 532952.23 | AD12: =+SUM(CU12:CX12) -> 595479.24 | AE12: =+SUM(CY12:DB12) -> 665551.41 | AI12: =+'Monthly Nos Company'!$K$6 -> 126634 | AJ12: =+'Monthly Nos Company'!$K$9 -> 148667 | AK12: =+'Monthly Nos Company'!$K$12 -> 148965 | AL12: =+'Monthly Nos Company'!$K$15 -> 156445 | AM12: =+'Monthly Nos Company'!$K$18 -> 116497 | AN12: =+'Monthly Nos Company'!$K$21 -> 114756 | AO12: =+'Monthly Nos Company'!$K$24 -> 95456 | AP12: =+'Monthly Nos Company'!$K$27 -> 93472 | AQ12: =+'Monthly Nos Company'!$K$30 -> 84505 | AR12: =+'Monthly Nos Company'!$K$33 -> 93422 | AS12: =+'Monthly Nos Company'!$K$36 -> 89945 | AT12: =+'Monthly Nos Company'!$K$39 -> 96701 | AU12: =+'Monthly Nos Company'!$K$42 -> 83478 | AV12: =+'Monthly Nos Company'!$K$45 -> 91247 | AW12: =+'Monthly Nos Company'!$K$48 -> 89574 | AX12: =+'Monthly Nos Company'!$K$51 -> 114499 | AY12: =+'Monthly Nos Company'!$K$54 -> 91444 | AZ12: =+'Monthly Nos Company'!$K$57 -> 92180 | BA12: =+'Monthly Nos Company'!$K$60 -> 91693 | BB12: =+'Monthly Nos Company'!$K$63 -> 109712 | BC12: =+'Monthly Nos Company'!$K$66 -> 74520 | BD12: =+'Monthly Nos Company'!$K$69 -> 106091 | BE12: =+'Monthly Nos Company'!$K$72 -> 123091 | BF12: =+'Monthly Nos Company'!$K$75 -> 145579 | BG12: =+'Monthly Nos Company'!$K$78 -> 123215 | BH12: =+'Monthly Nos Company'!$K$81 -> 136184 | BI12: =+'Monthly Nos Company'!$K$84 -> 121785 | BJ12: =+'Monthly Nos Company'!$K$87 -> 138593 | BK12: =+'Monthly Nos Company'!$K$90 -> 99610 | BL12: =+'Monthly Nos Company'!$K$93 -> 78602 | BM12: =+'Monthly Nos Company'!$K$96 -> 92672 | BN12: =+'Monthly Nos Company'!$K$99 -> 69069 | BO12: =+'Monthly Nos Company'!$K$102 -> 19666 | BP12: =+'Monthly Nos Company'!$K$105 -> 55487 | BQ12: =+'Monthly Nos Company'!$K$108 -> 89323 | BR12: =+'Monthly Nos Company'!$K$111 -> 107377 | BS12: =+'Monthly Nos Company'!$K$114 -> 50145 | BT12: =+'Monthly Nos Company'!$K$117 -> 86887 | BU12: =+'Monthly Nos Company'!$K$120 -> 100070 | BV12: =+'Monthly Nos Company'!$K$123 -> 119870 | BW12: =+'Monthly Nos Company'!$K$126 -> 100921 | BX12: =+'Monthly Nos Company'!$K$129 -> 100536 | BY12: =+'Monthly Nos Company'!$K$132 -> 95914 | BZ12: =+'Monthly Nos Company'!$K$135 -> 116168 | CA12: =+'Monthly Nos Company'!$K$138 -> 85795 | CB12: =+'Monthly Nos Company'!$K$141 -> 104085 | CC12: =+'Monthly Nos Company'!$K$144 -> 96526 | CD12: =+'Monthly Nos Company'!$K$147 -> 109439 | CE12: =+'Monthly Nos Company'!$K$150 -> 91209 | CF12: =+'Monthly Nos Company'!$K$153 -> 84281 | CG12: =+'Monthly Nos Company'!$K$156 -> 95770 | CH12: =+'Monthly Nos Company'!$K$159 -> 105643 | CI12: =+'Monthly Nos Company'!$K$162 -> 85606 | CJ12: =+'Monthly Nos Company'!$K$165 -> 94681 | CK12: =+'Monthly Nos Company'!$K$168 -> 114554 | CL12: =+'Monthly Nos Company'!$K$171 -> 132465 | CM12: =+'Monthly Nos Company'!$K$174 -> 95538 | CN12: =+'Monthly Nos Company'!$K$177 -> 105843.18 | CO12: =+'Monthly Nos Company'!$K$180 -> 128026.56 | CP12: =+'Monthly Nos Company'!$K$183 -> 147732.42 | CQ12: =+'Monthly Nos Company'!$K$186 -> 106655.2 | CR12: =+'Monthly Nos Company'!$K$189 -> 118358.75 | CS12: =+'Monthly Nos Company'!$K$192 -> 143128.78 | CT12: =+'Monthly Nos Company'!$K$195 -> 164809.51 | CU12: =+'Monthly Nos Company'!$K$198 -> 119102.99 | CV12: =+'Monthly Nos Company'!$K$201 -> 132396.25 | CW12: =+'Monthly Nos Company'!$K$204 -> 160063.16 | CX12: =+'Monthly Nos Company'!$K$207 -> 183916.85 | CY12: =+'Monthly Nos Company'!$K$210 -> 133045.08 | CZ12: =+'Monthly Nos Company'!$K$213 -> 148145.73 | DA12: =+'Monthly Nos Company'!$K$216 -> 179057.98 | DB12: =+'Monthly Nos Company'!$K$219 -> 205302.62
A13: Volume YoY% | O13: =+O12/N12-1 -> -0.27643699 | P13: =+P12/O12-1 -> -0.13234297 | Q13: =+Q12/P12-1 -> 0.039018249 | R13: =+R12/Q12-1 -> 0.0164494 | S13: =+S12/R12-1 -> 0.16687574 | T13: =+T12/S12-1 -> 0.15690848 | U13: =+U12/T12-1 -> -0.34596375 | V13: =+V12/U12-1 -> -0.20032181 | ... AE13: =+AE12/AD12-1 -> 0.11767356 | AM13: =+AM12/AI12-1 -> -0.080049592 | AN13: =+AN12/AJ12-1 -> -0.22810039 | AO13: =+AO12/AK12-1 -> -0.35920518 | AP13: =+AP12/AL12-1 -> -0.40252485 | AQ13: =+AQ12/AM12-1 -> -0.27461651 | AR13: =+AR12/AN12-1 -> -0.18590749 | AS13: =+AS12/AO12-1 -> -0.057733406 | AT13: =+AT12/AP12-1 -> 0.034545104 | ... DB13: =+DB12/CX12-1 -> 0.11627954
A15: Unit Matrix
A16: Realisation | N16: =+N32*10^7/N12 -> 823222.94 | O16: =+O32*10^7/O12 -> 865397.76 | P16: =+P32*10^7/P12 -> 1043984 | Q16: =+Q32*10^7/Q12 -> 1262029.6 | R16: =+R32*10^7/R12 -> 1289159.8 | S16: =+S32*10^7/S12 -> 1316443.2 | T16: =+T32*10^7/T12 -> 1339817.7 | U16: =+U32*10^7/U12 -> 1305197.5 | ... AE16: =+AE32*10^7/AE12 -> 1774090 | AI16: =+AI32*10^7/AI12 -> 835984.81 | AJ16: =+AJ32*10^7/AJ12 -> 839550.14 | AK16: =+AK32*10^7/AK12 -> 713596.48 | AL16: =+AL32*10^7/AL12 -> 707455.66 | AM16: =+AM32*10^7/AM12 -> 781522.27 | AN16: =+AN32*10^7/AN12 -> 772809.26 | AO16: =+AO32*10^7/AO12 -> 813953.03 | AP16: =+AP32*10^7/AP12 -> 914229.93 | ... CL16: =+CL32*10^7/CL12 -> 1865851.4 | CM16: =+AVERAGE(CI16:CL16) -> 1827462.8 | CN16: =+AVERAGE(CJ16:CM16) -> 1826358.3 | CO16: =+AVERAGE(CK16:CN16) -> 1830164.3 | CP16: =+AVERAGE(CL16:CO16) -> 1837459.2 | CQ16: =+AVERAGE(CM16:CP16)*0.98 -> 1793753.9 | CR16: =+AVERAGE(CN16:CQ16)*0.98 -> 1785495.2 | CS16: =+AVERAGE(CO16:CR16)*0.98 -> 1775483.8 | CT16: =+AVERAGE(CP16:CS16)*0.98 -> 1762087.1 | CU16: =+AVERAGE(CQ16:CT16) -> 1779205 | CV16: =+AVERAGE(CR16:CU16) -> 1775567.8 | CW16: =+AVERAGE(CS16:CV16) -> 1773085.9 | CX16: =+AVERAGE(CT16:CW16) -> 1772486.4 | CY16: =+AVERAGE(CU16:CX16) -> 1775086.3 | CZ16: =+AVERAGE(CV16:CY16) -> 1774056.6 | DA16: =+AVERAGE(CW16:CZ16) -> 1773678.8 | DB16: =+AVERAGE(CX16:DA16) -> 1773827 | DF16: 1834268.4
A17: RM | N17: =+N16-N18 -> 567668.43 | O17: =+O16-O18 -> 616743.97 | P17: =+P16-P18 -> 741734.85 | Q17: =+Q16-Q18 -> 768468.15 | R17: =+R16-R18 -> 814106.99 | S17: =+S16-S18 -> 950071.56 | T17: =+T16-T18 -> 973797.99 | U17: =+U16-U18 -> 958206.28 | ... AE17: =+AE16-AE18 -> 1217393.6 | AI17: =+AI16-AI18 -> 586951.37 | AJ17: =+AJ16-AJ18 -> 623870.8 | AK17: =+AK16-AK18 -> 537531.63 | AL17: =+AL16-AL18 -> 527347.63 | AM17: =+AM16-AM18 -> 567435.21 | AN17: =+AN16-AN18 -> 573697.24 | AO17: =+AO16-AO18 -> 624667.91 | AP17: =+AP16-AP18 -> 722955.54 | ... DB17: =+DB16-DB18 -> 1198966.3 | DF17: 1276624.2
A18: Delta | N18: =+N38*10^7/N12 -> 255554.52 | O18: =+O38*10^7/O12 -> 248653.79 | P18: =+P38*10^7/P12 -> 302249.17 | Q18: =+Q38*10^7/Q12 -> 493561.48 | R18: =+R38*10^7/R12 -> 475052.79 | S18: =+S38*10^7/S12 -> 366371.6 | T18: =+T38*10^7/T12 -> 366019.66 | U18: =+U38*10^7/U12 -> 346991.2 | ... AE18: =+AE38*10^7/AE12 -> 556696.37 | AI18: =+AI38*10^7/AI12 -> 249033.43 | AJ18: =+AJ38*10^7/AJ12 -> 215679.34 | AK18: =+AK38*10^7/AK12 -> 176064.85 | AL18: =+AL38*10^7/AL12 -> 180108.03 | AM18: =+AM38*10^7/AM12 -> 214087.06 | AN18: =+AN38*10^7/AN12 -> 199112.03 | AO18: =+AO38*10^7/AO12 -> 189285.12 | AP18: =+AP38*10^7/AP12 -> 191274.39 | ... CL18: =+CL38*10^7/CL12 -> 578718.91 | CM18: =+AVERAGE(CI18:CL18) -> 579845.43 | CN18: =+AVERAGE(CJ18:CM18) -> 574087.22 | CO18: =+AVERAGE(CK18:CN18) -> 571962.06 | CP18: =+AVERAGE(CL18:CO18) -> 576153.4 | CQ18: =+AVERAGE(CM18:CP18) -> 575512.03 | CR18: =+AVERAGE(CN18:CQ18) -> 574428.68 | CS18: =+AVERAGE(CO18:CR18) -> 574514.04 | CT18: =+AVERAGE(CP18:CS18) -> 575152.04 | ... DB18: =+AVERAGE(CX18:DA18) -> 574860.69 | DF18: 557644.24
A19: Delta Margin % | N19: =+N18/N16 -> 0.31043172 | O19: =+O18/O16 -> 0.2873289 | P19: =+P18/P16 -> 0.28951513 | Q19: =+Q18/Q16 -> 0.39108549 | R19: =+R18/R16 -> 0.36849799 | S19: =+S18/S16 -> 0.27830416 | T19: =+T18/T16 -> 0.27318617 | U19: =+U18/U16 -> 0.26585341 | ... AE19: =+AE18/AE16 -> 0.31379263 | AI19: =+AI18/AI16 -> 0.2978923 | AJ19: =+AJ18/AJ16 -> 0.2568987 | AK19: =+AK18/AK16 -> 0.24672886 | AL19: =+AL18/AL16 -> 0.2545856 | AM19: =+AM18/AM16 -> 0.27393597 | AN19: =+AN18/AN16 -> 0.25764705 | AO19: =+AO18/AO16 -> 0.23255042 | AP19: =+AP18/AP16 -> 0.20921913 | ... DB19: =+DB18/DB16 -> 0.32407934 | DF19: 0.30401452
A20: Employee Cost | N20: =+N45*10^7/N12 -> 48853.905 | O20: =+O45*10^7/O12 -> 68486.914 | P20: =+P45*10^7/P12 -> 84796.735 | Q20: =+Q45*10^7/Q12 -> 84186.559 | R20: =+R45*10^7/R12 -> 97767.96 | S20: =+S45*10^7/S12 -> 88290.624 | T20: =+T45*10^7/T12 -> 82210.256 | U20: =+U45*10^7/U12 -> 128968.12 | ... AE20: =+AE45*10^7/AE12 -> 91699.396 | AI20: =+AI45*10^7/AI12 -> 55819.132 | AJ20: =+AJ45*10^7/AJ12 -> 50393.833 | AK20: =+AK45*10^7/AK12 -> 49100.795 | AL20: =+AL45*10^7/AL12 -> 41517.466 | AM20: =+AM45*10^7/AM12 -> 64163.884 | AN20: =+AN45*10^7/AN12 -> 60716.651 | AO20: =+AO45*10^7/AO12 -> 75472.469 | AP20: =+AP45*10^7/AP12 -> 76280.597 | ... CL20: =+CL45*10^7/CL12 -> 89080.134 | CM20: =+CI20 -> 135971.78 | CN20: =+CJ20 -> 122516.66 | CO20: =+CK20 -> 100563.93 | CP20: =+CL20 -> 89080.134 | CQ20: =+CM20 -> 135971.78 | CR20: =+CN20 -> 122516.66 | CS20: =+CO20 -> 100563.93 | CT20: =+CP20 -> 89080.134 | ... DB20: =+CX20 -> 89080.134 | DF20: 105070.85
A21: Employee cost % | N21: =+N20/N16 -> 0.059344683 | O21: =+O20/O16 -> 0.079139232 | P21: =+P20/P16 -> 0.081224169 | Q21: =+Q20/Q16 -> 0.066707276 | R21: =+R20/R16 -> 0.075838513 | S21: =+S20/S16 -> 0.067067555 | T21: =+T20/T16 -> 0.061359287 | U21: =+U20/U16 -> 0.098811194 | ... AE21: =+AE20/AE16 -> 0.051688132 | AI21: =+AI20/AI16 -> 0.06677051 | AJ21: =+AJ20/AJ16 -> 0.060024805 | AK21: =+AK20/AK16 -> 0.068807508 | AL21: =+AL20/AL16 -> 0.058685609 | AM21: =+AM20/AM16 -> 0.082101159 | AN21: =+AN20/AN16 -> 0.078566153 | AO21: =+AO20/AO16 -> 0.092723372 | AP21: =+AP20/AP16 -> 0.083436994 | ... DB21: =+DB20/DB16 -> 0.050219177 | DF21: 0.057282157
A22: Other Cost | N22: =+N18-N20-N23 -> 124771.36 | O22: =+O18-O20-O23 -> 152477.55 | P22: =+P18-P20-P23 -> 203141.76 | Q22: =+Q18-Q20-Q23 -> 200648.37 | R22: =+R18-R20-R23 -> 203850.36 | S22: =+S18-S20-S23 -> 197074.21 | T22: =+T18-T20-T23 -> 176212.3 | U22: =+U18-U20-U23 -> 217133.84 | ... AE22: =+AE18-AE20-AE23 -> 461154.61 | AI22: =+AI18-AI20-AI23 -> 137951.89 | AJ22: =+AJ18-AJ20-AJ23 -> 121329.55 | AK22: =+AK18-AK20-AK23 -> 117212.77 | AL22: =+AL18-AL20-AL23 -> 124566.46 | AM22: =+AM18-AM20-AM23 -> 140893.76 | AN22: =+AN18-AN20-AN23 -> 131309.04 | AO22: =+AO18-AO20-AO23 -> 161906.01 | AP22: =+AP18-AP20-AP23 -> 183251.67 | ... DB22: =+DB18-DB20-DB23 -> 236129.71 | DF22: 321225.36
A23: EBITDA | N23: =+N52*10^7/N12 -> 81929.254 | O23: =+O52*10^7/O12 -> 27689.32 | P23: =+P52*10^7/P12 -> 14310.678 | Q23: =+Q52*10^7/Q12 -> 208726.55 | R23: =+R52*10^7/R12 -> 173434.47 | S23: =+S52*10^7/S12 -> 81006.764 | T23: =+T52*10^7/T12 -> 107597.1 | U23: =+U52*10^7/U12 -> 889.24057 | ... AE23: =+AE52*10^7/AE12 -> 3842.3563 | AI23: =+AI52*10^7/AI12 -> 55262.41 | AJ23: =+AJ52*10^7/AJ12 -> 43955.955 | AK23: =+AK52*10^7/AK12 -> 9751.2839 | AL23: =+AL52*10^7/AL12 -> 14024.098 | AM23: =+AM52*10^7/AM12 -> 9029.4171 | AN23: =+AN52*10^7/AN12 -> 7086.3397 | AO23: =+AO52*10^7/AO12 -> -48093.362 | AP23: =+AP52*10^7/AP12 -> -68257.874 | ... CL23: =+CL52*10^7/CL12 -> 249650.85 | CM23: =+CI23 -> 220778.92 | CN23: =+CJ23 -> 219368.19 | CO23: =+CK23 -> 227490.96 | CP23: =+CL23 -> 249650.85 | CQ23: =+CM23 -> 220778.92 | CR23: =+CN23 -> 219368.19 | CS23: =+CO23 -> 227490.96 | CT23: =+CP23 -> 249650.85 | ... DB23: =+CX23 -> 249650.85 | DF23: 131348.03
A24: EBITDA margin % | N24: =+N23/N16 -> 0.099522559 | O24: =+O23/O16 -> 0.031996062 | P24: =+P23/P16 -> 0.013707756 | Q24: =+Q23/Q16 -> 0.16538958 | R24: =+R23/R16 -> 0.13453295 | S24: =+S23/S16 -> 0.06153457 | T24: =+T23/T16 -> 0.080307275 | U24: =+U23/U16 -> 0.0006813073 | ... AE24: =+AE23/AE16 -> 0.0021658182 | AI24: =+AI23/AI16 -> 0.066104562 | AJ24: =+AJ23/AJ16 -> 0.052356558 | AK24: =+AK23/AK16 -> 0.013664983 | AL24: =+AL23/AL16 -> 0.019823289 | AM24: =+AM23/AM16 -> 0.011553627 | AN24: =+AN23/AN16 -> 0.0091695843 | AO24: =+AO23/AO16 -> -0.059086165 | AP24: =+AP23/AP16 -> -0.074661605 | ... CK24: =+CK23/CK16 -> 0.12631477 | CL24: s | CM24: =+CM23/CM16 -> 0.12081172 | CN24: =+CN23/CN16 -> 0.12011236 | CO24: =+CO23/CO16 -> 0.12430084 | CP24: =+CP23/CP16 -> 0.13586743 | CQ24: =+CQ23/CQ16 -> 0.12308205 | CR24: =+CR23/CR16 -> 0.12286126 | CS24: =+CS23/CS16 -> 0.128129 | CT24: =+CT23/CT16 -> 0.14167907 | ... DB24: =+DB23/DB16 -> 0.14074137 | DF24: 0.071607857
A27: Presentation Data (End)
A28: Profit & Loss- Annual (Start)
A29: Gross Revenue | B29: ='Annual Raw'!C6 -> 0 | C29: ='Annual Raw'!D6 -> 0 | D29: ='Annual Raw'!E6 -> 0 | E29: 15018.59 | F29: 19940.72 | G29: 22912.09 | H29: 30710.67 | I29: 31933.41 | J29: 27426.12 | K29: 37134.35 | L29: 50611.05 | M29: 57401.682 | N29: 47412.782 | O29: 35981.23 | P29: 37656.599 | Q29: 47383.61 | R29: 49054.49 | S29: 58689.81 | T29: 69202.76 | U29: 43928.17 | V29: 47031.47 | W29: 46880.97 | X29: 65298.84 | Y29: 72746 | Z29: 68869 | AA29: 68869 | AB29: =+SUM(CM29:CP29) -> 87366.164 | AC29: =+SUM(CQ29:CT29) -> 94717.369 | AD29: =+SUM(CU29:CX29) -> 105678.3 | AE29: =+SUM(CY29:DB29) -> 118074.81 | AI29: 11581.7 | AJ29: 13714.36 | AK29: 11584.57 | AL29: 12046.42 | AM29: 10013.05 | AN29: 9657.43 | AO29: 8458.27 | AP29: 9248.11 | AQ29: 8256.46 | AR29: 9377.22 | AS29: 9681.92 | AT29: 11804.5 | AU29: 10262.76 | AV29: 11601 | AW29: 10892.22 | AX29: 14147.98 | AY29: 11434.91 | AZ29: 11365.86 | BA29: 11207.2 | BB29: 15080.56 | BC29: 10366.19 | BD29: 13310.37 | BE29: 15962.39 | BF29: 19173.46 | BG29: 16674.99 | BH29: 17758.69 | BI29: 16207.67 | BJ29: 18561.41 | BK29: 13351.91 | BL29: 10000.48 | BM29: 10842.91 | BN29: 9732.87 | BO29: 2686.87 | BP29: 9668.1 | BQ29: 14630.6 | BR29: 20045.9 | BS29: 11904.19 | BT29: 10996.02 | BU29: 12352.78 | BV29: 17338.27 | BW29: 14874.44 | BX29: 14946.78 | BY29: 15793.98 | BZ29: 20142.13 | CA29: 15832.57 | CB29: 18541.7 | CC29: 18668.56 | CD29: 20260.24 | CE29: 16862 | CF29: 15518 | CG29: 17040 | CH29: 19999 | CI29: 15682 | CJ29: ='QTR Raw'!BD6+'QTR Raw'!BD8 -> 16861 | CK29: ='QTR Raw'!BE6+'QTR Raw'!BE8 -> 20404 | CL29: ='QTR Raw'!BF6+'QTR Raw'!BF8 -> 24452 | CM29: =+CM12*CM16/10^7 -> 17459.214 | CN29: =+CN12*CN16/10^7 -> 19330.757 | CO29: =+CO12*CO16/10^7 -> 23430.964 | CP29: =+CP12*CP16/10^7 -> 27145.229 | CQ29: =+CQ12*CQ16/10^7 -> 19131.317 | CR29: =+CR12*CR16/10^7 -> 21132.898 | CS29: =+CS12*CS16/10^7 -> 25412.283 | CT29: =+CT12*CT16/10^7 -> 29040.871 | ... DB29: =+DB12*DB16/10^7 -> 36417.133 | DF29: 24297.637
A30: Other operating income | E30: 103.88 | F30: 105.68 | G30: 132.04 | H30: 208.27 | I30: 208.91 | J30: 255.96 | K30: 219.27 | L30: 233.04 | M30: 301.16 | N30: 392.68 | O30: 381.14 | P30: 404.24 | Q30: 421.82 | R30: 581.9 | S30: 455.48 | T30: 437.88 | U30: 442.41 | V30: 472.08 | W30: 382.71 | X30: 458.49 | Y30: 557 | Z30: 550 | AA30: 550 | AI30: 75.77 | AJ30: 84.97 | AK30: 101.43 | AL30: 130.51 | AM30: 68.89 | AN30: 107.35 | AO30: 98.27 | AP30: 106.63 | AQ30: 91.87 | AR30: 94.23 | AS30: 112.51 | AT30: 108.09 | AU30: 137.59 | AV30: 192.9 | AW30: 163.05 | AX30: 0 | AY30: 0 | AZ30: 0 | BA30: 0 | BB30: 0 | BC30: 0 | BD30: 0 | BE30: 0 | BF30: 0 | BG30: 0 | BH30: 0 | BI30: 0 | BJ30: 0 | BK30: 0 | BL30: 0 | BM30: 0 | BN30: 0 | BO30: 0 | BP30: 0 | BQ30: 0 | BR30: 0 | BS30: 0 | BT30: 0 | BU30: 0 | BV30: 0 | BW30: 0 | BX30: 0 | BY30: 0 | BZ30: 0 | CA30: 0 | CB30: 0 | CC30: 0 | CD30: 0 | CE30: 0 | CF30: 0 | CG30: 0 | CH30: 0 | CI30: 0 | CJ30: 0 | CK30: 0 | CL30: 0
A31: Less: Exise Duty | B31: ='Annual Raw'!C7+'Annual Raw'!C8+'Annual Raw'!C9 -> 0 | C31: ='Annual Raw'!D7+'Annual Raw'!D8+'Annual Raw'!D9 -> 0 | D31: ='Annual Raw'!E7+'Annual Raw'!E8+'Annual Raw'!E9 -> 0 | E31: ='Annual Raw'!F7+'Annual Raw'!F8+'Annual Raw'!F9 -> 0 | F31: ='Annual Raw'!G7+'Annual Raw'!G8+'Annual Raw'!G9 -> 0 | G31: ='Annual Raw'!H7+'Annual Raw'!H8+'Annual Raw'!H9 -> 0 | H31: ='Annual Raw'!I7+'Annual Raw'!I8+'Annual Raw'!I9 -> 0 | I31: ='Annual Raw'!J7+'Annual Raw'!J8+'Annual Raw'!J9 -> 0 | ... AA31: ='Annual Raw'!AB7+'Annual Raw'!AB8+'Annual Raw'!AB9 -> 0 | AI31: 1071.06 | AJ31: 1317.99 | AK31: 1055.91 | AL31: 1109.14 | AM31: 977.44 | AN31: 896.33 | AO31: 786.87 | AP31: 809.25 | AQ31: 643.57 | AR31: 719.37 | AS31: 738.35 | AT31: 1128.31 | AU31: 1076.15 | AV31: 1100.21 | AW31: 1013.48 | AX31: 1348.3 | AY31: 1145.19 | AZ31: 1083.69 | BA31: 1001.78 | BB31: 1506.42 | BC31: 1278.37 | BD31: -487.7 | BE31: 0 | BF31: 0 | BG31: 0 | BH31: 0 | BI31: 0 | BJ31: 0 | BK31: 0 | BL31: 0 | BM31: 0 | BN31: 0 | BO31: 0 | BP31: 0 | BQ31: 0 | BR31: 0 | BS31: 0 | BT31: 0 | BU31: 0 | BV31: 0 | BW31: 0 | BX31: 0 | BY31: 0 | BZ31: 0 | CA31: 0 | CB31: 0 | CC31: 0 | CD31: 0 | CE31: 0 | CF31: 0 | CG31: 0 | CH31: 0 | CI31: 0 | CJ31: ='QTR Raw'!BD21+'QTR Raw'!BD20+'QTR Raw'!BD19+'QTR Raw'!BD13+'QTR Raw'!BD7 -> -287 | CK31: ='QTR Raw'!BE21+'QTR Raw'!BE20+'QTR Raw'!BE19+'QTR Raw'!BE13+'QTR Raw'!BE7 -> -227 | CL31: ='QTR Raw'!BF21+'QTR Raw'!BF20+'QTR Raw'!BF19+'QTR Raw'!BF13+'QTR Raw'!BF7 -> -264
A32: Net Revenue | B32: =+B29-B31 -> 0 | C32: =+C29-C31 -> 0 | D32: =+D29-D31 -> 0 | E32: =+E29-E31+E30 -> 15122.47 | F32: =+F29-F31+F30 -> 20046.4 | G32: =+G29-G31+G30 -> 23044.13 | H32: =+H29-H31+H30 -> 30918.94 | I32: =+I29-I31+I30 -> 32142.32 | J32: =+J29-J31+J30 -> 27682.08 | K32: =+K29-K31+K30 -> 37353.62 | L32: =+L29-L31+L30 -> 50844.09 | ... AE32: =+AE29-AE31+AE30 -> 118074.81 | AI32: =+AI29-AI31+AI30 -> 10586.41 | AJ32: =+AJ29-AJ31+AJ30 -> 12481.34 | AK32: =+AK29-AK31+AK30 -> 10630.09 | AL32: =+AL29-AL31+AL30 -> 11067.79 | AM32: =+AM29-AM31+AM30 -> 9104.5 | AN32: =+AN29-AN31+AN30 -> 8868.45 | AO32: =+AO29-AO31+AO30 -> 7769.67 | AP32: =+AP29-AP31+AP30 -> 8545.49 | ... CL32: =+CL29-CL31+CL30 -> 24716 | CM32: =+CM29-CM31 -> 17459.214 | CN32: =+CN29-CN31 -> 19330.757 | CO32: =+CO29-CO31 -> 23430.964 | CP32: =+CP29-CP31 -> 27145.229 | CQ32: =+CQ29-CQ31 -> 19131.317 | CR32: =+CR29-CR31 -> 21132.898 | CS32: =+CS29-CS31 -> 25412.283 | CT32: =+CT29-CT31 -> 29040.871 | ... DB32: =+DB29-DB31 -> 36417.133 | DF32: 24297.637
A33: Net Revenue YOY% | C33: =C32/B32-1 -> #DIV/0! | D33: =D32/C32-1 -> #DIV/0! | F33: =F32/E32-1 -> 0.32560356 | G33: =G32/F32-1 -> 0.14953957 | H33: =H32/G32-1 -> 0.34172737 | I33: =I32/H32-1 -> 0.039567333 | J33: =J32/I32-1 -> -0.13876534 | K33: =K32/J32-1 -> 0.34937909 | L33: =L32/K32-1 -> 0.36115563 | M33: =M32/L32-1 -> 0.13489772 | ... AE33: =AE32/AD32-1 -> 0.1173042 | AM33: =+AM32/AI32-1 -> -0.1399823 | AN33: =+AN32/AJ32-1 -> -0.28946331 | AO33: =+AO32/AK32-1 -> -0.26908709 | AP33: =+AP32/AL32-1 -> -0.22789554 | AQ33: =+AQ32/AM32-1 -> -0.15374156 | AR33: =+AR32/AN32-1 -> -0.013121797 | AS33: =+AS32/AO32-1 -> 0.16556816 | AT33: =+AT32/AP32-1 -> 0.26198498 | ... CI33: =+CI32/CE32-1 -> -0.069979836 | CJ33: =+IF(CF32<0,1-CJ32/CF32,CJ32/CF32-1) -> 0.10503931 | CK33: =+IF(CG32<0,1-CK32/CG32,CK32/CG32-1) -> 0.21073944 | CL33: =+IF(CH32<0,1-CL32/CH32,CL32/CH32-1) -> 0.23586179 | CM33: =+AVERAGE(CI33:CL33) -> 0.12041518 | CN33: =+AVERAGE(CJ33:CM33) -> 0.16801393 | CO33: =+AVERAGE(CK33:CN33) -> 0.18375758 | CP33: =+AVERAGE(CL33:CO33) -> 0.17701212 | CQ33: =+AVERAGE(CM33:CP33) -> 0.1622997 | CR33: =+AVERAGE(CN33:CQ33) -> 0.17277083 | CS33: =+AVERAGE(CO33:CR33) -> 0.17396006 | CT33: =+AVERAGE(CP33:CS33) -> 0.17151068 | ... DB33: =+AVERAGE(CX33:DA33) -> 0.17153161 | DF33: 0.058226172
A34: Net Revenue QOQ% | AJ34: =+AJ32/AI32-1 -> 0.17899647 | AK34: =+AK32/AJ32-1 -> -0.14832141 | AL34: =+AL32/AK32-1 -> 0.041175569 | AM34: =+AM32/AL32-1 -> -0.17738772 | AN34: =+AN32/AM32-1 -> -0.02592674 | AO34: =+AO32/AN32-1 -> -0.12389764 | AP34: =+AP32/AO32-1 -> 0.099852375 | AQ34: =+AQ32/AP32-1 -> -0.09838289 | ... CI34: =+CI32/CH32-1 -> -0.21586079 | CJ34: =+IF(CI32<0,1-CJ32/CI32,CJ32/CI32-1) -> 0.093482974 | CK34: =+IF(CJ32<0,1-CK32/CJ32,CK32/CJ32-1) -> 0.20311407 | CL34: =+IF(CK32<0,1-CL32/CK32,CL32/CK32-1) -> 0.19800301 | CM34: =+CM32/CL32-1 -> -0.29360681 | CN34: =+CN32/CM32-1 -> 0.10719512 | CO34: =+CO32/CN32-1 -> 0.21210794 | CP34: =+CP32/CO32-1 -> 0.15851953 | CQ34: =+CQ32/CP32-1 -> -0.29522358 | CR34: =+CR32/CQ32-1 -> 0.10462326 | CS34: =+CS32/CR32-1 -> 0.2024987 | CT34: =+CT32/CS32-1 -> 0.14278875 | ... DB34: =+DB32/DA32-1 -> 0.14666639 | DF34: 0.17772462
A35: Increase/Decrease in Stock | B35: ='Annual Raw'!C11 -> 0 | C35: ='Annual Raw'!D11 -> 0 | D35: ='Annual Raw'!E11 -> 0 | E35: 141.98 | F35: -144 | G35: -256.91 | H35: -349.68 | I35: 40.48 | J35: 238.04 | K35: -606.63 | L35: -354.22 | M35: -623.84 | N35: -143.6 | O35: 371.72 | P35: -878.82 | Q35: 10.05 | R35: -252.14 | S35: 842.05 | T35: 144.69 | U35: 722.68 | V35: -69.02 | W35: -403.87 | X35: 484.69 | Y35: -600 | Z35: 284 | AA35: 284 | AB35: =+SUM(CM35:CP35) -> 0 | AC35: =+SUM(CQ35:CT35) -> 0 | AD35: =+SUM(CU35:CX35) -> 0 | AE35: =+SUM(CY35:DB35) -> 0 | AI35: -982.01 | AJ35: 89.36 | AK35: 348.41 | AL35: 400.64 | AM35: -426.13 | AN35: 44.92 | AO35: 415.82 | AP35: 337.11 | AQ35: -541.8 | AR35: -128.28 | AS35: -31.57 | AT35: -177.17 | AU35: -418.81 | AV35: 37.43 | AW35: 408.97 | AX35: -17.54 | AY35: -836.16 | AZ35: -105.23 | BA35: -99.14 | BB35: 789.89 | BC35: -482.6 | BD35: 663.73 | BE35: 153.73 | BF35: 507.19 | BG35: -1090.68 | BH35: -119.6 | BI35: -149.62 | BJ35: 1504.59 | BK35: -1458.96 | BL35: 644.83 | BM35: 1063.21 | BN35: 473.6 | BO35: 309.56 | BP35: -174.86 | BQ35: -591.5 | BR35: 387.78 | BS35: -1401.54 | BT35: -26.29 | BU35: -188.35 | BV35: 870.43 | BW35: -919.23 | BX35: 349.83 | BY35: -65.26 | BZ35: 1119.34 | CA35: -1395.71 | CB35: -9.06 | CC35: -861.33 | CD35: 1665.66 | CE35: -601 | CF35: 222 | CG35: 229 | CH35: 555 | CI35: -1175 | CJ35: ='QTR Raw'!BD10 -> 263 | CK35: ='QTR Raw'!BE10 -> 317 | CL35: ='QTR Raw'!BF10 -> 164 | DF35: -431
A36: Purchase of Finished Goods | B36: 0 | C36: 0 | D36: 0 | E36: 467.98 | F36: 665.12 | G36: 998.74 | H36: 1459.2 | I36: 1598.11 | J36: 2180.32 | K36: 4513.23 | L36: 7363.13 | M36: 0 | N36: 0 | O36: 5049.82 | P36: 5765.24 | Q36: 4101.97 | R36: 3945.97 | S36: 4762.41 | T36: 6722.32 | U36: 5679.98 | V36: 5490.67 | W36: 5030 | X36: 6561.32 | Y36: 7764 | Z36: 7367 | AA36: 7367 | AB36: =+SUM(CM36:CP36) -> 0 | AC36: =+SUM(CQ36:CT36) -> 0 | AD36: =+SUM(CU36:CX36) -> 0 | AE36: =+SUM(CY36:DB36) -> 0 | AI36: 8414.81 | AJ36: 9185.54 | AK36: 7658.93 | AL36: 7849.45 | AM36: 7036.58 | AN36: 6538.6 | AO36: 5547.01 | AP36: 6420.5 | AQ36: 6243.26 | AR36: 6772.3 | AS36: 7022.76 | AT36: 7882.15 | AU36: 6781.98 | AV36: 7314.29 | AW36: 6630.5 | AX36: 8372.6 | AY36: 7722.68 | AZ36: 7527.7 | BA36: 7578.25 | BB36: 8771.3 | BC36: 6901.31 | BD36: 9645.37 | BE36: 11629.71 | BF36: 13666.47 | BG36: 13166.95 | BH36: 13029.6 | BI36: 11970.03 | BJ36: 12304.51 | BK36: 11052.99 | BL36: 6834.85 | BM36: 6978.51 | BN36: 6985.48 | BO36: 1630.44 | BP36: 7425.18 | BQ36: 11471.09 | BR36: 14974.57 | BS36: 10536.15 | BT36: 8439.31 | BU36: 9842.37 | BV36: 12642.26 | BW36: 12181.8 | BX36: 11187.41 | BY36: 11698.98 | BZ36: 13719.94 | CA36: 12832.74 | CB36: 13333.45 | CC36: 13950.07 | CD36: 12672.93 | CE36: 12157 | CF36: 10307 | CG36: 11489 | CH36: 13158 | CI36: =(99330+17630)/10 -> 11696 | CJ36: ='QTR Raw'!BD12 -> 1744 | CK36: ='QTR Raw'!BE12 -> 1954 | CL36: ='QTR Raw'!BF12 -> 2488 | DF36: 17882
A37: Raw Material Consumed | B37: ='Annual Raw'!C12 -> 0 | C37: ='Annual Raw'!D12 -> 0 | D37: ='Annual Raw'!E12 -> 0 | E37: 7873.41 | F37: 11264.36 | G37: 13265.12 | H37: 17915.73 | I37: 18592.08 | J37: 16187.68 | K37: 20392.6 | L37: 27058.47 | M37: 40328.77 | N37: 33108.73 | O37: 20492.87 | P37: 22155.23 | Q37: 24997.4 | R37: 27651.65 | S37: 37080.45 | T37: 43748.77 | U37: 26171.85 | V37: 30010.61 | W37: 31693.11 | X37: 42226.81 | Y37: 45025 | Z37: 39865 | AA37: 39865 | AB37: =+SUM(CM37:CP37) -> 59914.564 | AC37: =+SUM(CQ37:CT37) -> 64989.366 | AD37: =+SUM(CU37:CX37) -> 72516.398 | AE37: =+SUM(CY37:DB37) -> 81023.803 | AI37: =('QTR Raw'!C11)/10 -> 0 | AJ37: =('QTR Raw'!D11)/10 -> 0 | AK37: =('QTR Raw'!E11)/10 -> 0 | AL37: =('QTR Raw'!F11)/10 -> 0 | AM37: =('QTR Raw'!G11)/10 -> 0 | AN37: =('QTR Raw'!H11)/10 -> 0 | AO37: =('QTR Raw'!I11)/10 -> 0 | AP37: =('QTR Raw'!J11)/10 -> 0 | ... CE37: =('QTR Raw'!AY11)/10 -> 0 | CF37: 0 | CG37: =('QTR Raw'!BA11)/10 -> 974.1 | CH37: =('QTR Raw'!BB11)/10 -> 1110.4 | CI37: =('QTR Raw'!BC11)/10 -> 0 | CJ37: ='QTR Raw'!BD11 -> 9625 | CK37: ='QTR Raw'!BE11 -> 12000 | CL37: ='QTR Raw'!BF11 -> 14398 | CM37: =+CM32-CM38 -> 11919.357 | CN37: =+CN32-CN38 -> 13254.083 | CO37: =+CO32-CO38 -> 16108.244 | CP37: =+CP32-CP38 -> 18632.879 | CQ37: =+CQ32-CQ38 -> 13115.647 | CR37: =+CR32-CR38 -> 14502.968 | CS37: =+CS32-CS38 -> 17443.783 | CT37: =+CT32-CT38 -> 19926.968 | ... DB37: =+DB32-DB38 -> 24989.58 | DF37: 16562.707
A38: Gross Profit | B38: =B32-B35-B37-B36 -> 0 | C38: =C32-C35-C37-C36 -> 0 | D38: =D32-D35-D37-D36 -> 0 | E38: =E32-E35-E37-E36 -> 6639.1 | F38: =F32-F35-F37-F36 -> 8260.92 | G38: =G32-G35-G37-G36 -> 9037.18 | H38: =H32-H35-H37-H36 -> 11893.69 | I38: =I32-I35-I37-I36 -> 11911.65 | ... AE38: =AE32-AE35-AE37-AE36 -> 37051.005 | AH38: 10 | AI38: =AI32-AI35-AI37-AI36 -> 3153.61 | AJ38: =AJ32-AJ35-AJ37-AJ36 -> 3206.44 | AK38: =AK32-AK35-AK37-AK36 -> 2622.75 | AL38: =AL32-AL35-AL37-AL36 -> 2817.7 | AM38: =AM32-AM35-AM37-AM36 -> 2494.05 | AN38: =AN32-AN35-AN37-AN36 -> 2284.93 | AO38: =AO32-AO35-AO37-AO36 -> 1806.84 | AP38: =AP32-AP35-AP37-AP36 -> 1787.88 | ... CL38: =CL32-CL35-CL37-CL36 -> 7666 | CM38: =+CM39*CM32 -> 5539.8567 | CN38: =+CN39*CN32 -> 6076.6733 | CO38: =+CO39*CO32 -> 7322.7195 | CP38: =+CP39*CP32 -> 8512.3501 | CQ38: =+CQ39*CQ32 -> 6015.6707 | CR38: =+CR39*CR32 -> 6629.9305 | CS38: =+CS39*CS32 -> 7968.4993 | CT38: =+CT39*CT32 -> 9113.9029 | ... DB38: =+DB39*DB32 -> 11427.553 | DF38: 7734.9295
A39: GP% | B39: =B38/B32 -> #DIV/0! | C39: =C38/C32 -> #DIV/0! | D39: =D38/D32 -> #DIV/0! | E39: =E38/E32 -> 0.4390222 | F39: =F38/F32 -> 0.41208995 | G39: =G38/G32 -> 0.39216842 | H39: =H38/H32 -> 0.38467328 | I39: =I38/I32 -> 0.37059086 | ... AE39: =AE38/AE32 -> 0.31379263 | AI39: =AI38/AI32 -> 0.2978923 | AJ39: =AJ38/AJ32 -> 0.2568987 | AK39: =AK38/AK32 -> 0.24672886 | AL39: =AL38/AL32 -> 0.2545856 | AM39: =AM38/AM32 -> 0.27393597 | AN39: =AN38/AN32 -> 0.25764705 | AO39: =AO38/AO32 -> 0.23255042 | AP39: =AP38/AP32 -> 0.20921913 | ... CL39: =CL38/CL32 -> 0.31016346 | CM39: =AVERAGE(CI39:CL39) -> 0.31730275 | CN39: =AVERAGE(CJ39:CM39) -> 0.31435258 | CO39: =AVERAGE(CK39:CN39) -> 0.31252319 | CP39: =AVERAGE(CL39:CO39) -> 0.31358549 | CQ39: =AVERAGE(CM39:CP39) -> 0.314441 | CR39: =AVERAGE(CN39:CQ39) -> 0.31372557 | CS39: =AVERAGE(CO39:CR39) -> 0.31356881 | CT39: =AVERAGE(CP39:CS39) -> 0.31383022 | ... DB39: =AVERAGE(CX39:DA39) -> 0.31379606 | DF39: 0.31834082
A40: GP YOY% | C40: =+C38/B38-1 -> #DIV/0! | D40: =+D38/C38-1 -> #DIV/0! | F40: =+F38/E38-1 -> 0.24428311 | G40: =+G38/F38-1 -> 0.093967742 | H40: =+H38/G38-1 -> 0.31608422 | I40: =+I38/H38-1 -> 0.0015100444 | J40: =+J38/I38-1 -> -0.2380535 | K40: =+K38/J38-1 -> 0.43833875 | L40: =+L38/K38-1 -> 0.28513638 | M40: =+M38/L38-1 -> 0.072791484 | ... AE40: =+AE38/AD38-1 -> 0.11727625 | AM40: =+IF(AI38<0,1-AM38/AI38,AM38/AI38-1) -> -0.20914444 | AN40: =+IF(AJ38<0,1-AN38/AJ38,AN38/AJ38-1) -> -0.2873935 | AO40: =+IF(AK38<0,1-AO38/AK38,AO38/AK38-1) -> -0.31108951 | AP40: =+IF(AL38<0,1-AP38/AL38,AP38/AL38-1) -> -0.36548249 | AQ40: =+IF(AM38<0,1-AQ38/AM38,AQ38/AM38-1) -> -0.19676831 | AR40: =+IF(AN38<0,1-AR38/AN38,AR38/AN38-1) -> -0.077407185 | AS40: =+IF(AO38<0,1-AS38/AO38,AS38/AO38-1) -> 0.1428184 | AT40: =+IF(AP38<0,1-AT38/AP38,AT38/AP38-1) -> 0.72231917 | ... CL40: =+IF(CH38<0,1-CL38/CH38,CL38/CH38-1) -> 0.48118093 | CM40: =+CM38/CI38-1 -> 0.073407615 | CN40: =+CN38/CJ38-1 -> 0.10164491 | CO40: =+CO38/CK38-1 -> 0.15137098 | CP40: =+CP38/CL38-1 -> 0.11040309 | CQ40: =+CQ38/CM38-1 -> 0.085889222 | CR40: =+CR38/CN38-1 -> 0.091046064 | CS40: =+CS38/CO38-1 -> 0.088188525 | CT40: =+CT38/CP38-1 -> 0.070668234 | ... DB40: =+DB38/CX38-1 -> 0.1170771 | DF40: 0.23050104
A41: GP QOQ% | AJ41: =+IF(AI38<0,1-AJ38/AI38,AJ38/AI38-1) -> 0.01675223 | AK41: =+IF(AJ38<0,1-AK38/AJ38,AK38/AJ38-1) -> -0.18203678 | AL41: =+IF(AK38<0,1-AL38/AK38,AL38/AK38-1) -> 0.074330378 | AM41: =+IF(AL38<0,1-AM38/AL38,AM38/AL38-1) -> -0.11486319 | AN41: =+IF(AM38<0,1-AN38/AM38,AN38/AM38-1) -> -0.083847557 | AO41: =+IF(AN38<0,1-AO38/AN38,AO38/AN38-1) -> -0.20923617 | AP41: =+IF(AO38<0,1-AP38/AO38,AP38/AO38-1) -> -0.010493458 | AQ41: =+IF(AP38<0,1-AQ38/AP38,AQ38/AP38-1) -> 0.12048907 | ... CL41: =+IF(CK38<0,1-CL38/CK38,CL38/CK38-1) -> 0.20534591 | CM41: =+CM38/CL38-1 -> -0.27734716 | CN41: =+CN38/CM38-1 -> 0.096900809 | CO41: =+CO38/CN38-1 -> 0.205054 | CP41: =+CP38/CO38-1 -> 0.16245749 | CQ41: =+CQ38/CP38-1 -> -0.29330084 | CR41: =+CR38/CQ38-1 -> 0.10210994 | CS41: =+CS38/CR38-1 -> 0.20189786 | CT41: =+CT38/CS38-1 -> 0.14374144 | ... DB41: =+DB38/DA38-1 -> 0.14669194 | DF41: 0.21618389
A42: Power & Fuel Cost | B42: ='Annual Raw'!C13 -> 0 | C42: ='Annual Raw'!D13 -> 0 | D42: ='Annual Raw'!E13 -> 0 | E42: 214.52 | F42: 237.81 | G42: 258.51 | H42: 327.41 | I42: 325.19 | J42: 304.94 | K42: 362.62 | L42: 471.28 | M42: 550.89 | N42: 484.66 | O42: 392.09 | P42: 395.88 | Q42: 402.36 | R42: 483.48 | S42: 545.11 | T42: 598.62 | U42: 428.85 | V42: 371.78 | W42: 344.78 | X42: 420.98 | Y42: 424 | Z42: 419 | AA42: 419 | AB42: =+SUM(CM42:CP42) -> 0 | AC42: =+SUM(CQ42:CT42) -> 0 | AD42: =+SUM(CU42:CX42) -> 0 | AE42: =+SUM(CY42:DB42) -> 0 | DF42: 0
A43: Selling and Distribution Expenses | B43: ='Annual Raw'!C18 -> 0 | C43: ='Annual Raw'!D18 -> 0 | D43: ='Annual Raw'!E18 -> 0 | E43: 455.56 | F43: 598.75 | G43: 759.54 | H43: 1068.56 | I43: 1173.8 | J43: 1224.15 | K43: 1578.14 | L43: 2283.19 | M43: 2913.1746 | N43: 2567.6283 | O43: 2168.6634 | P43: 2521.2651 | Q43: 2674.8469 | R43: 2878.46 | S43: 3189.51 | T43: 3601.22 | U43: 2462.16 | V43: 966.194 | W43: 2064.8 | X43: 2578.25 | Y43: 2999 | Z43: 3686 | AA43: 3686 | AB43: =+SUM(CM43:CP43) -> 0 | AC43: =+SUM(CQ43:CT43) -> 0 | AD43: =+SUM(CU43:CX43) -> 0 | AE43: =+SUM(CY43:DB43) -> 0 | DF43: 0
A44: Other Manufacturing Expenses | B44: ='Annual Raw'!C15+'Annual Raw'!C16 -> 0 | C44: ='Annual Raw'!D15+'Annual Raw'!D16 -> 0 | D44: ='Annual Raw'!E15+'Annual Raw'!E16 -> 0 | E44: 236.73 | F44: 315.8 | G44: 369.16 | H44: 504.63 | I44: 465.4 | J44: 402.43 | K44: 451.91 | L44: 625.45 | M44: 753.02 | N44: 655.67 | O44: 497.9 | P44: 447.36 | Q44: 470.94 | R44: 653.61 | S44: 639.35 | T44: 617.67 | U44: 461.37 | V44: 417.57 | W44: 406.36 | X44: 424.32 | Y44: 494 | Z44: 441 | AA44: 441 | AB44: =+SUM(CM44:CP44) -> 11342.614 | AC44: =+SUM(CQ44:CT44) -> 12045.624 | AD44: =+SUM(CU44:CX44) -> 13491.849 | AE44: =+SUM(CY44:DB44) -> 15346.105 | AI44: 1890.94 | AJ44: 1962.24 | AK44: 1920.43 | AL44: 2000.04 | AM44: 1789.32 | AN44: 1675.88 | AO44: 1685.01 | AP44: 1836.76 | AQ44: 1730.62 | AR44: 1824.08 | AS44: 2031.12 | AT44: 2218.64 | AU44: 1843.68 | AV44: 1965.18 | AW44: 1836.43 | AX44: 2571.36 | AY44: 2081.35 | AZ44: 1887.49 | BA44: 1960.04 | BB44: 2669.67 | BC44: 1924.38 | BD44: 1806.02 | BE44: 2119.06 | BF44: 3387.46 | BG44: 2410.69 | BH44: 2548.51 | BI44: 2134.94 | BJ44: 2586.32 | BK44: 2051.94 | BL44: 1928.47 | BM44: 1890.01 | BN44: 1850.33 | BO44: 661.73 | BP44: 1283.21 | BQ44: 1738.42 | BR44: 2118.54 | BS44: 1495.12 | BT44: 1548.94 | BU44: 1589.72 | BV44: 1832.57 | BW44: 1923.4 | BX44: 1846.41 | BY44: 1842.19 | BZ44: 2207.74 | CA44: 2039.3 | CB44: 2192.86 | CC44: 2355.53 | CD44: 2373.29 | CE44: 2292 | CF44: 2220 | CG44: 2248 | CH44: 2728 | CI44: 2212 | CJ44: ='QTR Raw'!BD14 -> 2279 | CK44: ='QTR Raw'!BE14 -> 2602 | CL44: ='QTR Raw'!BF14 -> 3179 | CM44: =CM50-CM45 -> 2104.3056 | CN44: =CN50-CN45 -> 2386.8657 | CO44: =CO50-CO45 -> 3089.6098 | CP44: =CP50-CP45 -> 3761.8325 | CQ44: =CQ50-CQ45 -> 2214.3683 | CR44: =CR50-CR45 -> 2556.2668 | CS44: =CS50-CS45 -> 3327.613 | CT44: =CT50-CT45 -> 3947.3759 | ... DB44: =DB50-DB45 -> 5069.3911 | DF44: 3553.3759
A45: Employee Cost | B45: ='Annual Raw'!C14 -> 0 | C45: ='Annual Raw'!D14 -> 0 | D45: ='Annual Raw'!E14 -> 0 | E45: 882.49 | F45: 1039.34 | G45: 1143.13 | H45: 1324.83 | I45: 1544.57 | J45: 1551.39 | K45: 1836.13 | L45: 2294.02 | M45: 2691.45 | N45: 2837 | O45: 2877.69 | P45: 3091.46 | Q45: 3188.97 | R45: 3764.35 | S45: 3966.73 | T45: 4273.1 | U45: 4384.31 | V45: 4212.99 | W45: 3601.51 | X45: 4021.63 | Y45: 4308 | Z45: 4513 | AA45: 4513 | AB45: =+SUM(CM45:CP45) -> 4981.92 | AC45: =+SUM(CQ45:CT45) -> 5330.6544 | AD45: =+SUM(CU45:CX45) -> 5703.8002 | AE45: =+SUM(CY45:DB45) -> 6103.0662 | AI45: 706.86 | AJ45: 749.19 | AK45: 731.43 | AL45: 649.52 | AM45: 747.49 | AN45: 696.76 | AO45: 720.43 | AP45: 713.01 | AQ45: 739.5 | AR45: 751 | AS45: 764.71 | AT45: 836.2 | AU45: 808.25 | AV45: 769.49 | AW45: 824.98 | AX45: 785.36 | AY45: 898.94 | AZ45: 881.7 | BA45: 845.35 | BB45: 983.94 | BC45: 937.65 | BD45: 941.97 | BE45: 983.51 | BF45: 1103.6 | BG45: 1032.92 | BH45: 1045.4 | BI45: 1060.11 | BJ45: 1134.67 | BK45: 1149.34 | BL45: 1067.09 | BM45: 1018.27 | BN45: 1149.61 | BO45: 966.74 | BP45: 1058.6 | BQ45: 1105.89 | BR45: 1081.76 | BS45: 1180.41 | BT45: 886.25 | BU45: 918.1 | BV45: 875.6 | BW45: 1062.85 | BX45: 964.43 | BY45: 972.28 | BZ45: 1022.07 | CA45: 1064.47 | CB45: 1085.96 | CC45: 1110.48 | CD45: 1047.27 | CE45: 1151 | CF45: 1141 | CG45: 1111 | CH45: 1110 | CI45: 1164 | CJ45: ='QTR Raw'!BD16 -> 1160 | CK45: ='QTR Raw'!BE16 -> 1152 | CL45: ='QTR Raw'!BF16 -> 1180 | CM45: =CI45*107% -> 1245.48 | CN45: =CJ45*107% -> 1241.2 | CO45: =CK45*107% -> 1232.64 | CP45: =CL45*107% -> 1262.6 | CQ45: =CM45*107% -> 1332.6636 | CR45: =CN45*107% -> 1328.084 | CS45: =CO45*107% -> 1318.9248 | CT45: =CP45*107% -> 1350.982 | ... DB45: =CX45*107% -> 1546.7393 | DF45: 1187.7
A46: General and Administration Expenses | B46: ='Annual Raw'!C17 -> 0 | C46: ='Annual Raw'!D17 -> 0 | D46: ='Annual Raw'!E17 -> 0 | E46: 388.59 | F46: 555.66 | G46: 625.7 | H46: 823.79 | I46: 851.43 | J46: 810.6 | K46: 1212.9 | L46: 1676.07 | M46: 2057.51 | N46: 1743.64 | O46: 1416.7 | P46: 1450.57 | Q46: 1507.21 | R46: 1004.45 | S46: 1240.88 | T46: 1567.89 | U46: 1051.13 | V46: 953.49 | W46: 1039.05 | X46: 1292.71 | Y46: 1610 | Z46: 1229 | AA46: 1229 | AB46: =+SUM(CM44:CP44) -> 11342.614 | AC46: =+SUM(CQ44:CT44) -> 12045.624 | AD46: =+SUM(CU44:CX44) -> 13491.849 | AE46: =+SUM(CY44:DB44) -> 15346.105 | DF46: 0
...

Sheet Monthly Nos Company
A1: Monthly Volume
A3: Month | B3: M& HCV | C3: LCV | D3: CV Export | E3: CV | G3: 3M Rolling' | H3: M& HCV | I3: LCV | J3: CV Export | K3: CV | M3: 3M YoY% | N3: M& HCV | O3: LCV | P3: CV Export | Q3: CV | S3: 12M Rolling | T3: M& HCV | U3: LCV | V3: CV Export | W3: CV | Y3: 12M YoY% | Z3: M& HCV | AA3: LCV | AB3: CV Export | AC3: CV
A4: 41000 | B4: 9829 | C4: 24818 | D4: 2213 | E4: =+C4+B4+D4 -> 36860
A5: =+EOMONTH(A4,1) -> 41060 | B5: 12451 | C5: 27174 | D5: 3752 | E5: =+C5+B5+D5 -> 43377
A6: =+EOMONTH(A5,1) -> 41090 | B6: 12663 | C6: 28363 | D6: 5371 | E6: =+C6+B6+D6 -> 46397 | H6: =+SUM(B4:B6) -> 34943 | I6: =+SUM(C4:C6) -> 80355 | J6: =+SUM(D4:D6) -> 11336 | K6: =+H6+I6+J6 -> 126634
A7: =+EOMONTH(A6,1) -> 41121 | B7: 12786 | C7: 29601 | D7: 4196 | E7: =+C7+B7+D7 -> 46583 | H7: =+SUM(B5:B7) -> 37900 | I7: =+SUM(C5:C7) -> 85138 | J7: =+SUM(D5:D7) -> 13319 | K7: =+H7+I7+J7 -> 136357
A8: =+EOMONTH(A7,1) -> 41152 | B8: 14681 | C8: 30461 | D8: 3603 | E8: =+C8+B8+D8 -> 48745 | H8: =+SUM(B6:B8) -> 40130 | I8: =+SUM(C6:C8) -> 88425 | J8: =+SUM(D6:D8) -> 13170 | K8: =+H8+I8+J8 -> 141725
A9: =+EOMONTH(A8,1) -> 41182 | B9: 15287 | C9: 33393 | D9: 4659 | E9: =+C9+B9+D9 -> 53339 | H9: =+SUM(B7:B9) -> 42754 | I9: =+SUM(C7:C9) -> 93455 | J9: =+SUM(D7:D9) -> 12458 | K9: =+H9+I9+J9 -> 148667
A10: =+EOMONTH(A9,1) -> 41213 | B10: 12120 | C10: 34905 | D10: 3378 | E10: =+C10+B10+D10 -> 50403 | H10: =+SUM(B8:B10) -> 42088 | I10: =+SUM(C8:C10) -> 98759 | J10: =+SUM(D8:D10) -> 11640 | K10: =+H10+I10+J10 -> 152487
A11: =+EOMONTH(A10,1) -> 41243 | B11: 9495 | C11: 34828 | D11: 3300 | E11: =+C11+B11+D11 -> 47623 | H11: =+SUM(B9:B11) -> 36902 | I11: =+SUM(C9:C11) -> 103126 | J11: =+SUM(D9:D11) -> 11337 | K11: =+H11+I11+J11 -> 151365
A12: =+EOMONTH(A11,1) -> 41274 | B12: 9866 | C12: 37649 | D12: 3424 | E12: =+C12+B12+D12 -> 50939 | H12: =+SUM(B10:B12) -> 31481 | I12: =+SUM(C10:C12) -> 107382 | J12: =+SUM(D10:D12) -> 10102 | K12: =+H12+I12+J12 -> 148965
A13: =+EOMONTH(A12,1) -> 41305 | B13: 8722 | C13: 33849 | D13: 3381 | E13: =+C13+B13+D13 -> 45952 | H13: =+SUM(B11:B13) -> 28083 | I13: =+SUM(C11:C13) -> 106326 | J13: =+SUM(D11:D13) -> 10105 | K13: =+H13+I13+J13 -> 144514
A14: =+EOMONTH(A13,1) -> 41333 | B14: 10629 | C14: 36760 | D14: 3432 | E14: =+C14+B14+D14 -> 50821 | H14: =+SUM(B12:B14) -> 29217 | I14: =+SUM(C12:C14) -> 108258 | J14: =+SUM(D12:D14) -> 10237 | K14: =+H14+I14+J14 -> 147712
A15: =+EOMONTH(A14,1) -> 41364 | B15: 14852 | C15: 41961 | D15: 2859 | E15: =+C15+B15+D15 -> 59672 | H15: =+SUM(B13:B15) -> 34203 | I15: =+SUM(C13:C15) -> 112570 | J15: =+SUM(D13:D15) -> 9672 | K15: =+H15+I15+J15 -> 156445 | T15: =+SUM(B4:B15) -> 143381 | U15: =+SUM(C4:C15) -> 393762 | V15: =+SUM(D4:D15) -> 43568 | W15: =+SUM(E4:E15) -> 580711
A16: =+EOMONTH(A15,1) -> 41394 | B16: 10002 | C16: 26023 | D16: 2737 | E16: =+C16+B16+D16 -> 38762 | H16: =+SUM(B14:B16) -> 35483 | I16: =+SUM(C14:C16) -> 104744 | J16: =+SUM(D14:D16) -> 9028 | K16: =+H16+I16+J16 -> 149255 | T16: =+SUM(B5:B16) -> 143554 | U16: =+SUM(C5:C16) -> 394967 | V16: =+SUM(D5:D16) -> 44092 | W16: =+SUM(E5:E16) -> 582613
A17: =+EOMONTH(A16,1) -> 41425 | B17: 10123 | C17: 24173 | D17: 3076 | E17: =+C17+B17+D17 -> 37372 | H17: =+SUM(B15:B17) -> 34977 | I17: =+SUM(C15:C17) -> 92157 | J17: =+SUM(D15:D17) -> 8672 | K17: =+H17+I17+J17 -> 135806 | T17: =+SUM(B6:B17) -> 141226 | U17: =+SUM(C6:C17) -> 391966 | V17: =+SUM(D6:D17) -> 43416 | W17: =+SUM(E6:E17) -> 576608
A18: =+EOMONTH(A17,1) -> 41455 | B18: 11130 | C18: 25778 | D18: 3455 | E18: =+C18+B18+D18 -> 40363 | H18: =+SUM(B16:B18) -> 31255 | I18: =+SUM(C16:C18) -> 75974 | J18: =+SUM(D16:D18) -> 9268 | K18: =+H18+I18+J18 -> 116497 | N18: =+H18/H6-1 -> -0.10554331 | O18: =+I18/I6-1 -> -0.054520565 | P18: =+J18/J6-1 -> -0.18242766 | Q18: =+K18/K6-1 -> -0.080049592 | T18: =+SUM(B7:B18) -> 139693 | U18: =+SUM(C7:C18) -> 389381 | V18: =+SUM(D7:D18) -> 41500 | W18: =+SUM(E7:E18) -> 570574
A19: =+EOMONTH(A18,1) -> 41486 | B19: 9758 | C19: 26609 | D19: 3579 | E19: =+C19+B19+D19 -> 39946 | H19: =+SUM(B17:B19) -> 31011 | I19: =+SUM(C17:C19) -> 76560 | J19: =+SUM(D17:D19) -> 10110 | K19: =+H19+I19+J19 -> 117681 | N19: =+H19/H7-1 -> -0.18176781 | O19: =+I19/I7-1 -> -0.10075407 | P19: =+J19/J7-1 -> -0.240934 | Q19: =+K19/K7-1 -> -0.136964 | T19: =+SUM(B8:B19) -> 136665 | U19: =+SUM(C8:C19) -> 386389 | V19: =+SUM(D8:D19) -> 40883 | W19: =+SUM(E8:E19) -> 563937
A20: =+EOMONTH(A19,1) -> 41517 | B20: 8249 | C20: 24904 | D20: 3879 | E20: =+C20+B20+D20 -> 37032 | H20: =+SUM(B18:B20) -> 29137 | I20: =+SUM(C18:C20) -> 77291 | J20: =+SUM(D18:D20) -> 10913 | K20: =+H20+I20+J20 -> 117341 | N20: =+H20/H8-1 -> -0.27393471 | O20: =+I20/I8-1 -> -0.12591462 | P20: =+J20/J8-1 -> -0.17137434 | Q20: =+K20/K8-1 -> -0.17205151 | T20: =+SUM(B9:B20) -> 130233 | U20: =+SUM(C9:C20) -> 380832 | V20: =+SUM(D9:D20) -> 41159 | W20: =+SUM(E9:E20) -> 552224
A21: =+EOMONTH(A20,1) -> 41547 | B21: 8815 | C21: 24304 | D21: 4659 | E21: =+C21+B21+D21 -> 37778 | H21: =+SUM(B19:B21) -> 26822 | I21: =+SUM(C19:C21) -> 75817 | J21: =+SUM(D19:D21) -> 12117 | K21: =+H21+I21+J21 -> 114756 | N21: =+H21/H9-1 -> -0.3726435 | O21: =+I21/I9-1 -> -0.18873255 | P21: =+J21/J9-1 -> -0.02737197 | Q21: =+K21/K9-1 -> -0.22810039 | T21: =+SUM(B10:B21) -> 123761 | U21: =+SUM(C10:C21) -> 371743 | V21: =+SUM(D10:D21) -> 41159 | W21: =+SUM(E10:E21) -> 536663
A22: =+EOMONTH(A21,1) -> 41578 | B22: 7935 | C22: 24858 | D22: 4188 | E22: =+C22+B22+D22 -> 36981 | H22: =+SUM(B20:B22) -> 24999 | I22: =+SUM(C20:C22) -> 74066 | J22: =+SUM(D20:D22) -> 12726 | K22: =+H22+I22+J22 -> 111791 | N22: =+H22/H10-1 -> -0.40603022 | O22: =+I22/I10-1 -> -0.25003291 | P22: =+J22/J10-1 -> 0.093298969 | Q22: =+K22/K10-1 -> -0.26688177 | T22: =+SUM(B11:B22) -> 119576 | U22: =+SUM(C11:C22) -> 361696 | V22: =+SUM(D11:D22) -> 41969 | W22: =+SUM(E11:E22) -> 523241
A23: =+EOMONTH(A22,1) -> 41608 | B23: 6823 | C23: 19993 | D23: 3300 | E23: =+C23+B23+D23 -> 30116 | H23: =+SUM(B21:B23) -> 23573 | I23: =+SUM(C21:C23) -> 69155 | J23: =+SUM(D21:D23) -> 12147 | K23: =+H23+I23+J23 -> 104875 | N23: =+H23/H11-1 -> -0.36119993 | O23: =+I23/I11-1 -> -0.32941256 | P23: =+J23/J11-1 -> 0.071447473 | Q23: =+K23/K11-1 -> -0.30713837 | T23: =+SUM(B12:B23) -> 116904 | U23: =+SUM(C12:C23) -> 346861 | V23: =+SUM(D12:D23) -> 41969 | W23: =+SUM(E12:E23) -> 505734
A24: =+EOMONTH(A23,1) -> 41639 | B24: 7659 | C24: 18079 | D24: 2621 | E24: =+C24+B24+D24 -> 28359 | H24: =+SUM(B22:B24) -> 22417 | I24: =+SUM(C22:C24) -> 62930 | J24: =+SUM(D22:D24) -> 10109 | K24: =+H24+I24+J24 -> 95456 | N24: =+H24/H12-1 -> -0.2879197 | O24: =+I24/I12-1 -> -0.41396137 | P24: =+J24/J12-1 -> 0.00069293209 | Q24: =+K24/K12-1 -> -0.35920518 | T24: =+SUM(B13:B24) -> 114697 | U24: =+SUM(C13:C24) -> 327291 | V24: =+SUM(D13:D24) -> 41166 | W24: =+SUM(E13:E24) -> 483154
A25: =+EOMONTH(A24,1) -> 41670 | B25: 8166 | C25: 17517 | D25: 3387 | E25: =+C25+B25+D25 -> 29070 | H25: =+SUM(B23:B25) -> 22648 | I25: =+SUM(C23:C25) -> 55589 | J25: =+SUM(D23:D25) -> 9308 | K25: =+H25+I25+J25 -> 87545 | N25: =+H25/H13-1 -> -0.19353345 | O25: =+I25/I13-1 -> -0.47718338 | P25: =+J25/J13-1 -> -0.078871846 | Q25: =+K25/K13-1 -> -0.39421094 | T25: =+SUM(B14:B25) -> 114141 | U25: =+SUM(C14:C25) -> 310959 | V25: =+SUM(D14:D25) -> 41172 | W25: =+SUM(E14:E25) -> 466272
A26: =+EOMONTH(A25,1) -> 41698 | B26: 9109 | C26: 14881 | D26: 4197 | E26: =+C26+B26+D26 -> 28187 | H26: =+SUM(B24:B26) -> 24934 | I26: =+SUM(C24:C26) -> 50477 | J26: =+SUM(D24:D26) -> 10205 | K26: =+H26+I26+J26 -> 85616 | N26: =+H26/H14-1 -> -0.14659274 | O26: =+I26/I14-1 -> -0.53373423 | P26: =+J26/J14-1 -> -0.0031259158 | Q26: =+K26/K14-1 -> -0.42038562 | T26: =+SUM(B15:B26) -> 112621 | U26: =+SUM(C15:C26) -> 289080 | V26: =+SUM(D15:D26) -> 41937 | W26: =+SUM(E15:E26) -> 443638
A27: =+EOMONTH(A26,1) -> 41729 | B27: 12418 | C27: 20938 | D27: 2859 | E27: =+C27+B27+D27 -> 36215 | H27: =+SUM(B25:B27) -> 29693 | I27: =+SUM(C25:C27) -> 53336 | J27: =+SUM(D25:D27) -> 10443 | K27: =+H27+I27+J27 -> 93472 | N27: =+H27/H15-1 -> -0.13185978 | O27: =+I27/I15-1 -> -0.52619703 | P27: =+J27/J15-1 -> 0.07971464 | Q27: =+K27/K15-1 -> -0.40252485 | T27: =+SUM(B16:B27) -> 110187 | U27: =+SUM(C16:C27) -> 268057 | V27: =+SUM(D16:D27) -> 41937 | W27: =+SUM(E16:E27) -> 420181 | Z27: =+T27/T15-1 -> -0.23150906 | AA27: =+U27/U15-1 -> -0.31924106 | AB27: =+V27/V15-1 -> -0.037435733 | AC27: =+W27/W15-1 -> -0.27643699
A28: =+EOMONTH(A27,1) -> 41759 | B28: 8425 | C28: 14804 | D28: 2828 | E28: =+C28+B28+D28 -> 26057 | H28: =+SUM(B26:B28) -> 29952 | I28: =+SUM(C26:C28) -> 50623 | J28: =+SUM(D26:D28) -> 9884 | K28: =+H28+I28+J28 -> 90459 | N28: =+H28/H16-1 -> -0.15587746 | O28: =+I28/I16-1 -> -0.51669785 | P28: =+J28/J16-1 -> 0.094816128 | Q28: =+K28/K16-1 -> -0.39392985 | T28: =+SUM(B17:B28) -> 108610 | U28: =+SUM(C17:C28) -> 256838 | V28: =+SUM(D17:D28) -> 42028 | W28: =+SUM(E17:E28) -> 407476 | Z28: =+T28/T16-1 -> -0.24342059 | AA28: =+U28/U16-1 -> -0.34972289 | AB28: =+V28/V16-1 -> -0.046811213 | AC28: =+W28/W16-1 -> -0.30060606
A29: =+EOMONTH(A28,1) -> 41790 | B29: 9113 | C29: 15991 | D29: 3005 | E29: =+C29+B29+D29 -> 28109 | H29: =+SUM(B27:B29) -> 29956 | I29: =+SUM(C27:C29) -> 51733 | J29: =+SUM(D27:D29) -> 8692 | K29: =+H29+I29+J29 -> 90381 | N29: =+H29/H17-1 -> -0.14355148 | O29: =+I29/I17-1 -> -0.43864275 | P29: =+J29/J17-1 -> 0.0023062731 | Q29: =+K29/K17-1 -> -0.33448449 | T29: =+SUM(B18:B29) -> 107600 | U29: =+SUM(C18:C29) -> 248656 | V29: =+SUM(D18:D29) -> 41957 | W29: =+SUM(E18:E29) -> 398213 | Z29: =+T29/T17-1 -> -0.23810063 | AA29: =+U29/U17-1 -> -0.36561845 | AB29: =+V29/V17-1 -> -0.033605123 | AC29: =+W29/W17-1 -> -0.30938697
A30: =+EOMONTH(A29,1) -> 41820 | B30: 9620 | C30: 17212 | D30: 3507 | E30: =+C30+B30+D30 -> 30339 | H30: =+SUM(B28:B30) -> 27158 | I30: =+SUM(C28:C30) -> 48007 | J30: =+SUM(D28:D30) -> 9340 | K30: =+H30+I30+J30 -> 84505 | N30: =+H30/H18-1 -> -0.13108303 | O30: =+I30/I18-1 -> -0.36811278 | P30: =+J30/J18-1 -> 0.0077686664 | Q30: =+K30/K18-1 -> -0.27461651 | T30: =+SUM(B19:B30) -> 106090 | U30: =+SUM(C19:C30) -> 240090 | V30: =+SUM(D19:D30) -> 42009 | W30: =+SUM(E19:E30) -> 388189 | Z30: =+T30/T18-1 -> -0.24054892 | AA30: =+U30/U18-1 -> -0.38340597 | AB30: =+V30/V18-1 -> 0.01226506 | AC30: =+W30/W18-1 -> -0.31965179
A31: =+EOMONTH(A30,1) -> 41851 | B31: 9725 | C31: 16364 | D31: 3996 | E31: =+C31+B31+D31 -> 30085 | H31: =+SUM(B29:B31) -> 28458 | I31: =+SUM(C29:C31) -> 49567 | J31: =+SUM(D29:D31) -> 10508 | K31: =+H31+I31+J31 -> 88533 | N31: =+H31/H19-1 -> -0.082325626 | O31: =+I31/I19-1 -> -0.35257315 | P31: =+J31/J19-1 -> 0.039366963 | Q31: =+K31/K19-1 -> -0.24768654 | T31: =+SUM(B20:B31) -> 106057 | U31: =+SUM(C20:C31) -> 229845 | V31: =+SUM(D20:D31) -> 42426 | W31: =+SUM(E20:E31) -> 378328 | Z31: =+T31/T19-1 -> -0.22396371 | AA31: =+U31/U19-1 -> -0.40514611 | AB31: =+V31/V19-1 -> 0.037741849 | AC31: =+W31/W19-1 -> -0.32913074
A32: =+EOMONTH(A31,1) -> 41882 | B32: 9141 | C32: 16287 | D32: 4117 | E32: =+C32+B32+D32 -> 29545 | H32: =+SUM(B30:B32) -> 28486 | I32: =+SUM(C30:C32) -> 49863 | J32: =+SUM(D30:D32) -> 11620 | K32: =+H32+I32+J32 -> 89969 | N32: =+H32/H20-1 -> -0.022342726 | O32: =+I32/I20-1 -> -0.35486667 | P32: =+J32/J20-1 -> 0.064785119 | Q32: =+K32/K20-1 -> -0.23326885 | T32: =+SUM(B21:B32) -> 106949 | U32: =+SUM(C21:C32) -> 221228 | V32: =+SUM(D21:D32) -> 42664 | W32: =+SUM(E21:E32) -> 370841 | Z32: =+T32/T20-1 -> -0.17878725 | AA32: =+U32/U20-1 -> -0.41909293 | AB32: =+V32/V20-1 -> 0.036565514 | AC32: =+W32/W20-1 -> -0.3284591
A33: =+EOMONTH(A32,1) -> 41912 | B33: 10404 | C33: 18539 | D33: 4849 | E33: =+C33+B33+D33 -> 33792 | H33: =+SUM(B31:B33) -> 29270 | I33: =+SUM(C31:C33) -> 51190 | J33: =+SUM(D31:D33) -> 12962 | K33: =+H33+I33+J33 -> 93422 | N33: =+H33/H21-1 -> 0.091268362 | O33: =+I33/I21-1 -> -0.32482161 | P33: =+J33/J21-1 -> 0.069736734 | Q33: =+K33/K21-1 -> -0.18590749 | T33: =+SUM(B22:B33) -> 108538 | U33: =+SUM(C22:C33) -> 215463 | V33: =+SUM(D22:D33) -> 42854 | W33: =+SUM(E22:E33) -> 366855 | Z33: =+T33/T21-1 -> -0.12300321 | AA33: =+U33/U21-1 -> -0.42039796 | AB33: =+V33/V21-1 -> 0.041181759 | AC33: =+W33/W21-1 -> -0.31641458
A34: =+EOMONTH(A33,1) -> 41943 | B34: 10352 | C34: 16897 | D34: 3780 | E34: =+C34+B34+D34 -> 31029 | H34: =+SUM(B32:B34) -> 29897 | I34: =+SUM(C32:C34) -> 51723 | J34: =+SUM(D32:D34) -> 12746 | K34: =+H34+I34+J34 -> 94366 | N34: =+H34/H22-1 -> 0.19592784 | O34: =+I34/I22-1 -> -0.30166338 | P34: =+J34/J22-1 -> 0.0015715857 | Q34: =+K34/K22-1 -> -0.15587122 | T34: =+SUM(B23:B34) -> 110955 | U34: =+SUM(C23:C34) -> 207502 | V34: =+SUM(D23:D34) -> 42446 | W34: =+SUM(E23:E34) -> 360903 | Z34: =+T34/T22-1 -> -0.072096407 | AA34: =+U34/U22-1 -> -0.42630828 | AB34: =+V34/V22-1 -> 0.011365532 | AC34: =+W34/W22-1 -> -0.31025474
A35: =+EOMONTH(A34,1) -> 41973 | B35: 9452 | C35: 15954 | D35: 3959 | E35: =+C35+B35+D35 -> 29365 | H35: =+SUM(B33:B35) -> 30208 | I35: =+SUM(C33:C35) -> 51390 | J35: =+SUM(D33:D35) -> 12588 | K35: =+H35+I35+J35 -> 94186 | N35: =+H35/H23-1 -> 0.28146608 | O35: =+I35/I23-1 -> -0.2568867 | P35: =+J35/J23-1 -> 0.036305261 | Q35: =+K35/K23-1 -> -0.10192133 | T35: =+SUM(B24:B35) -> 113584 | U35: =+SUM(C24:C35) -> 203463 | V35: =+SUM(D24:D35) -> 43105 | W35: =+SUM(E24:E35) -> 360152 | Z35: =+T35/T23-1 -> -0.02839937 | AA35: =+U35/U23-1 -> -0.41341633 | AB35: =+V35/V23-1 -> 0.027067598 | AC35: =+W35/W23-1 -> -0.28786279
A36: =+EOMONTH(A35,1) -> 42004 | B36: 12438 | C36: 13298 | D36: 3815 | E36: =+C36+B36+D36 -> 29551 | H36: =+SUM(B34:B36) -> 32242 | I36: =+SUM(C34:C36) -> 46149 | J36: =+SUM(D34:D36) -> 11554 | K36: =+H36+I36+J36 -> 89945 | N36: =+H36/H24-1 -> 0.43828345 | O36: =+I36/I24-1 -> -0.26666137 | P36: =+J36/J24-1 -> 0.14294193 | Q36: =+K36/K24-1 -> -0.057733406 | T36: =+SUM(B25:B36) -> 118363 | U36: =+SUM(C25:C36) -> 198682 | V36: =+SUM(D25:D36) -> 44299 | W36: =+SUM(E25:E36) -> 361344 | Z36: =+T36/T24-1 -> 0.031962475 | AA36: =+U36/U24-1 -> -0.39295 | AB36: =+V36/V24-1 -> 0.076106496 | AC36: =+W36/W24-1 -> -0.25211423
A37: =+EOMONTH(A36,1) -> 42035 | B37: 11273 | C37: 14301 | D37: 3714 | E37: =+C37+B37+D37 -> 29288 | H37: =+SUM(B35:B37) -> 33163 | I37: =+SUM(C35:C37) -> 43553 | J37: =+SUM(D35:D37) -> 11488 | K37: =+H37+I37+J37 -> 88204 | N37: =+H37/H25-1 -> 0.46427941 | O37: =+I37/I25-1 -> -0.21651766 | P37: =+J37/J25-1 -> 0.23420713 | Q37: =+K37/K25-1 -> 0.0075275573 | T37: =+SUM(B26:B37) -> 121470 | U37: =+SUM(C26:C37) -> 195466 | V37: =+SUM(D26:D37) -> 44626 | W37: =+SUM(E26:E37) -> 361562 | Z37: =+T37/T25-1 -> 0.064210056 | AA37: =+U37/U25-1 -> -0.37140909 | AB37: =+V37/V25-1 -> 0.083891965 | AC37: =+W37/W25-1 -> -0.22456849
A38: =+EOMONTH(A37,1) -> 42063 | B38: 12190 | C38: 14357 | D38: 3726 | E38: =+C38+B38+D38 -> 30273 | H38: =+SUM(B36:B38) -> 35901 | I38: =+SUM(C36:C38) -> 41956 | J38: =+SUM(D36:D38) -> 11255 | K38: =+H38+I38+J38 -> 89112 | N38: =+H38/H26-1 -> 0.43984118 | O38: =+I38/I26-1 -> -0.16880956 | P38: =+J38/J26-1 -> 0.10289074 | Q38: =+K38/K26-1 -> 0.040833489 | T38: =+SUM(B27:B38) -> 124551 | U38: =+SUM(C27:C38) -> 194942 | V38: =+SUM(D27:D38) -> 44155 | W38: =+SUM(E27:E38) -> 363648 | Z38: =+T38/T26-1 -> 0.10593051 | AA38: =+U38/U26-1 -> -0.32564688 | AB38: =+V38/V26-1 -> 0.052888857 | AC38: =+W38/W26-1 -> -0.18030466
... A99: =+EOMONTH(A98,1) -> 43921 | B99: 2819 | C99: 2517 | D99: 1787 | E99: =+C99+B99+D99 -> 7123 | H99: =+SUM(B97:B99) -> 23849 | I99: =+SUM(C97:C99) -> 38407 | J99: =+SUM(D97:D99) -> 6813 | K99: =+H99+I99+J99 -> 69069 | N99: =+H99/H87-1 -> -0.55017164 | O99: =+I99/I87-1 -> -0.48167991 | P99: =+J99/J87-1 -> -0.40632625 | Q99: =+K99/K87-1 -> -0.5016415 | T99: =+SUM(B88:B99) -> 111752 | U99: =+SUM(C88:C99) -> 198409 | V99: =+SUM(D88:D99) -> 29792 | W99: =+SUM(E88:E99) -> 339953 | Z99: =+T99/T87-1 -> -0.42626258 | AA99: =+U99/U87-1 -> -0.27564957 | AB99: =+V99/V87-1 -> -0.41681511 | AC99: =+W99/W87-1 -> -0.34596375
A100: =+EOMONTH(A99,1) -> 43951 | B100: 3000 | C100: 3000 | E100: =+C100+B100+D100 -> 6000 | H100: =+SUM(B98:B100) -> 15924 | I100: =+SUM(C98:C100) -> 20984 | J100: =+SUM(D98:D100) -> 4301 | K100: =+H100+I100+J100 -> 41209 | N100: =+H100/H88-1 -> -0.67901633 | O100: =+I100/I88-1 -> -0.69853607 | P100: =+J100/J88-1 -> -0.55600289 | Q100: =+K100/K88-1 -> -0.68031248 | T100: =+SUM(B89:B100) -> 102581 | U100: =+SUM(C89:C100) -> 184391 | V100: =+SUM(D89:D100) -> 28495 | W100: =+SUM(E89:E100) -> 315467 | Z100: =+T100/T88-1 -> -0.46117764 | AA100: =+U100/U88-1 -> -0.32015485 | AB100: =+V100/V88-1 -> -0.42401763 | AC100: =+W100/W88-1 -> -0.38274076
A101: =+EOMONTH(A100,1) -> 43982 | B101: 3000 | C101: 3000 | E101: =+C101+B101+D101 -> 6000 | H101: =+SUM(B99:B101) -> 8819 | I101: =+SUM(C99:C101) -> 8517 | J101: =+SUM(D99:D101) -> 1787 | K101: =+H101+I101+J101 -> 19123 | N101: =+H101/H89-1 -> -0.80143201 | O101: =+I101/I89-1 -> -0.86901356 | P101: =+J101/J89-1 -> -0.78700834 | Q101: =+K101/K89-1 -> -0.83769998 | T101: =+SUM(B90:B101) -> 94472 | U101: =+SUM(C90:C101) -> 169171 | V101: =+SUM(D90:D101) -> 27021 | W101: =+SUM(E90:E101) -> 290664 | Z101: =+T101/T89-1 -> -0.49120794 | AA101: =+U101/U89-1 -> -0.36982071 | AB101: =+V101/V89-1 -> -0.42904535 | AC101: =+W101/W89-1 -> -0.4203576
...

Sheet Monthly Nos Vahan
A1: Vahan Registrations
A3: Month | B3: Registrations | C3: YoY% | E3: 3M Rolling | F3: QoQ% | G3: YoY% | I3: 12M Rolling | J3: YoY%
A4: 44197
A5: =+EOMONTH(A4,1) -> 44255
A6: =+EOMONTH(A5,1) -> 44286
A7: =+EOMONTH(A6,1) -> 44316
A8: =+EOMONTH(A7,1) -> 44347
A9: =+EOMONTH(A8,1) -> 44377
A10: =+EOMONTH(A9,1) -> 44408
A11: =+EOMONTH(A10,1) -> 44439
A12: =+EOMONTH(A11,1) -> 44469
A13: =+EOMONTH(A12,1) -> 44500
A14: =+EOMONTH(A13,1) -> 44530
A15: =+EOMONTH(A14,1) -> 44561
A16: =+EOMONTH(A15,1) -> 44592
A17: =+EOMONTH(A16,1) -> 44620 | B17: 35748
A18: =+EOMONTH(A17,1) -> 44651 | B18: 38458
A19: =+EOMONTH(A18,1) -> 44681 | B19: 36650 | E19: =+SUM(B17:B19) -> 110856
A20: =+EOMONTH(A19,1) -> 44712 | B20: 30256 | E20: =+SUM(B18:B20) -> 105364 | F20: =+E20/E19-1 -> -0.049541748
A21: =+EOMONTH(A20,1) -> 44742 | B21: 30238 | E21: =+SUM(B19:B21) -> 97144 | F21: =+E21/E20-1 -> -0.078015261
A22: =+EOMONTH(A21,1) -> 44773 | B22: 29389 | E22: =+SUM(B20:B22) -> 89883 | F22: =+E22/E21-1 -> -0.074744709
A23: =+EOMONTH(A22,1) -> 44804 | B23: 29910 | E23: =+SUM(B21:B23) -> 89537 | F23: =+E23/E22-1 -> -0.0038494487
A24: =+EOMONTH(A23,1) -> 44834 | B24: 30811 | E24: =+SUM(B22:B24) -> 90110 | F24: =+E24/E23-1 -> 0.006399589
A25: =+EOMONTH(A24,1) -> 44865 | B25: 29402 | E25: =+SUM(B23:B25) -> 90123 | F25: =+E25/E24-1 -> 0.00014426812
A26: =+EOMONTH(A25,1) -> 44895 | B26: 32717 | E26: =+SUM(B24:B26) -> 92930 | F26: =+E26/E25-1 -> 0.031146322
A27: =+EOMONTH(A26,1) -> 44926 | B27: 28400 | E27: =+SUM(B25:B27) -> 90519 | F27: =+E27/E26-1 -> -0.025944259
A28: =+EOMONTH(A27,1) -> 44957 | B28: 34438 | E28: =+SUM(B26:B28) -> 95555 | F28: =+E28/E27-1 -> 0.055634729 | I28: =+SUM(B17:B28) -> 386417
A29: =+EOMONTH(A28,1) -> 44985 | B29: 32587 | C29: =+B29/B17-1 -> -0.088424527 | E29: =+SUM(B27:B29) -> 95425 | F29: =+E29/E28-1 -> -0.001360473 | I29: =+SUM(B18:B29) -> 383256
A30: =+EOMONTH(A29,1) -> 45016 | B30: 38197 | C30: =+B30/B18-1 -> -0.0067866244 | E30: =+SUM(B28:B30) -> 105222 | F30: =+E30/E29-1 -> 0.10266702 | I30: =+SUM(B19:B30) -> 382995
A31: =+EOMONTH(A30,1) -> 45046 | B31: 34453 | C31: =+B31/B19-1 -> -0.05994543 | E31: =+SUM(B29:B31) -> 105237 | F31: =+E31/E30-1 -> 0.00014255574 | G31: =+E31/E19-1 -> -0.050687378 | I31: =+SUM(B20:B31) -> 380798
A32: =+EOMONTH(A31,1) -> 45077 | B32: 27485 | C32: =+B32/B20-1 -> -0.09158514 | E32: =+SUM(B30:B32) -> 100135 | F32: =+E32/E31-1 -> -0.048481048 | G32: =+E32/E20-1 -> -0.049627956 | I32: =+SUM(B21:B32) -> 378027
A33: =+EOMONTH(A32,1) -> 45107 | B33: 27608 | C33: =+B33/B21-1 -> -0.086976652 | E33: =+SUM(B31:B33) -> 89546 | F33: =+E33/E32-1 -> -0.10574724 | G33: =+E33/E21-1 -> -0.078213786 | I33: =+SUM(B22:B33) -> 375397
A34: =+EOMONTH(A33,1) -> 45138 | B34: 28446 | C34: =+B34/B22-1 -> -0.032086835 | E34: =+SUM(B32:B34) -> 83539 | F34: =+E34/E33-1 -> -0.06708284 | G34: =+E34/E22-1 -> -0.070580644 | I34: =+SUM(B23:B34) -> 374454
A35: =+EOMONTH(A34,1) -> 45169 | B35: 29189 | C35: =+B35/B23-1 -> -0.02410565 | E35: =+SUM(B33:B35) -> 85243 | F35: =+E35/E34-1 -> 0.020397659 | G35: =+E35/E23-1 -> -0.047957827 | I35: =+SUM(B24:B35) -> 373733
A36: =+EOMONTH(A35,1) -> 45199 | B36: 30479 | C36: =+B36/B24-1 -> -0.010775372 | E36: =+SUM(B34:B36) -> 88114 | F36: =+E36/E35-1 -> 0.033680185 | G36: =+E36/E24-1 -> -0.022150705 | I36: =+SUM(B25:B36) -> 373401
A37: =+EOMONTH(A36,1) -> 45230 | B37: 33554 | C37: =+B37/B25-1 -> 0.14121488 | E37: =+SUM(B35:B37) -> 93222 | F37: =+E37/E36-1 -> 0.057970357 | G37: =+E37/E25-1 -> 0.034386339 | I37: =+SUM(B26:B37) -> 377553
A38: =+EOMONTH(A37,1) -> 45260 | B38: 31152 | C38: =+B38/B26-1 -> -0.047834459 | E38: =+SUM(B36:B38) -> 95185 | F38: =+E38/E37-1 -> 0.021057261 | G38: =+E38/E26-1 -> 0.024265576 | I38: =+SUM(B27:B38) -> 375988
