Workbook

Sheet Template
A1: =+'Annual Raw'!C4 -> Tata Power Company Ltd. | B1: 36951 | C1: =EOMONTH(B1,12) -> 37346 | D1: =EOMONTH(C1,12) -> 37711 | E1: =EOMONTH(D1,12) -> 38077 | F1: =EOMONTH(E1,12) -> 38442 | G1: =EOMONTH(F1,12) -> 38807 | H1: =EOMONTH(G1,12) -> 39172 | I1: =EOMONTH(H1,12) -> 39538 | J1: =EOMONTH(I1,12) -> 39903 | ... AE1: =EOMONTH(AD1,12) -> 47573 | AH1: QTR | AI1: 41061 | AJ1: 41153 | AK1: 41244 | AL1: 41334 | AM1: 41426 | AN1: 41518 | AO1: 41609 | AP1: 41699 | AQ1: 41791 | AR1: 41883 | AS1: 41974 | AT1: 42064 | AU1: 42156 | AV1: 42248 | AW1: 42339 | AX1: 42430 | AY1: 42522 | AZ1: 42614 | BA1: 42705 | BB1: 42795 | BC1: 42887 | BD1: 42979 | BE1: 43070 | BF1: 43160 | BG1: 43252 | BH1: 43344 | BI1: 43435 | BJ1: 43525 | BK1: 43617 | BL1: 43709 | BM1: 43800 | BN1: 43891 | BO1: 43983 | BP1: 44075 | BQ1: =EOMONTH(BP1,3) -> 44196 | BR1: =EOMONTH(BQ1,3) -> 44286 | BS1: =EOMONTH(BR1,3) -> 44377 | BT1: =EOMONTH(BS1,3) -> 44469 | BU1: =EOMONTH(BT1,3) -> 44561 | BV1: =EOMONTH(BU1,3) -> 44651 | BW1: =EOMONTH(BV1,3) -> 44742 | BX1: =EOMONTH(BW1,3) -> 44834 | ... DB1: =EOMONTH(DA1,3) -> 47573 | DE1: HISTORICAL ESTIMATES | DF1: 46112
A2: Presentation Data (Start)
A4: Sales - Segment wise
A5: Thermal Generation, Coal and Hydro | X5: =SUM(X6:X9) -> 18212 | Y5: =SUM(Y6:Y9) -> 19613 | Z5: =SUM(Z6:Z9) -> 19740 | AA5: =SUM(AA6:AA9) -> 11630 | AB5: =SUM(AB6:AB9) -> 17827 | AC5: =SUM(AC6:AC9) -> 20552 | AD5: =SUM(AD6:AD9) -> 20552 | AE5: =SUM(AE6:AE9) -> 20552 | BW5: =SUM(BW6:BW9) -> 5125 | BX5: =SUM(BX6:BX9) -> 4834 | BY5: =SUM(BY6:BY9) -> 5370 | BZ5: =SUM(BZ6:BZ9) -> 2883 | CA5: =SUM(CA6:CA9) -> 4827 | CB5: =SUM(CB6:CB9) -> 4973 | CC5: =SUM(CC6:CC9) -> 4958 | CD5: =SUM(CD6:CD9) -> 4855 | ... DB5: =SUM(DB6:DB9) -> 5159
A6: Maithon Power Limited (MPL) | X6: =SUM(BW6:BZ6) -> 3029 | Y6: =SUM(CA6:CD6) -> 3359 | Z6: =SUM(CE6:CH6) -> 2955 | AA6: =SUM(CI6:CL6) -> 3095 | AB6: =SUM(CM6:CP6) -> 3095 | AC6: =SUM(CQ6:CT6) -> 3095 | AD6: =SUM(CU6:CX6) -> 3095 | AE6: =SUM(CY6:DB6) -> 3095 | BW6: 754 | BX6: 810 | BY6: 809 | BZ6: 656 | CA6: 850 | CB6: 761 | CC6: 845 | CD6: 903 | CE6: 819 | CF6: 767 | CG6: 640 | CH6: 729 | CI6: 771 | CJ6: 829 | CK6: 695 | CL6: 800 | CM6: =CI6 -> 771 | CN6: =CJ6 -> 829 | CO6: =CK6 -> 695 | CP6: =CL6 -> 800 | CQ6: =CM6 -> 771 | CR6: =CN6 -> 829 | CS6: =CO6 -> 695 | CT6: =CP6 -> 800 | ... DB6: =CX6 -> 800
A7: Traditional Generation (incl. Mumbai and Hydro) | X7: =SUM(BW7:BZ7) -> 6884 | Y7: =SUM(CA7:CD7) -> 5880 | Z7: =SUM(CE7:CH7) -> 5262 | AA7: =SUM(CI7:CL7) -> 5124 | AB7: =SUM(CM7:CP7) -> 5124 | AC7: =SUM(CQ7:CT7) -> 5124 | AD7: =SUM(CU7:CX7) -> 5124 | AE7: =SUM(CY7:DB7) -> 5124 | BW7: 1978 | BX7: 1725 | BY7: 1671 | BZ7: 1510 | CA7: 1596 | CB7: 1422 | CC7: 1455 | CD7: 1407 | CE7: 1563 | CF7: 1402 | CG7: 927 | CH7: 1370 | CI7: 1266 | CJ7: 1291 | CK7: 1246 | CL7: 1321 | CM7: =CI7 -> 1266 | CN7: =CJ7 -> 1291 | CO7: =CK7 -> 1246 | CP7: =CL7 -> 1321 | CQ7: =CM7 -> 1266 | CR7: =CN7 -> 1291 | CS7: =CO7 -> 1246 | CT7: =CP7 -> 1321 | ... DB7: =CX7 -> 1321
A8: Others (Incl. eliminations) | X8: =SUM(BW8:BZ8) -> 130 | Y8: =SUM(CA8:CD8) -> 131 | Z8: =SUM(CE8:CH8) -> 126 | AA8: =SUM(CI8:CL8) -> 133 | AB8: =SUM(CM8:CP8) -> 133 | AC8: =SUM(CQ8:CT8) -> 133 | AD8: =SUM(CU8:CX8) -> 133 | AE8: =SUM(CY8:DB8) -> 133 | BW8: 32 | BX8: 30 | BY8: 34 | BZ8: 34 | CA8: 32 | CB8: 34 | CC8: 35 | CD8: 30 | CE8: 32 | CF8: 31 | CG8: 33 | CH8: 30 | CI8: 27 | CJ8: 33 | CK8: 35 | CL8: 38 | CM8: =CI8 -> 27 | CN8: =CJ8 -> 33 | CO8: =CK8 -> 35 | CP8: =CL8 -> 38 | CQ8: =CM8 -> 27 | CR8: =CN8 -> 33 | CS8: =CO8 -> 35 | CT8: =CP8 -> 38 | ... DB8: =CX8 -> 38
A9: Mundra, Coal and Shipping | X9: =SUM(BW9:BZ9) -> 8169 | Y9: =SUM(CA9:CD9) -> 10243 | Z9: =SUM(CE9:CH9) -> 11397 | AA9: =SUM(CI9:CL9) -> 3278 | AB9: =SUM(CM9:CP9) -> 9475 | AC9: =SUM(CQ9:CT9) -> 12200 | AD9: =SUM(CU9:CX9) -> 12200 | AE9: =SUM(CY9:DB9) -> 12200 | BW9: 2361 | BX9: 2269 | BY9: 2856 | BZ9: 683 | CA9: 2349 | CB9: 2756 | CC9: 2623 | CD9: 2515 | CE9: 2803 | CF9: 2110 | CG9: 3325 | CH9: 3159 | CI9: 2780 | CJ9: 177 | CK9: 46 | CL9: 275 | CM9: =CL9 -> 275 | CN9: 3200 | CO9: 3000 | CP9: 3000 | CQ9: 3000 | CR9: =CN9 -> 3200 | CS9: =CO9 -> 3000 | CT9: =CP9 -> 3000 | CU9: =CQ9 -> 3000 | CV9: =CR9 -> 3200 | CW9: =CS9 -> 3000 | CX9: =CT9 -> 3000 | CY9: =CU9 -> 3000 | ... DB9: =CX9 -> 3000
A11: Renewables | X11: =SUM(X12:X15) -> 8197 | Y11: =SUM(Y12:Y15) -> 10176 | Z11: =SUM(Z12:Z15) -> 9883 | AA11: =SUM(AA12:AA15) -> 15026 | AB11: =SUM(AB12:AB15) -> 17897.943 | AC11: =SUM(AC12:AC15) -> 19842.7 | AD11: =SUM(AD12:AD15) -> 22861.377 | AE11: =SUM(AE12:AE15) -> 26290.926 | BW11: =SUM(BW12:BW15) -> 2090 | BX11: =SUM(BX12:BX15) -> 1603 | BY11: =SUM(BY12:BY15) -> 1917 | BZ11: =SUM(BZ12:BZ15) -> 2587 | CA11: =SUM(CA12:CA15) -> 2089 | CB11: =SUM(CB12:CB15) -> 2146 | CC11: =SUM(CC12:CC15) -> 2484 | CD11: =SUM(CD12:CD15) -> 3457 | ... DB11: =SUM(DB12:DB15) -> 6427.5063
A12: RE Gencos (Incl. CSL) | X12: =SUM(BW12:BZ12) -> 3206 | Y12: =SUM(CA12:CD12) -> 3427 | Z12: =SUM(CE12:CH12) -> 3809 | AA12: =SUM(CI12:CL12) -> 4130 | AB12: =SUM(CM12:CP12) -> 4543 | AC12: =SUM(CQ12:CT12) -> 4997.3 | AD12: =SUM(CU12:CX12) -> 5746.895 | AE12: =SUM(CY12:DB12) -> 6608.9293 | BW12: 905 | BX12: 806 | BY12: 704 | BZ12: 791 | CA12: 933 | CB12: 910 | CC12: 737 | CD12: 847 | CE12: 1002 | CF12: 959 | CG12: 827 | CH12: 1021 | CI12: 1135 | CJ12: 991 | CK12: 978 | CL12: 1026 | CM12: =CI12*(1+CM38) -> 1248.5 | CN12: =CJ12*(1+CN38) -> 1090.1 | CO12: =CK12*(1+CO38) -> 1075.8 | CP12: =CL12*(1+CP38) -> 1128.6 | CQ12: =CM12*(1+CQ38) -> 1373.35 | CR12: =CN12*(1+CR38) -> 1199.11 | CS12: =CO12*(1+CS38) -> 1183.38 | CT12: =CP12*(1+CT38) -> 1241.46 | ... DB12: =CX12*(1+DB38) -> 1641.8309
A13: Solar EPC (TPSSL) | X13: =SUM(BW13:BZ13) -> 6876 | Y13: =SUM(CA13:CD13) -> 11726 | Z13: =SUM(CE13:CH13) -> 10043 | AA13: =SUM(CI13:CL13) -> 9797 | AB13: =SUM(CM13:CP13) -> 10874.67 | AC13: =SUM(CQ13:CT13) -> 12070.884 | AD13: =SUM(CU13:CX13) -> 13881.516 | AE13: =SUM(CY13:DB13) -> 15963.744 | BW13: 1353 | BX13: 1135 | BY13: 1430 | BZ13: 2958 | CA13: 1492 | CB13: 1910 | CC13: 4037 | CD13: 4287 | CE13: 2171 | CF13: 3013 | CG13: 1749 | CH13: 3110 | CI13: 2508 | CJ13: 2667 | CK13: 2414 | CL13: 2208 | CM13: =CI13*(1+CM39) -> 2783.88 | CN13: =CJ13*(1+CN39) -> 2960.37 | CO13: =CK13*(1+CO39) -> 2679.54 | CP13: =CL13*(1+CP39) -> 2450.88 | CQ13: =CM13*(1+CQ39) -> 3090.1068 | CR13: =CN13*(1+CR39) -> 3286.0107 | CS13: =CO13*(1+CS39) -> 2974.2894 | CT13: =CP13*(1+CT39) -> 2720.4768 | ... DB13: =CX13*(1+DB39) -> 3597.8306
A14: TP solar (4.3GW cell & module manufacturing plant | X14: =SUM(BW14:BZ14) -> 0 | Y14: =SUM(CA14:CD14) -> 233 | Z14: =SUM(CE14:CH14) -> 5337 | AA14: =SUM(CI14:CL14) -> 6968 | AB14: =SUM(CM14:CP14) -> 7734.48 | AC14: =SUM(CQ14:CT14) -> 8585.2728 | AD14: =SUM(CU14:CX14) -> 9873.0637 | AE14: =SUM(CY14:DB14) -> 11354.023 | CA14: 0 | CB14: 0 | CC14: 0 | CD14: 233 | CE14: 1068 | CF14: 1410 | CG14: 1353 | CH14: 1506 | CI14: 1613 | CJ14: 1772 | CK14: 1704 | CL14: 1879 | CM14: =CI14*(1+CM40) -> 1790.43 | CN14: =CJ14*(1+CN40) -> 1966.92 | CO14: =CK14*(1+CO40) -> 1891.44 | CP14: =CL14*(1+CP40) -> 2085.69 | CQ14: =CM14*(1+CQ40) -> 1987.3773 | CR14: =CN14*(1+CR40) -> 2183.2812 | CS14: =CO14*(1+CS40) -> 2099.4984 | CT14: =CP14*(1+CT40) -> 2315.1159 | ... DB14: =CX14*(1+DB40) -> 3061.7408
A15: Others (Incl. eliminations#) | X15: =SUM(BW15:BZ15) -> -1885 | Y15: =SUM(CA15:CD15) -> -5210 | Z15: =SUM(CE15:CH15) -> -9306 | AA15: =SUM(CI15:CL15) -> -5869 | AB15: =SUM(CM15:CP15) -> -5254.2075 | AC15: =SUM(CQ15:CT15) -> -5810.7568 | AD15: =SUM(CU15:CX15) -> -6640.0977 | AE15: =SUM(CY15:DB15) -> -7635.7699 | BW15: -168 | BX15: -338 | BY15: -217 | BZ15: -1162 | CA15: -336 | CB15: -674 | CC15: -2290 | CD15: -1910 | CE15: -1858 | CF15: -3462 | CG15: -1806 | CH15: -2180 | CI15: -1631 | CJ15: -1817 | CK15: -1312 | CL15: -1109 | CM15: =CL11*-30% -> -1201.2 | CN15: =CM11*-30% -> -1386.483 | CO15: =CN11*-30% -> -1389.2721 | CP15: =CO11*-30% -> -1277.2524 | CQ15: =CP11*-30% -> -1316.3753 | CR15: =CQ11*-30% -> -1540.3376 | CS15: =CR11*-30% -> -1538.4193 | CT15: =CS11*-30% -> -1415.6246 | ... DB15: =DA11*-30% -> -1873.8959
A17: Transmission & Distribution Services | X17: =SUM(X18:X19) -> 34533 | Y17: =SUM(Y18:Y19) -> 36206 | Z17: =SUM(Z18:Z19) -> 39122 | AA17: =SUM(AA18:AA19) -> 40890 | AB17: =SUM(AB18:AB19) -> 42617.81 | AC17: =SUM(AC18:AC19) -> 44486.497 | AD17: =SUM(AD18:AD19) -> 46669.139 | AE17: =SUM(AE18:AE19) -> 49050.704 | BW17: =SUM(BW18:BW19) -> 8961 | BX17: =SUM(BX18:BX19) -> 9020 | BY17: =SUM(BY18:BY19) -> 8256 | BZ17: =SUM(BZ18:BZ19) -> 8296 | CA17: =SUM(CA18:CA19) -> 9277 | CB17: =SUM(CB18:CB19) -> 9453 | CC17: =SUM(CC18:CC19) -> 8451 | CD17: =SUM(CD18:CD19) -> 9025 | ... DB17: =SUM(DB18:DB19) -> 12348.488
A18: Transmission | X18: =SUM(BW18:BZ18) -> 1111 | Y18: =SUM(CA18:CD18) -> 1261 | Z18: =SUM(CE18:CH18) -> 1413 | AA18: =SUM(CI18:CL18) -> 1354 | AB18: =SUM(CM18:CP18) -> 1394.62 | AC18: =SUM(CQ18:CT18) -> 1436.4586 | AD18: =SUM(CU18:CX18) -> 1479.5524 | AE18: =SUM(CY18:DB18) -> 1523.9389 | BW18: 249 | BX18: 249 | BY18: 254 | BZ18: 359 | CA18: 298 | CB18: 288 | CC18: 296 | CD18: 379 | CE18: 329 | CF18: 336 | CG18: 329 | CH18: 419 | CI18: 317 | CJ18: 309 | CK18: 314 | CL18: 414 | CM18: =CI18*(1+CM43) -> 326.51 | CN18: =CJ18*(1+CN43) -> 318.27 | CO18: =CK18*(1+CO43) -> 323.42 | CP18: =CL18*(1+CP43) -> 426.42 | CQ18: =CM18*(1+CQ43) -> 336.3053 | CR18: =CN18*(1+CR43) -> 327.8181 | CS18: =CO18*(1+CS43) -> 333.1226 | CT18: =CP18*(1+CT43) -> 439.2126 | ... DB18: =CX18*(1+DB43) -> 465.96065
A19: Distribution and Services | X19: =SUM(X20:X23) -> 33422 | Y19: =SUM(Y20:Y23) -> 34945 | Z19: =SUM(Z20:Z23) -> 37709 | AA19: =SUM(AA20:AA23) -> 39536 | AB19: =SUM(AB20:AB23) -> 41223.19 | AC19: =SUM(AC20:AC23) -> 43050.038 | AD19: =SUM(AD20:AD23) -> 45189.587 | AE19: =SUM(AE20:AE23) -> 47526.765 | BW19: =SUM(BW20:BW23) -> 8712 | BX19: =SUM(BX20:BX23) -> 8771 | BY19: =SUM(BY20:BY23) -> 8002 | BZ19: =SUM(BZ20:BZ23) -> 7937 | CA19: =SUM(CA20:CA23) -> 8979 | CB19: =SUM(CB20:CB23) -> 9165 | CC19: =SUM(CC20:CC23) -> 8155 | CD19: =SUM(CD20:CD23) -> 8646 | ... DB19: =SUM(DB20:DB23) -> 11882.527
A20: Mumbai | X20: =SUM(BW20:BZ20) -> 4972 | Y20: =SUM(CA20:CD20) -> 4388 | Z20: =SUM(CE20:CH20) -> 4418 | AA20: =SUM(CI20:CL20) -> 4569 | AB20: =SUM(CM20:CP20) -> 4934.52 | AC20: =SUM(CQ20:CT20) -> 5329.2816 | AD20: =SUM(CU20:CX20) -> 5915.5026 | AE20: =SUM(CY20:DB20) -> 6566.2079 | BW20: 1444 | BX20: 1227 | BY20: 1206 | BZ20: 1095 | CA20: 1183 | CB20: 1057 | CC20: 1089 | CD20: 1059 | CE20: 1240 | CF20: 1146 | CG20: 972 | CH20: 1060 | CI20: 1178 | CJ20: 1129 | CK20: 1091 | CL20: 1171 | CM20: =CI20*(1+CM45) -> 1272.24 | CN20: =CJ20*(1+CN45) -> 1219.32 | CO20: =CK20*(1+CO45) -> 1178.28 | CP20: =CL20*(1+CP45) -> 1264.68 | CQ20: =CM20*(1+CQ45) -> 1374.0192 | CR20: =CN20*(1+CR45) -> 1316.8656 | CS20: =CO20*(1+CS45) -> 1272.5424 | CT20: =CP20*(1+CT45) -> 1365.8544 | ... DB20: =CX20*(1+DB45) -> 1682.8692
A21: Odisha | X21: =SUM(BW21:BZ21) -> 16460 | Y21: =SUM(CA21:CD21) -> 18435 | Z21: =SUM(CE21:CH21) -> 19692 | AA21: =SUM(CI21:CL21) -> 19998 | AB21: =SUM(CM21:CP21) -> 20197.98 | AC21: =SUM(CQ21:CT21) -> 20399.96 | AD21: =SUM(CU21:CX21) -> 20603.959 | AE21: =SUM(CY21:DB21) -> 20809.999 | BW21: 3961 | BX21: 4226 | BY21: 4096 | BZ21: 4177 | CA21: 4622 | CB21: 4678 | CC21: 4396 | CD21: 4739 | CE21: 5156 | CF21: 4815 | CG21: 4589 | CH21: 5132 | CI21: 5164 | CJ21: 5198 | CK21: 4621 | CL21: 5015 | CM21: =CI21*(1+CM46) -> 5215.64 | CN21: =CJ21*(1+CN46) -> 5249.98 | CO21: =CK21*(1+CO46) -> 4667.21 | CP21: =CL21*(1+CP46) -> 5065.15 | CQ21: =CM21*(1+CQ46) -> 5267.7964 | CR21: =CN21*(1+CR46) -> 5302.4798 | CS21: =CO21*(1+CS46) -> 4713.8821 | CT21: =CP21*(1+CT46) -> 5115.8015 | ... DB21: =CX21*(1+DB46) -> 5218.6291
A22: Delhi | X22: =SUM(BW22:BZ22) -> 10381 | Y22: =SUM(CA22:CD22) -> 10027 | Z22: =SUM(CE22:CH22) -> 10303 | AA22: =SUM(CI22:CL22) -> 10800 | AB22: =SUM(CM22:CP22) -> 11880 | AC22: =SUM(CQ22:CT22) -> 13068 | AD22: =SUM(CU22:CX22) -> 14374.8 | AE22: =SUM(CY22:DB22) -> 15812.28 | BW22: 3124 | BX22: 2964 | BY22: 2236 | BZ22: 2057 | CA22: 2805 | CB22: 2940 | CC22: 2231 | CD22: 2051 | CE22: 2992 | CF22: 3105 | CG22: 2182 | CH22: 2024 | CI22: 2400 | CJ22: 3147 | CK22: 2460 | CL22: 2793 | CM22: =CI22*(1+CM47) -> 2640 | CN22: =CJ22*(1+CN47) -> 3461.7 | CO22: =CK22*(1+CO47) -> 2706 | CP22: =CL22*(1+CP47) -> 3072.3 | CQ22: =CM22*(1+CQ47) -> 2904 | CR22: =CN22*(1+CR47) -> 3807.87 | CS22: =CO22*(1+CS47) -> 2976.6 | CT22: =CP22*(1+CT47) -> 3379.53 | ... DB22: =CX22*(1+DB47) -> 4089.2313
A23: Others (T&D incl, TPADL, TPTCL and eliminations) | X23: =SUM(BW23:BZ23) -> 1609 | Y23: =SUM(CA23:CD23) -> 2095 | Z23: =SUM(CE23:CH23) -> 3296 | AA23: =SUM(CI23:CL23) -> 4169 | AB23: =SUM(CM23:CP23) -> 4210.69 | AC23: =SUM(CQ23:CT23) -> 4252.7969 | AD23: =SUM(CU23:CX23) -> 4295.3249 | AE23: =SUM(CY23:DB23) -> 4338.2781 | BW23: 183 | BX23: 354 | BY23: 464 | BZ23: 608 | CA23: 369 | CB23: 490 | CC23: 439 | CD23: 797 | CE23: 755 | CF23: 804 | CG23: 781 | CH23: 956 | CI23: 1019 | CJ23: 1153 | CK23: 1140 | CL23: 857 | CM23: =CI23*(1+CM48) -> 1029.19 | CN23: =CJ23*(1+CN48) -> 1164.53 | CO23: =CK23*(1+CO48) -> 1151.4 | CP23: =CL23*(1+CP48) -> 865.57 | CQ23: =CM23*(1+CQ48) -> 1039.4819 | CR23: =CN23*(1+CR48) -> 1176.1753 | CS23: =CO23*(1+CS48) -> 1162.914 | CT23: =CP23*(1+CT48) -> 874.2257 | ... DB23: =CX23*(1+DB48) -> 891.79764
A25: Others (Incl. Tata Projects, Nelco and inter cluster eliminations#) | X25: =SUM(BW25:BZ25) -> -4907 | Y25: =SUM(CA25:CD25) -> -4453 | Z25: =SUM(CE25:CH25) -> -4242 | AA25: =SUM(CI25:CL25) -> -4327 | BW25: -1399 | BX25: -1295 | BY25: -1203 | BZ25: -1010 | CA25: -1190 | CB25: -1130 | CC25: -1052 | CD25: -1081 | CE25: -1263 | CF25: -1190 | CG25: -782 | CH25: -1007 | CI25: -1084 | CJ25: -1116 | CK25: -949 | CL25: =145-1323 -> -1178
A26: Others (total movement in regulatory deferral balances | X26: =SUM(BW26:BZ26) -> 925.92 | Y26: =SUM(CA26:CD26) -> -524.26 | Z26: =SUM(CE26:CH26) -> -975.23 | AA26: =SUM(CI26:CL26) -> 792.74 | BW26: 281.52 | BX26: 131.28 | BY26: 210.88 | BZ26: 302.24 | CA26: -210.29 | CB26: -296.03 | CC26: 190 | CD26: -207.94 | CE26: -484.62 | CF26: -451.67 | CG26: -272.06 | CH26: 233.12 | CI26: -572.07 | CJ26: 218.09 | CK26: 536.92 | CL26: 609.8
A27: Total | X27: =X5+X11+X17+X25-X26 -> 55109.08 | Y27: =Y5+Y11+Y17+Y25-Y26 -> 62066.26 | Z27: =Z5+Z11+Z17+Z25-Z26 -> 65478.23 | AA27: =AA5+AA11+AA17+AA25-AA26 -> 62426.26 | AB27: =AB17+AB11+AB5 -> 78342.753 | AC27: =AC17+AC11+AC5 -> 84881.197 | AD27: =AD17+AD11+AD5 -> 90082.516 | AE27: =AE17+AE11+AE5 -> 95893.63 | BW27: =BW5+BW11+BW17+BW25-BW26 -> 14495.48 | BX27: =BX5+BX11+BX17+BX25-BX26 -> 14030.72 | BY27: =BY5+BY11+BY17+BY25-BY26 -> 14129.12 | BZ27: =BZ5+BZ11+BZ17+BZ25-BZ26 -> 12453.76 | CA27: =CA5+CA11+CA17+CA25-CA26 -> 15213.29 | CB27: =CB5+CB11+CB17+CB25-CB26 -> 15738.03 | CC27: =CC5+CC11+CC17+CC25-CC26 -> 14651 | CD27: =CD5+CD11+CD17+CD25-CD26 -> 16463.94 | ... CL27: =CL5+CL11+CL17+CL25-CL26 -> 14900.2 | CM27: =CM5+CM11+CM17 -> 17444.19 | CN27: =CN5+CN11+CN17 -> 21397.707 | CO27: =CO5+CO11+CO17 -> 19259.818 | CP27: =CP5+CP11+CP17 -> 20241.038 | CQ27: =CQ5+CQ11+CQ17 -> 21120.062 | CR27: =CR5+CR11+CR17 -> 22412.273 | CS27: =CS5+CS11+CS17 -> 20153.81 | CT27: =CT5+CT11+CT17 -> 21195.052 | ... DB27: =DB5+DB11+DB17 -> 23934.994
A28: checksum | X28: =X27-X101 -> 0 | Y28: =Y27-Y101 -> 617.36 | Z28: =Z27-Z101 -> -0.01 | AA28: =AA27-AA101 -> -2.33 | AB28: =AB27-AB101 -> 0 | AC28: =AC27-AC101 -> 0 | AD28: =AD27-AD101 -> 0 | AE28: =AE27-AE101 -> 0 | BW28: =BW27-BW101 -> 0 | BX28: =BX27-BX101 -> 0 | BY28: =BY27-BY101 -> 0 | BZ28: =BZ27-BZ101 -> 0 | CA28: =CA27-CA101 -> 0 | CB28: =CB27-CB101 -> 0 | CC28: =CC27-CC101 -> 0 | CD28: =CD27-CD101-CD127 -> -1.2505552e-12 | CE28: =CE27-CE101 -> 0 | CF28: =CF27-CF101 -> 0 | CG28: =CG27-CG101 -> 0 | CH28: =CH27-CH101 -> 0 | CI28: =CI27-CI101 -> 0 | CJ28: =CJ27-CJ101 -> 0 | CK28: =CK27-CK101 -> -2.33 | CL28: =CL27-CL101 -> 0
A30: Growth Y-o-Y %
A31: Thermal Generation, Coal and Hydro % | Y31: =Y5/X5-1 -> 0.076927301 | Z31: =Z5/Y5-1 -> 0.006475297 | AA31: =AA5/Z5-1 -> -0.41084093 | AB31: =AB5/AA5-1 -> 0.53284609 | AC31: =AC5/AB5-1 -> 0.15285802 | AD31: =AD5/AC5-1 -> 0 | AE31: =AE5/AD5-1 -> 0 | CA31: =CA5/BW5-1 -> -0.058146341 | CB31: =CB5/BX5-1 -> 0.028754655 | CC31: =CC5/BY5-1 -> -0.076722533 | CD31: =CD5/BZ5-1 -> 0.68400971 | CE31: =CE5/CA5-1 -> 0.080795525 | CF31: =CF5/CB5-1 -> -0.13331993 | CG31: =CG5/CC5-1 -> -0.0066559096 | CH31: =CH5/CD5-1 -> 0.089186406 | ... DB31: =DB5/CX5-1 -> 0
A32: Maithon Power Limited (MPL) % | Y32: =Y6/X6-1 -> 0.10894685 | Z32: =Z6/Y6-1 -> -0.12027389 | AA32: =AA6/Z6-1 -> 0.047377327 | AB32: =AB6/AA6-1 -> 0 | AC32: =AC6/AB6-1 -> 0 | AD32: =AD6/AC6-1 -> 0 | AE32: =AE6/AD6-1 -> 0 | CA32: =CA6/BW6-1 -> 0.12732095 | CB32: =CB6/BX6-1 -> -0.060493827 | CC32: =CC6/BY6-1 -> 0.044499382 | CD32: =CD6/BZ6-1 -> 0.37652439 | CE32: =CE6/CA6-1 -> -0.036470588 | CF32: =CF6/CB6-1 -> 0.0078843627 | CG32: =CG6/CC6-1 -> -0.24260355 | CH32: =CH6/CD6-1 -> -0.19269103 | ... DB32: =DB6/CX6-1 -> 0
A33: Traditional Generation (incl. Mumbai and Hydro) % | Y33: =Y7/X7-1 -> -0.14584544 | Z33: =Z7/Y7-1 -> -0.10510204 | AA33: =AA7/Z7-1 -> -0.02622577 | AB33: =AB7/AA7-1 -> 0 | AC33: =AC7/AB7-1 -> 0 | AD33: =AD7/AC7-1 -> 0 | AE33: =AE7/AD7-1 -> 0 | CA33: =CA7/BW7-1 -> -0.19312437 | CB33: =CB7/BX7-1 -> -0.17565217 | CC33: =CC7/BY7-1 -> -0.12926391 | CD33: =CD7/BZ7-1 -> -0.068211921 | CE33: =CE7/CA7-1 -> -0.020676692 | CF33: =CF7/CB7-1 -> -0.014064698 | CG33: =CG7/CC7-1 -> -0.3628866 | CH33: =CH7/CD7-1 -> -0.026297086 | ... DB33: =DB7/CX7-1 -> 0
A34: Others (Incl. eliminations) % | Y34: =Y8/X8-1 -> 0.0076923077 | Z34: =Z8/Y8-1 -> -0.038167939 | AA34: =AA8/Z8-1 -> 0.055555556 | AB34: =AB8/AA8-1 -> 0 | AC34: =AC8/AB8-1 -> 0 | AD34: =AD8/AC8-1 -> 0 | AE34: =AE8/AD8-1 -> 0 | CA34: =CA8/BW8-1 -> 0 | CB34: =CB8/BX8-1 -> 0.13333333 | CC34: =CC8/BY8-1 -> 0.029411765 | CD34: =CD8/BZ8-1 -> -0.11764706 | CE34: =CE8/CA8-1 -> 0 | CF34: =CF8/CB8-1 -> -0.088235294 | CG34: =CG8/CC8-1 -> -0.057142857 | CH34: =CH8/CD8-1 -> 0 | ... DB34: =DB8/CX8-1 -> 0
A35: Mundra, Coal and Shipping % | Y35: =Y9/X9-1 -> 0.25388664 | Z35: =Z9/Y9-1 -> 0.11266231 | AA35: =AA9/Z9-1 -> -0.71238045 | AB35: =AB9/AA9-1 -> 1.890482 | AC35: =AC9/AB9-1 -> 0.28759894 | AD35: =AD9/AC9-1 -> 0 | AE35: =AE9/AD9-1 -> 0 | CA35: =CA9/BW9-1 -> -0.0050825921 | CB35: =CB9/BX9-1 -> 0.214632 | CC35: =CC9/BY9-1 -> -0.081582633 | CD35: =CD9/BZ9-1 -> 2.682284 | CE35: =CE9/CA9-1 -> 0.19327373 | CF35: =CF9/CB9-1 -> -0.23439768 | CG35: =CG9/CC9-1 -> 0.26763248 | CH35: =CH9/CD9-1 -> 0.25606362 | ... DB35: =DB9/CX9-1 -> 0
A37: Renewables % | Y37: =Y11/X11-1 -> 0.24142979 | Z37: =Z11/Y11-1 -> -0.028793239 | AA37: =AA11/Z11-1 -> 0.52038855 | AB37: =AB11/AA11-1 -> 0.19113154 | AC37: =AC11/AB11-1 -> 0.10865814 | AD37: =AD11/AC11-1 -> 0.15213039 | AE37: =AE11/AD11-1 -> 0.15001498 | CA37: =CA11/BW11-1 -> -0.0004784689 | CB37: =CB11/BX11-1 -> 0.33873986 | CC37: =CC11/BY11-1 -> 0.29577465 | CD37: =CD11/BZ11-1 -> 0.33629687 | CE37: =CE11/CA11-1 -> 0.14073719 | CF37: =CF11/CB11-1 -> -0.10531221 | CG37: =CG11/CC11-1 -> -0.14533011 | CH37: =CH11/CD11-1 -> 0 | ... DB37: =DB11/CX11-1 -> 0.14999783
A38: RE Gencos (Incl. CSL) % | Y38: =Y12/X12-1 -> 0.06893325 | Z38: =Z12/Y12-1 -> 0.11146776 | AA38: =AA12/Z12-1 -> 0.084274088 | AB38: =AB12/AA12-1 -> 0.1 | AC38: =AC12/AB12-1 -> 0.1 | AD38: =AD12/AC12-1 -> 0.15 | AE38: =AE12/AD12-1 -> 0.15 | CA38: =CA12/BW12-1 -> 0.030939227 | CB38: =CB12/BX12-1 -> 0.12903226 | CC38: =CC12/BY12-1 -> 0.046875 | CD38: =CD12/BZ12-1 -> 0.07079646 | CE38: =CE12/CA12-1 -> 0.073954984 | CF38: =CF12/CB12-1 -> 0.053846154 | CG38: =CG12/CC12-1 -> 0.12211669 | CH38: =CH12/CD12-1 -> 0.20543093 | ... CL38: =CL12/CH12-1 -> 0.0048971596 | CM38: 0.1 | CN38: 0.1 | CO38: 0.1 | CP38: 0.1 | CQ38: 0.1 | CR38: 0.1 | CS38: 0.1 | CT38: 0.1 | CU38: 0.15 | CV38: 0.15 | CW38: 0.15 | CX38: 0.15 | CY38: 0.15 | CZ38: 0.15 | DA38: 0.15 | DB38: 0.15
A39: Solar EPC (TPSSL) % | Y39: =Y13/X13-1 -> 0.70535195 | Z39: =Z13/Y13-1 -> -0.1435272 | AA39: =AA13/Z13-1 -> -0.024494673 | AB39: =AB13/AA13-1 -> 0.11 | AC39: =AC13/AB13-1 -> 0.11 | AD39: =AD13/AC13-1 -> 0.15 | AE39: =AE13/AD13-1 -> 0.15 | CA39: =CA13/BW13-1 -> 0.10273466 | CB39: =CB13/BX13-1 -> 0.68281938 | CC39: =CC13/BY13-1 -> 1.8230769 | CD39: =CD13/BZ13-1 -> 0.44929006 | CE39: =CE13/CA13-1 -> 0.45509383 | CF39: =CF13/CB13-1 -> 0.57748691 | CG39: =CG13/CC13-1 -> -0.56675749 | CH39: =CH13/CD13-1 -> -0.27455097 | ... CL39: =CL13/CH13-1 -> -0.29003215 | CM39: 0.11 | CN39: 0.11 | CO39: 0.11 | CP39: 0.11 | CQ39: 0.11 | CR39: 0.11 | CS39: 0.11 | CT39: 0.11 | CU39: 0.15 | CV39: 0.15 | CW39: 0.15 | CX39: 0.15 | CY39: 0.15 | CZ39: 0.15 | DA39: 0.15 | DB39: 0.15
A40: TP solar (4.3GW cell & module manufacturing plant % | Y40: =Y14/X14-1 -> #DIV/0! | Z40: =Z14/Y14-1 -> 21.905579 | AA40: =AA14/Z14-1 -> 0.3056024 | AB40: =AB14/AA14-1 -> 0.11 | AC40: =AC14/AB14-1 -> 0.11 | AD40: =AD14/AC14-1 -> 0.15 | AE40: =AE14/AD14-1 -> 0.15 | CA40: =CA14/BW14-1 -> #DIV/0! | CB40: =CB14/BX14-1 -> #DIV/0! | CC40: =CC14/BY14-1 -> #DIV/0! | CD40: =CD14/BZ14-1 -> #DIV/0! | CE40: =CE14/CA14-1 -> #DIV/0! | CF40: =CF14/CB14-1 -> #DIV/0! | CG40: =CG14/CC14-1 -> #DIV/0! | CH40: =CH14/CD14-1 -> 5.4635193 | ... CL40: =CL14/CH14-1 -> 0.24767596 | CM40: 0.11 | CN40: 0.11 | CO40: 0.11 | CP40: 0.11 | CQ40: 0.11 | CR40: 0.11 | CS40: 0.11 | CT40: 0.11 | CU40: 0.15 | CV40: 0.15 | CW40: 0.15 | CX40: 0.15 | CY40: 0.15 | CZ40: 0.15 | DA40: 0.15 | DB40: 0.15
A42: Transmission & Distribution Services % | Y42: =Y17/X17-1 -> 0.048446414 | Z42: =Z17/Y17-1 -> 0.080539137 | AA42: =AA17/Z17-1 -> 0.045191964 | AB42: =AB17/AA17-1 -> 0.042255075 | AC42: =AC17/AB17-1 -> 0.043847558 | AD42: =AD17/AC17-1 -> 0.049063029 | AE42: =AE17/AD17-1 -> 0.051030825 | CA42: =CA17/BW17-1 -> 0.035263921 | CB42: =CB17/BX17-1 -> 0.048004435 | CC42: =CC17/BY17-1 -> 0.023619186 | CD42: =CD17/BZ17-1 -> 0.087873674 | CE42: =CE17/CA17-1 -> 0.12881319 | CF42: =CF17/CB17-1 -> 0.079657252 | CG42: =CG17/CC17-1 -> 0.047568335 | CH42: =CH17/CD17-1 -> 0.062714681 | ... CL42: =CL17/CH17-1 -> 0.068710249 | CM42: 0.05 | CN42: 0.05 | CO42: 0.05 | CP42: 0.05 | CQ42: 0.08 | CR42: 0.08 | CS42: 0.08 | CT42: 0.08 | CU42: 0.08 | CV42: 0.08 | CW42: 0.08 | CX42: 0.08 | CY42: 0.08 | CZ42: 0.08 | DA42: 0.08 | DB42: 0.08
A43: Transmission % | Y43: =Y18/X18-1 -> 0.1350135 | Z43: =Z18/Y18-1 -> 0.12053925 | AA43: =AA18/Z18-1 -> -0.041755131 | AB43: =AB18/AA18-1 -> 0.03 | AC43: =AC18/AB18-1 -> 0.03 | AD43: =AD18/AC18-1 -> 0.03 | AE43: =AE18/AD18-1 -> 0.03 | CA43: =CA18/BW18-1 -> 0.19678715 | CB43: =CB18/BX18-1 -> 0.15662651 | CC43: =CC18/BY18-1 -> 0.16535433 | CD43: =CD18/BZ18-1 -> 0.055710306 | CE43: =CE18/CA18-1 -> 0.10402685 | CF43: =CF18/CB18-1 -> 0.16666667 | CG43: =CG18/CC18-1 -> 0.11148649 | CH43: =CH18/CD18-1 -> 0.1055409 | ... CL43: =CL18/CH18-1 -> -0.011933174 | CM43: 0.03 | CN43: 0.03 | CO43: 0.03 | CP43: 0.03 | CQ43: 0.03 | CR43: 0.03 | CS43: 0.03 | CT43: 0.03 | CU43: 0.03 | CV43: 0.03 | CW43: 0.03 | CX43: 0.03 | CY43: 0.03 | CZ43: 0.03 | DA43: 0.03 | DB43: 0.03
A44: Distribution and Services % | Y44: =Y19/X19-1 -> 0.045568787 | Z44: =Z19/Y19-1 -> 0.079095722 | AA44: =AA19/Z19-1 -> 0.048449972 | AB44: =AB19/AA19-1 -> 0.042674777 | AC44: =AC19/AB19-1 -> 0.044316034 | AD44: =AD19/AC19-1 -> 0.049699109 | AE44: =AE19/AD19-1 -> 0.051719396 | CA44: =CA19/BW19-1 -> 0.030647383 | CB44: =CB19/BX19-1 -> 0.044920762 | CC44: =CC19/BY19-1 -> 0.01912022 | CD44: =CD19/BZ19-1 -> 0.089328462 | CE44: =CE19/CA19-1 -> 0.12963582 | CF44: =CF19/CB19-1 -> 0.076923077 | CG44: =CG19/CC19-1 -> 0.045248314 | CH44: =CH19/CD19-1 -> 0.060837381 | ... DB44: =DB19/CX19-1 -> 0.053087954
A45: Mumbai % | Y45: =Y20/X20-1 -> -0.11745776 | Z45: =Z20/Y20-1 -> 0.0068368277 | AA45: =AA20/Z20-1 -> 0.034178361 | AB45: =AB20/AA20-1 -> 0.08 | AC45: =AC20/AB20-1 -> 0.08 | AD45: =AD20/AC20-1 -> 0.11 | AE45: =AE20/AD20-1 -> 0.11 | CA45: =CA20/BW20-1 -> -0.18074792 | CB45: =CB20/BX20-1 -> -0.13854931 | CC45: =CC20/BY20-1 -> -0.097014925 | CD45: =CD20/BZ20-1 -> -0.032876712 | CE45: =CE20/CA20-1 -> 0.048182587 | CF45: =CF20/CB20-1 -> 0.084200568 | CG45: =CG20/CC20-1 -> -0.10743802 | CH45: =CH20/CD20-1 -> 0.00094428706 | ... CL45: =CL20/CH20-1 -> 0.10471698 | CM45: 0.08 | CN45: 0.08 | CO45: 0.08 | CP45: 0.08 | CQ45: 0.08 | CR45: 0.08 | CS45: 0.08 | CT45: 0.08 | CU45: 0.11 | CV45: 0.11 | CW45: 0.11 | CX45: 0.11 | CY45: 0.11 | CZ45: 0.11 | DA45: 0.11 | DB45: 0.11
A46: Odisha % | Y46: =Y21/X21-1 -> 0.11998785 | Z46: =Z21/Y21-1 -> 0.068185517 | AA46: =AA21/Z21-1 -> 0.015539305 | AB46: =AB21/AA21-1 -> 0.01 | AC46: =AC21/AB21-1 -> 0.01 | AD46: =AD21/AC21-1 -> 0.01 | AE46: =AE21/AD21-1 -> 0.01 | CA46: =CA21/BW21-1 -> 0.16687705 | CB46: =CB21/BX21-1 -> 0.10695693 | CC46: =CC21/BY21-1 -> 0.073242188 | CD46: =CD21/BZ21-1 -> 0.13454633 | CE46: =CE21/CA21-1 -> 0.1155344 | CF46: =CF21/CB21-1 -> 0.02928602 | CG46: =CG21/CC21-1 -> 0.043903549 | CH46: =CH21/CD21-1 -> 0.082928888 | ... CL46: =CL21/CH21-1 -> -0.022798129 | CM46: 0.01 | CN46: 0.01 | CO46: 0.01 | CP46: 0.01 | CQ46: 0.01 | CR46: 0.01 | CS46: 0.01 | CT46: 0.01 | CU46: 0.01 | CV46: 0.01 | CW46: 0.01 | CX46: 0.01 | CY46: 0.01 | CZ46: 0.01 | DA46: 0.01 | DB46: 0.01
A47: Delhi % | Y47: =Y22/X22-1 -> -0.034100761 | Z47: =Z22/Y22-1 -> 0.027525681 | AA47: =AA22/Z22-1 -> 0.048238377 | AB47: =AB22/AA22-1 -> 0.1 | AC47: =AC22/AB22-1 -> 0.1 | AD47: =AD22/AC22-1 -> 0.1 | AE47: =AE22/AD22-1 -> 0.1 | CA47: =CA22/BW22-1 -> -0.10211268 | CB47: =CB22/BX22-1 -> -0.008097166 | CC47: =CC22/BY22-1 -> -0.002236136 | CD47: =CD22/BZ22-1 -> -0.0029168692 | CE47: =CE22/CA22-1 -> 0.066666667 | CF47: =CF22/CB22-1 -> 0.056122449 | CG47: =CG22/CC22-1 -> -0.021963245 | CH47: =CH22/CD22-1 -> -0.01316431 | ... CL47: =CL22/CH22-1 -> 0.37994071 | CM47: 0.1 | CN47: 0.1 | CO47: 0.1 | CP47: 0.1 | CQ47: 0.1 | CR47: 0.1 | CS47: 0.1 | CT47: 0.1 | CU47: 0.1 | CV47: 0.1 | CW47: 0.1 | CX47: 0.1 | CY47: 0.1 | CZ47: 0.1 | DA47: 0.1 | DB47: 0.1
...

Sheet QTR Raw
A1: ='Annual Raw'!A1 -> 100400 | B1: X | C1: 201206 | D1: 201209 | E1: 201212 | F1: 201303 | G1: 201306 | H1: 201309 | I1: 201312 | J1: 201403 | K1: 201406 | L1: 201409 | M1: 201412 | N1: 201503 | O1: 201506 | P1: 201509 | Q1: 201512 | R1: 201603 | S1: 201606 | T1: 201609 | U1: 201612 | V1: 201703 | W1: 201706 | X1: 201709 | Y1: 201712 | Z1: 201803 | AA1: 201806 | AB1: 201809 | AC1: 201812 | AD1: 201903 | AE1: 201906 | AF1: 201909 | AG1: 201912 | AH1: 202003 | AI1: 202006 | AJ1: 202009 | AK1: 202012 | AL1: 202103 | AM1: 202106 | AN1: 202109 | AO1: 202112 | AP1: 202203 | AQ1: 202206 | AR1: 202209 | AS1: 202212 | AT1: 202303 | AU1: 202306 | AV1: 202309 | AW1: 202312 | AX1: 202403 | AY1: 202406 | AZ1: 202409 | BA1: 202412 | BB1: 202503 | BC1: 202506 | BD1: 202509 | BE1: 202512 | BF1: 202603 | BG1: 202606 | BH1: 202609 | BI1: 202612 | BJ1: 202703 | BK1: 202706 | BL1: 202709 | BM1: 202712 | BN1: 202803 | BO1: 202806 | BP1: 202809 | BQ1: 202812 | BR1: 202903 | BS1: 202906 | BT1: 202909 | BU1: 202912 | BV1: 203003
A3: Field Description | B3: Field Name
A4: Company Name | B4: CD_COMPNAME | C4: =_xll.EQNXTDZ(A1,B4,C1) -> Tata Power Company Ltd.
A5: Date End | B5: QTR_DATE_END | C5: =_xll.EQNXTDZ($A$1,$B5,C$1,$B$1) -> 201206 | D5: =_xll.EQNXTDZ($A$1,$B5,D$1,$B$1) -> 201209 | E5: =_xll.EQNXTDZ($A$1,$B5,E$1,$B$1) -> 201212 | F5: =_xll.EQNXTDZ($A$1,$B5,F$1,$B$1) -> 201303 | G5: =_xll.EQNXTDZ($A$1,$B5,G$1,$B$1) -> 201306 | H5: =_xll.EQNXTDZ($A$1,$B5,H$1,$B$1) -> 201309 | I5: =_xll.EQNXTDZ($A$1,$B5,I$1,$B$1) -> 201312 | J5: =_xll.EQNXTDZ($A$1,$B5,J$1,$B$1) -> 201403 | ... BV5: =_xll.EQNXTDZ($A$1,$B5,BV$1,$B$1) -> 0
A6: Gross Sales | B6: QTR_GROSS_SALE | C6: =_xll.EQNXTDZ($A$1,$B6,C$1,$B$1) -> 7197.57 | D6: =_xll.EQNXTDZ($A$1,$B6,D$1,$B$1) -> 7649.49 | E6: =_xll.EQNXTDZ($A$1,$B6,E$1,$B$1) -> 8991.68 | F6: =_xll.EQNXTDZ($A$1,$B6,F$1,$B$1) -> 8997.31 | G6: =_xll.EQNXTDZ($A$1,$B6,G$1,$B$1) -> 9291.77 | H6: =_xll.EQNXTDZ($A$1,$B6,H$1,$B$1) -> 8717.11 | I6: =_xll.EQNXTDZ($A$1,$B6,I$1,$B$1) -> 8656.11 | J6: =_xll.EQNXTDZ($A$1,$B6,J$1,$B$1) -> 8862.5 | ... BV6: =_xll.EQNXTDZ($A$1,$B6,BV$1,$B$1) -> 0
A7: Less: Excise Duty | B7: QTR_EXCISE_DUTY | C7: =_xll.EQNXTDZ($A$1,$B7,C$1,$B$1) -> 0 | D7: =_xll.EQNXTDZ($A$1,$B7,D$1,$B$1) -> 0 | E7: =_xll.EQNXTDZ($A$1,$B7,E$1,$B$1) -> 0 | F7: =_xll.EQNXTDZ($A$1,$B7,F$1,$B$1) -> 0 | G7: =_xll.EQNXTDZ($A$1,$B7,G$1,$B$1) -> 0 | H7: =_xll.EQNXTDZ($A$1,$B7,H$1,$B$1) -> 0 | I7: =_xll.EQNXTDZ($A$1,$B7,I$1,$B$1) -> 0 | J7: =_xll.EQNXTDZ($A$1,$B7,J$1,$B$1) -> 0 | ... BV7: =_xll.EQNXTDZ($A$1,$B7,BV$1,$B$1) -> 0
A8: Other operating income | B8: QTR_JOB_WORKS | C8: =_xll.EQNXTDZ($A$1,$B8,C$1,$B$1) -> 56.32 | D8: =_xll.EQNXTDZ($A$1,$B8,D$1,$B$1) -> 50.28 | E8: =_xll.EQNXTDZ($A$1,$B8,E$1,$B$1) -> 47.63 | F8: =_xll.EQNXTDZ($A$1,$B8,F$1,$B$1) -> 35.15 | G8: =_xll.EQNXTDZ($A$1,$B8,G$1,$B$1) -> 47.72 | H8: =_xll.EQNXTDZ($A$1,$B8,H$1,$B$1) -> 47.58 | I8: =_xll.EQNXTDZ($A$1,$B8,I$1,$B$1) -> 43.91 | J8: =_xll.EQNXTDZ($A$1,$B8,J$1,$B$1) -> 39.31 | ... BV8: =_xll.EQNXTDZ($A$1,$B8,BV$1,$B$1) -> 0
A9: Net Sales & Other Operating Income | B9: QTR_NET_SALES | C9: =_xll.EQNXTDZ($A$1,$B9,C$1,$B$1) -> 7253.89 | D9: =_xll.EQNXTDZ($A$1,$B9,D$1,$B$1) -> 7699.77 | E9: =_xll.EQNXTDZ($A$1,$B9,E$1,$B$1) -> 9039.31 | F9: =_xll.EQNXTDZ($A$1,$B9,F$1,$B$1) -> 9032.46 | G9: =_xll.EQNXTDZ($A$1,$B9,G$1,$B$1) -> 9339.49 | H9: =_xll.EQNXTDZ($A$1,$B9,H$1,$B$1) -> 8764.69 | I9: =_xll.EQNXTDZ($A$1,$B9,I$1,$B$1) -> 8700.02 | J9: =_xll.EQNXTDZ($A$1,$B9,J$1,$B$1) -> 8901.81 | ... BV9: =_xll.EQNXTDZ($A$1,$B9,BV$1,$B$1) -> 0
A10: (Increase) / Decrease In Stocks | B10: QTR_INC_DEC_INVENTORY | C10: =_xll.EQNXTDZ($A$1,$B10,C$1,$B$1) -> -0.18 | D10: =_xll.EQNXTDZ($A$1,$B10,D$1,$B$1) -> -252.37 | E10: =_xll.EQNXTDZ($A$1,$B10,E$1,$B$1) -> -115.71 | F10: =_xll.EQNXTDZ($A$1,$B10,F$1,$B$1) -> 93.14 | G10: =_xll.EQNXTDZ($A$1,$B10,G$1,$B$1) -> 54.72 | H10: =_xll.EQNXTDZ($A$1,$B10,H$1,$B$1) -> -129.44 | I10: =_xll.EQNXTDZ($A$1,$B10,I$1,$B$1) -> 136.87 | J10: =_xll.EQNXTDZ($A$1,$B10,J$1,$B$1) -> 68.62 | ... BV10: =_xll.EQNXTDZ($A$1,$B10,BV$1,$B$1) -> 0
A11: Cost of Services & Raw Materials | B11: QTR_RAW_MATERIAL_COST | C11: =_xll.EQNXTDZ($A$1,$B11,C$1,$B$1) -> 72.17 | D11: =_xll.EQNXTDZ($A$1,$B11,D$1,$B$1) -> 110.85 | E11: =_xll.EQNXTDZ($A$1,$B11,E$1,$B$1) -> 141.34 | F11: =_xll.EQNXTDZ($A$1,$B11,F$1,$B$1) -> 154.48 | G11: =_xll.EQNXTDZ($A$1,$B11,G$1,$B$1) -> 116.02 | H11: =_xll.EQNXTDZ($A$1,$B11,H$1,$B$1) -> 123.09 | I11: =_xll.EQNXTDZ($A$1,$B11,I$1,$B$1) -> 204.04 | J11: =_xll.EQNXTDZ($A$1,$B11,J$1,$B$1) -> 308.51 | ... BV11: =_xll.EQNXTDZ($A$1,$B11,BV$1,$B$1) -> 0
A12: Purchase of Finished Goods | B12: QTR_PURCHASE_FIN_GOOD | C12: =_xll.EQNXTDZ($A$1,$B12,C$1,$B$1) -> 11.77 | D12: =_xll.EQNXTDZ($A$1,$B12,D$1,$B$1) -> 9.26 | E12: =_xll.EQNXTDZ($A$1,$B12,E$1,$B$1) -> 7.15 | F12: =_xll.EQNXTDZ($A$1,$B12,F$1,$B$1) -> 9.29 | G12: =_xll.EQNXTDZ($A$1,$B12,G$1,$B$1) -> 14.56 | H12: =_xll.EQNXTDZ($A$1,$B12,H$1,$B$1) -> 9.7 | I12: =_xll.EQNXTDZ($A$1,$B12,I$1,$B$1) -> 10.17 | J12: =_xll.EQNXTDZ($A$1,$B12,J$1,$B$1) -> 9.27 | ... BV12: =_xll.EQNXTDZ($A$1,$B12,BV$1,$B$1) -> 0
A13: Excise Duty | B13: QTR_EXCISE | C13: =_xll.EQNXTDZ($A$1,$B13,C$1,$B$1) -> 0 | D13: =_xll.EQNXTDZ($A$1,$B13,D$1,$B$1) -> 0 | E13: =_xll.EQNXTDZ($A$1,$B13,E$1,$B$1) -> 0 | F13: =_xll.EQNXTDZ($A$1,$B13,F$1,$B$1) -> 0 | G13: =_xll.EQNXTDZ($A$1,$B13,G$1,$B$1) -> 0 | H13: =_xll.EQNXTDZ($A$1,$B13,H$1,$B$1) -> 0 | I13: =_xll.EQNXTDZ($A$1,$B13,I$1,$B$1) -> 0 | J13: =_xll.EQNXTDZ($A$1,$B13,J$1,$B$1) -> 0 | ... BV13: =_xll.EQNXTDZ($A$1,$B13,BV$1,$B$1) -> 0
A14: Operating & Manufacturing Expenses | B14: QTR_MFG_EXPS | C14: =_xll.EQNXTDZ($A$1,$B14,C$1,$B$1) -> 1674.97 | D14: =_xll.EQNXTDZ($A$1,$B14,D$1,$B$1) -> 1751.01 | E14: =_xll.EQNXTDZ($A$1,$B14,E$1,$B$1) -> 1921.1 | F14: =_xll.EQNXTDZ($A$1,$B14,F$1,$B$1) -> 1377.23 | G14: =_xll.EQNXTDZ($A$1,$B14,G$1,$B$1) -> 1974.36 | H14: =_xll.EQNXTDZ($A$1,$B14,H$1,$B$1) -> 1949.61 | I14: =_xll.EQNXTDZ($A$1,$B14,I$1,$B$1) -> 2297.17 | J14: =_xll.EQNXTDZ($A$1,$B14,J$1,$B$1) -> 2194.44 | ... BV14: =_xll.EQNXTDZ($A$1,$B14,BV$1,$B$1) -> 0
A15: Electricity Power & Fuel Cost | B15: QTR_ELECTRICITY_POWER_FUEL | C15: =_xll.EQNXTDZ($A$1,$B15,C$1,$B$1) -> 3771.24 | D15: =_xll.EQNXTDZ($A$1,$B15,D$1,$B$1) -> 4225.36 | E15: =_xll.EQNXTDZ($A$1,$B15,E$1,$B$1) -> 4895.53 | F15: =_xll.EQNXTDZ($A$1,$B15,F$1,$B$1) -> 5206.78 | G15: =_xll.EQNXTDZ($A$1,$B15,G$1,$B$1) -> 4781.93 | H15: =_xll.EQNXTDZ($A$1,$B15,H$1,$B$1) -> 4473.64 | I15: =_xll.EQNXTDZ($A$1,$B15,I$1,$B$1) -> 3942.25 | J15: =_xll.EQNXTDZ($A$1,$B15,J$1,$B$1) -> 4110.68 | ... BV15: =_xll.EQNXTDZ($A$1,$B15,BV$1,$B$1) -> 0
A16: Employee Cost | B16: QTR_EXPLOYEE_COST | C16: =_xll.EQNXTDZ($A$1,$B16,C$1,$B$1) -> 309.79 | D16: =_xll.EQNXTDZ($A$1,$B16,D$1,$B$1) -> 345.32 | E16: =_xll.EQNXTDZ($A$1,$B16,E$1,$B$1) -> 333.66 | F16: =_xll.EQNXTDZ($A$1,$B16,F$1,$B$1) -> 334.18 | G16: =_xll.EQNXTDZ($A$1,$B16,G$1,$B$1) -> 330.16 | H16: =_xll.EQNXTDZ($A$1,$B16,H$1,$B$1) -> 307.4 | I16: =_xll.EQNXTDZ($A$1,$B16,I$1,$B$1) -> 323.03 | J16: =_xll.EQNXTDZ($A$1,$B16,J$1,$B$1) -> 388.76 | ... BV16: =_xll.EQNXTDZ($A$1,$B16,BV$1,$B$1) -> 0
... A42: Consolidated PAT(after extra items) | B42: QTR_CONS_PAT_EXITM | C42: =_xll.EQNXTDZ($A$1,$B42,C$1,$B$1) -> 145.93 | D42: =_xll.EQNXTDZ($A$1,$B42,D$1,$B$1) -> -83.8 | E42: =_xll.EQNXTDZ($A$1,$B42,E$1,$B$1) -> -328.92 | F42: =_xll.EQNXTDZ($A$1,$B42,F$1,$B$1) -> 181.36 | G42: =_xll.EQNXTDZ($A$1,$B42,G$1,$B$1) -> -114.7 | H42: =_xll.EQNXTDZ($A$1,$B42,H$1,$B$1) -> 74.97 | I42: =_xll.EQNXTDZ($A$1,$B42,I$1,$B$1) -> -74.91 | J42: =_xll.EQNXTDZ($A$1,$B42,J$1,$B$1) -> -145.33 | ... BV42: =_xll.EQNXTDZ($A$1,$B42,BV$1,$B$1) -> 0
A44: Field Description | B44: Field Name
A45: Equity Capital | B45: QTR_EQUITY_CAP | C45: =_xll.EQNXTDZ($A$1,$B45,C$1,$B$1) -> 237.29 | D45: =_xll.EQNXTDZ($A$1,$B45,D$1,$B$1) -> 237.29 | E45: =_xll.EQNXTDZ($A$1,$B45,E$1,$B$1) -> 237.29 | F45: =_xll.EQNXTDZ($A$1,$B45,F$1,$B$1) -> 237.29 | G45: =_xll.EQNXTDZ($A$1,$B45,G$1,$B$1) -> 237.29 | H45: =_xll.EQNXTDZ($A$1,$B45,H$1,$B$1) -> 237.29 | I45: =_xll.EQNXTDZ($A$1,$B45,I$1,$B$1) -> 237.29 | J45: =_xll.EQNXTDZ($A$1,$B45,J$1,$B$1) -> 237.29 | ... BV45: =_xll.EQNXTDZ($A$1,$B45,BV$1,$B$1) -> 0
A46: Face Value | B46: QTR_FV | C46: =_xll.EQNXTDZ($A$1,$B46,C$1,$B$1) -> 1 | D46: =_xll.EQNXTDZ($A$1,$B46,D$1,$B$1) -> 1 | E46: =_xll.EQNXTDZ($A$1,$B46,E$1,$B$1) -> 1 | F46: =_xll.EQNXTDZ($A$1,$B46,F$1,$B$1) -> 1 | G46: =_xll.EQNXTDZ($A$1,$B46,G$1,$B$1) -> 1 | H46: =_xll.EQNXTDZ($A$1,$B46,H$1,$B$1) -> 1 | I46: =_xll.EQNXTDZ($A$1,$B46,I$1,$B$1) -> 1 | J46: =_xll.EQNXTDZ($A$1,$B46,J$1,$B$1) -> 1 | ... BV46: =_xll.EQNXTDZ($A$1,$B46,BV$1,$B$1) -> 0
A47: Month End | B47: BMONTH_MONTHEND | C47: =_xll.EQNXTDZ($A$1,$B47,C$5) -> 201206 | D47: =_xll.EQNXTDZ($A$1,$B47,D$5) -> 201209 | E47: =_xll.EQNXTDZ($A$1,$B47,E$5) -> 201212 | F47: =_xll.EQNXTDZ($A$1,$B47,F$5) -> 201303 | G47: =_xll.EQNXTDZ($A$1,$B47,G$5) -> 201306 | H47: =_xll.EQNXTDZ($A$1,$B47,H$5) -> 201309 | I47: =_xll.EQNXTDZ($A$1,$B47,I$5) -> 201312 | J47: =_xll.EQNXTDZ($A$1,$B47,J$5) -> 201403 | ... BV47: =_xll.EQNXTDZ($A$1,$B47,BV$5) -> 0
A48: Close | B48: BMONTH_CLOSE | C48: =_xll.EQNXTDZ($A$1,$B48,C$5) -> 101.03726 | D48: =_xll.EQNXTDZ($A$1,$B48,D$5) -> 103.20855 | E48: =_xll.EQNXTDZ($A$1,$B48,E$5) -> 106.48961 | F48: =_xll.EQNXTDZ($A$1,$B48,F$5) -> 93.027623 | G48: =_xll.EQNXTDZ($A$1,$B48,G$5) -> 83.039698 | H48: =_xll.EQNXTDZ($A$1,$B48,H$5) -> 78.262865 | I48: =_xll.EQNXTDZ($A$1,$B48,I$5) -> 88.154288 | J48: =_xll.EQNXTDZ($A$1,$B48,J$5) -> 84.8 | ... BV48: =_xll.EQNXTDZ($A$1,$B48,BV$5) -> 0
A49: Total of Promoter and Promoter Group | B49: SHP_TPFTOTALPROMOTER | C49: =_xll.EQNXTDZ($A$1,$B49,C$5) -> 31.75 | D49: =_xll.EQNXTDZ($A$1,$B49,D$5) -> 31.75 | E49: =_xll.EQNXTDZ($A$1,$B49,E$5) -> 31.75 | F49: =_xll.EQNXTDZ($A$1,$B49,F$5) -> 32.47 | G49: =_xll.EQNXTDZ($A$1,$B49,G$5) -> 32.47 | H49: =_xll.EQNXTDZ($A$1,$B49,H$5) -> 32.47 | I49: =_xll.EQNXTDZ($A$1,$B49,I$5) -> 32.47 | J49: =_xll.EQNXTDZ($A$1,$B49,J$5) -> 32.47 | ... BV49: =_xll.EQNXTDZ($A$1,$B49,BV$5) -> 0
A50: Total of Promoter and Promoter Group Pledged | B50: SHP_PSHFTOTALPROMOTER | C50: =_xll.EQNXTDZ($A$1,$B50,C$5) -> 6.91 | D50: =_xll.EQNXTDZ($A$1,$B50,D$5) -> 6.91 | E50: =_xll.EQNXTDZ($A$1,$B50,E$5) -> 6.91 | F50: =_xll.EQNXTDZ($A$1,$B50,F$5) -> 6.76 | G50: =_xll.EQNXTDZ($A$1,$B50,G$5) -> 4.59 | H50: =_xll.EQNXTDZ($A$1,$B50,H$5) -> 4.59 | I50: =_xll.EQNXTDZ($A$1,$B50,I$5) -> 4.59 | J50: =_xll.EQNXTDZ($A$1,$B50,J$5) -> 4.59 | ... BV50: =_xll.EQNXTDZ($A$1,$B50,BV$5) -> 0
A54: Field Description | B54: Field Name | C54: =_xll.EQNXTDZ($A$1,$B54,C$5) -> 0 | D54: =_xll.EQNXTDZ($A$1,$B54,D$5) -> 0 | E54: =_xll.EQNXTDZ($A$1,$B54,E$5) -> 0 | F54: =_xll.EQNXTDZ($A$1,$B54,F$5) -> 0 | G54: =_xll.EQNXTDZ($A$1,$B54,G$5) -> 0 | H54: =_xll.EQNXTDZ($A$1,$B54,H$5) -> 0 | I54: =_xll.EQNXTDZ($A$1,$B54,I$5) -> 0 | J54: =_xll.EQNXTDZ($A$1,$B54,J$5) -> 0 | ... BV54: =_xll.EQNXTDZ($A$1,$B54,BV$5) -> 0
A55: Year End | B55: QTRB_DATE_END | C55: =_xll.EQNXTDZ($A$1,$B55,C$5,$B$1) -> 0 | D55: =_xll.EQNXTDZ($A$1,$B55,D$5,$B$1) -> 201209 | E55: =_xll.EQNXTDZ($A$1,$B55,E$5,$B$1) -> 0 | F55: =_xll.EQNXTDZ($A$1,$B55,F$5,$B$1) -> 201303 | G55: =_xll.EQNXTDZ($A$1,$B55,G$5,$B$1) -> 0 | H55: =_xll.EQNXTDZ($A$1,$B55,H$5,$B$1) -> 201309 | I55: =_xll.EQNXTDZ($A$1,$B55,I$5,$B$1) -> 0 | J55: =_xll.EQNXTDZ($A$1,$B55,J$5,$B$1) -> 201403 | ... BV55: =_xll.EQNXTDZ($A$1,$B55,BV$5,$B$1) -> 0
A56: Share Capital | B56: QTRB_SHARE_CAPITAL | C56: =_xll.EQNXTDZ($A$1,$B56,C$5,$B$1) -> 0 | D56: =_xll.EQNXTDZ($A$1,$B56,D$5,$B$1) -> 237.33 | E56: =_xll.EQNXTDZ($A$1,$B56,E$5,$B$1) -> 0 | F56: =_xll.EQNXTDZ($A$1,$B56,F$5,$B$1) -> 237.29 | G56: =_xll.EQNXTDZ($A$1,$B56,G$5,$B$1) -> 0 | H56: =_xll.EQNXTDZ($A$1,$B56,H$5,$B$1) -> 237.29 | I56: =_xll.EQNXTDZ($A$1,$B56,I$5,$B$1) -> 0 | J56: =_xll.EQNXTDZ($A$1,$B56,J$5,$B$1) -> 237.29 | ... BV56: =_xll.EQNXTDZ($A$1,$B56,BV$5,$B$1) -> 0
A57: Share Warrants & outstandings | B57: QTRB_SHAREWARNDOUT | C57: =_xll.EQNXTDZ($A$1,$B57,C$5,$B$1) -> 0 | D57: =_xll.EQNXTDZ($A$1,$B57,D$5,$B$1) -> 0 | E57: =_xll.EQNXTDZ($A$1,$B57,E$5,$B$1) -> 0 | F57: =_xll.EQNXTDZ($A$1,$B57,F$5,$B$1) -> 0 | G57: =_xll.EQNXTDZ($A$1,$B57,G$5,$B$1) -> 0 | H57: =_xll.EQNXTDZ($A$1,$B57,H$5,$B$1) -> 0 | I57: =_xll.EQNXTDZ($A$1,$B57,I$5,$B$1) -> 0 | J57: =_xll.EQNXTDZ($A$1,$B57,J$5,$B$1) -> 0 | ... BV57: =_xll.EQNXTDZ($A$1,$B57,BV$5,$B$1) -> 0
A58: Reserves & Surplus | B58: QTRB_RESERVE | C58: =_xll.EQNXTDZ($A$1,$B58,C$5,$B$1) -> 0 | D58: =_xll.EQNXTDZ($A$1,$B58,D$5,$B$1) -> 12164.02 | E58: =_xll.EQNXTDZ($A$1,$B58,E$5,$B$1) -> 0 | F58: =_xll.EQNXTDZ($A$1,$B58,F$5,$B$1) -> 12098.5 | G58: =_xll.EQNXTDZ($A$1,$B58,G$5,$B$1) -> 0 | H58: =_xll.EQNXTDZ($A$1,$B58,H$5,$B$1) -> 12811.78 | I58: =_xll.EQNXTDZ($A$1,$B58,I$5,$B$1) -> 0 | J58: =_xll.EQNXTDZ($A$1,$B58,J$5,$B$1) -> 12163.78 | ... BV58: =_xll.EQNXTDZ($A$1,$B58,BV$5,$B$1) -> 0
A59: Shareholder's Funds | B59: QTRB_SHAREHODERS_FUNDS | C59: =_xll.EQNXTDZ($A$1,$B59,C$5,$B$1) -> 0 | D59: =_xll.EQNXTDZ($A$1,$B59,D$5,$B$1) -> 12401.35 | E59: =_xll.EQNXTDZ($A$1,$B59,E$5,$B$1) -> 0 | F59: =_xll.EQNXTDZ($A$1,$B59,F$5,$B$1) -> 12335.79 | G59: =_xll.EQNXTDZ($A$1,$B59,G$5,$B$1) -> 0 | H59: =_xll.EQNXTDZ($A$1,$B59,H$5,$B$1) -> 13049.07 | I59: =_xll.EQNXTDZ($A$1,$B59,I$5,$B$1) -> 0 | J59: =_xll.EQNXTDZ($A$1,$B59,J$5,$B$1) -> 12401.07 | ... BV59: =_xll.EQNXTDZ($A$1,$B59,BV$5,$B$1) -> 0
A60: Minority Interest | B60: QTRB_MINORITY_INTEREST_BS | C60: =_xll.EQNXTDZ($A$1,$B60,C$5,$B$1) -> 0 | D60: =_xll.EQNXTDZ($A$1,$B60,D$5,$B$1) -> 0 | E60: =_xll.EQNXTDZ($A$1,$B60,E$5,$B$1) -> 0 | F60: =_xll.EQNXTDZ($A$1,$B60,F$5,$B$1) -> 2064.6 | G60: =_xll.EQNXTDZ($A$1,$B60,G$5,$B$1) -> 0 | H60: =_xll.EQNXTDZ($A$1,$B60,H$5,$B$1) -> 2163.78 | I60: =_xll.EQNXTDZ($A$1,$B60,I$5,$B$1) -> 0 | J60: =_xll.EQNXTDZ($A$1,$B60,J$5,$B$1) -> 2273.31 | ... BV60: =_xll.EQNXTDZ($A$1,$B60,BV$5,$B$1) -> 0
A61: Long Term Borrowings | B61: QTRB_TOTAL_DEBTS | C61: =_xll.EQNXTDZ($A$1,$B61,C$5,$B$1) -> 0 | D61: =_xll.EQNXTDZ($A$1,$B61,D$5,$B$1) -> 9940.71 | E61: =_xll.EQNXTDZ($A$1,$B61,E$5,$B$1) -> 0 | F61: =_xll.EQNXTDZ($A$1,$B61,F$5,$B$1) -> 33099.34 | G61: =_xll.EQNXTDZ($A$1,$B61,G$5,$B$1) -> 0 | H61: =_xll.EQNXTDZ($A$1,$B61,H$5,$B$1) -> 34342.24 | I61: =_xll.EQNXTDZ($A$1,$B61,I$5,$B$1) -> 0 | J61: =_xll.EQNXTDZ($A$1,$B61,J$5,$B$1) -> 31969.94 | ... BV61: =_xll.EQNXTDZ($A$1,$B61,BV$5,$B$1) -> 0
A62: Secured Loans | B62: QTRB_SECURED_LOANS | C62: =_xll.EQNXTDZ($A$1,$B62,C$5,$B$1) -> 0 | D62: =_xll.EQNXTDZ($A$1,$B62,D$5,$B$1) -> 0 | E62: =_xll.EQNXTDZ($A$1,$B62,E$5,$B$1) -> 0 | F62: =_xll.EQNXTDZ($A$1,$B62,F$5,$B$1) -> 0 | G62: =_xll.EQNXTDZ($A$1,$B62,G$5,$B$1) -> 0 | H62: =_xll.EQNXTDZ($A$1,$B62,H$5,$B$1) -> 0 | I62: =_xll.EQNXTDZ($A$1,$B62,I$5,$B$1) -> 0 | J62: =_xll.EQNXTDZ($A$1,$B62,J$5,$B$1) -> 0 | ... BV62: =_xll.EQNXTDZ($A$1,$B62,BV$5,$B$1) -> 0
A63: Unsecured Loans | B63: QTRB_UNSECURED_LOANS_NF | C63: =_xll.EQNXTDZ($A$1,$B63,C$5,$B$1) -> 0 | D63: =_xll.EQNXTDZ($A$1,$B63,D$5,$B$1) -> 9940.71 | E63: =_xll.EQNXTDZ($A$1,$B63,E$5,$B$1) -> 0 | F63: =_xll.EQNXTDZ($A$1,$B63,F$5,$B$1) -> 33099.34 | G63: =_xll.EQNXTDZ($A$1,$B63,G$5,$B$1) -> 0 | H63: =_xll.EQNXTDZ($A$1,$B63,H$5,$B$1) -> 34342.24 | I63: =_xll.EQNXTDZ($A$1,$B63,I$5,$B$1) -> 0 | J63: =_xll.EQNXTDZ($A$1,$B63,J$5,$B$1) -> 31969.94 | ... BV63: =_xll.EQNXTDZ($A$1,$B63,BV$5,$B$1) -> 0
A64: Other Long Term Liabilities | B64: QTRB_OTHER_LT_LIABILITIES | C64: =_xll.EQNXTDZ($A$1,$B64,C$5,$B$1) -> 0 | D64: =_xll.EQNXTDZ($A$1,$B64,D$5,$B$1) -> 99.86 | E64: =_xll.EQNXTDZ($A$1,$B64,E$5,$B$1) -> 0 | F64: =_xll.EQNXTDZ($A$1,$B64,F$5,$B$1) -> 949.11 | G64: =_xll.EQNXTDZ($A$1,$B64,G$5,$B$1) -> 0 | H64: =_xll.EQNXTDZ($A$1,$B64,H$5,$B$1) -> 993.27 | I64: =_xll.EQNXTDZ($A$1,$B64,I$5,$B$1) -> 0 | J64: =_xll.EQNXTDZ($A$1,$B64,J$5,$B$1) -> 974.57 | ... BV64: =_xll.EQNXTDZ($A$1,$B64,BV$5,$B$1) -> 0
A65: Long Term Trade Payables | B65: QTRB_LT_TRADE_PAYABLE | C65: =_xll.EQNXTDZ($A$1,$B65,C$5,$B$1) -> 0 | D65: =_xll.EQNXTDZ($A$1,$B65,D$5,$B$1) -> 0 | E65: =_xll.EQNXTDZ($A$1,$B65,E$5,$B$1) -> 0 | F65: =_xll.EQNXTDZ($A$1,$B65,F$5,$B$1) -> 0 | G65: =_xll.EQNXTDZ($A$1,$B65,G$5,$B$1) -> 0 | H65: =_xll.EQNXTDZ($A$1,$B65,H$5,$B$1) -> 0 | I65: =_xll.EQNXTDZ($A$1,$B65,I$5,$B$1) -> 0 | J65: =_xll.EQNXTDZ($A$1,$B65,J$5,$B$1) -> 0 | ... BV65: =_xll.EQNXTDZ($A$1,$B65,BV$5,$B$1) -> 0
A66: Lont Term Provisions | B66: QTRB_LT_PROVISIONS | C66: =_xll.EQNXTDZ($A$1,$B66,C$5,$B$1) -> 0 | D66: =_xll.EQNXTDZ($A$1,$B66,D$5,$B$1) -> 529.38 | E66: =_xll.EQNXTDZ($A$1,$B66,E$5,$B$1) -> 0 | F66: =_xll.EQNXTDZ($A$1,$B66,F$5,$B$1) -> 1164.59 | G66: =_xll.EQNXTDZ($A$1,$B66,G$5,$B$1) -> 0 | H66: =_xll.EQNXTDZ($A$1,$B66,H$5,$B$1) -> 1273.11 | I66: =_xll.EQNXTDZ($A$1,$B66,I$5,$B$1) -> 0 | J66: =_xll.EQNXTDZ($A$1,$B66,J$5,$B$1) -> 914.77 | ... BV66: =_xll.EQNXTDZ($A$1,$B66,BV$5,$B$1) -> 0
... A97: Total Assets | B97: QTRB_TOTAL_APPLICATIONS | C97: =_xll.EQNXTDZ($A$1,$B97,C$5,$B$1) -> 0 | D97: =_xll.EQNXTDZ($A$1,$B97,D$5,$B$1) -> 22971.3 | E97: =_xll.EQNXTDZ($A$1,$B97,E$5,$B$1) -> 0 | F97: =_xll.EQNXTDZ($A$1,$B97,F$5,$B$1) -> 49613.43 | G97: =_xll.EQNXTDZ($A$1,$B97,G$5,$B$1) -> 0 | H97: =_xll.EQNXTDZ($A$1,$B97,H$5,$B$1) -> 51821.47 | I97: =_xll.EQNXTDZ($A$1,$B97,I$5,$B$1) -> 0 | J97: =_xll.EQNXTDZ($A$1,$B97,J$5,$B$1) -> 48533.66 | ... BV97: =_xll.EQNXTDZ($A$1,$B97,BV$5,$B$1) -> 0

Sheet Annual Raw
A1: 100400 | B1: X | C1: 200103 | D1: 200203 | E1: 200303 | F1: 200403 | G1: 200503 | H1: 200603 | I1: 200703 | J1: 200803 | K1: 200903 | L1: 201003 | M1: 201103 | N1: 201203 | O1: 201303 | P1: 201403 | Q1: 201503 | R1: 201603 | S1: 201703 | T1: 201803 | U1: 201903 | V1: 202003 | W1: 202103 | X1: 202203 | Y1: 202303 | Z1: 202403 | AA1: 202503 | AB1: 202603 | AC1: 202703 | AD1: 202803 | AE1: 202903 | AF1: 203003
A3: Field Description | B3: Field Name
A4: Company Name | B4: CD_COMPNAME | C4: =_xll.EQNXTDZ(A1,B4,"L") -> Tata Power Company Ltd.
A5: Year End | B5: PL_YEAR_END | C5: =_xll.EQNXTDZ($A$1,$B5,C$1,$B$1) -> 200103 | D5: =_xll.EQNXTDZ($A$1,$B5,D$1,$B$1) -> 200203 | E5: =_xll.EQNXTDZ($A$1,$B5,E$1,$B$1) -> 200303 | F5: =_xll.EQNXTDZ($A$1,$B5,F$1,$B$1) -> 200403 | G5: =_xll.EQNXTDZ($A$1,$B5,G$1,$B$1) -> 200503 | H5: =_xll.EQNXTDZ($A$1,$B5,H$1,$B$1) -> 200603 | I5: =_xll.EQNXTDZ($A$1,$B5,I$1,$B$1) -> 200703 | J5: =_xll.EQNXTDZ($A$1,$B5,J$1,$B$1) -> 200803 | ... AF5: =_xll.EQNXTDZ($A$1,$B5,AF$1,$B$1) -> 0
A6: Sales Turnover | B6: PL_TOTAL_GROSS_SALES | C6: =_xll.EQNXTDZ($A$1,$B6,C$1,$B$1) -> 3374.8175 | D6: =_xll.EQNXTDZ($A$1,$B6,D$1,$B$1) -> 3861.06 | E6: =_xll.EQNXTDZ($A$1,$B6,E$1,$B$1) -> 4805.45 | F6: =_xll.EQNXTDZ($A$1,$B6,F$1,$B$1) -> 4996.38 | G6: =_xll.EQNXTDZ($A$1,$B6,G$1,$B$1) -> 4900.58 | H6: =_xll.EQNXTDZ($A$1,$B6,H$1,$B$1) -> 5623.21 | I6: =_xll.EQNXTDZ($A$1,$B6,I$1,$B$1) -> 6484.23 | J6: =_xll.EQNXTDZ($A$1,$B6,J$1,$B$1) -> 10904.19 | ... AF6: =_xll.EQNXTDZ($A$1,$B6,AF$1,$B$1) -> 0
A7: Less: Inter divisional transfers | B7: PL_INTER_DIV_TRF | C7: =_xll.EQNXTDZ($A$1,$B7,C$1,$B$1) -> 0 | D7: =_xll.EQNXTDZ($A$1,$B7,D$1,$B$1) -> 0 | E7: =_xll.EQNXTDZ($A$1,$B7,E$1,$B$1) -> 0 | F7: =_xll.EQNXTDZ($A$1,$B7,F$1,$B$1) -> 0 | G7: =_xll.EQNXTDZ($A$1,$B7,G$1,$B$1) -> 0 | H7: =_xll.EQNXTDZ($A$1,$B7,H$1,$B$1) -> 0 | I7: =_xll.EQNXTDZ($A$1,$B7,I$1,$B$1) -> 0 | J7: =_xll.EQNXTDZ($A$1,$B7,J$1,$B$1) -> 0 | ... AF7: =_xll.EQNXTDZ($A$1,$B7,AF$1,$B$1) -> 0
A8: Less: Sales Returns | B8: PL_SALES_RETURN | C8: =_xll.EQNXTDZ($A$1,$B8,C$1,$B$1) -> 0 | D8: =_xll.EQNXTDZ($A$1,$B8,D$1,$B$1) -> 0 | E8: =_xll.EQNXTDZ($A$1,$B8,E$1,$B$1) -> 0 | F8: =_xll.EQNXTDZ($A$1,$B8,F$1,$B$1) -> 0 | G8: =_xll.EQNXTDZ($A$1,$B8,G$1,$B$1) -> 0 | H8: =_xll.EQNXTDZ($A$1,$B8,H$1,$B$1) -> 0 | I8: =_xll.EQNXTDZ($A$1,$B8,I$1,$B$1) -> 0 | J8: =_xll.EQNXTDZ($A$1,$B8,J$1,$B$1) -> 0 | ... AF8: =_xll.EQNXTDZ($A$1,$B8,AF$1,$B$1) -> 0
A9: Less: Excise | B9: PL_EXCISE | C9: =_xll.EQNXTDZ($A$1,$B9,C$1,$B$1) -> 0.355909 | D9: =_xll.EQNXTDZ($A$1,$B9,D$1,$B$1) -> 0 | E9: =_xll.EQNXTDZ($A$1,$B9,E$1,$B$1) -> 0 | F9: =_xll.EQNXTDZ($A$1,$B9,F$1,$B$1) -> 2.66 | G9: =_xll.EQNXTDZ($A$1,$B9,G$1,$B$1) -> 0.29 | H9: =_xll.EQNXTDZ($A$1,$B9,H$1,$B$1) -> 1.95 | I9: =_xll.EQNXTDZ($A$1,$B9,I$1,$B$1) -> 8.59 | J9: =_xll.EQNXTDZ($A$1,$B9,J$1,$B$1) -> 13.33 | ... AF9: =_xll.EQNXTDZ($A$1,$B9,AF$1,$B$1) -> 0
A10: Net Sales | B10: PL_NET_SALES | C10: =_xll.EQNXTDZ($A$1,$B10,C$1,$B$1) -> 3374.4616 | D10: =_xll.EQNXTDZ($A$1,$B10,D$1,$B$1) -> 3861.06 | E10: =_xll.EQNXTDZ($A$1,$B10,E$1,$B$1) -> 4805.45 | F10: =_xll.EQNXTDZ($A$1,$B10,F$1,$B$1) -> 4993.72 | G10: =_xll.EQNXTDZ($A$1,$B10,G$1,$B$1) -> 4900.29 | H10: =_xll.EQNXTDZ($A$1,$B10,H$1,$B$1) -> 5621.26 | I10: =_xll.EQNXTDZ($A$1,$B10,I$1,$B$1) -> 6475.64 | J10: =_xll.EQNXTDZ($A$1,$B10,J$1,$B$1) -> 10890.86 | ... AF10: =_xll.EQNXTDZ($A$1,$B10,AF$1,$B$1) -> 0
A11: Increase/Decrease in Stock | B11: PL_INC_DEC_INVENTORY | C11: =_xll.EQNXTDZ($A$1,$B11,C$1,$B$1) -> -7.9388933 | D11: =_xll.EQNXTDZ($A$1,$B11,D$1,$B$1) -> 1.81 | E11: =_xll.EQNXTDZ($A$1,$B11,E$1,$B$1) -> 19.2 | F11: =_xll.EQNXTDZ($A$1,$B11,F$1,$B$1) -> 0.58 | G11: =_xll.EQNXTDZ($A$1,$B11,G$1,$B$1) -> 1.88 | H11: =_xll.EQNXTDZ($A$1,$B11,H$1,$B$1) -> -28.48 | I11: =_xll.EQNXTDZ($A$1,$B11,I$1,$B$1) -> -7.71 | J11: =_xll.EQNXTDZ($A$1,$B11,J$1,$B$1) -> 17.26 | ... AF11: =_xll.EQNXTDZ($A$1,$B11,AF$1,$B$1) -> 0
A12: Raw Material Consumed | B12: PL_RAW_MATRS_CONSUMED | C12: =_xll.EQNXTDZ($A$1,$B12,C$1,$B$1) -> 0 | D12: =_xll.EQNXTDZ($A$1,$B12,D$1,$B$1) -> 0 | E12: =_xll.EQNXTDZ($A$1,$B12,E$1,$B$1) -> 0 | F12: =_xll.EQNXTDZ($A$1,$B12,F$1,$B$1) -> 0 | G12: =_xll.EQNXTDZ($A$1,$B12,G$1,$B$1) -> 0 | H12: =_xll.EQNXTDZ($A$1,$B12,H$1,$B$1) -> 0 | I12: =_xll.EQNXTDZ($A$1,$B12,I$1,$B$1) -> 0 | J12: =_xll.EQNXTDZ($A$1,$B12,J$1,$B$1) -> 0 | ... AF12: =_xll.EQNXTDZ($A$1,$B12,AF$1,$B$1) -> 0
A13: Power & Fuel Cost | B13: PL_POWER_FUEL | C13: =_xll.EQNXTDZ($A$1,$B13,C$1,$B$1) -> 2107.8016 | D13: =_xll.EQNXTDZ($A$1,$B13,D$1,$B$1) -> 2188.79 | E13: =_xll.EQNXTDZ($A$1,$B13,E$1,$B$1) -> 2783.68 | F13: =_xll.EQNXTDZ($A$1,$B13,F$1,$B$1) -> 2698.83 | G13: =_xll.EQNXTDZ($A$1,$B13,G$1,$B$1) -> 3011.47 | H13: =_xll.EQNXTDZ($A$1,$B13,H$1,$B$1) -> 3770.73 | I13: =_xll.EQNXTDZ($A$1,$B13,I$1,$B$1) -> 4626 | J13: =_xll.EQNXTDZ($A$1,$B13,J$1,$B$1) -> 6512.76 | ... AF13: =_xll.EQNXTDZ($A$1,$B13,AF$1,$B$1) -> 0
A14: Employee Cost | B14: PL_EMPLOYEES | C14: =_xll.EQNXTDZ($A$1,$B14,C$1,$B$1) -> 133.60525 | D14: =_xll.EQNXTDZ($A$1,$B14,D$1,$B$1) -> 137.15 | E14: =_xll.EQNXTDZ($A$1,$B14,E$1,$B$1) -> 181.63 | F14: =_xll.EQNXTDZ($A$1,$B14,F$1,$B$1) -> 245.5 | G14: =_xll.EQNXTDZ($A$1,$B14,G$1,$B$1) -> 209.4 | H14: =_xll.EQNXTDZ($A$1,$B14,H$1,$B$1) -> 234.95 | I14: =_xll.EQNXTDZ($A$1,$B14,I$1,$B$1) -> 275.21 | J14: =_xll.EQNXTDZ($A$1,$B14,J$1,$B$1) -> 448.32 | ... AF14: =_xll.EQNXTDZ($A$1,$B14,AF$1,$B$1) -> 0
A15: Operating & Manufacturing Expenses | B15: PL_GEN_OTHER_MFG_EXPS | C15: =_xll.EQNXTDZ($A$1,$B15,C$1,$B$1) -> 151.80271 | D15: =_xll.EQNXTDZ($A$1,$B15,D$1,$B$1) -> 195.58 | E15: =_xll.EQNXTDZ($A$1,$B15,E$1,$B$1) -> 190.96 | F15: =_xll.EQNXTDZ($A$1,$B15,F$1,$B$1) -> 322.6 | G15: =_xll.EQNXTDZ($A$1,$B15,G$1,$B$1) -> 237.45 | H15: =_xll.EQNXTDZ($A$1,$B15,H$1,$B$1) -> 470.94 | I15: =_xll.EQNXTDZ($A$1,$B15,I$1,$B$1) -> 333.98 | J15: =_xll.EQNXTDZ($A$1,$B15,J$1,$B$1) -> 1298.52 | ... AF15: =_xll.EQNXTDZ($A$1,$B15,AF$1,$B$1) -> 0
A16: Cost of Software development | B16: PL_COST_SW | C16: =_xll.EQNXTDZ($A$1,$B16,C$1,$B$1) -> 0 | D16: =_xll.EQNXTDZ($A$1,$B16,D$1,$B$1) -> 0 | E16: =_xll.EQNXTDZ($A$1,$B16,E$1,$B$1) -> 0 | F16: =_xll.EQNXTDZ($A$1,$B16,F$1,$B$1) -> 0 | G16: =_xll.EQNXTDZ($A$1,$B16,G$1,$B$1) -> 0 | H16: =_xll.EQNXTDZ($A$1,$B16,H$1,$B$1) -> 0 | I16: =_xll.EQNXTDZ($A$1,$B16,I$1,$B$1) -> 0 | J16: =_xll.EQNXTDZ($A$1,$B16,J$1,$B$1) -> 0 | ... AF16: =_xll.EQNXTDZ($A$1,$B16,AF$1,$B$1) -> 0
... A36: Profit After Tax from Discontinued Operations | B36: PL_PAT_DIS_OP | C36: =_xll.EQNXTDZ($A$1,$B36,C$1,$B$1) -> 0 | D36: =_xll.EQNXTDZ($A$1,$B36,D$1,$B$1) -> 0 | E36: =_xll.EQNXTDZ($A$1,$B36,E$1,$B$1) -> 0 | F36: =_xll.EQNXTDZ($A$1,$B36,F$1,$B$1) -> 0 | G36: =_xll.EQNXTDZ($A$1,$B36,G$1,$B$1) -> 0 | H36: =_xll.EQNXTDZ($A$1,$B36,H$1,$B$1) -> 0 | I36: =_xll.EQNXTDZ($A$1,$B36,I$1,$B$1) -> 0 | J36: =_xll.EQNXTDZ($A$1,$B36,J$1,$B$1) -> 0 | ... AF36: =_xll.EQNXTDZ($A$1,$B36,AF$1,$B$1) -> 0
A39: Field Description | B39: Field Name
A40: Year End | B40: BS_YEAR_END | C40: =_xll.EQNXTDZ($A$1,$B40,C$1,$B$1) -> 200103 | D40: =_xll.EQNXTDZ($A$1,$B40,D$1,$B$1) -> 200203 | E40: =_xll.EQNXTDZ($A$1,$B40,E$1,$B$1) -> 200303 | F40: =_xll.EQNXTDZ($A$1,$B40,F$1,$B$1) -> 200403 | G40: =_xll.EQNXTDZ($A$1,$B40,G$1,$B$1) -> 200503 | H40: =_xll.EQNXTDZ($A$1,$B40,H$1,$B$1) -> 200603 | I40: =_xll.EQNXTDZ($A$1,$B40,I$1,$B$1) -> 200703 | J40: =_xll.EQNXTDZ($A$1,$B40,J$1,$B$1) -> 200803 | ... AF40: =_xll.EQNXTDZ($A$1,$B40,AF$1,$B$1) -> 0
A41: Share Capital | B41: BS_SHARE_CAPITAL | C41: =_xll.EQNXTDZ($A$1,$B41,C$1,$B$1) -> 197.91345 | D41: =_xll.EQNXTDZ($A$1,$B41,D$1,$B$1) -> 197.87 | E41: =_xll.EQNXTDZ($A$1,$B41,E$1,$B$1) -> 197.87 | F41: =_xll.EQNXTDZ($A$1,$B41,F$1,$B$1) -> 197.88 | G41: =_xll.EQNXTDZ($A$1,$B41,G$1,$B$1) -> 197.88 | H41: =_xll.EQNXTDZ($A$1,$B41,H$1,$B$1) -> 197.88 | I41: =_xll.EQNXTDZ($A$1,$B41,I$1,$B$1) -> 197.88 | J41: =_xll.EQNXTDZ($A$1,$B41,J$1,$B$1) -> 220.68 | ... AF41: =_xll.EQNXTDZ($A$1,$B41,AF$1,$B$1) -> 0
A42: Share Warrants & Outstandings | B42: BS_SHAREWROUTST | C42: =_xll.EQNXTDZ($A$1,$B42,C$1,$B$1) -> 0 | D42: =_xll.EQNXTDZ($A$1,$B42,D$1,$B$1) -> 0 | E42: =_xll.EQNXTDZ($A$1,$B42,E$1,$B$1) -> 0 | F42: =_xll.EQNXTDZ($A$1,$B42,F$1,$B$1) -> 0 | G42: =_xll.EQNXTDZ($A$1,$B42,G$1,$B$1) -> 0 | H42: =_xll.EQNXTDZ($A$1,$B42,H$1,$B$1) -> 0 | I42: =_xll.EQNXTDZ($A$1,$B42,I$1,$B$1) -> 0 | J42: =_xll.EQNXTDZ($A$1,$B42,J$1,$B$1) -> 60.99 | ... AF42: =_xll.EQNXTDZ($A$1,$B42,AF$1,$B$1) -> 0
A43: Total Reserves | B43: BS_RESERVE | C43: =_xll.EQNXTDZ($A$1,$B43,C$1,$B$1) -> 3670.1513 | D43: =_xll.EQNXTDZ($A$1,$B43,D$1,$B$1) -> 4027.96 | E43: =_xll.EQNXTDZ($A$1,$B43,E$1,$B$1) -> 4270.37 | F43: =_xll.EQNXTDZ($A$1,$B43,F$1,$B$1) -> 4592.28 | G43: =_xll.EQNXTDZ($A$1,$B43,G$1,$B$1) -> 4723.34 | H43: =_xll.EQNXTDZ($A$1,$B43,H$1,$B$1) -> 5284.03 | I43: =_xll.EQNXTDZ($A$1,$B43,I$1,$B$1) -> 5825.76 | J43: =_xll.EQNXTDZ($A$1,$B43,J$1,$B$1) -> 8063.15 | ... AF43: =_xll.EQNXTDZ($A$1,$B43,AF$1,$B$1) -> 0
A44: Shareholder's Funds | B44: BS_SHAREHODERS_FUNDS | C44: =_xll.EQNXTDZ($A$1,$B44,C$1,$B$1) -> 3868.0647 | D44: =_xll.EQNXTDZ($A$1,$B44,D$1,$B$1) -> 4225.83 | E44: =_xll.EQNXTDZ($A$1,$B44,E$1,$B$1) -> 4468.24 | F44: =_xll.EQNXTDZ($A$1,$B44,F$1,$B$1) -> 4790.16 | G44: =_xll.EQNXTDZ($A$1,$B44,G$1,$B$1) -> 4921.22 | H44: =_xll.EQNXTDZ($A$1,$B44,H$1,$B$1) -> 5481.91 | I44: =_xll.EQNXTDZ($A$1,$B44,I$1,$B$1) -> 6023.64 | J44: =_xll.EQNXTDZ($A$1,$B44,J$1,$B$1) -> 8344.82 | ... AF44: =_xll.EQNXTDZ($A$1,$B44,AF$1,$B$1) -> 0
A45: Minority Interest | B45: BS_MINORITY_INTEREST | C45: =_xll.EQNXTDZ($A$1,$B45,C$1,$B$1) -> 0 | D45: =_xll.EQNXTDZ($A$1,$B45,D$1,$B$1) -> 9.57 | E45: =_xll.EQNXTDZ($A$1,$B45,E$1,$B$1) -> 10 | F45: =_xll.EQNXTDZ($A$1,$B45,F$1,$B$1) -> 10.1 | G45: =_xll.EQNXTDZ($A$1,$B45,G$1,$B$1) -> 95.6 | H45: =_xll.EQNXTDZ($A$1,$B45,H$1,$B$1) -> 206.75 | I45: =_xll.EQNXTDZ($A$1,$B45,I$1,$B$1) -> 249.62 | J45: =_xll.EQNXTDZ($A$1,$B45,J$1,$B$1) -> 806.17 | ... AF45: =_xll.EQNXTDZ($A$1,$B45,AF$1,$B$1) -> 0
A46: Long-Term Borrowings | B46: BS_LTRM_BORROWING | C46: =_xll.EQNXTDZ($A$1,$B46,C$1,$B$1) -> 0 | D46: =_xll.EQNXTDZ($A$1,$B46,D$1,$B$1) -> 0 | E46: =_xll.EQNXTDZ($A$1,$B46,E$1,$B$1) -> 0 | F46: =_xll.EQNXTDZ($A$1,$B46,F$1,$B$1) -> 0 | G46: =_xll.EQNXTDZ($A$1,$B46,G$1,$B$1) -> 0 | H46: =_xll.EQNXTDZ($A$1,$B46,H$1,$B$1) -> 0 | I46: =_xll.EQNXTDZ($A$1,$B46,I$1,$B$1) -> 0 | J46: =_xll.EQNXTDZ($A$1,$B46,J$1,$B$1) -> 0 | ... AF46: =_xll.EQNXTDZ($A$1,$B46,AF$1,$B$1) -> 0
A47: Secured Loans | B47: BS_SECURED_LOANS | C47: =_xll.EQNXTDZ($A$1,$B47,C$1,$B$1) -> 1337.9599 | D47: =_xll.EQNXTDZ($A$1,$B47,D$1,$B$1) -> 1516.3 | E47: =_xll.EQNXTDZ($A$1,$B47,E$1,$B$1) -> 1691.54 | F47: =_xll.EQNXTDZ($A$1,$B47,F$1,$B$1) -> 1090.93 | G47: =_xll.EQNXTDZ($A$1,$B47,G$1,$B$1) -> 1949.47 | H47: =_xll.EQNXTDZ($A$1,$B47,H$1,$B$1) -> 2363.93 | I47: =_xll.EQNXTDZ($A$1,$B47,I$1,$B$1) -> 2822.83 | J47: =_xll.EQNXTDZ($A$1,$B47,J$1,$B$1) -> 8208.08 | ... AF47: =_xll.EQNXTDZ($A$1,$B47,AF$1,$B$1) -> 0
A48: Unsecured Loans | B48: BS_UNSECURED_LOANS_NF | C48: =_xll.EQNXTDZ($A$1,$B48,C$1,$B$1) -> 1259.9256 | D48: =_xll.EQNXTDZ($A$1,$B48,D$1,$B$1) -> 1290.45 | E48: =_xll.EQNXTDZ($A$1,$B48,E$1,$B$1) -> 1059.15 | F48: =_xll.EQNXTDZ($A$1,$B48,F$1,$B$1) -> 1003.36 | G48: =_xll.EQNXTDZ($A$1,$B48,G$1,$B$1) -> 1806.3 | H48: =_xll.EQNXTDZ($A$1,$B48,H$1,$B$1) -> 1864.54 | I48: =_xll.EQNXTDZ($A$1,$B48,I$1,$B$1) -> 2355.61 | J48: =_xll.EQNXTDZ($A$1,$B48,J$1,$B$1) -> 952.08 | ... AF48: =_xll.EQNXTDZ($A$1,$B48,AF$1,$B$1) -> 0
A49: Deferred Tax Assets / Liabilities | B49: BS_NET_DEF_TAX_NF | C49: =_xll.EQNXTDZ($A$1,$B49,C$1,$B$1) -> 0 | D49: =_xll.EQNXTDZ($A$1,$B49,D$1,$B$1) -> 130.57 | E49: =_xll.EQNXTDZ($A$1,$B49,E$1,$B$1) -> -21.22 | F49: =_xll.EQNXTDZ($A$1,$B49,F$1,$B$1) -> -17.66 | G49: =_xll.EQNXTDZ($A$1,$B49,G$1,$B$1) -> 43.96 | H49: =_xll.EQNXTDZ($A$1,$B49,H$1,$B$1) -> 33.62 | I49: =_xll.EQNXTDZ($A$1,$B49,I$1,$B$1) -> 45.82 | J49: =_xll.EQNXTDZ($A$1,$B49,J$1,$B$1) -> 282.02 | ... AF49: =_xll.EQNXTDZ($A$1,$B49,AF$1,$B$1) -> 0
A50: Other Long Term Liabilities | B50: BS_OTH_LT_LIAB | C50: =_xll.EQNXTDZ($A$1,$B50,C$1,$B$1) -> 0 | D50: =_xll.EQNXTDZ($A$1,$B50,D$1,$B$1) -> 0 | E50: =_xll.EQNXTDZ($A$1,$B50,E$1,$B$1) -> 0 | F50: =_xll.EQNXTDZ($A$1,$B50,F$1,$B$1) -> 0 | G50: =_xll.EQNXTDZ($A$1,$B50,G$1,$B$1) -> 0 | H50: =_xll.EQNXTDZ($A$1,$B50,H$1,$B$1) -> 0 | I50: =_xll.EQNXTDZ($A$1,$B50,I$1,$B$1) -> 0 | J50: =_xll.EQNXTDZ($A$1,$B50,J$1,$B$1) -> 0 | ... AF50: =_xll.EQNXTDZ($A$1,$B50,AF$1,$B$1) -> 0
A51: Long Term Trade Payables | B51: BS_LT_TRADE_PAYABLES | C51: =_xll.EQNXTDZ($A$1,$B51,C$1,$B$1) -> 0 | D51: =_xll.EQNXTDZ($A$1,$B51,D$1,$B$1) -> 0 | E51: =_xll.EQNXTDZ($A$1,$B51,E$1,$B$1) -> 0 | F51: =_xll.EQNXTDZ($A$1,$B51,F$1,$B$1) -> 0 | G51: =_xll.EQNXTDZ($A$1,$B51,G$1,$B$1) -> 0 | H51: =_xll.EQNXTDZ($A$1,$B51,H$1,$B$1) -> 0 | I51: =_xll.EQNXTDZ($A$1,$B51,I$1,$B$1) -> 0 | J51: =_xll.EQNXTDZ($A$1,$B51,J$1,$B$1) -> 0 | ... AF51: =_xll.EQNXTDZ($A$1,$B51,AF$1,$B$1) -> 0
... A99: Estimated Capital Contracts Remaining | B99: BS_ESTIMATED_CAPITAL_CONTRACT | C99: =_xll.EQNXTDZ($A$1,$B99,C$1,$B$1) -> 0 | D99: =_xll.EQNXTDZ($A$1,$B99,D$1,$B$1) -> 0 | E99: =_xll.EQNXTDZ($A$1,$B99,E$1,$B$1) -> 0 | F99: =_xll.EQNXTDZ($A$1,$B99,F$1,$B$1) -> 0 | G99: =_xll.EQNXTDZ($A$1,$B99,G$1,$B$1) -> 0 | H99: =_xll.EQNXTDZ($A$1,$B99,H$1,$B$1) -> 0 | I99: =_xll.EQNXTDZ($A$1,$B99,I$1,$B$1) -> 0 | J99: =_xll.EQNXTDZ($A$1,$B99,J$1,$B$1) -> 0 | ... AF99: =_xll.EQNXTDZ($A$1,$B99,AF$1,$B$1) -> 0
A103: Field Description | B103: Field Name
A104: Equity Paid Up | B104: BS_EQUITY_PAIDUP | C104: =_xll.EQNXTDZ($A$1,$B104,C$1,$B$1) -> 197.84458 | D104: =_xll.EQNXTDZ($A$1,$B104,D$1,$B$1) -> 197.81 | E104: =_xll.EQNXTDZ($A$1,$B104,E$1,$B$1) -> 197.81 | F104: =_xll.EQNXTDZ($A$1,$B104,F$1,$B$1) -> 197.82 | G104: =_xll.EQNXTDZ($A$1,$B104,G$1,$B$1) -> 197.82 | H104: =_xll.EQNXTDZ($A$1,$B104,H$1,$B$1) -> 197.82 | I104: =_xll.EQNXTDZ($A$1,$B104,I$1,$B$1) -> 197.82 | J104: =_xll.EQNXTDZ($A$1,$B104,J$1,$B$1) -> 220.62 | ... AF104: =_xll.EQNXTDZ($A$1,$B104,AF$1,$B$1) -> 0
A105: Face Value | B105: BS_FACE_VALUE | C105: =_xll.EQNXTDZ($A$1,$B105,C$1,$B$1) -> 10 | D105: =_xll.EQNXTDZ($A$1,$B105,D$1,$B$1) -> 10 | E105: =_xll.EQNXTDZ($A$1,$B105,E$1,$B$1) -> 10 | F105: =_xll.EQNXTDZ($A$1,$B105,F$1,$B$1) -> 10 | G105: =_xll.EQNXTDZ($A$1,$B105,G$1,$B$1) -> 10 | H105: =_xll.EQNXTDZ($A$1,$B105,H$1,$B$1) -> 10 | I105: =_xll.EQNXTDZ($A$1,$B105,I$1,$B$1) -> 10 | J105: =_xll.EQNXTDZ($A$1,$B105,J$1,$B$1) -> 10 | ... AF105: =_xll.EQNXTDZ($A$1,$B105,AF$1,$B$1) -> 0
A106: Close Price (Unit Curr.) | B106: FH_YEAR_PRICE | C106: =_xll.EQNXTDZ($A$1,$B106,C$1,$B$1) -> 9.5681419 | D106: =_xll.EQNXTDZ($A$1,$B106,D$1,$B$1) -> 10.952941 | E106: =_xll.EQNXTDZ($A$1,$B106,E$1,$B$1) -> 10.91434 | F106: =_xll.EQNXTDZ($A$1,$B106,F$1,$B$1) -> 36.37631 | G106: =_xll.EQNXTDZ($A$1,$B106,G$1,$B$1) -> 34.489702 | H106: =_xll.EQNXTDZ($A$1,$B106,H$1,$B$1) -> 55.9179 | I106: =_xll.EQNXTDZ($A$1,$B106,I$1,$B$1) -> 49.162783 | J106: =_xll.EQNXTDZ($A$1,$B106,J$1,$B$1) -> 113.09032 | ... AF106: =_xll.EQNXTDZ($A$1,$B106,AF$1,$B$1) -> 0
A107: High Price (Unit Curr.) | B107: FH_HIGH | C107: =_xll.EQNXTDZ($A$1,$B107,C$1,$B$1) -> 17.437854 | D107: =_xll.EQNXTDZ($A$1,$B107,D$1,$B$1) -> 14.92881 | E107: =_xll.EQNXTDZ($A$1,$B107,E$1,$B$1) -> 13.341358 | F107: =_xll.EQNXTDZ($A$1,$B107,F$1,$B$1) -> 41.30272 | G107: =_xll.EQNXTDZ($A$1,$B107,G$1,$B$1) -> 41.013215 | H107: =_xll.EQNXTDZ($A$1,$B107,H$1,$B$1) -> 58.436594 | I107: =_xll.EQNXTDZ($A$1,$B107,I$1,$B$1) -> 61.761077 | J107: =_xll.EQNXTDZ($A$1,$B107,J$1,$B$1) -> 158.35926 | ... AF107: =_xll.EQNXTDZ($A$1,$B107,AF$1,$B$1) -> 0
A108: Low Price (Unit Curr.) | B108: FH_LOW | C108: =_xll.EQNXTDZ($A$1,$B108,C$1,$B$1) -> 4.2701995 | D108: =_xll.EQNXTDZ($A$1,$B108,D$1,$B$1) -> 8.6851515 | E108: =_xll.EQNXTDZ($A$1,$B108,E$1,$B$1) -> 8.8781549 | F108: =_xll.EQNXTDZ($A$1,$B108,F$1,$B$1) -> 10.899865 | G108: =_xll.EQNXTDZ($A$1,$B108,G$1,$B$1) -> 20.516258 | H108: =_xll.EQNXTDZ($A$1,$B108,H$1,$B$1) -> 32.067509 | I108: =_xll.EQNXTDZ($A$1,$B108,I$1,$B$1) -> 37.635656 | J108: =_xll.EQNXTDZ($A$1,$B108,J$1,$B$1) -> 47.382326 | ... AF108: =_xll.EQNXTDZ($A$1,$B108,AF$1,$B$1) -> 0
A109: Market Capitalization | B109: FH_MCAP | C109: =_xll.EQNXTDZ($A$1,$B109,C$1,$B$1) -> 1961.629 | D109: =_xll.EQNXTDZ($A$1,$B109,D$1,$B$1) -> 2245.1435 | E109: =_xll.EQNXTDZ($A$1,$B109,E$1,$B$1) -> 2237.2311 | F109: =_xll.EQNXTDZ($A$1,$B109,F$1,$B$1) -> 7456.8249 | G109: =_xll.EQNXTDZ($A$1,$B109,G$1,$B$1) -> 7070.0868 | H109: =_xll.EQNXTDZ($A$1,$B109,H$1,$B$1) -> 11462.68 | I109: =_xll.EQNXTDZ($A$1,$B109,I$1,$B$1) -> 10077.94 | J109: =_xll.EQNXTDZ($A$1,$B109,J$1,$B$1) -> 25854.458 | ... AF109: =_xll.EQNXTDZ($A$1,$B109,AF$1,$B$1) -> 0
