Workbook
Name \a: #REF!
Name \b: #REF!
Name \c: #REF!
Name \COMM: #REF!
Name \COMM2: #REF!
Name \d: #REF!
Name \e: #REF!
Name \f: #REF!
Name \g: #REF!
Name \GROW: [1]Financials!$F$785
Name \h: #REF!
Name \i: #REF!
Name \j: #REF!
Name \L: #REF!
Name \M: #REF!
Name \MUL: #REF!
Name \MUL1: #REF!
Name \o: #REF!
Name \p: #REF!
Name \Q: [2]B!#REF!
Name \r: #REF!
Name \s: #REF!
Name \T: #REF!
Name \v: #REF!
Name \VEH: [1]Financials!$C$919
Name \w: #REF!
Name \x: #REF!
Name \y: #REF!
Name \Z: #REF!
Name __bs2: '[4]main standalone'!$A$98
Name __GROSS_SALES_T: #REF!
Name __NET_SALES_TO_: #REF!
Name _1_: [5]Old!#REF!
Name _2_0RMconsu: '[6]Operating Statistics'!#REF!
Name _3_0RMconsu: '[5]Operating Statistics'!#REF!
Name _bs2: '[4]main standalone'!$A$98
Name _CD201..D205__: #REF!
Name _DOWN_: #REF!
Name _EDIT__HOME__DE: #REF!
Name _kd17: #REF!
Name _kd18: #REF!
Name _kd19: #REF!
Name _kd20: #REF!
Name _kd21: #REF!
Name _kd22: #REF!
Name _kd23: #REF!
Name _kd24: #REF!
Name _kd25: #REF!
Name _MUL2: #REF!
Name _pc01: #REF!
Name _pc02: #REF!
Name _pc03: #REF!
Name _pc04: #REF!
Name _PG1: #REF!
Name _PL1: [7]Financials!#REF!
Name _RT1: #REF!
Name _RT2: #REF!
Name _RT3: #REF!
Name _RV__: #REF!
Name a: #REF!

Sheet Template
A1: =+'Annual Raw'!C4 -> Tata Motors Passenger Vehicles Ltd. | B1: 36951 | C1: =EOMONTH(B1,12) -> 37346 | D1: =EOMONTH(C1,12) -> 37711 | E1: =EOMONTH(D1,12) -> 38077 | F1: =EOMONTH(E1,12) -> 38442 | G1: =EOMONTH(F1,12) -> 38807 | H1: =EOMONTH(G1,12) -> 39172 | I1: =EOMONTH(H1,12) -> 39538 | J1: =EOMONTH(I1,12) -> 39903 | ... AE1: =EOMONTH(AD1,12) -> 47573 | AH1: QTR | AI1: 41061 | AJ1: 41153 | AK1: 41244 | AL1: 41334 | AM1: 41426 | AN1: 41518 | AO1: 41609 | AP1: 41699 | AQ1: 41791 | AR1: 41883 | AS1: 41974 | AT1: 42064 | AU1: 42156 | AV1: 42248 | AW1: 42339 | AX1: 42430 | AY1: 42522 | AZ1: 42614 | BA1: 42705 | BB1: 42795 | BC1: 42887 | BD1: 42979 | BE1: 43070 | BF1: 43160 | BG1: 43252 | BH1: 43344 | BI1: 43435 | BJ1: 43525 | BK1: 43617 | BL1: 43709 | BM1: 43800 | BN1: 43891 | BO1: 43983 | BP1: 44075 | BQ1: =EOMONTH(BP1,3) -> 44196 | BR1: =EOMONTH(BQ1,3) -> 44286 | BS1: =EOMONTH(BR1,3) -> 44377 | BT1: =EOMONTH(BS1,3) -> 44469 | BU1: =EOMONTH(BT1,3) -> 44561 | BV1: =EOMONTH(BU1,3) -> 44651 | BW1: =EOMONTH(BV1,3) -> 44742 | BX1: =EOMONTH(BW1,3) -> 44834 | ... DB1: =EOMONTH(DA1,3) -> 47573 | DE1: HISTORICAL ESTIMATES | DF1: 46112
A2: Presentation Data (Start)
A4: Volume | N4: =+SUM(N5:N6) -> 228900 | O4: =+SUM(O5:O6) -> 145786 | P4: =+SUM(P5:P6) -> 137565 | Q4: =+SUM(Q5:Q6) -> 132974 | R4: =+SUM(R5:R6) -> 157294 | S4: =+SUM(S5:S6) -> 189512 | T4: =+SUM(T5:T6) -> 212164 | U4: =+SUM(U5:U6) -> 133424 | ... AA4: =+SUM(AA5:AA6) -> 642771 | AB4: =+SUM(CM4:CP4) -> 909104.42 | AC4: =+SUM(CQ4:CT4) -> 1292943.7 | AD4: =+SUM(CU4:CX4) -> 1838846.4 | AE4: =+SUM(CY4:DB4) -> 2615238.5 | AI4: =+SUM(AI5:AI6) -> 62140 | AJ4: =+SUM(AJ5:AJ6) -> 72423 | AK4: =+SUM(AK5:AK6) -> 54412 | AL4: =+SUM(AL5:AL6) -> 39925 | AM4: =+SUM(AM5:AM6) -> 36675 | AN4: =+SUM(AN5:AN6) -> 37722 | AO4: =+SUM(AO5:AO6) -> 34881 | AP4: =+SUM(AP5:AP6) -> 36508 | ... CJ4: =+SUM(CJ5:CJ6) -> 144397 | CK4: =SUM(CK5:CK6) -> 172197 | CL4: =SUM(CL5:CL6) -> 201368 | CM4: =+'Monthly Nos Company'!$J$173 -> 172450.09 | CN4: =+'Monthly Nos Company'!$J$176 -> 205363.86 | CO4: =+'Monthly Nos Company'!$J$179 -> 244901.49 | CP4: =+'Monthly Nos Company'!$J$182 -> 286388.98 | CQ4: =+'Monthly Nos Company'!$J$185 -> 245261.44 | CR4: =+'Monthly Nos Company'!$J$188 -> 292071.96 | CS4: =+'Monthly Nos Company'!$J$191 -> 348303.05 | CT4: =+'Monthly Nos Company'!$J$194 -> 407307.26 | CU4: =+'Monthly Nos Company'!$J$197 -> 348814.98 | CV4: =+'Monthly Nos Company'!$J$200 -> 415389.69 | CW4: =+'Monthly Nos Company'!$J$203 -> 495362.49 | CX4: =+'Monthly Nos Company'!$J$206 -> 579279.28 | CY4: =+'Monthly Nos Company'!$J$209 -> 496090.57 | CZ4: =+'Monthly Nos Company'!$J$212 -> 590774.25 | DA4: =+'Monthly Nos Company'!$J$215 -> 704512.93 | DB4: =+'Monthly Nos Company'!$J$218 -> 823860.8
A5: Volume - Domestic | N5: =+SUM(AI5:AL5) -> 222112 | O5: =+SUM(AM5:AP5) -> 138455 | P5: =+SUM(AQ5:AT5) -> 134079 | Q5: =+SUM(AU5:AX5) -> 126534 | R5: =+SUM(AY5:BB5) -> 153257 | S5: =+SUM(BC5:BF5) -> 187321 | T5: =+SUM(BG5:BJ5) -> 210143 | U5: =+SUM(BK5:BN5) -> 131891 | V5: =+SUM(BO5:BR5) -> 218876 | W5: =+SUM(BS5:BV5) -> 370372 | X5: =+SUM(BW5:BZ5) -> 538942 | Y5: =+SUM(CA5:CD5) -> 570985 | Z5: =+SUM(CE5:CH5) -> 553585 | AA5: =SUM(CI5:CL5) -> 631548 | AI5: =+'Monthly Nos Company'!$K$5 -> 60405 | AJ5: =+'Monthly Nos Company'!$K$8 -> 70203 | AK5: =+'Monthly Nos Company'!$K$11 -> 53335 | AL5: =+'Monthly Nos Company'!$K$14 -> 38169 | AM5: =+'Monthly Nos Company'!$K$17 -> 34508 | AN5: =+'Monthly Nos Company'!$K$20 -> 35227 | AO5: =+'Monthly Nos Company'!$K$23 -> 33781 | AP5: =+'Monthly Nos Company'!$K$26 -> 34939 | AQ5: =+'Monthly Nos Company'!$K$29 -> 24582 | AR5: =+'Monthly Nos Company'!$K$32 -> 32072 | AS5: =+'Monthly Nos Company'!$K$35 -> 35572 | AT5: =+'Monthly Nos Company'!$K$38 -> 41853 | AU5: =+'Monthly Nos Company'!$K$41 -> 31649 | AV5: =+'Monthly Nos Company'!$K$44 -> 33357 | AW5: =+'Monthly Nos Company'!$K$47 -> 31384 | AX5: =+'Monthly Nos Company'!$K$50 -> 30144 | AY5: =+'Monthly Nos Company'!$K$53 -> 31621 | AZ5: =+'Monthly Nos Company'!$K$56 -> 41150 | BA5: =+'Monthly Nos Company'!$K$59 -> 39874 | BB5: =+'Monthly Nos Company'!$K$62 -> 40612 | BC5: =+'Monthly Nos Company'!$K$65 -> 34858 | BD5: =+'Monthly Nos Company'!$K$68 -> 46559 | BE5: =+'Monthly Nos Company'!$K$71 -> 47812 | BF5: =+'Monthly Nos Company'!$K$74 -> 58092 | BG5: =+'Monthly Nos Company'!$K$77 -> 52937 | BH5: =+'Monthly Nos Company'!$K$80 -> 53928 | BI5: =+'Monthly Nos Company'!$K$83 -> 49532 | BJ5: =+'Monthly Nos Company'!$K$86 -> 53746 | BK5: =+'Monthly Nos Company'!$K$89 -> 37639 | BL5: =+'Monthly Nos Company'!$K$92 -> 25898 | BM5: =+'Monthly Nos Company'!$K$95 -> 36354 | BN5: =+'Monthly Nos Company'!$K$98 -> 32000 | BO5: =+'Monthly Nos Company'!$K$101 -> 11419 | BP5: =+'Monthly Nos Company'!$K$104 -> 54794 | BQ5: =+'Monthly Nos Company'!$K$107 -> 68806 | BR5: =+'Monthly Nos Company'!$K$110 -> 83857 | BS5: =+'Monthly Nos Company'!$K$113 -> 64386 | BT5: =+'Monthly Nos Company'!$K$116 -> 83933 | BU5: =+'Monthly Nos Company'!$K$119 -> 99002 | BV5: =+'Monthly Nos Company'!$K$122 -> 123051 | BW5: =+'Monthly Nos Company'!$K$125 -> 130125 | BX5: =+'Monthly Nos Company'!$K$128 -> 142325 | BY5: =+'Monthly Nos Company'!$K$131 -> 131297 | BZ5: =+'Monthly Nos Company'!$K$134 -> 135195 | CA5: =+'Monthly Nos Company'!$K$137 -> 140120 | CB5: =+'Monthly Nos Company'!$K$140 -> 137950 | CC5: =+'Monthly Nos Company'!$K$143 -> 137875 | CD5: =+'Monthly Nos Company'!$K$146 -> 155040 | CE5: =+'Monthly Nos Company'!$K$149 -> 138104 | CF5: =+'Monthly Nos Company'!$K$152 -> 129930 | CG5: =+'Monthly Nos Company'!$K$155 -> 139424 | CH5: =+'Monthly Nos Company'!$K$158 -> 146127 | CI5: =+'Monthly Nos Company'!$K$161 -> 123839 | CJ5: =+'Monthly Nos Company'!$K$164 -> 140189 | CK5: =+'Monthly Nos Company'!$K$167 -> 168777 | CL5: ='Monthly Nos Company'!K170 -> 198743
A6: Volume - Export | N6: =+SUM(AI6:AL6) -> 6788 | O6: =+SUM(AM6:AP6) -> 7331 | P6: =+SUM(AQ6:AT6) -> 3486 | Q6: =+SUM(AU6:AX6) -> 6440 | R6: =+SUM(AY6:BB6) -> 4037 | S6: =+SUM(BC6:BF6) -> 2191 | T6: =+SUM(BG6:BJ6) -> 2021 | U6: =+SUM(BK6:BN6) -> 1533 | V6: =+SUM(BO6:BR6) -> 552 | W6: =+SUM(BS6:BV6) -> 1892 | X6: =+SUM(BW6:BZ6) -> 2447 | Y6: =+SUM(CA6:CD6) -> 2540 | Z6: =+SUM(CE6:CH6) -> 2678 | AA6: =SUM(CI6:CL6) -> 11223 | AI6: =+'Monthly Nos Company'!$L$5 -> 1735 | AJ6: =+'Monthly Nos Company'!$L$8 -> 2220 | AK6: =+'Monthly Nos Company'!$L$11 -> 1077 | AL6: =+'Monthly Nos Company'!$L$14 -> 1756 | AM6: =+'Monthly Nos Company'!$L$17 -> 2167 | AN6: =+'Monthly Nos Company'!$L$20 -> 2495 | AO6: =+'Monthly Nos Company'!$L$23 -> 1100 | AP6: =+'Monthly Nos Company'!$L$26 -> 1569 | AQ6: =+'Monthly Nos Company'!$L$29 -> 887 | AR6: =+'Monthly Nos Company'!$L$32 -> 1127 | AS6: =+'Monthly Nos Company'!$L$35 -> 756 | AT6: =+'Monthly Nos Company'!$L$38 -> 716 | AU6: =+'Monthly Nos Company'!$L$41 -> 1444 | AV6: =+'Monthly Nos Company'!$L$44 -> 1455 | AW6: =+'Monthly Nos Company'!$L$47 -> 1419 | AX6: =+'Monthly Nos Company'!$L$50 -> 2122 | AY6: =+'Monthly Nos Company'!$L$53 -> 664 | AZ6: =+'Monthly Nos Company'!$L$56 -> 1539 | BA6: =+'Monthly Nos Company'!$L$59 -> 1090 | BB6: =+'Monthly Nos Company'!$L$62 -> 744 | BC6: =+'Monthly Nos Company'!$L$65 -> 313 | BD6: =+'Monthly Nos Company'!$L$68 -> 406 | BE6: =+'Monthly Nos Company'!$L$71 -> 605 | BF6: =+'Monthly Nos Company'!$L$74 -> 867 | BG6: =+'Monthly Nos Company'!$L$77 -> 382 | BH6: =+'Monthly Nos Company'!$L$80 -> 503 | BI6: =+'Monthly Nos Company'!$L$83 -> 460 | BJ6: =+'Monthly Nos Company'!$L$86 -> 676 | BK6: =+'Monthly Nos Company'!$L$89 -> 296 | BL6: =+'Monthly Nos Company'!$L$92 -> 531 | BM6: =+'Monthly Nos Company'!$L$95 -> 355 | BN6: =+'Monthly Nos Company'!$L$98 -> 351 | BO6: =+'Monthly Nos Company'!$L$101 -> 20 | BP6: =+'Monthly Nos Company'!$L$104 -> 64 | BQ6: =+'Monthly Nos Company'!$L$107 -> 89 | BR6: =+'Monthly Nos Company'!$L$110 -> 379 | BS6: =+'Monthly Nos Company'!$L$113 -> 343 | BT6: =+'Monthly Nos Company'!$L$116 -> 450 | BU6: =+'Monthly Nos Company'!$L$119 -> 561 | BV6: =+'Monthly Nos Company'!$L$122 -> 538 | BW6: =+'Monthly Nos Company'!$L$125 -> 202 | BX6: =+'Monthly Nos Company'!$L$128 -> 526 | BY6: =+'Monthly Nos Company'!$L$131 -> 958 | BZ6: =+'Monthly Nos Company'!$L$134 -> 761 | CA6: =+'Monthly Nos Company'!$L$137 -> 330 | CB6: =+'Monthly Nos Company'!$L$140 -> 989 | CC6: =+'Monthly Nos Company'!$L$143 -> 580 | CD6: =+'Monthly Nos Company'!$L$146 -> 641 | CE6: =+'Monthly Nos Company'!$L$149 -> 578 | CF6: =+'Monthly Nos Company'!$L$152 -> 823 | CG6: =+'Monthly Nos Company'!$L$155 -> 405 | CH6: =+'Monthly Nos Company'!$L$158 -> 872 | CI6: =+'Monthly Nos Company'!$L$161 -> 970 | CJ6: =+'Monthly Nos Company'!$L$164 -> 4208 | CK6: =+'Monthly Nos Company'!$L$167 -> 3420 | CL6: ='Monthly Nos Company'!L170 -> 2625
A7: Volume YoY% | O7: =+O4/N4-1 -> -0.36310179 | P7: =+P4/O4-1 -> -0.056390874 | Q7: =+Q4/P4-1 -> -0.033373314 | R7: =+R4/Q4-1 -> 0.1828929 | S7: =+S4/R4-1 -> 0.20482663 | T7: =+T4/S4-1 -> 0.11952805 | U7: =+U4/T4-1 -> -0.371128 | V7: =+V4/U4-1 -> 0.64459168 | ... AE7: =+AE4/AD4-1 -> 0.42221694 | AM7: =+AM4/AI4-1 -> -0.40980045 | AN7: =+AN4/AJ4-1 -> -0.47914337 | AO7: =+AO4/AK4-1 -> -0.35894656 | AP7: =+AP4/AL4-1 -> -0.085585473 | AQ7: =+AQ4/AM4-1 -> -0.30554874 | AR7: =+AR4/AN4-1 -> -0.1199035 | AS7: =+AS4/AO4-1 -> 0.041483902 | AT7: =+AT4/AP4-1 -> 0.16601841 | ... DB7: =+DB4/CX4-1 -> 0.42221694
A9: Co. reported Volume TTM | N9: =N4 -> 228900 | O9: =O4 -> 145786 | P9: =P4 -> 137565 | Q9: =Q4 -> 132974 | R9: =R4 -> 157294 | S9: =S4 -> 189512 | T9: =T4 -> 212164 | U9: =U4 -> 133424 | ... AA9: =AA4 -> 642771 | AL9: =SUM(AI4:AL4) -> 228900 | AM9: =SUM(AJ4:AM4) -> 203435 | AN9: =SUM(AK4:AN4) -> 168734 | AO9: =SUM(AL4:AO4) -> 149203 | AP9: =SUM(AM4:AP4) -> 145786 | AQ9: =SUM(AN4:AQ4) -> 134580 | AR9: =SUM(AO4:AR4) -> 130057 | AS9: =SUM(AP4:AS4) -> 131504 | ... CL9: =SUM(CI4:CL4) -> 642771
A10: Vahan Volume TTM | N10: =N28 -> 0 | O10: =O28 -> 0 | P10: =P28 -> 0 | Q10: =Q28 -> 0 | R10: =R28 -> 0 | S10: =S28 -> 0 | T10: =T28 -> 583718 | U10: =U28 -> 536165 | ... AA10: =AA28 -> 518234 | AL10: =SUM(AI28:AL28) -> 0 | AM10: =SUM(AJ28:AM28) -> 0 | AN10: =SUM(AK28:AN28) -> 0 | AO10: =SUM(AL28:AO28) -> 0 | AP10: =SUM(AM28:AP28) -> 0 | AQ10: =SUM(AN28:AQ28) -> 0 | AR10: =SUM(AO28:AR28) -> 0 | AS10: =SUM(AP28:AS28) -> 0 | ... CL10: =SUM(CI28:CL28) -> 518234
A11: Co. reported Volume TTM Growth YoY | O11: =O9/N9-1 -> -0.36310179 | P11: =P9/O9-1 -> -0.056390874 | Q11: =Q9/P9-1 -> -0.033373314 | R11: =R9/Q9-1 -> 0.1828929 | S11: =S9/R9-1 -> 0.20482663 | T11: =T9/S9-1 -> 0.11952805 | U11: =U9/T9-1 -> -0.371128 | V11: =V9/U9-1 -> 0.64459168 | ... AA11: =AA9/Z9-1 -> 0.15551637 | AP11: =AP9/AL9-1 -> -0.36310179 | AQ11: =AQ9/AM9-1 -> -0.33846192 | AR11: =AR9/AN9-1 -> -0.22921877 | AS11: =AS9/AO9-1 -> -0.11862362 | AT11: =AT9/AP9-1 -> -0.056390874 | AU11: =AU9/AQ9-1 -> 0.078830435 | AV11: =AV9/AR9-1 -> 0.12875124 | AW11: =AW9/AS9-1 -> 0.089525794 | ... CL11: =CL9/CH9-1 -> 0.15551637
A12: Vahan Volume TTM Growth YoY | U12: =U10/T10-1 -> -0.081465708 | V12: =V10/U10-1 -> -0.34499641 | W12: =W10/V10-1 -> 0.45944361 | X12: =X10/W10-1 -> -0.057285062 | Y12: =Y10/X10-1 -> -0.019479243 | Z12: =Z10/Y10-1 -> -0.013422153 | AA12: =AA10/Z10-1 -> 0.10873537 | BJ12: =BJ10/BF10-1 -> 2.7270887 | BK12: =BK10/BG10-1 -> 0.87123438 | BL12: =BL10/BH10-1 -> 0.2362062 | BM12: =BM10/BI10-1 -> -0.11804803 | BN12: =BN10/BJ10-1 -> -0.081465708 | BO12: =BO10/BK10-1 -> -0.25469276 | BP12: =BP10/BL10-1 -> -0.30775122 | BQ12: =BQ10/BM10-1 -> -0.28135714 | ... CL12: =CL10/CH10-1 -> 0.10873537
A14: Unit Matrix - Realisation | N14: =+N36*10^7/N4 -> 8247823.9 | O14: =+O36*10^7/O4 -> 15970920 | P14: =+P36*10^7/P4 -> 19129792 | Q14: =+Q36*10^7/Q4 -> 20533758 | R14: =+R36*10^7/R4 -> 17145760 | S14: =+S36*10^7/S4 -> 15384275 | T14: =+T36*10^7/T4 -> 14231368 | U14: =+U36*10^7/U4 -> 19566792 | ... AE14: =+AE36*10^7/AE4 -> 2191527.4 | AI14: =+AI36*10^7/AI4 -> 6971936 | AJ14: =+AJ36*10^7/AJ4 -> 5992969.1 | AK14: =+AK36*10^7/AK4 -> 8470466.1 | AL14: =+AL36*10^7/AL4 -> 14026760 | AM14: =+AM36*10^7/AM4 -> 12759774 | AN14: =+AN36*10^7/AN4 -> 15075227 | AO14: =+AO36*10^7/AO4 -> 18306035 | AP14: =+AP36*10^7/AP4 -> 17891185 | ... CL14: =+CL36*10^7/CL4 -> 5173314.5 | CM14: =+AVERAGE(CI14:CL14)*0.91 -> 5148762.5 | CN14: =+AVERAGE(CJ14:CM14)*0.91 -> 4407876.6 | CO14: =+AVERAGE(CK14:CN14)*0.91 -> 4276485 | CP14: =+AVERAGE(CL14:CO14)*0.91 -> 4323964.8 | CQ14: =+AVERAGE(CM14:CP14)*0.85 -> 3858381.4 | CR14: =+AVERAGE(CN14:CQ14)*0.85 -> 3584175.4 | CS14: =+AVERAGE(CO14:CR14)*0.85 -> 3409138.9 | CT14: =+AVERAGE(CP14:CS14)*0.85 -> 3224827.9 | CU14: =+AVERAGE(CQ14:CT14)*0.84 -> 2956070 | CV14: =+AVERAGE(CR14:CU14)*0.84 -> 2766584.6 | CW14: =+AVERAGE(CS14:CV14)*0.84 -> 2594890.5 | CX14: =+AVERAGE(CT14:CW14)*0.84 -> 2423898.3 | CY14: =+AVERAGE(CU14:CX14)*0.89 -> 2389971.1 | CZ14: =+AVERAGE(CV14:CY14)*0.89 -> 2264014.1 | DA14: =+AVERAGE(CW14:CZ14)*0.89 -> 2152192.2 | DB14: =+AVERAGE(CX14:DA14)*0.89 -> 2053691.9
A16: Standalone Revenue - TMPV | AI16: 10586.41 | AJ16: 12481.43 | AK16: 10630.09 | AL16: 11067.79 | AM16: 9104.5 | AN16: 8868.45 | AO16: 7769.67 | AP16: 8545.49 | AQ16: 7704.76 | AR16: 8752.08 | AS16: 9060.33 | AT16: 10785.79 | AU16: 9324.2 | AV16: 10693.69 | AW16: 11055.27 | AX16: 14147.98 | AY16: 11434.91 | AZ16: 11365.86 | BA16: 11207.2 | BB16: 15080.56 | BC16: 10366.19 | BD16: 13310.37 | BE16: 15962.39 | BF16: 19173.46 | BG16: 16674.99 | BH16: 17758.69 | BI16: 16207.67 | BJ16: 18561.41 | BK16: 13351.91 | BL16: 10000.48 | BM16: 10842.91 | BN16: 9732.87 | BO16: 2686.87 | BP16: 5594.6 | BQ16: 9635.78 | BR16: 13480.42 | BS16: 6576.61 | BT16: 10996.02 | BU16: 12352.78 | BV16: 17338.27 | BW16: 14874.44 | BX16: 14946.78 | BY16: 15793.98 | BZ16: 20142.13 | CA16: 15833 | CB16: 18542 | CC16: 18669 | CD16: 20260 | CE16: 16862 | CF16: 12055 | CG16: 17040 | CH16: 19999 | CI16: 15682 | CJ16: 12955
A18: Realisation YoY% | O18: =+O14/N14-1 -> 0.93637989 | P18: =+P14/O14-1 -> 0.19778894 | Q18: =+Q14/P14-1 -> 0.073391638 | R18: =+R14/Q14-1 -> -0.16499653 | S18: =+S14/R14-1 -> -0.10273585 | T18: =+T14/S14-1 -> -0.074940625 | U18: =+U14/T14-1 -> 0.37490592 | V18: =+V14/U14-1 -> -0.4182028 | ... AE18: =+AE14/AD14-1 -> -0.17248458 | AM18: =+AM14/AI14-1 -> 0.83016221 | AN18: =+AN14/AJ14-1 -> 1.5154855 | AO18: =+AO14/AK14-1 -> 1.1611603 | AP18: =+AP14/AL14-1 -> 0.27550377 | AQ18: =+AQ14/AM14-1 -> 0.99037152 | AR18: =+AR14/AN14-1 -> 0.21011636 | AS18: =+AS14/AO14-1 -> 0.055784452 | AT18: =+AT14/AP14-1 -> -0.11007299 | ... DB18: =+DB14/CX14-1 -> -0.15273183
A20: Volume - JLR | N20: =+SUM(N21:N22) -> 746698 | O20: =+SUM(O21:O22) -> 864172 | P20: =+SUM(P21:P22) -> 928688 | Q20: =+SUM(Q21:Q22) -> 1065656 | R20: =+SUM(R21:R22) -> 1204815 | S20: =+SUM(S21:S22) -> 1247819 | T20: =+SUM(T21:T22) -> 1144221 | U20: =+SUM(U21:U22) -> 1034061 | ... Z20: =+SUM(Z21:Z22) -> 829752 | AA20: =+SUM(CI20:CL20) -> 660266 | AB20: =+SUM(CM20:CP20) -> 0 | AC20: =+SUM(CQ20:CT20) -> 0 | AD20: =+SUM(CU20:CX20) -> 0 | AE20: =+SUM(CY20:DB20) -> 0 | AI20: =+SUM(AI21:AI22) -> 169210 | AJ20: =+SUM(AJ21:AJ22) -> 162191 | AK20: =+SUM(AK21:AK22) -> 183486 | AL20: =+SUM(AL21:AL22) -> 231811 | AM20: =+SUM(AM21:AM22) -> 185339 | AN20: =+SUM(AN21:AN22) -> 204575 | AO20: =+SUM(AO21:AO22) -> 228529 | AP20: =+SUM(AP21:AP22) -> 245729 | ... CL20: =+SUM(CL21:CL22) -> 188100
A21: Volume JLR - Wholesale | N21: =+SUM(AI21:AL21) -> 372062 | O21: =+SUM(AM21:AP21) -> 429861 | P21: =+SUM(AQ21:AT21) -> 466479 | Q21: =+SUM(AU21:AX21) -> 544085 | R21: =+SUM(AY21:BB21) -> 600806 | S21: =+SUM(BC21:BF21) -> 633510 | T21: =+SUM(BG21:BJ21) -> 565306 | U21: =+SUM(BK21:BN21) -> 525402 | V21: =+SUM(BO21:BR21) -> 412911 | W21: =+SUM(BS21:BV21) -> 347650 | X21: =+SUM(BW21:BZ21) -> 359480 | Y21: =+SUM(CA21:CD21) -> 401303 | Z21: =+SUM(CE21:CH21) -> 400898 | AI21: 83452 | AJ21: 77442 | AK21: 94828 | AL21: 116340 | AM21: 90620 | AN21: 101931 | AO21: 116357 | AP21: 120953 | AQ21: 115156 | AR21: 103975 | AS21: 122187 | AT21: 125161 | AU21: 114452 | AV21: 116745 | AW21: 150461 | AX21: 162427 | AY21: 134326 | AZ21: 139235 | BA21: 152245 | BB21: 175000 | BC21: 138476 | BD21: 153210 | BE21: 159067 | BF21: 182757 | BG21: 131560 | BH21: 130652 | BI21: 141552 | BJ21: 161542 | BK21: 118550 | BL21: 134489 | BM21: 145384 | BN21: 126979 | BO21: 65425 | BP21: 91367 | BQ21: 119658 | BR21: 136461 | BS21: 97141 | BT21: 78251 | BU21: 83110 | BV21: 89148 | BW21: 82587 | BX21: 89899 | BY21: 92345 | BZ21: 94649 | CA21: 93253 | CB21: 96817 | CC21: 101043 | CD21: 110190 | CE21: 97755 | CF21: 87303 | CG21: 104427 | CH21: 111413 | CI21: 87286 | CJ21: 66165 | CK21: 59200 | CL21: 95300
A22: Volume JLR - Retail | N22: =+SUM(AI22:AL22) -> 374636 | O22: =+SUM(AM22:AP22) -> 434311 | P22: =+SUM(AQ22:AT22) -> 462209 | Q22: =+SUM(AU22:AX22) -> 521571 | R22: =+SUM(AY22:BB22) -> 604009 | S22: =+SUM(BC22:BF22) -> 614309 | T22: =+SUM(BG22:BJ22) -> 578915 | U22: =+SUM(BK22:BN22) -> 508659 | V22: =+SUM(BO22:BR22) -> 439588 | W22: =+SUM(BS22:BV22) -> 376381 | X22: =+SUM(BW22:BZ22) -> 354662 | Y22: =+SUM(CA22:CD22) -> 431733 | Z22: =+SUM(CE22:CH22) -> 428854 | AI22: 85758 | AJ22: 84749 | AK22: 88658 | AL22: 115471 | AM22: 94719 | AN22: 102644 | AO22: 112172 | AP22: 124776 | AQ22: 115596 | AR22: 110781 | AS22: 111525 | AT22: 124307 | AU22: 114905 | AV22: 110200 | AW22: 137653 | AX22: 158813 | AY22: 132753 | AZ22: 142459 | BA22: 149288 | BB22: 179509 | BC22: 137463 | BD22: 149690 | BE22: 154447 | BF22: 172709 | BG22: 145510 | BH22: 129887 | BI22: 144602 | BJ22: 158916 | BK22: 128615 | BL22: 128953 | BM22: 141222 | BN22: 109869 | BO22: 74067 | BP22: 113569 | BQ22: 128469 | BR22: 123483 | BS22: 124537 | BT22: 92710 | BU22: 80126 | BV22: 79008 | BW22: 78825 | BX22: 88121 | BY22: 84827 | BZ22: 102889 | CA22: 101994 | CB22: 106561 | CC22: 109140 | CD22: 114038 | CE22: 111180 | CF22: 103108 | CG22: 106334 | CH22: 108232 | CI22: 94420 | CJ22: 85495 | CK22: 79600 | CL22: 92800
A24: Volume JLR YoY% | N24: =+N20/M20-1 -> #DIV/0! | O24: =+O20/N20-1 -> 0.15732465 | P24: =+P20/O20-1 -> 0.074656434 | Q24: =+Q20/P20-1 -> 0.14748548 | R24: =+R20/Q20-1 -> 0.13058529 | S24: =+S20/R20-1 -> 0.035693447 | T24: =+T20/S20-1 -> -0.083023259 | U24: =+U20/T20-1 -> -0.096275108 | ... AE24: =+AE20/AD20-1 -> #DIV/0! | AM24: =+AM20/AI20-1 -> 0.095319426 | AN24: =+AN20/AJ20-1 -> 0.26132153 | AO24: =+AO20/AK20-1 -> 0.24548467 | AP24: =+AP20/AL20-1 -> 0.060040291 | AQ24: =+AQ20/AM20-1 -> 0.24502668 | AR24: =+AR20/AN20-1 -> 0.049766589 | AS24: =+AS20/AO20-1 -> 0.022679835 | AT24: =+AT20/AP20-1 -> 0.015215949 | ... CL24: =+CL20/CH20-1 -> -0.14361811
A25: Volume JLR YoY% - Wholesale | N25: =+N21/M21-1 -> #DIV/0! | O25: =+O21/N21-1 -> 0.15534776 | P25: =+P21/O21-1 -> 0.085185676 | Q25: =+Q21/P21-1 -> 0.16636547 | R25: =+R21/Q21-1 -> 0.10425026 | S25: =+S21/R21-1 -> 0.054433544 | T25: =+T21/S21-1 -> -0.10766049 | U25: =+U21/T21-1 -> -0.070588319 | ... AE25: =+AE21/AD21-1 -> #DIV/0! | AM25: =+AM21/AI21-1 -> 0.085893687 | AN25: =+AN21/AJ21-1 -> 0.31622375 | AO25: =+AO21/AK21-1 -> 0.2270321 | AP25: =+AP21/AL21-1 -> 0.039651023 | AQ25: =+AQ21/AM21-1 -> 0.27075701 | AR25: =+AR21/AN21-1 -> 0.020052781 | AS25: =+AS21/AO21-1 -> 0.05010442 | AT25: =+AT21/AP21-1 -> 0.034790373 | ... CL25: =+CL21/CH21-1 -> -0.14462406
A26: Volume JLR YoY% - Retail | N26: =+N22/M22-1 -> #DIV/0! | O26: =+O22/N22-1 -> 0.15928795 | P26: =+P22/O22-1 -> 0.064235076 | Q26: =+Q22/P22-1 -> 0.12843108 | R26: =+R22/Q22-1 -> 0.1580571 | S26: =+S22/R22-1 -> 0.017052726 | T26: =+T22/S22-1 -> -0.057615955 | U26: =+U22/T22-1 -> -0.12135806 | ... AE26: =+AE22/AD22-1 -> #DIV/0! | AM26: =+AM22/AI22-1 -> 0.10449171 | AN26: =+AN22/AJ22-1 -> 0.21115293 | AO26: =+AO22/AK22-1 -> 0.26522141 | AP26: =+AP22/AL22-1 -> 0.080583004 | AQ26: =+AQ22/AM22-1 -> 0.22040984 | AR26: =+AR22/AN22-1 -> 0.079273996 | AS26: =+AS22/AO22-1 -> -0.0057679278 | AT26: =+AT22/AP22-1 -> -0.0037587357 | ... CL26: =+CL22/CH22-1 -> -0.1425826
A28: Volume Vahan | T28: =+SUM(BG28:BJ28) -> 583718 | U28: =+SUM(BK28:BN28) -> 536165 | V28: =+SUM(BO28:BR28) -> 351190 | W28: =+SUM(BS28:BV28) -> 512542 | X28: =+SUM(BW28:BZ28) -> 483181 | Y28: =+SUM(CA28:CD28) -> 473769 | Z28: =+SUM(CE28:CH28) -> 467410 | AA28: =+SUM(CI28:CL28) -> 518234 | AB28: =+SUM(CM28:CP28) -> 0 | AC28: =+SUM(CQ28:CT28) -> 0 | AD28: =+SUM(CU28:CX28) -> 0 | AE28: =+SUM(CY28:DB28) -> 0 | BF28: =+'Ignore-TMotors Retail-vaahan'!$F$6 -> 156615 | BG28: =+'Ignore-TMotors Retail-vaahan'!$F$9 -> 148381 | BH28: =+'Ignore-TMotors Retail-vaahan'!$F$12 -> 137558 | BI28: =+'Ignore-TMotors Retail-vaahan'!$F$15 -> 146452 | BJ28: =+'Ignore-TMotors Retail-vaahan'!$F$18 -> 151327 | BK28: =+'Ignore-TMotors Retail-vaahan'!$F$21 -> 135382 | BL28: =+'Ignore-TMotors Retail-vaahan'!$F$24 -> 113927 | BM28: =+'Ignore-TMotors Retail-vaahan'!$F$27 -> 118839 | BN28: =+'Ignore-TMotors Retail-vaahan'!$F$30 -> 168017 | BO28: =+'Ignore-TMotors Retail-vaahan'!$F$33 -> 24578 | BP28: =+'Ignore-TMotors Retail-vaahan'!$F$36 -> 67287 | BQ28: =+'Ignore-TMotors Retail-vaahan'!$F$39 -> 113435 | BR28: =+'Ignore-TMotors Retail-vaahan'!$F$42 -> 145890 | BS28: =+'Ignore-TMotors Retail-vaahan'!$F$45 -> 92557 | BT28: =+'Ignore-TMotors Retail-vaahan'!$F$48 -> 138997 | BU28: =+'Ignore-TMotors Retail-vaahan'!$F$51 -> 162102 | BV28: =+'Ignore-TMotors Retail-vaahan'!$F$54 -> 118886 | BW28: =+'Ignore-TMotors Retail-vaahan'!$F$57 -> 111072 | BX28: =+'Ignore-TMotors Retail-vaahan'!$F$60 -> 114327 | BY28: =+'Ignore-TMotors Retail-vaahan'!$F$63 -> 127271 | BZ28: =+'Ignore-TMotors Retail-vaahan'!$F$66 -> 130511 | CA28: =+'Ignore-TMotors Retail-vaahan'!$F$69 -> 113368 | CB28: =+'Ignore-TMotors Retail-vaahan'!$F$72 -> 102616 | CC28: =+'Ignore-TMotors Retail-vaahan'!$F$75 -> 131772 | CD28: =+'Ignore-TMotors Retail-vaahan'!$F$78 -> 126013 | CE28: =+'Ignore-TMotors Retail-vaahan'!$F$81 -> 108847 | CF28: =+'Ignore-TMotors Retail-vaahan'!$F$84 -> 100357 | CG28: =+'Ignore-TMotors Retail-vaahan'!$F$87 -> 130855 | CH28: =+'Ignore-TMotors Retail-vaahan'!$F$90 -> 127351 | CI28: =+'Ignore-TMotors Retail-vaahan'!$F$93 -> 100409 | CJ28: =+'Ignore-TMotors Retail-vaahan'!$F$96 -> 98985 | CK28: =+'Ignore-TMotors Retail-vaahan'!$F$99 -> 159488 | CL28: ='Ignore-TMotors Retail-vaahan'!F102 -> 159352
A29: Volume Vahan YoY% | U29: =+U28/T28-1 -> -0.081465708 | V29: =+V28/U28-1 -> -0.34499641 | W29: =+W28/V28-1 -> 0.45944361 | X29: =+X28/W28-1 -> -0.057285062 | Y29: =+Y28/X28-1 -> -0.019479243 | Z29: =+Z28/Y28-1 -> -0.013422153 | AA29: =+AA28/Z28-1 -> 0.10873537 | AB29: =+AB28/AA28-1 -> -1 | ... AE29: =+AE28/AD28-1 -> #DIV/0! | BJ29: =+BJ28/BF28-1 -> -0.033764327 | BK29: =+BK28/BG28-1 -> -0.087605556 | BL29: =+BL28/BH28-1 -> -0.17178935 | BM29: =+BM28/BI28-1 -> -0.18854642 | BN29: =+BN28/BJ28-1 -> 0.11029096 | BO29: =+BO28/BK28-1 -> -0.81845445 | BP29: =+BP28/BL28-1 -> -0.40938496 | BQ29: =+BQ28/BM28-1 -> -0.045473287 | ... CL29: =+CL28/CH28-1 -> 0.25128189
A32: Presentation Data (End)
A33: Profit & Loss- Annual (Start)
A34: Gross Revenue | B34: ='Annual Raw'!C6 -> 8077.81 | C34: ='Annual Raw'!D6 -> 9302.29 | D34: ='Annual Raw'!E6 -> 11425.36 | E34: ='Annual Raw'!F6 -> 16284.84 | F34: ='Annual Raw'!G6 -> 22708.23 | G34: ='Annual Raw'!H6 -> 27263.73 | H34: ='Annual Raw'!I6 -> 36922.61 | I34: ='Annual Raw'!J6 -> 40340.79 | ... AA34: ='Annual Raw'!AB6 -> 335582 | AB34: =+SUM(CM34:CP34) -> 407877.65 | AC34: =+SUM(CQ34:CT34) -> 449405.86 | AD34: =+SUM(CU34:CX34) -> 486985.76 | AE34: =+SUM(CY34:DB34) -> 573136.69 | AI34: ='QTR Raw'!C6+'QTR Raw'!C8 -> 44329.33 | AJ34: ='QTR Raw'!D6+'QTR Raw'!D8 -> 44689.05 | AK34: ='QTR Raw'!E6+'QTR Raw'!E8 -> 47322.45 | AL34: ='QTR Raw'!F6+'QTR Raw'!F8 -> 57273.79 | AM34: ='QTR Raw'!G6+'QTR Raw'!G8 -> 47862.53 | AN34: ='QTR Raw'!H6+'QTR Raw'!H8 -> 57827.96 | AO34: ='QTR Raw'!I6+'QTR Raw'!I8 -> 64718.41 | AP34: ='QTR Raw'!J6+'QTR Raw'!J8 -> 66217.53 | ... CL34: ='QTR Raw'!BF6+'QTR Raw'!BF8 -> 105447 | CM34: =+CM14*CM4/10^7 -> 88790.456 | CN34: =+CN14*CN4/10^7 -> 90521.856 | CO34: =+CO14*CO4/10^7 -> 104731.76 | CP34: =+CP14*CP4/10^7 -> 123833.59 | CQ34: =+CQ14*CQ4/10^7 -> 94631.219 | CR34: =+CR14*CR4/10^7 -> 104683.71 | CS34: =+CS14*CS4/10^7 -> 118741.35 | CT34: =+CT14*CT4/10^7 -> 131349.58 | ... DB34: =+DB14*DB4/10^7 -> 169195.62 | DF34: 102938.9
A35: Less: Exise Duty | B35: ='Annual Raw'!C7+'Annual Raw'!C8+'Annual Raw'!C9 -> 1292.24 | C35: ='Annual Raw'!D7+'Annual Raw'!D8+'Annual Raw'!D9 -> 1390.47 | D35: ='Annual Raw'!E7+'Annual Raw'!E8+'Annual Raw'!E9 -> 1816.72 | E35: ='Annual Raw'!F7+'Annual Raw'!F8+'Annual Raw'!F9 -> 2360.12 | F35: ='Annual Raw'!G7+'Annual Raw'!G8+'Annual Raw'!G9 -> 3175.39 | G35: ='Annual Raw'!H7+'Annual Raw'!H8+'Annual Raw'!H9 -> 3494.28 | H35: ='Annual Raw'!I7+'Annual Raw'!I8+'Annual Raw'!I9 -> 4561.41 | I35: ='Annual Raw'!J7+'Annual Raw'!J8+'Annual Raw'!J9 -> 4680.72 | ... AA35: ='Annual Raw'!AB7+'Annual Raw'!AB8+'Annual Raw'!AB9 -> 0 | AB35: =+SUM(CM35:CP35) -> 0 | AC35: =+SUM(CQ35:CT35) -> 0 | AD35: =+SUM(CU35:CX35) -> 0 | AE35: =+SUM(CY35:DB35) -> 0 | AI35: =+'QTR Raw'!C20+'QTR Raw'!C19+'QTR Raw'!C13+'QTR Raw'!C7 -> 1005.72 | AJ35: =+'QTR Raw'!D20+'QTR Raw'!D19+'QTR Raw'!D13+'QTR Raw'!D7 -> 1286.17 | AK35: =+'QTR Raw'!E20+'QTR Raw'!E19+'QTR Raw'!E13+'QTR Raw'!E7 -> 1232.95 | AL35: =+'QTR Raw'!F20+'QTR Raw'!F19+'QTR Raw'!F13+'QTR Raw'!F7 -> 1271.95 | AM35: =+'QTR Raw'!G20+'QTR Raw'!G19+'QTR Raw'!G13+'QTR Raw'!G7 -> 1066.06 | AN35: =+'QTR Raw'!H20+'QTR Raw'!H19+'QTR Raw'!H13+'QTR Raw'!H7 -> 961.19 | AO35: =+'QTR Raw'!I20+'QTR Raw'!I19+'QTR Raw'!I13+'QTR Raw'!I7 -> 865.13 | AP35: =+'QTR Raw'!J20+'QTR Raw'!J19+'QTR Raw'!J13+'QTR Raw'!J7 -> 900.39 | ... CL35: =+'QTR Raw'!BF20+'QTR Raw'!BF19+'QTR Raw'!BF13+'QTR Raw'!BF7 -> 1273 | DF35: 1696
A36: Net Revenue | B36: =+B34-B35 -> 6785.57 | C36: =+C34-C35 -> 7911.82 | D36: =+D34-D35 -> 9608.64 | E36: =+E34-E35 -> 13924.72 | F36: =+F34-F35 -> 19532.84 | G36: =+G34-G35 -> 23769.45 | H36: =+H34-H35 -> 32361.2 | I36: =+I34-I35 -> 35660.07 | ... AE36: =+AE34-AE35 -> 573136.69 | AI36: =+AI34-AI35 -> 43323.61 | AJ36: =+AJ34-AJ35 -> 43402.88 | AK36: =+AK34-AK35 -> 46089.5 | AL36: =+AL34-AL35 -> 56001.84 | AM36: =+AM34-AM35 -> 46796.47 | AN36: =+AN34-AN35 -> 56866.77 | AO36: =+AO34-AO35 -> 63853.28 | AP36: =+AP34-AP35 -> 65317.14 | ... DB36: =+DB34-DB35 -> 169195.62 | DF36: 102938.9
A37: Net Revenue YOY% | C37: =C36/B36-1 -> 0.16597721 | D37: =D36/C36-1 -> 0.21446646 | E37: =E36/D36-1 -> 0.4491874 | F37: =F36/E36-1 -> 0.40274562 | G37: =G36/F36-1 -> 0.21689677 | H37: =H36/G36-1 -> 0.36146188 | I37: =I36/H36-1 -> 0.10193905 | J37: =J36/I36-1 -> 0.98768398 | ... AE37: =AE36/AD36-1 -> 0.17690645 | AM37: =+IF(AI36<0,1-AM36/AI36,AM36/AI36-1) -> 0.08016091 | AN37: =+IF(AJ36<0,1-AN36/AJ36,AN36/AJ36-1) -> 0.31020729 | AO37: =+IF(AK36<0,1-AO36/AK36,AO36/AK36-1) -> 0.38541924 | AP37: =+IF(AL36<0,1-AP36/AL36,AP36/AL36-1) -> 0.16633918 | AQ37: =+IF(AM36<0,1-AQ36/AM36,AQ36/AM36-1) -> 0.38221601 | AR37: =+IF(AN36<0,1-AR36/AN36,AR36/AN36-1) -> 0.065019167 | AS37: =+IF(AO36<0,1-AS36/AO36,AS36/AO36-1) -> 0.099582512 | AT37: =+IF(AP36<0,1-AT36/AP36,AT36/AP36-1) -> 0.037671276 | ... DB37: =+IF(CX36<0,1-DB36/CX36,DB36/CX36-1) -> 0.20499913 | DF37: -0.13986063
A38: Net Revenue QOQ% | AJ38: =+IF(AI36<0,1-AJ36/AI36,AJ36/AI36-1) -> 0.0018297183 | AK38: =+IF(AJ36<0,1-AK36/AJ36,AK36/AJ36-1) -> 0.061899579 | AL38: =+IF(AK36<0,1-AL36/AK36,AL36/AK36-1) -> 0.21506721 | AM38: =+IF(AL36<0,1-AM36/AL36,AM36/AL36-1) -> -0.16437621 | AN38: =+IF(AM36<0,1-AN36/AM36,AN36/AM36-1) -> 0.21519358 | AO38: =+IF(AN36<0,1-AO36/AN36,AO36/AN36-1) -> 0.12285751 | AP38: =+IF(AO36<0,1-AP36/AO36,AP36/AO36-1) -> 0.022925369 | AQ38: =+IF(AP36<0,1-AQ36/AP36,AQ36/AP36-1) -> -0.0097112335 | ... CL38: =+IF(CK36<0,1-CL36/CK36,CL36/CK36-1) -> 0.48722268 | CM38: =+CM36/CL36-1 -> -0.14767162 | CN38: =+CN36/CM36-1 -> 0.019499839 | CO38: =+CO36/CN36-1 -> 0.15697756 | CP38: =+CP36/CO36-1 -> 0.18238815 | CQ38: =+CQ36/CP36-1 -> -0.23581945 | CR38: =+CR36/CQ36-1 -> 0.10622811 | CS38: =+CS36/CR36-1 -> 0.13428673 | CT38: =+CT36/CS36-1 -> 0.10618233 | ... DB38: =+DB36/DA36-1 -> 0.11588413 | DF38: 0.46958997
A39: Increase/Decrease in Stock | B39: ='Annual Raw'!C11 -> -56.67 | C39: ='Annual Raw'!D11 -> 97.92 | D39: ='Annual Raw'!E11 -> -103.48 | E39: ='Annual Raw'!F11 -> 75.33 | F39: ='Annual Raw'!G11 -> -231.75 | G39: ='Annual Raw'!H11 -> -207.62 | H39: ='Annual Raw'!I11 -> -333.76 | I39: ='Annual Raw'!J11 -> -13.49 | ... AA39: ='Annual Raw'!AB11 -> 1661 | AB39: =+SUM(CM39:CP39) -> 0 | AC39: =+SUM(CQ39:CT39) -> 0 | AD39: =+SUM(CU39:CX39) -> 0 | AE39: =+SUM(CY39:DB39) -> 0 | AI39: ='QTR Raw'!C10 -> -1962.03 | AJ39: ='QTR Raw'!D10 -> -1005.76 | AK39: ='QTR Raw'!E10 -> -1434.99 | AL39: ='QTR Raw'!F10 -> 1373 | AM39: ='QTR Raw'!G10 -> -2942.98 | AN39: ='QTR Raw'!H10 -> 253.76 | AO39: ='QTR Raw'!I10 -> 588.93 | AP39: ='QTR Raw'!J10 -> -740.29 | ... CL39: ='QTR Raw'!BF10 -> 6124 | DF39: 419
A40: Purchase of Finished Goods | B40: 0 | C40: 0 | D40: 0 | E40: 0 | F40: 0 | G40: 0 | H40: 0 | I40: 0 | J40: 0 | K40: 0 | L40: 0 | M40: 0 | N40: 0 | O40: 0 | P40: 0 | Q40: 0 | R40: 0 | S40: 0 | T40: 0 | U40: 0 | V40: 0 | W40: 0 | X40: 0 | Y40: 0 | Z40: 0 | AA40: 0 | AB40: =+SUM(CM40:CP40) -> 0 | AC40: =+SUM(CQ40:CT40) -> 0 | AD40: =+SUM(CU40:CX40) -> 0 | AE40: =+SUM(CY40:DB40) -> 0 | AI40: ='QTR Raw'!C12 -> 2913.9 | AJ40: ='QTR Raw'!D12 -> 3043.78 | AK40: ='QTR Raw'!E12 -> 2062.67 | AL40: ='QTR Raw'!F12 -> 2482.61 | AM40: ='QTR Raw'!G12 -> 2345.95 | AN40: ='QTR Raw'!H12 -> 3435.19 | AO40: ='QTR Raw'!I12 -> 1967.72 | AP40: ='QTR Raw'!J12 -> 3128.09 | ... CL40: ='QTR Raw'!BF12 -> 4989 | DF40: 18637
A41: Raw Material Consumed | B41: ='Annual Raw'!C12 -> 4728.07 | C41: ='Annual Raw'!D12 -> 4915.76 | D41: ='Annual Raw'!E12 -> 6018.45 | E41: ='Annual Raw'!F12 -> 8882.95 | F41: ='Annual Raw'!G12 -> 13504.17 | G41: ='Annual Raw'!H12 -> 16258.62 | H41: ='Annual Raw'!I12 -> 22372.59 | I41: ='Annual Raw'!J12 -> 24375.84 | ... AA41: ='Annual Raw'!AB12 -> 212421 | AB41: =+SUM(CM41:CP41) -> 261317.42 | AC41: =+SUM(CQ41:CT41) -> 287784.91 | AD41: =+SUM(CU41:CX41) -> 311820.34 | AE41: =+SUM(CY41:DB41) -> 366978.49 | AI41: ='QTR Raw'!C11 -> 26797.51 | AJ41: ='QTR Raw'!D11 -> 25683.23 | AK41: ='QTR Raw'!E11 -> 29043.7 | AL41: ='QTR Raw'!F11 -> 31274.13 | AM41: ='QTR Raw'!G11 -> 29440.78 | AN41: ='QTR Raw'!H11 -> 30873.07 | AO41: ='QTR Raw'!I11 -> 37340.23 | AP41: ='QTR Raw'!J11 -> 37895.96 | ... CL41: ='QTR Raw'!BF11 -> 55465 | CM41: =+CM36-CM42 -> 57011.81 | CN41: =+CN36-CN42 -> 58224.95 | CO41: =+CO36-CO42 -> 66767.639 | CP41: =+CP36-CP42 -> 79313.026 | CQ41: =+CQ36-CQ42 -> 60642.046 | CR41: =+CR36-CR42 -> 67050.727 | CS41: =+CS36-CS42 -> 75974.405 | CT41: =+CT36-CT42 -> 84117.731 | ... DB41: =+DB36-DB42 -> 108336.79 | DF41: 65687.1
A42: Gross Profit | B42: =B36-B39-B41-B40 -> 2114.17 | C42: =C36-C39-C41-C40 -> 2898.14 | D42: =D36-D39-D41-D40 -> 3693.67 | E42: =E36-E39-E41-E40 -> 4966.44 | F42: =F36-F39-F41-F40 -> 6260.42 | G42: =G36-G39-G41-G40 -> 7718.45 | H42: =H36-H39-H41-H40 -> 10322.37 | I42: =I36-I39-I41-I40 -> 11297.72 | ... AE42: =AE36-AE39-AE41-AE40 -> 206158.2 | AI42: =AI36-AI39-AI41-AI40 -> 15574.23 | AJ42: =AJ36-AJ39-AJ41-AJ40 -> 15681.63 | AK42: =AK36-AK39-AK41-AK40 -> 16418.12 | AL42: =AL36-AL39-AL41-AL40 -> 20872.1 | AM42: =AM36-AM39-AM41-AM40 -> 17952.72 | AN42: =AN36-AN39-AN41-AN40 -> 22304.75 | AO42: =AO36-AO39-AO41-AO40 -> 23956.4 | AP42: =AP36-AP39-AP41-AP40 -> 25033.38 | ... CL42: =CL36-CL39-CL41-CL40 -> 37596 | CM42: =+CM43*CM36 -> 31778.647 | CN42: =+CN43*CN36 -> 32296.906 | CO42: =+CO43*CO36 -> 37964.117 | CP42: =+CP43*CP36 -> 44520.561 | CQ42: =+CQ43*CQ36 -> 33989.172 | CR42: =+CR43*CR36 -> 37632.987 | CS42: =+CS43*CS36 -> 42766.943 | CT42: =+CT43*CT36 -> 47231.848 | ... DB42: =+DB43*DB36 -> 60858.837 | DF42: 37251.8
A43: GP% | B43: =B42/B36 -> 0.31156852 | C43: =C42/C36 -> 0.3663051 | D43: =D42/D36 -> 0.38441132 | E43: =E42/E36 -> 0.35666355 | F43: =F42/F36 -> 0.32050741 | G43: =G42/G36 -> 0.32472144 | H43: =H42/H36 -> 0.31897365 | I43: =I42/I36 -> 0.3168171 | ... AE43: =AE42/AE36 -> 0.35970163 | AI43: =AI42/AI36 -> 0.35948597 | AJ43: =AJ42/AJ36 -> 0.3613039 | AK43: =AK42/AK36 -> 0.35622257 | AL43: =AL42/AL36 -> 0.37270383 | AM43: =AM42/AM36 -> 0.38363406 | AN43: =AN42/AN36 -> 0.39222819 | AO43: =AO42/AO36 -> 0.37517885 | AP43: =AP42/AP36 -> 0.38325897 | ... CL43: =CL42/CL36 -> 0.36089619 | CM43: =AVERAGE(CI43:CL43) -> 0.35790611 | CN43: =AVERAGE(CJ43:CM43) -> 0.35678573 | CO43: =AVERAGE(CK43:CN43) -> 0.36248907 | CP43: =AVERAGE(CL43:CO43) -> 0.35951928 | CQ43: =AVERAGE(CM43:CP43) -> 0.35917505 | CR43: =AVERAGE(CN43:CQ43) -> 0.35949228 | CS43: =AVERAGE(CO43:CR43) -> 0.36016892 | CT43: =AVERAGE(CP43:CS43) -> 0.35958888 | ... DB43: =AVERAGE(CX43:DA43) -> 0.3596951 | DF43: 0.36188263
A44: GP YOY% | C44: =+IF(B42<0,1-C42/B42,C42/B42-1) -> 0.37081692 | D44: =+IF(C42<0,1-D42/C42,D42/C42-1) -> 0.27449675 | E44: =+IF(D42<0,1-E42/D42,E42/D42-1) -> 0.34458141 | F44: =+IF(E42<0,1-F42/E42,F42/E42-1) -> 0.26054478 | G44: =+IF(F42<0,1-G42/F42,G42/F42-1) -> 0.23289651 | H44: =+IF(G42<0,1-H42/G42,H42/G42-1) -> 0.33736307 | I44: =+IF(H42<0,1-I42/H42,I42/H42-1) -> 0.094488959 | J44: =+IF(I42<0,1-J42/I42,J42/I42-1) -> 1.0282845 | ... AE44: =+IF(AD42<0,1-AE42/AD42,AE42/AD42-1) -> 0.17693435 | AM44: =+IF(AI42<0,1-AM42/AI42,AM42/AI42-1) -> 0.15271959 | AN44: =+IF(AJ42<0,1-AN42/AJ42,AN42/AJ42-1) -> 0.42234895 | AO44: =+IF(AK42<0,1-AO42/AK42,AO42/AK42-1) -> 0.45914392 | AP44: =+IF(AL42<0,1-AP42/AL42,AP42/AL42-1) -> 0.19937045 | AQ44: =+IF(AM42<0,1-AQ42/AM42,AQ42/AM42-1) -> 0.38957495 | AR44: =+IF(AN42<0,1-AR42/AN42,AR42/AN42-1) -> 0.057913225 | AS44: =+IF(AO42<0,1-AS42/AO42,AS42/AO42-1) -> 0.1485148 | AT44: =+IF(AP42<0,1-AT42/AP42,AT42/AP42-1) -> 0.088916878 | ... CL44: =+IF(CH42<0,1-CL42/CH42,CL42/CH42-1) -> -0.03307443 | CM44: =+CM42/CI42-1 -> -0.16409378 | CN44: =+CN42/CJ42-1 -> 0.34335355 | CO44: =+CO42/CK42-1 -> 0.44774119 | CP44: =+CP42/CL42-1 -> 0.18418346 | CQ44: =+CQ42/CM42-1 -> 0.069560094 | CR44: =+CR42/CN42-1 -> 0.16521957 | CS44: =+CS42/CO42-1 -> 0.1265096 | CT44: =+CT42/CP42-1 -> 0.060899654 | ... DB44: =+DB42/CX42-1 -> 0.20508424 | DF44: -0.18055874
A45: GP QOQ% | AJ45: =+IF(AI42<0,1-AJ42/AI42,AJ42/AI42-1) -> 0.0068960071 | AK45: =+IF(AJ42<0,1-AK42/AJ42,AK42/AJ42-1) -> 0.046965143 | AL45: =+IF(AK42<0,1-AL42/AK42,AL42/AK42-1) -> 0.27128441 | AM45: =+IF(AL42<0,1-AM42/AL42,AM42/AL42-1) -> -0.13986997 | AN45: =+IF(AM42<0,1-AN42/AM42,AN42/AM42-1) -> 0.24241619 | AO45: =+IF(AN42<0,1-AO42/AN42,AO42/AN42-1) -> 0.07404925 | AP45: =+IF(AO42<0,1-AP42/AO42,AP42/AO42-1) -> 0.044955836 | AQ45: =+IF(AP42<0,1-AQ42/AP42,AQ42/AP42-1) -> -0.0034645741 | ... CL45: =+IF(CK42<0,1-CL42/CK42,CL42/CK42-1) -> 0.43370324 | CM45: =+CM42/CL42-1 -> -0.15473331 | CN45: =+CN42/CM42-1 -> 0.016308416 | CO45: =+CO42/CN42-1 -> 0.17547227 | CP45: =+CP42/CO42-1 -> 0.17270108 | CQ45: =+CQ42/CP42-1 -> -0.23655113 | CR45: =+CR42/CQ42-1 -> 0.10720516 | CS45: =+CS42/CR42-1 -> 0.13642169 | CT45: =+CT42/CS42-1 -> 0.10440086 | ... DB45: =+DB42/DA42-1 -> 0.11583794 | DF45: 0.42057734
A46: Employee Cost | B46: ='Annual Raw'!C14 -> 624.26 | C46: ='Annual Raw'!D14 -> 899.67 | D46: ='Annual Raw'!E14 -> 916.67 | E46: ='Annual Raw'!F14 -> 1084.33 | F46: ='Annual Raw'!G14 -> 1424.35 | G46: ='Annual Raw'!H14 -> 1777.43 | H46: ='Annual Raw'!I14 -> 2408.9 | I46: ='Annual Raw'!J14 -> 2735 | ... AA46: ='Annual Raw'!AB14 -> 45150 | AB46: =+SUM(CM46:CP46) -> 49863.07 | AC46: =+SUM(CQ46:CT46) -> 53353.485 | AD46: =+SUM(CU46:CX46) -> 57088.229 | AE46: =+SUM(CY46:DB46) -> 61084.405 | AI46: ='QTR Raw'!C16 -> 3789.69 | AJ46: ='QTR Raw'!D16 -> 4019.06 | AK46: ='QTR Raw'!E16 -> 4352.91 | AL46: ='QTR Raw'!F16 -> 4434.57 | AM46: ='QTR Raw'!G16 -> 4472.8 | AN46: ='QTR Raw'!H16 -> 5191.05 | AO46: ='QTR Raw'!I16 -> 5865.26 | AP46: ='QTR Raw'!J16 -> 6027.31 | ... CL46: ='QTR Raw'!BF16 -> 11898 | CM46: =CI46*107% -> 13365.37 | CN46: =CJ46*107% -> 11589.17 | CO46: =CK46*107% -> 12177.67 | CP46: =CL46*107% -> 12730.86 | CQ46: =CM46*107% -> 14300.946 | CR46: =CN46*107% -> 12400.412 | CS46: =CO46*107% -> 13030.107 | CT46: =CP46*107% -> 13622.02 | ... DB46: =CX46*107% -> 15595.851 | DF46: 13549.41
A47: General and Administration Expenses | B47: ='Annual Raw'!C17 -> 187.18 | C47: ='Annual Raw'!D17 -> 224.17 | D47: ='Annual Raw'!E17 -> 313.65 | E47: ='Annual Raw'!F17 -> 545.07 | F47: ='Annual Raw'!G17 -> 642.07 | G47: ='Annual Raw'!H17 -> 815.35 | H47: ='Annual Raw'!I17 -> 1015.66 | I47: ='Annual Raw'!J17 -> 772.69 | ... AA47: ='Annual Raw'!AB17 -> -4163 | AB47: =+SUM(CM47:CP47) -> 0 | AC47: =+SUM(CQ47:CT47) -> 0 | AD47: =+SUM(CU47:CX47) -> 0 | AE47: =+SUM(CY47:DB47) -> 0 | AI47: ='QTR Raw'!C17 -> 0 | AJ47: ='QTR Raw'!D17 -> 0 | AK47: ='QTR Raw'!E17 -> 0 | AL47: ='QTR Raw'!F17 -> 0 | AM47: ='QTR Raw'!G17 -> 0 | AN47: ='QTR Raw'!H17 -> 0 | AO47: ='QTR Raw'!I17 -> 0 | AP47: ='QTR Raw'!J17 -> 0 | ... CL47: ='QTR Raw'!BF17 -> 0 | DF47: 0
A48: Miscellaneous Expenses | B48: ='Annual Raw'!C19-'Annual Raw'!C20 -> 248.73 | C48: ='Annual Raw'!D19-'Annual Raw'!D20 -> 210.92 | D48: ='Annual Raw'!E19-'Annual Raw'!E20 -> 136.14 | E48: ='Annual Raw'!F19-'Annual Raw'!F20 -> 69.84 | F48: ='Annual Raw'!G19-'Annual Raw'!G20 -> 62.37 | G48: ='Annual Raw'!H19-'Annual Raw'!H20 -> 87.95 | H48: ='Annual Raw'!I19-'Annual Raw'!I20 -> 188.54 | I48: ='Annual Raw'!J19-'Annual Raw'!J20 -> 453.14 | ... AA48: ='Annual Raw'!AB19-'Annual Raw'!AB20 -> 1328 | AB48: =+SUM(CM48:CP48) -> 0 | AC48: =+SUM(CQ48:CT48) -> 0 | AD48: =+SUM(CU48:CX48) -> 0 | AE48: =+SUM(CY48:DB48) -> 0 | AI48: =+'QTR Raw'!C21 -> -2609.48 | AJ48: =+'QTR Raw'!D21 -> -2758.89 | AK48: =+'QTR Raw'!E21 -> -2532.49 | AL48: =+'QTR Raw'!F21 -> -2290.33 | AM48: =+'QTR Raw'!G21 -> -2811.29 | AN48: =+'QTR Raw'!H21 -> -3465.97 | AO48: =+'QTR Raw'!I21 -> -3598.72 | AP48: =+'QTR Raw'!J21 -> -3661.87 | ... CL48: =+'QTR Raw'!BF21 -> -8815 | DF48: -31983
A49: Other Manufacturing Expenses | B49: ='Annual Raw'!C15+'Annual Raw'!C16 -> 458.8 | C49: ='Annual Raw'!D15+'Annual Raw'!D16 -> 421.19 | D49: ='Annual Raw'!E15+'Annual Raw'!E16 -> 515.14 | E49: ='Annual Raw'!F15+'Annual Raw'!F16 -> 739.24 | F49: ='Annual Raw'!G15+'Annual Raw'!G16 -> 1071.26 | G49: ='Annual Raw'!H15+'Annual Raw'!H16 -> 1330.29 | H49: ='Annual Raw'!I15+'Annual Raw'!I16 -> 1762.78 | I49: ='Annual Raw'!J15+'Annual Raw'!J16 -> 1751.83 | ... AA49: ='Annual Raw'!AB15+'Annual Raw'!AB16 -> 29363 | AB49: =+SUM(CM49:CP49) -> 57951.14 | AC49: =+SUM(CQ49:CT49) -> 62423.392 | AD49: =+SUM(CU49:CX49) -> 63276.115 | AE49: =+SUM(CY49:DB49) -> 44909.033 | AI49: ='QTR Raw'!C14 -> 8639.14 | AJ49: ='QTR Raw'!D14 -> 9087.84 | AK49: ='QTR Raw'!E14 -> 8940.41 | AL49: ='QTR Raw'!F14 -> 10914.4 | AM49: ='QTR Raw'!G14 -> 10057.69 | AN49: ='QTR Raw'!H14 -> 11933.39 | AO49: ='QTR Raw'!I14 -> 11731.74 | AP49: ='QTR Raw'!J14 -> 12668.16 | ... CL49: ='QTR Raw'!BF14 -> 23254 | CM49: =CM52-CM46-CM47-CM48-CM50-CM51 -> 8531.1067 | CN49: =CN52-CN46-CN47-CN48-CN50-CN51 -> 14526.041 | CO49: =CO52-CO46-CO47-CO48-CO50-CO51 -> 16420.759 | CP49: =CP52-CP46-CP47-CP48-CP50-CP51 -> 18473.233 | CQ49: =CQ52-CQ46-CQ47-CQ48-CQ50-CQ51 -> 10278.313 | CR49: =CR52-CR46-CR47-CR48-CR50-CR51 -> 15126.578 | CS49: =CS52-CS46-CS47-CS48-CS50-CS51 -> 17450.325 | CT49: =CT52-CT46-CT47-CT48-CT50-CT51 -> 19568.176 | ... DB49: =DB52-DB46-DB47-DB48-DB50-DB51 -> 12928.864 | DF49: 12212.936
A50: Power & Fuel Cost | B50: ='Annual Raw'!C13 -> 185.18 | C50: ='Annual Raw'!D13 -> 200.7 | D50: ='Annual Raw'!E13 -> 210.52 | E50: ='Annual Raw'!F13 -> 235.34 | F50: ='Annual Raw'!G13 -> 267.69 | G50: ='Annual Raw'!H13 -> 291.45 | H50: ='Annual Raw'!I13 -> 368.53 | I50: ='Annual Raw'!J13 -> 377.72 | ... AA50: ='Annual Raw'!AB13 -> 1836 | AB50: =+SUM(CM50:CP50) -> 0 | AC50: =+SUM(CQ50:CT50) -> 0 | AD50: =+SUM(CU50:CX50) -> 0 | AE50: =+SUM(CY50:DB50) -> 0 | AI50: ='QTR Raw'!C15 -> 0 | AJ50: ='QTR Raw'!D15 -> 0 | AK50: ='QTR Raw'!E15 -> 0 | AL50: ='QTR Raw'!F15 -> 0 | AM50: ='QTR Raw'!G15 -> 0 | AN50: ='QTR Raw'!H15 -> 0 | AO50: ='QTR Raw'!I15 -> 0 | AP50: ='QTR Raw'!J15 -> 0 | ... CL50: ='QTR Raw'!BF15 -> 0 | DF50: 0
...

Sheet Monthly Nos Company
B2: Date | C2: PV Total | D2: Domestic | E2: PV Export | I2: 3 months rolling | J2: Total | K2: Domestic | L2: Export | M2: 3M Total YoY% | O2: 12 months rolling | P2: PV | Q2: Domestic | R2: Export | S2: 12M Total YoY%
B3: 41029 | C3: =+D3+E3 -> 23226 | D3: 22658 | E3: 568 | U3: 2781 | V3: 4219 | W3: 6071 | X3: 4864 | Y3: 4373 | Z3: 5441 | AA3: 3626 | AB3: 3671 | AC3: 3882 | AD3: 3880 | AE3: 3996 | AF3: 3552 | AG3: 3565 | AH3: 3874 | AI3: 3996 | AJ3: 4277 | AK3: 4894 | AL3: 5441 | AM3: 4712 | AN3: 3671 | AO3: 2826 | AP3: 3824 | AQ3: 4636 | AR3: 3552 | AS3: 3222 | AT3: 3191 | AU3: 3814 | AV3: 4363 | AW3: 4480 | AX3: 5246 | AY3: 4059 | AZ3: 4293 | BA3: 3958 | BB3: 3961 | BC3: 3895 | BD3: 5435 | BE3: 3786 | BF3: 4678 | BG3: 5047 | BH3: 5078 | BI3: 5212 | BJ3: 4402 | BK3: 4569 | BL3: 3573 | BM3: 4557 | BN3: 5636 | BO3: 5142 | BP3: 6356 | BQ3: 3785 | BR3: 4428 | BS3: 5603 | BT3: 5371 | BU3: 6595 | BV3: 5687 | BW3: 6333 | BX3: 5626 | BY3: 5119 | BZ3: 4921 | CA3: 4895 | CB3: 5836 | CC3: 2128 | CD3: 3900 | CE3: 3504 | CF3: 3441 | CG3: 3082 | CH3: 3887 | CI3: 4311 | CJ3: 4927 | CK3: 6293 | CL3: 5183 | CM3: 4768 | CN3: 6713 | CO3: 3010 | CP3: 3699 | CQ3: 5246 | CR3: 4971 | CS3: 5478 | CT3: 5393 | CU3: 4554 | CV3: 4604 | CW3: 3999 | CX3: 3270 | CY3: 2930 | CZ3: 5952 | DA3: 1402 | DB3: 1563 | DC3: 2701 | DD3: 3374 | DE3: 3203 | DF3: 4000 | DG3: 2202 | DH3: 3067 | DI3: 2649 | DJ3: 2620 | DK3: 2632 | DL3: 1912 | DO3: 856 | DP3: 687 | DQ3: 1085 | DR3: 1685 | DS3: 2463 | DT3: 1791 | DU3: 3003 | DV3: 2217 | DW3: 2892 | DX3: 3787 | DY3: 2328 | DZ3: 2109 | EA3: 2651 | EB3: 2138 | EC3: 3805 | ED3: 3168 | EE3: 2678 | EF3: 4119 | EG3: 3305 | EH3: 3725 | EI3: 3858 | EJ3: 2798 | EK3: 1001 | EL3: 1455 | EM3: 2964 | EN3: 2812 | EO3: 2364 | EP3: 2121 | EQ3: 1798 | ER3: 2011 | ES3: 1359 | ET3: 1388 | EU3: 1699 | EV3: 1697 | EW3: 1085 | EX3: 1525 | EY3: 1290 | EZ3: 1789 | FA3: 1749 | FB3: 2358 | FC3: 2129 | FD3: 1525 | FE3: 1717 | FF3: 1849 | FG3: 1572 | FH3: 1737
B4: =+EOMONTH(B3,1) -> 41060 | C4: =+D4+E4 -> 20970 | D4: 20503 | E4: 467 | U4: 18610 | V4: 17371 | W4: 13595 | X4: 21153 | Y4: 17727 | Z4: 17133 | AA4: 16444 | AB4: 13538 | AC4: 11257 | AD4: 11192 | AE4: 7769 | AF4: 8903 | AG4: 8918 | AH4: 8927 | AI4: 9628 | AJ4: 8546 | AK4: 8761 | AL4: 9766 | AM4: 10944 | AN4: 7910 | AO4: 6537 | AP4: 8463 | AQ4: 9026 | AR4: 9761 | AS4: 5653 | AT4: 6932 | AU4: 5933 | AV4: 6703 | AW4: 8229 | AX4: 9765 | AY4: 9594 | AZ4: 10286 | BA4: 9956 | BB4: 11637 | BC4: 11805 | BD4: 12977 | BE4: 8925 | BF4: 9176 | BG4: 8516 | BH4: 8520 | BI4: 9814 | BJ4: 10226 | BK4: 11049 | BL4: 9172 | BM4: 6900 | BN4: 9350 | BO4: 9284 | BP4: 6876 | BQ4: 9106 | BR4: 7787 | BS4: 11705 | BT4: 12209 | BU4: 11435 | BV4: 12997 | BW4: 14483 | BX4: 11546 | BY4: 9632 | BZ4: 10600 | CA4: 9967 | CB4: 13032 | CC4: 11220 | CD4: 9794 | CE4: 9985 | CF4: 12125 | CG4: 11462 | CH4: 14286 | CI4: 11331 | CJ4: 11556 | CK4: 8138 | CL4: 13415 | CM4: 11653 | CN4: 12513 | CO4: 10657 | CP4: 11516 | CQ4: 12291 | CR4: 11466 | CS4: 12024 | CT4: 12191 | CU4: 11563 | CV4: 11411 | CW4: 8082 | CX4: 11007 | CY4: 10384 | CZ4: 8795 | DA4: 6800 | DB4: 4162 | DC4: 7551 | DD4: 6137 | DE4: 4187 | DF4: 4087 | DG4: 7079 | DH4: 6022 | DI4: 6597 | DJ4: 9747 | DK4: 7743 | DL4: 2398
B5: =+EOMONTH(B4,1) -> 41090 | C5: =+D5+E5 -> 17944 | D5: 17244 | E5: 700 | J5: =+SUM(C3:C5) -> 62140 | K5: =+SUM(D3:D5) -> 60405 | L5: =+SUM(E3:E5) -> 1735
B6: =+EOMONTH(B5,1) -> 41121 | C6: =+D6+E6 -> 26908 | D6: 26240 | E6: 668 | J6: =+SUM(C4:C6) -> 65822 | K6: =+SUM(D4:D6) -> 63987 | L6: =+SUM(E4:E6) -> 1835
B7: =+EOMONTH(B6,1) -> 41152 | C7: =+D7+E7 -> 23081 | D7: 22311 | E7: 770 | J7: =+SUM(C5:C7) -> 67933 | K7: =+SUM(D5:D7) -> 65795 | L7: =+SUM(E5:E7) -> 2138
B8: =+EOMONTH(B7,1) -> 41182 | C8: =+D8+E8 -> 22434 | D8: 21652 | E8: 782 | J8: =+SUM(C6:C8) -> 72423 | K8: =+SUM(D6:D8) -> 70203 | L8: =+SUM(E6:E8) -> 2220
B9: =+EOMONTH(B8,1) -> 41213 | C9: =+D9+E9 -> 21367 | D9: 21119 | E9: 248 | J9: =+SUM(C7:C9) -> 66882 | K9: =+SUM(D7:D9) -> 65082 | L9: =+SUM(E7:E9) -> 1800
B10: =+EOMONTH(B9,1) -> 41243 | C10: =+D10+E10 -> 18402 | D10: 18031 | E10: 371 | J10: =+SUM(C8:C10) -> 62203 | K10: =+SUM(D8:D10) -> 60802 | L10: =+SUM(E8:E10) -> 1401
B11: =+EOMONTH(B10,1) -> 41274 | C11: =+D11+E11 -> 14643 | D11: 14185 | E11: 458 | J11: =+SUM(C9:C11) -> 54412 | K11: =+SUM(D9:D11) -> 53335 | L11: =+SUM(E9:E11) -> 1077
B12: =+EOMONTH(B11,1) -> 41305 | C12: =+D12+E12 -> 15708 | D12: 15209 | E12: 499 | J12: =+SUM(C10:C12) -> 48753 | K12: =+SUM(D10:D12) -> 47425 | L12: =+SUM(E10:E12) -> 1328
B13: =+EOMONTH(B12,1) -> 41333 | C13: =+D13+E13 -> 11177 | D13: 10613 | E13: 564 | J13: =+SUM(C11:C13) -> 41528 | K13: =+SUM(D11:D13) -> 40007 | L13: =+SUM(E11:E13) -> 1521
B14: =+EOMONTH(B13,1) -> 41364 | C14: =+D14+E14 -> 13040 | D14: 12347 | E14: 693 | J14: =+SUM(C12:C14) -> 39925 | K14: =+SUM(D12:D14) -> 38169 | L14: =+SUM(E12:E14) -> 1756 | P14: =+SUM(C3:C14) -> 228900 | Q14: =+SUM(D3:D14) -> 222112 | R14: =+SUM(E3:E14) -> 6788
B15: =+EOMONTH(B14,1) -> 41394 | C15: =+D15+E15 -> 12398 | D15: 11570 | E15: 828 | J15: =+SUM(C13:C15) -> 36615 | K15: =+SUM(D13:D15) -> 34530 | L15: =+SUM(E13:E15) -> 2085 | P15: =+SUM(C4:C15) -> 218072 | Q15: =+SUM(D4:D15) -> 211024 | R15: =+SUM(E4:E15) -> 7048
B16: =+EOMONTH(B15,1) -> 41425 | C16: =+D16+E16 -> 11932 | D16: 11134 | E16: 798 | J16: =+SUM(C14:C16) -> 37370 | K16: =+SUM(D14:D16) -> 35051 | L16: =+SUM(E14:E16) -> 2319 | P16: =+SUM(C5:C16) -> 209034 | Q16: =+SUM(D5:D16) -> 201655 | R16: =+SUM(E5:E16) -> 7379
B17: =+EOMONTH(B16,1) -> 41455 | C17: =+D17+E17 -> 12345 | D17: 11804 | E17: 541 | J17: =+SUM(C15:C17) -> 36675 | K17: =+SUM(D15:D17) -> 34508 | L17: =+SUM(E15:E17) -> 2167 | M17: =+J17/J5-1 -> -0.40980045 | P17: =+SUM(C6:C17) -> 203435 | Q17: =+SUM(D6:D17) -> 196215 | R17: =+SUM(E6:E17) -> 7220 | S17: =+P17/P5-1 -> #DIV/0!
B18: =+EOMONTH(B17,1) -> 41486 | C18: =+D18+E18 -> 11522 | D18: 10824 | E18: 698 | J18: =+SUM(C16:C18) -> 35799 | K18: =+SUM(D16:D18) -> 33762 | L18: =+SUM(E16:E18) -> 2037 | M18: =+J18/J6-1 -> -0.45612409 | P18: =+SUM(C7:C18) -> 188049 | Q18: =+SUM(D7:D18) -> 180799 | R18: =+SUM(E7:E18) -> 7250 | S18: =+P18/P6-1 -> #DIV/0!
B19: =+EOMONTH(B18,1) -> 41517 | C19: =+D19+E19 -> 12579 | D19: 11564 | E19: 1015 | J19: =+SUM(C17:C19) -> 36446 | K19: =+SUM(D17:D19) -> 34192 | L19: =+SUM(E17:E19) -> 2254 | M19: =+J19/J7-1 -> -0.4635008 | P19: =+SUM(C8:C19) -> 177547 | Q19: =+SUM(D8:D19) -> 170052 | R19: =+SUM(E8:E19) -> 7495 | S19: =+P19/P7-1 -> #DIV/0!
B20: =+EOMONTH(B19,1) -> 41547 | C20: =+D20+E20 -> 13621 | D20: 12839 | E20: 782 | J20: =+SUM(C18:C20) -> 37722 | K20: =+SUM(D18:D20) -> 35227 | L20: =+SUM(E18:E20) -> 2495 | M20: =+J20/J8-1 -> -0.47914337 | P20: =+SUM(C9:C20) -> 168734 | Q20: =+SUM(D9:D20) -> 161239 | R20: =+SUM(E9:E20) -> 7495 | S20: =+P20/P8-1 -> #DIV/0!
B21: =+EOMONTH(B20,1) -> 41578 | C21: =+D21+E21 -> 14657 | D21: 14133 | E21: 524 | J21: =+SUM(C19:C21) -> 40857 | K21: =+SUM(D19:D21) -> 38536 | L21: =+SUM(E19:E21) -> 2321 | M21: =+J21/J9-1 -> -0.38911815 | P21: =+SUM(C10:C21) -> 162024 | Q21: =+SUM(D10:D21) -> 154253 | R21: =+SUM(E10:E21) -> 7771 | S21: =+P21/P9-1 -> #DIV/0!
B22: =+EOMONTH(B21,1) -> 41608 | C22: =+D22+E22 -> 10747 | D22: 10376 | E22: 371 | J22: =+SUM(C20:C22) -> 39025 | K22: =+SUM(D20:D22) -> 37348 | L22: =+SUM(E20:E22) -> 1677 | M22: =+J22/J10-1 -> -0.37261868 | P22: =+SUM(C11:C22) -> 154369 | Q22: =+SUM(D11:D22) -> 146598 | R22: =+SUM(E11:E22) -> 7771 | S22: =+P22/P10-1 -> #DIV/0!
B23: =+EOMONTH(B22,1) -> 41639 | C23: =+D23+E23 -> 9477 | D23: 9272 | E23: 205 | J23: =+SUM(C21:C23) -> 34881 | K23: =+SUM(D21:D23) -> 33781 | L23: =+SUM(E21:E23) -> 1100 | M23: =+J23/J11-1 -> -0.35894656 | P23: =+SUM(C12:C23) -> 149203 | Q23: =+SUM(D12:D23) -> 141685 | R23: =+SUM(E12:E23) -> 7518 | S23: =+P23/P11-1 -> #DIV/0!
B24: =+EOMONTH(B23,1) -> 41670 | C24: =+D24+E24 -> 11411 | D24: 10974 | E24: 437 | J24: =+SUM(C22:C24) -> 31635 | K24: =+SUM(D22:D24) -> 30622 | L24: =+SUM(E22:E24) -> 1013 | M24: =+J24/J12-1 -> -0.35111685 | P24: =+SUM(C13:C24) -> 144906 | Q24: =+SUM(D13:D24) -> 137450 | R24: =+SUM(E13:E24) -> 7456 | S24: =+P24/P12-1 -> #DIV/0!
B25: =+EOMONTH(B24,1) -> 41698 | C25: =+D25+E25 -> 11764 | D25: 11325 | E25: 439 | J25: =+SUM(C23:C25) -> 32652 | K25: =+SUM(D23:D25) -> 31571 | L25: =+SUM(E23:E25) -> 1081 | M25: =+J25/J13-1 -> -0.21373531 | P25: =+SUM(C14:C25) -> 145493 | Q25: =+SUM(D14:D25) -> 138162 | R25: =+SUM(E14:E25) -> 7331 | S25: =+P25/P13-1 -> #DIV/0!
B26: =+EOMONTH(B25,1) -> 41729 | C26: =+D26+E26 -> 13333 | D26: 12640 | E26: 693 | J26: =+SUM(C24:C26) -> 36508 | K26: =+SUM(D24:D26) -> 34939 | L26: =+SUM(E24:E26) -> 1569 | M26: =+J26/J14-1 -> -0.085585473 | P26: =+SUM(C15:C26) -> 145786 | Q26: =+SUM(D15:D26) -> 138455 | R26: =+SUM(E15:E26) -> 7331 | S26: =+P26/P14-1 -> -0.36310179
B27: =+EOMONTH(B26,1) -> 41759 | C27: =+D27+E27 -> 7835 | D27: 7441 | E27: 394 | J27: =+SUM(C25:C27) -> 32932 | K27: =+SUM(D25:D27) -> 31406 | L27: =+SUM(E25:E27) -> 1526 | M27: =+J27/J15-1 -> -0.10058719 | P27: =+SUM(C16:C27) -> 141223 | Q27: =+SUM(D16:D27) -> 134326 | R27: =+SUM(E16:E27) -> 6897 | S27: =+P27/P15-1 -> -0.35240196
B28: =+EOMONTH(B27,1) -> 41790 | C28: =+D28+E28 -> 9416 | D28: 9230 | E28: 186 | J28: =+SUM(C26:C28) -> 30584 | K28: =+SUM(D26:D28) -> 29311 | L28: =+SUM(E26:E28) -> 1273 | M28: =+J28/J16-1 -> -0.18158951 | P28: =+SUM(C17:C28) -> 138707 | Q28: =+SUM(D17:D28) -> 132422 | R28: =+SUM(E17:E28) -> 6285 | S28: =+P28/P16-1 -> -0.33643809
... B98: =+EOMONTH(B97,1) -> 43921 | C98: =+D98+E98 -> 5801 | D98: 5676 | E98: 125 | J98: =+SUM(C96:C98) -> 32351 | K98: =+SUM(D96:D98) -> 32000 | L98: =+SUM(E96:E98) -> 351 | M98: =+J98/J86-1 -> -0.4055529 | P98: =+SUM(C87:C98) -> 133424 | Q98: =+SUM(D87:D98) -> 131891 | R98: =+SUM(E87:E98) -> 1533 | S98: =+P98/P86-1 -> -0.371128
B99: =+EOMONTH(B98,1) -> 43951 | C99: =+D99+E99 -> 0 | J99: =+SUM(C97:C99) -> 18349 | K99: =+SUM(D97:D99) -> 18106 | L99: =+SUM(E97:E99) -> 243 | M99: =+J99/J87-1 -> -0.63232141 | P99: =+SUM(C88:C99) -> 119931 | Q99: =+SUM(D88:D99) -> 118503 | R99: =+SUM(E88:E99) -> 1428 | S99: =+P99/P87-1 -> -0.42429988
B100: =+EOMONTH(B99,1) -> 43982 | C100: =+D100+E100 -> 0 | J100: =+SUM(C98:C100) -> 5801 | K100: =+SUM(D98:D100) -> 5676 | L100: =+SUM(E98:E100) -> 125 | M100: =+J100/J88-1 -> -0.86390616 | P100: =+SUM(C89:C100) -> 108942 | Q100: =+SUM(D89:D100) -> 107603 | R100: =+SUM(E89:E100) -> 1339 | S100: =+P100/P88-1 -> -0.45999613
B101: =+EOMONTH(B100,1) -> 44012 | C101: =+D101+E101 -> 11439 | D101: 11419 | E101: 20 | J101: =+SUM(C99:C101) -> 11439 | K101: =+SUM(D99:D101) -> 11419 | L101: =+SUM(E99:E101) -> 20 | M101: =+J101/J89-1 -> -0.69845789 | P101: =+SUM(C90:C101) -> 106928 | Q101: =+SUM(D90:D101) -> 105671 | R101: =+SUM(E90:E101) -> 1257 | S101: =+P101/P89-1 -> -0.45661144
B102: =+EOMONTH(B101,1) -> 44043 | C102: =+D102+E102 -> 15023 | D102: 15012 | E102: 11 | J102: =+SUM(C100:C102) -> 26462 | K102: =+SUM(D100:D102) -> 26431 | L102: =+SUM(E100:E102) -> 31 | M102: =+J102/J90-1 -> -0.24590351 | P102: =+SUM(C91:C102) -> 111302 | Q102: =+SUM(D91:D102) -> 110198 | R102: =+SUM(E91:E102) -> 1104 | S102: =+P102/P90-1 -> -0.41493902
B103: =+EOMONTH(B102,1) -> 44074 | C103: =+D103+E103 -> 18616 | D103: 18583 | E103: 33 | J103: =+SUM(C101:C103) -> 45078 | K103: =+SUM(D101:D103) -> 45014 | L103: =+SUM(E101:E103) -> 64 | M103: =+J103/J91-1 -> 0.42719645 | P103: =+SUM(C92:C103) -> 122435 | Q103: =+SUM(D92:D103) -> 121465 | R103: =+SUM(E92:E103) -> 970 | S103: =+P103/P91-1 -> -0.31620805
B104: =+EOMONTH(B103,1) -> 44104 | C104: =+D104+E104 -> 21219 | D104: 21199 | E104: 20 | J104: =+SUM(C102:C104) -> 54858 | K104: =+SUM(D102:D104) -> 54794 | L104: =+SUM(E102:E104) -> 64 | M104: =+J104/J92-1 -> 1.0756744 | P104: =+SUM(C93:C104) -> 135357 | Q104: =+SUM(D93:D104) -> 134567 | R104: =+SUM(E93:E104) -> 790 | S104: =+P104/P92-1 -> -0.19801751
B105: =+EOMONTH(B104,1) -> 44135 | C105: =+D105+E105 -> 23660 | D105: 23617 | E105: 43 | J105: =+SUM(C103:C105) -> 63495 | K105: =+SUM(D103:D105) -> 63399 | L105: =+SUM(E103:E105) -> 96 | M105: =+J105/J93-1 -> 1.179562 | P105: =+SUM(C94:C105) -> 145665 | Q105: =+SUM(D94:D105) -> 145015 | R105: =+SUM(E94:E105) -> 650 | S105: =+P105/P93-1 -> -0.11005688
B106: =+EOMONTH(B105,1) -> 44165 | C106: =+D106+E106 -> 21671 | D106: 21644 | E106: 27 | J106: =+SUM(C104:C106) -> 66550 | K106: =+SUM(D104:D106) -> 66460 | L106: =+SUM(E104:E106) -> 90 | M106: =+J106/J94-1 -> 1.0677334 | P106: =+SUM(C95:C106) -> 156800 | Q106: =+SUM(D95:D106) -> 156259 | R106: =+SUM(E95:E106) -> 541 | S106: =+P106/P94-1 -> -0.0018969051
B107: =+EOMONTH(B106,1) -> 44196 | C107: =+D107+E107 -> 23564 | D107: 23545 | E107: 19 | J107: =+SUM(C105:C107) -> 68895 | K107: =+SUM(D105:D107) -> 68806 | L107: =+SUM(E105:E107) -> 89 | M107: =+J107/J95-1 -> 0.87678771 | P107: =+SUM(C96:C107) -> 167543 | Q107: =+SUM(D96:D107) -> 167019 | R107: =+SUM(E96:E107) -> 524 | S107: =+P107/P95-1 -> 0.077481591
B108: =+EOMONTH(B107,1) -> 44227 | C108: =+D108+E108 -> 27050 | D108: 26978 | E108: 72 | J108: =+SUM(C106:C108) -> 72285 | K108: =+SUM(D106:D108) -> 72167 | L108: =+SUM(E106:E108) -> 118 | M108: =+J108/J96-1 -> 0.93487513 | P108: =+SUM(C97:C108) -> 180591 | Q108: =+SUM(D97:D108) -> 180103 | R108: =+SUM(E97:E108) -> 488 | S108: =+P108/P96-1 -> 0.1921221
B109: =+EOMONTH(B108,1) -> 44255 | C109: =+D109+E109 -> 27399 | D109: 27225 | E109: 174 | J109: =+SUM(C107:C109) -> 78013 | K109: =+SUM(D107:D109) -> 77748 | L109: =+SUM(E107:E109) -> 265 | M109: =+J109/J97-1 -> 0.98148383 | P109: =+SUM(C98:C109) -> 195442 | Q109: =+SUM(D98:D109) -> 194898 | R109: =+SUM(E98:E109) -> 544 | S109: =+P109/P97-1 -> 0.34079278
B110: =+EOMONTH(B109,1) -> 44286 | C110: =+D110+E110 -> 29787 | D110: 29654 | E110: 133 | J110: =+SUM(C108:C110) -> 84236 | K110: =+SUM(D108:D110) -> 83857 | L110: =+SUM(E108:E110) -> 379 | M110: =+J110/J98-1 -> 1.6038144 | P110: =+SUM(C99:C110) -> 219428 | Q110: =+SUM(D99:D110) -> 218876 | R110: =+SUM(E99:E110) -> 552 | S110: =+P110/P98-1 -> 0.64459168
...

Sheet Ignore-TMotors Retail-vaahan
B1: Vaahan Data - Tata Motors PV
U2: Export
B3: Month | C3: Registrations | D3: YoY% | F3: 3M Rolling | G3: QoQ% | H3: YoY% | J3: 12M Rolling | K3: YoY%
B4: 43101 | C4: 55165
B5: 43159 | C5: 48810
B6: 43190 | C6: 52640 | F6: =+SUM(C4:C6) -> 156615
B7: 43220 | C7: 54004 | F7: =+SUM(C5:C7) -> 155454 | G7: =+F7/F6-1 -> -0.007413083
B8: 43251 | C8: 49410 | F8: =+SUM(C6:C8) -> 156054 | G8: =+F8/F7-1 -> 0.0038596627
B9: 43281 | C9: 44967 | F9: =+SUM(C7:C9) -> 148381 | G9: =+F9/F8-1 -> -0.049168877
B10: 43312 | C10: 46856 | F10: =+SUM(C8:C10) -> 141233 | G10: =+F10/F9-1 -> -0.048173284
B11: 43343 | C11: 44248 | F11: =+SUM(C9:C11) -> 136071 | G11: =+F11/F10-1 -> -0.036549532
B12: 43373 | C12: 46454 | F12: =+SUM(C10:C12) -> 137558 | G12: =+F12/F11-1 -> 0.010928118
B13: 43404 | C13: 50125 | F13: =+SUM(C11:C13) -> 140827 | G13: =+F13/F12-1 -> 0.023764521
B14: 43434 | C14: 50025 | F14: =+SUM(C12:C14) -> 146604 | G14: =+F14/F13-1 -> 0.041021963 | U14: =+SUM(F3:F14) -> 1318797
B15: 43465 | C15: 46302 | F15: =+SUM(C13:C15) -> 146452 | G15: =+F15/F14-1 -> -0.0010368066 | J15: =+SUM(C4:C15) -> 589006 | U15: =+SUM(F4:F15) -> 1465249
B16: 43496 | C16: 54043 | D16: =+C16/C4-1 -> -0.020338983 | F16: =+SUM(C14:C16) -> 150370 | G16: =+F16/F15-1 -> 0.026752793 | J16: =+SUM(C5:C16) -> 587884 | U16: =+SUM(F5:F16) -> 1615619
B17: 43524 | C17: 46567 | D17: =+C17/C5-1 -> -0.045953698 | F17: =+SUM(C15:C17) -> 146912 | G17: =+F17/F16-1 -> -0.022996608 | J17: =+SUM(C6:C17) -> 585641 | U17: =+SUM(F6:F17) -> 1762531
B18: 43555 | C18: 50717 | D18: =+C18/C6-1 -> -0.036531155 | F18: =+SUM(C16:C18) -> 151327 | G18: =+F18/F17-1 -> 0.030052004 | H18: =+F18/F6-1 -> -0.033764327 | J18: =+SUM(C7:C18) -> 583718 | U18: =+SUM(F7:F18) -> 1757243
B19: 43585 | C19: 49999 | D19: =+C19/C7-1 -> -0.074161173 | F19: =+SUM(C17:C19) -> 147283 | G19: =+F19/F18-1 -> -0.026723585 | H19: =+F19/F7-1 -> -0.052562173 | J19: =+SUM(C8:C19) -> 579713 | U19: =+SUM(F8:F19) -> 1749072
B20: 43616 | C20: 46580 | D20: =+C20/C8-1 -> -0.057275855 | F20: =+SUM(C18:C20) -> 147296 | G20: =+F20/F19-1 -> 8.8265448e-05 | H20: =+F20/F8-1 -> -0.056121599 | J20: =+SUM(C9:C20) -> 576883 | U20: =+SUM(F9:F20) -> 1740314
B21: 43646 | C21: 38803 | D21: =+C21/C9-1 -> -0.1370783 | F21: =+SUM(C19:C21) -> 135382 | G21: =+F21/F20-1 -> -0.080884749 | H21: =+F21/F9-1 -> -0.087605556 | J21: =+SUM(C10:C21) -> 570719 | U21: =+SUM(F10:F21) -> 1727315
B22: 43677 | C22: 40652 | D22: =+C22/C10-1 -> -0.13240567 | F22: =+SUM(C20:C22) -> 126035 | G22: =+F22/F21-1 -> -0.069041675 | H22: =+F22/F10-1 -> -0.10760941 | J22: =+SUM(C11:C22) -> 564515 | U22: =+SUM(F11:F22) -> 1712117
B23: 43708 | C23: 37547 | D23: =+C23/C11-1 -> -0.15144187 | F23: =+SUM(C21:C23) -> 117002 | G23: =+F23/F22-1 -> -0.071670568 | H23: =+F23/F11-1 -> -0.14014007 | J23: =+SUM(C12:C23) -> 557814 | U23: =+SUM(F12:F23) -> 1693048
B24: 43738 | C24: 35728 | D24: =+C24/C12-1 -> -0.23089508 | F24: =+SUM(C22:C24) -> 113927 | G24: =+F24/F23-1 -> -0.026281602 | H24: =+F24/F12-1 -> -0.17178935 | J24: =+SUM(C13:C24) -> 547088 | U24: =+SUM(F13:F24) -> 1669417
B25: 43769 | C25: 39095 | D25: =+C25/C13-1 -> -0.22004988 | F25: =+SUM(C23:C25) -> 112370 | G25: =+F25/F24-1 -> -0.013666646 | H25: =+F25/F13-1 -> -0.20207063 | J25: =+SUM(C14:C25) -> 536058 | U25: =+SUM(F14:F25) -> 1640960
B26: 43799 | C26: 43473 | D26: =+C26/C14-1 -> -0.13097451 | F26: =+SUM(C24:C26) -> 118296 | G26: =+F26/F25-1 -> 0.052736496 | H26: =+F26/F14-1 -> -0.19309159 | J26: =+SUM(C15:C26) -> 529506 | U26: =+SUM(F15:F26) -> 1612652
B27: 43830 | C27: 36271 | D27: =+C27/C15-1 -> -0.21664291 | F27: =+SUM(C25:C27) -> 118839 | G27: =+F27/F26-1 -> 0.0045901806 | H27: =+F27/F15-1 -> -0.18854642 | J27: =+SUM(C16:C27) -> 519475 | K27: =+J27/J15-1 -> -0.11804803 | U27: =+SUM(F16:F27) -> 1585039
B28: 43861 | C28: 47812 | D28: =+C28/C16-1 -> -0.11529708 | F28: =+SUM(C26:C28) -> 127556 | G28: =+F28/F27-1 -> 0.073351341 | H28: =+F28/F16-1 -> -0.15171909 | J28: =+SUM(C17:C28) -> 513244 | K28: =+J28/J16-1 -> -0.12696382 | U28: =+SUM(F17:F28) -> 1562225
B29: 43890 | C29: 49588 | D29: =+C29/C17-1 -> 0.064874267 | F29: =+SUM(C27:C29) -> 133671 | G29: =+F29/F28-1 -> 0.047939728 | H29: =+F29/F17-1 -> -0.090128785 | J29: =+SUM(C18:C29) -> 516265 | K29: =+J29/J17-1 -> -0.11846165 | U29: =+SUM(F18:F29) -> 1548984
B30: 43921 | C30: 70617 | D30: =+C30/C18-1 -> 0.39237337 | F30: =+SUM(C28:C30) -> 168017 | G30: =+F30/F29-1 -> 0.25694429 | H30: =+F30/F18-1 -> 0.11029096 | J30: =+SUM(C19:C30) -> 536165 | K30: =+J30/J18-1 -> -0.081465708 | U30: =+SUM(F19:F30) -> 1565674
