Workbook

Sheet Template
A1: =+'Annual Raw'!C4 -> Thyrocare Technologies Ltd. | B1: 36951 | C1: =EOMONTH(B1,12) -> 37346 | D1: =EOMONTH(C1,12) -> 37711 | E1: =EOMONTH(D1,12) -> 38077 | F1: =EOMONTH(E1,12) -> 38442 | G1: =EOMONTH(F1,12) -> 38807 | H1: =EOMONTH(G1,12) -> 39172 | I1: =EOMONTH(H1,12) -> 39538 | J1: =EOMONTH(I1,12) -> 39903 | ... AE1: =EOMONTH(AD1,12) -> 47573 | AH1: QTR | AI1: 41061 | AJ1: 41153 | AK1: 41244 | AL1: 41334 | AM1: 41426 | AN1: 41518 | AO1: 41609 | AP1: 41699 | AQ1: 41791 | AR1: 41883 | AS1: 41974 | AT1: 42064 | AU1: 42156 | AV1: 42248 | AW1: 42339 | AX1: 42430 | AY1: 42522 | AZ1: 42614 | BA1: 42705 | BB1: 42795 | BC1: 42887 | BD1: 42979 | BE1: 43070 | BF1: 43160 | BG1: 43252 | BH1: 43344 | BI1: 43435 | BJ1: 43525 | BK1: 43617 | BL1: 43709 | BM1: 43800 | BN1: 43891 | BO1: 43983 | BP1: 44075 | BQ1: =EOMONTH(BP1,3) -> 44196 | BR1: =EOMONTH(BQ1,3) -> 44286 | BS1: =EOMONTH(BR1,3) -> 44377 | BT1: =EOMONTH(BS1,3) -> 44469 | BU1: =EOMONTH(BT1,3) -> 44561 | BV1: =EOMONTH(BU1,3) -> 44651 | BW1: =EOMONTH(BV1,3) -> 44742 | BX1: =EOMONTH(BW1,3) -> 44834 | ... DB1: =EOMONTH(DA1,3) -> 47573 | DE1: HISTORICAL ESTIMATES | DF1: 46112
A2: Presentation Data (Start)
A4: Revenue Breakup
A5: Pathology | Q5: =SUM(AU5:AX5) -> 214.29 | R5: =SUM(AY5:BB5) -> 273.2 | S5: =SUM(BC5:BF5) -> 328.96 | T5: =SUM(BG5:BJ5) -> 368.11 | U5: =SUM(BK5:BN5) -> 397.06 | V5: =SUM(BO5:BR5) -> 472.87 | W5: =SUM(BS5:BV5) -> 555.43 | X5: =SUM(BW5:BZ5) -> 481.21 | Y5: =SUM(CA5:CD5) -> 522.23 | Z5: =SUM(CE5:CH5) -> 629.69 | AA5: =SUM(CI5:CL5) -> 775.8 | AB5: =+SUM(CM5:CP5) -> 919.51997 | AC5: =+SUM(CQ5:CT5) -> 1097.3551 | AD5: =+SUM(CU5:CX5) -> 1309.5836 | AE5: =+SUM(CY5:DB5) -> 1562.8571 | AU5: 50.64 | AV5: 55.58 | AW5: 50.29 | AX5: 57.78 | AY5: 62 | AZ5: 70.1 | BA5: 62.63 | BB5: 78.47 | BC5: 81.5 | BD5: 81.04 | BE5: 77.02 | BF5: 89.4 | BG5: 88.87 | BH5: 95.18 | BI5: 87.42 | BJ5: 96.64 | BK5: 99.97 | BL5: 106.99 | BM5: 97.25 | BN5: 92.85 | BO5: 54.1 | BP5: 148.25 | BQ5: 131.84 | BR5: 138.68 | BS5: 156.94 | BT5: 167.13 | BU5: 109.3 | BV5: 122.06 | BW5: 118.43 | BX5: 123.83 | BY5: 115.74 | BZ5: 123.21 | CA5: 121.94 | CB5: 136.75 | CC5: 122.43 | CD5: 141.11 | CE5: 143.21 | CF5: 161.92 | CG5: 151.87 | CH5: 172.69 | CI5: 178.9 | CJ5: 202.3 | CK5: 183.1 | CL5: 211.5 | CM5: =CM22 -> 212.4527 | CN5: =CN22 -> 240.12261 | CO5: =CO22 -> 216.72788 | CP5: =CP22 -> 250.21678 | CQ5: =CQ22 -> 253.54105 | CR5: =CR22 -> 286.56232 | CS5: =CS22 -> 258.64305 | CT5: =CT22 -> 298.60871 | ... DB5: =DB22 -> 425.27959
A6: Radiology | Q6: =SUM(AU6:AX6) -> 26.68 | R6: =SUM(AY6:BB6) -> 33.61 | S6: =SUM(BC6:BF6) -> 27.37 | T6: =SUM(BG6:BJ6) -> 34.8 | U6: =SUM(BK6:BN6) -> 37.03 | V6: =SUM(BO6:BR6) -> 21.76 | W6: =SUM(BS6:BV6) -> 33.38 | X6: =SUM(BW6:BZ6) -> 45.46 | Y6: =SUM(CA6:CD6) -> 49.65 | Z6: =SUM(CE6:CH6) -> 57.67 | AA6: =SUM(CI6:CL6) -> 53.16 | AB6: =+SUM(CM6:CP6) -> 49.6 | AC6: =+SUM(CQ6:CT6) -> 49.6 | AD6: =+SUM(CU6:CX6) -> 49.6 | AE6: =+SUM(CY6:DB6) -> 49.6 | AU6: 6.36 | AV6: 6.68 | AW6: 6.37 | AX6: 7.27 | AY6: 7.36 | AZ6: 8.62 | BA6: 8.42 | BB6: 9.21 | BC6: 6.26 | BD6: 7 | BE6: 6.85 | BF6: 7.26 | BG6: 8.28 | BH6: 8.7 | BI6: 8.87 | BJ6: 8.95 | BK6: 10 | BL6: 9.51 | BM6: 8.65 | BN6: 8.87 | BO6: 2.17 | BP6: 5 | BQ6: 6.43 | BR6: 8.16 | BS6: 7.7 | BT6: 9.08 | BU6: 8.1 | BV6: 8.5 | BW6: 9.36 | BX6: 11.14 | BY6: 12.29 | BZ6: 12.67 | CA6: 12.95 | CB6: 11.25 | CC6: 12.31 | CD6: 13.14 | CE6: 13.7 | CF6: 15.44 | CG6: 14.06 | CH6: 14.47 | CI6: 14.13 | CJ6: 14.23 | CK6: 12.4 | CL6: 12.4 | CM6: =CL6 -> 12.4 | CN6: =CM6 -> 12.4 | CO6: =CN6 -> 12.4 | CP6: =CO6 -> 12.4 | CQ6: =CP6 -> 12.4 | CR6: =CQ6 -> 12.4 | CS6: =CR6 -> 12.4 | CT6: =CS6 -> 12.4 | ... DB6: =DA6 -> 12.4
A7: Total Revenue | Q7: =+SUM(Q5:Q6) -> 240.97 | R7: =+SUM(R5:R6) -> 306.81 | S7: =+SUM(S5:S6) -> 356.33 | T7: =+SUM(T5:T6) -> 402.91 | U7: =+SUM(U5:U6) -> 434.09 | V7: =+SUM(V5:V6) -> 494.63 | W7: =+SUM(W5:W6) -> 588.81 | X7: =+SUM(X5:X6) -> 526.67 | ... AE7: =+SUM(AE5:AE6) -> 1612.4571 | AU7: =+SUM(AU5:AU6) -> 57 | AV7: =+SUM(AV5:AV6) -> 62.26 | AW7: =+SUM(AW5:AW6) -> 56.66 | AX7: =+SUM(AX5:AX6) -> 65.05 | AY7: =+SUM(AY5:AY6) -> 69.36 | AZ7: =+SUM(AZ5:AZ6) -> 78.72 | BA7: =+SUM(BA5:BA6) -> 71.05 | BB7: =+SUM(BB5:BB6) -> 87.68 | ... DB7: =+SUM(DB5:DB6) -> 437.67959
A8: Checksum | Q8: =+Q7-Q41 -> 0.005 | R8: =+R7-R41 -> 2.423 | S8: =+S7-S41 -> 0.01 | T8: =+T7-T41 -> 0 | U8: =+U7-U41 -> -0.17 | V8: =+V7-V41 -> 0.01 | W8: =+W7-W41 -> -0.05 | X8: =+X7-X41 -> 0 | ... Z8: =+Z7-Z41 -> 0.01 | AU8: =+AU7-AU41 -> 0.005 | AV8: =+AV7-AV41 -> -0.005 | AW8: =+AW7-AW41 -> 0.008 | AX8: =+AX7-AX41 -> -0.005 | AY8: =+AY7-AY41 -> 0.615 | AZ8: =+AZ7-AZ41 -> 0.572 | BA8: =+BA7-BA41 -> 0.672 | BB8: =+BB7-BB41 -> 0.564 | ... DB8: =+DB7-DB41 -> 0
A10: EBITDA Breakup
A11: Pathology | Q11: =SUM(AU11:AX11) -> 0 | R11: =SUM(AY11:BB11) -> 0 | S11: =SUM(BC11:BF11) -> 0 | U11: =SUM(BK11:BN11) -> 167.08 | V11: =SUM(BO11:BR11) -> 171.07 | W11: =SUM(BS11:BV11) -> 230.54 | X11: =SUM(BW11:BZ11) -> 142.53 | Y11: =SUM(CA11:CD11) -> 157.3 | Z11: =SUM(CE11:CH11) -> 203.8 | AA11: =SUM(CI11:CL11) -> 267.4 | AB11: =+SUM(CM11:CP11) -> 0 | AC11: =+SUM(CQ11:CT11) -> 0 | AD11: =+SUM(CU11:CX11) -> 0 | AE11: =+SUM(CY11:DB11) -> 0 | BK11: 44.02 | BL11: 50.92 | BM11: 42.84 | BN11: 29.3 | BO11: 9.51 | BP11: 61.7 | BQ11: 49.17 | BR11: 50.69 | BS11: 70.47 | BT11: 87 | BU11: 36 | BV11: 37.07 | BW11: 34.08 | BX11: 37.53 | BY11: 32.27 | BZ11: 38.65 | CA11: 40.3 | CB11: 41.5 | CC11: 34.3 | CD11: 41.2 | CE11: 43.5 | CF11: 50.7 | CG11: 47.1 | CH11: 62.5 | CI11: 61.7 | CJ11: 72.6 | CK11: 60.7 | CL11: 72.4
A12: Radiology (incl.ESOP cost) | Q12: =SUM(AU12:AX12) -> 0 | R12: =SUM(AY12:BB12) -> 0 | S12: =SUM(BC12:BF12) -> 0 | U12: =SUM(BK12:BN12) -> 4.76 | V12: =SUM(BO12:BR12) -> 0.05 | W12: =SUM(BS12:BV12) -> 3.32 | X12: =SUM(BW12:BZ12) -> 5.81 | Y12: =SUM(CA12:CD12) -> 4.5 | Z12: =SUM(CE12:CH12) -> 6.2 | AA12: =SUM(CI12:CL12) -> 8.7 | AB12: =+SUM(CM12:CP12) -> 0 | AC12: =+SUM(CQ12:CT12) -> 0 | AD12: =+SUM(CU12:CX12) -> 0 | AE12: =+SUM(CY12:DB12) -> 0 | BK12: 1.32 | BL12: 1.25 | BM12: 0.87 | BN12: 1.32 | BO12: -1.14 | BP12: -0.2 | BQ12: 0.65 | BR12: 0.74 | BS12: 0.6 | BT12: 1.6 | BU12: 0.7 | BV12: 0.42 | BW12: 0.42 | BX12: 1.64 | BY12: 2.11 | BZ12: 1.64 | CA12: 1.4 | CB12: 1.1 | CC12: 1 | CD12: 1 | CE12: 1.3 | CF12: -0.2 | CG12: 2.3 | CH12: 2.8 | CI12: 1.7 | CJ12: 2.8 | CK12: 1.5 | CL12: 2.7
A13: ESOP Cost(b/f) | BV13: 0.1 | BW13: 1.42 | BX13: -7.59 | BY13: -6.52 | BZ13: -15.6 | CA13: -7.19 | CB13: -5.08 | CC13: -3.71 | CD13: -8.39 | CE13: -2.16 | CF13: -2.21 | CG13: -7.67 | CH13: -7.6 | CI13: -5.63 | CJ13: -4.05 | CK13: -4.37 | CL13: 0
A14: Total EBITDA | Q14: =+Q11+Q12 -> 0 | R14: =+R11+R12 -> 0 | S14: =+S11+S12 -> 0 | U14: =+U11+U12 -> 171.84 | V14: =+V11+V12 -> 171.12 | W14: =+W11+W12 -> 233.86 | X14: =+X11+X12 -> 148.34 | Y14: =+Y11+Y12 -> 161.8 | Z14: =+Z11+Z12 -> 210 | AA14: =+AA11+AA12 -> 276.1 | AB14: =+AB11+AB12 -> 0 | ... AE14: =+AE11+AE12 -> 0 | BK14: =+BK11+BK12 -> 45.34 | BL14: =+BL11+BL12 -> 52.17 | BM14: =+BM11+BM12 -> 43.71 | BN14: =+BN11+BN12 -> 30.62 | BO14: =+BO11+BO12 -> 8.37 | BP14: =+BP11+BP12 -> 61.5 | BQ14: =+BQ11+BQ12 -> 49.82 | BR14: =+BR11+BR12 -> 51.43 | ... BU14: =+BU11+BU12 -> 36.7 | BV14: =+BV11+BV12+BV13 -> 37.59 | BW14: =+BW11+BW12+BW13 -> 35.92 | BX14: =+BX11+BX12+BX13 -> 31.58 | BY14: =+BY11+BY12+BY13 -> 27.86 | BZ14: =+BZ11+BZ12+BZ13 -> 24.69 | CA14: =+CA11+CA12+CA13 -> 34.51 | CB14: =+CB11+CB12+CB13 -> 37.52 | CC14: =+CC11+CC12+CC13 -> 31.59 | ... CL14: =+CL11+CL12+CL13 -> 75.1
A15: Checksum | Q15: =+Q14-Q70 -> -94.049 | R15: =+R14-R70 -> -115.379 | S15: =+S14-S70 -> -144.72 | U15: =+U14-U70 -> -1.73 | V15: =+V14-V70 -> -0.14 | W15: =+W14-W70 -> -1.87 | X15: =+X14-X70 -> 25.81 | Y15: =+Y14-Y70 -> 23.04 | Z15: =+Z14-Z70 -> 19.44 | BK15: =+BK14-BK70 -> -0.27 | BL15: =+BL14-BL70 -> 0.01 | BM15: =+BM14-BM70 -> -0.07 | BN15: =+BN14-BN70 -> -0.35 | BO15: =+BO14-BO70 -> -0.09 | BP15: =+BP14-BP70 -> -0.4 | BQ15: =+BQ14-BQ70 -> 0.2 | BR15: =+BR14-BR70 -> -0.1 | ... CL15: =+CL14-CL70 -> 0.01
A17: Pathology- Revenue Breakup
A18: Franchise | Q18: =SUM(AU18:AX18) -> 0 | R18: =SUM(AY18:BB18) -> 0 | S18: =SUM(BC18:BF18) -> 0 | T18: =SUM(BG18:BJ18) -> 0 | U18: =SUM(BK18:BN18) -> 0 | V18: =SUM(BO18:BR18) -> 0 | W18: =SUM(BS18:BV18) -> 247 | X18: =SUM(BW18:BZ18) -> 280 | Y18: =SUM(CA18:CD18) -> 325.2 | Z18: =SUM(CE18:CH18) -> 399 | AA18: =SUM(CI18:CL18) -> 477.7 | AB18: =+SUM(CM18:CP18) -> 919.51997 | AC18: =+SUM(CQ18:CT18) -> 1097.3551 | AD18: =+SUM(CU18:CX18) -> 1309.5836 | AE18: =+SUM(CY18:DB18) -> 1562.8571 | BS18: 60 | BT18: 65 | BU18: 60 | BV18: 62 | BW18: 68 | BX18: 72 | BY18: 67 | BZ18: 73 | CA18: 79.4 | CB18: 86.3 | CC18: 76 | CD18: 83.5 | CE18: 88.5 | CF18: 104.9 | CG18: 100.2 | CH18: 105.4 | CI18: 112.5 | CJ18: 125.4 | CK18: 112.2 | CL18: 127.6 | CM18: =CM32*CM28/10 -> 212.4527 | CN18: =CN32*CN28/10 -> 240.12261 | CO18: =CO32*CO28/10 -> 216.72788 | CP18: =CP32*CP28/10 -> 250.21678 | CQ18: =CQ32*CQ28/10 -> 253.54105 | CR18: =CR32*CR28/10 -> 286.56232 | CS18: =CS32*CS28/10 -> 258.64305 | CT18: =CT32*CT28/10 -> 298.60871 | ... DB18: =DB32*DB28/10 -> 425.27959
A19: Partnerships (Includes B2G) | Q19: =SUM(AU19:AX19) -> 0 | R19: =SUM(AY19:BB19) -> 0 | S19: =SUM(BC19:BF19) -> 0 | T19: =SUM(BG19:BJ19) -> 0 | U19: =SUM(BK19:BN19) -> 0 | V19: =SUM(BO19:BR19) -> 0 | W19: =SUM(BS19:BV19) -> 104 | X19: =SUM(BW19:BZ19) -> 149 | Y19: =SUM(CA19:CD19) -> 151.2 | Z19: =SUM(CE19:CH19) -> 191.8 | AA19: =SUM(CI19:CL19) -> 253.6 | AB19: =+SUM(CM19:CP19) -> 0 | AC19: =+SUM(CQ19:CT19) -> 0 | AD19: =+SUM(CU19:CX19) -> 0 | AE19: =+SUM(CY19:DB19) -> 0 | BS19: 20 | BT19: 28 | BU19: 25 | BV19: 31 | BW19: 38 | BX19: 38 | BY19: 35 | BZ19: 38 | CA19: 32.3 | CB19: 36.9 | CC19: 35.2 | CD19: 46.8 | CE19: 41.5 | CF19: 48.9 | CG19: 43.2 | CH19: 58.2 | CI19: 56.3 | CJ19: 65.6 | CK19: 60.1 | CL19: 71.6
A20: D2C | Q20: =SUM(AU20:AX20) -> 0 | R20: =SUM(AY20:BB20) -> 0 | S20: =SUM(BC20:BF20) -> 0 | T20: =SUM(BG20:BJ20) -> 0 | U20: =SUM(BK20:BN20) -> 0 | V20: =SUM(BO20:BR20) -> 0 | W20: =SUM(BS20:BV20) -> 25 | X20: =SUM(BW20:BZ20) -> 28 | Y20: =SUM(CA20:CD20) -> 31.6 | Z20: =SUM(CE20:CH20) -> 38 | AA20: =SUM(CI20:CL20) -> 43 | AB20: =+SUM(CM20:CP20) -> 0 | AC20: =+SUM(CQ20:CT20) -> 0 | AD20: =+SUM(CU20:CX20) -> 0 | AE20: =+SUM(CY20:DB20) -> 0 | BS20: 4 | BT20: 7 | BU20: 6 | BV20: 8 | BW20: 6 | BX20: 7 | BY20: 7 | BZ20: 8 | CA20: 7.4 | CB20: 8.3 | CC20: 7.4 | CD20: 8.5 | CE20: 8.6 | CF20: 10 | CG20: 9.1 | CH20: 10.3 | CI20: 10.1 | CJ20: 11.2 | CK20: 10.2 | CL20: 11.5
A21: Covid Materials & Others | Q21: =SUM(AU21:AX21) -> 0 | R21: =SUM(AY21:BB21) -> 0 | S21: =SUM(BC21:BF21) -> 0 | T21: =SUM(BG21:BJ21) -> 0 | U21: =SUM(BK21:BN21) -> 0 | V21: =SUM(BO21:BR21) -> 0 | W21: =SUM(BS21:BV21) -> 185.49 | X21: =SUM(BW21:BZ21) -> 29.46 | Y21: =SUM(CA21:CD21) -> 16 | Z21: =SUM(CE21:CH21) -> 5 | AA21: =SUM(CI21:CL21) -> 0 | AB21: =+SUM(CM21:CP21) -> 0 | AC21: =+SUM(CQ21:CT21) -> 0 | AD21: =+SUM(CU21:CX21) -> 0 | AE21: =+SUM(CY21:DB21) -> 0 | BS21: 75.26 | BT21: 68.7 | BU21: 19.2 | BV21: 22.33 | BW21: 7.24 | BX21: 8.23 | BY21: 8.17 | BZ21: 5.82 | CA21: 4.51 | CB21: 4.79 | CC21: 4.3 | CD21: 2.4 | CE21: 5
A22: Total Pathology Revenue | Q22: =+SUM(Q18:Q21) -> 0 | R22: =+SUM(R18:R21) -> 0 | S22: =+SUM(S18:S21) -> 0 | T22: =+SUM(T18:T21) -> 0 | U22: =+SUM(U18:U21) -> 0 | V22: =+SUM(V18:V21) -> 0 | W22: =+SUM(W18:W21) -> 561.49 | X22: =+SUM(X18:X21) -> 486.46 | ... AE22: =+SUM(AE18:AE21) -> 1562.8571 | BS22: =+SUM(BS18:BS21) -> 159.26 | BT22: =+SUM(BT18:BT21) -> 168.7 | BU22: =+SUM(BU18:BU21) -> 110.2 | BV22: =+SUM(BV18:BV21) -> 123.33 | BW22: =+SUM(BW18:BW21) -> 119.24 | BX22: =+SUM(BX18:BX21) -> 125.23 | BY22: =+SUM(BY18:BY21) -> 117.17 | BZ22: =+SUM(BZ18:BZ21) -> 124.82 | ... DB22: =+SUM(DB18:DB21) -> 425.27959
A23: Checksum | W23: =+W22-W5 -> 6.06 | X23: =+X22-X5 -> 5.25 | Y23: =+Y22-Y5 -> 1.77 | Z23: =+Z22-Z5 -> 4.11 | AA23: =+AA22-AA5 -> -1.5 | AB23: =+AB22-AB5 -> 0 | AC23: =+AC22-AC5 -> 0 | AD23: =+AD22-AD5 -> 0 | AE23: =+AE22-AE5 -> 0 | BS23: =+BS22-BS5 -> 2.32 | BT23: =+BT22-BT5 -> 1.57 | BU23: =+BU22-BU5 -> 0.9 | BV23: =+BV22-BV5 -> 1.27 | BW23: =+BW22-BW5 -> 0.81 | BX23: =+BX22-BX5 -> 1.4 | BY23: =+BY22-BY5 -> 1.43 | BZ23: =+BZ22-BZ5 -> 1.61 | ... DB23: =+DB22-DB5 -> 0
A25: Key Metrics
A26: Franchisees | X26: =+BZ26 -> 9481 | Y26: =+CD26 -> 9696 | Z26: =+CH26 -> 11249 | AA26: =CL26 -> 10800 | AB26: =CP26 -> 12636 | AC26: =CT26 -> 14784.12 | AD26: =CX26 -> 17297.42 | AE26: =DB26 -> 20237.982 | BY26: 7171 | BZ26: 9481 | CA26: 7633 | CB26: 7451 | CC26: 7284 | CD26: 9696 | CE26: 8145 | CF26: 8446 | CG26: 9158 | CH26: 11249 | CI26: 9551 | CJ26: 10159 | CK26: 10278 | CL26: 10800 | CM26: =CI26+(CI26*CM27) -> 11174.67 | CN26: =CJ26+(CJ26*CN27) -> 11886.03 | CO26: =CK26+(CK26*CO27) -> 12025.26 | CP26: =CL26+(CL26*CP27) -> 12636 | CQ26: =CM26+(CM26*CQ27) -> 13074.364 | CR26: =CN26+(CN26*CR27) -> 13906.655 | CS26: =CO26+(CO26*CS27) -> 14069.554 | CT26: =CP26+(CP26*CT27) -> 14784.12 | ... DB26: =CX26+(CX26*DB27) -> 20237.982
A27: YOY% | Y27: =Y26/X26-1 -> 0.022676933 | Z27: =Z26/Y26-1 -> 0.16016914 | AA27: =AA26/Z26-1 -> -0.039914659 | AB27: =AB26/AA26-1 -> 0.17 | AC27: =AC26/AB26-1 -> 0.17 | AD27: =AD26/AC26-1 -> 0.17 | AE27: =AE26/AD26-1 -> 0.17 | CC27: =CC26/BY26-1 -> 0.015757914 | CD27: =CD26/BZ26-1 -> 0.022676933 | CE27: =CE26/CA26-1 -> 0.067077165 | CF27: =CF26/CB26-1 -> 0.13353912 | CG27: =CG26/CC26-1 -> 0.25727622 | CH27: =CH26/CD26-1 -> 0.16016914 | CI27: =CI26/CE26-1 -> 0.17262124 | CJ27: =CJ26/CF26-1 -> 0.2028179 | ... CL27: =CL26/CH26-1 -> -0.039914659 | CM27: 0.17 | CN27: 0.17 | CO27: 0.17 | CP27: 0.17 | CQ27: 0.17 | CR27: 0.17 | CS27: 0.17 | CT27: 0.17 | CU27: 0.17 | CV27: 0.17 | CW27: 0.17 | CX27: 0.17 | CY27: 0.17 | CZ27: 0.17 | DA27: 0.17 | DB27: 0.17
A28: No. Of Tests Performed(mn) | X28: =SUM(BW28:BZ28) -> 141.4 | Y28: =SUM(CA28:CD28) -> 147 | Z28: =SUM(CE28:CH28) -> 167.9 | AA28: =SUM(CI28:CL28) -> 208.8 | AB28: =+SUM(CM28:CP28) -> 244.296 | AC28: =+SUM(CQ28:CT28) -> 285.82632 | AD28: =+SUM(CU28:CX28) -> 334.41679 | AE28: =+SUM(CY28:DB28) -> 391.26765 | BW28: 35 | BX28: 36.2 | BY28: 33.9 | BZ28: 36.3 | CA28: 35.086207 | CB28: 38.2 | CC28: 34.2 | CD28: 39.513793 | CE28: 40.7 | CF28: 44 | CG28: 39 | CH28: 44.2 | CI28: 46.9 | CJ28: 53.3 | CK28: 49.6 | CL28: 59 | CM28: =CM29*3*CM26/10^6 -> 54.873 | CN28: =CN29*3*CN26/10^6 -> 62.361 | CO28: =CO29*3*CO26/10^6 -> 58.032 | CP28: =CP29*3*CP26/10^6 -> 69.03 | CQ28: =CQ29*3*CQ26/10^6 -> 64.20141 | CR28: =CR29*3*CR26/10^6 -> 72.96237 | CS28: =CS29*3*CS26/10^6 -> 67.89744 | CT28: =CT29*3*CT26/10^6 -> 80.7651 | ... DB28: =DB29*3*DB26/10^6 -> 110.55935
A29: Test Per Franchisee per month | X29: =X28/X26*1000000/12 -> 1242.8366 | Y29: =Y28/Y26*1000000/12 -> 1263.4076 | Z29: =Z28/Z26*1000000/12 -> 1243.8143 | AA29: =AA28/AA26*1000000/12 -> 1611.1111 | AB29: =AB28/AB26*1000000/12 -> 1611.1111 | AC29: =AC28/AC26*1000000/12 -> 1611.1111 | AD29: =AD28/AD26*1000000/12 -> 1611.1111 | AE29: =AE28/AE26*1000000/12 -> 1611.1111 | BY29: =BY28*1000000/BY26/3 -> 1575.7914 | BZ29: =BZ28*1000000/BZ26/3 -> 1276.2367 | CA29: =CA28*1000000/CA26/3 -> 1532.2157 | CB29: =CB28*1000000/CB26/3 -> 1708.9429 | CC29: =CC28*1000000/CC26/3 -> 1565.0741 | CD29: =CD28*1000000/CD26/3 -> 1358.4225 | CE29: =CE28*1000000/CE26/3 -> 1665.6435 | CF29: =CF28*1000000/CF26/3 -> 1736.5222 | ... CL29: =CL28*1000000/CL26/3 -> 1820.9877 | CM29: =CI29+(CI29*CM30) -> 1636.8269 | CN29: =CJ29+(CJ29*CN30) -> 1748.8598 | CO29: =CK29+(CK29*CO30) -> 1608.6139 | CP29: =CL29+(CL29*CP30) -> 1820.9877 | CQ29: =CM29+(CM29*CQ30) -> 1636.8269 | CR29: =CN29+(CN29*CR30) -> 1748.8598 | CS29: =CO29+(CO29*CS30) -> 1608.6139 | CT29: =CP29+(CP29*CT30) -> 1820.9877 | ... DB29: =CX29+(CX29*DB30) -> 1820.9877
A30: YOY% | Y30: =Y29/X29-1 -> 0.016551686 | Z30: =Z29/Y29-1 -> -0.015508317 | AA30: =AA29/Z29-1 -> 0.29529879 | AB30: =AB29/AA29-1 -> 0 | AC30: =AC29/AB29-1 -> 0 | AD30: =AD29/AC29-1 -> 0 | AE30: =AE29/AD29-1 -> 0 | CC30: =CC29/BY29-1 -> -0.0068011838 | CD30: =CD29/BZ29-1 -> 0.064396986 | CE30: =CE29/CA29-1 -> 0.087081645 | CF30: =CF29/CB29-1 -> 0.016138251 | CG30: =CG29/CC29-1 -> -0.092998931 | CH30: =CH29/CD29-1 -> -0.035833056 | CI30: =CI29/CE29-1 -> -0.017300631 | CJ30: =CJ29/CF29-1 -> 0.0071047616 | ... CL30: =CL29/CH29-1 -> 0.39033643 | CM30: 0 | CN30: 0 | CO30: 0 | CP30: 0 | CQ30: 0 | CR30: 0 | CS30: 0 | CT30: 0 | CU30: 0 | CV30: 0 | CW30: 0 | CX30: 0 | CY30: 0 | CZ30: 0 | DA30: 0 | DB30: 0
A31: No. Of Patients(mn) | X31: =SUM(BW31:BZ31) -> 15.4 | Y31: =SUM(CA31:CD31) -> 15.1 | Z31: =SUM(CE31:CH31) -> 16.7 | BW31: 3.7 | BX31: 4 | BY31: 3.7 | BZ31: 4 | CA31: 3.7614679 | CB31: 4 | CC31: 3.5 | CD31: 3.8385321 | CE31: 4.1 | CF31: 4.4 | CG31: 3.9 | CH31: 4.3 | CI31: 4.6 | CJ31: 5 | CK31: 4.5 | CL31: 5.1
A32: Revenue Per Test (Pathology) | X32: =+X22*10^7/X28/10^6 -> 34.403112 | Y32: =+Y22*10^7/Y28/10^6 -> 35.646259 | Z32: =+Z22*10^7/Z28/10^6 -> 37.74866 | AA32: =+AA22*10^7/AA28/10^6 -> 37.083333 | AB32: =+AB22*10^7/AB28/10^6 -> 37.639583 | AC32: =+AC22*10^7/AC28/10^6 -> 38.392375 | AD32: =+AD22*10^7/AD28/10^6 -> 39.160223 | AE32: =+AE22*10^7/AE28/10^6 -> 39.943427 | BW32: =+BW22*10^7/BW28/10^6 -> 34.068571 | BX32: =+BX22*10^7/BX28/10^6 -> 34.593923 | BY32: =+BY22*10^7/BY28/10^6 -> 34.563422 | BZ32: =+BZ22*10^7/BZ28/10^6 -> 34.385675 | CA32: =+CA22*10^7/CA28/10^6 -> 35.230369 | CB32: =+CB22*10^7/CB28/10^6 -> 35.67801 | CC32: =+CC22*10^7/CC28/10^6 -> 35.935673 | CD32: =+CD22*10^7/CD28/10^6 -> 35.734357 | ... CL32: =+CL22*10^7/CL28/10^6 -> 35.711864 | CM32: =CI32+(CI32*CM33) -> 38.717164 | CN32: =CJ32+(CJ32*CN33) -> 38.505253 | CO32: =CK32+(CK32*CO33) -> 37.34627 | CP32: =CL32+(CL32*CP33) -> 36.247542 | CQ32: =CM32+(CM32*CQ33) -> 39.491507 | CR32: =CN32+(CN32*CR33) -> 39.275358 | CS32: =CO32+(CO32*CS33) -> 38.093196 | CT32: =CP32+(CP32*CT33) -> 36.972493 | ... DB32: =CX32+(CX32*DB33) -> 38.466182
A33: YOY% | Y33: =Y32/X32-1 -> 0.036134719 | Z33: =Z32/Y32-1 -> 0.058979582 | AA33: =AA32/Z32-1 -> -0.017625171 | AB33: =AB32/AA32-1 -> 0.015 | AC33: =AC32/AB32-1 -> 0.02 | AD33: =AD32/AC32-1 -> 0.02 | AE33: =AE32/AD32-1 -> 0.02 | CC33: =CC32/BY32-1 -> 0.039702397 | CD33: =CD32/BZ32-1 -> 0.039222215 | CE33: =CE32/CA32-1 -> 0.0014812996 | CF33: =CF32/CB32-1 -> 0.043423449 | CG33: =CG32/CC32-1 -> 0.088126682 | CH33: =CH32/CD32-1 -> 0.10101019 | CI33: =CI32/CE32-1 -> 0.081128876 | CJ33: =CJ32/CF32-1 -> 0.019043496 | ... CL33: =CL32/CH32-1 -> -0.09231489 | CM33: 0.015 | CN33: 0.015 | CO33: 0.015 | CP33: 0.015 | CQ33: 0.02 | CR33: 0.02 | CS33: 0.02 | CT33: 0.02 | CU33: 0.02 | CV33: 0.02 | CW33: 0.02 | CX33: 0.02 | CY33: 0.02 | CZ33: 0.02 | DA33: 0.02 | DB33: 0.02
A39: Presentation Data (End)
A40: Profit & Loss- Annual (Start)
A41: Gross Revenue | B41: ='Annual Raw'!C6 -> 0 | C41: ='Annual Raw'!D6 -> 0 | D41: ='Annual Raw'!E6 -> 0 | E41: ='Annual Raw'!F6 -> 0 | F41: ='Annual Raw'!G6 -> 0 | G41: ='Annual Raw'!H6 -> 0 | H41: ='Annual Raw'!I6 -> 33.754414 | I41: ='Annual Raw'!J6 -> 44.410636 | ... AA41: ='Annual Raw'!AB6 -> 829.04 | AB41: =+SUM(CM41:CP41) -> 969.11997 | AC41: =+SUM(CQ41:CT41) -> 1146.9551 | AD41: =+SUM(CU41:CX41) -> 1359.1836 | AE41: =+SUM(CY41:DB41) -> 1612.4571 | AI41: ='QTR Raw'!C6+'QTR Raw'!C8 -> 0 | AJ41: ='QTR Raw'!D6+'QTR Raw'!D8 -> 0 | AK41: ='QTR Raw'!E6+'QTR Raw'!E8 -> 0 | AL41: ='QTR Raw'!F6+'QTR Raw'!F8 -> 0 | AM41: ='QTR Raw'!G6+'QTR Raw'!G8 -> 0 | AN41: ='QTR Raw'!H6+'QTR Raw'!H8 -> 0 | AO41: ='QTR Raw'!I6+'QTR Raw'!I8 -> 0 | AP41: ='QTR Raw'!J6+'QTR Raw'!J8 -> 0 | ... CL41: ='QTR Raw'!BF6+'QTR Raw'!BF8 -> 223.95 | CM41: =CM7 -> 224.8527 | CN41: =CN7 -> 252.52261 | CO41: =CO7 -> 229.12788 | CP41: =CP7 -> 262.61678 | CQ41: =CQ7 -> 265.94105 | CR41: =CR7 -> 298.96232 | CS41: =CS7 -> 271.04305 | CT41: =CT7 -> 311.00871 | ... DB41: =DB7 -> 437.67959 | DF41: 219.93226
A42: Less: Exise Duty | B42: ='Annual Raw'!C7+'Annual Raw'!C8+'Annual Raw'!C9 -> 0 | C42: ='Annual Raw'!D7+'Annual Raw'!D8+'Annual Raw'!D9 -> 0 | D42: ='Annual Raw'!E7+'Annual Raw'!E8+'Annual Raw'!E9 -> 0 | E42: ='Annual Raw'!F7+'Annual Raw'!F8+'Annual Raw'!F9 -> 0 | F42: ='Annual Raw'!G7+'Annual Raw'!G8+'Annual Raw'!G9 -> 0 | G42: ='Annual Raw'!H7+'Annual Raw'!H8+'Annual Raw'!H9 -> 0 | H42: ='Annual Raw'!I7+'Annual Raw'!I8+'Annual Raw'!I9 -> 0 | I42: ='Annual Raw'!J7+'Annual Raw'!J8+'Annual Raw'!J9 -> 0 | ... AA42: ='Annual Raw'!AB7+'Annual Raw'!AB8+'Annual Raw'!AB9 -> 0 | AB42: =+SUM(CM42:CP42) -> 0 | AC42: =+SUM(CQ42:CT42) -> 0 | AD42: =+SUM(CU42:CX42) -> 0 | AE42: =+SUM(CY42:DB42) -> 0 | AI42: =+'QTR Raw'!C20+'QTR Raw'!C19+'QTR Raw'!C13+'QTR Raw'!C7 -> 0 | AJ42: =+'QTR Raw'!D20+'QTR Raw'!D19+'QTR Raw'!D13+'QTR Raw'!D7 -> 0 | AK42: =+'QTR Raw'!E20+'QTR Raw'!E19+'QTR Raw'!E13+'QTR Raw'!E7 -> 0 | AL42: =+'QTR Raw'!F20+'QTR Raw'!F19+'QTR Raw'!F13+'QTR Raw'!F7 -> 0 | AM42: =+'QTR Raw'!G20+'QTR Raw'!G19+'QTR Raw'!G13+'QTR Raw'!G7 -> 0 | AN42: =+'QTR Raw'!H20+'QTR Raw'!H19+'QTR Raw'!H13+'QTR Raw'!H7 -> 0 | AO42: =+'QTR Raw'!I20+'QTR Raw'!I19+'QTR Raw'!I13+'QTR Raw'!I7 -> 0 | AP42: =+'QTR Raw'!J20+'QTR Raw'!J19+'QTR Raw'!J13+'QTR Raw'!J7 -> 0 | ... CL42: =+'QTR Raw'!BF20+'QTR Raw'!BF19+'QTR Raw'!BF13+'QTR Raw'!BF7 -> 0 | DF42: 0
A43: Net Revenue | B43: =+B41-B42 -> 0 | C43: =+C41-C42 -> 0 | D43: =+D41-D42 -> 0 | E43: =+E41-E42 -> 0 | F43: =+F41-F42 -> 0 | G43: =+G41-G42 -> 0 | H43: =+H41-H42 -> 33.754414 | I43: =+I41-I42 -> 44.410636 | ... AE43: =+AE41-AE42 -> 1612.4571 | AI43: =+AI41-AI42 -> 0 | AJ43: =+AJ41-AJ42 -> 0 | AK43: =+AK41-AK42 -> 0 | AL43: =+AL41-AL42 -> 0 | AM43: =+AM41-AM42 -> 0 | AN43: =+AN41-AN42 -> 0 | AO43: =+AO41-AO42 -> 0 | AP43: =+AP41-AP42 -> 0 | ... DB43: =+DB41-DB42 -> 437.67959 | DF43: 219.93226
A44: Net Revenue YOY% | C44: =C43/B43-1 -> #DIV/0! | D44: =D43/C43-1 -> #DIV/0! | E44: =E43/D43-1 -> #DIV/0! | F44: =F43/E43-1 -> #DIV/0! | G44: =G43/F43-1 -> #DIV/0! | H44: =H43/G43-1 -> #DIV/0! | I44: =I43/H43-1 -> 0.31569863 | J44: =J43/I43-1 -> 0.019539038 | ... AE44: =AE43/AD43-1 -> 0.18634235 | AM44: =+IF(AI43<0,1-AM43/AI43,AM43/AI43-1) -> #DIV/0! | AN44: =+IF(AJ43<0,1-AN43/AJ43,AN43/AJ43-1) -> #DIV/0! | AO44: =+IF(AK43<0,1-AO43/AK43,AO43/AK43-1) -> #DIV/0! | AP44: =+IF(AL43<0,1-AP43/AL43,AP43/AL43-1) -> #DIV/0! | AQ44: =+IF(AM43<0,1-AQ43/AM43,AQ43/AM43-1) -> #DIV/0! | AR44: =+IF(AN43<0,1-AR43/AN43,AR43/AN43-1) -> #DIV/0! | AS44: =+IF(AO43<0,1-AS43/AO43,AS43/AO43-1) -> #DIV/0! | AT44: =+IF(AP43<0,1-AT43/AP43,AT43/AP43-1) -> #DIV/0! | ... DB44: =+IF(CX43<0,1-DB43/CX43,DB43/CX43-1) -> 0.18689669 | DF44: 0.17510291
A45: Net Revenue QOQ% | AJ45: =+IF(AI43<0,1-AJ43/AI43,AJ43/AI43-1) -> #DIV/0! | AK45: =+IF(AJ43<0,1-AK43/AJ43,AK43/AJ43-1) -> #DIV/0! | AL45: =+IF(AK43<0,1-AL43/AK43,AL43/AK43-1) -> #DIV/0! | AM45: =+IF(AL43<0,1-AM43/AL43,AM43/AL43-1) -> #DIV/0! | AN45: =+IF(AM43<0,1-AN43/AM43,AN43/AM43-1) -> #DIV/0! | AO45: =+IF(AN43<0,1-AO43/AN43,AO43/AN43-1) -> #DIV/0! | AP45: =+IF(AO43<0,1-AP43/AO43,AP43/AO43-1) -> #DIV/0! | AQ45: =+IF(AP43<0,1-AQ43/AP43,AQ43/AP43-1) -> #DIV/0! | ... DB45: =+IF(DA43<0,1-DB43/DA43,DB43/DA43-1) -> 0.14948837 | DF45: 0.12480059
A46: Increase/Decrease in Stock | B46: ='Annual Raw'!C11 -> 0 | C46: ='Annual Raw'!D11 -> 0 | D46: ='Annual Raw'!E11 -> 0 | E46: ='Annual Raw'!F11 -> 0 | F46: ='Annual Raw'!G11 -> 0 | G46: ='Annual Raw'!H11 -> 0 | H46: ='Annual Raw'!I11 -> 0 | I46: ='Annual Raw'!J11 -> 0 | ... AA46: ='Annual Raw'!AB11 -> -0.24 | AB46: =+SUM(CM46:CP46) -> 0 | AC46: =+SUM(CQ46:CT46) -> 0 | AD46: =+SUM(CU46:CX46) -> 0 | AE46: =+SUM(CY46:DB46) -> 0 | AI46: ='QTR Raw'!C10 -> 0 | AJ46: ='QTR Raw'!D10 -> 0 | AK46: ='QTR Raw'!E10 -> 0 | AL46: ='QTR Raw'!F10 -> 0 | AM46: ='QTR Raw'!G10 -> 0 | AN46: ='QTR Raw'!H10 -> 0 | AO46: ='QTR Raw'!I10 -> 0 | AP46: ='QTR Raw'!J10 -> 0 | ... CL46: ='QTR Raw'!BF10 -> -0.51 | DF46: -0.23
A47: Purchase of Finished Goods | B47: 0 | C47: 0 | D47: 0 | E47: 0 | F47: 0 | G47: 0 | H47: 0 | I47: 0 | J47: 0 | K47: 0 | L47: 0 | M47: 0 | N47: 0 | O47: 0 | P47: 0 | Q47: 0 | R47: 0 | S47: 0 | T47: 0 | U47: 0 | V47: 0 | W47: 0 | X47: 0 | Y47: 0 | Z47: 0 | AA47: 0 | AB47: =+SUM(CM47:CP47) -> 0 | AC47: =+SUM(CQ47:CT47) -> 0 | AD47: =+SUM(CU47:CX47) -> 0 | AE47: =+SUM(CY47:DB47) -> 0 | AI47: ='QTR Raw'!C12 -> 0 | AJ47: ='QTR Raw'!D12 -> 0 | AK47: ='QTR Raw'!E12 -> 0 | AL47: ='QTR Raw'!F12 -> 0 | AM47: ='QTR Raw'!G12 -> 0 | AN47: ='QTR Raw'!H12 -> 0 | AO47: ='QTR Raw'!I12 -> 0 | AP47: ='QTR Raw'!J12 -> 0 | ... CL47: ='QTR Raw'!BF12 -> 0.77 | DF47: 1.09
A48: Raw Material Consumed | B48: ='Annual Raw'!C12 -> 0 | C48: ='Annual Raw'!D12 -> 0 | D48: ='Annual Raw'!E12 -> 0 | E48: ='Annual Raw'!F12 -> 0 | F48: ='Annual Raw'!G12 -> 0 | G48: ='Annual Raw'!H12 -> 0 | H48: ='Annual Raw'!I12 -> 11.50973 | I48: ='Annual Raw'!J12 -> 11.1301 | ... AA48: ='Annual Raw'!AB12 -> 219.8 | AB48: =+SUM(CM48:CP48) -> 251.15758 | AC48: =+SUM(CQ48:CT48) -> 296.05356 | AD48: =+SUM(CU48:CX48) -> 350.62471 | AE48: =+SUM(CY48:DB48) -> 415.93349 | AI48: ='QTR Raw'!C11 -> 0 | AJ48: ='QTR Raw'!D11 -> 0 | AK48: ='QTR Raw'!E11 -> 0 | AL48: ='QTR Raw'!F11 -> 0 | AM48: ='QTR Raw'!G11 -> 0 | AN48: ='QTR Raw'!H11 -> 0 | AO48: ='QTR Raw'!I11 -> 0 | AP48: ='QTR Raw'!J11 -> 0 | ... CL48: ='QTR Raw'!BF11 -> 56.42 | CM48: =+CM43-CM49 -> 59.589106 | CN48: =+CN43-CN49 -> 65.458679 | CO48: =+CO43-CO49 -> 58.354313 | CP48: =+CP43-CP49 -> 67.755483 | CQ48: =+CQ43-CQ49 -> 68.939532 | CR48: =+CR43-CR49 -> 77.067192 | CS48: =+CS43-CS49 -> 69.772739 | CT48: =+CT43-CT49 -> 80.274097 | ... DB48: =+DB43-DB49 -> 112.90375 | DF48: 58.902422
A49: Gross Profit | B49: =B43-B46-B48-B47 -> 0 | C49: =C43-C46-C48-C47 -> 0 | D49: =D43-D46-D48-D47 -> 0 | E49: =E43-E46-E48-E47 -> 0 | F49: =F43-F46-F48-F47 -> 0 | G49: =G43-G46-G48-G47 -> 0 | H49: =H43-H46-H48-H47 -> 22.244684 | I49: =I43-I46-I48-I47 -> 33.280536 | ... AE49: =AE43-AE46-AE48-AE47 -> 1196.5236 | AI49: =AI43-AI46-AI48-AI47 -> 0 | AJ49: =AJ43-AJ46-AJ48-AJ47 -> 0 | AK49: =AK43-AK46-AK48-AK47 -> 0 | AL49: =AL43-AL46-AL48-AL47 -> 0 | AM49: =AM43-AM46-AM48-AM47 -> 0 | AN49: =AN43-AN46-AN48-AN47 -> 0 | AO49: =AO43-AO46-AO48-AO47 -> 0 | AP49: =AP43-AP46-AP48-AP47 -> 0 | ... CL49: =CL43-CL46-CL48-CL47 -> 167.27 | CM49: =+CM50*CM43 -> 165.26359 | CN49: =+CN50*CN43 -> 187.06393 | CO49: =+CO50*CO43 -> 170.77356 | CP49: =+CP50*CP43 -> 194.8613 | CQ49: =+CQ50*CQ43 -> 197.00151 | CR49: =+CR50*CR43 -> 221.89513 | CS49: =+CS50*CS43 -> 201.27031 | CT49: =+CT50*CT43 -> 230.73461 | ... DB49: =+DB50*DB43 -> 324.77584 | DF49: 161.02984
...

Sheet QTR Raw
A1: ='Annual Raw'!A1 -> 218764 | B1: X | C1: 201206 | D1: 201209 | E1: 201212 | F1: 201303 | G1: 201306 | H1: 201309 | I1: 201312 | J1: 201403 | K1: 201406 | L1: 201409 | M1: 201412 | N1: 201503 | O1: 201506 | P1: 201509 | Q1: 201512 | R1: 201603 | S1: 201606 | T1: 201609 | U1: 201612 | V1: 201703 | W1: 201706 | X1: 201709 | Y1: 201712 | Z1: 201803 | AA1: 201806 | AB1: 201809 | AC1: 201812 | AD1: 201903 | AE1: 201906 | AF1: 201909 | AG1: 201912 | AH1: 202003 | AI1: 202006 | AJ1: 202009 | AK1: 202012 | AL1: 202103 | AM1: 202106 | AN1: 202109 | AO1: 202112 | AP1: 202203 | AQ1: 202206 | AR1: 202209 | AS1: 202212 | AT1: 202303 | AU1: 202306 | AV1: 202309 | AW1: 202312 | AX1: 202403 | AY1: 202406 | AZ1: 202409 | BA1: 202412 | BB1: 202503 | BC1: 202506 | BD1: 202509 | BE1: 202512 | BF1: 202603 | BG1: 202606 | BH1: 202609 | BI1: 202612 | BJ1: 202703 | BK1: 202706 | BL1: 202709 | BM1: 202712 | BN1: 202803 | BO1: 202806 | BP1: 202809 | BQ1: 202812 | BR1: 202903 | BS1: 202906 | BT1: 202909 | BU1: 202912 | BV1: 203003
A3: Field Description | B3: Field Name
A4: Company Name | B4: CD_COMPNAME | C4: =_xll.EQNXTDZ(A1,B4,C1) -> Thyrocare Technologies Ltd.
A5: Date End | B5: QTR_DATE_END | C5: =_xll.EQNXTDZ($A$1,$B5,C$1,$B$1) -> 0 | D5: =_xll.EQNXTDZ($A$1,$B5,D$1,$B$1) -> 0 | E5: =_xll.EQNXTDZ($A$1,$B5,E$1,$B$1) -> 0 | F5: =_xll.EQNXTDZ($A$1,$B5,F$1,$B$1) -> 0 | G5: =_xll.EQNXTDZ($A$1,$B5,G$1,$B$1) -> 0 | H5: =_xll.EQNXTDZ($A$1,$B5,H$1,$B$1) -> 0 | I5: =_xll.EQNXTDZ($A$1,$B5,I$1,$B$1) -> 0 | J5: =_xll.EQNXTDZ($A$1,$B5,J$1,$B$1) -> 0 | ... BV5: =_xll.EQNXTDZ($A$1,$B5,BV$1,$B$1) -> 0
A6: Gross Sales | B6: QTR_GROSS_SALE | C6: =_xll.EQNXTDZ($A$1,$B6,C$1,$B$1) -> 0 | D6: =_xll.EQNXTDZ($A$1,$B6,D$1,$B$1) -> 0 | E6: =_xll.EQNXTDZ($A$1,$B6,E$1,$B$1) -> 0 | F6: =_xll.EQNXTDZ($A$1,$B6,F$1,$B$1) -> 0 | G6: =_xll.EQNXTDZ($A$1,$B6,G$1,$B$1) -> 0 | H6: =_xll.EQNXTDZ($A$1,$B6,H$1,$B$1) -> 0 | I6: =_xll.EQNXTDZ($A$1,$B6,I$1,$B$1) -> 0 | J6: =_xll.EQNXTDZ($A$1,$B6,J$1,$B$1) -> 0 | ... BV6: =_xll.EQNXTDZ($A$1,$B6,BV$1,$B$1) -> 0
A7: Less: Excise Duty | B7: QTR_EXCISE_DUTY | C7: =_xll.EQNXTDZ($A$1,$B7,C$1,$B$1) -> 0 | D7: =_xll.EQNXTDZ($A$1,$B7,D$1,$B$1) -> 0 | E7: =_xll.EQNXTDZ($A$1,$B7,E$1,$B$1) -> 0 | F7: =_xll.EQNXTDZ($A$1,$B7,F$1,$B$1) -> 0 | G7: =_xll.EQNXTDZ($A$1,$B7,G$1,$B$1) -> 0 | H7: =_xll.EQNXTDZ($A$1,$B7,H$1,$B$1) -> 0 | I7: =_xll.EQNXTDZ($A$1,$B7,I$1,$B$1) -> 0 | J7: =_xll.EQNXTDZ($A$1,$B7,J$1,$B$1) -> 0 | ... BV7: =_xll.EQNXTDZ($A$1,$B7,BV$1,$B$1) -> 0
A8: Other operating income | B8: QTR_JOB_WORKS | C8: =_xll.EQNXTDZ($A$1,$B8,C$1,$B$1) -> 0 | D8: =_xll.EQNXTDZ($A$1,$B8,D$1,$B$1) -> 0 | E8: =_xll.EQNXTDZ($A$1,$B8,E$1,$B$1) -> 0 | F8: =_xll.EQNXTDZ($A$1,$B8,F$1,$B$1) -> 0 | G8: =_xll.EQNXTDZ($A$1,$B8,G$1,$B$1) -> 0 | H8: =_xll.EQNXTDZ($A$1,$B8,H$1,$B$1) -> 0 | I8: =_xll.EQNXTDZ($A$1,$B8,I$1,$B$1) -> 0 | J8: =_xll.EQNXTDZ($A$1,$B8,J$1,$B$1) -> 0 | ... BV8: =_xll.EQNXTDZ($A$1,$B8,BV$1,$B$1) -> 0
A9: Net Sales & Other Operating Income | B9: QTR_NET_SALES | C9: =_xll.EQNXTDZ($A$1,$B9,C$1,$B$1) -> 0 | D9: =_xll.EQNXTDZ($A$1,$B9,D$1,$B$1) -> 0 | E9: =_xll.EQNXTDZ($A$1,$B9,E$1,$B$1) -> 0 | F9: =_xll.EQNXTDZ($A$1,$B9,F$1,$B$1) -> 0 | G9: =_xll.EQNXTDZ($A$1,$B9,G$1,$B$1) -> 0 | H9: =_xll.EQNXTDZ($A$1,$B9,H$1,$B$1) -> 0 | I9: =_xll.EQNXTDZ($A$1,$B9,I$1,$B$1) -> 0 | J9: =_xll.EQNXTDZ($A$1,$B9,J$1,$B$1) -> 0 | ... BV9: =_xll.EQNXTDZ($A$1,$B9,BV$1,$B$1) -> 0
A10: (Increase) / Decrease In Stocks | B10: QTR_INC_DEC_INVENTORY | C10: =_xll.EQNXTDZ($A$1,$B10,C$1,$B$1) -> 0 | D10: =_xll.EQNXTDZ($A$1,$B10,D$1,$B$1) -> 0 | E10: =_xll.EQNXTDZ($A$1,$B10,E$1,$B$1) -> 0 | F10: =_xll.EQNXTDZ($A$1,$B10,F$1,$B$1) -> 0 | G10: =_xll.EQNXTDZ($A$1,$B10,G$1,$B$1) -> 0 | H10: =_xll.EQNXTDZ($A$1,$B10,H$1,$B$1) -> 0 | I10: =_xll.EQNXTDZ($A$1,$B10,I$1,$B$1) -> 0 | J10: =_xll.EQNXTDZ($A$1,$B10,J$1,$B$1) -> 0 | ... BV10: =_xll.EQNXTDZ($A$1,$B10,BV$1,$B$1) -> 0
A11: Cost of Services & Raw Materials | B11: QTR_RAW_MATERIAL_COST | C11: =_xll.EQNXTDZ($A$1,$B11,C$1,$B$1) -> 0 | D11: =_xll.EQNXTDZ($A$1,$B11,D$1,$B$1) -> 0 | E11: =_xll.EQNXTDZ($A$1,$B11,E$1,$B$1) -> 0 | F11: =_xll.EQNXTDZ($A$1,$B11,F$1,$B$1) -> 0 | G11: =_xll.EQNXTDZ($A$1,$B11,G$1,$B$1) -> 0 | H11: =_xll.EQNXTDZ($A$1,$B11,H$1,$B$1) -> 0 | I11: =_xll.EQNXTDZ($A$1,$B11,I$1,$B$1) -> 0 | J11: =_xll.EQNXTDZ($A$1,$B11,J$1,$B$1) -> 0 | ... BV11: =_xll.EQNXTDZ($A$1,$B11,BV$1,$B$1) -> 0
A12: Purchase of Finished Goods | B12: QTR_PURCHASE_FIN_GOOD | C12: =_xll.EQNXTDZ($A$1,$B12,C$1,$B$1) -> 0 | D12: =_xll.EQNXTDZ($A$1,$B12,D$1,$B$1) -> 0 | E12: =_xll.EQNXTDZ($A$1,$B12,E$1,$B$1) -> 0 | F12: =_xll.EQNXTDZ($A$1,$B12,F$1,$B$1) -> 0 | G12: =_xll.EQNXTDZ($A$1,$B12,G$1,$B$1) -> 0 | H12: =_xll.EQNXTDZ($A$1,$B12,H$1,$B$1) -> 0 | I12: =_xll.EQNXTDZ($A$1,$B12,I$1,$B$1) -> 0 | J12: =_xll.EQNXTDZ($A$1,$B12,J$1,$B$1) -> 0 | ... BV12: =_xll.EQNXTDZ($A$1,$B12,BV$1,$B$1) -> 0
A13: Excise Duty | B13: QTR_EXCISE | C13: =_xll.EQNXTDZ($A$1,$B13,C$1,$B$1) -> 0 | D13: =_xll.EQNXTDZ($A$1,$B13,D$1,$B$1) -> 0 | E13: =_xll.EQNXTDZ($A$1,$B13,E$1,$B$1) -> 0 | F13: =_xll.EQNXTDZ($A$1,$B13,F$1,$B$1) -> 0 | G13: =_xll.EQNXTDZ($A$1,$B13,G$1,$B$1) -> 0 | H13: =_xll.EQNXTDZ($A$1,$B13,H$1,$B$1) -> 0 | I13: =_xll.EQNXTDZ($A$1,$B13,I$1,$B$1) -> 0 | J13: =_xll.EQNXTDZ($A$1,$B13,J$1,$B$1) -> 0 | ... BV13: =_xll.EQNXTDZ($A$1,$B13,BV$1,$B$1) -> 0
A14: Operating & Manufacturing Expenses | B14: QTR_MFG_EXPS | C14: =_xll.EQNXTDZ($A$1,$B14,C$1,$B$1) -> 0 | D14: =_xll.EQNXTDZ($A$1,$B14,D$1,$B$1) -> 0 | E14: =_xll.EQNXTDZ($A$1,$B14,E$1,$B$1) -> 0 | F14: =_xll.EQNXTDZ($A$1,$B14,F$1,$B$1) -> 0 | G14: =_xll.EQNXTDZ($A$1,$B14,G$1,$B$1) -> 0 | H14: =_xll.EQNXTDZ($A$1,$B14,H$1,$B$1) -> 0 | I14: =_xll.EQNXTDZ($A$1,$B14,I$1,$B$1) -> 0 | J14: =_xll.EQNXTDZ($A$1,$B14,J$1,$B$1) -> 0 | ... BV14: =_xll.EQNXTDZ($A$1,$B14,BV$1,$B$1) -> 0
A15: Electricity Power & Fuel Cost | B15: QTR_ELECTRICITY_POWER_FUEL | C15: =_xll.EQNXTDZ($A$1,$B15,C$1,$B$1) -> 0 | D15: =_xll.EQNXTDZ($A$1,$B15,D$1,$B$1) -> 0 | E15: =_xll.EQNXTDZ($A$1,$B15,E$1,$B$1) -> 0 | F15: =_xll.EQNXTDZ($A$1,$B15,F$1,$B$1) -> 0 | G15: =_xll.EQNXTDZ($A$1,$B15,G$1,$B$1) -> 0 | H15: =_xll.EQNXTDZ($A$1,$B15,H$1,$B$1) -> 0 | I15: =_xll.EQNXTDZ($A$1,$B15,I$1,$B$1) -> 0 | J15: =_xll.EQNXTDZ($A$1,$B15,J$1,$B$1) -> 0 | ... BV15: =_xll.EQNXTDZ($A$1,$B15,BV$1,$B$1) -> 0
A16: Employee Cost | B16: QTR_EXPLOYEE_COST | C16: =_xll.EQNXTDZ($A$1,$B16,C$1,$B$1) -> 0 | D16: =_xll.EQNXTDZ($A$1,$B16,D$1,$B$1) -> 0 | E16: =_xll.EQNXTDZ($A$1,$B16,E$1,$B$1) -> 0 | F16: =_xll.EQNXTDZ($A$1,$B16,F$1,$B$1) -> 0 | G16: =_xll.EQNXTDZ($A$1,$B16,G$1,$B$1) -> 0 | H16: =_xll.EQNXTDZ($A$1,$B16,H$1,$B$1) -> 0 | I16: =_xll.EQNXTDZ($A$1,$B16,I$1,$B$1) -> 0 | J16: =_xll.EQNXTDZ($A$1,$B16,J$1,$B$1) -> 0 | ... BV16: =_xll.EQNXTDZ($A$1,$B16,BV$1,$B$1) -> 0
... A42: Consolidated PAT(after extra items) | B42: QTR_CONS_PAT_EXITM | C42: =_xll.EQNXTDZ($A$1,$B42,C$1,$B$1) -> 0 | D42: =_xll.EQNXTDZ($A$1,$B42,D$1,$B$1) -> 0 | E42: =_xll.EQNXTDZ($A$1,$B42,E$1,$B$1) -> 0 | F42: =_xll.EQNXTDZ($A$1,$B42,F$1,$B$1) -> 0 | G42: =_xll.EQNXTDZ($A$1,$B42,G$1,$B$1) -> 0 | H42: =_xll.EQNXTDZ($A$1,$B42,H$1,$B$1) -> 0 | I42: =_xll.EQNXTDZ($A$1,$B42,I$1,$B$1) -> 0 | J42: =_xll.EQNXTDZ($A$1,$B42,J$1,$B$1) -> 0 | ... BV42: =_xll.EQNXTDZ($A$1,$B42,BV$1,$B$1) -> 0
A44: Field Description | B44: Field Name
A45: Equity Capital | B45: QTR_EQUITY_CAP | C45: =_xll.EQNXTDZ($A$1,$B45,C$1,$B$1) -> 0 | D45: =_xll.EQNXTDZ($A$1,$B45,D$1,$B$1) -> 0 | E45: =_xll.EQNXTDZ($A$1,$B45,E$1,$B$1) -> 0 | F45: =_xll.EQNXTDZ($A$1,$B45,F$1,$B$1) -> 0 | G45: =_xll.EQNXTDZ($A$1,$B45,G$1,$B$1) -> 0 | H45: =_xll.EQNXTDZ($A$1,$B45,H$1,$B$1) -> 0 | I45: =_xll.EQNXTDZ($A$1,$B45,I$1,$B$1) -> 0 | J45: =_xll.EQNXTDZ($A$1,$B45,J$1,$B$1) -> 0 | ... BV45: =_xll.EQNXTDZ($A$1,$B45,BV$1,$B$1) -> 0
A46: Face Value | B46: QTR_FV | C46: =_xll.EQNXTDZ($A$1,$B46,C$1,$B$1) -> 0 | D46: =_xll.EQNXTDZ($A$1,$B46,D$1,$B$1) -> 0 | E46: =_xll.EQNXTDZ($A$1,$B46,E$1,$B$1) -> 0 | F46: =_xll.EQNXTDZ($A$1,$B46,F$1,$B$1) -> 0 | G46: =_xll.EQNXTDZ($A$1,$B46,G$1,$B$1) -> 0 | H46: =_xll.EQNXTDZ($A$1,$B46,H$1,$B$1) -> 0 | I46: =_xll.EQNXTDZ($A$1,$B46,I$1,$B$1) -> 0 | J46: =_xll.EQNXTDZ($A$1,$B46,J$1,$B$1) -> 0 | ... BV46: =_xll.EQNXTDZ($A$1,$B46,BV$1,$B$1) -> 0
A47: Month End | B47: BMONTH_MONTHEND | C47: =_xll.EQNXTDZ($A$1,$B47,C$5) -> 0 | D47: =_xll.EQNXTDZ($A$1,$B47,D$5) -> 0 | E47: =_xll.EQNXTDZ($A$1,$B47,E$5) -> 0 | F47: =_xll.EQNXTDZ($A$1,$B47,F$5) -> 0 | G47: =_xll.EQNXTDZ($A$1,$B47,G$5) -> 0 | H47: =_xll.EQNXTDZ($A$1,$B47,H$5) -> 0 | I47: =_xll.EQNXTDZ($A$1,$B47,I$5) -> 0 | J47: =_xll.EQNXTDZ($A$1,$B47,J$5) -> 0 | ... BV47: =_xll.EQNXTDZ($A$1,$B47,BV$5) -> 0
A48: Close | B48: BMONTH_CLOSE | C48: =_xll.EQNXTDZ($A$1,$B48,C$5) -> 0 | D48: =_xll.EQNXTDZ($A$1,$B48,D$5) -> 0 | E48: =_xll.EQNXTDZ($A$1,$B48,E$5) -> 0 | F48: =_xll.EQNXTDZ($A$1,$B48,F$5) -> 0 | G48: =_xll.EQNXTDZ($A$1,$B48,G$5) -> 0 | H48: =_xll.EQNXTDZ($A$1,$B48,H$5) -> 0 | I48: =_xll.EQNXTDZ($A$1,$B48,I$5) -> 0 | J48: =_xll.EQNXTDZ($A$1,$B48,J$5) -> 0 | ... BV48: =_xll.EQNXTDZ($A$1,$B48,BV$5) -> 0
A49: Total of Promoter and Promoter Group | B49: SHP_TPFTOTALPROMOTER | C49: =_xll.EQNXTDZ($A$1,$B49,C$5) -> 0 | D49: =_xll.EQNXTDZ($A$1,$B49,D$5) -> 0 | E49: =_xll.EQNXTDZ($A$1,$B49,E$5) -> 0 | F49: =_xll.EQNXTDZ($A$1,$B49,F$5) -> 0 | G49: =_xll.EQNXTDZ($A$1,$B49,G$5) -> 0 | H49: =_xll.EQNXTDZ($A$1,$B49,H$5) -> 0 | I49: =_xll.EQNXTDZ($A$1,$B49,I$5) -> 0 | J49: =_xll.EQNXTDZ($A$1,$B49,J$5) -> 0 | ... BV49: =_xll.EQNXTDZ($A$1,$B49,BV$5) -> 0
A50: Total of Promoter and Promoter Group Pledged | B50: SHP_PSHFTOTALPROMOTER | C50: =_xll.EQNXTDZ($A$1,$B50,C$5) -> 0 | D50: =_xll.EQNXTDZ($A$1,$B50,D$5) -> 0 | E50: =_xll.EQNXTDZ($A$1,$B50,E$5) -> 0 | F50: =_xll.EQNXTDZ($A$1,$B50,F$5) -> 0 | G50: =_xll.EQNXTDZ($A$1,$B50,G$5) -> 0 | H50: =_xll.EQNXTDZ($A$1,$B50,H$5) -> 0 | I50: =_xll.EQNXTDZ($A$1,$B50,I$5) -> 0 | J50: =_xll.EQNXTDZ($A$1,$B50,J$5) -> 0 | ... BV50: =_xll.EQNXTDZ($A$1,$B50,BV$5) -> 0
A54: Field Description | B54: Field Name | C54: =_xll.EQNXTDZ($A$1,$B54,C$5) -> 0 | D54: =_xll.EQNXTDZ($A$1,$B54,D$5) -> 0 | E54: =_xll.EQNXTDZ($A$1,$B54,E$5) -> 0 | F54: =_xll.EQNXTDZ($A$1,$B54,F$5) -> 0 | G54: =_xll.EQNXTDZ($A$1,$B54,G$5) -> 0 | H54: =_xll.EQNXTDZ($A$1,$B54,H$5) -> 0 | I54: =_xll.EQNXTDZ($A$1,$B54,I$5) -> 0 | J54: =_xll.EQNXTDZ($A$1,$B54,J$5) -> 0 | ... BV54: =_xll.EQNXTDZ($A$1,$B54,BV$5) -> 0
A55: Year End | B55: QTRB_DATE_END | C55: =_xll.EQNXTDZ($A$1,$B55,C$5,$B$1) -> 0 | D55: =_xll.EQNXTDZ($A$1,$B55,D$5,$B$1) -> 0 | E55: =_xll.EQNXTDZ($A$1,$B55,E$5,$B$1) -> 0 | F55: =_xll.EQNXTDZ($A$1,$B55,F$5,$B$1) -> 0 | G55: =_xll.EQNXTDZ($A$1,$B55,G$5,$B$1) -> 0 | H55: =_xll.EQNXTDZ($A$1,$B55,H$5,$B$1) -> 0 | I55: =_xll.EQNXTDZ($A$1,$B55,I$5,$B$1) -> 0 | J55: =_xll.EQNXTDZ($A$1,$B55,J$5,$B$1) -> 0 | ... BV55: =_xll.EQNXTDZ($A$1,$B55,BV$5,$B$1) -> 0
A56: Share Capital | B56: QTRB_SHARE_CAPITAL | C56: =_xll.EQNXTDZ($A$1,$B56,C$5,$B$1) -> 0 | D56: =_xll.EQNXTDZ($A$1,$B56,D$5,$B$1) -> 0 | E56: =_xll.EQNXTDZ($A$1,$B56,E$5,$B$1) -> 0 | F56: =_xll.EQNXTDZ($A$1,$B56,F$5,$B$1) -> 0 | G56: =_xll.EQNXTDZ($A$1,$B56,G$5,$B$1) -> 0 | H56: =_xll.EQNXTDZ($A$1,$B56,H$5,$B$1) -> 0 | I56: =_xll.EQNXTDZ($A$1,$B56,I$5,$B$1) -> 0 | J56: =_xll.EQNXTDZ($A$1,$B56,J$5,$B$1) -> 0 | ... BV56: =_xll.EQNXTDZ($A$1,$B56,BV$5,$B$1) -> 0
A57: Share Warrants & outstandings | B57: QTRB_SHAREWARNDOUT | C57: =_xll.EQNXTDZ($A$1,$B57,C$5,$B$1) -> 0 | D57: =_xll.EQNXTDZ($A$1,$B57,D$5,$B$1) -> 0 | E57: =_xll.EQNXTDZ($A$1,$B57,E$5,$B$1) -> 0 | F57: =_xll.EQNXTDZ($A$1,$B57,F$5,$B$1) -> 0 | G57: =_xll.EQNXTDZ($A$1,$B57,G$5,$B$1) -> 0 | H57: =_xll.EQNXTDZ($A$1,$B57,H$5,$B$1) -> 0 | I57: =_xll.EQNXTDZ($A$1,$B57,I$5,$B$1) -> 0 | J57: =_xll.EQNXTDZ($A$1,$B57,J$5,$B$1) -> 0 | ... BV57: =_xll.EQNXTDZ($A$1,$B57,BV$5,$B$1) -> 0
A58: Reserves & Surplus | B58: QTRB_RESERVE | C58: =_xll.EQNXTDZ($A$1,$B58,C$5,$B$1) -> 0 | D58: =_xll.EQNXTDZ($A$1,$B58,D$5,$B$1) -> 0 | E58: =_xll.EQNXTDZ($A$1,$B58,E$5,$B$1) -> 0 | F58: =_xll.EQNXTDZ($A$1,$B58,F$5,$B$1) -> 0 | G58: =_xll.EQNXTDZ($A$1,$B58,G$5,$B$1) -> 0 | H58: =_xll.EQNXTDZ($A$1,$B58,H$5,$B$1) -> 0 | I58: =_xll.EQNXTDZ($A$1,$B58,I$5,$B$1) -> 0 | J58: =_xll.EQNXTDZ($A$1,$B58,J$5,$B$1) -> 0 | ... BV58: =_xll.EQNXTDZ($A$1,$B58,BV$5,$B$1) -> 0
A59: Shareholder's Funds | B59: QTRB_SHAREHODERS_FUNDS | C59: =_xll.EQNXTDZ($A$1,$B59,C$5,$B$1) -> 0 | D59: =_xll.EQNXTDZ($A$1,$B59,D$5,$B$1) -> 0 | E59: =_xll.EQNXTDZ($A$1,$B59,E$5,$B$1) -> 0 | F59: =_xll.EQNXTDZ($A$1,$B59,F$5,$B$1) -> 0 | G59: =_xll.EQNXTDZ($A$1,$B59,G$5,$B$1) -> 0 | H59: =_xll.EQNXTDZ($A$1,$B59,H$5,$B$1) -> 0 | I59: =_xll.EQNXTDZ($A$1,$B59,I$5,$B$1) -> 0 | J59: =_xll.EQNXTDZ($A$1,$B59,J$5,$B$1) -> 0 | ... BV59: =_xll.EQNXTDZ($A$1,$B59,BV$5,$B$1) -> 0
A60: Minority Interest | B60: QTRB_MINORITY_INTEREST_BS | C60: =_xll.EQNXTDZ($A$1,$B60,C$5,$B$1) -> 0 | D60: =_xll.EQNXTDZ($A$1,$B60,D$5,$B$1) -> 0 | E60: =_xll.EQNXTDZ($A$1,$B60,E$5,$B$1) -> 0 | F60: =_xll.EQNXTDZ($A$1,$B60,F$5,$B$1) -> 0 | G60: =_xll.EQNXTDZ($A$1,$B60,G$5,$B$1) -> 0 | H60: =_xll.EQNXTDZ($A$1,$B60,H$5,$B$1) -> 0 | I60: =_xll.EQNXTDZ($A$1,$B60,I$5,$B$1) -> 0 | J60: =_xll.EQNXTDZ($A$1,$B60,J$5,$B$1) -> 0 | ... BV60: =_xll.EQNXTDZ($A$1,$B60,BV$5,$B$1) -> 0
A61: Long Term Borrowings | B61: QTRB_TOTAL_DEBTS | C61: =_xll.EQNXTDZ($A$1,$B61,C$5,$B$1) -> 0 | D61: =_xll.EQNXTDZ($A$1,$B61,D$5,$B$1) -> 0 | E61: =_xll.EQNXTDZ($A$1,$B61,E$5,$B$1) -> 0 | F61: =_xll.EQNXTDZ($A$1,$B61,F$5,$B$1) -> 0 | G61: =_xll.EQNXTDZ($A$1,$B61,G$5,$B$1) -> 0 | H61: =_xll.EQNXTDZ($A$1,$B61,H$5,$B$1) -> 0 | I61: =_xll.EQNXTDZ($A$1,$B61,I$5,$B$1) -> 0 | J61: =_xll.EQNXTDZ($A$1,$B61,J$5,$B$1) -> 0 | ... BV61: =_xll.EQNXTDZ($A$1,$B61,BV$5,$B$1) -> 0
A62: Secured Loans | B62: QTRB_SECURED_LOANS | C62: =_xll.EQNXTDZ($A$1,$B62,C$5,$B$1) -> 0 | D62: =_xll.EQNXTDZ($A$1,$B62,D$5,$B$1) -> 0 | E62: =_xll.EQNXTDZ($A$1,$B62,E$5,$B$1) -> 0 | F62: =_xll.EQNXTDZ($A$1,$B62,F$5,$B$1) -> 0 | G62: =_xll.EQNXTDZ($A$1,$B62,G$5,$B$1) -> 0 | H62: =_xll.EQNXTDZ($A$1,$B62,H$5,$B$1) -> 0 | I62: =_xll.EQNXTDZ($A$1,$B62,I$5,$B$1) -> 0 | J62: =_xll.EQNXTDZ($A$1,$B62,J$5,$B$1) -> 0 | ... BV62: =_xll.EQNXTDZ($A$1,$B62,BV$5,$B$1) -> 0
A63: Unsecured Loans | B63: QTRB_UNSECURED_LOANS_NF | C63: =_xll.EQNXTDZ($A$1,$B63,C$5,$B$1) -> 0 | D63: =_xll.EQNXTDZ($A$1,$B63,D$5,$B$1) -> 0 | E63: =_xll.EQNXTDZ($A$1,$B63,E$5,$B$1) -> 0 | F63: =_xll.EQNXTDZ($A$1,$B63,F$5,$B$1) -> 0 | G63: =_xll.EQNXTDZ($A$1,$B63,G$5,$B$1) -> 0 | H63: =_xll.EQNXTDZ($A$1,$B63,H$5,$B$1) -> 0 | I63: =_xll.EQNXTDZ($A$1,$B63,I$5,$B$1) -> 0 | J63: =_xll.EQNXTDZ($A$1,$B63,J$5,$B$1) -> 0 | ... BV63: =_xll.EQNXTDZ($A$1,$B63,BV$5,$B$1) -> 0
A64: Other Long Term Liabilities | B64: QTRB_OTHER_LT_LIABILITIES | C64: =_xll.EQNXTDZ($A$1,$B64,C$5,$B$1) -> 0 | D64: =_xll.EQNXTDZ($A$1,$B64,D$5,$B$1) -> 0 | E64: =_xll.EQNXTDZ($A$1,$B64,E$5,$B$1) -> 0 | F64: =_xll.EQNXTDZ($A$1,$B64,F$5,$B$1) -> 0 | G64: =_xll.EQNXTDZ($A$1,$B64,G$5,$B$1) -> 0 | H64: =_xll.EQNXTDZ($A$1,$B64,H$5,$B$1) -> 0 | I64: =_xll.EQNXTDZ($A$1,$B64,I$5,$B$1) -> 0 | J64: =_xll.EQNXTDZ($A$1,$B64,J$5,$B$1) -> 0 | ... BV64: =_xll.EQNXTDZ($A$1,$B64,BV$5,$B$1) -> 0
A65: Long Term Trade Payables | B65: QTRB_LT_TRADE_PAYABLE | C65: =_xll.EQNXTDZ($A$1,$B65,C$5,$B$1) -> 0 | D65: =_xll.EQNXTDZ($A$1,$B65,D$5,$B$1) -> 0 | E65: =_xll.EQNXTDZ($A$1,$B65,E$5,$B$1) -> 0 | F65: =_xll.EQNXTDZ($A$1,$B65,F$5,$B$1) -> 0 | G65: =_xll.EQNXTDZ($A$1,$B65,G$5,$B$1) -> 0 | H65: =_xll.EQNXTDZ($A$1,$B65,H$5,$B$1) -> 0 | I65: =_xll.EQNXTDZ($A$1,$B65,I$5,$B$1) -> 0 | J65: =_xll.EQNXTDZ($A$1,$B65,J$5,$B$1) -> 0 | ... BV65: =_xll.EQNXTDZ($A$1,$B65,BV$5,$B$1) -> 0
A66: Lont Term Provisions | B66: QTRB_LT_PROVISIONS | C66: =_xll.EQNXTDZ($A$1,$B66,C$5,$B$1) -> 0 | D66: =_xll.EQNXTDZ($A$1,$B66,D$5,$B$1) -> 0 | E66: =_xll.EQNXTDZ($A$1,$B66,E$5,$B$1) -> 0 | F66: =_xll.EQNXTDZ($A$1,$B66,F$5,$B$1) -> 0 | G66: =_xll.EQNXTDZ($A$1,$B66,G$5,$B$1) -> 0 | H66: =_xll.EQNXTDZ($A$1,$B66,H$5,$B$1) -> 0 | I66: =_xll.EQNXTDZ($A$1,$B66,I$5,$B$1) -> 0 | J66: =_xll.EQNXTDZ($A$1,$B66,J$5,$B$1) -> 0 | ... BV66: =_xll.EQNXTDZ($A$1,$B66,BV$5,$B$1) -> 0
... A97: Total Assets | B97: QTRB_TOTAL_APPLICATIONS | C97: =_xll.EQNXTDZ($A$1,$B97,C$5,$B$1) -> 0 | D97: =_xll.EQNXTDZ($A$1,$B97,D$5,$B$1) -> 0 | E97: =_xll.EQNXTDZ($A$1,$B97,E$5,$B$1) -> 0 | F97: =_xll.EQNXTDZ($A$1,$B97,F$5,$B$1) -> 0 | G97: =_xll.EQNXTDZ($A$1,$B97,G$5,$B$1) -> 0 | H97: =_xll.EQNXTDZ($A$1,$B97,H$5,$B$1) -> 0 | I97: =_xll.EQNXTDZ($A$1,$B97,I$5,$B$1) -> 0 | J97: =_xll.EQNXTDZ($A$1,$B97,J$5,$B$1) -> 0 | ... BV97: =_xll.EQNXTDZ($A$1,$B97,BV$5,$B$1) -> 0

Sheet Annual Raw
A1: 218764 | B1: X | C1: 200103 | D1: 200203 | E1: 200303 | F1: 200403 | G1: 200503 | H1: 200603 | I1: 200703 | J1: 200803 | K1: 200903 | L1: 201003 | M1: 201103 | N1: 201203 | O1: 201303 | P1: 201403 | Q1: 201503 | R1: 201603 | S1: 201703 | T1: 201803 | U1: 201903 | V1: 202003 | W1: 202103 | X1: 202203 | Y1: 202303 | Z1: 202403 | AA1: 202503 | AB1: 202603 | AC1: 202703 | AD1: 202803 | AE1: 202903 | AF1: 203003
A3: Field Description | B3: Field Name
A4: Company Name | B4: CD_COMPNAME | C4: =_xll.EQNXTDZ(A1,B4,"L") -> Thyrocare Technologies Ltd.
A5: Year End | B5: PL_YEAR_END | C5: =_xll.EQNXTDZ($A$1,$B5,C$1,$B$1) -> 0 | D5: =_xll.EQNXTDZ($A$1,$B5,D$1,$B$1) -> 0 | E5: =_xll.EQNXTDZ($A$1,$B5,E$1,$B$1) -> 0 | F5: =_xll.EQNXTDZ($A$1,$B5,F$1,$B$1) -> 0 | G5: =_xll.EQNXTDZ($A$1,$B5,G$1,$B$1) -> 0 | H5: =_xll.EQNXTDZ($A$1,$B5,H$1,$B$1) -> 0 | I5: =_xll.EQNXTDZ($A$1,$B5,I$1,$B$1) -> 200703 | J5: =_xll.EQNXTDZ($A$1,$B5,J$1,$B$1) -> 200803 | ... AF5: =_xll.EQNXTDZ($A$1,$B5,AF$1,$B$1) -> 0
A6: Sales Turnover | B6: PL_TOTAL_GROSS_SALES | C6: =_xll.EQNXTDZ($A$1,$B6,C$1,$B$1) -> 0 | D6: =_xll.EQNXTDZ($A$1,$B6,D$1,$B$1) -> 0 | E6: =_xll.EQNXTDZ($A$1,$B6,E$1,$B$1) -> 0 | F6: =_xll.EQNXTDZ($A$1,$B6,F$1,$B$1) -> 0 | G6: =_xll.EQNXTDZ($A$1,$B6,G$1,$B$1) -> 0 | H6: =_xll.EQNXTDZ($A$1,$B6,H$1,$B$1) -> 0 | I6: =_xll.EQNXTDZ($A$1,$B6,I$1,$B$1) -> 33.754414 | J6: =_xll.EQNXTDZ($A$1,$B6,J$1,$B$1) -> 44.410636 | ... AF6: =_xll.EQNXTDZ($A$1,$B6,AF$1,$B$1) -> 0
A7: Less: Inter divisional transfers | B7: PL_INTER_DIV_TRF | C7: =_xll.EQNXTDZ($A$1,$B7,C$1,$B$1) -> 0 | D7: =_xll.EQNXTDZ($A$1,$B7,D$1,$B$1) -> 0 | E7: =_xll.EQNXTDZ($A$1,$B7,E$1,$B$1) -> 0 | F7: =_xll.EQNXTDZ($A$1,$B7,F$1,$B$1) -> 0 | G7: =_xll.EQNXTDZ($A$1,$B7,G$1,$B$1) -> 0 | H7: =_xll.EQNXTDZ($A$1,$B7,H$1,$B$1) -> 0 | I7: =_xll.EQNXTDZ($A$1,$B7,I$1,$B$1) -> 0 | J7: =_xll.EQNXTDZ($A$1,$B7,J$1,$B$1) -> 0 | ... AF7: =_xll.EQNXTDZ($A$1,$B7,AF$1,$B$1) -> 0
A8: Less: Sales Returns | B8: PL_SALES_RETURN | C8: =_xll.EQNXTDZ($A$1,$B8,C$1,$B$1) -> 0 | D8: =_xll.EQNXTDZ($A$1,$B8,D$1,$B$1) -> 0 | E8: =_xll.EQNXTDZ($A$1,$B8,E$1,$B$1) -> 0 | F8: =_xll.EQNXTDZ($A$1,$B8,F$1,$B$1) -> 0 | G8: =_xll.EQNXTDZ($A$1,$B8,G$1,$B$1) -> 0 | H8: =_xll.EQNXTDZ($A$1,$B8,H$1,$B$1) -> 0 | I8: =_xll.EQNXTDZ($A$1,$B8,I$1,$B$1) -> 0 | J8: =_xll.EQNXTDZ($A$1,$B8,J$1,$B$1) -> 0 | ... AF8: =_xll.EQNXTDZ($A$1,$B8,AF$1,$B$1) -> 0
A9: Less: Excise | B9: PL_EXCISE | C9: =_xll.EQNXTDZ($A$1,$B9,C$1,$B$1) -> 0 | D9: =_xll.EQNXTDZ($A$1,$B9,D$1,$B$1) -> 0 | E9: =_xll.EQNXTDZ($A$1,$B9,E$1,$B$1) -> 0 | F9: =_xll.EQNXTDZ($A$1,$B9,F$1,$B$1) -> 0 | G9: =_xll.EQNXTDZ($A$1,$B9,G$1,$B$1) -> 0 | H9: =_xll.EQNXTDZ($A$1,$B9,H$1,$B$1) -> 0 | I9: =_xll.EQNXTDZ($A$1,$B9,I$1,$B$1) -> 0 | J9: =_xll.EQNXTDZ($A$1,$B9,J$1,$B$1) -> 0 | ... AF9: =_xll.EQNXTDZ($A$1,$B9,AF$1,$B$1) -> 0
A10: Net Sales | B10: PL_NET_SALES | C10: =_xll.EQNXTDZ($A$1,$B10,C$1,$B$1) -> 0 | D10: =_xll.EQNXTDZ($A$1,$B10,D$1,$B$1) -> 0 | E10: =_xll.EQNXTDZ($A$1,$B10,E$1,$B$1) -> 0 | F10: =_xll.EQNXTDZ($A$1,$B10,F$1,$B$1) -> 0 | G10: =_xll.EQNXTDZ($A$1,$B10,G$1,$B$1) -> 0 | H10: =_xll.EQNXTDZ($A$1,$B10,H$1,$B$1) -> 0 | I10: =_xll.EQNXTDZ($A$1,$B10,I$1,$B$1) -> 33.754414 | J10: =_xll.EQNXTDZ($A$1,$B10,J$1,$B$1) -> 44.410636 | ... AF10: =_xll.EQNXTDZ($A$1,$B10,AF$1,$B$1) -> 0
A11: Increase/Decrease in Stock | B11: PL_INC_DEC_INVENTORY | C11: =_xll.EQNXTDZ($A$1,$B11,C$1,$B$1) -> 0 | D11: =_xll.EQNXTDZ($A$1,$B11,D$1,$B$1) -> 0 | E11: =_xll.EQNXTDZ($A$1,$B11,E$1,$B$1) -> 0 | F11: =_xll.EQNXTDZ($A$1,$B11,F$1,$B$1) -> 0 | G11: =_xll.EQNXTDZ($A$1,$B11,G$1,$B$1) -> 0 | H11: =_xll.EQNXTDZ($A$1,$B11,H$1,$B$1) -> 0 | I11: =_xll.EQNXTDZ($A$1,$B11,I$1,$B$1) -> 0 | J11: =_xll.EQNXTDZ($A$1,$B11,J$1,$B$1) -> 0 | ... AF11: =_xll.EQNXTDZ($A$1,$B11,AF$1,$B$1) -> 0
A12: Raw Material Consumed | B12: PL_RAW_MATRS_CONSUMED | C12: =_xll.EQNXTDZ($A$1,$B12,C$1,$B$1) -> 0 | D12: =_xll.EQNXTDZ($A$1,$B12,D$1,$B$1) -> 0 | E12: =_xll.EQNXTDZ($A$1,$B12,E$1,$B$1) -> 0 | F12: =_xll.EQNXTDZ($A$1,$B12,F$1,$B$1) -> 0 | G12: =_xll.EQNXTDZ($A$1,$B12,G$1,$B$1) -> 0 | H12: =_xll.EQNXTDZ($A$1,$B12,H$1,$B$1) -> 0 | I12: =_xll.EQNXTDZ($A$1,$B12,I$1,$B$1) -> 11.50973 | J12: =_xll.EQNXTDZ($A$1,$B12,J$1,$B$1) -> 11.1301 | ... AF12: =_xll.EQNXTDZ($A$1,$B12,AF$1,$B$1) -> 0
A13: Power & Fuel Cost | B13: PL_POWER_FUEL | C13: =_xll.EQNXTDZ($A$1,$B13,C$1,$B$1) -> 0 | D13: =_xll.EQNXTDZ($A$1,$B13,D$1,$B$1) -> 0 | E13: =_xll.EQNXTDZ($A$1,$B13,E$1,$B$1) -> 0 | F13: =_xll.EQNXTDZ($A$1,$B13,F$1,$B$1) -> 0 | G13: =_xll.EQNXTDZ($A$1,$B13,G$1,$B$1) -> 0 | H13: =_xll.EQNXTDZ($A$1,$B13,H$1,$B$1) -> 0 | I13: =_xll.EQNXTDZ($A$1,$B13,I$1,$B$1) -> 0.3917144 | J13: =_xll.EQNXTDZ($A$1,$B13,J$1,$B$1) -> 0.3645711 | ... AF13: =_xll.EQNXTDZ($A$1,$B13,AF$1,$B$1) -> 0
A14: Employee Cost | B14: PL_EMPLOYEES | C14: =_xll.EQNXTDZ($A$1,$B14,C$1,$B$1) -> 0 | D14: =_xll.EQNXTDZ($A$1,$B14,D$1,$B$1) -> 0 | E14: =_xll.EQNXTDZ($A$1,$B14,E$1,$B$1) -> 0 | F14: =_xll.EQNXTDZ($A$1,$B14,F$1,$B$1) -> 0 | G14: =_xll.EQNXTDZ($A$1,$B14,G$1,$B$1) -> 0 | H14: =_xll.EQNXTDZ($A$1,$B14,H$1,$B$1) -> 0 | I14: =_xll.EQNXTDZ($A$1,$B14,I$1,$B$1) -> 1.5794924 | J14: =_xll.EQNXTDZ($A$1,$B14,J$1,$B$1) -> 1.7314282 | ... AF14: =_xll.EQNXTDZ($A$1,$B14,AF$1,$B$1) -> 0
A15: Operating & Manufacturing Expenses | B15: PL_GEN_OTHER_MFG_EXPS | C15: =_xll.EQNXTDZ($A$1,$B15,C$1,$B$1) -> 0 | D15: =_xll.EQNXTDZ($A$1,$B15,D$1,$B$1) -> 0 | E15: =_xll.EQNXTDZ($A$1,$B15,E$1,$B$1) -> 0 | F15: =_xll.EQNXTDZ($A$1,$B15,F$1,$B$1) -> 0 | G15: =_xll.EQNXTDZ($A$1,$B15,G$1,$B$1) -> 0 | H15: =_xll.EQNXTDZ($A$1,$B15,H$1,$B$1) -> 0 | I15: =_xll.EQNXTDZ($A$1,$B15,I$1,$B$1) -> 0.3454323 | J15: =_xll.EQNXTDZ($A$1,$B15,J$1,$B$1) -> 0.4266916 | ... AF15: =_xll.EQNXTDZ($A$1,$B15,AF$1,$B$1) -> 0
A16: Cost of Software development | B16: PL_COST_SW | C16: =_xll.EQNXTDZ($A$1,$B16,C$1,$B$1) -> 0 | D16: =_xll.EQNXTDZ($A$1,$B16,D$1,$B$1) -> 0 | E16: =_xll.EQNXTDZ($A$1,$B16,E$1,$B$1) -> 0 | F16: =_xll.EQNXTDZ($A$1,$B16,F$1,$B$1) -> 0 | G16: =_xll.EQNXTDZ($A$1,$B16,G$1,$B$1) -> 0 | H16: =_xll.EQNXTDZ($A$1,$B16,H$1,$B$1) -> 0 | I16: =_xll.EQNXTDZ($A$1,$B16,I$1,$B$1) -> 0 | J16: =_xll.EQNXTDZ($A$1,$B16,J$1,$B$1) -> 0 | ... AF16: =_xll.EQNXTDZ($A$1,$B16,AF$1,$B$1) -> 0
... A36: Profit After Tax from Discontinued Operations | B36: PL_PAT_DIS_OP | C36: =_xll.EQNXTDZ($A$1,$B36,C$1,$B$1) -> 0 | D36: =_xll.EQNXTDZ($A$1,$B36,D$1,$B$1) -> 0 | E36: =_xll.EQNXTDZ($A$1,$B36,E$1,$B$1) -> 0 | F36: =_xll.EQNXTDZ($A$1,$B36,F$1,$B$1) -> 0 | G36: =_xll.EQNXTDZ($A$1,$B36,G$1,$B$1) -> 0 | H36: =_xll.EQNXTDZ($A$1,$B36,H$1,$B$1) -> 0 | I36: =_xll.EQNXTDZ($A$1,$B36,I$1,$B$1) -> 0 | J36: =_xll.EQNXTDZ($A$1,$B36,J$1,$B$1) -> 0 | ... AF36: =_xll.EQNXTDZ($A$1,$B36,AF$1,$B$1) -> 0
A39: Field Description | B39: Field Name
A40: Year End | B40: BS_YEAR_END | C40: =_xll.EQNXTDZ($A$1,$B40,C$1,$B$1) -> 0 | D40: =_xll.EQNXTDZ($A$1,$B40,D$1,$B$1) -> 0 | E40: =_xll.EQNXTDZ($A$1,$B40,E$1,$B$1) -> 0 | F40: =_xll.EQNXTDZ($A$1,$B40,F$1,$B$1) -> 0 | G40: =_xll.EQNXTDZ($A$1,$B40,G$1,$B$1) -> 0 | H40: =_xll.EQNXTDZ($A$1,$B40,H$1,$B$1) -> 0 | I40: =_xll.EQNXTDZ($A$1,$B40,I$1,$B$1) -> 200703 | J40: =_xll.EQNXTDZ($A$1,$B40,J$1,$B$1) -> 200803 | ... AF40: =_xll.EQNXTDZ($A$1,$B40,AF$1,$B$1) -> 0
A41: Share Capital | B41: BS_SHARE_CAPITAL | C41: =_xll.EQNXTDZ($A$1,$B41,C$1,$B$1) -> 0 | D41: =_xll.EQNXTDZ($A$1,$B41,D$1,$B$1) -> 0 | E41: =_xll.EQNXTDZ($A$1,$B41,E$1,$B$1) -> 0 | F41: =_xll.EQNXTDZ($A$1,$B41,F$1,$B$1) -> 0 | G41: =_xll.EQNXTDZ($A$1,$B41,G$1,$B$1) -> 0 | H41: =_xll.EQNXTDZ($A$1,$B41,H$1,$B$1) -> 0 | I41: =_xll.EQNXTDZ($A$1,$B41,I$1,$B$1) -> 10.407425 | J41: =_xll.EQNXTDZ($A$1,$B41,J$1,$B$1) -> 10.407425 | ... AF41: =_xll.EQNXTDZ($A$1,$B41,AF$1,$B$1) -> 0
A42: Share Warrants & Outstandings | B42: BS_SHAREWROUTST | C42: =_xll.EQNXTDZ($A$1,$B42,C$1,$B$1) -> 0 | D42: =_xll.EQNXTDZ($A$1,$B42,D$1,$B$1) -> 0 | E42: =_xll.EQNXTDZ($A$1,$B42,E$1,$B$1) -> 0 | F42: =_xll.EQNXTDZ($A$1,$B42,F$1,$B$1) -> 0 | G42: =_xll.EQNXTDZ($A$1,$B42,G$1,$B$1) -> 0 | H42: =_xll.EQNXTDZ($A$1,$B42,H$1,$B$1) -> 0 | I42: =_xll.EQNXTDZ($A$1,$B42,I$1,$B$1) -> 0 | J42: =_xll.EQNXTDZ($A$1,$B42,J$1,$B$1) -> 0 | ... AF42: =_xll.EQNXTDZ($A$1,$B42,AF$1,$B$1) -> 0
A43: Total Reserves | B43: BS_RESERVE | C43: =_xll.EQNXTDZ($A$1,$B43,C$1,$B$1) -> 0 | D43: =_xll.EQNXTDZ($A$1,$B43,D$1,$B$1) -> 0 | E43: =_xll.EQNXTDZ($A$1,$B43,E$1,$B$1) -> 0 | F43: =_xll.EQNXTDZ($A$1,$B43,F$1,$B$1) -> 0 | G43: =_xll.EQNXTDZ($A$1,$B43,G$1,$B$1) -> 0 | H43: =_xll.EQNXTDZ($A$1,$B43,H$1,$B$1) -> 0 | I43: =_xll.EQNXTDZ($A$1,$B43,I$1,$B$1) -> 16.519602 | J43: =_xll.EQNXTDZ($A$1,$B43,J$1,$B$1) -> 20.176686 | ... AF43: =_xll.EQNXTDZ($A$1,$B43,AF$1,$B$1) -> 0
A44: Shareholder's Funds | B44: BS_SHAREHODERS_FUNDS | C44: =_xll.EQNXTDZ($A$1,$B44,C$1,$B$1) -> 0 | D44: =_xll.EQNXTDZ($A$1,$B44,D$1,$B$1) -> 0 | E44: =_xll.EQNXTDZ($A$1,$B44,E$1,$B$1) -> 0 | F44: =_xll.EQNXTDZ($A$1,$B44,F$1,$B$1) -> 0 | G44: =_xll.EQNXTDZ($A$1,$B44,G$1,$B$1) -> 0 | H44: =_xll.EQNXTDZ($A$1,$B44,H$1,$B$1) -> 0 | I44: =_xll.EQNXTDZ($A$1,$B44,I$1,$B$1) -> 26.927027 | J44: =_xll.EQNXTDZ($A$1,$B44,J$1,$B$1) -> 30.584111 | ... AF44: =_xll.EQNXTDZ($A$1,$B44,AF$1,$B$1) -> 0
A45: Minority Interest | B45: BS_MINORITY_INTEREST | C45: =_xll.EQNXTDZ($A$1,$B45,C$1,$B$1) -> 0 | D45: =_xll.EQNXTDZ($A$1,$B45,D$1,$B$1) -> 0 | E45: =_xll.EQNXTDZ($A$1,$B45,E$1,$B$1) -> 0 | F45: =_xll.EQNXTDZ($A$1,$B45,F$1,$B$1) -> 0 | G45: =_xll.EQNXTDZ($A$1,$B45,G$1,$B$1) -> 0 | H45: =_xll.EQNXTDZ($A$1,$B45,H$1,$B$1) -> 0 | I45: =_xll.EQNXTDZ($A$1,$B45,I$1,$B$1) -> 0 | J45: =_xll.EQNXTDZ($A$1,$B45,J$1,$B$1) -> 0 | ... AF45: =_xll.EQNXTDZ($A$1,$B45,AF$1,$B$1) -> 0
A46: Long-Term Borrowings | B46: BS_LTRM_BORROWING | C46: =_xll.EQNXTDZ($A$1,$B46,C$1,$B$1) -> 0 | D46: =_xll.EQNXTDZ($A$1,$B46,D$1,$B$1) -> 0 | E46: =_xll.EQNXTDZ($A$1,$B46,E$1,$B$1) -> 0 | F46: =_xll.EQNXTDZ($A$1,$B46,F$1,$B$1) -> 0 | G46: =_xll.EQNXTDZ($A$1,$B46,G$1,$B$1) -> 0 | H46: =_xll.EQNXTDZ($A$1,$B46,H$1,$B$1) -> 0 | I46: =_xll.EQNXTDZ($A$1,$B46,I$1,$B$1) -> 0 | J46: =_xll.EQNXTDZ($A$1,$B46,J$1,$B$1) -> 0 | ... AF46: =_xll.EQNXTDZ($A$1,$B46,AF$1,$B$1) -> 0
A47: Secured Loans | B47: BS_SECURED_LOANS | C47: =_xll.EQNXTDZ($A$1,$B47,C$1,$B$1) -> 0 | D47: =_xll.EQNXTDZ($A$1,$B47,D$1,$B$1) -> 0 | E47: =_xll.EQNXTDZ($A$1,$B47,E$1,$B$1) -> 0 | F47: =_xll.EQNXTDZ($A$1,$B47,F$1,$B$1) -> 0 | G47: =_xll.EQNXTDZ($A$1,$B47,G$1,$B$1) -> 0 | H47: =_xll.EQNXTDZ($A$1,$B47,H$1,$B$1) -> 0 | I47: =_xll.EQNXTDZ($A$1,$B47,I$1,$B$1) -> 0 | J47: =_xll.EQNXTDZ($A$1,$B47,J$1,$B$1) -> 0 | ... AF47: =_xll.EQNXTDZ($A$1,$B47,AF$1,$B$1) -> 0
A48: Unsecured Loans | B48: BS_UNSECURED_LOANS_NF | C48: =_xll.EQNXTDZ($A$1,$B48,C$1,$B$1) -> 0 | D48: =_xll.EQNXTDZ($A$1,$B48,D$1,$B$1) -> 0 | E48: =_xll.EQNXTDZ($A$1,$B48,E$1,$B$1) -> 0 | F48: =_xll.EQNXTDZ($A$1,$B48,F$1,$B$1) -> 0 | G48: =_xll.EQNXTDZ($A$1,$B48,G$1,$B$1) -> 0 | H48: =_xll.EQNXTDZ($A$1,$B48,H$1,$B$1) -> 0 | I48: =_xll.EQNXTDZ($A$1,$B48,I$1,$B$1) -> 25 | J48: =_xll.EQNXTDZ($A$1,$B48,J$1,$B$1) -> 25 | ... AF48: =_xll.EQNXTDZ($A$1,$B48,AF$1,$B$1) -> 0
A49: Deferred Tax Assets / Liabilities | B49: BS_NET_DEF_TAX_NF | C49: =_xll.EQNXTDZ($A$1,$B49,C$1,$B$1) -> 0 | D49: =_xll.EQNXTDZ($A$1,$B49,D$1,$B$1) -> 0 | E49: =_xll.EQNXTDZ($A$1,$B49,E$1,$B$1) -> 0 | F49: =_xll.EQNXTDZ($A$1,$B49,F$1,$B$1) -> 0 | G49: =_xll.EQNXTDZ($A$1,$B49,G$1,$B$1) -> 0 | H49: =_xll.EQNXTDZ($A$1,$B49,H$1,$B$1) -> 0 | I49: =_xll.EQNXTDZ($A$1,$B49,I$1,$B$1) -> 0.3283898 | J49: =_xll.EQNXTDZ($A$1,$B49,J$1,$B$1) -> 0.2511328 | ... AF49: =_xll.EQNXTDZ($A$1,$B49,AF$1,$B$1) -> 0
A50: Other Long Term Liabilities | B50: BS_OTH_LT_LIAB | C50: =_xll.EQNXTDZ($A$1,$B50,C$1,$B$1) -> 0 | D50: =_xll.EQNXTDZ($A$1,$B50,D$1,$B$1) -> 0 | E50: =_xll.EQNXTDZ($A$1,$B50,E$1,$B$1) -> 0 | F50: =_xll.EQNXTDZ($A$1,$B50,F$1,$B$1) -> 0 | G50: =_xll.EQNXTDZ($A$1,$B50,G$1,$B$1) -> 0 | H50: =_xll.EQNXTDZ($A$1,$B50,H$1,$B$1) -> 0 | I50: =_xll.EQNXTDZ($A$1,$B50,I$1,$B$1) -> 0 | J50: =_xll.EQNXTDZ($A$1,$B50,J$1,$B$1) -> 0 | ... AF50: =_xll.EQNXTDZ($A$1,$B50,AF$1,$B$1) -> 0
A51: Long Term Trade Payables | B51: BS_LT_TRADE_PAYABLES | C51: =_xll.EQNXTDZ($A$1,$B51,C$1,$B$1) -> 0 | D51: =_xll.EQNXTDZ($A$1,$B51,D$1,$B$1) -> 0 | E51: =_xll.EQNXTDZ($A$1,$B51,E$1,$B$1) -> 0 | F51: =_xll.EQNXTDZ($A$1,$B51,F$1,$B$1) -> 0 | G51: =_xll.EQNXTDZ($A$1,$B51,G$1,$B$1) -> 0 | H51: =_xll.EQNXTDZ($A$1,$B51,H$1,$B$1) -> 0 | I51: =_xll.EQNXTDZ($A$1,$B51,I$1,$B$1) -> 0 | J51: =_xll.EQNXTDZ($A$1,$B51,J$1,$B$1) -> 0 | ... AF51: =_xll.EQNXTDZ($A$1,$B51,AF$1,$B$1) -> 0
... A99: Estimated Capital Contracts Remaining | B99: BS_ESTIMATED_CAPITAL_CONTRACT | C99: =_xll.EQNXTDZ($A$1,$B99,C$1,$B$1) -> 0 | D99: =_xll.EQNXTDZ($A$1,$B99,D$1,$B$1) -> 0 | E99: =_xll.EQNXTDZ($A$1,$B99,E$1,$B$1) -> 0 | F99: =_xll.EQNXTDZ($A$1,$B99,F$1,$B$1) -> 0 | G99: =_xll.EQNXTDZ($A$1,$B99,G$1,$B$1) -> 0 | H99: =_xll.EQNXTDZ($A$1,$B99,H$1,$B$1) -> 0 | I99: =_xll.EQNXTDZ($A$1,$B99,I$1,$B$1) -> 0 | J99: =_xll.EQNXTDZ($A$1,$B99,J$1,$B$1) -> 0 | ... AF99: =_xll.EQNXTDZ($A$1,$B99,AF$1,$B$1) -> 0
A103: Field Description | B103: Field Name
A104: Equity Paid Up | B104: BS_EQUITY_PAIDUP | C104: =_xll.EQNXTDZ($A$1,$B104,C$1,$B$1) -> 0 | D104: =_xll.EQNXTDZ($A$1,$B104,D$1,$B$1) -> 0 | E104: =_xll.EQNXTDZ($A$1,$B104,E$1,$B$1) -> 0 | F104: =_xll.EQNXTDZ($A$1,$B104,F$1,$B$1) -> 0 | G104: =_xll.EQNXTDZ($A$1,$B104,G$1,$B$1) -> 0 | H104: =_xll.EQNXTDZ($A$1,$B104,H$1,$B$1) -> 0 | I104: =_xll.EQNXTDZ($A$1,$B104,I$1,$B$1) -> 10.407425 | J104: =_xll.EQNXTDZ($A$1,$B104,J$1,$B$1) -> 10.407425 | ... AF104: =_xll.EQNXTDZ($A$1,$B104,AF$1,$B$1) -> 0
A105: Face Value | B105: BS_FACE_VALUE | C105: =_xll.EQNXTDZ($A$1,$B105,C$1,$B$1) -> 0 | D105: =_xll.EQNXTDZ($A$1,$B105,D$1,$B$1) -> 0 | E105: =_xll.EQNXTDZ($A$1,$B105,E$1,$B$1) -> 0 | F105: =_xll.EQNXTDZ($A$1,$B105,F$1,$B$1) -> 0 | G105: =_xll.EQNXTDZ($A$1,$B105,G$1,$B$1) -> 0 | H105: =_xll.EQNXTDZ($A$1,$B105,H$1,$B$1) -> 0 | I105: =_xll.EQNXTDZ($A$1,$B105,I$1,$B$1) -> 10 | J105: =_xll.EQNXTDZ($A$1,$B105,J$1,$B$1) -> 10 | ... AF105: =_xll.EQNXTDZ($A$1,$B105,AF$1,$B$1) -> 0
A106: Close Price (Unit Curr.) | B106: FH_YEAR_PRICE | C106: =_xll.EQNXTDZ($A$1,$B106,C$1,$B$1) -> 0 | D106: =_xll.EQNXTDZ($A$1,$B106,D$1,$B$1) -> 0 | E106: =_xll.EQNXTDZ($A$1,$B106,E$1,$B$1) -> 0 | F106: =_xll.EQNXTDZ($A$1,$B106,F$1,$B$1) -> 0 | G106: =_xll.EQNXTDZ($A$1,$B106,G$1,$B$1) -> 0 | H106: =_xll.EQNXTDZ($A$1,$B106,H$1,$B$1) -> 0 | I106: =_xll.EQNXTDZ($A$1,$B106,I$1,$B$1) -> 0 | J106: =_xll.EQNXTDZ($A$1,$B106,J$1,$B$1) -> 0 | ... AF106: =_xll.EQNXTDZ($A$1,$B106,AF$1,$B$1) -> 0
A107: High Price (Unit Curr.) | B107: FH_HIGH | C107: =_xll.EQNXTDZ($A$1,$B107,C$1,$B$1) -> 0 | D107: =_xll.EQNXTDZ($A$1,$B107,D$1,$B$1) -> 0 | E107: =_xll.EQNXTDZ($A$1,$B107,E$1,$B$1) -> 0 | F107: =_xll.EQNXTDZ($A$1,$B107,F$1,$B$1) -> 0 | G107: =_xll.EQNXTDZ($A$1,$B107,G$1,$B$1) -> 0 | H107: =_xll.EQNXTDZ($A$1,$B107,H$1,$B$1) -> 0 | I107: =_xll.EQNXTDZ($A$1,$B107,I$1,$B$1) -> 0 | J107: =_xll.EQNXTDZ($A$1,$B107,J$1,$B$1) -> 0 | ... AF107: =_xll.EQNXTDZ($A$1,$B107,AF$1,$B$1) -> 0
A108: Low Price (Unit Curr.) | B108: FH_LOW | C108: =_xll.EQNXTDZ($A$1,$B108,C$1,$B$1) -> 0 | D108: =_xll.EQNXTDZ($A$1,$B108,D$1,$B$1) -> 0 | E108: =_xll.EQNXTDZ($A$1,$B108,E$1,$B$1) -> 0 | F108: =_xll.EQNXTDZ($A$1,$B108,F$1,$B$1) -> 0 | G108: =_xll.EQNXTDZ($A$1,$B108,G$1,$B$1) -> 0 | H108: =_xll.EQNXTDZ($A$1,$B108,H$1,$B$1) -> 0 | I108: =_xll.EQNXTDZ($A$1,$B108,I$1,$B$1) -> 0 | J108: =_xll.EQNXTDZ($A$1,$B108,J$1,$B$1) -> 0 | ... AF108: =_xll.EQNXTDZ($A$1,$B108,AF$1,$B$1) -> 0
A109: Market Capitalization | B109: FH_MCAP | C109: =_xll.EQNXTDZ($A$1,$B109,C$1,$B$1) -> 0 | D109: =_xll.EQNXTDZ($A$1,$B109,D$1,$B$1) -> 0 | E109: =_xll.EQNXTDZ($A$1,$B109,E$1,$B$1) -> 0 | F109: =_xll.EQNXTDZ($A$1,$B109,F$1,$B$1) -> 0 | G109: =_xll.EQNXTDZ($A$1,$B109,G$1,$B$1) -> 0 | H109: =_xll.EQNXTDZ($A$1,$B109,H$1,$B$1) -> 0 | I109: =_xll.EQNXTDZ($A$1,$B109,I$1,$B$1) -> 0 | J109: =_xll.EQNXTDZ($A$1,$B109,J$1,$B$1) -> 0 | ... AF109: =_xll.EQNXTDZ($A$1,$B109,AF$1,$B$1) -> 0
A110: Adj DPS(Rs) | B110: FR_ADJ_DPS | C110: =_xll.EQNXTDZ($A$1,$B110,C$1,$B$1) -> 0 | D110: =_xll.EQNXTDZ($A$1,$B110,D$1,$B$1) -> 0 | E110: =_xll.EQNXTDZ($A$1,$B110,E$1,$B$1) -> 0 | F110: =_xll.EQNXTDZ($A$1,$B110,F$1,$B$1) -> 0 | G110: =_xll.EQNXTDZ($A$1,$B110,G$1,$B$1) -> 0 | H110: =_xll.EQNXTDZ($A$1,$B110,H$1,$B$1) -> 0 | I110: =_xll.EQNXTDZ($A$1,$B110,I$1,$B$1) -> 0 | J110: =_xll.EQNXTDZ($A$1,$B110,J$1,$B$1) -> 1.25 | ... AF110: =_xll.EQNXTDZ($A$1,$B110,AF$1,$B$1) -> 0
A111: Date End | B111: SHP_DATE_END | C111: =_xll.EQNXTDZ($A$1,$B111,C$5) -> 0 | D111: =_xll.EQNXTDZ($A$1,$B111,D$5) -> 0 | E111: =_xll.EQNXTDZ($A$1,$B111,E$5) -> 0 | F111: =_xll.EQNXTDZ($A$1,$B111,F$5) -> 0 | G111: =_xll.EQNXTDZ($A$1,$B111,G$5) -> 0 | H111: =_xll.EQNXTDZ($A$1,$B111,H$5) -> 0 | I111: =_xll.EQNXTDZ($A$1,$B111,I$5) -> 0 | J111: =_xll.EQNXTDZ($A$1,$B111,J$5) -> 0 | ... AF111: =_xll.EQNXTDZ($A$1,$B111,AF$5) -> 0
