Workbook

Sheet Template
A1: =+'Annual Raw'!C4 -> Voltas Ltd. | B1: 36951 | C1: =EOMONTH(B1,12) -> 37346 | D1: =EOMONTH(C1,12) -> 37711 | E1: =EOMONTH(D1,12) -> 38077 | F1: =EOMONTH(E1,12) -> 38442 | G1: =EOMONTH(F1,12) -> 38807 | H1: =EOMONTH(G1,12) -> 39172 | I1: =EOMONTH(H1,12) -> 39538 | J1: =EOMONTH(I1,12) -> 39903 | ... AE1: =EOMONTH(AD1,12) -> 47573 | AH1: QTR | AI1: 41061 | AJ1: 41153 | AK1: 41244 | AL1: 41334 | AM1: 41426 | AN1: 41518 | AO1: 41609 | AP1: 41699 | AQ1: 41791 | AR1: 41883 | AS1: 41974 | AT1: 42064 | AU1: 42156 | AV1: 42248 | AW1: 42339 | AX1: 42430 | AY1: 42522 | AZ1: 42614 | BA1: 42705 | BB1: 42795 | BC1: 42887 | BD1: 42979 | BE1: 43070 | BF1: 43160 | BG1: 43252 | BH1: 43344 | BI1: 43435 | BJ1: 43525 | BK1: 43617 | BL1: 43709 | BM1: 43800 | BN1: 43891 | BO1: 43983 | BP1: 44075 | BQ1: =EOMONTH(BP1,3) -> 44196 | BR1: =EOMONTH(BQ1,3) -> 44286 | BS1: =EOMONTH(BR1,3) -> 44377 | BT1: =EOMONTH(BS1,3) -> 44469 | BU1: =EOMONTH(BT1,3) -> 44561 | BV1: =EOMONTH(BU1,3) -> 44651 | BW1: =EOMONTH(BV1,3) -> 44742 | BX1: =EOMONTH(BW1,3) -> 44834 | ... DB1: =EOMONTH(DA1,3) -> 47573 | DE1: HISTORICAL ESTIMATES | DF1: 46112
A2: Presentation Data (Start)
A4: Revenue - Electro Mechanical Projects & Services | O4: =+SUM(AM4:AP4) -> 2692.42 | P4: =+SUM(AQ4:AT4) -> 2208.54 | Q4: =+SUM(AU4:AX4) -> 2717.15 | R4: =+SUM(AY4:BB4) -> 2655.03 | S4: =+SUM(BC4:BF4) -> 2845.21 | T4: =+SUM(BG4:BJ4) -> 3619.08 | U4: =+SUM(BK4:BN4) -> 3246.14 | V4: =+SUM(BO4:BR4) -> 3566.38 | W4: =+SUM(BS4:BV4) -> 2470.49 | X4: =+SUM(BW4:BZ4) -> 2402.91 | Y4: =+SUM(CA4:CD4) -> 3683.03 | Z4: =+SUM(CE4:CH4) -> 4156.79 | AA4: =+SUM(CI4:CL4) -> 2862.18 | AB4: =+SUM(CM4:CP4) -> 0 | AC4: =+SUM(CQ4:CT4) -> 0 | AD4: =+SUM(CU4:CX4) -> 0 | AE4: =+SUM(CY4:DB4) -> 0 | AL4: 883.35 | AM4: 692.95 | AN4: 670.88 | AO4: 642.91 | AP4: 685.68 | AQ4: 622.24 | AR4: 525.32 | AS4: 461.31 | AT4: 599.67 | AU4: 555.93 | AV4: 620.8 | AW4: 721.87 | AX4: 818.55 | AY4: 580.21 | AZ4: 543.24 | BA4: 702.58 | BB4: 829 | BC4: 660.83 | BD4: 557.47 | BE4: 753.37 | BF4: 873.54 | BG4: 866.37 | BH4: 901.48 | BI4: 875.23 | BJ4: 976 | BK4: 824.12 | BL4: 809.33 | BM4: 808.13 | BN4: 804.56 | BO4: 518.09 | BP4: 927.8 | BQ4: 1016.66 | BR4: 1103.83 | BS4: 688.42 | BT4: 536.48 | BU4: 553.78 | BV4: 691.81 | BW4: 454.69 | BX4: 554.04 | BY4: 648.39 | BZ4: 745.79 | CA4: 679.06 | CB4: 924.19 | CC4: 981.88 | CD4: 1097.9 | CE4: 949.13 | CF4: 879.91 | CG4: 1190.23 | CH4: 1137.52 | CI4: 921.83 | CJ4: 966.17 | CK4: 974.18
A5: Revenue - Engineering Product Services | O5: =+SUM(AM5:AP5) -> 448.22 | P5: =+SUM(AQ5:AT5) -> 360.06 | Q5: =+SUM(AU5:AX5) -> 370.19 | R5: =+SUM(AY5:BB5) -> 331.81 | S5: =+SUM(BC5:BF5) -> 309.93 | T5: =+SUM(BG5:BJ5) -> 311.65 | U5: =+SUM(BK5:BN5) -> 331.66 | V5: =+SUM(BO5:BR5) -> 359.49 | W5: =+SUM(BS5:BV5) -> 488.66 | X5: =+SUM(BW5:BZ5) -> 521.96 | Y5: =+SUM(CA5:CD5) -> 587.91 | Z5: =+SUM(CE5:CH5) -> 568.25 | AA5: =+SUM(CI5:CL5) -> 431.06 | AB5: =+SUM(CM5:CP5) -> 0 | AC5: =+SUM(CQ5:CT5) -> 0 | AD5: =+SUM(CU5:CX5) -> 0 | AE5: =+SUM(CY5:DB5) -> 0 | AL5: 103.9 | AM5: 111.17 | AN5: 126.46 | AO5: 111.83 | AP5: 98.76 | AQ5: 110.89 | AR5: 87.17 | AS5: 80.95 | AT5: 81.05 | AU5: 70 | AV5: 96.12 | AW5: 111.41 | AX5: 92.66 | AY5: 69.14 | AZ5: 75.1 | BA5: 80.74 | BB5: 106.83 | BC5: 90.35 | BD5: 66.62 | BE5: 69.52 | BF5: 83.44 | BG5: 77.16 | BH5: 72.86 | BI5: 83.16 | BJ5: 78.47 | BK5: 73.96 | BL5: 80.3 | BM5: 82.6 | BN5: 94.8 | BO5: 47.61 | BP5: 93.29 | BQ5: 120.91 | BR5: 97.68 | BS5: 115.06 | BT5: 125.42 | BU5: 124.68 | BV5: 123.5 | BW5: 124.33 | BX5: 137.37 | BY5: 117.91 | BZ5: 142.35 | CA5: 142.31 | CB5: 134.44 | CC5: 154.8 | CD5: 156.36 | CE5: 160.78 | CF5: 145.71 | CG5: 129.67 | CH5: 132.09 | CI5: 135.44 | CJ5: 139.05 | CK5: 156.57
A6: Revenue - Unitary Cooling Products | O6: =+SUM(AM6:AP6) -> 2052.42 | P6: =+SUM(AQ6:AT6) -> 2510.49 | Q6: =+SUM(AU6:AX6) -> 2556.63 | R6: =+SUM(AY6:BB6) -> 3046.86 | S6: =+SUM(BC6:BF6) -> 3226.09 | T6: =+SUM(BG6:BJ6) -> 3155.56 | U6: =+SUM(BK6:BN6) -> 4073.7 | V6: =+SUM(BO6:BR6) -> 3555.04 | W6: =+SUM(BS6:BV6) -> 4881.92 | X6: =+SUM(BW6:BZ6) -> 6474.5 | Y6: =+SUM(CA6:CD6) -> 8153.5 | Z6: =+SUM(CE6:CH6) -> 10613.92 | AA6: =+SUM(CI6:CL6) -> 6007.19 | AB6: =+SUM(CM6:CP6) -> 0 | AC6: =+SUM(CQ6:CT6) -> 0 | AD6: =+SUM(CU6:CX6) -> 0 | AE6: =+SUM(CY6:DB6) -> 0 | AL6: 585.51 | AM6: 786.74 | AN6: 264.31 | AO6: 347.04 | AP6: 654.33 | AQ6: 1001.38 | AR6: 344.87 | AS6: 383.51 | AT6: 780.73 | AU6: 948.95 | AV6: 314.1 | AW6: 434.53 | AX6: 859.05 | AY6: 1195.62 | AZ6: 354.16 | BA6: 411.07 | BB6: 1086.01 | BC6: 1211.66 | BD6: 407.77 | BE6: 542.17 | BF6: 1064.49 | BG6: 1191.06 | BH6: 441.01 | BI6: 525.92 | BJ6: 997.57 | BK6: 1748.78 | BL6: 525.55 | BM6: 600.51 | BN6: 1198.86 | BO6: 707.11 | BP6: 571.65 | BQ6: 839.61 | BR6: 1436.67 | BS6: 963.11 | BT6: 1006.8 | BU6: 1093.6 | BV6: 1818.41 | BW6: 2162.2 | BX6: 1047.71 | BY6: 1215.97 | BZ6: 2048.62 | CA6: 2513.97 | CB6: 1208.8 | CC6: 1475.61 | CD6: 2955.12 | CE6: 3802.17 | CF6: 1582.19 | CG6: 1771.13 | CH6: 3458.43 | CI6: 2867.86 | CJ6: 1215.13 | CK6: 1924.2
A7: Revenue - Others | O7: =+SUM(AM7:AP7) -> 52.04 | P7: =+SUM(AQ7:AT7) -> 66.12 | Q7: =+SUM(AU7:AX7) -> 188.45 | R7: =+SUM(AY7:BB7) -> 0 | S7: =+SUM(BC7:BF7) -> 0 | T7: =+SUM(BG7:BJ7) -> 0 | U7: =+SUM(BK7:BN7) -> 0 | V7: =+SUM(BO7:BR7) -> 0 | W7: =+SUM(BS7:BV7) -> 0 | X7: =+SUM(BW7:BZ7) -> 0 | Y7: =+SUM(CA7:CD7) -> 0 | Z7: =+SUM(CE7:CH7) -> 0 | AA7: =+SUM(CI7:CL7) -> 0 | AB7: =+SUM(CM7:CP7) -> 0 | AC7: =+SUM(CQ7:CT7) -> 0 | AD7: =+SUM(CU7:CX7) -> 0 | AE7: =+SUM(CY7:DB7) -> 0 | AL7: 19.82 | AM7: 11.16 | AN7: 15.05 | AO7: 13.36 | AP7: 12.47 | AQ7: 18.11 | AR7: 11.68 | AS7: 13.39 | AT7: 22.94 | AU7: 20.53 | AV7: 28.88 | AW7: 33.44 | AX7: 105.6
A8: Revenue - Other operating income | O8: =+SUM(AM8:AP8) -> 22.38 | P8: =+SUM(AQ8:AT8) -> 38.8 | Q8: =+SUM(AU8:AX8) -> 26.84 | R8: =+SUM(AY8:BB8) -> 62.24 | S8: =+SUM(BC8:BF8) -> 47.59 | T8: =+SUM(BG8:BJ8) -> 39.48 | U8: =+SUM(BK8:BN8) -> 30.93 | V8: =+SUM(BO8:BR8) -> 99.23 | W8: =+SUM(BS8:BV8) -> 93.38 | X8: =+SUM(BW8:BZ8) -> 99.4 | Y8: =+SUM(CA8:CD8) -> 73.85 | Z8: =+SUM(CE8:CH8) -> 92.34 | AA8: =+SUM(CI8:CL8) -> 77.21 | AB8: =+SUM(CM8:CP8) -> 0 | AC8: =+SUM(CQ8:CT8) -> 0 | AD8: =+SUM(CU8:CX8) -> 0 | AE8: =+SUM(CY8:DB8) -> 0 | AL8: 4.89 | AM8: 1.52 | AN8: 4 | AO8: 4.41 | AP8: 12.45 | AQ8: 5.03 | AR8: 15.73 | AS8: 12.16 | AT8: 5.88 | AU8: 3.1 | AV8: 3.02 | AW8: 6.77 | AX8: 13.95 | AY8: 10.37 | AZ8: 9.17 | BA8: 5.95 | BB8: 36.75 | BC8: 5.74 | BD8: 5.05 | BE8: 9.72 | BF8: 27.08 | BG8: 13.68 | BH8: 6.66 | BI8: 7.93 | BJ8: 11.21 | BK8: 7.33 | BL8: 6.92 | BM8: 5.44 | BN8: 11.24 | BO8: 26.18 | BP8: 24.99 | BQ8: 24.24 | BR8: 23.82 | BS8: 18.61 | BT8: 20.38 | BU8: 21.53 | BV8: 32.86 | BW8: 26.78 | BX8: 29.24 | BY8: 23.34 | BZ8: 20.04 | CA8: 24.52 | CB8: 25.32 | CC8: 13.43 | CD8: 10.58 | CE8: 17.11 | CF8: 17.96 | CG8: 17.75 | CH8: 39.52 | CI8: 26.29 | CJ8: 32.92 | CK8: 18
A9: Less: Inter-segment Revenue | O9: =+SUM(AM9:AP9) -> 1.44 | P9: =+SUM(AQ9:AT9) -> 0.92 | Q9: =+SUM(AU9:AX9) -> 112.6 | R9: =+SUM(AY9:BB9) -> 0.92 | S9: =+SUM(BC9:BF9) -> 0.95 | T9: =+SUM(BG9:BJ9) -> 1.7 | U9: =+SUM(BK9:BN9) -> 24.35 | V9: =+SUM(BO9:BR9) -> 24.36 | W9: =+SUM(BS9:BV9) -> 0 | X9: =+SUM(BW9:BZ9) -> 0 | Y9: =+SUM(CA9:CD9) -> 17.08 | Z9: =+SUM(CE9:CH9) -> 19.5 | AA9: =+SUM(CI9:CL9) -> 20.98 | AB9: =+SUM(CM9:CP9) -> 0 | AC9: =+SUM(CQ9:CT9) -> 0 | AD9: =+SUM(CU9:CX9) -> 0 | AE9: =+SUM(CY9:DB9) -> 0 | AL9: 0.36 | AM9: 0.24 | AN9: 0.17 | AO9: 0.15 | AP9: 0.88 | AQ9: 0.31 | AR9: 0.12 | AS9: 0.19 | AT9: 0.3 | AU9: 34.24 | AV9: 16.24 | AW9: 35.67 | AX9: 26.45 | AY9: 0.16 | AZ9: 0.21 | BA9: 0.22 | BB9: 0.33 | BC9: 0.47 | BD9: 0.2 | BE9: 0.11 | BF9: 0.17 | BG9: 0.18 | BH9: 0.65 | BI9: 0.46 | BJ9: 0.41 | BK9: 0.19 | BL9: 0.16 | BM9: 4.17 | BN9: 19.83 | BO9: 2.05 | BP9: 5.19 | BQ9: 6.78 | BR9: 10.34 | BS9: 0 | BT9: 0 | BU9: 0 | BV9: 0 | BW9: 0 | BX9: 0 | BY9: 0 | BZ9: 0 | CA9: 0 | CB9: 0 | CC9: 0 | CD9: 17.08 | CE9: 8.17 | CF9: 7.66 | CG9: 3.67 | CI9: 12.84 | CJ9: 5.96 | CK9: 2.18
A10: Net Revenue | O10: =+SUM(O4:O8)-O9 -> 5266.04 | P10: =+SUM(P4:P8)-P9 -> 5183.09 | Q10: =+SUM(Q4:Q8)-Q9 -> 5746.66 | R10: =+SUM(R4:R8)-R9 -> 6095.02 | S10: =+SUM(S4:S8)-S9 -> 6427.87 | T10: =+SUM(T4:T8)-T9 -> 7124.07 | U10: =+SUM(U4:U8)-U9 -> 7658.08 | V10: =+SUM(V4:V8)-V9 -> 7555.78 | ... AE10: =+SUM(AE4:AE8)-AE9 -> 0 | AL10: =+SUM(AL4:AL8)-AL9 -> 1597.11 | AM10: =+SUM(AM4:AM8)-AM9 -> 1603.3 | AN10: =+SUM(AN4:AN8)-AN9 -> 1080.53 | AO10: =+SUM(AO4:AO8)-AO9 -> 1119.4 | AP10: =+SUM(AP4:AP8)-AP9 -> 1462.81 | AQ10: =+SUM(AQ4:AQ8)-AQ9 -> 1757.34 | AR10: =+SUM(AR4:AR8)-AR9 -> 984.65 | AS10: =+SUM(AS4:AS8)-AS9 -> 951.13 | ... CK10: =+SUM(CK4:CK8)-CK9 -> 3070.77
O11: =+O10-O24 -> -36.8148 | P11: =+P10-P24 -> -21.7067 | Q11: =+Q10-Q24 -> 0.0071 | R11: =+R10-R24 -> 0 | S11: =+S10-S24 -> 0 | T11: =+T10-T24 -> 0 | U11: =+U10-U24 -> 0 | V11: =+V10-V24 -> 0 | ... Z11: =+Z10-Z24 -> -0.99 | AL11: =+AL10-AL24 -> 0 | AM11: =+AM10-AM24 -> 0 | AN11: =+AN10-AN24 -> 0 | AO11: =+AO10-AO24 -> 0 | AP11: =+AP10-AP24 -> 0 | AQ11: =+AQ10-AQ24 -> 0 | AR11: =+AR10-AR24 -> 0 | AS11: =+AS10-AS24 -> 0 | ... CK11: =+CK10-CK24 -> 0
A13: Revenue YoY% - Electro Mechanical Projects & Services | P13: =+P4/O4-1 -> -0.17971936 | Q13: =+Q4/P4-1 -> 0.23029241 | R13: =+R4/Q4-1 -> -0.02286219 | S13: =+S4/R4-1 -> 0.071630076 | T13: =+T4/S4-1 -> 0.27199047 | U13: =+U4/T4-1 -> -0.10304829 | V13: =+V4/U4-1 -> 0.098652553 | W13: =+W4/V4-1 -> -0.30728358 | ... AE13: =+AE4/AD4-1 -> #DIV/0! | AP13: =+AP4/AL4-1 -> -0.22377314 | AQ13: =+AQ4/AM4-1 -> -0.10204199 | AR13: =+AR4/AN4-1 -> -0.21696876 | AS13: =+AS4/AO4-1 -> -0.28246566 | AT13: =+AT4/AP4-1 -> -0.12543752 | AU13: =+AU4/AQ4-1 -> -0.1065666 | AV13: =+AV4/AR4-1 -> 0.18175588 | AW13: =+AW4/AS4-1 -> 0.56482626 | ... CK13: =+CK4/CG4-1 -> -0.18151954
A14: Revenue YoY% - Engineering Product Services | P14: =+P5/O5-1 -> -0.19668913 | Q14: =+Q5/P5-1 -> 0.0281342 | R14: =+R5/Q5-1 -> -0.10367649 | S14: =+S5/R5-1 -> -0.065941352 | T14: =+T5/S5-1 -> 0.0055496402 | U14: =+U5/T5-1 -> 0.064206642 | V14: =+V5/U5-1 -> 0.083911234 | W14: =+W5/V5-1 -> 0.35931458 | ... AE14: =+AE5/AD5-1 -> #DIV/0! | AP14: =+AP5/AL5-1 -> -0.049470645 | AQ14: =+AQ5/AM5-1 -> -0.0025186651 | AR14: =+AR5/AN5-1 -> -0.31069113 | AS14: =+AS5/AO5-1 -> -0.27613342 | AT14: =+AT5/AP5-1 -> -0.17932361 | AU14: =+AU5/AQ5-1 -> -0.3687438 | AV14: =+AV5/AR5-1 -> 0.10267294 | AW14: =+AW5/AS5-1 -> 0.37628166 | ... CK14: =+CK5/CG5-1 -> 0.20744968
A15: Revenue YoY% - Unitary Cooling Products | P15: =+P6/O6-1 -> 0.22318531 | Q15: =+Q6/P6-1 -> 0.018378882 | R15: =+R6/Q6-1 -> 0.19174851 | S15: =+S6/R6-1 -> 0.058824495 | T15: =+T6/S6-1 -> -0.021862378 | U15: =+U6/T6-1 -> 0.29095945 | V15: =+V6/U6-1 -> -0.12731914 | W15: =+W6/V6-1 -> 0.37323912 | ... AE15: =+AE6/AD6-1 -> #DIV/0! | AP15: =+AP6/AL6-1 -> 0.11753856 | AQ15: =+AQ6/AM6-1 -> 0.27282203 | AR15: =+AR6/AN6-1 -> 0.30479361 | AS15: =+AS6/AO6-1 -> 0.10508875 | AT15: =+AT6/AP6-1 -> 0.1931747 | AU15: =+AU6/AQ6-1 -> -0.052357746 | AV15: =+AV6/AR6-1 -> -0.089222026 | AW15: =+AW6/AS6-1 -> 0.13303434 | ... CK15: =+CK6/CG6-1 -> 0.086425051
A16: Revenue YoY% - Others | P16: =+P7/O7-1 -> 0.27056111 | Q16: =+Q7/P7-1 -> 1.850121 | R16: =+R7/Q7-1 -> -1 | AP16: =+AP7/AL7-1 -> -0.37083754 | AQ16: =+AQ7/AM7-1 -> 0.62275986 | AR16: =+AR7/AN7-1 -> -0.22392027 | AS16: =+AS7/AO7-1 -> 0.002245509 | AT16: =+AT7/AP7-1 -> 0.83961508 | AU16: =+AU7/AQ7-1 -> 0.13362783 | AV16: =+AV7/AR7-1 -> 1.4726027 | AW16: =+AW7/AS7-1 -> 1.4973861 | ... BB16: =+BB7/AX7-1 -> -1
A17: Revenue YoY% - Other operating income | P17: =+P8/O8-1 -> 0.7336908 | Q17: =+Q8/P8-1 -> -0.30824742 | R17: =+R8/Q8-1 -> 1.318927 | S17: =+S8/R8-1 -> -0.23537918 | T17: =+T8/S8-1 -> -0.17041395 | U17: =+U8/T8-1 -> -0.21656535 | V17: =+V8/U8-1 -> 2.2082121 | W17: =+W8/V8-1 -> -0.058953945 | ... AE17: =+AE8/AD8-1 -> #DIV/0! | AP17: =+AP8/AL8-1 -> 1.5460123 | AQ17: =+AQ8/AM8-1 -> 2.3092105 | AR17: =+AR8/AN8-1 -> 2.9325 | AS17: =+AS8/AO8-1 -> 1.7573696 | AT17: =+AT8/AP8-1 -> -0.52771084 | AU17: =+AU8/AQ8-1 -> -0.38369781 | AV17: =+AV8/AR8-1 -> -0.80801017 | AW17: =+AW8/AS8-1 -> -0.44325658 | ... CK17: =+CK8/CG8-1 -> 0.014084507
A18: Inter-segment Revenue YoY% | P18: =+P9/O9-1 -> -0.36111111 | Q18: =+Q9/P9-1 -> 121.3913 | R18: =+R9/Q9-1 -> -0.99182948 | S18: =+S9/R9-1 -> 0.032608696 | T18: =+T9/S9-1 -> 0.78947368 | U18: =+U9/T9-1 -> 13.323529 | V18: =+V9/U9-1 -> 0.00041067762 | W18: =+W9/V9-1 -> -1 | ... AE18: =+AE9/AD9-1 -> #DIV/0! | AP18: =+AP9/AL9-1 -> 1.4444444 | AQ18: =+AQ9/AM9-1 -> 0.29166667 | AR18: =+AR9/AN9-1 -> -0.29411765 | AS18: =+AS9/AO9-1 -> 0.26666667 | AT18: =+AT9/AP9-1 -> -0.65909091 | AU18: =+AU9/AQ9-1 -> 109.45161 | AV18: =+AV9/AR9-1 -> 134.33333 | AW18: =+AW9/AS9-1 -> 186.73684 | ... BV18: =+BV9/BR9-1 -> -1 | CH18: =+CH9/CD9-1 -> -1 | CI18: =+CI9/CE9-1 -> 0.57160343 | CJ18: =+CJ9/CF9-1 -> -0.22193211 | CK18: =+CK9/CG9-1 -> -0.40599455
A19: Net Revenue YoY% | P19: =+P10/O10-1 -> -0.015751874 | Q19: =+Q10/P10-1 -> 0.10873244 | R19: =+R10/Q10-1 -> 0.06061956 | S19: =+S10/R10-1 -> 0.054610157 | T19: =+T10/S10-1 -> 0.1083096 | U19: =+U10/T10-1 -> 0.074958556 | V19: =+V10/U10-1 -> -0.01335844 | W19: =+W10/V10-1 -> 0.050116599 | ... AE19: =+AE10/AD10-1 -> #DIV/0! | AP19: =+AP10/AL10-1 -> -0.084089386 | AQ19: =+AQ10/AM10-1 -> 0.096076842 | AR19: =+AR10/AN10-1 -> -0.088734232 | AS19: =+AS10/AO10-1 -> -0.1503216 | AT19: =+AT10/AP10-1 -> 0.018567005 | AU19: =+AU10/AQ10-1 -> -0.10986491 | AV19: =+AV10/AR10-1 -> 0.062997004 | AW19: =+AW10/AS10-1 -> 0.3377246 | ... CK19: =+CK10/CG10-1 -> -0.01105919
A22: Presentation Data (End)
A23: Profit & Loss- Annual (Start)
A24: Gross Revenue | B24: ='Annual Raw'!C6 -> 853.7166 | C24: ='Annual Raw'!D6 -> 956.7624 | D24: ='Annual Raw'!E6 -> 1342.1175 | E24: ='Annual Raw'!F6 -> 1437.5206 | F24: ='Annual Raw'!G6 -> 1550.7879 | G24: ='Annual Raw'!H6 -> 2022.7089 | H24: ='Annual Raw'!I6 -> 2598.301 | I24: ='Annual Raw'!J6 -> 3264.3878 | ... AA24: ='Annual Raw'!AB6 -> 14244.5 | AB24: =+SUM(CM24:CP24) -> 17093.4 | AC24: =+SUM(CQ24:CT24) -> 19657.41 | AD24: =+SUM(CU24:CX24) -> 22606.021 | AE24: =+SUM(CY24:DB24) -> 25996.925 | AI24: ='QTR Raw'!C6+'QTR Raw'!C8 -> 1616.82 | AJ24: ='QTR Raw'!D6+'QTR Raw'!D8 -> 1164.49 | AK24: ='QTR Raw'!E6+'QTR Raw'!E8 -> 1152.54 | AL24: ='QTR Raw'!F6+'QTR Raw'!F8 -> 1597.11 | AM24: ='QTR Raw'!G6+'QTR Raw'!G8 -> 1603.3 | AN24: ='QTR Raw'!H6+'QTR Raw'!H8 -> 1080.53 | AO24: ='QTR Raw'!I6+'QTR Raw'!I8 -> 1119.4 | AP24: ='QTR Raw'!J6+'QTR Raw'!J8 -> 1462.81 | ... CL24: ='QTR Raw'!BF6+'QTR Raw'!BF8 -> 4887.83 | CM24: =+CI26+(CM27*CI26) -> 4726.296 | CN24: =+CJ26+(CN27*CJ26) -> 2816.784 | CO24: =+CK26+(CO27*CK26) -> 3684.924 | CP24: =+CL26+(CP27*CL26) -> 5865.396 | CQ24: =+CM26+(CQ27*CM26) -> 5435.2404 | CR24: =+CN26+(CR27*CN26) -> 3239.3016 | CS24: =+CO26+(CS27*CO26) -> 4237.6626 | CT24: =+CP26+(CT27*CP26) -> 6745.2054 | ... DB24: =+CX26+(DB27*CX26) -> 8920.5341 | DF24: 5268.1538
A25: Less: Exise Duty | B25: ='Annual Raw'!C7+'Annual Raw'!C8+'Annual Raw'!C9 -> 89.1636 | C25: ='Annual Raw'!D7+'Annual Raw'!D8+'Annual Raw'!D9 -> 75.602 | D25: ='Annual Raw'!E7+'Annual Raw'!E8+'Annual Raw'!E9 -> 86.575 | E25: ='Annual Raw'!F7+'Annual Raw'!F8+'Annual Raw'!F9 -> 77.567 | F25: ='Annual Raw'!G7+'Annual Raw'!G8+'Annual Raw'!G9 -> 73.7203 | G25: ='Annual Raw'!H7+'Annual Raw'!H8+'Annual Raw'!H9 -> 68.2717 | H25: ='Annual Raw'!I7+'Annual Raw'!I8+'Annual Raw'!I9 -> 71.564 | I25: ='Annual Raw'!J7+'Annual Raw'!J8+'Annual Raw'!J9 -> 61.4611 | ... AA25: ='Annual Raw'!AB7+'Annual Raw'!AB8+'Annual Raw'!AB9 -> 0 | AB25: =+SUM(CM25:CP25) -> 0 | AC25: =+SUM(CQ25:CT25) -> 0 | AD25: =+SUM(CU25:CX25) -> 0 | AE25: =+SUM(CY25:DB25) -> 0 | AI25: =+'QTR Raw'!C20+'QTR Raw'!C19+'QTR Raw'!C13+'QTR Raw'!C7 -> 0 | AJ25: =+'QTR Raw'!D20+'QTR Raw'!D19+'QTR Raw'!D13+'QTR Raw'!D7 -> 0 | AK25: =+'QTR Raw'!E20+'QTR Raw'!E19+'QTR Raw'!E13+'QTR Raw'!E7 -> 0 | AL25: =+'QTR Raw'!F20+'QTR Raw'!F19+'QTR Raw'!F13+'QTR Raw'!F7 -> 0 | AM25: =+'QTR Raw'!G20+'QTR Raw'!G19+'QTR Raw'!G13+'QTR Raw'!G7 -> 0 | AN25: =+'QTR Raw'!H20+'QTR Raw'!H19+'QTR Raw'!H13+'QTR Raw'!H7 -> 0 | AO25: =+'QTR Raw'!I20+'QTR Raw'!I19+'QTR Raw'!I13+'QTR Raw'!I7 -> 0 | AP25: =+'QTR Raw'!J20+'QTR Raw'!J19+'QTR Raw'!J13+'QTR Raw'!J7 -> 0 | ... CL25: =+'QTR Raw'!BF20+'QTR Raw'!BF19+'QTR Raw'!BF13+'QTR Raw'!BF7 -> 0 | DF25: 0
A26: Net Revenue | B26: =+B24-B25 -> 764.553 | C26: =+C24-C25 -> 881.1604 | D26: =+D24-D25 -> 1255.5425 | E26: =+E24-E25 -> 1359.9536 | F26: =+F24-F25 -> 1477.0676 | G26: =+G24-G25 -> 1954.4372 | H26: =+H24-H25 -> 2526.737 | I26: =+I24-I25 -> 3202.9267 | ... AE26: =+AE24-AE25 -> 25996.925 | AI26: =+AI24-AI25 -> 1616.82 | AJ26: =+AJ24-AJ25 -> 1164.49 | AK26: =+AK24-AK25 -> 1152.54 | AL26: =+AL24-AL25 -> 1597.11 | AM26: =+AM24-AM25 -> 1603.3 | AN26: =+AN24-AN25 -> 1080.53 | AO26: =+AO24-AO25 -> 1119.4 | AP26: =+AP24-AP25 -> 1462.81 | ... DB26: =+DB24-DB25 -> 8920.5341 | DF26: 5268.1538
A27: Net Revenue YOY% | C27: =C26/B26-1 -> 0.15251709 | D27: =D26/C26-1 -> 0.42487395 | E27: =E26/D26-1 -> 0.083160148 | F27: =F26/E26-1 -> 0.086116173 | G27: =G26/F26-1 -> 0.32318737 | H27: =H26/G26-1 -> 0.29282077 | I27: =I26/H26-1 -> 0.2676138 | J27: =J26/I26-1 -> 0.35060781 | ... AE27: =AE26/AD26-1 -> 0.15 | AM27: =+IF(AI26<0,1-AM26/AI26,AM26/AI26-1) -> -0.0083620935 | AN27: =+IF(AJ26<0,1-AN26/AJ26,AN26/AJ26-1) -> -0.072100233 | AO27: =+IF(AK26<0,1-AO26/AK26,AO26/AK26-1) -> -0.028753883 | AP27: =+IF(AL26<0,1-AP26/AL26,AP26/AL26-1) -> -0.084089386 | AQ27: =+IF(AM26<0,1-AQ26/AM26,AQ26/AM26-1) -> 0.096076842 | AR27: =+IF(AN26<0,1-AR26/AN26,AR26/AN26-1) -> -0.088734232 | AS27: =+IF(AO26<0,1-AS26/AO26,AS26/AO26-1) -> -0.1503216 | AT27: =+IF(AP26<0,1-AT26/AP26,AT26/AP26-1) -> 0.018567005 | ... CL27: =+IF(CH26<0,1-CL26/CH26,CL26/CH26-1) -> 0.025226741 | CM27: 0.2 | CN27: 0.2 | CO27: 0.2 | CP27: 0.2 | CQ27: 0.15 | CR27: 0.15 | CS27: 0.15 | CT27: 0.15 | CU27: =+AVERAGE(CQ27:CT27) -> 0.15 | CV27: =+AVERAGE(CR27:CU27) -> 0.15 | CW27: =+AVERAGE(CS27:CV27) -> 0.15 | CX27: =+AVERAGE(CT27:CW27) -> 0.15 | CY27: =+AVERAGE(CU27:CX27) -> 0.15 | CZ27: =+AVERAGE(CV27:CY27) -> 0.15 | DA27: =+AVERAGE(CW27:CZ27) -> 0.15 | DB27: =+AVERAGE(CX27:DA27) -> 0.15 | DF27: 0.105
A28: Net Revenue QOQ% | AJ28: =+IF(AI26<0,1-AJ26/AI26,AJ26/AI26-1) -> -0.27976522 | AK28: =+IF(AJ26<0,1-AK26/AJ26,AK26/AJ26-1) -> -0.010262003 | AL28: =+IF(AK26<0,1-AL26/AK26,AL26/AK26-1) -> 0.38573065 | AM28: =+IF(AL26<0,1-AM26/AL26,AM26/AL26-1) -> 0.0038757506 | AN28: =+IF(AM26<0,1-AN26/AM26,AN26/AM26-1) -> -0.32605875 | AO28: =+IF(AN26<0,1-AO26/AN26,AO26/AN26-1) -> 0.035973087 | AP28: =+IF(AO26<0,1-AP26/AO26,AP26/AO26-1) -> 0.30678042 | AQ28: =+IF(AP26<0,1-AQ26/AP26,AQ26/AP26-1) -> 0.20134536 | ... CL28: =+IF(CK26<0,1-CL26/CK26,CL26/CK26-1) -> 0.59172781 | CM28: =+CM26/CL26-1 -> -0.033048203 | CN28: =+CN26/CM26-1 -> -0.40401871 | CO28: =+CO26/CN26-1 -> 0.30820255 | CP28: =+CP26/CO26-1 -> 0.59172781 | CQ28: =+CQ26/CP26-1 -> -0.073337862 | CR28: =+CR26/CQ26-1 -> -0.40401871 | CS28: =+CS26/CR26-1 -> 0.30820255 | CT28: =+CT26/CS26-1 -> 0.59172781 | ... DB28: =+DB26/DA26-1 -> 0.59172781 | DF28: 0.71558072
A29: Increase/Decrease in Stock | B29: ='Annual Raw'!C11 -> 29.476 | C29: ='Annual Raw'!D11 -> 65.8875 | D29: ='Annual Raw'!E11 -> 40.0038 | E29: ='Annual Raw'!F11 -> 10.4407 | F29: ='Annual Raw'!G11 -> -346.5813 | G29: ='Annual Raw'!H11 -> -608.1094 | H29: ='Annual Raw'!I11 -> 0 | I29: ='Annual Raw'!J11 -> 0 | ... AA29: ='Annual Raw'!AB11 -> -269.75 | AB29: =+SUM(CM29:CP29) -> 0 | AC29: =+SUM(CQ29:CT29) -> 0 | AD29: =+SUM(CU29:CX29) -> 0 | AE29: =+SUM(CY29:DB29) -> 0 | AI29: ='QTR Raw'!C10 -> 37.85 | AJ29: ='QTR Raw'!D10 -> -21.29 | AK29: ='QTR Raw'!E10 -> -67.99 | AL29: ='QTR Raw'!F10 -> -84.79 | AM29: ='QTR Raw'!G10 -> 192.03 | AN29: ='QTR Raw'!H10 -> -63.66 | AO29: ='QTR Raw'!I10 -> -82.12 | AP29: ='QTR Raw'!J10 -> 71.7 | ... CL29: ='QTR Raw'!BF10 -> 88.31 | DF29: -269.75
A30: Purchase of Finished Goods | B30: 0 | C30: 0 | D30: 0 | E30: 0 | F30: 0 | G30: 0 | H30: 0 | I30: 0 | J30: 0 | K30: 0 | L30: 0 | M30: 0 | N30: 0 | O30: 0 | P30: 0 | Q30: 0 | R30: 0 | S30: 0 | T30: 0 | U30: 0 | V30: 0 | W30: 0 | X30: 0 | Y30: 0 | Z30: 0 | AA30: 0 | AB30: =+SUM(CM30:CP30) -> 0 | AC30: =+SUM(CQ30:CT30) -> 0 | AD30: =+SUM(CU30:CX30) -> 0 | AE30: =+SUM(CY30:DB30) -> 0 | AI30: ='QTR Raw'!C12 -> 176.4 | AJ30: ='QTR Raw'!D12 -> 89.98 | AK30: ='QTR Raw'!E12 -> 101.68 | AL30: ='QTR Raw'!F12 -> 218.44 | AM30: ='QTR Raw'!G12 -> 131.3 | AN30: ='QTR Raw'!H12 -> 161.37 | AO30: ='QTR Raw'!I12 -> 175.73 | AP30: ='QTR Raw'!J12 -> 104.81 | ... CL30: ='QTR Raw'!BF12 -> 1158.04 | DF30: 3083.26
A31: Raw Material Consumed | B31: ='Annual Raw'!C12 -> 632.75 | C31: ='Annual Raw'!D12 -> 612.7476 | D31: ='Annual Raw'!E12 -> 974.4928 | E31: ='Annual Raw'!F12 -> 991.7907 | F31: ='Annual Raw'!G12 -> 1434.6836 | G31: ='Annual Raw'!H12 -> 2065.1993 | H31: ='Annual Raw'!I12 -> 1878.1579 | I31: ='Annual Raw'!J12 -> 2338.4082 | ... AA31: ='Annual Raw'!AB12 -> 11339.53 | AB31: =+SUM(CM31:CP31) -> 12949.998 | AC31: =+SUM(CQ31:CT31) -> 14878.298 | AD31: =+SUM(CU31:CX31) -> 17107.062 | AE31: =+SUM(CY31:DB31) -> 19672.536 | AI31: ='QTR Raw'!C11 -> 990.66 | AJ31: ='QTR Raw'!D11 -> 779.77 | AK31: ='QTR Raw'!E11 -> 847.57 | AL31: ='QTR Raw'!F11 -> 1098.75 | AM31: ='QTR Raw'!G11 -> 900.11 | AN31: ='QTR Raw'!H11 -> 673.43 | AO31: ='QTR Raw'!I11 -> 679.11 | AP31: ='QTR Raw'!J11 -> 910.44 | ... CL31: ='QTR Raw'!BF11 -> 2635.2 | CM31: =+CM26-CM32 -> 3598.6735 | CN31: =+CN26-CN32 -> 2129.5928 | CO31: =+CO26-CO32 -> 2790.1422 | CP31: =+CP26-CP32 -> 4431.5896 | CQ31: =+CQ26-CQ32 -> 4117.4365 | CR31: =+CR26-CR32 -> 2450.7806 | CS31: =+CS26-CS32 -> 3206.6894 | CT31: =+CT26-CT32 -> 5103.3911 | ... DB31: =+DB26-DB32 -> 6750.363 | DF31: 3999.4552
A32: Gross Profit | B32: =B26-B29-B31-B30 -> 102.327 | C32: =C26-C29-C31-C30 -> 202.5253 | D32: =D26-D29-D31-D30 -> 241.0459 | E32: =E26-E29-E31-E30 -> 357.7222 | F32: =F26-F29-F31-F30 -> 388.9653 | G32: =G26-G29-G31-G30 -> 497.3473 | H32: =H26-H29-H31-H30 -> 648.5791 | I32: =I26-I29-I31-I30 -> 864.5185 | ... AE32: =AE26-AE29-AE31-AE30 -> 6324.3886 | AI32: =AI26-AI29-AI31-AI30 -> 411.91 | AJ32: =AJ26-AJ29-AJ31-AJ30 -> 316.03 | AK32: =AK26-AK29-AK31-AK30 -> 271.28 | AL32: =AL26-AL29-AL31-AL30 -> 364.71 | AM32: =AM26-AM29-AM31-AM30 -> 379.86 | AN32: =AN26-AN29-AN31-AN30 -> 309.39 | AO32: =AO26-AO29-AO31-AO30 -> 346.68 | AP32: =AP26-AP29-AP31-AP30 -> 375.86 | ... CL32: =CL26-CL29-CL31-CL30 -> 1006.28 | CM32: =+CM33*CM26 -> 1127.6225 | CN32: =+CN33*CN26 -> 687.19122 | CO32: =+CO33*CO26 -> 894.78178 | CP32: =+CP33*CP26 -> 1433.8064 | CQ32: =+CQ33*CQ26 -> 1317.8039 | CR32: =+CR33*CR26 -> 788.52101 | CS32: =+CS33*CS26 -> 1030.9732 | CT32: =+CT33*CT26 -> 1641.8143 | ... DB32: =+DB33*DB26 -> 2170.1711 | DF32: 1268.6986
A33: GP% | B33: =B32/B26 -> 0.13383899 | C33: =C32/C26 -> 0.22983931 | D33: =D32/D26 -> 0.19198546 | E33: =E32/E26 -> 0.26304 | F33: =F32/F26 -> 0.26333615 | G33: =G32/G26 -> 0.25447085 | H33: =H32/H26 -> 0.25668643 | I33: =I32/I26 -> 0.26991517 | ... AE33: =AE32/AE26 -> 0.24327449 | AI33: =AI32/AI26 -> 0.25476553 | AJ33: =AJ32/AJ26 -> 0.27138919 | AK33: =AK32/AK26 -> 0.23537578 | AL33: =AL32/AL26 -> 0.22835622 | AM33: =AM32/AM26 -> 0.23692384 | AN33: =AN32/AN26 -> 0.28633171 | AO33: =AO32/AO26 -> 0.30970163 | AP33: =AP32/AP26 -> 0.25694383 | ... CL33: =CL32/CL26 -> 0.20587459 | CM33: =AVERAGE(CI33:CL33)*1.05 -> 0.23858483 | CN33: =AVERAGE(CJ33:CM33)*1.05 -> 0.24396305 | CO33: =AVERAGE(CK33:CN33)*1.05 -> 0.24282232 | CP33: =AVERAGE(CL33:CO33)*1.05 -> 0.24445176 | CQ33: =AVERAGE(CM33:CP33) -> 0.24245549 | CR33: =AVERAGE(CN33:CQ33) -> 0.24342315 | CS33: =AVERAGE(CO33:CR33) -> 0.24328818 | CT33: =AVERAGE(CP33:CS33) -> 0.24340464 | CU33: =AVERAGE(CQ33:CT33) -> 0.24314287 | CV33: =AVERAGE(CR33:CU33) -> 0.24331471 | CW33: =AVERAGE(CS33:CV33) -> 0.2432876 | CX33: =AVERAGE(CT33:CW33) -> 0.24328745 | ... DB33: =AVERAGE(CX33:DA33) -> 0.24327816 | DF33: 0.24082413
A34: GP YOY% | C34: =+IF(B32<0,1-C32/B32,C32/B32-1) -> 0.97919708 | D34: =+IF(C32<0,1-D32/C32,D32/C32-1) -> 0.19020142 | E34: =+IF(D32<0,1-E32/D32,E32/D32-1) -> 0.48404184 | F34: =+IF(E32<0,1-F32/E32,F32/E32-1) -> 0.087339002 | G34: =+IF(F32<0,1-G32/F32,G32/F32-1) -> 0.27864182 | H34: =+IF(G32<0,1-H32/G32,H32/G32-1) -> 0.30407685 | I34: =+IF(H32<0,1-I32/H32,I32/H32-1) -> 0.33294227 | J34: =+IF(I32<0,1-J32/I32,J32/I32-1) -> 0.3387422 | ... AE34: =+IF(AD32<0,1-AE32/AD32,AE32/AD32-1) -> 0.15010633 | AM34: =+IF(AI32<0,1-AM32/AI32,AM32/AI32-1) -> -0.077808259 | AN34: =+IF(AJ32<0,1-AN32/AJ32,AN32/AJ32-1) -> -0.021010664 | AO34: =+IF(AK32<0,1-AO32/AK32,AO32/AK32-1) -> 0.27794161 | AP34: =+IF(AL32<0,1-AP32/AL32,AP32/AL32-1) -> 0.030572235 | AQ34: =+IF(AM32<0,1-AQ32/AM32,AQ32/AM32-1) -> 0.2426157 | AR34: =+IF(AN32<0,1-AR32/AN32,AR32/AN32-1) -> 0.10714632 | AS34: =+IF(AO32<0,1-AS32/AO32,AS32/AO32-1) -> -0.096775124 | AT34: =+IF(AP32<0,1-AT32/AP32,AT32/AP32-1) -> 0.21840579 | ... CL34: =+IF(CH32<0,1-CL32/CH32,CL32/CH32-1) -> -0.015564621 | CM34: =+CM32/CI32-1 -> 0.31273068 | CN34: =+CN32/CJ32-1 -> 0.17899876 | CO34: =+CO32/CK32-1 -> 0.231481 | CP34: =+CP32/CL32-1 -> 0.42485825 | CQ34: =+CQ32/CM32-1 -> 0.16865692 | CR34: =+CR32/CN32-1 -> 0.14745501 | CS34: =+CS32/CO32-1 -> 0.15220631 | CT34: =+CT32/CP32-1 -> 0.14507396 | ... DB34: =+DB32/CX32-1 -> 0.14995607 | DF34: 0.2411573
A35: GP QOQ% | AJ35: =+IF(AI32<0,1-AJ32/AI32,AJ32/AI32-1) -> -0.23276929 | AK35: =+IF(AJ32<0,1-AK32/AJ32,AK32/AJ32-1) -> -0.14160048 | AL35: =+IF(AK32<0,1-AL32/AK32,AL32/AK32-1) -> 0.34440431 | AM35: =+IF(AL32<0,1-AM32/AL32,AM32/AL32-1) -> 0.041539854 | AN35: =+IF(AM32<0,1-AN32/AM32,AN32/AM32-1) -> -0.18551572 | AO35: =+IF(AN32<0,1-AO32/AN32,AO32/AN32-1) -> 0.12052749 | AP35: =+IF(AO32<0,1-AP32/AO32,AP32/AO32-1) -> 0.08416984 | AQ35: =+IF(AP32<0,1-AQ32/AP32,AQ32/AP32-1) -> 0.25583994 | ... CL35: =+IF(CK32<0,1-CL32/CK32,CL32/CK32-1) -> 0.38493511 | CM35: =+CM32/CL32-1 -> 0.12058525 | CN35: =+CN32/CM32-1 -> -0.39058399 | CO35: =+CO32/CN32-1 -> 0.30208558 | CP35: =+CP32/CO32-1 -> 0.60240898 | CQ35: =+CQ32/CP32-1 -> -0.08090527 | CR35: =+CR32/CQ32-1 -> -0.40164009 | CS35: =+CS32/CR32-1 -> 0.30747717 | CT35: =+CT32/CS32-1 -> 0.59248979 | ... DB35: =+DB32/DA32-1 -> 0.59171546 | DF35: 0.74609969
A36: Employee Cost | B36: ='Annual Raw'!C14 -> 100.3037 | C36: ='Annual Raw'!D14 -> 110.8011 | D36: ='Annual Raw'!E14 -> 134.5882 | E36: ='Annual Raw'!F14 -> 135.1971 | F36: ='Annual Raw'!G14 -> 153.6958 | G36: ='Annual Raw'!H14 -> 190.9696 | H36: ='Annual Raw'!I14 -> 258.6337 | I36: ='Annual Raw'!J14 -> 297.6833 | ... AA36: ='Annual Raw'!AB14 -> 938.59 | AB36: =+SUM(CM36:CP36) -> 1004.2913 | AC36: =+SUM(CQ36:CT36) -> 1074.5917 | AD36: =+SUM(CU36:CX36) -> 1149.8131 | AE36: =+SUM(CY36:DB36) -> 1230.3 | AI36: ='QTR Raw'!C16 -> 164.49 | AJ36: ='QTR Raw'!D16 -> 162.99 | AK36: ='QTR Raw'!E16 -> 147.26 | AL36: ='QTR Raw'!F16 -> 157.79 | AM36: ='QTR Raw'!G16 -> 164.86 | AN36: ='QTR Raw'!H16 -> 152.65 | AO36: ='QTR Raw'!I16 -> 146.47 | AP36: ='QTR Raw'!J16 -> 130.71 | ... CL36: ='QTR Raw'!BF16 -> 242.68 | CM36: =CI36*107% -> 246.6457 | CN36: =CJ36*107% -> 257.6132 | CO36: =CK36*107% -> 240.3648 | CP36: =CL36*107% -> 259.6676 | CQ36: =CM36*107% -> 263.9109 | CR36: =CN36*107% -> 275.64612 | CS36: =CO36*107% -> 257.19034 | CT36: =CP36*107% -> 277.84433 | ... DB36: =CX36*107% -> 318.10398 | DF36: 233.795
A37: General and Administration Expenses | B37: ='Annual Raw'!C17 -> -68.082 | C37: ='Annual Raw'!D17 -> 19.8816 | D37: ='Annual Raw'!E17 -> 12.0623 | E37: ='Annual Raw'!F17 -> 115.5002 | F37: ='Annual Raw'!G17 -> 122.9156 | G37: ='Annual Raw'!H17 -> 138.0629 | H37: ='Annual Raw'!I17 -> 184.709 | I37: ='Annual Raw'!J17 -> 209.0765 | ... AA37: ='Annual Raw'!AB17 -> 674.14 | AB37: =+SUM(CM37:CP37) -> 0 | AC37: =+SUM(CQ37:CT37) -> 0 | AD37: =+SUM(CU37:CX37) -> 0 | AE37: =+SUM(CY37:DB37) -> 0 | AI37: ='QTR Raw'!C17 -> 0 | AJ37: ='QTR Raw'!D17 -> 0 | AK37: ='QTR Raw'!E17 -> 0 | AL37: ='QTR Raw'!F17 -> 0 | AM37: ='QTR Raw'!G17 -> 0 | AN37: ='QTR Raw'!H17 -> 0 | AO37: ='QTR Raw'!I17 -> 0 | AP37: ='QTR Raw'!J17 -> 0 | ... CL37: ='QTR Raw'!BF17 -> 0 | DF37: 0
A38: Miscellaneous Expenses | B38: ='Annual Raw'!C19-'Annual Raw'!C20 -> 6.9943 | C38: ='Annual Raw'!D19-'Annual Raw'!D20 -> 9.6995 | D38: ='Annual Raw'!E19-'Annual Raw'!E20 -> 10.1377 | E38: ='Annual Raw'!F19-'Annual Raw'!F20 -> 17.7687 | F38: ='Annual Raw'!G19-'Annual Raw'!G20 -> 15.1924 | G38: ='Annual Raw'!H19-'Annual Raw'!H20 -> 7.6245 | H38: ='Annual Raw'!I19-'Annual Raw'!I20 -> 15.9955 | I38: ='Annual Raw'!J19-'Annual Raw'!J20 -> 12.1042 | ... AA38: ='Annual Raw'!AB19-'Annual Raw'!AB20 -> 191.46 | AB38: =+SUM(CM38:CP38) -> 0 | AC38: =+SUM(CQ38:CT38) -> 0 | AD38: =+SUM(CU38:CX38) -> 0 | AE38: =+SUM(CY38:DB38) -> 0 | AI38: =+'QTR Raw'!C21 -> 0 | AJ38: =+'QTR Raw'!D21 -> 0 | AK38: =+'QTR Raw'!E21 -> 0 | AL38: =+'QTR Raw'!F21 -> 0 | AM38: =+'QTR Raw'!G21 -> 0 | AN38: =+'QTR Raw'!H21 -> 0 | AO38: =+'QTR Raw'!I21 -> 0 | AP38: =+'QTR Raw'!J21 -> 0 | ... CL38: =+'QTR Raw'!BF21 -> 0 | DF38: 0
A39: Other Manufacturing Expenses | B39: ='Annual Raw'!C15+'Annual Raw'!C16 -> 7.5553 | C39: ='Annual Raw'!D15+'Annual Raw'!D16 -> 8.841 | D39: ='Annual Raw'!E15+'Annual Raw'!E16 -> 7.32 | E39: ='Annual Raw'!F15+'Annual Raw'!F16 -> 7.5075 | F39: ='Annual Raw'!G15+'Annual Raw'!G16 -> 6.7282 | G39: ='Annual Raw'!H15+'Annual Raw'!H16 -> 7.0118 | H39: ='Annual Raw'!I15+'Annual Raw'!I16 -> 10.0716 | I39: ='Annual Raw'!J15+'Annual Raw'!J16 -> 12.8489 | ... AA39: ='Annual Raw'!AB15+'Annual Raw'!AB16 -> 117.42 | AB39: =+SUM(CM39:CP39) -> 2089.7031 | AC39: =+SUM(CQ39:CT39) -> 2404.2659 | AD39: =+SUM(CU39:CX39) -> 2847.4853 | AE39: =+SUM(CY39:DB39) -> 3364.969 | AI39: ='QTR Raw'!C14 -> 153.51 | AJ39: ='QTR Raw'!D14 -> 109.06 | AK39: ='QTR Raw'!E14 -> 99.76 | AL39: ='QTR Raw'!F14 -> 125.13 | AM39: ='QTR Raw'!G14 -> 164.53 | AN39: ='QTR Raw'!H14 -> 114.47 | AO39: ='QTR Raw'!I14 -> 132.71 | AP39: ='QTR Raw'!J14 -> 139.78 | ... CL39: ='QTR Raw'!BF14 -> 542.93 | CM39: =CM42-CM36-CM37-CM38-CM40-CM41 -> 621.0338 | CN39: =CN42-CN36-CN37-CN38-CN40-CN41 -> 267.1634 | CO39: =CO42-CO36-CO37-CO38-CO40-CO41 -> 416.51385 | CP39: =CP42-CP36-CP37-CP38-CP40-CP41 -> 784.99204 | CQ39: =CQ42-CQ36-CQ37-CQ38-CQ40-CQ41 -> 703.19574 | CR39: =CR42-CR36-CR37-CR38-CR40-CR41 -> 302.08067 | CS39: =CS42-CS36-CS37-CS38-CS40-CS41 -> 490.25072 | CT39: =CT42-CT36-CT37-CT38-CT40-CT41 -> 908.73882 | ... DB39: =DB42-DB36-DB37-DB38-DB40-DB41 -> 1258.4958 | DF39: 669.67049
A40: Power & Fuel Cost | B40: ='Annual Raw'!C13 -> 6.6359 | C40: ='Annual Raw'!D13 -> 5.844 | D40: ='Annual Raw'!E13 -> 5.1779 | E40: ='Annual Raw'!F13 -> 4.9364 | F40: ='Annual Raw'!G13 -> 4.3908 | G40: ='Annual Raw'!H13 -> 4.1447 | H40: ='Annual Raw'!I13 -> 4.258 | I40: ='Annual Raw'!J13 -> 4.0643 | ... AA40: ='Annual Raw'!AB13 -> 30.29 | AB40: =+SUM(CM40:CP40) -> 0 | AC40: =+SUM(CQ40:CT40) -> 0 | AD40: =+SUM(CU40:CX40) -> 0 | AE40: =+SUM(CY40:DB40) -> 0 | AI40: ='QTR Raw'!C15 -> 0 | AJ40: ='QTR Raw'!D15 -> 0 | AK40: ='QTR Raw'!E15 -> 0 | AL40: ='QTR Raw'!F15 -> 0 | AM40: ='QTR Raw'!G15 -> 0 | AN40: ='QTR Raw'!H15 -> 0 | AO40: ='QTR Raw'!I15 -> 0 | AP40: ='QTR Raw'!J15 -> 0 | ... CL40: ='QTR Raw'!BF15 -> 0 | DF40: 0
A41: Selling and Distribution Expenses | B41: ='Annual Raw'!C18 -> 21.4302 | C41: ='Annual Raw'!D18 -> 25.2276 | D41: ='Annual Raw'!E18 -> 36.8914 | E41: ='Annual Raw'!F18 -> 35.8005 | F41: ='Annual Raw'!G18 -> 33.266 | G41: ='Annual Raw'!H18 -> 37.9538 | H41: ='Annual Raw'!I18 -> 46.844 | I41: ='Annual Raw'!J18 -> 75.7394 | ... AA41: ='Annual Raw'!AB18 -> 620.72 | AB41: =+SUM(CM41:CP41) -> 0 | AC41: =+SUM(CQ41:CT41) -> 0 | AD41: =+SUM(CU41:CX41) -> 0 | AE41: =+SUM(CY41:DB41) -> 0 | AI41: ='QTR Raw'!C18 -> 0 | AJ41: ='QTR Raw'!D18 -> 0 | AK41: ='QTR Raw'!E18 -> 0 | AL41: ='QTR Raw'!F18 -> 0 | AM41: ='QTR Raw'!G18 -> 0 | AN41: ='QTR Raw'!H18 -> 0 | AO41: ='QTR Raw'!I18 -> 0 | AP41: ='QTR Raw'!J18 -> 0 | ... CL41: ='QTR Raw'!BF18 -> 0 | DF41: 0
A42: Total Cost | B42: =+SUM(B36:B41) -> 74.8374 | C42: =+SUM(C36:C41) -> 180.2948 | D42: =+SUM(D36:D41) -> 206.1775 | E42: =+SUM(E36:E41) -> 316.7104 | F42: =+SUM(F36:F41) -> 336.1888 | G42: =+SUM(G36:G41) -> 385.7673 | H42: =+SUM(H36:H41) -> 520.5118 | I42: =+SUM(I36:I41) -> 611.5166 | ... AE42: =+SUM(AE36:AE41) -> 4595.269 | AI42: =+SUM(AI36:AI41) -> 318 | AJ42: =+SUM(AJ36:AJ41) -> 272.05 | AK42: =+SUM(AK36:AK41) -> 247.02 | AL42: =+SUM(AL36:AL41) -> 282.92 | AM42: =+SUM(AM36:AM41) -> 329.39 | AN42: =+SUM(AN36:AN41) -> 267.12 | AO42: =+SUM(AO36:AO41) -> 279.18 | AP42: =+SUM(AP36:AP41) -> 270.49 | ... CL42: =+SUM(CL36:CL41) -> 785.61 | CM42: =CM43*CM26 -> 867.6795 | CN42: =CN43*CN26 -> 524.7766 | CO42: =CO43*CO26 -> 656.87865 | CP42: =CP43*CP26 -> 1044.6596 | CQ42: =CQ43*CQ26 -> 967.10664 | CR42: =CR43*CR26 -> 577.7268 | CS42: =CS43*CS26 -> 747.44105 | CT42: =CT43*CT26 -> 1186.5831 | ... DB42: =DB43*DB26 -> 1576.5998 | DF42: 903.46549
A43: Cost % | B43: =B42/B26 -> 0.097883862 | C43: =C42/C26 -> 0.20461065 | D43: =D42/D26 -> 0.16421388 | E43: =E42/E26 -> 0.23288324 | F43: =F42/F26 -> 0.22760556 | G43: =G42/G26 -> 0.19738025 | H43: =H42/H26 -> 0.20600157 | I43: =I42/I26 -> 0.19092432 | ... AE43: =AE42/AE26 -> 0.17676202 | AI43: =AI42/AI26 -> 0.19668238 | AJ43: =AJ42/AJ26 -> 0.23362159 | AK43: =AK42/AK26 -> 0.21432662 | AL43: =AL42/AL26 -> 0.17714497 | AM43: =AM42/AM26 -> 0.20544502 | AN43: =AN42/AN26 -> 0.24721202 | AO43: =AO42/AO26 -> 0.24940147 | AP43: =AP42/AP26 -> 0.18491123 | ... CL43: =CL42/CL26 -> 0.16072777 | CM43: =AVERAGE(CI43:CL43)*1.005 -> 0.18358552 | CN43: =AVERAGE(CJ43:CM43)*1.005 -> 0.18630346 | CO43: =AVERAGE(CK43:CN43)*1.005 -> 0.17826111 | CP43: =AVERAGE(CL43:CO43)*1.005 -> 0.17810556 | CQ43: =AVERAGE(CM43:CP43)*0.98 -> 0.17793263 | CR43: =AVERAGE(CN43:CQ43)*0.99 -> 0.17834918 | CS43: =AVERAGE(CO43:CR43)*0.99 -> 0.1763805 | CT43: =AVERAGE(CP43:CS43)*0.99 -> 0.17591505 | CU43: =AVERAGE(CQ43:CT43) -> 0.17714434 | CV43: =AVERAGE(CR43:CU43) -> 0.17694727 | CW43: =AVERAGE(CS43:CV43) -> 0.17659679 | CX43: =AVERAGE(CT43:CW43) -> 0.17665086 | CY43: =AVERAGE(CU43:CX43) -> 0.17683482 | CZ43: =AVERAGE(CV43:CY43) -> 0.17675744 | DA43: =AVERAGE(CW43:CZ43) -> 0.17670998 | DB43: =AVERAGE(CX43:DA43) -> 0.17673827 | DF43: 0.17149566
A44: EBITDA | B44: =B32-B42 -> 27.4896 | C44: =C32-C42 -> 22.2305 | D44: =D32-D42 -> 34.8684 | E44: =E32-E42 -> 41.0118 | F44: =F32-F42 -> 52.7765 | G44: =G32-G42 -> 111.58 | H44: =H32-H42 -> 128.0673 | I44: =I32-I42 -> 253.0019 | ... AE44: =AE32-AE42 -> 1729.1196 | AI44: =AI32-AI42 -> 93.91 | AJ44: =AJ32-AJ42 -> 43.98 | AK44: =AK32-AK42 -> 24.26 | AL44: =AL32-AL42 -> 81.79 | AM44: =AM32-AM42 -> 50.47 | AN44: =AN32-AN42 -> 42.27 | AO44: =AO32-AO42 -> 67.5 | AP44: =AP32-AP42 -> 105.37 | ... DB44: =DB32-DB42 -> 593.57134 | DF44: 365.23308
...

Sheet QTR Raw
A1: ='Annual Raw'!A1 -> 100575 | B1: X | C1: 201206 | D1: 201209 | E1: 201212 | F1: 201303 | G1: 201306 | H1: 201309 | I1: 201312 | J1: 201403 | K1: 201406 | L1: 201409 | M1: 201412 | N1: 201503 | O1: 201506 | P1: 201509 | Q1: 201512 | R1: 201603 | S1: 201606 | T1: 201609 | U1: 201612 | V1: 201703 | W1: 201706 | X1: 201709 | Y1: 201712 | Z1: 201803 | AA1: 201806 | AB1: 201809 | AC1: 201812 | AD1: 201903 | AE1: 201906 | AF1: 201909 | AG1: 201912 | AH1: 202003 | AI1: 202006 | AJ1: 202009 | AK1: 202012 | AL1: 202103 | AM1: 202106 | AN1: 202109 | AO1: 202112 | AP1: 202203 | AQ1: 202206 | AR1: 202209 | AS1: 202212 | AT1: 202303 | AU1: 202306 | AV1: 202309 | AW1: 202312 | AX1: 202403 | AY1: 202406 | AZ1: 202409 | BA1: 202412 | BB1: 202503 | BC1: 202506 | BD1: 202509 | BE1: 202512 | BF1: 202603 | BG1: 202606 | BH1: 202609 | BI1: 202612 | BJ1: 202703 | BK1: 202706 | BL1: 202709 | BM1: 202712 | BN1: 202803 | BO1: 202806 | BP1: 202809 | BQ1: 202812 | BR1: 202903 | BS1: 202906 | BT1: 202909 | BU1: 202912 | BV1: 203003
A3: Field Description | B3: Field Name
A4: Company Name | B4: CD_COMPNAME | C4: =_xll.EQNXTDZ(A1,B4,C1) -> Voltas Ltd.
A5: Date End | B5: QTR_DATE_END | C5: =_xll.EQNXTDZ($A$1,$B5,C$1,$B$1) -> 201206 | D5: =_xll.EQNXTDZ($A$1,$B5,D$1,$B$1) -> 201209 | E5: =_xll.EQNXTDZ($A$1,$B5,E$1,$B$1) -> 201212 | F5: =_xll.EQNXTDZ($A$1,$B5,F$1,$B$1) -> 201303 | G5: =_xll.EQNXTDZ($A$1,$B5,G$1,$B$1) -> 201306 | H5: =_xll.EQNXTDZ($A$1,$B5,H$1,$B$1) -> 201309 | I5: =_xll.EQNXTDZ($A$1,$B5,I$1,$B$1) -> 201312 | J5: =_xll.EQNXTDZ($A$1,$B5,J$1,$B$1) -> 201403 | ... BV5: =_xll.EQNXTDZ($A$1,$B5,BV$1,$B$1) -> 0
A6: Gross Sales | B6: QTR_GROSS_SALE | C6: =_xll.EQNXTDZ($A$1,$B6,C$1,$B$1) -> 1611.57 | D6: =_xll.EQNXTDZ($A$1,$B6,D$1,$B$1) -> 1160.1 | E6: =_xll.EQNXTDZ($A$1,$B6,E$1,$B$1) -> 1150.17 | F6: =_xll.EQNXTDZ($A$1,$B6,F$1,$B$1) -> 1592.22 | G6: =_xll.EQNXTDZ($A$1,$B6,G$1,$B$1) -> 1601.78 | H6: =_xll.EQNXTDZ($A$1,$B6,H$1,$B$1) -> 1076.53 | I6: =_xll.EQNXTDZ($A$1,$B6,I$1,$B$1) -> 1114.99 | J6: =_xll.EQNXTDZ($A$1,$B6,J$1,$B$1) -> 1450.36 | ... BV6: =_xll.EQNXTDZ($A$1,$B6,BV$1,$B$1) -> 0
A7: Less: Excise Duty | B7: QTR_EXCISE_DUTY | C7: =_xll.EQNXTDZ($A$1,$B7,C$1,$B$1) -> 0 | D7: =_xll.EQNXTDZ($A$1,$B7,D$1,$B$1) -> 0 | E7: =_xll.EQNXTDZ($A$1,$B7,E$1,$B$1) -> 0 | F7: =_xll.EQNXTDZ($A$1,$B7,F$1,$B$1) -> 0 | G7: =_xll.EQNXTDZ($A$1,$B7,G$1,$B$1) -> 0 | H7: =_xll.EQNXTDZ($A$1,$B7,H$1,$B$1) -> 0 | I7: =_xll.EQNXTDZ($A$1,$B7,I$1,$B$1) -> 0 | J7: =_xll.EQNXTDZ($A$1,$B7,J$1,$B$1) -> 0 | ... BV7: =_xll.EQNXTDZ($A$1,$B7,BV$1,$B$1) -> 0
A8: Other operating income | B8: QTR_JOB_WORKS | C8: =_xll.EQNXTDZ($A$1,$B8,C$1,$B$1) -> 5.25 | D8: =_xll.EQNXTDZ($A$1,$B8,D$1,$B$1) -> 4.39 | E8: =_xll.EQNXTDZ($A$1,$B8,E$1,$B$1) -> 2.37 | F8: =_xll.EQNXTDZ($A$1,$B8,F$1,$B$1) -> 4.89 | G8: =_xll.EQNXTDZ($A$1,$B8,G$1,$B$1) -> 1.52 | H8: =_xll.EQNXTDZ($A$1,$B8,H$1,$B$1) -> 4 | I8: =_xll.EQNXTDZ($A$1,$B8,I$1,$B$1) -> 4.41 | J8: =_xll.EQNXTDZ($A$1,$B8,J$1,$B$1) -> 12.45 | ... BV8: =_xll.EQNXTDZ($A$1,$B8,BV$1,$B$1) -> 0
A9: Net Sales & Other Operating Income | B9: QTR_NET_SALES | C9: =_xll.EQNXTDZ($A$1,$B9,C$1,$B$1) -> 1616.82 | D9: =_xll.EQNXTDZ($A$1,$B9,D$1,$B$1) -> 1164.49 | E9: =_xll.EQNXTDZ($A$1,$B9,E$1,$B$1) -> 1152.54 | F9: =_xll.EQNXTDZ($A$1,$B9,F$1,$B$1) -> 1597.11 | G9: =_xll.EQNXTDZ($A$1,$B9,G$1,$B$1) -> 1603.3 | H9: =_xll.EQNXTDZ($A$1,$B9,H$1,$B$1) -> 1080.53 | I9: =_xll.EQNXTDZ($A$1,$B9,I$1,$B$1) -> 1119.4 | J9: =_xll.EQNXTDZ($A$1,$B9,J$1,$B$1) -> 1462.81 | ... BV9: =_xll.EQNXTDZ($A$1,$B9,BV$1,$B$1) -> 0
A10: (Increase) / Decrease In Stocks | B10: QTR_INC_DEC_INVENTORY | C10: =_xll.EQNXTDZ($A$1,$B10,C$1,$B$1) -> 37.85 | D10: =_xll.EQNXTDZ($A$1,$B10,D$1,$B$1) -> -21.29 | E10: =_xll.EQNXTDZ($A$1,$B10,E$1,$B$1) -> -67.99 | F10: =_xll.EQNXTDZ($A$1,$B10,F$1,$B$1) -> -84.79 | G10: =_xll.EQNXTDZ($A$1,$B10,G$1,$B$1) -> 192.03 | H10: =_xll.EQNXTDZ($A$1,$B10,H$1,$B$1) -> -63.66 | I10: =_xll.EQNXTDZ($A$1,$B10,I$1,$B$1) -> -82.12 | J10: =_xll.EQNXTDZ($A$1,$B10,J$1,$B$1) -> 71.7 | ... BV10: =_xll.EQNXTDZ($A$1,$B10,BV$1,$B$1) -> 0
A11: Cost of Services & Raw Materials | B11: QTR_RAW_MATERIAL_COST | C11: =_xll.EQNXTDZ($A$1,$B11,C$1,$B$1) -> 990.66 | D11: =_xll.EQNXTDZ($A$1,$B11,D$1,$B$1) -> 779.77 | E11: =_xll.EQNXTDZ($A$1,$B11,E$1,$B$1) -> 847.57 | F11: =_xll.EQNXTDZ($A$1,$B11,F$1,$B$1) -> 1098.75 | G11: =_xll.EQNXTDZ($A$1,$B11,G$1,$B$1) -> 900.11 | H11: =_xll.EQNXTDZ($A$1,$B11,H$1,$B$1) -> 673.43 | I11: =_xll.EQNXTDZ($A$1,$B11,I$1,$B$1) -> 679.11 | J11: =_xll.EQNXTDZ($A$1,$B11,J$1,$B$1) -> 910.44 | ... BV11: =_xll.EQNXTDZ($A$1,$B11,BV$1,$B$1) -> 0
A12: Purchase of Finished Goods | B12: QTR_PURCHASE_FIN_GOOD | C12: =_xll.EQNXTDZ($A$1,$B12,C$1,$B$1) -> 176.4 | D12: =_xll.EQNXTDZ($A$1,$B12,D$1,$B$1) -> 89.98 | E12: =_xll.EQNXTDZ($A$1,$B12,E$1,$B$1) -> 101.68 | F12: =_xll.EQNXTDZ($A$1,$B12,F$1,$B$1) -> 218.44 | G12: =_xll.EQNXTDZ($A$1,$B12,G$1,$B$1) -> 131.3 | H12: =_xll.EQNXTDZ($A$1,$B12,H$1,$B$1) -> 161.37 | I12: =_xll.EQNXTDZ($A$1,$B12,I$1,$B$1) -> 175.73 | J12: =_xll.EQNXTDZ($A$1,$B12,J$1,$B$1) -> 104.81 | ... BV12: =_xll.EQNXTDZ($A$1,$B12,BV$1,$B$1) -> 0
A13: Excise Duty | B13: QTR_EXCISE | C13: =_xll.EQNXTDZ($A$1,$B13,C$1,$B$1) -> 0 | D13: =_xll.EQNXTDZ($A$1,$B13,D$1,$B$1) -> 0 | E13: =_xll.EQNXTDZ($A$1,$B13,E$1,$B$1) -> 0 | F13: =_xll.EQNXTDZ($A$1,$B13,F$1,$B$1) -> 0 | G13: =_xll.EQNXTDZ($A$1,$B13,G$1,$B$1) -> 0 | H13: =_xll.EQNXTDZ($A$1,$B13,H$1,$B$1) -> 0 | I13: =_xll.EQNXTDZ($A$1,$B13,I$1,$B$1) -> 0 | J13: =_xll.EQNXTDZ($A$1,$B13,J$1,$B$1) -> 0 | ... BV13: =_xll.EQNXTDZ($A$1,$B13,BV$1,$B$1) -> 0
A14: Operating & Manufacturing Expenses | B14: QTR_MFG_EXPS | C14: =_xll.EQNXTDZ($A$1,$B14,C$1,$B$1) -> 153.51 | D14: =_xll.EQNXTDZ($A$1,$B14,D$1,$B$1) -> 109.06 | E14: =_xll.EQNXTDZ($A$1,$B14,E$1,$B$1) -> 99.76 | F14: =_xll.EQNXTDZ($A$1,$B14,F$1,$B$1) -> 125.13 | G14: =_xll.EQNXTDZ($A$1,$B14,G$1,$B$1) -> 164.53 | H14: =_xll.EQNXTDZ($A$1,$B14,H$1,$B$1) -> 114.47 | I14: =_xll.EQNXTDZ($A$1,$B14,I$1,$B$1) -> 132.71 | J14: =_xll.EQNXTDZ($A$1,$B14,J$1,$B$1) -> 139.78 | ... BV14: =_xll.EQNXTDZ($A$1,$B14,BV$1,$B$1) -> 0
A15: Electricity Power & Fuel Cost | B15: QTR_ELECTRICITY_POWER_FUEL | C15: =_xll.EQNXTDZ($A$1,$B15,C$1,$B$1) -> 0 | D15: =_xll.EQNXTDZ($A$1,$B15,D$1,$B$1) -> 0 | E15: =_xll.EQNXTDZ($A$1,$B15,E$1,$B$1) -> 0 | F15: =_xll.EQNXTDZ($A$1,$B15,F$1,$B$1) -> 0 | G15: =_xll.EQNXTDZ($A$1,$B15,G$1,$B$1) -> 0 | H15: =_xll.EQNXTDZ($A$1,$B15,H$1,$B$1) -> 0 | I15: =_xll.EQNXTDZ($A$1,$B15,I$1,$B$1) -> 0 | J15: =_xll.EQNXTDZ($A$1,$B15,J$1,$B$1) -> 0 | ... BV15: =_xll.EQNXTDZ($A$1,$B15,BV$1,$B$1) -> 0
A16: Employee Cost | B16: QTR_EXPLOYEE_COST | C16: =_xll.EQNXTDZ($A$1,$B16,C$1,$B$1) -> 164.49 | D16: =_xll.EQNXTDZ($A$1,$B16,D$1,$B$1) -> 162.99 | E16: =_xll.EQNXTDZ($A$1,$B16,E$1,$B$1) -> 147.26 | F16: =_xll.EQNXTDZ($A$1,$B16,F$1,$B$1) -> 157.79 | G16: =_xll.EQNXTDZ($A$1,$B16,G$1,$B$1) -> 164.86 | H16: =_xll.EQNXTDZ($A$1,$B16,H$1,$B$1) -> 152.65 | I16: =_xll.EQNXTDZ($A$1,$B16,I$1,$B$1) -> 146.47 | J16: =_xll.EQNXTDZ($A$1,$B16,J$1,$B$1) -> 130.71 | ... BV16: =_xll.EQNXTDZ($A$1,$B16,BV$1,$B$1) -> 0
... A42: Consolidated PAT(after extra items) | B42: QTR_CONS_PAT_EXITM | C42: =_xll.EQNXTDZ($A$1,$B42,C$1,$B$1) -> 79.12 | D42: =_xll.EQNXTDZ($A$1,$B42,D$1,$B$1) -> 42.93 | E42: =_xll.EQNXTDZ($A$1,$B42,E$1,$B$1) -> 76.81 | F42: =_xll.EQNXTDZ($A$1,$B42,F$1,$B$1) -> 8.92 | G42: =_xll.EQNXTDZ($A$1,$B42,G$1,$B$1) -> 40.75 | H42: =_xll.EQNXTDZ($A$1,$B42,H$1,$B$1) -> 42.28 | I42: =_xll.EQNXTDZ($A$1,$B42,I$1,$B$1) -> 61.92 | J42: =_xll.EQNXTDZ($A$1,$B42,J$1,$B$1) -> 100.41 | ... BV42: =_xll.EQNXTDZ($A$1,$B42,BV$1,$B$1) -> 0
A44: Field Description | B44: Field Name
A45: Equity Capital | B45: QTR_EQUITY_CAP | C45: =_xll.EQNXTDZ($A$1,$B45,C$1,$B$1) -> 33.07 | D45: =_xll.EQNXTDZ($A$1,$B45,D$1,$B$1) -> 33.07 | E45: =_xll.EQNXTDZ($A$1,$B45,E$1,$B$1) -> 33.07 | F45: =_xll.EQNXTDZ($A$1,$B45,F$1,$B$1) -> 33.07 | G45: =_xll.EQNXTDZ($A$1,$B45,G$1,$B$1) -> 33.07 | H45: =_xll.EQNXTDZ($A$1,$B45,H$1,$B$1) -> 33.07 | I45: =_xll.EQNXTDZ($A$1,$B45,I$1,$B$1) -> 33.07 | J45: =_xll.EQNXTDZ($A$1,$B45,J$1,$B$1) -> 33.07 | ... BV45: =_xll.EQNXTDZ($A$1,$B45,BV$1,$B$1) -> 0
A46: Face Value | B46: QTR_FV | C46: =_xll.EQNXTDZ($A$1,$B46,C$1,$B$1) -> 1 | D46: =_xll.EQNXTDZ($A$1,$B46,D$1,$B$1) -> 1 | E46: =_xll.EQNXTDZ($A$1,$B46,E$1,$B$1) -> 1 | F46: =_xll.EQNXTDZ($A$1,$B46,F$1,$B$1) -> 1 | G46: =_xll.EQNXTDZ($A$1,$B46,G$1,$B$1) -> 1 | H46: =_xll.EQNXTDZ($A$1,$B46,H$1,$B$1) -> 1 | I46: =_xll.EQNXTDZ($A$1,$B46,I$1,$B$1) -> 1 | J46: =_xll.EQNXTDZ($A$1,$B46,J$1,$B$1) -> 1 | ... BV46: =_xll.EQNXTDZ($A$1,$B46,BV$1,$B$1) -> 0
A47: Month End | B47: BMONTH_MONTHEND | C47: =_xll.EQNXTDZ($A$1,$B47,C$5) -> 201206 | D47: =_xll.EQNXTDZ($A$1,$B47,D$5) -> 201209 | E47: =_xll.EQNXTDZ($A$1,$B47,E$5) -> 201212 | F47: =_xll.EQNXTDZ($A$1,$B47,F$5) -> 201303 | G47: =_xll.EQNXTDZ($A$1,$B47,G$5) -> 201306 | H47: =_xll.EQNXTDZ($A$1,$B47,H$5) -> 201309 | I47: =_xll.EQNXTDZ($A$1,$B47,I$5) -> 201312 | J47: =_xll.EQNXTDZ($A$1,$B47,J$5) -> 201403 | ... BV47: =_xll.EQNXTDZ($A$1,$B47,BV$5) -> 0
A48: Close | B48: BMONTH_CLOSE | C48: =_xll.EQNXTDZ($A$1,$B48,C$5) -> 104.65 | D48: =_xll.EQNXTDZ($A$1,$B48,D$5) -> 124.6 | E48: =_xll.EQNXTDZ($A$1,$B48,E$5) -> 105.85 | F48: =_xll.EQNXTDZ($A$1,$B48,F$5) -> 75.45 | G48: =_xll.EQNXTDZ($A$1,$B48,G$5) -> 80.95 | H48: =_xll.EQNXTDZ($A$1,$B48,H$5) -> 73.95 | I48: =_xll.EQNXTDZ($A$1,$B48,I$5) -> 115.8 | J48: =_xll.EQNXTDZ($A$1,$B48,J$5) -> 160.95 | ... BV48: =_xll.EQNXTDZ($A$1,$B48,BV$5) -> 0
A49: Total of Promoter and Promoter Group | B49: SHP_TPFTOTALPROMOTER | C49: =_xll.EQNXTDZ($A$1,$B49,C$5) -> 30.15 | D49: =_xll.EQNXTDZ($A$1,$B49,D$5) -> 30.15 | E49: =_xll.EQNXTDZ($A$1,$B49,E$5) -> 30.15 | F49: =_xll.EQNXTDZ($A$1,$B49,F$5) -> 30.15 | G49: =_xll.EQNXTDZ($A$1,$B49,G$5) -> 30.15 | H49: =_xll.EQNXTDZ($A$1,$B49,H$5) -> 30.15 | I49: =_xll.EQNXTDZ($A$1,$B49,I$5) -> 30.3 | J49: =_xll.EQNXTDZ($A$1,$B49,J$5) -> 30.3 | ... BV49: =_xll.EQNXTDZ($A$1,$B49,BV$5) -> 0
A50: Total of Promoter and Promoter Group Pledged | B50: SHP_PSHFTOTALPROMOTER | C50: =_xll.EQNXTDZ($A$1,$B50,C$5) -> 0 | D50: =_xll.EQNXTDZ($A$1,$B50,D$5) -> 0 | E50: =_xll.EQNXTDZ($A$1,$B50,E$5) -> 0 | F50: =_xll.EQNXTDZ($A$1,$B50,F$5) -> 0 | G50: =_xll.EQNXTDZ($A$1,$B50,G$5) -> 0 | H50: =_xll.EQNXTDZ($A$1,$B50,H$5) -> 0 | I50: =_xll.EQNXTDZ($A$1,$B50,I$5) -> 0 | J50: =_xll.EQNXTDZ($A$1,$B50,J$5) -> 0 | ... BV50: =_xll.EQNXTDZ($A$1,$B50,BV$5) -> 0
A54: Field Description | B54: Field Name | C54: =_xll.EQNXTDZ($A$1,$B54,C$5) -> 0 | D54: =_xll.EQNXTDZ($A$1,$B54,D$5) -> 0 | E54: =_xll.EQNXTDZ($A$1,$B54,E$5) -> 0 | F54: =_xll.EQNXTDZ($A$1,$B54,F$5) -> 0 | G54: =_xll.EQNXTDZ($A$1,$B54,G$5) -> 0 | H54: =_xll.EQNXTDZ($A$1,$B54,H$5) -> 0 | I54: =_xll.EQNXTDZ($A$1,$B54,I$5) -> 0 | J54: =_xll.EQNXTDZ($A$1,$B54,J$5) -> 0 | ... BV54: =_xll.EQNXTDZ($A$1,$B54,BV$5) -> 0
A55: Year End | B55: QTRB_DATE_END | C55: =_xll.EQNXTDZ($A$1,$B55,C$5,$B$1) -> 0 | D55: =_xll.EQNXTDZ($A$1,$B55,D$5,$B$1) -> 201209 | E55: =_xll.EQNXTDZ($A$1,$B55,E$5,$B$1) -> 0 | F55: =_xll.EQNXTDZ($A$1,$B55,F$5,$B$1) -> 201303 | G55: =_xll.EQNXTDZ($A$1,$B55,G$5,$B$1) -> 0 | H55: =_xll.EQNXTDZ($A$1,$B55,H$5,$B$1) -> 201309 | I55: =_xll.EQNXTDZ($A$1,$B55,I$5,$B$1) -> 0 | J55: =_xll.EQNXTDZ($A$1,$B55,J$5,$B$1) -> 201403 | ... BV55: =_xll.EQNXTDZ($A$1,$B55,BV$5,$B$1) -> 0
A56: Share Capital | B56: QTRB_SHARE_CAPITAL | C56: =_xll.EQNXTDZ($A$1,$B56,C$5,$B$1) -> 0 | D56: =_xll.EQNXTDZ($A$1,$B56,D$5,$B$1) -> 33.07 | E56: =_xll.EQNXTDZ($A$1,$B56,E$5,$B$1) -> 0 | F56: =_xll.EQNXTDZ($A$1,$B56,F$5,$B$1) -> 33.07 | G56: =_xll.EQNXTDZ($A$1,$B56,G$5,$B$1) -> 0 | H56: =_xll.EQNXTDZ($A$1,$B56,H$5,$B$1) -> 33.07 | I56: =_xll.EQNXTDZ($A$1,$B56,I$5,$B$1) -> 0 | J56: =_xll.EQNXTDZ($A$1,$B56,J$5,$B$1) -> 33.07 | ... BV56: =_xll.EQNXTDZ($A$1,$B56,BV$5,$B$1) -> 0
A57: Share Warrants & outstandings | B57: QTRB_SHAREWARNDOUT | C57: =_xll.EQNXTDZ($A$1,$B57,C$5,$B$1) -> 0 | D57: =_xll.EQNXTDZ($A$1,$B57,D$5,$B$1) -> 0 | E57: =_xll.EQNXTDZ($A$1,$B57,E$5,$B$1) -> 0 | F57: =_xll.EQNXTDZ($A$1,$B57,F$5,$B$1) -> 0 | G57: =_xll.EQNXTDZ($A$1,$B57,G$5,$B$1) -> 0 | H57: =_xll.EQNXTDZ($A$1,$B57,H$5,$B$1) -> 0 | I57: =_xll.EQNXTDZ($A$1,$B57,I$5,$B$1) -> 0 | J57: =_xll.EQNXTDZ($A$1,$B57,J$5,$B$1) -> 0 | ... BV57: =_xll.EQNXTDZ($A$1,$B57,BV$5,$B$1) -> 0
A58: Reserves & Surplus | B58: QTRB_RESERVE | C58: =_xll.EQNXTDZ($A$1,$B58,C$5,$B$1) -> 0 | D58: =_xll.EQNXTDZ($A$1,$B58,D$5,$B$1) -> 1569.59 | E58: =_xll.EQNXTDZ($A$1,$B58,E$5,$B$1) -> 0 | F58: =_xll.EQNXTDZ($A$1,$B58,F$5,$B$1) -> 1592.55 | G58: =_xll.EQNXTDZ($A$1,$B58,G$5,$B$1) -> 0 | H58: =_xll.EQNXTDZ($A$1,$B58,H$5,$B$1) -> 1698.52 | I58: =_xll.EQNXTDZ($A$1,$B58,I$5,$B$1) -> 0 | J58: =_xll.EQNXTDZ($A$1,$B58,J$5,$B$1) -> 1786.25 | ... BV58: =_xll.EQNXTDZ($A$1,$B58,BV$5,$B$1) -> 0
A59: Shareholder's Funds | B59: QTRB_SHAREHODERS_FUNDS | C59: =_xll.EQNXTDZ($A$1,$B59,C$5,$B$1) -> 0 | D59: =_xll.EQNXTDZ($A$1,$B59,D$5,$B$1) -> 1602.66 | E59: =_xll.EQNXTDZ($A$1,$B59,E$5,$B$1) -> 0 | F59: =_xll.EQNXTDZ($A$1,$B59,F$5,$B$1) -> 1625.62 | G59: =_xll.EQNXTDZ($A$1,$B59,G$5,$B$1) -> 0 | H59: =_xll.EQNXTDZ($A$1,$B59,H$5,$B$1) -> 1731.59 | I59: =_xll.EQNXTDZ($A$1,$B59,I$5,$B$1) -> 0 | J59: =_xll.EQNXTDZ($A$1,$B59,J$5,$B$1) -> 1819.32 | ... BV59: =_xll.EQNXTDZ($A$1,$B59,BV$5,$B$1) -> 0
A60: Minority Interest | B60: QTRB_MINORITY_INTEREST_BS | C60: =_xll.EQNXTDZ($A$1,$B60,C$5,$B$1) -> 0 | D60: =_xll.EQNXTDZ($A$1,$B60,D$5,$B$1) -> 12.82 | E60: =_xll.EQNXTDZ($A$1,$B60,E$5,$B$1) -> 0 | F60: =_xll.EQNXTDZ($A$1,$B60,F$5,$B$1) -> 11.81 | G60: =_xll.EQNXTDZ($A$1,$B60,G$5,$B$1) -> 0 | H60: =_xll.EQNXTDZ($A$1,$B60,H$5,$B$1) -> 12.71 | I60: =_xll.EQNXTDZ($A$1,$B60,I$5,$B$1) -> 0 | J60: =_xll.EQNXTDZ($A$1,$B60,J$5,$B$1) -> 13.82 | ... BV60: =_xll.EQNXTDZ($A$1,$B60,BV$5,$B$1) -> 0
A61: Long Term Borrowings | B61: QTRB_TOTAL_DEBTS | C61: =_xll.EQNXTDZ($A$1,$B61,C$5,$B$1) -> 0 | D61: =_xll.EQNXTDZ($A$1,$B61,D$5,$B$1) -> 7.45 | E61: =_xll.EQNXTDZ($A$1,$B61,E$5,$B$1) -> 0 | F61: =_xll.EQNXTDZ($A$1,$B61,F$5,$B$1) -> 6.02 | G61: =_xll.EQNXTDZ($A$1,$B61,G$5,$B$1) -> 0 | H61: =_xll.EQNXTDZ($A$1,$B61,H$5,$B$1) -> 5.6 | I61: =_xll.EQNXTDZ($A$1,$B61,I$5,$B$1) -> 0 | J61: =_xll.EQNXTDZ($A$1,$B61,J$5,$B$1) -> 5.37 | ... BV61: =_xll.EQNXTDZ($A$1,$B61,BV$5,$B$1) -> 0
A62: Secured Loans | B62: QTRB_SECURED_LOANS | C62: =_xll.EQNXTDZ($A$1,$B62,C$5,$B$1) -> 0 | D62: =_xll.EQNXTDZ($A$1,$B62,D$5,$B$1) -> 0 | E62: =_xll.EQNXTDZ($A$1,$B62,E$5,$B$1) -> 0 | F62: =_xll.EQNXTDZ($A$1,$B62,F$5,$B$1) -> 0 | G62: =_xll.EQNXTDZ($A$1,$B62,G$5,$B$1) -> 0 | H62: =_xll.EQNXTDZ($A$1,$B62,H$5,$B$1) -> 0 | I62: =_xll.EQNXTDZ($A$1,$B62,I$5,$B$1) -> 0 | J62: =_xll.EQNXTDZ($A$1,$B62,J$5,$B$1) -> 0 | ... BV62: =_xll.EQNXTDZ($A$1,$B62,BV$5,$B$1) -> 0
A63: Unsecured Loans | B63: QTRB_UNSECURED_LOANS_NF | C63: =_xll.EQNXTDZ($A$1,$B63,C$5,$B$1) -> 0 | D63: =_xll.EQNXTDZ($A$1,$B63,D$5,$B$1) -> 7.45 | E63: =_xll.EQNXTDZ($A$1,$B63,E$5,$B$1) -> 0 | F63: =_xll.EQNXTDZ($A$1,$B63,F$5,$B$1) -> 6.02 | G63: =_xll.EQNXTDZ($A$1,$B63,G$5,$B$1) -> 0 | H63: =_xll.EQNXTDZ($A$1,$B63,H$5,$B$1) -> 5.6 | I63: =_xll.EQNXTDZ($A$1,$B63,I$5,$B$1) -> 0 | J63: =_xll.EQNXTDZ($A$1,$B63,J$5,$B$1) -> 5.37 | ... BV63: =_xll.EQNXTDZ($A$1,$B63,BV$5,$B$1) -> 0
A64: Other Long Term Liabilities | B64: QTRB_OTHER_LT_LIABILITIES | C64: =_xll.EQNXTDZ($A$1,$B64,C$5,$B$1) -> 0 | D64: =_xll.EQNXTDZ($A$1,$B64,D$5,$B$1) -> 32.84 | E64: =_xll.EQNXTDZ($A$1,$B64,E$5,$B$1) -> 0 | F64: =_xll.EQNXTDZ($A$1,$B64,F$5,$B$1) -> 27.96 | G64: =_xll.EQNXTDZ($A$1,$B64,G$5,$B$1) -> 0 | H64: =_xll.EQNXTDZ($A$1,$B64,H$5,$B$1) -> 36.78 | I64: =_xll.EQNXTDZ($A$1,$B64,I$5,$B$1) -> 0 | J64: =_xll.EQNXTDZ($A$1,$B64,J$5,$B$1) -> 29.87 | ... BV64: =_xll.EQNXTDZ($A$1,$B64,BV$5,$B$1) -> 0
A65: Long Term Trade Payables | B65: QTRB_LT_TRADE_PAYABLE | C65: =_xll.EQNXTDZ($A$1,$B65,C$5,$B$1) -> 0 | D65: =_xll.EQNXTDZ($A$1,$B65,D$5,$B$1) -> 0 | E65: =_xll.EQNXTDZ($A$1,$B65,E$5,$B$1) -> 0 | F65: =_xll.EQNXTDZ($A$1,$B65,F$5,$B$1) -> 0 | G65: =_xll.EQNXTDZ($A$1,$B65,G$5,$B$1) -> 0 | H65: =_xll.EQNXTDZ($A$1,$B65,H$5,$B$1) -> 0 | I65: =_xll.EQNXTDZ($A$1,$B65,I$5,$B$1) -> 0 | J65: =_xll.EQNXTDZ($A$1,$B65,J$5,$B$1) -> 0 | ... BV65: =_xll.EQNXTDZ($A$1,$B65,BV$5,$B$1) -> 0
A66: Lont Term Provisions | B66: QTRB_LT_PROVISIONS | C66: =_xll.EQNXTDZ($A$1,$B66,C$5,$B$1) -> 0 | D66: =_xll.EQNXTDZ($A$1,$B66,D$5,$B$1) -> 90.44 | E66: =_xll.EQNXTDZ($A$1,$B66,E$5,$B$1) -> 0 | F66: =_xll.EQNXTDZ($A$1,$B66,F$5,$B$1) -> 89.83 | G66: =_xll.EQNXTDZ($A$1,$B66,G$5,$B$1) -> 0 | H66: =_xll.EQNXTDZ($A$1,$B66,H$5,$B$1) -> 95.37 | I66: =_xll.EQNXTDZ($A$1,$B66,I$5,$B$1) -> 0 | J66: =_xll.EQNXTDZ($A$1,$B66,J$5,$B$1) -> 90.23 | ... BV66: =_xll.EQNXTDZ($A$1,$B66,BV$5,$B$1) -> 0
... A97: Total Assets | B97: QTRB_TOTAL_APPLICATIONS | C97: =_xll.EQNXTDZ($A$1,$B97,C$5,$B$1) -> 0 | D97: =_xll.EQNXTDZ($A$1,$B97,D$5,$B$1) -> 1746.21 | E97: =_xll.EQNXTDZ($A$1,$B97,E$5,$B$1) -> 0 | F97: =_xll.EQNXTDZ($A$1,$B97,F$5,$B$1) -> 1761.24 | G97: =_xll.EQNXTDZ($A$1,$B97,G$5,$B$1) -> 0 | H97: =_xll.EQNXTDZ($A$1,$B97,H$5,$B$1) -> 1882.05 | I97: =_xll.EQNXTDZ($A$1,$B97,I$5,$B$1) -> 0 | J97: =_xll.EQNXTDZ($A$1,$B97,J$5,$B$1) -> 1958.61 | ... BV97: =_xll.EQNXTDZ($A$1,$B97,BV$5,$B$1) -> 0

Sheet Annual Raw
A1: 100575 | B1: X | C1: 200103 | D1: 200203 | E1: 200303 | F1: 200403 | G1: 200503 | H1: 200603 | I1: 200703 | J1: 200803 | K1: 200903 | L1: 201003 | M1: 201103 | N1: 201203 | O1: 201303 | P1: 201403 | Q1: 201503 | R1: 201603 | S1: 201703 | T1: 201803 | U1: 201903 | V1: 202003 | W1: 202103 | X1: 202203 | Y1: 202303 | Z1: 202403 | AA1: 202503 | AB1: 202603 | AC1: 202703 | AD1: 202803 | AE1: 202903 | AF1: 203003
A3: Field Description | B3: Field Name
A4: Company Name | B4: CD_COMPNAME | C4: =_xll.EQNXTDZ(A1,B4,"L") -> Voltas Ltd.
A5: Year End | B5: PL_YEAR_END | C5: =_xll.EQNXTDZ($A$1,$B5,C$1,$B$1) -> 200103 | D5: =_xll.EQNXTDZ($A$1,$B5,D$1,$B$1) -> 200203 | E5: =_xll.EQNXTDZ($A$1,$B5,E$1,$B$1) -> 200303 | F5: =_xll.EQNXTDZ($A$1,$B5,F$1,$B$1) -> 200403 | G5: =_xll.EQNXTDZ($A$1,$B5,G$1,$B$1) -> 200503 | H5: =_xll.EQNXTDZ($A$1,$B5,H$1,$B$1) -> 200603 | I5: =_xll.EQNXTDZ($A$1,$B5,I$1,$B$1) -> 200703 | J5: =_xll.EQNXTDZ($A$1,$B5,J$1,$B$1) -> 200803 | ... AF5: =_xll.EQNXTDZ($A$1,$B5,AF$1,$B$1) -> 0
A6: Sales Turnover | B6: PL_TOTAL_GROSS_SALES | C6: =_xll.EQNXTDZ($A$1,$B6,C$1,$B$1) -> 853.7166 | D6: =_xll.EQNXTDZ($A$1,$B6,D$1,$B$1) -> 956.7624 | E6: =_xll.EQNXTDZ($A$1,$B6,E$1,$B$1) -> 1342.1175 | F6: =_xll.EQNXTDZ($A$1,$B6,F$1,$B$1) -> 1437.5206 | G6: =_xll.EQNXTDZ($A$1,$B6,G$1,$B$1) -> 1550.7879 | H6: =_xll.EQNXTDZ($A$1,$B6,H$1,$B$1) -> 2022.7089 | I6: =_xll.EQNXTDZ($A$1,$B6,I$1,$B$1) -> 2598.301 | J6: =_xll.EQNXTDZ($A$1,$B6,J$1,$B$1) -> 3264.3878 | ... AF6: =_xll.EQNXTDZ($A$1,$B6,AF$1,$B$1) -> 0
A7: Less: Inter divisional transfers | B7: PL_INTER_DIV_TRF | C7: =_xll.EQNXTDZ($A$1,$B7,C$1,$B$1) -> 0 | D7: =_xll.EQNXTDZ($A$1,$B7,D$1,$B$1) -> 0 | E7: =_xll.EQNXTDZ($A$1,$B7,E$1,$B$1) -> 0 | F7: =_xll.EQNXTDZ($A$1,$B7,F$1,$B$1) -> 0 | G7: =_xll.EQNXTDZ($A$1,$B7,G$1,$B$1) -> 0 | H7: =_xll.EQNXTDZ($A$1,$B7,H$1,$B$1) -> 0 | I7: =_xll.EQNXTDZ($A$1,$B7,I$1,$B$1) -> 0 | J7: =_xll.EQNXTDZ($A$1,$B7,J$1,$B$1) -> 0 | ... AF7: =_xll.EQNXTDZ($A$1,$B7,AF$1,$B$1) -> 0
A8: Less: Sales Returns | B8: PL_SALES_RETURN | C8: =_xll.EQNXTDZ($A$1,$B8,C$1,$B$1) -> 0 | D8: =_xll.EQNXTDZ($A$1,$B8,D$1,$B$1) -> 0 | E8: =_xll.EQNXTDZ($A$1,$B8,E$1,$B$1) -> 0 | F8: =_xll.EQNXTDZ($A$1,$B8,F$1,$B$1) -> 0 | G8: =_xll.EQNXTDZ($A$1,$B8,G$1,$B$1) -> 0 | H8: =_xll.EQNXTDZ($A$1,$B8,H$1,$B$1) -> 0 | I8: =_xll.EQNXTDZ($A$1,$B8,I$1,$B$1) -> 0 | J8: =_xll.EQNXTDZ($A$1,$B8,J$1,$B$1) -> 0 | ... AF8: =_xll.EQNXTDZ($A$1,$B8,AF$1,$B$1) -> 0
A9: Less: Excise | B9: PL_EXCISE | C9: =_xll.EQNXTDZ($A$1,$B9,C$1,$B$1) -> 89.1636 | D9: =_xll.EQNXTDZ($A$1,$B9,D$1,$B$1) -> 75.602 | E9: =_xll.EQNXTDZ($A$1,$B9,E$1,$B$1) -> 86.575 | F9: =_xll.EQNXTDZ($A$1,$B9,F$1,$B$1) -> 77.567 | G9: =_xll.EQNXTDZ($A$1,$B9,G$1,$B$1) -> 73.7203 | H9: =_xll.EQNXTDZ($A$1,$B9,H$1,$B$1) -> 68.2717 | I9: =_xll.EQNXTDZ($A$1,$B9,I$1,$B$1) -> 71.564 | J9: =_xll.EQNXTDZ($A$1,$B9,J$1,$B$1) -> 61.4611 | ... AF9: =_xll.EQNXTDZ($A$1,$B9,AF$1,$B$1) -> 0
A10: Net Sales | B10: PL_NET_SALES | C10: =_xll.EQNXTDZ($A$1,$B10,C$1,$B$1) -> 764.553 | D10: =_xll.EQNXTDZ($A$1,$B10,D$1,$B$1) -> 881.1604 | E10: =_xll.EQNXTDZ($A$1,$B10,E$1,$B$1) -> 1255.5425 | F10: =_xll.EQNXTDZ($A$1,$B10,F$1,$B$1) -> 1359.9536 | G10: =_xll.EQNXTDZ($A$1,$B10,G$1,$B$1) -> 1477.0676 | H10: =_xll.EQNXTDZ($A$1,$B10,H$1,$B$1) -> 1954.4372 | I10: =_xll.EQNXTDZ($A$1,$B10,I$1,$B$1) -> 2526.737 | J10: =_xll.EQNXTDZ($A$1,$B10,J$1,$B$1) -> 3202.9267 | ... AF10: =_xll.EQNXTDZ($A$1,$B10,AF$1,$B$1) -> 0
A11: Increase/Decrease in Stock | B11: PL_INC_DEC_INVENTORY | C11: =_xll.EQNXTDZ($A$1,$B11,C$1,$B$1) -> 29.476 | D11: =_xll.EQNXTDZ($A$1,$B11,D$1,$B$1) -> 65.8875 | E11: =_xll.EQNXTDZ($A$1,$B11,E$1,$B$1) -> 40.0038 | F11: =_xll.EQNXTDZ($A$1,$B11,F$1,$B$1) -> 10.4407 | G11: =_xll.EQNXTDZ($A$1,$B11,G$1,$B$1) -> -346.5813 | H11: =_xll.EQNXTDZ($A$1,$B11,H$1,$B$1) -> -608.1094 | I11: =_xll.EQNXTDZ($A$1,$B11,I$1,$B$1) -> 0 | J11: =_xll.EQNXTDZ($A$1,$B11,J$1,$B$1) -> 0 | ... AF11: =_xll.EQNXTDZ($A$1,$B11,AF$1,$B$1) -> 0
A12: Raw Material Consumed | B12: PL_RAW_MATRS_CONSUMED | C12: =_xll.EQNXTDZ($A$1,$B12,C$1,$B$1) -> 632.75 | D12: =_xll.EQNXTDZ($A$1,$B12,D$1,$B$1) -> 612.7476 | E12: =_xll.EQNXTDZ($A$1,$B12,E$1,$B$1) -> 974.4928 | F12: =_xll.EQNXTDZ($A$1,$B12,F$1,$B$1) -> 991.7907 | G12: =_xll.EQNXTDZ($A$1,$B12,G$1,$B$1) -> 1434.6836 | H12: =_xll.EQNXTDZ($A$1,$B12,H$1,$B$1) -> 2065.1993 | I12: =_xll.EQNXTDZ($A$1,$B12,I$1,$B$1) -> 1878.1579 | J12: =_xll.EQNXTDZ($A$1,$B12,J$1,$B$1) -> 2338.4082 | ... AF12: =_xll.EQNXTDZ($A$1,$B12,AF$1,$B$1) -> 0
A13: Power & Fuel Cost | B13: PL_POWER_FUEL | C13: =_xll.EQNXTDZ($A$1,$B13,C$1,$B$1) -> 6.6359 | D13: =_xll.EQNXTDZ($A$1,$B13,D$1,$B$1) -> 5.844 | E13: =_xll.EQNXTDZ($A$1,$B13,E$1,$B$1) -> 5.1779 | F13: =_xll.EQNXTDZ($A$1,$B13,F$1,$B$1) -> 4.9364 | G13: =_xll.EQNXTDZ($A$1,$B13,G$1,$B$1) -> 4.3908 | H13: =_xll.EQNXTDZ($A$1,$B13,H$1,$B$1) -> 4.1447 | I13: =_xll.EQNXTDZ($A$1,$B13,I$1,$B$1) -> 4.258 | J13: =_xll.EQNXTDZ($A$1,$B13,J$1,$B$1) -> 4.0643 | ... AF13: =_xll.EQNXTDZ($A$1,$B13,AF$1,$B$1) -> 0
A14: Employee Cost | B14: PL_EMPLOYEES | C14: =_xll.EQNXTDZ($A$1,$B14,C$1,$B$1) -> 100.3037 | D14: =_xll.EQNXTDZ($A$1,$B14,D$1,$B$1) -> 110.8011 | E14: =_xll.EQNXTDZ($A$1,$B14,E$1,$B$1) -> 134.5882 | F14: =_xll.EQNXTDZ($A$1,$B14,F$1,$B$1) -> 135.1971 | G14: =_xll.EQNXTDZ($A$1,$B14,G$1,$B$1) -> 153.6958 | H14: =_xll.EQNXTDZ($A$1,$B14,H$1,$B$1) -> 190.9696 | I14: =_xll.EQNXTDZ($A$1,$B14,I$1,$B$1) -> 258.6337 | J14: =_xll.EQNXTDZ($A$1,$B14,J$1,$B$1) -> 297.6833 | ... AF14: =_xll.EQNXTDZ($A$1,$B14,AF$1,$B$1) -> 0
A15: Operating & Manufacturing Expenses | B15: PL_GEN_OTHER_MFG_EXPS | C15: =_xll.EQNXTDZ($A$1,$B15,C$1,$B$1) -> 7.5553 | D15: =_xll.EQNXTDZ($A$1,$B15,D$1,$B$1) -> 8.841 | E15: =_xll.EQNXTDZ($A$1,$B15,E$1,$B$1) -> 7.32 | F15: =_xll.EQNXTDZ($A$1,$B15,F$1,$B$1) -> 7.5075 | G15: =_xll.EQNXTDZ($A$1,$B15,G$1,$B$1) -> 6.7282 | H15: =_xll.EQNXTDZ($A$1,$B15,H$1,$B$1) -> 7.0118 | I15: =_xll.EQNXTDZ($A$1,$B15,I$1,$B$1) -> 10.0716 | J15: =_xll.EQNXTDZ($A$1,$B15,J$1,$B$1) -> 12.8489 | ... AF15: =_xll.EQNXTDZ($A$1,$B15,AF$1,$B$1) -> 0
A16: Cost of Software development | B16: PL_COST_SW | C16: =_xll.EQNXTDZ($A$1,$B16,C$1,$B$1) -> 0 | D16: =_xll.EQNXTDZ($A$1,$B16,D$1,$B$1) -> 0 | E16: =_xll.EQNXTDZ($A$1,$B16,E$1,$B$1) -> 0 | F16: =_xll.EQNXTDZ($A$1,$B16,F$1,$B$1) -> 0 | G16: =_xll.EQNXTDZ($A$1,$B16,G$1,$B$1) -> 0 | H16: =_xll.EQNXTDZ($A$1,$B16,H$1,$B$1) -> 0 | I16: =_xll.EQNXTDZ($A$1,$B16,I$1,$B$1) -> 0 | J16: =_xll.EQNXTDZ($A$1,$B16,J$1,$B$1) -> 0 | ... AF16: =_xll.EQNXTDZ($A$1,$B16,AF$1,$B$1) -> 0
... A36: Profit After Tax from Discontinued Operations | B36: PL_PAT_DIS_OP | C36: =_xll.EQNXTDZ($A$1,$B36,C$1,$B$1) -> 0 | D36: =_xll.EQNXTDZ($A$1,$B36,D$1,$B$1) -> 0 | E36: =_xll.EQNXTDZ($A$1,$B36,E$1,$B$1) -> 0 | F36: =_xll.EQNXTDZ($A$1,$B36,F$1,$B$1) -> 0 | G36: =_xll.EQNXTDZ($A$1,$B36,G$1,$B$1) -> 0 | H36: =_xll.EQNXTDZ($A$1,$B36,H$1,$B$1) -> 0 | I36: =_xll.EQNXTDZ($A$1,$B36,I$1,$B$1) -> 0 | J36: =_xll.EQNXTDZ($A$1,$B36,J$1,$B$1) -> 0 | ... AF36: =_xll.EQNXTDZ($A$1,$B36,AF$1,$B$1) -> 0
A39: Field Description | B39: Field Name
A40: Year End | B40: BS_YEAR_END | C40: =_xll.EQNXTDZ($A$1,$B40,C$1,$B$1) -> 200103 | D40: =_xll.EQNXTDZ($A$1,$B40,D$1,$B$1) -> 200203 | E40: =_xll.EQNXTDZ($A$1,$B40,E$1,$B$1) -> 200303 | F40: =_xll.EQNXTDZ($A$1,$B40,F$1,$B$1) -> 200403 | G40: =_xll.EQNXTDZ($A$1,$B40,G$1,$B$1) -> 200503 | H40: =_xll.EQNXTDZ($A$1,$B40,H$1,$B$1) -> 200603 | I40: =_xll.EQNXTDZ($A$1,$B40,I$1,$B$1) -> 200703 | J40: =_xll.EQNXTDZ($A$1,$B40,J$1,$B$1) -> 200803 | ... AF40: =_xll.EQNXTDZ($A$1,$B40,AF$1,$B$1) -> 0
A41: Share Capital | B41: BS_SHARE_CAPITAL | C41: =_xll.EQNXTDZ($A$1,$B41,C$1,$B$1) -> 33.0539 | D41: =_xll.EQNXTDZ($A$1,$B41,D$1,$B$1) -> 33.0539 | E41: =_xll.EQNXTDZ($A$1,$B41,E$1,$B$1) -> 33.0539 | F41: =_xll.EQNXTDZ($A$1,$B41,F$1,$B$1) -> 33.0553 | G41: =_xll.EQNXTDZ($A$1,$B41,G$1,$B$1) -> 33.0553 | H41: =_xll.EQNXTDZ($A$1,$B41,H$1,$B$1) -> 33.0626 | I41: =_xll.EQNXTDZ($A$1,$B41,I$1,$B$1) -> 33.0683 | J41: =_xll.EQNXTDZ($A$1,$B41,J$1,$B$1) -> 33.0695 | ... AF41: =_xll.EQNXTDZ($A$1,$B41,AF$1,$B$1) -> 0
