Workbook

Sheet Template
A1: =+'Annual Raw'!C4 -> Varun Beverages Ltd. | B1: 36951 | C1: =EOMONTH(B1,12) -> 37346 | D1: 37591 | E1: =EOMONTH(D1,12) -> 37986 | F1: =EOMONTH(E1,12) -> 38352 | G1: =EOMONTH(F1,12) -> 38717 | H1: =EOMONTH(G1,12) -> 39082 | I1: =EOMONTH(H1,12) -> 39447 | J1: =EOMONTH(I1,12) -> 39813 | K1: =EOMONTH(J1,12) -> 40178 | L1: =EOMONTH(K1,12) -> 40543 | ... AE1: =EOMONTH(AD1,12) -> 47483 | AH1: QTR | AI1: 41061 | AJ1: 41153 | AK1: 41244 | AL1: 41334 | AM1: 41426 | AN1: 41518 | AO1: 41609 | AP1: 41699 | AQ1: 41791 | AR1: 41883 | AS1: 41974 | AT1: 42064 | AU1: 42156 | AV1: 42248 | AW1: 42339 | AX1: 42430 | AY1: 42522 | AZ1: 42614 | BA1: 42705 | BB1: 42795 | BC1: 42887 | BD1: 42979 | BE1: 43070 | BF1: 43160 | BG1: 43252 | BH1: 43344 | BI1: 43435 | BJ1: 43525 | BK1: 43617 | BL1: 43709 | BM1: 43800 | BN1: 43891 | BO1: 43983 | BP1: 44075 | BQ1: =EOMONTH(BP1,3) -> 44196 | BR1: =EOMONTH(BQ1,3) -> 44286 | BS1: =EOMONTH(BR1,3) -> 44377 | BT1: =EOMONTH(BS1,3) -> 44469 | BU1: =EOMONTH(BT1,3) -> 44561 | BV1: =EOMONTH(BU1,3) -> 44651 | BW1: =EOMONTH(BV1,3) -> 44742 | BX1: =EOMONTH(BW1,3) -> 44834 | ... DA1: =EOMONTH(CZ1,3) -> 47483 | DD1: HISTORICAL ESTIMATES
A2: Presentation Data (Start)
A4: Volume
A5: Volume Mn Units - CSD | S5: =SUM(BB5:BE5) -> 220 | T5: =SUM(BF5:BI5) -> 257 | U5: =SUM(BJ5:BM5) -> 347 | V5: =SUM(BN5:BQ5) -> 309 | W5: =SUM(BR5:BU5) -> 400 | X5: =SUM(BV5:BY5) -> 562 | Y5: =SUM(BZ5:CC5) -> 657 | Z5: =SUM(CD5:CG5) -> 833 | AA5: =SUM(CH5:CK5) -> 897 | AB5: =SUM(CL5:CO5) -> 977.5159 | AC5: =SUM(CP5:CS5) -> 1060.1004 | AD5: =SUM(CT5:CW5) -> 1143.3609 | AE5: =SUM(CX5:DA5) -> 1233.5061 | BB5: 51 | BC5: 92 | BD5: 53 | BE5: 24 | BF5: 60 | BG5: 107 | BH5: 59 | BI5: 31 | BJ5: 64 | BK5: 145 | BL5: 86 | BM5: 52 | BN5: 76 | BO5: 89 | BP5: 89 | BQ5: 55 | BR5: 106 | BS5: 118 | BT5: 108 | BU5: 68 | BV5: 126 | BW5: 218 | BX5: 133 | BY5: 85 | BZ5: 160 | CA5: 232 | CB5: 159 | CC5: 106 | CD5: 169 | CE5: 306 | CF5: 200 | CG5: 158 | CH5: 234 | CI5: 291 | CJ5: 202 | CK5: 170 | CL5: 268 | CM5: =+CI5*(1+CM11) -> 305.58287 | CN5: =+CJ5*(1+CN11) -> 217.62963 | CO5: =+CK5*(1+CO11) -> 186.3034 | CP5: =+CL5*(1+CP11) -> 295.17237 | CQ5: =+CM5*(1+CQ11) -> 328.40967 | CR5: =+CN5*(1+CR11) -> 235.11705 | CS5: =+CO5*(1+CS11) -> 201.40131 | CT5: =+CP5*(1+CT11) -> 318.0839 | ... DA5: =+CW5*(1+DA11) -> 234.48356
A6: Volume Mn Units - Juice | S6: =SUM(BB6:BE6) -> 14 | T6: =SUM(BF6:BI6) -> 22 | U6: =SUM(BJ6:BM6) -> 23 | V6: =SUM(BN6:BQ6) -> 26 | W6: =SUM(BR6:BU6) -> 36 | X6: =SUM(BV6:BY6) -> 57 | Y6: =SUM(BZ6:CC6) -> 58 | Z6: =SUM(CD6:CG6) -> 69.3 | AA6: =SUM(CH6:CK6) -> 72 | AB6: =SUM(CL6:CO6) -> 84.464503 | AC6: =SUM(CP6:CS6) -> 99.771826 | AD6: =SUM(CT6:CW6) -> 116.72322 | AE6: =SUM(CX6:DA6) -> 136.015 | BB6: 3 | BC6: 7 | BD6: 3 | BE6: 1 | BF6: 5 | BG6: 10 | BH6: 4 | BI6: 3 | BJ6: 6 | BK6: 5 | BL6: 7 | BM6: 5 | BN6: 8 | BO6: 8 | BP6: 6 | BQ6: 4 | BR6: 11 | BS6: 11 | BT6: 8 | BU6: 6 | BV6: 13 | BW6: 26 | BX6: 11 | BY6: 7 | BZ6: 16 | CA6: 23 | CB6: 11 | CC6: 8 | CD6: 18 | CE6: 32 | CF6: 11.3 | CG6: 8 | CH6: 22 | CI6: 28 | CJ6: 12 | CK6: 10 | CL6: 27 | CM6: =+CI6*(1+CM12) -> 31.189491 | CN6: =+CJ6*(1+CN12) -> 14.155329 | CO6: =+CK6*(1+CO12) -> 12.119683 | CP6: =+CL6*(1+CP12) -> 32.440759 | CQ6: =+CM6*(1+CQ12) -> 36.371462 | CR6: =+CN6*(1+CR12) -> 16.680921 | CS6: =+CO6*(1+CS12) -> 14.278684 | CT6: =+CP6*(1+CT12) -> 37.961864 | ... DA6: =+CW6*(1+DA12) -> 19.407676
A7: Volume Mn Units - Water | S7: =SUM(BB7:BE7) -> 44 | T7: =SUM(BF7:BI7) -> 61 | U7: =SUM(BJ7:BM7) -> 111 | V7: =SUM(BN7:BQ7) -> 90 | W7: =SUM(BR7:BU7) -> 132 | X7: =SUM(BV7:BY7) -> 182 | Y7: =SUM(BZ7:CC7) -> 199 | Z7: =SUM(CD7:CG7) -> 221 | AA7: =SUM(CH7:CK7) -> 244 | AB7: =SUM(CL7:CO7) -> 288.28631 | AC7: =SUM(CP7:CS7) -> 339.71225 | AD7: =SUM(CT7:CW7) -> 399.71925 | AE7: =SUM(CX7:DA7) -> 475.15727 | BB7: 13 | BC7: 13 | BD7: 10 | BE7: 8 | BF7: 15 | BG7: 19 | BH7: 15 | BI7: 12 | BJ7: 20 | BK7: 35 | BL7: 31 | BM7: 25 | BN7: 30 | BO7: 8 | BP7: 24 | BQ7: 28 | BR7: 34 | BS7: 23 | BT7: 37 | BU7: 38 | BV7: 41 | BW7: 55 | BX7: 46 | BY7: 40 | BZ7: 48 | CA7: 59 | CB7: 50 | CC7: 42 | CD7: 53 | CE7: 63 | CF7: 56 | CG7: 49 | CH7: 56 | CI7: 71 | CJ7: 60 | CK7: 57 | CL7: 68 | CM7: =+CI7*(1+CM13) -> 82.245692 | CN7: =+CJ7*(1+CN13) -> 70.021599 | CO7: =+CK7*(1+CO13) -> 68.019018 | CP7: =+CL7*(1+CP13) -> 81.707446 | CQ7: =+CM7*(1+CQ13) -> 96.16771 | CR7: =+CN7*(1+CR13) -> 82.05349 | CS7: =+CO7*(1+CS13) -> 79.783602 | CT7: =+CP7*(1+CT13) -> 95.448723 | ... DA7: =+CW7*(1+DA13) -> 112.48104
A8: Total Volume Mn Units | S8: =SUM(S5:S7) -> 278 | T8: =SUM(T5:T7) -> 340 | U8: =SUM(U5:U7) -> 481 | V8: =SUM(V5:V7) -> 425 | W8: =SUM(W5:W7) -> 568 | X8: =SUM(X5:X7) -> 801 | Y8: =SUM(Y5:Y7) -> 914 | Z8: =SUM(Z5:Z7) -> 1123.3 | ... AE8: =SUM(AE5:AE7) -> 1844.6784 | BB8: =SUM(BB5:BB7) -> 67 | BC8: =SUM(BC5:BC7) -> 112 | BD8: =SUM(BD5:BD7) -> 66 | BE8: =SUM(BE5:BE7) -> 33 | BF8: =SUM(BF5:BF7) -> 80 | BG8: =SUM(BG5:BG7) -> 136 | BH8: =SUM(BH5:BH7) -> 78 | BI8: =SUM(BI5:BI7) -> 46 | ... DA8: =SUM(DA5:DA7) -> 366.37228
A10: Volume Growth % Y-o-Y
A11: Volume Growth YoY% - CSD | T11: =T5/S5-1 -> 0.16818182 | U11: =U5/T5-1 -> 0.35019455 | V11: =V5/U5-1 -> -0.10951009 | W11: =W5/V5-1 -> 0.29449838 | X11: =X5/W5-1 -> 0.405 | Y11: =Y5/X5-1 -> 0.16903915 | Z11: =Z5/Y5-1 -> 0.26788432 | AA11: =AA5/Z5-1 -> 0.076830732 | ... AE11: =AE5/AD5-1 -> 0.078842281 | BF11: =BF5/BB5-1 -> 0.17647059 | BG11: =BG5/BC5-1 -> 0.16304348 | BH11: =BH5/BD5-1 -> 0.11320755 | BI11: =BI5/BE5-1 -> 0.29166667 | BJ11: =BJ5/BF5-1 -> 0.066666667 | BK11: =BK5/BG5-1 -> 0.35514019 | BL11: =BL5/BH5-1 -> 0.45762712 | BM11: =BM5/BI5-1 -> 0.67741935 | ... CL11: =CL5/CH5-1 -> 0.14529915 | CM11: =+AVERAGE(CI11:CL11)*1.1 -> 0.050112949 | CN11: =+AVERAGE(CJ11:CM11)*1.1 -> 0.077374402 | CO11: =+AVERAGE(CK11:CN11)*1.1 -> 0.095902362 | CP11: =+AVERAGE(CL11:CO11)*1.1 -> 0.10138944 | CQ11: =+AVERAGE(CM11:CP11)*0.92 -> 0.074699204 | CR11: =+AVERAGE(CN11:CQ11)*0.92 -> 0.080354043 | CS11: =+AVERAGE(CO11:CR11)*0.92 -> 0.08103936 | CT11: =+AVERAGE(CP11:CS11)*0.92 -> 0.07762087 | CU11: =+AVERAGE(CQ11:CT11) -> 0.078428369 | CV11: =+AVERAGE(CR11:CU11) -> 0.079360661 | CW11: =+AVERAGE(CS11:CV11) -> 0.079112315 | CX11: =+AVERAGE(CT11:CW11) -> 0.078630554 | CY11: =+AVERAGE(CU11:CX11) -> 0.078882975 | CZ11: =+AVERAGE(CV11:CY11) -> 0.078996626 | DA11: =+AVERAGE(CW11:CZ11) -> 0.078905617
A12: Volume Growth YoY% - Juice | T12: =T6/S6-1 -> 0.57142857 | U12: =U6/T6-1 -> 0.045454545 | V12: =V6/U6-1 -> 0.13043478 | W12: =W6/V6-1 -> 0.38461538 | X12: =X6/W6-1 -> 0.58333333 | Y12: =Y6/X6-1 -> 0.01754386 | Z12: =Z6/Y6-1 -> 0.19482759 | AA12: =AA6/Z6-1 -> 0.038961039 | ... AE12: =AE6/AD6-1 -> 0.16527795 | BF12: =BF6/BB6-1 -> 0.66666667 | BG12: =BG6/BC6-1 -> 0.42857143 | BH12: =BH6/BD6-1 -> 0.33333333 | BI12: =BI6/BE6-1 -> 2 | BJ12: =BJ6/BF6-1 -> 0.2 | BK12: =BK6/BG6-1 -> -0.5 | BL12: =BL6/BH6-1 -> 0.75 | BM12: =BM6/BI6-1 -> 0.66666667 | ... CL12: =CL6/CH6-1 -> 0.22727273 | CM12: =+AVERAGE(CI12:CL12)*1.1 -> 0.1139104 | CN12: =+AVERAGE(CJ12:CM12)*1.1 -> 0.17961076 | CO12: =+AVERAGE(CK12:CN12)*1.1 -> 0.21196832 | CP12: =+AVERAGE(CL12:CO12)*1.1 -> 0.20150961 | CQ12: =+AVERAGE(CM12:CP12)*0.94 -> 0.16614478 | CR12: =+AVERAGE(CN12:CQ12)*0.94 -> 0.17841986 | CS12: =+AVERAGE(CO12:CR12)*0.94 -> 0.17814 | CT12: =+AVERAGE(CP12:CS12)*0.94 -> 0.17019035 | CU12: =+AVERAGE(CQ12:CT12)*0.98 -> 0.16975928 | CV12: =+AVERAGE(CR12:CU12)*0.98 -> 0.17064483 | CW12: =+AVERAGE(CS12:CV12)*0.98 -> 0.16873994 | CX12: =+AVERAGE(CT12:CW12)*0.98 -> 0.16643693 | CY12: =+AVERAGE(CU12:CX12)*0.98 -> 0.16551734 | CZ12: =+AVERAGE(CV12:CY12)*0.98 -> 0.16447806 | DA12: =+AVERAGE(CW12:CZ12)*0.98 -> 0.16296721
A13: Volume Growth YoY% - Water | T13: =T7/S7-1 -> 0.38636364 | U13: =U7/T7-1 -> 0.81967213 | V13: =V7/U7-1 -> -0.18918919 | W13: =W7/V7-1 -> 0.46666667 | X13: =X7/W7-1 -> 0.37878788 | Y13: =Y7/X7-1 -> 0.093406593 | Z13: =Z7/Y7-1 -> 0.11055276 | AA13: =AA7/Z7-1 -> 0.1040724 | ... AE13: =AE7/AD7-1 -> 0.18872751 | BF13: =BF7/BB7-1 -> 0.15384615 | BG13: =BG7/BC7-1 -> 0.46153846 | BH13: =BH7/BD7-1 -> 0.5 | BI13: =BI7/BE7-1 -> 0.5 | BJ13: =BJ7/BF7-1 -> 0.33333333 | BK13: =BK7/BG7-1 -> 0.84210526 | BL13: =BL7/BH7-1 -> 1.0666667 | BM13: =BM7/BI7-1 -> 1.0833333 | ... CL13: =CL7/CH7-1 -> 0.21428571 | CM13: =+AVERAGE(CI13:CL13)*1.1 -> 0.15839002 | CN13: =+AVERAGE(CJ13:CM13)*1.1 -> 0.16702664 | CO13: =+AVERAGE(CK13:CN13)*1.1 -> 0.19331611 | CP13: =+AVERAGE(CL13:CO13)*1.1 -> 0.20158009 | CQ13: =+AVERAGE(CM13:CP13)*0.94 -> 0.16927352 | CR13: =+AVERAGE(CN13:CQ13)*0.94 -> 0.17183115 | CS13: =+AVERAGE(CO13:CR13)*0.94 -> 0.1729602 | CT13: =+AVERAGE(CP13:CS13)*0.94 -> 0.16817657 | CU13: =+AVERAGE(CQ13:CT13)*1.04 -> 0.17738277 | CV13: =+AVERAGE(CR13:CU13)*1.04 -> 0.17949118 | CW13: =+AVERAGE(CS13:CV13)*1.04 -> 0.18148279 | CX13: =+AVERAGE(CT13:CW13)*1.04 -> 0.18369866 | CY13: =+AVERAGE(CU13:CX13)*1.04 -> 0.1877344 | CZ13: =+AVERAGE(CV13:CY13)*1.04 -> 0.19042583 | DA13: =+AVERAGE(CW13:CZ13)*1.04 -> 0.19326884
A14: Total Volume Growth YoY% | T14: =T8/S8-1 -> 0.22302158 | U14: =U8/T8-1 -> 0.41470588 | V14: =V8/U8-1 -> -0.11642412 | W14: =W8/V8-1 -> 0.33647059 | X14: =X8/W8-1 -> 0.41021127 | Y14: =Y8/X8-1 -> 0.14107366 | Z14: =Z8/Y8-1 -> 0.22899344 | AA14: =AA8/Z8-1 -> 0.079854002 | ... AE14: =AE8/AD8-1 -> 0.11138366 | BF14: =BF8/BB8-1 -> 0.19402985 | BG14: =BG8/BC8-1 -> 0.21428571 | BH14: =BH8/BD8-1 -> 0.18181818 | BI14: =BI8/BE8-1 -> 0.39393939 | BJ14: =BJ8/BF8-1 -> 0.125 | BK14: =BK8/BG8-1 -> 0.36029412 | BL14: =BL8/BH8-1 -> 0.58974359 | BM14: =BM8/BI8-1 -> 0.7826087 | ... CL14: =CL8/CH8-1 -> 0.16346154
A16: Unit Metrics
A17: Realisation | S17: =+S30/S8 -> 14.401223 | T17: =+T30/T8 -> 15.015456 | U17: =+U30/U8 -> 14.822407 | V17: =+V30/V8 -> 15.176805 | W17: =+W30/W8 -> 15.533856 | X17: =+X30/X8 -> 16.44587 | Y17: =+Y30/Y8 -> 17.552058 | Z17: =+Z30/Z8 -> 17.811493 | ... AE17: =+AE30/AE8 -> 20.233643 | BB17: =+BB30/BB8 -> 13.122343 | BC17: =+BC30/BC8 -> 14.583884 | BD17: =+BD30/BD8 -> 14.597697 | BE17: =+BE30/BE8 -> 15.984848 | BF17: =+BF30/BF8 -> 13.684625 | BG17: =+BG30/BG8 -> 15.140669 | BH17: =+BH30/BH8 -> 14.945346 | BI17: =+BI30/BI8 -> 17.07863 | ... CL17: =+CL30/CL8 -> 18.110716 | CM17: =+CI17*1.04 -> 18.712989 | CN17: =+CJ17*1.04 -> 18.585825 | CO17: =+CK17*1.04 -> 18.449789 | CP17: =+CL17*1.05 -> 19.016252 | CQ17: =+CM17*1.05 -> 19.648639 | CR17: =+CN17*1.04 -> 19.329258 | CS17: =+CO17*1.04 -> 19.18778 | CT17: =+CP17*0.97 -> 18.445765 | CU17: =+CQ17*0.97 -> 19.05918 | CV17: =+CR17*0.97 -> 18.74938 | CW17: =+CS17*0.97 -> 18.612147 | CX17: =+CT17*1.08 -> 19.921426 | CY17: =+CU17*1.08 -> 20.583914 | CZ17: =+CV17*1.08 -> 20.24933 | DA17: =+CW17*1.08 -> 20.101119
A18: RM | S18: =S17-S19 -> 6.5109928 | T18: =T17-T19 -> 6.6002912 | U18: =U17-U19 -> 6.6931975 | V18: =V17-V19 -> 6.5033812 | W18: =W17-W19 -> 7.1032746 | X18: =X17-X19 -> 7.8166742 | Y18: =Y17-Y19 -> 8.101628 | Z18: =Z17-Z19 -> 7.9272892 | ... AE18: =AE17-AE19 -> 9.0063499 | BB18: =BB17-BB19 -> 5.9717313 | BC18: =BC17-BC19 -> 6.9906518 | BD18: =BD17-BD19 -> 6.594303 | BE18: =BE17-BE19 -> 5.811303 | BF18: =BF17-BF19 -> 6.14495 | BG18: =BG17-BG19 -> 7.0503309 | BH18: =BH17-BH19 -> 6.7524872 | BI18: =BI17-BI19 -> 5.8035652 | ... CL18: =CL17-CL19 -> 8.1147245
A19: GP | S19: =+S36/S8 -> 7.8902302 | T19: =+T36/T8 -> 8.4151647 | U19: =+U36/U8 -> 8.12921 | V19: =+V36/V8 -> 8.6734235 | W19: =+W36/W8 -> 8.430581 | X19: =+X36/X8 -> 8.629196 | Y19: =+Y36/Y8 -> 9.45043 | Z19: =+Z36/Z8 -> 9.8842037 | ... AE19: =+AE36/AE8 -> 11.227293 | BB19: =+BB36/BB8 -> 7.1506119 | BC19: =+BC36/BC8 -> 7.5932321 | BD19: =+BD36/BD8 -> 8.0033939 | BE19: =+BE36/BE8 -> 10.173545 | BF19: =+BF36/BF8 -> 7.539675 | BG19: =+BG36/BG8 -> 8.0903382 | BH19: =+BH36/BH8 -> 8.192859 | BI19: =+BI36/BI8 -> 11.275065 | ... CL19: =+CL36/CL8 -> 9.9959917
A20: VC | S20: =+S42/S8 -> 1.5667878 | T20: =+T42/T8 -> 1.8364618 | U20: =+U42/U8 -> 1.7132308 | V20: =+V42/V8 -> 2.0541671 | W20: =+W42/W8 -> 1.8911162 | X20: =+X42/X8 -> 1.9125655 | Y20: =+Y42/Y8 -> 2.0002407 | Z20: =+Z42/Z8 -> 2.1126876 | ... AE20: =+AE42/AE8 -> 4.9048081 | BB20: =+BB42/BB8 -> 3.4605522 | BC20: =+BC42/BC8 -> 2.2573571 | BD20: =+BD42/BD8 -> 3.3761061 | BE20: =+BE42/BE8 -> 5.9801212 | BF20: =+BF42/BF8 -> 3.6482375 | BG20: =+BG42/BG8 -> 2.7526691 | BH20: =+BH42/BH8 -> 3.5793333 | BI20: =+BI42/BI8 -> 7.0914783 | ... CL20: =+CL42/CL8 -> 4.0780854
A21: Contribution | S21: =+S19-S20 -> 6.3234424 | T21: =+T19-T20 -> 6.5787029 | U21: =+U19-U20 -> 6.4159792 | V21: =+V19-V20 -> 6.6192565 | W21: =+W19-W20 -> 6.5394648 | X21: =+X19-X20 -> 6.7166305 | Y21: =+Y19-Y20 -> 7.4501893 | Z21: =+Z19-Z20 -> 7.7715161 | ... AE21: =+AE19-AE20 -> 6.3224854 | BB21: =+BB19-BB20 -> 3.6900597 | BC21: =+BC19-BC20 -> 5.335875 | BD21: =+BD19-BD20 -> 4.6272879 | BE21: =+BE19-BE20 -> 4.1934242 | BF21: =+BF19-BF20 -> 3.8914375 | BG21: =+BG19-BG20 -> 5.3376691 | BH21: =+BH19-BH20 -> 4.6135256 | BI21: =+BI19-BI20 -> 4.183587 | ... CL21: =+CL19-CL20 -> 5.9179063
A22: FC | S22: =+S43/S8 -> 1.6649065 | T22: =+T43/T8 -> 1.7145618 | U22: =+U43/U8 -> 1.6856861 | V22: =+V43/V8 -> 2.0934965 | W22: =+W43/W8 -> 1.774118 | X22: =+X43/X8 -> 1.5189039 | Y22: =+Y43/Y8 -> 1.5826991 | Z22: =+Z43/Z8 -> 1.6781145 | ... AE22: =+AE43/AE8 -> 1.6116015 | BB22: =+BB43/BB8 -> 1.6417612 | BC22: =+BC43/BC8 -> 1.0456964 | BD22: =+BD43/BD8 -> 1.8175758 | BE22: =+BE43/BE8 -> 3.5081212 | BF22: =+BF43/BF8 -> 1.7327625 | BG22: =+BG43/BG8 -> 1.1107721 | BH22: =+BH43/BH8 -> 1.9053077 | BI22: =+BI43/BI8 -> 3.144587 | ... CL22: =+CL43/CL8 -> 1.7059862
A23: EBITDA | S23: =S21-S22 -> 4.658536 | T23: =T21-T22 -> 4.8641412 | U23: =U21-U22 -> 4.7302931 | V23: =V21-V22 -> 4.52576 | W23: =W21-W22 -> 4.7653468 | X23: =X21-X22 -> 5.1977266 | Y23: =Y21-Y22 -> 5.8674902 | Z23: =Z21-Z22 -> 6.0934016 | ... AE23: =AE21-AE22 -> 4.7108839 | BB23: =BB21-BB22 -> 2.0482985 | BC23: =BC21-BC22 -> 4.2901786 | BD23: =BD21-BD22 -> 2.8097121 | BE23: =BE21-BE22 -> 0.68530303 | BF23: =BF21-BF22 -> 2.158675 | BG23: =BG21-BG22 -> 4.2268971 | BH23: =BH21-BH22 -> 2.7082179 | BI23: =BI21-BI22 -> 1.039 | ... CL23: =CL21-CL22 -> 4.2119201
A26: Presentation Data (End)
A27: Profit & Loss- Annual (Start)
A28: Gross Revenue | B28: ='Annual Raw'!C6 -> 0 | C28: ='Annual Raw'!D6 -> 0 | D28: ='Annual Raw'!E6 -> 0 | E28: ='Annual Raw'!F6 -> 0 | F28: ='Annual Raw'!G6 -> 340.68526 | G28: ='Annual Raw'!H6 -> 367.68239 | H28: ='Annual Raw'!I6 -> 373.99352 | I28: ='Annual Raw'!J6 -> 425.89375 | ... Z28: ='Annual Raw'!AA6 -> 21234.143 | AA28: =SUM(CH28:CK28) -> 22225.584 | AB28: =+SUM(CL28:CO28) -> 25087.742 | AC28: =+SUM(CP28:CS28) -> 28963.152 | AD28: =+SUM(CT28:CW28) -> 31096.131 | AE28: =+SUM(CX28:DA28) -> 37324.564 | AI28: ='QTR Raw'!C6+'QTR Raw'!C8 -> 0 | AJ28: ='QTR Raw'!D6+'QTR Raw'!D8 -> 0 | AK28: ='QTR Raw'!E6+'QTR Raw'!E8 -> 0 | AL28: ='QTR Raw'!F6+'QTR Raw'!F8 -> 0 | AM28: ='QTR Raw'!G6+'QTR Raw'!G8 -> 0 | AN28: ='QTR Raw'!H6+'QTR Raw'!H8 -> 0 | AO28: ='QTR Raw'!I6+'QTR Raw'!I8 -> 0 | AP28: ='QTR Raw'!J6+'QTR Raw'!J8 -> 0 | ... CL28: ='QTR Raw'!BF6+'QTR Raw'!BF8 -> 6721.537 | CM28: =CM8*CM17 -> 7841.0803 | CN28: =CN8*CN17 -> 5609.3238 | CO28: =CO8*CO17 -> 4915.8005 | CP28: =CP8*CP17 -> 7783.7432 | CQ28: =CQ8*CQ17 -> 9057.0172 | CR28: =CR8*CR17 -> 6453.101 | CS28: =CS8*CS17 -> 5669.2905 | CT28: =CT8*CT17 -> 8328.1611 | ... DA28: =DA8*DA17 -> 7364.4926
A29: Less: Exise Duty | B29: ='Annual Raw'!C7+'Annual Raw'!C8+'Annual Raw'!C9 -> 0 | C29: ='Annual Raw'!D7+'Annual Raw'!D8+'Annual Raw'!D9 -> 0 | D29: ='Annual Raw'!E7+'Annual Raw'!E8+'Annual Raw'!E9 -> 0 | E29: ='Annual Raw'!F7+'Annual Raw'!F8+'Annual Raw'!F9 -> 0 | F29: ='Annual Raw'!G7+'Annual Raw'!G8+'Annual Raw'!G9 -> 57.193838 | G29: ='Annual Raw'!H7+'Annual Raw'!H8+'Annual Raw'!H9 -> 60.750738 | H29: ='Annual Raw'!I7+'Annual Raw'!I8+'Annual Raw'!I9 -> 46.140744 | I29: ='Annual Raw'!J7+'Annual Raw'!J8+'Annual Raw'!J9 -> 53.163081 | ... Z29: ='Annual Raw'!AA7+'Annual Raw'!AA8+'Annual Raw'!AA9 -> 1226.493 | AA29: =SUM(CH29:CK29) -> 540.205 | AB29: =+SUM(CL29:CO29) -> 147.347 | AC29: =+SUM(CP29:CS29) -> 0 | AD29: =+SUM(CT29:CW29) -> 0 | AE29: =+SUM(CX29:DA29) -> 0 | AI29: ='QTR Raw'!C21+'QTR Raw'!C20+'QTR Raw'!C19+'QTR Raw'!C13+'QTR Raw'!C7 -> 0 | AJ29: ='QTR Raw'!D21+'QTR Raw'!D20+'QTR Raw'!D19+'QTR Raw'!D13+'QTR Raw'!D7 -> 0 | AK29: ='QTR Raw'!E21+'QTR Raw'!E20+'QTR Raw'!E19+'QTR Raw'!E13+'QTR Raw'!E7 -> 0 | AL29: ='QTR Raw'!F21+'QTR Raw'!F20+'QTR Raw'!F19+'QTR Raw'!F13+'QTR Raw'!F7 -> 0 | AM29: ='QTR Raw'!G21+'QTR Raw'!G20+'QTR Raw'!G19+'QTR Raw'!G13+'QTR Raw'!G7 -> 0 | AN29: ='QTR Raw'!H21+'QTR Raw'!H20+'QTR Raw'!H19+'QTR Raw'!H13+'QTR Raw'!H7 -> 0 | AO29: ='QTR Raw'!I21+'QTR Raw'!I20+'QTR Raw'!I19+'QTR Raw'!I13+'QTR Raw'!I7 -> 0 | AP29: ='QTR Raw'!J21+'QTR Raw'!J20+'QTR Raw'!J19+'QTR Raw'!J13+'QTR Raw'!J7 -> 0 | ... CL29: ='QTR Raw'!BF21+'QTR Raw'!BF20+'QTR Raw'!BF19+'QTR Raw'!BF13+'QTR Raw'!BF7 -> 147.347
A30: Net Revenue | B30: =+B28-B29 -> 0 | C30: =+C28-C29 -> 0 | D30: =+D28-D29 -> 0 | E30: =+E28-E29 -> 0 | F30: =+F28-F29 -> 283.49143 | G30: =+G28-G29 -> 306.93166 | H30: =+H28-H29 -> 327.85278 | I30: =+I28-I29 -> 372.73067 | ... AE30: =+AE28-AE29 -> 37324.564 | AI30: =+AI28-AI29 -> 0 | AJ30: =+AJ28-AJ29 -> 0 | AK30: =+AK28-AK29 -> 0 | AL30: =+AL28-AL29 -> 0 | AM30: =+AM28-AM29 -> 0 | AN30: =+AN28-AN29 -> 0 | AO30: =+AO28-AO29 -> 0 | AP30: =+AP28-AP29 -> 0 | ... DA30: =+DA28-DA29 -> 7364.4926
A31: Net Revenue YOY% | C31: =C30/B30-1 -> #DIV/0! | D31: =D30/C30-1 -> #DIV/0! | E31: =E30/D30-1 -> #DIV/0! | F31: =F30/E30-1 -> #DIV/0! | G31: =G30/F30-1 -> 0.082684091 | H31: =H30/G30-1 -> 0.068162154 | I31: =I30/H30-1 -> 0.13688428 | J31: =J30/I30-1 -> 0.23371979 | ... AE31: =AE30/AD30-1 -> 0.20029609 | AM31: =+IF(AI30<0,1-AM30/AI30,AM30/AI30-1) -> #DIV/0! | AN31: =+IF(AJ30<0,1-AN30/AJ30,AN30/AJ30-1) -> #DIV/0! | AO31: =+IF(AK30<0,1-AO30/AK30,AO30/AK30-1) -> #DIV/0! | AP31: =+IF(AL30<0,1-AP30/AL30,AP30/AL30-1) -> #DIV/0! | AQ31: =+IF(AM30<0,1-AQ30/AM30,AQ30/AM30-1) -> #DIV/0! | AR31: =+IF(AN30<0,1-AR30/AN30,AR30/AN30-1) -> #DIV/0! | AS31: =+IF(AO30<0,1-AS30/AO30,AS30/AO30-1) -> #DIV/0! | AT31: =+IF(AP30<0,1-AT30/AP30,AT30/AP30-1) -> #DIV/0! | ... DA31: =+IF(CW30<0,1-DA30/CW30,DA30/CW30-1) -> 0.20529805
A32: Net Revenue QOQ% | AJ32: =+IF(AI30<0,1-AJ30/AI30,AJ30/AI30-1) -> #DIV/0! | AK32: =+IF(AJ30<0,1-AK30/AJ30,AK30/AJ30-1) -> #DIV/0! | AL32: =+IF(AK30<0,1-AL30/AK30,AL30/AK30-1) -> #DIV/0! | AM32: =+IF(AL30<0,1-AM30/AL30,AM30/AL30-1) -> #DIV/0! | AN32: =+IF(AM30<0,1-AN30/AM30,AN30/AM30-1) -> #DIV/0! | AO32: =+IF(AN30<0,1-AO30/AN30,AO30/AN30-1) -> #DIV/0! | AP32: =+IF(AO30<0,1-AP30/AO30,AP30/AO30-1) -> #DIV/0! | AQ32: =+IF(AP30<0,1-AQ30/AP30,AQ30/AP30-1) -> #DIV/0! | ... DA32: =+IF(CZ30<0,1-DA30/CZ30,DA30/CZ30-1) -> -0.11677086
A33: Increase/Decrease in Stock | B33: ='Annual Raw'!C11 -> 0 | C33: ='Annual Raw'!D11 -> 0 | D33: ='Annual Raw'!E11 -> 0 | E33: ='Annual Raw'!F11 -> 0 | F33: ='Annual Raw'!G11 -> -7.2403229 | G33: ='Annual Raw'!H11 -> 2.2733899 | H33: ='Annual Raw'!I11 -> -0.031626 | I33: ='Annual Raw'!J11 -> -2.1219878 | ... Z33: ='Annual Raw'!AA11 -> -74.94 | AA33: =SUM(CH33:CK33) -> 8.914 | AB33: =+SUM(CL33:CO33) -> -271.768 | AC33: =+SUM(CP33:CS33) -> 0 | AD33: =+SUM(CT33:CW33) -> 0 | AE33: =+SUM(CX33:DA33) -> 0 | AI33: ='QTR Raw'!C10 -> 0 | AJ33: ='QTR Raw'!D10 -> 0 | AK33: ='QTR Raw'!E10 -> 0 | AL33: ='QTR Raw'!F10 -> 0 | AM33: ='QTR Raw'!G10 -> 0 | AN33: ='QTR Raw'!H10 -> 0 | AO33: ='QTR Raw'!I10 -> 0 | AP33: ='QTR Raw'!J10 -> 0 | ... CL33: ='QTR Raw'!BF10 -> -271.768
A34: Purchase of Finished Goods | B34: 0 | C34: 0 | D34: 0 | E34: 0 | F34: 0 | G34: 0 | H34: 0 | I34: 0 | J34: 0 | K34: 0 | L34: 0 | M34: 0 | N34: 0 | O34: 0 | P34: 0 | Q34: 0 | R34: 0 | S34: 0 | T34: 0 | U34: 0 | V34: 0 | W34: 0 | X34: 0 | Y34: 0 | Z34: 0 | AA34: =SUM(CH34:CK34) -> 369.453 | AB34: =+SUM(CL34:CO34) -> 65.211 | AC34: =+SUM(CP34:CS34) -> 0 | AD34: =+SUM(CT34:CW34) -> 0 | AE34: =+SUM(CX34:DA34) -> 0 | AI34: ='QTR Raw'!C12 -> 0 | AJ34: ='QTR Raw'!D12 -> 0 | AK34: ='QTR Raw'!E12 -> 0 | AL34: ='QTR Raw'!F12 -> 0 | AM34: ='QTR Raw'!G12 -> 0 | AN34: ='QTR Raw'!H12 -> 0 | AO34: ='QTR Raw'!I12 -> 0 | AP34: ='QTR Raw'!J12 -> 0 | ... CL34: ='QTR Raw'!BF12 -> 65.211
A35: Raw Material Consumed | B35: ='Annual Raw'!C12 -> 0 | C35: ='Annual Raw'!D12 -> 0 | D35: ='Annual Raw'!E12 -> 0 | E35: ='Annual Raw'!F12 -> 0 | F35: ='Annual Raw'!G12 -> 146.19765 | G35: ='Annual Raw'!H12 -> 156.13787 | H35: ='Annual Raw'!I12 -> 175.91754 | I35: ='Annual Raw'!J12 -> 209.33044 | ... Z35: ='Annual Raw'!AA12 -> 8979.664 | AA35: =SUM(CH35:CK35) -> 9337.062 | AB35: =+SUM(CL35:CO35) -> 11321.696 | AC35: =+SUM(CP35:CS35) -> 12893.524 | AD35: =+SUM(CT35:CW35) -> 13841.444 | AE35: =+SUM(CX35:DA35) -> 16613.819 | AI35: ='QTR Raw'!C11 -> 0 | AJ35: ='QTR Raw'!D11 -> 0 | AK35: ='QTR Raw'!E11 -> 0 | AL35: ='QTR Raw'!F11 -> 0 | AM35: ='QTR Raw'!G11 -> 0 | AN35: ='QTR Raw'!H11 -> 0 | AO35: ='QTR Raw'!I11 -> 0 | AP35: ='QTR Raw'!J11 -> 0 | ... CL35: ='QTR Raw'!BF11 -> 3152.202 | CM35: =+CM30-CM36 -> 3492.8145 | CN35: =+CN30-CN36 -> 2485.6458 | CO35: =+CO30-CO36 -> 2191.0342 | CP35: =+CP30-CP36 -> 3468.3442 | CQ35: =+CQ30-CQ36 -> 4030.0987 | CR35: =+CR30-CR36 -> 2870.6589 | CS35: =+CS30-CS36 -> 2524.4218 | CT35: =+CT30-CT36 -> 3707.4631 | ... DA35: =+DA30-DA36 -> 3278.1227
A36: Gross Profit | B36: =B30-B33-B35-B34 -> 0 | C36: =C30-C33-C35-C34 -> 0 | D36: =D30-D33-D35-D34 -> 0 | E36: =E30-E33-E35-E34 -> 0 | F36: =F30-F33-F35-F34 -> 144.5341 | G36: =G30-G33-G35-G34 -> 148.52039 | H36: =H30-H33-H35-H34 -> 151.96687 | I36: =I30-I33-I35-I34 -> 165.52222 | ... AE36: =AE30-AE33-AE35-AE34 -> 20710.745 | AI36: =AI30-AI33-AI35-AI34 -> 0 | AJ36: =AJ30-AJ33-AJ35-AJ34 -> 0 | AK36: =AK30-AK33-AK35-AK34 -> 0 | AL36: =AL30-AL33-AL35-AL34 -> 0 | AM36: =AM30-AM33-AM35-AM34 -> 0 | AN36: =AN30-AN33-AN35-AN34 -> 0 | AO36: =AO30-AO33-AO35-AO34 -> 0 | AP36: =AP30-AP33-AP35-AP34 -> 0 | ... CL36: =CL30-CL33-CL35-CL34 -> 3628.545 | CM36: =+CM37*CM30 -> 4348.2658 | CN36: =+CN37*CN30 -> 3123.678 | CO36: =+CO37*CO30 -> 2724.7663 | CP36: =+CP37*CP30 -> 4315.399 | CQ36: =+CQ37*CQ30 -> 5026.9185 | CR36: =+CR37*CR30 -> 3582.4421 | CS36: =+CS37*CS30 -> 3144.8688 | CT36: =+CT37*CT30 -> 4620.698 | ... DA36: =+DA37*DA30 -> 4086.3699
A37: GP% | B37: =B36/B30 -> #DIV/0! | C37: =C36/C30 -> #DIV/0! | D37: =D36/D30 -> #DIV/0! | E37: =E36/E30 -> #DIV/0! | F37: =F36/F30 -> 0.50983587 | G37: =G36/G30 -> 0.4838875 | H37: =H36/H30 -> 0.46352167 | I37: =I36/I30 -> 0.44407995 | ... AE37: =AE36/AE30 -> 0.55488244 | AI37: =AI36/AI30 -> #DIV/0! | AJ37: =AJ36/AJ30 -> #DIV/0! | AK37: =AK36/AK30 -> #DIV/0! | AL37: =AL36/AL30 -> #DIV/0! | AM37: =AM36/AM30 -> #DIV/0! | AN37: =AN36/AN30 -> #DIV/0! | AO37: =AO36/AO30 -> #DIV/0! | AP37: =AP36/AP30 -> #DIV/0! | ... CL37: =CL36/CL30 -> 0.55193796 | CM37: =AVERAGE(CI37:CL37) -> 0.55454933 | CN37: =AVERAGE(CJ37:CM37) -> 0.55687247 | CO37: =AVERAGE(CK37:CN37) -> 0.55428741 | CP37: =AVERAGE(CL37:CO37) -> 0.55441179 | CQ37: =AVERAGE(CM37:CP37) -> 0.55503025 | CR37: =AVERAGE(CN37:CQ37) -> 0.55515048 | CS37: =AVERAGE(CO37:CR37) -> 0.55471998 | CT37: =AVERAGE(CP37:CS37) -> 0.55482813 | ... DA37: =AVERAGE(CW37:CZ37) -> 0.5548746
A38: GP YOY% | C38: =+IF(B36<0,1-C36/B36,C36/B36-1) -> #DIV/0! | D38: =+IF(C36<0,1-D36/C36,D36/C36-1) -> #DIV/0! | E38: =+IF(D36<0,1-E36/D36,E36/D36-1) -> #DIV/0! | F38: =+IF(E36<0,1-F36/E36,F36/E36-1) -> #DIV/0! | G38: =+IF(F36<0,1-G36/F36,G36/F36-1) -> 0.027580297 | H38: =+IF(G36<0,1-H36/G36,H36/G36-1) -> 0.023205412 | I38: =+IF(H36<0,1-I36/H36,I36/H36-1) -> 0.089199359 | J38: =+IF(I36<0,1-J36/I36,J36/I36-1) -> 0.21628057 | ... AE38: =+IF(AD36<0,1-AE36/AD36,AE36/AD36-1) -> 0.20029678 | AM38: =+IF(AI36<0,1-AM36/AI36,AM36/AI36-1) -> #DIV/0! | AN38: =+IF(AJ36<0,1-AN36/AJ36,AN36/AJ36-1) -> #DIV/0! | AO38: =+IF(AK36<0,1-AO36/AK36,AO36/AK36-1) -> #DIV/0! | AP38: =+IF(AL36<0,1-AP36/AL36,AP36/AL36-1) -> #DIV/0! | AQ38: =+IF(AM36<0,1-AQ36/AM36,AQ36/AM36-1) -> #DIV/0! | AR38: =+IF(AN36<0,1-AR36/AN36,AR36/AN36-1) -> #DIV/0! | AS38: =+IF(AO36<0,1-AS36/AO36,AS36/AO36-1) -> #DIV/0! | AT38: =+IF(AP36<0,1-AT36/AP36,AT36/AP36-1) -> #DIV/0! | ... CL38: =+IF(CH36<0,1-CL36/CH36,CL36/CH36-1) -> 0.19443643 | CM38: =+CM36/CI36-1 -> 0.13642449 | CN38: =+CN36/CJ36-1 -> 0.12466002 | CO38: =+CO36/CK36-1 -> 0.17024779 | CP38: =+CP36/CL36-1 -> 0.18929186 | CQ38: =+CQ36/CM36-1 -> 0.15607434 | CR38: =+CR36/CN36-1 -> 0.14686665 | CS38: =+CS36/CO36-1 -> 0.15417924 | CT38: =+CT36/CP36-1 -> 0.07074641 | ... DA38: =+DA36/CW36-1 -> 0.205358
A39: GP QOQ% | AJ39: =+IF(AI36<0,1-AJ36/AI36,AJ36/AI36-1) -> #DIV/0! | AK39: =+IF(AJ36<0,1-AK36/AJ36,AK36/AJ36-1) -> #DIV/0! | AL39: =+IF(AK36<0,1-AL36/AK36,AL36/AK36-1) -> #DIV/0! | AM39: =+IF(AL36<0,1-AM36/AL36,AM36/AL36-1) -> #DIV/0! | AN39: =+IF(AM36<0,1-AN36/AM36,AN36/AM36-1) -> #DIV/0! | AO39: =+IF(AN36<0,1-AO36/AN36,AO36/AN36-1) -> #DIV/0! | AP39: =+IF(AO36<0,1-AP36/AO36,AP36/AO36-1) -> #DIV/0! | AQ39: =+IF(AP36<0,1-AQ36/AP36,AQ36/AP36-1) -> #DIV/0! | ... CL39: =+IF(CK36<0,1-CL36/CK36,CL36/CK36-1) -> 0.55840767 | CM39: =+CM36/CL36-1 -> 0.1983497 | CN39: =+CN36/CM36-1 -> -0.28162672 | CO39: =+CO36/CN36-1 -> -0.12770575 | CP39: =+CP36/CO36-1 -> 0.58376847 | CQ39: =+CQ36/CP36-1 -> 0.16487919 | CR39: =+CR36/CQ36-1 -> -0.28734829 | CS39: =+CS36/CR36-1 -> -0.12214387 | CT39: =+CT36/CS36-1 -> 0.46928167 | ... DA39: =+DA36/CZ36-1 -> -0.1167814
A40: Power & Fuel Cost | B40: ='Annual Raw'!C13 -> 0 | C40: ='Annual Raw'!D13 -> 0 | D40: ='Annual Raw'!E13 -> 0 | E40: ='Annual Raw'!F13 -> 0 | F40: ='Annual Raw'!G13 -> 16.275857 | G40: ='Annual Raw'!H13 -> 17.007646 | H40: ='Annual Raw'!I13 -> 15.316662 | I40: ='Annual Raw'!J13 -> 14.83647 | ... Z40: ='Annual Raw'!AA13 -> 629.508 | AA40: =SUM(CH40:CK40) -> 0 | AB40: =+SUM(CL40:CO40) -> 0 | AC40: =+SUM(CP40:CS40) -> 0 | AD40: =+SUM(CT40:CW40) -> 0 | AE40: =+SUM(CX40:DA40) -> 0 | AI40: ='QTR Raw'!C15 -> 0 | AJ40: ='QTR Raw'!D15 -> 0 | AK40: ='QTR Raw'!E15 -> 0 | AL40: ='QTR Raw'!F15 -> 0 | AM40: ='QTR Raw'!G15 -> 0 | AN40: ='QTR Raw'!H15 -> 0 | AO40: ='QTR Raw'!I15 -> 0 | AP40: ='QTR Raw'!J15 -> 0 | ... CL40: ='QTR Raw'!BF15 -> 0
A41: Selling and Distribution Expenses | B41: =('Annual Raw'!C18) -> 0 | C41: =('Annual Raw'!D18) -> 0 | D41: =('Annual Raw'!E18) -> 0 | E41: =('Annual Raw'!F18) -> 0 | F41: =('Annual Raw'!G18) -> 2.9303384 | G41: =('Annual Raw'!H18) -> 4.3703567 | H41: =('Annual Raw'!I18) -> 2.9705899 | I41: =('Annual Raw'!J18) -> 4.6175069 | ... Z41: =('Annual Raw'!AA18) -> 669.552 | AA41: =SUM(CH41:CK41) -> 0 | AB41: =+SUM(CL41:CO41) -> 0 | AC41: =+SUM(CP41:CS41) -> 0 | AD41: =+SUM(CT41:CW41) -> 0 | AE41: =+SUM(CX41:DA41) -> 0 | AI41: ='QTR Raw'!C18 -> 0 | AJ41: ='QTR Raw'!D18 -> 0 | AK41: ='QTR Raw'!E18 -> 0 | AL41: ='QTR Raw'!F18 -> 0 | AM41: ='QTR Raw'!G18 -> 0 | AN41: ='QTR Raw'!H18 -> 0 | AO41: ='QTR Raw'!I18 -> 0 | AP41: ='QTR Raw'!J18 -> 0 | ... CL41: ='QTR Raw'!BF18 -> 0
A42: Other Manufacturing Expenses | B42: ='Annual Raw'!C15+'Annual Raw'!C16 -> 0 | C42: ='Annual Raw'!D15+'Annual Raw'!D16 -> 0 | D42: ='Annual Raw'!E15+'Annual Raw'!E16 -> 0 | E42: ='Annual Raw'!F15+'Annual Raw'!F16 -> 0 | F42: ='Annual Raw'!G15+'Annual Raw'!G16 -> 41.620309 | G42: ='Annual Raw'!H15+'Annual Raw'!H16 -> 43.679928 | H42: ='Annual Raw'!I15+'Annual Raw'!I16 -> 46.400612 | I42: ='Annual Raw'!J15+'Annual Raw'!J16 -> 51.546875 | ... Z42: ='Annual Raw'!AA15+'Annual Raw'!AA16 -> 2373.182 | AA42: =SUM(CH42:CK42) -> 4719.838 | AB42: =+SUM(CL42:CO42) -> 5675.9772 | AC42: =+SUM(CP42:CS42) -> 6582.8344 | AD42: =+SUM(CT42:CW42) -> 7225.6344 | AE42: =+SUM(CX42:DA42) -> 9047.7934 | AI42: ='QTR Raw'!C14 -> 0 | AJ42: ='QTR Raw'!D14 -> 0 | AK42: ='QTR Raw'!E14 -> 0 | AL42: ='QTR Raw'!F14 -> 0 | AM42: ='QTR Raw'!G14 -> 0 | AN42: ='QTR Raw'!H14 -> 0 | AO42: ='QTR Raw'!I14 -> 0 | AP42: ='QTR Raw'!J14 -> 0 | ... CL42: ='QTR Raw'!BF14 -> 1480.345 | CM42: =CM46-CM43 -> 1911.2194 | CN42: =CN46-CN43 -> 1275.2655 | CO42: =CO46-CO43 -> 1009.1473 | CP42: =CP46-CP43 -> 1798.5929 | CQ42: =CQ46-CQ43 -> 2227.55 | CR42: =CR46-CR43 -> 1396.807 | CS42: =CS46-CS43 -> 1159.8844 | CT42: =CT46-CT43 -> 1960.0268 | ... DA42: =DA46-DA43 -> 1603.3251
A43: Employee Cost | B43: ='Annual Raw'!C14 -> 0 | C43: ='Annual Raw'!D14 -> 0 | D43: ='Annual Raw'!E14 -> 0 | E43: ='Annual Raw'!F14 -> 0 | F43: ='Annual Raw'!G14 -> 15.354206 | G43: ='Annual Raw'!H14 -> 18.509317 | H43: ='Annual Raw'!I14 -> 20.416254 | I43: ='Annual Raw'!J14 -> 21.135453 | ... Z43: ='Annual Raw'!AA14 -> 1885.026 | AA43: =SUM(CH43:CK43) -> 2200.743 | AB43: =+SUM(CL43:CO43) -> 2426.7609 | AC43: =+SUM(CP43:CS43) -> 2596.6341 | AD43: =+SUM(CT43:CW43) -> 2778.3985 | AE43: =+SUM(CX43:DA43) -> 2972.8864 | AI43: ='QTR Raw'!C16 -> 0 | AJ43: ='QTR Raw'!D16 -> 0 | AK43: ='QTR Raw'!E16 -> 0 | AL43: ='QTR Raw'!F16 -> 0 | AM43: ='QTR Raw'!G16 -> 0 | AN43: ='QTR Raw'!H16 -> 0 | AO43: ='QTR Raw'!I16 -> 0 | AP43: ='QTR Raw'!J16 -> 0 | ... CL43: ='QTR Raw'!BF16 -> 619.273 | CM43: =CI43*107% -> 588.13406 | CN43: =CJ43*107% -> 592.0524 | CO43: =CK43*107% -> 627.30141 | CP43: =CL43*107% -> 662.62211 | CQ43: =CM43*107% -> 629.30344 | CR43: =CN43*107% -> 633.49607 | CS43: =CO43*107% -> 671.21251 | CT43: =CP43*107% -> 709.00566 | ... DA43: =CW43*107% -> 768.4712
A44: General and Administration Expenses | B44: ='Annual Raw'!C17 -> 0 | C44: ='Annual Raw'!D17 -> 0 | D44: ='Annual Raw'!E17 -> 0 | E44: ='Annual Raw'!F17 -> 0 | F44: ='Annual Raw'!G17 -> 6.838419 | G44: ='Annual Raw'!H17 -> 7.6012442 | H44: ='Annual Raw'!I17 -> 12.186069 | I44: ='Annual Raw'!J17 -> 13.76165 | ... Z44: ='Annual Raw'!AA17 -> 618.951 | AA44: =SUM(CH44:CK44) -> 0 | AB44: =+SUM(CL44:CO44) -> 0 | AC44: =+SUM(CP44:CS44) -> 0 | AD44: =+SUM(CT44:CW44) -> 0 | AE44: =+SUM(CX44:DA44) -> 0 | AI44: ='QTR Raw'!C17 -> 0 | AJ44: ='QTR Raw'!D17 -> 0 | AK44: ='QTR Raw'!E17 -> 0 | AL44: ='QTR Raw'!F17 -> 0 | AM44: ='QTR Raw'!G17 -> 0 | AN44: ='QTR Raw'!H17 -> 0 | AO44: ='QTR Raw'!I17 -> 0 | AP44: ='QTR Raw'!J17 -> 0 | ... CL44: ='QTR Raw'!BF17 -> 0
A45: Miscellaneous Expenses | B45: ='Annual Raw'!C19-'Annual Raw'!C20 -> 0 | C45: ='Annual Raw'!D19-'Annual Raw'!D20 -> 0 | D45: ='Annual Raw'!E19-'Annual Raw'!E20 -> 0 | E45: ='Annual Raw'!F19-'Annual Raw'!F20 -> 0 | F45: ='Annual Raw'!G19-'Annual Raw'!G20 -> 0.33951 | G45: ='Annual Raw'!H19-'Annual Raw'!H20 -> 2.0761435 | H45: ='Annual Raw'!I19-'Annual Raw'!I20 -> 0.178153 | I45: ='Annual Raw'!J19-'Annual Raw'!J20 -> 0.4061102 | ... Z45: ='Annual Raw'!AA19-'Annual Raw'!AA20 -> 183.164 | AA45: =SUM(CH45:CK45) -> 0 | AB45: =+SUM(CL45:CO45) -> 0 | AC45: =+SUM(CP45:CS45) -> 0 | AD45: =+SUM(CT45:CW45) -> 0 | AE45: =+SUM(CX45:DA45) -> 0
...

Sheet QTR Raw
A1: ='[1]Annual Raw'!A1 -> 209550 | B1: X | C1: 201206 | D1: 201209 | E1: 201212 | F1: 201303 | G1: 201306 | H1: 201309 | I1: 201312 | J1: 201403 | K1: 201406 | L1: 201409 | M1: 201412 | N1: 201503 | O1: 201506 | P1: 201509 | Q1: 201512 | R1: 201603 | S1: 201606 | T1: 201609 | U1: 201612 | V1: 201703 | W1: 201706 | X1: 201709 | Y1: 201712 | Z1: 201803 | AA1: 201806 | AB1: 201809 | AC1: 201812 | AD1: 201903 | AE1: 201906 | AF1: 201909 | AG1: 201912 | AH1: 202003 | AI1: 202006 | AJ1: 202009 | AK1: 202012 | AL1: 202103 | AM1: 202106 | AN1: 202109 | AO1: 202112 | AP1: 202203 | AQ1: 202206 | AR1: 202209 | AS1: 202212 | AT1: 202303 | AU1: 202306 | AV1: 202309 | AW1: 202312 | AX1: 202403 | AY1: 202406 | AZ1: 202409 | BA1: 202412 | BB1: 202503 | BC1: 202506 | BD1: 202509 | BE1: 202512 | BF1: 202603 | BG1: 202606 | BH1: 202609 | BI1: 202612 | BJ1: 202703 | BK1: 202706 | BL1: 202709 | BM1: 202712 | BN1: 202803 | BO1: 202806 | BP1: 202809 | BQ1: 202812 | BR1: 202903 | BS1: 202906 | BT1: 202909 | BU1: 202912
A3: Field Description | B3: Field Name
A4: Company Name | B4: CD_COMPNAME | C4: =_xll.EQNXTDZ(A1,B4,C1) -> Varun Beverages Ltd.
A5: Date End | B5: QTR_DATE_END | C5: =_xll.EQNXTDZ($A$1,$B5,C$1,$B$1) -> 0 | D5: =_xll.EQNXTDZ($A$1,$B5,D$1,$B$1) -> 0 | E5: =_xll.EQNXTDZ($A$1,$B5,E$1,$B$1) -> 0 | F5: =_xll.EQNXTDZ($A$1,$B5,F$1,$B$1) -> 0 | G5: =_xll.EQNXTDZ($A$1,$B5,G$1,$B$1) -> 0 | H5: =_xll.EQNXTDZ($A$1,$B5,H$1,$B$1) -> 0 | I5: =_xll.EQNXTDZ($A$1,$B5,I$1,$B$1) -> 0 | J5: =_xll.EQNXTDZ($A$1,$B5,J$1,$B$1) -> 0 | ... BU5: =_xll.EQNXTDZ($A$1,$B5,BU$1,$B$1) -> 0
A6: Gross Sales | B6: QTR_GROSS_SALE | C6: =_xll.EQNXTDZ($A$1,$B6,C$1,$B$1) -> 0 | D6: =_xll.EQNXTDZ($A$1,$B6,D$1,$B$1) -> 0 | E6: =_xll.EQNXTDZ($A$1,$B6,E$1,$B$1) -> 0 | F6: =_xll.EQNXTDZ($A$1,$B6,F$1,$B$1) -> 0 | G6: =_xll.EQNXTDZ($A$1,$B6,G$1,$B$1) -> 0 | H6: =_xll.EQNXTDZ($A$1,$B6,H$1,$B$1) -> 0 | I6: =_xll.EQNXTDZ($A$1,$B6,I$1,$B$1) -> 0 | J6: =_xll.EQNXTDZ($A$1,$B6,J$1,$B$1) -> 0 | ... BU6: =_xll.EQNXTDZ($A$1,$B6,BU$1,$B$1) -> 0
A7: Less: Excise Duty | B7: QTR_EXCISE_DUTY | C7: =_xll.EQNXTDZ($A$1,$B7,C$1,$B$1) -> 0 | D7: =_xll.EQNXTDZ($A$1,$B7,D$1,$B$1) -> 0 | E7: =_xll.EQNXTDZ($A$1,$B7,E$1,$B$1) -> 0 | F7: =_xll.EQNXTDZ($A$1,$B7,F$1,$B$1) -> 0 | G7: =_xll.EQNXTDZ($A$1,$B7,G$1,$B$1) -> 0 | H7: =_xll.EQNXTDZ($A$1,$B7,H$1,$B$1) -> 0 | I7: =_xll.EQNXTDZ($A$1,$B7,I$1,$B$1) -> 0 | J7: =_xll.EQNXTDZ($A$1,$B7,J$1,$B$1) -> 0 | ... BU7: =_xll.EQNXTDZ($A$1,$B7,BU$1,$B$1) -> 0
A8: Other operating income | B8: QTR_JOB_WORKS | C8: =_xll.EQNXTDZ($A$1,$B8,C$1,$B$1) -> 0 | D8: =_xll.EQNXTDZ($A$1,$B8,D$1,$B$1) -> 0 | E8: =_xll.EQNXTDZ($A$1,$B8,E$1,$B$1) -> 0 | F8: =_xll.EQNXTDZ($A$1,$B8,F$1,$B$1) -> 0 | G8: =_xll.EQNXTDZ($A$1,$B8,G$1,$B$1) -> 0 | H8: =_xll.EQNXTDZ($A$1,$B8,H$1,$B$1) -> 0 | I8: =_xll.EQNXTDZ($A$1,$B8,I$1,$B$1) -> 0 | J8: =_xll.EQNXTDZ($A$1,$B8,J$1,$B$1) -> 0 | ... BU8: =_xll.EQNXTDZ($A$1,$B8,BU$1,$B$1) -> 0
A9: Net Sales & Other Operating Income | B9: QTR_NET_SALES | C9: =_xll.EQNXTDZ($A$1,$B9,C$1,$B$1) -> 0 | D9: =_xll.EQNXTDZ($A$1,$B9,D$1,$B$1) -> 0 | E9: =_xll.EQNXTDZ($A$1,$B9,E$1,$B$1) -> 0 | F9: =_xll.EQNXTDZ($A$1,$B9,F$1,$B$1) -> 0 | G9: =_xll.EQNXTDZ($A$1,$B9,G$1,$B$1) -> 0 | H9: =_xll.EQNXTDZ($A$1,$B9,H$1,$B$1) -> 0 | I9: =_xll.EQNXTDZ($A$1,$B9,I$1,$B$1) -> 0 | J9: =_xll.EQNXTDZ($A$1,$B9,J$1,$B$1) -> 0 | ... BU9: =_xll.EQNXTDZ($A$1,$B9,BU$1,$B$1) -> 0
A10: (Increase) / Decrease In Stocks | B10: QTR_INC_DEC_INVENTORY | C10: =_xll.EQNXTDZ($A$1,$B10,C$1,$B$1) -> 0 | D10: =_xll.EQNXTDZ($A$1,$B10,D$1,$B$1) -> 0 | E10: =_xll.EQNXTDZ($A$1,$B10,E$1,$B$1) -> 0 | F10: =_xll.EQNXTDZ($A$1,$B10,F$1,$B$1) -> 0 | G10: =_xll.EQNXTDZ($A$1,$B10,G$1,$B$1) -> 0 | H10: =_xll.EQNXTDZ($A$1,$B10,H$1,$B$1) -> 0 | I10: =_xll.EQNXTDZ($A$1,$B10,I$1,$B$1) -> 0 | J10: =_xll.EQNXTDZ($A$1,$B10,J$1,$B$1) -> 0 | ... BU10: =_xll.EQNXTDZ($A$1,$B10,BU$1,$B$1) -> 0
A11: Cost of Services & Raw Materials | B11: QTR_RAW_MATERIAL_COST | C11: =_xll.EQNXTDZ($A$1,$B11,C$1,$B$1) -> 0 | D11: =_xll.EQNXTDZ($A$1,$B11,D$1,$B$1) -> 0 | E11: =_xll.EQNXTDZ($A$1,$B11,E$1,$B$1) -> 0 | F11: =_xll.EQNXTDZ($A$1,$B11,F$1,$B$1) -> 0 | G11: =_xll.EQNXTDZ($A$1,$B11,G$1,$B$1) -> 0 | H11: =_xll.EQNXTDZ($A$1,$B11,H$1,$B$1) -> 0 | I11: =_xll.EQNXTDZ($A$1,$B11,I$1,$B$1) -> 0 | J11: =_xll.EQNXTDZ($A$1,$B11,J$1,$B$1) -> 0 | ... BU11: =_xll.EQNXTDZ($A$1,$B11,BU$1,$B$1) -> 0
A12: Purchase of Finished Goods | B12: QTR_PURCHASE_FIN_GOOD | C12: =_xll.EQNXTDZ($A$1,$B12,C$1,$B$1) -> 0 | D12: =_xll.EQNXTDZ($A$1,$B12,D$1,$B$1) -> 0 | E12: =_xll.EQNXTDZ($A$1,$B12,E$1,$B$1) -> 0 | F12: =_xll.EQNXTDZ($A$1,$B12,F$1,$B$1) -> 0 | G12: =_xll.EQNXTDZ($A$1,$B12,G$1,$B$1) -> 0 | H12: =_xll.EQNXTDZ($A$1,$B12,H$1,$B$1) -> 0 | I12: =_xll.EQNXTDZ($A$1,$B12,I$1,$B$1) -> 0 | J12: =_xll.EQNXTDZ($A$1,$B12,J$1,$B$1) -> 0 | ... BU12: =_xll.EQNXTDZ($A$1,$B12,BU$1,$B$1) -> 0
A13: Excise Duty | B13: QTR_EXCISE | C13: =_xll.EQNXTDZ($A$1,$B13,C$1,$B$1) -> 0 | D13: =_xll.EQNXTDZ($A$1,$B13,D$1,$B$1) -> 0 | E13: =_xll.EQNXTDZ($A$1,$B13,E$1,$B$1) -> 0 | F13: =_xll.EQNXTDZ($A$1,$B13,F$1,$B$1) -> 0 | G13: =_xll.EQNXTDZ($A$1,$B13,G$1,$B$1) -> 0 | H13: =_xll.EQNXTDZ($A$1,$B13,H$1,$B$1) -> 0 | I13: =_xll.EQNXTDZ($A$1,$B13,I$1,$B$1) -> 0 | J13: =_xll.EQNXTDZ($A$1,$B13,J$1,$B$1) -> 0 | ... BU13: =_xll.EQNXTDZ($A$1,$B13,BU$1,$B$1) -> 0
A14: Operating & Manufacturing Expenses | B14: QTR_MFG_EXPS | C14: =_xll.EQNXTDZ($A$1,$B14,C$1,$B$1) -> 0 | D14: =_xll.EQNXTDZ($A$1,$B14,D$1,$B$1) -> 0 | E14: =_xll.EQNXTDZ($A$1,$B14,E$1,$B$1) -> 0 | F14: =_xll.EQNXTDZ($A$1,$B14,F$1,$B$1) -> 0 | G14: =_xll.EQNXTDZ($A$1,$B14,G$1,$B$1) -> 0 | H14: =_xll.EQNXTDZ($A$1,$B14,H$1,$B$1) -> 0 | I14: =_xll.EQNXTDZ($A$1,$B14,I$1,$B$1) -> 0 | J14: =_xll.EQNXTDZ($A$1,$B14,J$1,$B$1) -> 0 | ... BU14: =_xll.EQNXTDZ($A$1,$B14,BU$1,$B$1) -> 0
A15: Electricity Power & Fuel Cost | B15: QTR_ELECTRICITY_POWER_FUEL | C15: =_xll.EQNXTDZ($A$1,$B15,C$1,$B$1) -> 0 | D15: =_xll.EQNXTDZ($A$1,$B15,D$1,$B$1) -> 0 | E15: =_xll.EQNXTDZ($A$1,$B15,E$1,$B$1) -> 0 | F15: =_xll.EQNXTDZ($A$1,$B15,F$1,$B$1) -> 0 | G15: =_xll.EQNXTDZ($A$1,$B15,G$1,$B$1) -> 0 | H15: =_xll.EQNXTDZ($A$1,$B15,H$1,$B$1) -> 0 | I15: =_xll.EQNXTDZ($A$1,$B15,I$1,$B$1) -> 0 | J15: =_xll.EQNXTDZ($A$1,$B15,J$1,$B$1) -> 0 | ... BU15: =_xll.EQNXTDZ($A$1,$B15,BU$1,$B$1) -> 0
A16: Employee Cost | B16: QTR_EXPLOYEE_COST | C16: =_xll.EQNXTDZ($A$1,$B16,C$1,$B$1) -> 0 | D16: =_xll.EQNXTDZ($A$1,$B16,D$1,$B$1) -> 0 | E16: =_xll.EQNXTDZ($A$1,$B16,E$1,$B$1) -> 0 | F16: =_xll.EQNXTDZ($A$1,$B16,F$1,$B$1) -> 0 | G16: =_xll.EQNXTDZ($A$1,$B16,G$1,$B$1) -> 0 | H16: =_xll.EQNXTDZ($A$1,$B16,H$1,$B$1) -> 0 | I16: =_xll.EQNXTDZ($A$1,$B16,I$1,$B$1) -> 0 | J16: =_xll.EQNXTDZ($A$1,$B16,J$1,$B$1) -> 0 | ... BU16: =_xll.EQNXTDZ($A$1,$B16,BU$1,$B$1) -> 0
... A42: Consolidated PAT(after extra items) | B42: QTR_CONS_PAT_EXITM | C42: =_xll.EQNXTDZ($A$1,$B42,C$1,$B$1) -> 0 | D42: =_xll.EQNXTDZ($A$1,$B42,D$1,$B$1) -> 0 | E42: =_xll.EQNXTDZ($A$1,$B42,E$1,$B$1) -> 0 | F42: =_xll.EQNXTDZ($A$1,$B42,F$1,$B$1) -> 0 | G42: =_xll.EQNXTDZ($A$1,$B42,G$1,$B$1) -> 0 | H42: =_xll.EQNXTDZ($A$1,$B42,H$1,$B$1) -> 0 | I42: =_xll.EQNXTDZ($A$1,$B42,I$1,$B$1) -> 0 | J42: =_xll.EQNXTDZ($A$1,$B42,J$1,$B$1) -> 0 | ... BU42: =_xll.EQNXTDZ($A$1,$B42,BU$1,$B$1) -> 0
A44: Field Description | B44: Field Name
A45: Equity Capital | B45: QTR_EQUITY_CAP | C45: =_xll.EQNXTDZ($A$1,$B45,C$1,$B$1) -> 0 | D45: =_xll.EQNXTDZ($A$1,$B45,D$1,$B$1) -> 0 | E45: =_xll.EQNXTDZ($A$1,$B45,E$1,$B$1) -> 0 | F45: =_xll.EQNXTDZ($A$1,$B45,F$1,$B$1) -> 0 | G45: =_xll.EQNXTDZ($A$1,$B45,G$1,$B$1) -> 0 | H45: =_xll.EQNXTDZ($A$1,$B45,H$1,$B$1) -> 0 | I45: =_xll.EQNXTDZ($A$1,$B45,I$1,$B$1) -> 0 | J45: =_xll.EQNXTDZ($A$1,$B45,J$1,$B$1) -> 0 | ... BU45: =_xll.EQNXTDZ($A$1,$B45,BU$1,$B$1) -> 0
A46: Face Value | B46: QTR_FV | C46: =_xll.EQNXTDZ($A$1,$B46,C$1,$B$1) -> 0 | D46: =_xll.EQNXTDZ($A$1,$B46,D$1,$B$1) -> 0 | E46: =_xll.EQNXTDZ($A$1,$B46,E$1,$B$1) -> 0 | F46: =_xll.EQNXTDZ($A$1,$B46,F$1,$B$1) -> 0 | G46: =_xll.EQNXTDZ($A$1,$B46,G$1,$B$1) -> 0 | H46: =_xll.EQNXTDZ($A$1,$B46,H$1,$B$1) -> 0 | I46: =_xll.EQNXTDZ($A$1,$B46,I$1,$B$1) -> 0 | J46: =_xll.EQNXTDZ($A$1,$B46,J$1,$B$1) -> 0 | ... BU46: =_xll.EQNXTDZ($A$1,$B46,BU$1,$B$1) -> 0
A47: Month End | B47: BMONTH_MONTHEND | C47: =_xll.EQNXTDZ($A$1,$B47,C$5) -> 0 | D47: =_xll.EQNXTDZ($A$1,$B47,D$5) -> 0 | E47: =_xll.EQNXTDZ($A$1,$B47,E$5) -> 0 | F47: =_xll.EQNXTDZ($A$1,$B47,F$5) -> 0 | G47: =_xll.EQNXTDZ($A$1,$B47,G$5) -> 0 | H47: =_xll.EQNXTDZ($A$1,$B47,H$5) -> 0 | I47: =_xll.EQNXTDZ($A$1,$B47,I$5) -> 0 | J47: =_xll.EQNXTDZ($A$1,$B47,J$5) -> 0 | ... BU47: =_xll.EQNXTDZ($A$1,$B47,BU$5) -> 0
A48: Close | B48: BMONTH_CLOSE | C48: =_xll.EQNXTDZ($A$1,$B48,C$5) -> 0 | D48: =_xll.EQNXTDZ($A$1,$B48,D$5) -> 0 | E48: =_xll.EQNXTDZ($A$1,$B48,E$5) -> 0 | F48: =_xll.EQNXTDZ($A$1,$B48,F$5) -> 0 | G48: =_xll.EQNXTDZ($A$1,$B48,G$5) -> 0 | H48: =_xll.EQNXTDZ($A$1,$B48,H$5) -> 0 | I48: =_xll.EQNXTDZ($A$1,$B48,I$5) -> 0 | J48: =_xll.EQNXTDZ($A$1,$B48,J$5) -> 0 | ... BU48: =_xll.EQNXTDZ($A$1,$B48,BU$5) -> 0
A49: Total of Promoter and Promoter Group | B49: SHP_TPFTOTALPROMOTER | C49: =_xll.EQNXTDZ($A$1,$B49,C$5) -> 0 | D49: =_xll.EQNXTDZ($A$1,$B49,D$5) -> 0 | E49: =_xll.EQNXTDZ($A$1,$B49,E$5) -> 0 | F49: =_xll.EQNXTDZ($A$1,$B49,F$5) -> 0 | G49: =_xll.EQNXTDZ($A$1,$B49,G$5) -> 0 | H49: =_xll.EQNXTDZ($A$1,$B49,H$5) -> 0 | I49: =_xll.EQNXTDZ($A$1,$B49,I$5) -> 0 | J49: =_xll.EQNXTDZ($A$1,$B49,J$5) -> 0 | ... BU49: =_xll.EQNXTDZ($A$1,$B49,BU$5) -> 0
A50: Total of Promoter and Promoter Group Pledged | B50: SHP_PSHFTOTALPROMOTER | C50: =_xll.EQNXTDZ($A$1,$B50,C$5) -> 0 | D50: =_xll.EQNXTDZ($A$1,$B50,D$5) -> 0 | E50: =_xll.EQNXTDZ($A$1,$B50,E$5) -> 0 | F50: =_xll.EQNXTDZ($A$1,$B50,F$5) -> 0 | G50: =_xll.EQNXTDZ($A$1,$B50,G$5) -> 0 | H50: =_xll.EQNXTDZ($A$1,$B50,H$5) -> 0 | I50: =_xll.EQNXTDZ($A$1,$B50,I$5) -> 0 | J50: =_xll.EQNXTDZ($A$1,$B50,J$5) -> 0 | ... BU50: =_xll.EQNXTDZ($A$1,$B50,BU$5) -> 0
A54: Field Description | B54: Field Name | C54: =_xll.EQNXTDZ($A$1,$B54,C$5) -> 0 | D54: =_xll.EQNXTDZ($A$1,$B54,D$5) -> 0 | E54: =_xll.EQNXTDZ($A$1,$B54,E$5) -> 0 | F54: =_xll.EQNXTDZ($A$1,$B54,F$5) -> 0 | G54: =_xll.EQNXTDZ($A$1,$B54,G$5) -> 0 | H54: =_xll.EQNXTDZ($A$1,$B54,H$5) -> 0 | I54: =_xll.EQNXTDZ($A$1,$B54,I$5) -> 0 | J54: =_xll.EQNXTDZ($A$1,$B54,J$5) -> 0 | ... BU54: =_xll.EQNXTDZ($A$1,$B54,BU$5) -> 0
A55: Year End | B55: QTRB_DATE_END | C55: =_xll.EQNXTDZ($A$1,$B55,C$5,$B$1) -> 0 | D55: =_xll.EQNXTDZ($A$1,$B55,D$5,$B$1) -> 0 | E55: =_xll.EQNXTDZ($A$1,$B55,E$5,$B$1) -> 0 | F55: =_xll.EQNXTDZ($A$1,$B55,F$5,$B$1) -> 0 | G55: =_xll.EQNXTDZ($A$1,$B55,G$5,$B$1) -> 0 | H55: =_xll.EQNXTDZ($A$1,$B55,H$5,$B$1) -> 0 | I55: =_xll.EQNXTDZ($A$1,$B55,I$5,$B$1) -> 0 | J55: =_xll.EQNXTDZ($A$1,$B55,J$5,$B$1) -> 0 | ... BU55: =_xll.EQNXTDZ($A$1,$B55,BU$5,$B$1) -> 0
A56: Share Capital | B56: QTRB_SHARE_CAPITAL | C56: =_xll.EQNXTDZ($A$1,$B56,C$5,$B$1) -> 0 | D56: =_xll.EQNXTDZ($A$1,$B56,D$5,$B$1) -> 0 | E56: =_xll.EQNXTDZ($A$1,$B56,E$5,$B$1) -> 0 | F56: =_xll.EQNXTDZ($A$1,$B56,F$5,$B$1) -> 0 | G56: =_xll.EQNXTDZ($A$1,$B56,G$5,$B$1) -> 0 | H56: =_xll.EQNXTDZ($A$1,$B56,H$5,$B$1) -> 0 | I56: =_xll.EQNXTDZ($A$1,$B56,I$5,$B$1) -> 0 | J56: =_xll.EQNXTDZ($A$1,$B56,J$5,$B$1) -> 0 | ... BU56: =_xll.EQNXTDZ($A$1,$B56,BU$5,$B$1) -> 0
A57: Share Warrants & outstandings | B57: QTRB_SHAREWARNDOUT | C57: =_xll.EQNXTDZ($A$1,$B57,C$5,$B$1) -> 0 | D57: =_xll.EQNXTDZ($A$1,$B57,D$5,$B$1) -> 0 | E57: =_xll.EQNXTDZ($A$1,$B57,E$5,$B$1) -> 0 | F57: =_xll.EQNXTDZ($A$1,$B57,F$5,$B$1) -> 0 | G57: =_xll.EQNXTDZ($A$1,$B57,G$5,$B$1) -> 0 | H57: =_xll.EQNXTDZ($A$1,$B57,H$5,$B$1) -> 0 | I57: =_xll.EQNXTDZ($A$1,$B57,I$5,$B$1) -> 0 | J57: =_xll.EQNXTDZ($A$1,$B57,J$5,$B$1) -> 0 | ... BU57: =_xll.EQNXTDZ($A$1,$B57,BU$5,$B$1) -> 0
A58: Reserves & Surplus | B58: QTRB_RESERVE | C58: =_xll.EQNXTDZ($A$1,$B58,C$5,$B$1) -> 0 | D58: =_xll.EQNXTDZ($A$1,$B58,D$5,$B$1) -> 0 | E58: =_xll.EQNXTDZ($A$1,$B58,E$5,$B$1) -> 0 | F58: =_xll.EQNXTDZ($A$1,$B58,F$5,$B$1) -> 0 | G58: =_xll.EQNXTDZ($A$1,$B58,G$5,$B$1) -> 0 | H58: =_xll.EQNXTDZ($A$1,$B58,H$5,$B$1) -> 0 | I58: =_xll.EQNXTDZ($A$1,$B58,I$5,$B$1) -> 0 | J58: =_xll.EQNXTDZ($A$1,$B58,J$5,$B$1) -> 0 | ... BU58: =_xll.EQNXTDZ($A$1,$B58,BU$5,$B$1) -> 0
A59: Shareholder's Funds | B59: QTRB_SHAREHODERS_FUNDS | C59: =_xll.EQNXTDZ($A$1,$B59,C$5,$B$1) -> 0 | D59: =_xll.EQNXTDZ($A$1,$B59,D$5,$B$1) -> 0 | E59: =_xll.EQNXTDZ($A$1,$B59,E$5,$B$1) -> 0 | F59: =_xll.EQNXTDZ($A$1,$B59,F$5,$B$1) -> 0 | G59: =_xll.EQNXTDZ($A$1,$B59,G$5,$B$1) -> 0 | H59: =_xll.EQNXTDZ($A$1,$B59,H$5,$B$1) -> 0 | I59: =_xll.EQNXTDZ($A$1,$B59,I$5,$B$1) -> 0 | J59: =_xll.EQNXTDZ($A$1,$B59,J$5,$B$1) -> 0 | ... BU59: =_xll.EQNXTDZ($A$1,$B59,BU$5,$B$1) -> 0
A60: Minority Interest | B60: QTRB_MINORITY_INTEREST_BS | C60: =_xll.EQNXTDZ($A$1,$B60,C$5,$B$1) -> 0 | D60: =_xll.EQNXTDZ($A$1,$B60,D$5,$B$1) -> 0 | E60: =_xll.EQNXTDZ($A$1,$B60,E$5,$B$1) -> 0 | F60: =_xll.EQNXTDZ($A$1,$B60,F$5,$B$1) -> 0 | G60: =_xll.EQNXTDZ($A$1,$B60,G$5,$B$1) -> 0 | H60: =_xll.EQNXTDZ($A$1,$B60,H$5,$B$1) -> 0 | I60: =_xll.EQNXTDZ($A$1,$B60,I$5,$B$1) -> 0 | J60: =_xll.EQNXTDZ($A$1,$B60,J$5,$B$1) -> 0 | ... BU60: =_xll.EQNXTDZ($A$1,$B60,BU$5,$B$1) -> 0
A61: Long Term Borrowings | B61: QTRB_TOTAL_DEBTS | C61: =_xll.EQNXTDZ($A$1,$B61,C$5,$B$1) -> 0 | D61: =_xll.EQNXTDZ($A$1,$B61,D$5,$B$1) -> 0 | E61: =_xll.EQNXTDZ($A$1,$B61,E$5,$B$1) -> 0 | F61: =_xll.EQNXTDZ($A$1,$B61,F$5,$B$1) -> 0 | G61: =_xll.EQNXTDZ($A$1,$B61,G$5,$B$1) -> 0 | H61: =_xll.EQNXTDZ($A$1,$B61,H$5,$B$1) -> 0 | I61: =_xll.EQNXTDZ($A$1,$B61,I$5,$B$1) -> 0 | J61: =_xll.EQNXTDZ($A$1,$B61,J$5,$B$1) -> 0 | ... BU61: =_xll.EQNXTDZ($A$1,$B61,BU$5,$B$1) -> 0
A62: Secured Loans | B62: QTRB_SECURED_LOANS | C62: =_xll.EQNXTDZ($A$1,$B62,C$5,$B$1) -> 0 | D62: =_xll.EQNXTDZ($A$1,$B62,D$5,$B$1) -> 0 | E62: =_xll.EQNXTDZ($A$1,$B62,E$5,$B$1) -> 0 | F62: =_xll.EQNXTDZ($A$1,$B62,F$5,$B$1) -> 0 | G62: =_xll.EQNXTDZ($A$1,$B62,G$5,$B$1) -> 0 | H62: =_xll.EQNXTDZ($A$1,$B62,H$5,$B$1) -> 0 | I62: =_xll.EQNXTDZ($A$1,$B62,I$5,$B$1) -> 0 | J62: =_xll.EQNXTDZ($A$1,$B62,J$5,$B$1) -> 0 | ... BU62: =_xll.EQNXTDZ($A$1,$B62,BU$5,$B$1) -> 0
A63: Unsecured Loans | B63: QTRB_UNSECURED_LOANS_NF | C63: =_xll.EQNXTDZ($A$1,$B63,C$5,$B$1) -> 0 | D63: =_xll.EQNXTDZ($A$1,$B63,D$5,$B$1) -> 0 | E63: =_xll.EQNXTDZ($A$1,$B63,E$5,$B$1) -> 0 | F63: =_xll.EQNXTDZ($A$1,$B63,F$5,$B$1) -> 0 | G63: =_xll.EQNXTDZ($A$1,$B63,G$5,$B$1) -> 0 | H63: =_xll.EQNXTDZ($A$1,$B63,H$5,$B$1) -> 0 | I63: =_xll.EQNXTDZ($A$1,$B63,I$5,$B$1) -> 0 | J63: =_xll.EQNXTDZ($A$1,$B63,J$5,$B$1) -> 0 | ... BU63: =_xll.EQNXTDZ($A$1,$B63,BU$5,$B$1) -> 0
A64: Other Long Term Liabilities | B64: QTRB_OTHER_LT_LIABILITIES | C64: =_xll.EQNXTDZ($A$1,$B64,C$5,$B$1) -> 0 | D64: =_xll.EQNXTDZ($A$1,$B64,D$5,$B$1) -> 0 | E64: =_xll.EQNXTDZ($A$1,$B64,E$5,$B$1) -> 0 | F64: =_xll.EQNXTDZ($A$1,$B64,F$5,$B$1) -> 0 | G64: =_xll.EQNXTDZ($A$1,$B64,G$5,$B$1) -> 0 | H64: =_xll.EQNXTDZ($A$1,$B64,H$5,$B$1) -> 0 | I64: =_xll.EQNXTDZ($A$1,$B64,I$5,$B$1) -> 0 | J64: =_xll.EQNXTDZ($A$1,$B64,J$5,$B$1) -> 0 | ... BU64: =_xll.EQNXTDZ($A$1,$B64,BU$5,$B$1) -> 0
A65: Long Term Trade Payables | B65: QTRB_LT_TRADE_PAYABLE | C65: =_xll.EQNXTDZ($A$1,$B65,C$5,$B$1) -> 0 | D65: =_xll.EQNXTDZ($A$1,$B65,D$5,$B$1) -> 0 | E65: =_xll.EQNXTDZ($A$1,$B65,E$5,$B$1) -> 0 | F65: =_xll.EQNXTDZ($A$1,$B65,F$5,$B$1) -> 0 | G65: =_xll.EQNXTDZ($A$1,$B65,G$5,$B$1) -> 0 | H65: =_xll.EQNXTDZ($A$1,$B65,H$5,$B$1) -> 0 | I65: =_xll.EQNXTDZ($A$1,$B65,I$5,$B$1) -> 0 | J65: =_xll.EQNXTDZ($A$1,$B65,J$5,$B$1) -> 0 | ... BU65: =_xll.EQNXTDZ($A$1,$B65,BU$5,$B$1) -> 0
A66: Lont Term Provisions | B66: QTRB_LT_PROVISIONS | C66: =_xll.EQNXTDZ($A$1,$B66,C$5,$B$1) -> 0 | D66: =_xll.EQNXTDZ($A$1,$B66,D$5,$B$1) -> 0 | E66: =_xll.EQNXTDZ($A$1,$B66,E$5,$B$1) -> 0 | F66: =_xll.EQNXTDZ($A$1,$B66,F$5,$B$1) -> 0 | G66: =_xll.EQNXTDZ($A$1,$B66,G$5,$B$1) -> 0 | H66: =_xll.EQNXTDZ($A$1,$B66,H$5,$B$1) -> 0 | I66: =_xll.EQNXTDZ($A$1,$B66,I$5,$B$1) -> 0 | J66: =_xll.EQNXTDZ($A$1,$B66,J$5,$B$1) -> 0 | ... BU66: =_xll.EQNXTDZ($A$1,$B66,BU$5,$B$1) -> 0
... A97: Total Assets | B97: QTRB_TOTAL_APPLICATIONS | C97: =_xll.EQNXTDZ($A$1,$B97,C$5,$B$1) -> 0 | D97: =_xll.EQNXTDZ($A$1,$B97,D$5,$B$1) -> 0 | E97: =_xll.EQNXTDZ($A$1,$B97,E$5,$B$1) -> 0 | F97: =_xll.EQNXTDZ($A$1,$B97,F$5,$B$1) -> 0 | G97: =_xll.EQNXTDZ($A$1,$B97,G$5,$B$1) -> 0 | H97: =_xll.EQNXTDZ($A$1,$B97,H$5,$B$1) -> 0 | I97: =_xll.EQNXTDZ($A$1,$B97,I$5,$B$1) -> 0 | J97: =_xll.EQNXTDZ($A$1,$B97,J$5,$B$1) -> 0 | ... BU97: =_xll.EQNXTDZ($A$1,$B97,BU$5,$B$1) -> 0

Sheet Annual Raw
A1: 209550 | B1: X | C1: 200003 | D1: 200103 | E1: 200212 | F1: 200312 | G1: 200412 | H1: 200512 | I1: 200612 | J1: 200712 | K1: 200812 | L1: 200912 | M1: 201012 | N1: 201112 | O1: 201212 | P1: 201312 | Q1: 201412 | R1: 201512 | S1: 201612 | T1: 201712 | U1: 201812 | V1: 201912 | W1: 202012 | X1: 202112 | Y1: 202212 | Z1: 202312 | AA1: 202412 | AB1: 202512 | AC1: 202612 | AD1: 202712 | AE1: 202812 | AF1: 202912 | AG1: 203012
A3: Field Description | B3: Field Name
A4: Company Name | B4: CD_COMPNAME | C4: =_xll.EQNXTDZ(A1,B4,"L") -> Varun Beverages Ltd.
A5: Year End | B5: PL_YEAR_END | C5: =_xll.EQNXTDZ($A$1,$B5,C$1,$B$1) -> 0 | D5: =_xll.EQNXTDZ($A$1,$B5,D$1,$B$1) -> 0 | E5: =_xll.EQNXTDZ($A$1,$B5,E$1,$B$1) -> 0 | F5: =_xll.EQNXTDZ($A$1,$B5,F$1,$B$1) -> 0 | G5: =_xll.EQNXTDZ($A$1,$B5,G$1,$B$1) -> 200412 | H5: =_xll.EQNXTDZ($A$1,$B5,H$1,$B$1) -> 200512 | I5: =_xll.EQNXTDZ($A$1,$B5,I$1,$B$1) -> 200612 | J5: =_xll.EQNXTDZ($A$1,$B5,J$1,$B$1) -> 200712 | ... AG5: =_xll.EQNXTDZ($A$1,$B5,AG$1,$B$1) -> 0
A6: Sales Turnover | B6: PL_TOTAL_GROSS_SALES | C6: =_xll.EQNXTDZ($A$1,$B6,C$1,$B$1) -> 0 | D6: =_xll.EQNXTDZ($A$1,$B6,D$1,$B$1) -> 0 | E6: =_xll.EQNXTDZ($A$1,$B6,E$1,$B$1) -> 0 | F6: =_xll.EQNXTDZ($A$1,$B6,F$1,$B$1) -> 0 | G6: =_xll.EQNXTDZ($A$1,$B6,G$1,$B$1) -> 340.68526 | H6: =_xll.EQNXTDZ($A$1,$B6,H$1,$B$1) -> 367.68239 | I6: =_xll.EQNXTDZ($A$1,$B6,I$1,$B$1) -> 373.99352 | J6: =_xll.EQNXTDZ($A$1,$B6,J$1,$B$1) -> 425.89375 | ... AG6: =_xll.EQNXTDZ($A$1,$B6,AG$1,$B$1) -> 0
A7: Less: Inter divisional transfers | B7: PL_INTER_DIV_TRF | C7: =_xll.EQNXTDZ($A$1,$B7,C$1,$B$1) -> 0 | D7: =_xll.EQNXTDZ($A$1,$B7,D$1,$B$1) -> 0 | E7: =_xll.EQNXTDZ($A$1,$B7,E$1,$B$1) -> 0 | F7: =_xll.EQNXTDZ($A$1,$B7,F$1,$B$1) -> 0 | G7: =_xll.EQNXTDZ($A$1,$B7,G$1,$B$1) -> 0 | H7: =_xll.EQNXTDZ($A$1,$B7,H$1,$B$1) -> 0 | I7: =_xll.EQNXTDZ($A$1,$B7,I$1,$B$1) -> 0 | J7: =_xll.EQNXTDZ($A$1,$B7,J$1,$B$1) -> 0 | ... AG7: =_xll.EQNXTDZ($A$1,$B7,AG$1,$B$1) -> 0
A8: Less: Sales Returns | B8: PL_SALES_RETURN | C8: =_xll.EQNXTDZ($A$1,$B8,C$1,$B$1) -> 0 | D8: =_xll.EQNXTDZ($A$1,$B8,D$1,$B$1) -> 0 | E8: =_xll.EQNXTDZ($A$1,$B8,E$1,$B$1) -> 0 | F8: =_xll.EQNXTDZ($A$1,$B8,F$1,$B$1) -> 0 | G8: =_xll.EQNXTDZ($A$1,$B8,G$1,$B$1) -> 0 | H8: =_xll.EQNXTDZ($A$1,$B8,H$1,$B$1) -> 0 | I8: =_xll.EQNXTDZ($A$1,$B8,I$1,$B$1) -> 0 | J8: =_xll.EQNXTDZ($A$1,$B8,J$1,$B$1) -> 0 | ... AG8: =_xll.EQNXTDZ($A$1,$B8,AG$1,$B$1) -> 0
A9: Less: Excise | B9: PL_EXCISE | C9: =_xll.EQNXTDZ($A$1,$B9,C$1,$B$1) -> 0 | D9: =_xll.EQNXTDZ($A$1,$B9,D$1,$B$1) -> 0 | E9: =_xll.EQNXTDZ($A$1,$B9,E$1,$B$1) -> 0 | F9: =_xll.EQNXTDZ($A$1,$B9,F$1,$B$1) -> 0 | G9: =_xll.EQNXTDZ($A$1,$B9,G$1,$B$1) -> 57.193838 | H9: =_xll.EQNXTDZ($A$1,$B9,H$1,$B$1) -> 60.750738 | I9: =_xll.EQNXTDZ($A$1,$B9,I$1,$B$1) -> 46.140744 | J9: =_xll.EQNXTDZ($A$1,$B9,J$1,$B$1) -> 53.163081 | ... AG9: =_xll.EQNXTDZ($A$1,$B9,AG$1,$B$1) -> 0
A10: Net Sales | B10: PL_NET_SALES | C10: =_xll.EQNXTDZ($A$1,$B10,C$1,$B$1) -> 0 | D10: =_xll.EQNXTDZ($A$1,$B10,D$1,$B$1) -> 0 | E10: =_xll.EQNXTDZ($A$1,$B10,E$1,$B$1) -> 0 | F10: =_xll.EQNXTDZ($A$1,$B10,F$1,$B$1) -> 0 | G10: =_xll.EQNXTDZ($A$1,$B10,G$1,$B$1) -> 283.49143 | H10: =_xll.EQNXTDZ($A$1,$B10,H$1,$B$1) -> 306.93166 | I10: =_xll.EQNXTDZ($A$1,$B10,I$1,$B$1) -> 327.85278 | J10: =_xll.EQNXTDZ($A$1,$B10,J$1,$B$1) -> 372.73067 | ... AG10: =_xll.EQNXTDZ($A$1,$B10,AG$1,$B$1) -> 0
A11: Increase/Decrease in Stock | B11: PL_INC_DEC_INVENTORY | C11: =_xll.EQNXTDZ($A$1,$B11,C$1,$B$1) -> 0 | D11: =_xll.EQNXTDZ($A$1,$B11,D$1,$B$1) -> 0 | E11: =_xll.EQNXTDZ($A$1,$B11,E$1,$B$1) -> 0 | F11: =_xll.EQNXTDZ($A$1,$B11,F$1,$B$1) -> 0 | G11: =_xll.EQNXTDZ($A$1,$B11,G$1,$B$1) -> -7.2403229 | H11: =_xll.EQNXTDZ($A$1,$B11,H$1,$B$1) -> 2.2733899 | I11: =_xll.EQNXTDZ($A$1,$B11,I$1,$B$1) -> -0.031626 | J11: =_xll.EQNXTDZ($A$1,$B11,J$1,$B$1) -> -2.1219878 | ... AG11: =_xll.EQNXTDZ($A$1,$B11,AG$1,$B$1) -> 0
A12: Raw Material Consumed | B12: PL_RAW_MATRS_CONSUMED | C12: =_xll.EQNXTDZ($A$1,$B12,C$1,$B$1) -> 0 | D12: =_xll.EQNXTDZ($A$1,$B12,D$1,$B$1) -> 0 | E12: =_xll.EQNXTDZ($A$1,$B12,E$1,$B$1) -> 0 | F12: =_xll.EQNXTDZ($A$1,$B12,F$1,$B$1) -> 0 | G12: =_xll.EQNXTDZ($A$1,$B12,G$1,$B$1) -> 146.19765 | H12: =_xll.EQNXTDZ($A$1,$B12,H$1,$B$1) -> 156.13787 | I12: =_xll.EQNXTDZ($A$1,$B12,I$1,$B$1) -> 175.91754 | J12: =_xll.EQNXTDZ($A$1,$B12,J$1,$B$1) -> 209.33044 | ... AG12: =_xll.EQNXTDZ($A$1,$B12,AG$1,$B$1) -> 0
A13: Power & Fuel Cost | B13: PL_POWER_FUEL | C13: =_xll.EQNXTDZ($A$1,$B13,C$1,$B$1) -> 0 | D13: =_xll.EQNXTDZ($A$1,$B13,D$1,$B$1) -> 0 | E13: =_xll.EQNXTDZ($A$1,$B13,E$1,$B$1) -> 0 | F13: =_xll.EQNXTDZ($A$1,$B13,F$1,$B$1) -> 0 | G13: =_xll.EQNXTDZ($A$1,$B13,G$1,$B$1) -> 16.275857 | H13: =_xll.EQNXTDZ($A$1,$B13,H$1,$B$1) -> 17.007646 | I13: =_xll.EQNXTDZ($A$1,$B13,I$1,$B$1) -> 15.316662 | J13: =_xll.EQNXTDZ($A$1,$B13,J$1,$B$1) -> 14.83647 | ... AG13: =_xll.EQNXTDZ($A$1,$B13,AG$1,$B$1) -> 0
A14: Employee Cost | B14: PL_EMPLOYEES | C14: =_xll.EQNXTDZ($A$1,$B14,C$1,$B$1) -> 0 | D14: =_xll.EQNXTDZ($A$1,$B14,D$1,$B$1) -> 0 | E14: =_xll.EQNXTDZ($A$1,$B14,E$1,$B$1) -> 0 | F14: =_xll.EQNXTDZ($A$1,$B14,F$1,$B$1) -> 0 | G14: =_xll.EQNXTDZ($A$1,$B14,G$1,$B$1) -> 15.354206 | H14: =_xll.EQNXTDZ($A$1,$B14,H$1,$B$1) -> 18.509317 | I14: =_xll.EQNXTDZ($A$1,$B14,I$1,$B$1) -> 20.416254 | J14: =_xll.EQNXTDZ($A$1,$B14,J$1,$B$1) -> 21.135453 | ... AG14: =_xll.EQNXTDZ($A$1,$B14,AG$1,$B$1) -> 0
A15: Operating & Manufacturing Expenses | B15: PL_GEN_OTHER_MFG_EXPS | C15: =_xll.EQNXTDZ($A$1,$B15,C$1,$B$1) -> 0 | D15: =_xll.EQNXTDZ($A$1,$B15,D$1,$B$1) -> 0 | E15: =_xll.EQNXTDZ($A$1,$B15,E$1,$B$1) -> 0 | F15: =_xll.EQNXTDZ($A$1,$B15,F$1,$B$1) -> 0 | G15: =_xll.EQNXTDZ($A$1,$B15,G$1,$B$1) -> 41.620309 | H15: =_xll.EQNXTDZ($A$1,$B15,H$1,$B$1) -> 43.679928 | I15: =_xll.EQNXTDZ($A$1,$B15,I$1,$B$1) -> 46.400612 | J15: =_xll.EQNXTDZ($A$1,$B15,J$1,$B$1) -> 51.546875 | ... AG15: =_xll.EQNXTDZ($A$1,$B15,AG$1,$B$1) -> 0
A16: Cost of Software development | B16: PL_COST_SW | C16: =_xll.EQNXTDZ($A$1,$B16,C$1,$B$1) -> 0 | D16: =_xll.EQNXTDZ($A$1,$B16,D$1,$B$1) -> 0 | E16: =_xll.EQNXTDZ($A$1,$B16,E$1,$B$1) -> 0 | F16: =_xll.EQNXTDZ($A$1,$B16,F$1,$B$1) -> 0 | G16: =_xll.EQNXTDZ($A$1,$B16,G$1,$B$1) -> 0 | H16: =_xll.EQNXTDZ($A$1,$B16,H$1,$B$1) -> 0 | I16: =_xll.EQNXTDZ($A$1,$B16,I$1,$B$1) -> 0 | J16: =_xll.EQNXTDZ($A$1,$B16,J$1,$B$1) -> 0 | ... AG16: =_xll.EQNXTDZ($A$1,$B16,AG$1,$B$1) -> 0
... A36: Profit After Tax from Discontinued Operations | B36: PL_PAT_DIS_OP | C36: =_xll.EQNXTDZ($A$1,$B36,C$1,$B$1) -> 0 | D36: =_xll.EQNXTDZ($A$1,$B36,D$1,$B$1) -> 0 | E36: =_xll.EQNXTDZ($A$1,$B36,E$1,$B$1) -> 0 | F36: =_xll.EQNXTDZ($A$1,$B36,F$1,$B$1) -> 0 | G36: =_xll.EQNXTDZ($A$1,$B36,G$1,$B$1) -> 0 | H36: =_xll.EQNXTDZ($A$1,$B36,H$1,$B$1) -> 0 | I36: =_xll.EQNXTDZ($A$1,$B36,I$1,$B$1) -> 0 | J36: =_xll.EQNXTDZ($A$1,$B36,J$1,$B$1) -> 0 | ... AG36: =_xll.EQNXTDZ($A$1,$B36,AG$1,$B$1) -> 0
A39: Field Description | B39: Field Name
A40: Year End | B40: BS_YEAR_END | C40: =_xll.EQNXTDZ($A$1,$B40,C$1,$B$1) -> 0 | D40: =_xll.EQNXTDZ($A$1,$B40,D$1,$B$1) -> 0 | E40: =_xll.EQNXTDZ($A$1,$B40,E$1,$B$1) -> 0 | F40: =_xll.EQNXTDZ($A$1,$B40,F$1,$B$1) -> 0 | G40: =_xll.EQNXTDZ($A$1,$B40,G$1,$B$1) -> 200412 | H40: =_xll.EQNXTDZ($A$1,$B40,H$1,$B$1) -> 200512 | I40: =_xll.EQNXTDZ($A$1,$B40,I$1,$B$1) -> 200612 | J40: =_xll.EQNXTDZ($A$1,$B40,J$1,$B$1) -> 200712 | ... AG40: =_xll.EQNXTDZ($A$1,$B40,AG$1,$B$1) -> 0
A41: Share Capital | B41: BS_SHARE_CAPITAL | C41: =_xll.EQNXTDZ($A$1,$B41,C$1,$B$1) -> 0 | D41: =_xll.EQNXTDZ($A$1,$B41,D$1,$B$1) -> 0 | E41: =_xll.EQNXTDZ($A$1,$B41,E$1,$B$1) -> 0 | F41: =_xll.EQNXTDZ($A$1,$B41,F$1,$B$1) -> 0 | G41: =_xll.EQNXTDZ($A$1,$B41,G$1,$B$1) -> 85.37635 | H41: =_xll.EQNXTDZ($A$1,$B41,H$1,$B$1) -> 85.37635 | I41: =_xll.EQNXTDZ($A$1,$B41,I$1,$B$1) -> 85.37635 | J41: =_xll.EQNXTDZ($A$1,$B41,J$1,$B$1) -> 85.37635 | ... AG41: =_xll.EQNXTDZ($A$1,$B41,AG$1,$B$1) -> 0
A42: Share Warrants & Outstandings | B42: BS_SHAREWROUTST | C42: =_xll.EQNXTDZ($A$1,$B42,C$1,$B$1) -> 0 | D42: =_xll.EQNXTDZ($A$1,$B42,D$1,$B$1) -> 0 | E42: =_xll.EQNXTDZ($A$1,$B42,E$1,$B$1) -> 0 | F42: =_xll.EQNXTDZ($A$1,$B42,F$1,$B$1) -> 0 | G42: =_xll.EQNXTDZ($A$1,$B42,G$1,$B$1) -> 0 | H42: =_xll.EQNXTDZ($A$1,$B42,H$1,$B$1) -> 0 | I42: =_xll.EQNXTDZ($A$1,$B42,I$1,$B$1) -> 0 | J42: =_xll.EQNXTDZ($A$1,$B42,J$1,$B$1) -> 0 | ... AG42: =_xll.EQNXTDZ($A$1,$B42,AG$1,$B$1) -> 0
A43: Total Reserves | B43: BS_RESERVE | C43: =_xll.EQNXTDZ($A$1,$B43,C$1,$B$1) -> 0 | D43: =_xll.EQNXTDZ($A$1,$B43,D$1,$B$1) -> 0 | E43: =_xll.EQNXTDZ($A$1,$B43,E$1,$B$1) -> 0 | F43: =_xll.EQNXTDZ($A$1,$B43,F$1,$B$1) -> 0 | G43: =_xll.EQNXTDZ($A$1,$B43,G$1,$B$1) -> 62.854672 | H43: =_xll.EQNXTDZ($A$1,$B43,H$1,$B$1) -> 74.238345 | I43: =_xll.EQNXTDZ($A$1,$B43,I$1,$B$1) -> 87.674491 | J43: =_xll.EQNXTDZ($A$1,$B43,J$1,$B$1) -> 108.87775 | ... AG43: =_xll.EQNXTDZ($A$1,$B43,AG$1,$B$1) -> 0
A44: Shareholder's Funds | B44: BS_SHAREHODERS_FUNDS | C44: =_xll.EQNXTDZ($A$1,$B44,C$1,$B$1) -> 0 | D44: =_xll.EQNXTDZ($A$1,$B44,D$1,$B$1) -> 0 | E44: =_xll.EQNXTDZ($A$1,$B44,E$1,$B$1) -> 0 | F44: =_xll.EQNXTDZ($A$1,$B44,F$1,$B$1) -> 0 | G44: =_xll.EQNXTDZ($A$1,$B44,G$1,$B$1) -> 148.23102 | H44: =_xll.EQNXTDZ($A$1,$B44,H$1,$B$1) -> 159.61469 | I44: =_xll.EQNXTDZ($A$1,$B44,I$1,$B$1) -> 173.05084 | J44: =_xll.EQNXTDZ($A$1,$B44,J$1,$B$1) -> 194.2541 | ... AG44: =_xll.EQNXTDZ($A$1,$B44,AG$1,$B$1) -> 0
A45: Minority Interest | B45: BS_MINORITY_INTEREST | C45: =_xll.EQNXTDZ($A$1,$B45,C$1,$B$1) -> 0 | D45: =_xll.EQNXTDZ($A$1,$B45,D$1,$B$1) -> 0 | E45: =_xll.EQNXTDZ($A$1,$B45,E$1,$B$1) -> 0 | F45: =_xll.EQNXTDZ($A$1,$B45,F$1,$B$1) -> 0 | G45: =_xll.EQNXTDZ($A$1,$B45,G$1,$B$1) -> 0 | H45: =_xll.EQNXTDZ($A$1,$B45,H$1,$B$1) -> 0 | I45: =_xll.EQNXTDZ($A$1,$B45,I$1,$B$1) -> 0 | J45: =_xll.EQNXTDZ($A$1,$B45,J$1,$B$1) -> 0 | ... AG45: =_xll.EQNXTDZ($A$1,$B45,AG$1,$B$1) -> 0
A46: Long-Term Borrowings | B46: BS_LTRM_BORROWING | C46: =_xll.EQNXTDZ($A$1,$B46,C$1,$B$1) -> 0 | D46: =_xll.EQNXTDZ($A$1,$B46,D$1,$B$1) -> 0 | E46: =_xll.EQNXTDZ($A$1,$B46,E$1,$B$1) -> 0 | F46: =_xll.EQNXTDZ($A$1,$B46,F$1,$B$1) -> 0 | G46: =_xll.EQNXTDZ($A$1,$B46,G$1,$B$1) -> 0 | H46: =_xll.EQNXTDZ($A$1,$B46,H$1,$B$1) -> 0 | I46: =_xll.EQNXTDZ($A$1,$B46,I$1,$B$1) -> 0 | J46: =_xll.EQNXTDZ($A$1,$B46,J$1,$B$1) -> 0 | ... AG46: =_xll.EQNXTDZ($A$1,$B46,AG$1,$B$1) -> 0
A47: Secured Loans | B47: BS_SECURED_LOANS | C47: =_xll.EQNXTDZ($A$1,$B47,C$1,$B$1) -> 0 | D47: =_xll.EQNXTDZ($A$1,$B47,D$1,$B$1) -> 0 | E47: =_xll.EQNXTDZ($A$1,$B47,E$1,$B$1) -> 0 | F47: =_xll.EQNXTDZ($A$1,$B47,F$1,$B$1) -> 0 | G47: =_xll.EQNXTDZ($A$1,$B47,G$1,$B$1) -> 165.50054 | H47: =_xll.EQNXTDZ($A$1,$B47,H$1,$B$1) -> 139.91501 | I47: =_xll.EQNXTDZ($A$1,$B47,I$1,$B$1) -> 124.55949 | J47: =_xll.EQNXTDZ($A$1,$B47,J$1,$B$1) -> 105.7051 | ... AG47: =_xll.EQNXTDZ($A$1,$B47,AG$1,$B$1) -> 0
A48: Unsecured Loans | B48: BS_UNSECURED_LOANS_NF | C48: =_xll.EQNXTDZ($A$1,$B48,C$1,$B$1) -> 0 | D48: =_xll.EQNXTDZ($A$1,$B48,D$1,$B$1) -> 0 | E48: =_xll.EQNXTDZ($A$1,$B48,E$1,$B$1) -> 0 | F48: =_xll.EQNXTDZ($A$1,$B48,F$1,$B$1) -> 0 | G48: =_xll.EQNXTDZ($A$1,$B48,G$1,$B$1) -> 5 | H48: =_xll.EQNXTDZ($A$1,$B48,H$1,$B$1) -> 5 | I48: =_xll.EQNXTDZ($A$1,$B48,I$1,$B$1) -> 8.9282734 | J48: =_xll.EQNXTDZ($A$1,$B48,J$1,$B$1) -> 22.405578 | ... AG48: =_xll.EQNXTDZ($A$1,$B48,AG$1,$B$1) -> 0
A49: Deferred Tax Assets / Liabilities | B49: BS_NET_DEF_TAX_NF | C49: =_xll.EQNXTDZ($A$1,$B49,C$1,$B$1) -> 0 | D49: =_xll.EQNXTDZ($A$1,$B49,D$1,$B$1) -> 0 | E49: =_xll.EQNXTDZ($A$1,$B49,E$1,$B$1) -> 0 | F49: =_xll.EQNXTDZ($A$1,$B49,F$1,$B$1) -> 0 | G49: =_xll.EQNXTDZ($A$1,$B49,G$1,$B$1) -> 37.21096 | H49: =_xll.EQNXTDZ($A$1,$B49,H$1,$B$1) -> 44.297339 | I49: =_xll.EQNXTDZ($A$1,$B49,I$1,$B$1) -> 46.438748 | J49: =_xll.EQNXTDZ($A$1,$B49,J$1,$B$1) -> 50.766549 | ... AG49: =_xll.EQNXTDZ($A$1,$B49,AG$1,$B$1) -> 0
A50: Other Long Term Liabilities | B50: BS_OTH_LT_LIAB | C50: =_xll.EQNXTDZ($A$1,$B50,C$1,$B$1) -> 0 | D50: =_xll.EQNXTDZ($A$1,$B50,D$1,$B$1) -> 0 | E50: =_xll.EQNXTDZ($A$1,$B50,E$1,$B$1) -> 0 | F50: =_xll.EQNXTDZ($A$1,$B50,F$1,$B$1) -> 0 | G50: =_xll.EQNXTDZ($A$1,$B50,G$1,$B$1) -> 0 | H50: =_xll.EQNXTDZ($A$1,$B50,H$1,$B$1) -> 0 | I50: =_xll.EQNXTDZ($A$1,$B50,I$1,$B$1) -> 0 | J50: =_xll.EQNXTDZ($A$1,$B50,J$1,$B$1) -> 0 | ... AG50: =_xll.EQNXTDZ($A$1,$B50,AG$1,$B$1) -> 0
A51: Long Term Trade Payables | B51: BS_LT_TRADE_PAYABLES | C51: =_xll.EQNXTDZ($A$1,$B51,C$1,$B$1) -> 0 | D51: =_xll.EQNXTDZ($A$1,$B51,D$1,$B$1) -> 0 | E51: =_xll.EQNXTDZ($A$1,$B51,E$1,$B$1) -> 0 | F51: =_xll.EQNXTDZ($A$1,$B51,F$1,$B$1) -> 0 | G51: =_xll.EQNXTDZ($A$1,$B51,G$1,$B$1) -> 0 | H51: =_xll.EQNXTDZ($A$1,$B51,H$1,$B$1) -> 0 | I51: =_xll.EQNXTDZ($A$1,$B51,I$1,$B$1) -> 0 | J51: =_xll.EQNXTDZ($A$1,$B51,J$1,$B$1) -> 0 | ... AG51: =_xll.EQNXTDZ($A$1,$B51,AG$1,$B$1) -> 0
